# Ancient Warfare Structure Template File
# auto-generated structure file. created on: 4/21/2014 at: 17:29:51
# Lines beginning with # denote comments

header:
version=2.0
name=bandit_campsite_HuntingBlock
size=18,9,18
offset=7,1,17
:endheader

#### VALIDATION ####
validation:
type=ground
survival=false
worldGenEnabled=true
unique=false
preserveBlocks=false
selectionWeight=10
clusterValue=85
minDuplicateDistance=20
dimensionWhiteList=false
dimensionList=
biomeWhiteList=false
biomeList=
leveling=10
fill=5
border=5
validTargetBlocks=clay,lapis_ore,lit_redstone_ore,stone,carpet,tile.bop.mud,gravel,coal_block,diamond_ore,ice,snow,netherrack,tile.bop.longGrass,tile.bop.generic.hard_dirt,tile.bop.redRocks,dirt,redstone_ore,mycelium,tile.bop.holyStone,sand,grass,tile.bop.ash,iron_ore,soul_sand,snow_layer,stained_hardened_clay,coal_ore,gold_ore,tile.bop.generic.hard_sand
data:
:enddata
:endvalidation

#### LAYERS ####
layer: 0
1,1,1,1,1,1,1,1,1,1,1,1,1,1,1,1,1,1
1,1,1,1,1,2,3,3,3,2,1,1,1,1,1,1,1,1
1,1,1,1,1,2,4,4,4,2,1,1,1,1,1,1,1,1
1,1,1,1,1,2,4,4,4,2,1,1,1,1,1,1,1,1
1,1,1,1,1,2,4,4,4,2,1,1,1,1,1,1,1,1
1,1,1,1,1,2,4,4,4,2,1,1,1,1,1,1,1,1
1,1,1,1,1,1,5,5,5,1,1,1,1,1,1,1,1,1
1,1,1,1,1,1,5,5,5,5,1,1,1,1,1,1,1,1
1,1,1,1,1,5,5,5,5,5,5,1,2,2,2,2,2,1
1,2,2,2,5,5,5,1,1,5,5,5,4,4,4,4,4,1
1,2,4,4,5,5,5,1,1,1,5,5,4,4,4,4,4,1
1,2,2,2,5,5,5,5,5,5,5,5,4,4,4,4,4,1
1,1,1,1,1,5,5,5,5,5,5,5,2,2,2,2,2,1
1,1,1,1,5,5,6,7,8,5,5,1,1,1,1,1,1,1
1,1,1,1,5,5,6,9,8,5,5,1,1,1,1,1,1,1
1,1,1,1,5,5,6,10,8,5,5,1,1,1,1,1,1,1
1,1,1,1,1,5,5,5,5,5,1,1,1,1,1,1,1,1
1,1,1,1,1,1,5,5,5,1,1,1,1,1,1,1,1,1
:endlayer
layer: 1
0,0,0,0,0,11,0,0,0,11,0,0,0,0,0,0,0,0
0,0,0,0,0,3,3,3,3,3,0,0,0,0,0,0,0,0
0,0,0,0,0,3,12,13,12,3,0,0,0,0,0,0,0,0
0,0,0,0,14,3,15,0,15,3,16,0,0,0,0,0,0,0
0,0,0,0,0,3,0,0,0,3,0,0,0,0,0,0,0,0
0,0,0,0,0,3,0,17,0,3,0,0,0,0,0,0,0,0
0,0,0,0,0,18,0,0,0,18,0,0,0,0,0,0,0,0
0,0,0,0,0,0,0,0,0,0,0,0,0,0,11,0,0,0
0,0,0,0,0,0,0,0,0,0,0,14,3,3,3,3,3,16
0,3,4,3,0,0,0,0,0,0,0,0,0,0,19,20,3,0
0,4,21,22,0,0,0,0,0,0,0,0,17,0,0,0,3,0
0,3,4,3,0,0,0,0,0,0,0,0,0,0,19,20,3,0
0,0,0,0,0,0,0,0,0,0,0,14,3,3,3,3,3,16
0,0,0,0,0,0,17,17,17,0,0,0,0,0,18,0,0,0
0,0,0,0,0,0,17,23,17,0,0,0,0,0,0,0,0,0
0,0,0,0,0,0,17,17,17,0,0,0,0,0,0,0,0,0
0,0,0,0,0,0,0,0,0,0,0,0,0,0,0,0,0,0
0,0,0,0,0,0,0,0,0,0,0,0,0,0,0,0,0,0
:endlayer
layer: 2
0,0,0,0,0,0,0,0,0,0,0,0,0,0,0,0,0,0
0,0,0,0,0,8,3,17,3,6,0,0,0,0,0,0,0,0
0,0,0,0,0,8,0,0,0,6,0,0,0,0,0,0,0,0
0,0,0,0,0,8,0,0,0,6,0,0,0,0,0,0,0,0
0,0,0,0,0,8,0,0,0,6,0,0,0,0,0,0,0,0
0,0,0,0,0,8,0,17,0,6,0,0,0,0,0,0,0,0
0,0,0,0,0,0,0,0,0,0,0,0,0,0,0,0,0,0
0,0,0,0,0,0,0,0,0,0,0,0,0,0,0,0,0,0
0,0,0,0,0,0,0,0,0,0,0,0,10,10,10,10,10,0
0,3,4,3,0,0,0,0,0,0,0,0,0,0,0,0,3,0
0,4,21,24,0,0,0,0,0,0,0,0,17,0,0,0,17,0
0,3,4,3,0,0,0,0,0,0,0,0,0,0,0,0,3,0
0,0,0,0,0,0,0,0,0,0,0,0,7,7,7,7,7,0
0,0,0,0,0,0,0,0,0,0,0,0,0,0,0,0,0,0
0,0,0,0,0,0,0,0,0,0,0,0,0,0,0,0,0,0
0,0,0,0,0,0,0,0,0,0,0,0,0,0,0,0,0,0
0,0,0,0,0,0,0,0,0,0,0,0,0,0,0,0,0,0
0,0,0,0,0,0,0,0,0,0,0,0,0,0,0,0,0,0
:endlayer
layer: 3
0,0,0,0,0,0,0,0,0,0,0,0,0,0,0,0,0,0
0,0,0,0,0,0,8,3,6,0,0,0,0,0,0,0,0,0
0,0,0,0,0,0,8,0,6,0,0,0,0,0,0,0,0,0
0,0,0,0,0,0,8,0,6,0,0,0,0,0,0,0,0,0
0,0,0,0,0,0,8,0,6,0,0,0,0,0,0,0,0,0
0,0,0,0,0,0,8,17,6,0,0,0,0,0,0,0,0,0
0,0,0,0,0,0,0,0,0,0,0,0,0,0,0,0,0,0
0,0,0,0,0,0,0,0,0,0,0,0,0,0,0,0,0,0
0,0,11,0,0,0,0,0,0,0,0,0,0,0,0,0,0,0
0,17,4,17,0,0,0,0,0,0,0,0,10,10,10,10,10,0
14,4,21,4,16,0,0,0,0,0,0,0,17,0,0,0,3,0
0,17,4,17,0,0,0,0,0,0,0,0,7,7,7,7,7,0
0,0,18,0,0,0,0,0,0,0,0,0,0,0,0,0,0,0
0,0,0,0,0,0,0,0,0,0,0,0,0,0,0,0,0,0
0,0,0,0,0,0,0,0,0,0,0,0,0,0,0,0,0,0
0,0,0,0,0,0,0,0,0,0,0,0,0,0,0,0,0,0
0,0,0,0,0,0,0,0,0,0,0,0,0,0,0,0,0,0
0,0,0,0,0,0,0,0,0,0,0,0,0,0,0,0,0,0
:endlayer
layer: 4
0,0,0,0,0,0,0,0,0,0,0,0,0,0,0,0,0,0
0,0,0,0,0,0,0,25,0,0,0,0,0,0,0,0,0,0
0,0,0,0,0,0,0,25,0,0,0,0,0,0,0,0,0,0
0,0,0,0,0,0,0,25,0,0,0,0,0,0,0,0,0,0
0,0,0,0,0,0,0,25,0,0,0,0,0,0,0,0,0,0
0,0,0,0,0,0,0,25,0,0,0,0,0,0,0,0,0,0
0,0,0,0,0,0,0,0,0,0,0,0,0,0,0,0,0,0
0,0,0,0,0,0,0,0,0,0,0,0,0,0,0,0,0,0
0,0,0,0,0,0,0,0,0,0,0,0,0,0,0,0,0,0
0,17,4,17,0,0,0,0,0,0,0,0,0,0,0,0,0,0
0,4,21,4,0,0,0,0,0,0,0,0,25,25,25,25,25,0
0,17,4,17,0,0,0,0,0,0,0,0,0,0,0,0,0,0
0,0,0,0,0,0,0,0,0,0,0,0,0,0,0,0,0,0
0,0,0,0,0,0,0,0,0,0,0,0,0,0,0,0,0,0
0,0,0,0,0,0,0,0,0,0,0,0,0,0,0,0,0,0
0,0,0,0,0,0,0,0,0,0,0,0,0,0,0,0,0,0
0,0,0,0,0,0,0,0,0,0,0,0,0,0,0,0,0,0
0,0,0,0,0,0,0,0,0,0,0,0,0,0,0,0,0,0
:endlayer
layer: 5
0,0,0,0,0,0,0,0,0,0,0,0,0,0,0,0,0,0
0,0,0,0,0,0,0,0,0,0,0,0,0,0,0,0,0,0
0,0,0,0,0,0,0,0,0,0,0,0,0,0,0,0,0,0
0,0,0,0,0,0,0,0,0,0,0,0,0,0,0,0,0,0
0,0,0,0,0,0,0,0,0,0,0,0,0,0,0,0,0,0
0,0,0,0,0,0,0,0,0,0,0,0,0,0,0,0,0,0
0,0,0,0,0,0,0,0,0,0,0,0,0,0,0,0,0,0
0,0,0,0,0,0,0,0,0,0,0,0,0,0,0,0,0,0
0,0,0,0,0,0,0,0,0,0,0,0,0,0,0,0,0,0
0,17,4,17,0,0,0,0,0,0,0,0,0,0,0,0,0,0
0,4,21,4,0,0,0,0,0,0,0,0,0,0,0,0,0,0
0,17,4,17,0,0,0,0,0,0,0,0,0,0,0,0,0,0
0,0,0,0,0,0,0,0,0,0,0,0,0,0,0,0,0,0
0,0,0,0,0,0,0,0,0,0,0,0,0,0,0,0,0,0
0,0,0,0,0,0,0,0,0,0,0,0,0,0,0,0,0,0
0,0,0,0,0,0,0,0,0,0,0,0,0,0,0,0,0,0
0,0,0,0,0,0,0,0,0,0,0,0,0,0,0,0,0,0
0,0,0,0,0,0,0,0,0,0,0,0,0,0,0,0,0,0
:endlayer
layer: 6
0,0,0,0,0,0,0,0,0,0,0,0,0,0,0,0,0,0
0,0,0,0,0,0,0,0,0,0,0,0,0,0,0,0,0,0
0,0,0,0,0,0,0,0,0,0,0,0,0,0,0,0,0,0
0,0,0,0,0,0,0,0,0,0,0,0,0,0,0,0,0,0
0,0,0,0,0,0,0,0,0,0,0,0,0,0,0,0,0,0
0,0,0,0,0,0,0,0,0,0,0,0,0,0,0,0,0,0
0,0,0,0,0,0,0,0,0,0,0,0,0,0,0,0,0,0
0,0,0,0,0,0,0,0,0,0,0,0,0,0,0,0,0,0
0,17,17,17,0,0,0,0,0,0,0,0,0,0,0,0,0,0
17,3,26,3,17,0,0,0,0,0,0,0,0,0,0,0,0,0
17,27,21,28,17,0,0,0,0,0,0,0,0,0,0,0,0,0
17,3,29,3,17,0,0,0,0,0,0,0,0,0,0,0,0,0
0,17,17,17,0,0,0,0,0,0,0,0,0,0,0,0,0,0
0,0,0,0,0,0,0,0,0,0,0,0,0,0,0,0,0,0
0,0,0,0,0,0,0,0,0,0,0,0,0,0,0,0,0,0
0,0,0,0,0,0,0,0,0,0,0,0,0,0,0,0,0,0
0,0,0,0,0,0,0,0,0,0,0,0,0,0,0,0,0,0
0,0,0,0,0,0,0,0,0,0,0,0,0,0,0,0,0,0
:endlayer
layer: 7
0,0,0,0,0,0,0,0,0,0,0,0,0,0,0,0,0,0
0,0,0,0,0,0,0,0,0,0,0,0,0,0,0,0,0,0
0,0,0,0,0,0,0,0,0,0,0,0,0,0,0,0,0,0
0,0,0,0,0,0,0,0,0,0,0,0,0,0,0,0,0,0
0,0,0,0,0,0,0,0,0,0,0,0,0,0,0,0,0,0
0,0,0,0,0,0,0,0,0,0,0,0,0,0,0,0,0,0
0,0,0,0,0,0,0,0,0,0,0,0,0,0,0,0,0,0
0,0,0,0,0,0,0,0,0,0,0,0,0,0,0,0,0,0
0,30,30,30,0,0,0,0,0,0,0,0,0,0,0,0,0,0
30,30,0,30,30,0,0,0,0,0,0,0,0,0,0,0,0,0
30,0,0,0,30,0,0,0,0,0,0,0,0,0,0,0,0,0
30,30,0,30,30,0,0,0,0,0,0,0,0,0,0,0,0,0
0,30,30,30,0,0,0,0,0,0,0,0,0,0,0,0,0,0
0,0,0,0,0,0,0,0,0,0,0,0,0,0,0,0,0,0
0,0,0,0,0,0,0,0,0,0,0,0,0,0,0,0,0,0
0,0,0,0,0,0,0,0,0,0,0,0,0,0,0,0,0,0
0,0,0,0,0,0,0,0,0,0,0,0,0,0,0,0,0,0
0,0,0,0,0,0,0,0,0,0,0,0,0,0,0,0,0,0
:endlayer
layer: 8
0,0,0,0,0,0,0,0,0,0,0,0,0,0,0,0,0,0
0,0,0,0,0,0,0,0,0,0,0,0,0,0,0,0,0,0
0,0,0,0,0,0,0,0,0,0,0,0,0,0,0,0,0,0
0,0,0,0,0,0,0,0,0,0,0,0,0,0,0,0,0,0
0,0,0,0,0,0,0,0,0,0,0,0,0,0,0,0,0,0
0,0,0,0,0,0,0,0,0,0,0,0,0,0,0,0,0,0
0,0,0,0,0,0,0,0,0,0,0,0,0,0,0,0,0,0
0,0,0,0,0,0,0,0,0,0,0,0,0,0,0,0,0,0
0,0,0,0,0,0,0,0,0,0,0,0,0,0,0,0,0,0
0,0,0,0,0,0,0,0,0,0,0,0,0,0,0,0,0,0
0,0,0,0,0,0,0,0,0,0,0,0,0,0,0,0,0,0
0,0,0,31,0,0,0,0,0,0,0,0,0,0,0,0,0,0
0,0,0,0,0,0,0,0,0,0,0,0,0,0,0,0,0,0
0,0,0,0,0,0,0,0,0,0,0,0,0,0,0,0,0,0
0,0,0,0,0,0,0,0,0,0,0,0,0,0,0,0,0,0
0,0,0,0,0,0,0,0,0,0,0,0,0,0,0,0,0,0
0,0,0,0,0,0,0,0,0,0,0,0,0,0,0,0,0,0
0,0,0,0,0,0,0,0,0,0,0,0,0,0,0,0,0,0
:endlayer

#### RULES ####
rule:
plugin=vanillaBlocks
number=1
data:
tag:
TAG=10={
TAG=8=blockName{grass}
TAG=3=meta{0}
TAG=3=buildPass{0}
}
:endtag
:enddata
:endrule

rule:
plugin=vanillaBlocks
number=2
data:
tag:
TAG=10={
TAG=8=blockName{dirt}
TAG=3=meta{0}
TAG=3=buildPass{0}
}
:endtag
:enddata
:endrule

rule:
plugin=vanillaBlocks
number=3
data:
tag:
TAG=10={
TAG=8=blockName{nether_brick}
TAG=3=meta{0}
TAG=3=buildPass{0}
}
:endtag
:enddata
:endrule

rule:
plugin=vanillaBlocks
number=4
data:
tag:
TAG=10={
TAG=8=blockName{planks}
TAG=3=meta{0}
TAG=3=buildPass{0}
}
:endtag
:enddata
:endrule

rule:
plugin=vanillaBlocks
number=5
data:
tag:
TAG=10={
TAG=8=blockName{gravel}
TAG=3=meta{0}
TAG=3=buildPass{1}
}
:endtag
:enddata
:endrule

rule:
plugin=vanillaBlocks
number=6
data:
tag:
TAG=10={
TAG=8=blockName{nether_brick_stairs}
TAG=3=meta{1}
TAG=3=buildPass{0}
}
:endtag
:enddata
:endrule

rule:
plugin=vanillaBlocks
number=7
data:
tag:
TAG=10={
TAG=8=blockName{nether_brick_stairs}
TAG=3=meta{3}
TAG=3=buildPass{0}
}
:endtag
:enddata
:endrule

rule:
plugin=vanillaBlocks
number=8
data:
tag:
TAG=10={
TAG=8=blockName{nether_brick_stairs}
TAG=3=meta{0}
TAG=3=buildPass{0}
}
:endtag
:enddata
:endrule

rule:
plugin=vanillaBlocks
number=9
data:
tag:
TAG=10={
TAG=8=blockName{netherrack}
TAG=3=meta{0}
TAG=3=buildPass{0}
}
:endtag
:enddata
:endrule

rule:
plugin=vanillaBlocks
number=10
data:
tag:
TAG=10={
TAG=8=blockName{nether_brick_stairs}
TAG=3=meta{2}
TAG=3=buildPass{0}
}
:endtag
:enddata
:endrule

rule:
plugin=vanillaBlocks
number=11
data:
tag:
TAG=10={
TAG=8=blockName{torch}
TAG=3=meta{4}
TAG=3=buildPass{1}
}
:endtag
:enddata
:endrule

rule:
plugin=vanillaBlocks
number=12
data:
tag:
TAG=10={
TAG=8=blockName{bed}
TAG=3=meta{10}
TAG=3=buildPass{0}
}
:endtag
:enddata
:endrule

rule:
plugin=vanillaInventory
number=13
data:
tag:
TAG=10={
TAG=3=lootLevel{3}
TAG=8=blockName{chest}
TAG=3=meta{3}
TAG=3=buildPass{0}
}
:endtag
:enddata
:endrule

rule:
plugin=vanillaBlocks
number=14
data:
tag:
TAG=10={
TAG=8=blockName{torch}
TAG=3=meta{2}
TAG=3=buildPass{1}
}
:endtag
:enddata
:endrule

rule:
plugin=vanillaBlocks
number=15
data:
tag:
TAG=10={
TAG=8=blockName{bed}
TAG=3=meta{2}
TAG=3=buildPass{0}
}
:endtag
:enddata
:endrule

rule:
plugin=vanillaBlocks
number=16
data:
tag:
TAG=10={
TAG=8=blockName{torch}
TAG=3=meta{1}
TAG=3=buildPass{1}
}
:endtag
:enddata
:endrule

rule:
plugin=vanillaBlocks
number=17
data:
tag:
TAG=10={
TAG=8=blockName{nether_brick_fence}
TAG=3=meta{0}
TAG=3=buildPass{0}
}
:endtag
:enddata
:endrule

rule:
plugin=vanillaBlocks
number=18
data:
tag:
TAG=10={
TAG=8=blockName{torch}
TAG=3=meta{3}
TAG=3=buildPass{1}
}
:endtag
:enddata
:endrule

rule:
plugin=vanillaBlocks
number=19
data:
tag:
TAG=10={
TAG=8=blockName{bed}
TAG=3=meta{3}
TAG=3=buildPass{0}
}
:endtag
:enddata
:endrule

rule:
plugin=vanillaBlocks
number=20
data:
tag:
TAG=10={
TAG=8=blockName{bed}
TAG=3=meta{11}
TAG=3=buildPass{0}
}
:endtag
:enddata
:endrule

rule:
plugin=vanillaBlocks
number=21
data:
tag:
TAG=10={
TAG=8=blockName{ladder}
TAG=3=meta{5}
TAG=3=buildPass{1}
}
:endtag
:enddata
:endrule

rule:
plugin=vanillaDoors
number=22
data:
tag:
TAG=10={
TAG=1=sideFlag{8}
TAG=8=blockName{wooden_door}
TAG=3=meta{2}
TAG=3=buildPass{1}
}
:endtag
:enddata
:endrule

rule:
plugin=vanillaBlocks
number=23
data:
tag:
TAG=10={
TAG=8=blockName{fire}
TAG=3=meta{15}
TAG=3=buildPass{0}
}
:endtag
:enddata
:endrule

rule:
plugin=vanillaDoors
number=24
data:
tag:
TAG=10={
TAG=1=sideFlag{0}
TAG=8=blockName{wooden_door}
TAG=3=meta{8}
TAG=3=buildPass{1}
}
:endtag
:enddata
:endrule

rule:
plugin=vanillaBlocks
number=25
data:
tag:
TAG=10={
TAG=8=blockName{stone_slab}
TAG=3=meta{6}
TAG=3=buildPass{0}
}
:endtag
:enddata
:endrule

rule:
plugin=vanillaBlocks
number=26
data:
tag:
TAG=10={
TAG=8=blockName{oak_stairs}
TAG=3=meta{6}
TAG=3=buildPass{0}
}
:endtag
:enddata
:endrule

rule:
plugin=vanillaBlocks
number=27
data:
tag:
TAG=10={
TAG=8=blockName{oak_stairs}
TAG=3=meta{4}
TAG=3=buildPass{0}
}
:endtag
:enddata
:endrule

rule:
plugin=vanillaBlocks
number=28
data:
tag:
TAG=10={
TAG=8=blockName{oak_stairs}
TAG=3=meta{5}
TAG=3=buildPass{0}
}
:endtag
:enddata
:endrule

rule:
plugin=vanillaBlocks
number=29
data:
tag:
TAG=10={
TAG=8=blockName{oak_stairs}
TAG=3=meta{7}
TAG=3=buildPass{0}
}
:endtag
:enddata
:endrule

rule:
plugin=vanillaBlocks
number=30
data:
tag:
TAG=10={
TAG=8=blockName{fence}
TAG=3=meta{0}
TAG=3=buildPass{0}
}
:endtag
:enddata
:endrule

rule:
plugin=vanillaBlocks
number=31
data:
tag:
TAG=10={
TAG=8=blockName{torch}
TAG=3=meta{5}
TAG=3=buildPass{1}
}
:endtag
:enddata
:endrule

#### ENTITIES ####
entity:
plugin=awNpcOld
number=0
data:
position=2,7,9
tag:
TAG=10={
TAG=5=yOffset{0.0}
TAG=5=xOffset{0.5}
TAG=5=zOffset{0.5}
TAG=5=rotation{-248.76294}
TAG=3=npcLevel{3}
TAG=3=npcType{17}
TAG=3=npcTeam{17}
}
:endtag
:enddata
:endentity

entity:
plugin=awNpcOld
number=1
data:
position=2,7,11
tag:
TAG=10={
TAG=5=yOffset{0.0}
TAG=5=xOffset{0.5}
TAG=5=zOffset{0.5}
TAG=5=rotation{-289.5631}
TAG=3=npcLevel{3}
TAG=3=npcType{17}
TAG=3=npcTeam{17}
}
:endtag
:enddata
:endentity

entity:
plugin=awNpcOld
number=2
data:
position=7,1,8
tag:
TAG=10={
TAG=5=yOffset{0.0}
TAG=5=xOffset{0.5}
TAG=5=zOffset{0.5}
TAG=5=rotation{-173.91272}
TAG=3=npcLevel{2}
TAG=3=npcType{16}
TAG=3=npcTeam{17}
}
:endtag
:enddata
:endentity

entity:
plugin=awNpcOld
number=3
data:
position=10,1,10
tag:
TAG=10={
TAG=5=yOffset{0.0}
TAG=5=xOffset{0.5}
TAG=5=zOffset{0.5}
TAG=5=rotation{-110.16211}
TAG=3=npcLevel{0}
TAG=3=npcType{16}
TAG=3=npcTeam{17}
}
:endtag
:enddata
:endentity

entity:
plugin=awNpcOld
number=4
data:
position=5,1,9
tag:
TAG=10={
TAG=5=yOffset{0.0}
TAG=5=xOffset{0.5}
TAG=5=zOffset{0.5}
TAG=5=rotation{-197.46204}
TAG=3=npcLevel{0}
TAG=3=npcType{16}
TAG=3=npcTeam{17}
}
:endtag
:enddata
:endentity

entity:
plugin=awNpcOld
number=5
data:
position=10,1,12
tag:
TAG=10={
TAG=5=yOffset{0.0}
TAG=5=xOffset{0.5}
TAG=5=zOffset{0.5}
TAG=5=rotation{-82.41211}
TAG=3=npcLevel{3}
TAG=3=npcType{17}
TAG=3=npcTeam{17}
}
:endtag
:enddata
:endentity

