# Ancient Warfare Structure Template File
# auto-generated structure file. created on: 4/21/2014 at: 17:33:6
# Lines beginning with # denote comments

header:
version=2.0
name=barn_house_czarified
size=14,10,12
offset=12,1,10
:endheader

#### VALIDATION ####
validation:
type=ground
survival=true
worldGenEnabled=false
unique=false
preserveBlocks=false
selectionWeight=1
clusterValue=1
minDuplicateDistance=1
dimensionWhiteList=false
dimensionList=
biomeWhiteList=false
biomeList=
leveling=0
fill=0
border=0
validTargetBlocks=clay,lapis_ore,lit_redstone_ore,stone,tile.bop.mud,carpet,gravel,coal_block,diamond_ore,ice,snow,netherrack,tile.bop.generic.hard_dirt,tile.bop.longGrass,tile.bop.redRocks,dirt,redstone_ore,mycelium,tile.bop.holyStone,sand,grass,tile.bop.ash,iron_ore,soul_sand,snow_layer,stained_hardened_clay,coal_ore,gold_ore,tile.bop.generic.hard_sand
data:
:enddata
:endvalidation

#### LAYERS ####
layer: 0
1,1,1,1,1,1,1,1,1,1,1,1,1,1
4,4,4,4,4,4,4,4,4,4,4,4,4,4
4,4,4,3,4,4,5,4,5,4,3,4,4,4
4,5,4,4,5,4,4,3,4,4,4,4,3,4
4,4,3,5,4,3,5,4,4,3,5,4,4,4
4,5,4,4,4,4,4,5,5,4,3,4,3,4
4,5,4,4,5,4,4,3,4,4,4,4,3,4
4,4,3,3,4,5,3,4,5,5,4,3,4,4
4,4,4,4,4,4,4,4,4,5,4,4,4,4
4,4,4,4,4,4,4,4,4,4,4,4,4,4
1,1,1,1,1,1,1,1,3,3,3,1,2,1
1,1,1,1,1,1,1,1,1,1,1,1,1,1
:endlayer
layer: 1
0,0,0,0,0,0,0,0,0,0,0,0,0,0
7,8,8,7,8,8,7,8,7,8,8,7,8,7
9,0,0,0,0,0,10,0,0,0,0,0,0,9
9,0,0,0,0,0,0,0,0,0,0,0,0,9
9,0,0,0,0,0,0,0,0,0,0,0,0,9
9,0,0,0,0,0,0,0,0,0,0,0,0,9
9,0,0,0,0,0,0,0,0,0,0,0,0,9
9,0,0,0,0,0,0,0,0,0,0,0,0,9
9,0,0,0,0,0,0,0,0,0,0,0,0,9
7,8,8,7,8,8,7,8,7,8,8,7,0,7
0,0,0,0,0,0,0,0,0,0,0,0,0,0
0,0,0,6,0,6,6,0,6,6,6,6,0,0
:endlayer
layer: 2
0,0,0,0,0,0,0,0,0,0,0,0,0,0
7,8,8,7,0,0,7,8,7,0,0,7,8,7
9,0,0,0,0,0,10,0,0,0,0,0,0,9
9,0,0,0,0,0,0,0,0,0,0,0,0,9
9,0,0,0,0,0,0,0,0,0,0,0,0,9
9,0,0,0,0,0,0,0,0,0,0,0,11,9
9,0,0,0,0,0,0,0,0,0,0,0,0,9
9,0,0,0,0,0,0,0,0,0,0,0,0,9
9,0,0,0,0,0,0,0,0,0,0,0,0,9
7,8,8,7,0,0,7,8,7,0,0,7,0,7
0,0,0,0,0,0,0,0,0,0,0,0,0,0
0,0,0,0,0,0,0,0,0,0,0,0,0,0
:endlayer
layer: 3
0,0,0,0,0,0,0,0,0,0,0,12,0,0
7,8,8,7,0,0,7,8,7,0,0,7,8,13
9,0,0,15,0,0,10,0,0,0,0,0,0,13
9,0,0,0,0,0,0,0,0,0,0,0,0,13
9,0,0,0,0,0,0,0,0,0,0,0,0,13
9,0,0,0,0,0,0,0,0,0,0,0,0,13
9,0,0,0,0,0,0,0,0,0,0,0,0,13
9,0,0,0,0,0,0,0,0,0,0,0,0,13
9,0,0,0,0,0,14,0,0,0,0,0,0,13
7,8,8,7,0,0,7,8,7,0,0,7,8,7
0,0,0,0,0,0,0,0,0,0,0,12,0,0
0,0,0,0,0,0,0,0,0,0,0,0,0,0
:endlayer
layer: 4
16,12,0,0,0,0,0,0,0,12,16,16,0,0
16,17,17,7,17,17,7,17,7,17,16,16,16,0
16,0,0,0,0,0,10,0,0,0,0,16,16,0
16,0,0,0,0,0,0,0,0,0,0,0,16,0
16,0,0,0,0,0,0,0,0,0,0,0,16,0
16,0,0,0,0,0,0,0,0,0,0,0,16,0
16,0,0,0,0,0,0,0,0,0,0,0,16,0
16,0,0,0,0,0,0,0,0,0,0,0,16,0
16,0,0,0,0,0,0,0,0,0,0,16,16,0
16,17,17,7,17,17,7,17,7,17,16,16,16,0
16,12,0,0,0,0,0,0,0,12,16,16,0,0
0,0,0,0,0,0,0,0,0,0,0,0,0,0
:endlayer
layer: 5
0,16,12,0,0,0,0,0,12,16,0,0,0,0
0,16,17,7,18,18,7,17,19,16,0,0,0,0
0,16,0,19,20,20,10,20,19,16,16,0,0,0
0,16,0,19,20,20,20,20,19,16,16,16,0,0
0,16,0,19,20,20,20,20,19,16,16,16,0,0
0,16,0,19,20,20,20,20,19,16,16,16,0,0
0,16,0,19,20,20,20,20,19,16,16,16,0,0
0,16,0,19,20,20,20,20,19,16,16,16,0,0
0,16,0,19,20,20,20,20,19,16,16,0,0,0
0,16,17,7,18,18,7,17,7,16,0,0,0,0
0,16,12,0,0,0,0,0,12,16,0,0,0,0
0,0,0,0,0,0,0,0,0,0,0,0,0,0
:endlayer
layer: 6
0,0,16,12,0,0,0,12,16,0,0,0,0,0
0,0,16,7,17,17,7,17,16,0,0,0,0,0
0,0,16,0,0,0,0,0,16,0,0,0,0,0
0,0,16,0,0,0,0,12,0,0,0,0,0,0
0,0,16,0,0,0,0,0,12,0,0,0,0,0
0,0,16,0,0,0,0,0,12,0,0,0,0,0
0,0,16,0,0,0,0,0,12,0,0,0,0,0
0,0,16,0,0,0,0,12,0,0,0,0,0,0
0,0,16,0,0,21,0,0,16,0,0,0,0,0
0,0,16,7,17,17,7,17,16,0,0,0,0,0
0,0,16,12,0,0,0,12,16,0,0,0,0,0
0,0,0,0,0,0,0,0,0,0,0,0,0,0
:endlayer
layer: 7
0,0,0,16,12,0,12,16,0,0,0,0,0,0
0,0,0,16,17,17,7,16,0,0,0,0,0,0
0,0,0,16,0,15,0,16,0,0,0,0,0,0
0,0,0,16,0,0,0,12,0,0,0,0,0,0
0,0,0,16,0,0,0,0,12,0,0,0,0,0
0,0,0,16,0,0,0,0,0,0,0,0,0,0
0,0,0,16,0,0,0,0,12,0,0,0,0,0
0,0,0,16,0,0,0,12,0,0,0,0,0,0
0,0,0,16,0,14,0,16,0,0,0,0,0,0
0,0,0,16,17,17,7,16,0,0,0,0,0,0
0,0,0,16,12,0,12,16,0,0,0,0,0,0
0,0,0,0,0,0,0,0,0,0,0,0,0,0
:endlayer
layer: 8
0,0,0,0,16,12,16,0,0,0,0,0,0,0
0,0,0,0,16,19,16,0,0,0,0,0,0,0
0,0,0,0,16,19,16,0,0,0,0,0,0,0
0,0,0,0,16,19,20,22,0,0,0,0,0,0
0,0,0,0,16,19,20,22,23,0,0,0,0,0
0,0,0,0,16,19,20,22,23,0,0,0,0,0
0,0,0,0,16,19,20,22,23,0,0,0,0,0
0,0,0,0,16,19,20,22,0,0,0,0,0,0
0,0,0,0,16,19,16,0,0,0,0,0,0,0
0,0,0,0,16,19,16,0,0,0,0,0,0,0
0,0,0,0,16,19,16,0,0,0,0,0,0,0
0,0,0,0,0,0,0,0,0,0,0,0,0,0
:endlayer
layer: 9
0,0,0,0,0,16,0,0,0,0,0,0,0,0
0,0,0,0,0,16,0,0,0,0,0,0,0,0
0,0,0,0,0,16,0,0,0,0,0,0,0,0
0,0,0,0,0,16,0,0,0,0,0,0,0,0
0,0,0,0,0,16,23,0,0,0,0,0,0,0
0,0,0,0,0,16,23,0,0,0,0,0,0,0
0,0,0,0,0,16,23,0,0,0,0,0,0,0
0,0,0,0,0,16,0,0,0,0,0,0,0,0
0,0,0,0,0,16,0,0,0,0,0,0,0,0
0,0,0,0,0,16,0,0,0,0,0,0,0,0
0,0,0,0,0,16,0,0,0,0,0,0,0,0
0,0,0,0,0,0,0,0,0,0,0,0,0,0
:endlayer

#### RULES ####
rule:
plugin=vanillaBlocks
number=1
data:
tag:
TAG=10={
TAG=8=blockName{grass}
TAG=3=meta{0}
TAG=3=buildPass{0}
}
:endtag
:enddata
:endrule

rule:
plugin=vanillaBlocks
number=2
data:
tag:
TAG=10={
TAG=8=blockName{stone_slab}
TAG=3=meta{8}
TAG=3=buildPass{0}
}
:endtag
:enddata
:endrule

rule:
plugin=vanillaBlocks
number=3
data:
tag:
TAG=10={
TAG=8=blockName{gravel}
TAG=3=meta{0}
TAG=3=buildPass{1}
}
:endtag
:enddata
:endrule

rule:
plugin=vanillaBlocks
number=4
data:
tag:
TAG=10={
TAG=8=blockName{stained_hardened_clay}
TAG=3=meta{12}
TAG=3=buildPass{0}
}
:endtag
:enddata
:endrule

rule:
plugin=vanillaBlocks
number=5
data:
tag:
TAG=10={
TAG=8=blockName{dirt}
TAG=3=meta{0}
TAG=3=buildPass{0}
}
:endtag
:enddata
:endrule

rule:
plugin=vanillaBlocks
number=6
data:
tag:
TAG=10={
TAG=8=blockName{tallgrass}
TAG=3=meta{1}
TAG=3=buildPass{0}
}
:endtag
:enddata
:endrule

rule:
plugin=vanillaBlocks
number=7
data:
tag:
TAG=10={
TAG=8=blockName{log}
TAG=3=meta{0}
TAG=3=buildPass{0}
}
:endtag
:enddata
:endrule

rule:
plugin=vanillaBlocks
number=8
data:
tag:
TAG=10={
TAG=8=blockName{wool}
TAG=3=meta{0}
TAG=3=buildPass{0}
}
:endtag
:enddata
:endrule

rule:
plugin=vanillaBlocks
number=9
data:
tag:
TAG=10={
TAG=8=blockName{cobblestone}
TAG=3=meta{0}
TAG=3=buildPass{0}
}
:endtag
:enddata
:endrule

rule:
plugin=vanillaBlocks
number=10
data:
tag:
TAG=10={
TAG=8=blockName{ladder}
TAG=3=meta{3}
TAG=3=buildPass{1}
}
:endtag
:enddata
:endrule

rule:
plugin=vanillaBlocks
number=11
data:
tag:
TAG=10={
TAG=8=blockName{torch}
TAG=3=meta{2}
TAG=3=buildPass{1}
}
:endtag
:enddata
:endrule

rule:
plugin=vanillaBlocks
number=12
data:
tag:
TAG=10={
TAG=8=blockName{fence}
TAG=3=meta{0}
TAG=3=buildPass{0}
}
:endtag
:enddata
:endrule

rule:
plugin=vanillaBlocks
number=13
data:
tag:
TAG=10={
TAG=8=blockName{stone_stairs}
TAG=3=meta{1}
TAG=3=buildPass{0}
}
:endtag
:enddata
:endrule

rule:
plugin=vanillaBlocks
number=14
data:
tag:
TAG=10={
TAG=8=blockName{torch}
TAG=3=meta{4}
TAG=3=buildPass{1}
}
:endtag
:enddata
:endrule

rule:
plugin=vanillaBlocks
number=15
data:
tag:
TAG=10={
TAG=8=blockName{torch}
TAG=3=meta{3}
TAG=3=buildPass{1}
}
:endtag
:enddata
:endrule

rule:
plugin=vanillaBlocks
number=16
data:
tag:
TAG=10={
TAG=8=blockName{hay_block}
TAG=3=meta{8}
TAG=3=buildPass{0}
}
:endtag
:enddata
:endrule

rule:
plugin=vanillaBlocks
number=17
data:
tag:
TAG=10={
TAG=8=blockName{planks}
TAG=3=meta{0}
TAG=3=buildPass{0}
}
:endtag
:enddata
:endrule

rule:
plugin=vanillaBlocks
number=18
data:
tag:
TAG=10={
TAG=8=blockName{log}
TAG=3=meta{4}
TAG=3=buildPass{0}
}
:endtag
:enddata
:endrule

rule:
plugin=vanillaBlocks
number=19
data:
tag:
TAG=10={
TAG=8=blockName{log}
TAG=3=meta{8}
TAG=3=buildPass{0}
}
:endtag
:enddata
:endrule

rule:
plugin=vanillaBlocks
number=20
data:
tag:
TAG=10={
TAG=8=blockName{wooden_slab}
TAG=3=meta{8}
TAG=3=buildPass{0}
}
:endtag
:enddata
:endrule

rule:
plugin=vanillaInventory
number=21
data:
tag:
TAG=10={
TAG=3=lootLevel{0}
TAG=10=teData{
TAG=9=Items{
TAG=10={
TAG=2=id{265}
TAG=2=Damage{0}
TAG=1=Count{3}
TAG=1=Slot{4}
}
TAG=10={
TAG=2=id{297}
TAG=2=Damage{0}
TAG=1=Count{1}
TAG=1=Slot{8}
}
TAG=10={
TAG=2=id{417}
TAG=2=Damage{0}
TAG=1=Count{1}
TAG=1=Slot{10}
}
}
TAG=8=id{Chest}
}
TAG=8=blockName{chest}
TAG=3=meta{2}
TAG=3=buildPass{0}
}
:endtag
:enddata
:endrule

rule:
plugin=vanillaBlocks
number=22
data:
tag:
TAG=10={
TAG=8=blockName{oak_stairs}
TAG=3=meta{1}
TAG=3=buildPass{0}
}
:endtag
:enddata
:endrule

rule:
plugin=vanillaBlocks
number=23
data:
tag:
TAG=10={
TAG=8=blockName{wooden_slab}
TAG=3=meta{0}
TAG=3=buildPass{0}
}
:endtag
:enddata
:endrule

#### ENTITIES ####
