# Ancient Warfare Structure Template File
# auto-generated structure file. created on: 5/4/2014 at: 18:23:46
# Lines beginning with # denote comments

header:
version=2.0
name=CivCastleBaronsHostileMOH
size=43,56,39
offset=8,3,38
:endheader

#### VALIDATION ####
validation:
type=ground
survival=false
worldGenEnabled=true
unique=true
preserveBlocks=false
selectionWeight=34
clusterValue=34
minDuplicateDistance=1
dimensionWhiteList=false
dimensionList=
biomeWhiteList=true
biomeList=highlands.meadow,bop.meadow,ebxl.meadow,field,orchard
leveling=12
fill=6
border=6
validTargetBlocks=clay,sand,lapis_ore,grass,lit_redstone_ore,stone,gravel,iron_ore,diamond_ore,stained_hardened_clay,dirt,coal_ore,gold_ore,redstone_ore
data:
:enddata
:endvalidation

#### LAYERS ####
layer: 0
1,1,1,1,1,1,1,1,1,1,1,1,1,1,1,1,1,1,1,1,1,1,1,1,1,1,1,1,1,1,1,1,1,1,1,1,1,1,1,1,1,1,1
1,1,1,1,1,1,1,1,1,1,1,1,1,1,1,1,1,1,1,1,1,1,1,1,1,1,1,1,1,1,1,1,1,1,1,1,1,1,1,1,1,1,1
1,1,1,1,1,1,1,1,1,1,1,1,1,1,1,1,1,1,1,1,1,1,1,1,1,1,1,1,1,1,1,1,1,1,1,1,1,1,1,1,1,1,1
1,1,1,1,1,1,1,1,1,1,1,1,1,1,1,1,1,1,1,1,1,1,1,1,1,1,1,1,1,1,1,1,1,1,1,1,1,1,1,1,1,1,1
1,1,1,1,1,1,1,1,1,1,1,1,1,1,1,1,1,1,1,1,1,1,1,1,1,1,1,1,1,1,1,1,1,1,1,1,1,1,1,1,1,1,1
1,1,1,1,1,1,1,1,1,1,1,1,1,1,1,1,1,1,1,1,1,1,1,1,1,1,1,1,1,1,1,1,1,1,1,1,1,1,1,1,1,1,1
1,1,1,1,1,1,1,1,1,1,1,1,1,1,1,1,1,1,1,1,1,1,1,1,1,1,1,1,1,1,1,1,1,1,1,1,1,1,1,1,1,1,1
1,1,1,1,1,1,1,1,1,1,1,1,1,1,1,1,1,1,1,1,1,1,1,1,1,1,1,1,1,1,1,1,1,1,1,1,1,1,1,1,1,1,1
1,1,1,1,1,1,1,1,1,1,1,1,1,1,1,1,1,1,1,1,1,1,1,1,1,1,1,1,1,1,1,1,1,1,1,1,1,1,1,1,1,1,1
1,1,1,1,1,1,1,1,1,1,1,1,1,1,1,1,1,1,1,1,1,1,1,1,1,1,1,1,1,1,1,1,1,1,1,1,1,1,1,1,1,1,1
1,1,1,1,1,1,1,1,1,1,1,1,1,1,1,1,1,1,1,1,1,1,1,1,1,1,1,1,1,1,1,1,1,1,1,1,1,1,1,1,1,1,1
1,1,1,1,1,1,1,1,1,1,1,1,1,1,1,1,1,1,1,1,1,1,1,1,1,1,1,1,1,1,1,1,1,1,1,1,1,1,1,1,1,1,1
1,1,1,1,1,1,1,1,1,1,1,1,1,1,1,1,1,1,1,1,1,1,1,1,1,1,1,1,1,1,1,1,1,1,1,1,1,1,1,1,1,1,1
1,1,1,1,1,1,1,1,1,1,1,1,1,1,1,1,1,1,1,1,1,1,1,1,1,1,1,1,1,1,1,1,1,1,1,1,1,1,1,1,1,1,1
1,1,1,1,1,1,1,1,1,1,1,1,1,1,1,1,1,1,1,1,1,1,1,1,1,1,1,1,1,1,1,1,1,1,1,1,1,1,1,1,1,1,1
1,1,1,1,1,1,1,1,1,1,1,1,1,1,1,1,1,1,1,1,1,1,1,1,1,1,1,1,1,1,1,1,1,1,1,1,1,1,1,1,1,1,1
1,1,1,1,1,1,1,1,1,1,1,1,1,1,1,1,1,1,1,1,1,1,1,1,1,1,1,1,1,1,1,1,1,1,1,1,1,1,1,1,1,1,1
1,1,1,1,1,1,1,1,1,1,1,1,1,1,1,1,1,1,1,1,1,1,1,1,1,1,1,1,1,1,1,1,1,1,1,1,1,1,1,1,1,1,1
1,1,1,1,1,1,1,1,1,1,1,1,1,1,1,1,1,1,1,1,1,1,1,1,1,1,1,1,1,1,1,1,1,1,1,1,1,1,1,1,1,1,1
1,1,1,1,1,1,1,1,1,1,1,1,1,1,1,1,1,1,1,1,1,1,1,1,1,1,1,1,1,1,1,1,1,1,1,1,1,1,1,1,1,1,1
1,1,1,1,1,1,1,1,1,1,1,1,1,1,1,1,1,1,1,1,1,1,1,1,1,1,1,1,1,1,1,1,1,1,1,1,1,1,1,1,1,1,1
1,1,1,1,1,1,1,1,1,1,1,1,1,1,1,1,1,1,1,1,1,1,1,1,1,1,1,1,1,1,1,1,1,1,1,1,1,1,1,1,1,1,1
1,1,1,1,1,1,1,1,1,1,1,1,1,1,1,1,1,1,1,1,1,1,1,1,1,1,1,1,1,1,1,1,1,1,1,1,1,1,1,1,1,1,1
1,1,1,1,1,1,1,1,1,1,1,1,1,1,1,1,2,2,2,2,2,1,1,1,2,2,2,2,2,1,1,1,1,1,1,1,1,1,1,1,1,1,1
1,1,1,1,1,1,1,1,1,1,1,1,1,1,1,2,2,1,2,2,2,1,1,1,2,2,2,1,2,1,1,1,1,1,1,1,1,1,1,1,1,1,1
1,1,1,1,1,1,1,1,1,1,1,1,1,1,1,2,2,2,2,2,2,2,2,2,2,2,2,2,2,2,1,1,1,1,1,1,1,1,1,1,1,1,1
1,1,1,1,1,1,1,1,1,1,1,1,1,1,1,2,2,2,2,2,2,2,2,2,2,2,2,2,2,2,2,2,2,2,2,2,2,1,1,1,1,1,1
1,1,1,1,1,1,1,1,1,1,1,1,1,1,1,2,2,2,2,2,2,2,2,2,2,2,2,2,2,2,2,1,1,1,1,1,1,1,1,1,1,1,1
1,1,1,1,1,1,1,1,1,1,1,1,1,1,1,1,2,1,2,2,2,1,1,1,2,2,2,1,2,1,1,1,1,1,1,1,1,1,1,1,1,1,1
1,1,1,1,1,1,1,1,1,1,1,1,1,1,1,1,2,2,2,2,2,1,1,1,2,2,2,2,2,1,1,1,1,1,1,1,1,1,1,1,1,1,1
1,1,1,1,1,1,1,1,1,1,1,1,1,1,1,1,1,1,1,1,1,1,1,1,1,1,1,1,1,1,1,1,1,1,1,1,1,1,1,1,1,1,1
1,1,1,1,1,1,1,1,1,1,1,1,1,1,1,1,1,1,1,1,1,1,1,1,1,1,1,1,1,1,1,1,1,1,1,1,1,1,1,1,1,1,1
1,1,1,1,1,1,1,1,1,1,1,1,1,1,1,1,1,1,1,1,1,1,1,1,1,1,1,1,1,1,1,1,1,1,1,1,1,1,1,1,1,1,1
1,1,1,1,1,1,1,1,1,1,1,1,1,1,1,1,1,1,1,1,1,1,1,1,1,1,1,1,1,1,1,1,1,1,1,1,1,1,1,1,1,1,1
1,1,1,1,1,1,1,1,1,1,1,1,1,1,1,1,1,1,1,1,1,1,1,1,1,1,1,1,1,1,1,1,1,1,1,1,1,1,1,1,1,1,1
1,1,1,1,1,1,1,1,1,1,1,1,1,1,1,1,1,1,1,1,1,1,1,1,1,1,1,1,1,1,1,1,1,1,1,1,1,1,1,1,1,1,1
1,1,1,1,1,1,1,1,1,1,1,1,1,1,1,1,1,1,1,1,1,1,1,1,1,1,1,1,1,1,1,1,1,1,1,1,1,1,1,1,1,1,1
1,1,1,1,1,1,1,1,1,1,1,1,1,1,1,1,1,1,1,1,1,1,1,1,1,1,1,1,1,1,1,1,1,1,1,1,1,1,1,1,1,1,1
1,1,1,1,1,1,1,1,1,1,1,1,1,1,1,1,1,1,1,1,1,1,1,1,1,1,1,1,1,1,1,1,1,1,1,1,1,1,1,1,1,1,1
:endlayer
layer: 1
1,1,1,1,1,1,1,1,1,1,1,1,1,1,1,1,1,1,1,1,1,1,1,1,1,1,1,1,1,1,1,1,1,1,1,1,1,1,1,1,1,1,1
1,1,1,1,1,1,1,1,1,1,1,1,1,1,1,1,1,1,1,1,1,1,1,1,1,1,1,1,1,1,1,1,1,1,1,1,1,1,1,1,1,1,1
1,1,1,1,1,1,1,1,1,1,1,1,1,1,1,1,1,1,1,1,1,1,1,1,1,1,1,1,1,1,1,1,1,1,1,1,1,1,1,1,1,1,1
1,1,1,1,1,1,1,1,1,1,1,1,1,1,1,1,1,1,1,1,1,1,1,1,1,1,1,1,1,1,1,1,1,1,1,1,1,1,1,1,1,1,1
1,1,1,1,1,1,1,1,1,1,1,1,1,1,1,1,1,1,1,1,1,1,1,1,1,1,1,1,1,1,1,1,1,1,1,1,1,1,1,1,1,1,1
1,1,1,1,1,1,1,1,1,1,1,1,1,1,1,1,1,1,1,1,1,1,1,1,1,1,1,1,1,1,1,1,1,1,1,1,1,1,1,1,1,1,1
1,1,1,1,1,1,1,1,1,1,1,1,1,1,1,1,1,1,1,1,1,1,1,1,1,1,1,1,1,1,1,1,1,1,1,1,1,1,1,1,1,1,1
1,1,1,1,1,1,1,1,1,1,1,1,1,1,1,1,1,1,1,1,1,1,1,1,1,1,1,1,1,1,1,1,1,1,1,1,1,1,1,1,1,1,1
1,1,1,1,1,1,1,1,1,1,1,1,1,1,1,1,1,1,1,1,1,1,1,1,1,1,1,1,1,1,1,1,1,1,1,1,1,1,1,1,1,1,1
1,1,1,1,1,1,1,1,1,1,1,1,1,1,1,1,1,1,1,1,1,1,1,1,1,1,1,1,1,1,1,1,1,1,1,1,1,1,1,1,1,1,1
1,1,1,1,1,1,1,1,1,1,1,1,1,1,1,1,1,1,1,1,1,1,1,1,1,1,1,1,1,1,1,1,1,1,1,1,1,1,1,1,1,1,1
1,1,1,1,1,1,1,1,1,1,1,1,1,1,1,1,1,1,1,1,1,1,1,1,1,1,1,1,1,1,1,1,1,1,1,1,1,1,1,1,1,1,1
1,1,1,1,1,1,1,1,1,1,1,1,1,1,1,1,1,1,1,1,1,1,1,1,1,1,1,1,1,1,1,1,1,1,1,1,1,1,1,1,1,1,1
1,1,1,1,1,1,1,1,1,1,1,1,1,1,1,1,1,1,1,1,1,1,1,1,1,1,1,1,1,1,1,1,1,1,1,1,1,1,1,1,1,1,1
1,1,1,1,1,1,1,1,1,1,1,1,1,1,1,1,1,1,1,1,1,1,1,1,1,1,1,1,1,1,1,1,1,1,1,1,1,1,1,1,1,1,1
1,1,1,1,1,1,1,1,1,1,1,1,1,1,1,1,1,1,1,1,1,1,1,1,1,1,1,1,1,1,1,1,1,1,1,1,1,1,1,1,1,1,1
1,1,1,2,2,2,2,2,2,2,2,2,1,1,1,1,1,1,1,1,1,1,1,1,1,1,1,1,1,1,1,1,1,1,1,1,1,1,1,1,1,1,1
1,1,1,2,2,2,2,2,2,2,2,2,1,1,1,1,1,1,1,1,1,1,1,1,1,1,1,1,1,1,1,1,1,1,1,1,1,1,1,1,1,1,1
1,1,1,2,2,2,2,2,2,2,2,2,1,1,1,1,1,1,1,1,1,1,1,1,1,1,1,1,1,1,1,1,1,1,1,1,1,1,1,1,1,1,1
1,1,1,2,2,2,2,2,2,2,2,2,1,1,1,1,1,1,1,1,1,1,1,1,1,1,1,1,1,1,1,1,1,1,1,1,1,1,1,1,1,1,1
1,1,1,2,2,2,2,2,2,2,2,2,1,1,1,1,1,1,1,1,1,1,1,1,1,1,1,1,1,1,1,1,1,1,1,1,1,1,1,1,1,1,1
1,1,1,2,2,2,2,2,2,2,2,2,1,1,1,1,1,1,1,1,1,1,1,1,1,1,1,1,1,1,1,1,1,1,1,1,1,1,1,1,1,1,1
1,1,1,1,1,1,1,1,1,1,1,1,1,1,1,2,2,2,2,2,2,1,1,2,2,2,2,2,2,1,1,1,1,1,1,1,1,1,1,1,1,1,1
1,1,1,1,1,1,1,1,1,1,1,1,1,1,1,2,8,0,0,10,10,2,2,2,10,10,0,0,12,2,1,1,1,1,1,1,1,1,1,1,1,1,1
1,1,1,1,1,1,1,1,1,1,1,1,1,1,2,3,0,2,0,0,0,2,2,2,0,0,0,2,0,13,1,1,1,1,1,1,1,1,1,1,1,1,1
1,1,1,1,1,1,1,1,1,1,1,1,1,1,2,6,0,9,9,9,9,9,0,9,9,9,9,9,0,13,6,2,2,2,2,2,2,1,1,1,1,1,1
1,1,1,1,1,1,1,1,1,1,1,1,1,1,2,5,0,0,0,0,0,0,0,0,0,0,0,0,0,0,0,14,0,0,0,0,0,2,1,1,1,1,1
1,1,1,1,1,1,1,1,1,1,1,1,1,1,2,4,0,9,9,9,9,9,0,9,9,9,9,9,0,13,4,2,2,2,2,2,16,2,1,1,1,1,1
1,1,1,1,1,1,1,1,1,1,1,1,1,1,2,3,0,2,0,0,0,2,2,2,0,0,0,2,0,13,2,1,1,2,2,2,15,2,1,1,1,1,1
1,1,1,1,1,1,1,1,1,1,1,1,1,1,1,2,7,0,0,10,10,2,2,2,10,10,0,0,11,2,1,1,1,2,2,2,2,2,1,1,1,1,1
1,1,1,1,1,1,1,1,1,1,1,1,1,1,1,2,2,2,2,2,2,1,1,2,2,2,2,2,2,1,1,1,1,1,1,1,1,1,1,1,1,1,1
1,1,1,1,1,1,1,1,1,1,1,1,1,1,1,1,1,1,1,1,1,1,1,1,1,1,1,1,1,1,1,1,1,1,1,1,1,1,1,1,1,1,1
1,1,1,1,1,1,1,1,1,1,1,1,1,1,1,1,1,1,1,1,1,1,1,1,1,1,1,1,1,1,1,1,1,1,1,1,1,1,1,1,1,1,1
1,1,1,1,1,1,1,1,1,1,1,1,1,1,1,1,1,1,1,1,1,1,1,1,1,1,1,1,1,1,1,1,1,1,1,1,1,1,1,1,1,1,1
1,1,1,1,1,1,1,1,1,1,1,1,1,1,1,1,1,1,1,1,1,1,1,1,1,1,1,1,1,1,1,1,1,1,1,1,1,1,1,1,1,1,1
1,1,1,1,1,1,1,1,1,1,1,1,1,1,1,1,1,1,1,1,1,1,1,1,1,1,1,1,1,1,1,1,1,1,1,1,1,1,1,1,1,1,1
1,1,1,1,1,1,1,1,1,1,1,1,1,1,1,1,1,1,1,1,1,1,1,1,1,1,1,1,1,1,1,1,1,1,1,1,1,1,1,1,1,1,1
1,1,1,1,1,1,1,1,1,1,1,1,1,1,1,1,1,1,1,1,1,1,1,1,1,1,1,1,1,1,1,1,1,1,1,1,1,1,1,1,1,1,1
1,1,1,1,1,1,1,1,1,1,1,1,1,1,1,1,1,1,1,1,1,1,1,1,1,1,1,1,1,1,1,1,1,1,1,1,1,1,1,1,1,1,1
:endlayer
layer: 2
1,1,1,1,1,1,1,1,1,1,1,1,1,1,1,1,1,1,1,1,1,1,1,1,1,1,1,1,1,1,1,1,1,1,1,1,1,1,1,1,1,1,1
1,1,1,1,1,1,1,1,1,1,1,1,1,1,1,1,1,1,1,1,1,1,1,1,1,1,1,1,1,1,1,1,1,1,1,1,1,1,1,1,1,1,1
1,1,1,1,1,1,1,1,1,1,1,1,1,1,1,1,1,1,1,1,1,1,1,1,1,1,1,1,1,1,1,1,1,1,1,1,1,1,1,1,1,1,1
1,1,1,1,1,1,1,1,1,1,1,1,1,1,1,1,1,1,1,1,1,1,1,1,1,1,1,1,1,1,1,1,1,1,1,1,1,1,1,1,1,1,1
1,1,1,1,1,1,1,1,1,1,1,1,1,1,1,1,1,1,1,1,1,1,1,1,1,1,1,1,1,1,1,1,1,1,1,1,1,1,1,1,1,1,1
1,1,1,1,1,1,1,1,1,1,1,1,1,1,1,1,1,1,1,1,1,1,1,1,1,1,1,1,1,1,1,1,1,1,1,1,1,1,1,1,1,1,1
1,1,1,1,1,1,1,1,1,1,1,1,1,1,1,1,1,1,1,1,1,1,1,1,1,1,1,1,1,1,1,1,1,1,1,1,1,1,1,1,1,1,1
1,1,1,1,1,1,1,1,1,1,1,1,1,1,1,1,1,1,1,1,1,1,1,1,1,1,1,1,1,1,1,1,1,1,1,1,1,1,1,1,1,1,1
1,1,1,1,1,1,1,1,1,1,1,1,1,1,1,1,1,1,1,1,1,1,1,1,1,1,1,1,1,1,1,1,1,1,1,1,1,1,1,1,1,1,1
1,1,1,1,1,1,1,1,1,1,1,1,1,1,1,1,1,1,1,1,1,1,1,1,1,1,1,1,1,1,1,1,1,1,1,1,1,1,1,1,1,1,1
1,1,1,1,1,1,1,1,1,1,1,1,1,1,1,1,1,1,1,1,1,1,1,1,1,1,1,1,1,1,1,1,1,1,1,1,1,1,1,1,1,1,1
1,1,1,1,1,1,1,1,1,1,1,1,1,1,1,1,1,1,1,1,1,1,1,1,1,1,1,1,1,1,1,1,1,1,1,1,1,1,1,1,1,1,1
1,1,1,1,1,1,1,1,1,1,1,1,1,1,1,1,1,1,1,1,1,1,1,1,1,1,1,1,1,1,1,1,1,1,1,1,1,1,1,1,1,1,1
1,1,1,1,1,1,1,1,1,1,1,1,1,1,1,1,1,1,1,1,1,1,1,1,1,1,1,1,1,1,1,1,1,1,1,1,1,1,1,1,1,1,1
1,1,1,1,1,1,1,1,1,1,1,1,1,1,1,1,1,1,1,1,1,1,1,1,1,1,1,1,1,1,1,1,1,1,1,1,1,1,1,1,1,1,1
1,1,2,2,2,2,2,2,2,2,2,2,1,1,1,1,1,1,1,1,1,1,1,1,1,1,1,1,1,1,1,1,1,1,1,1,1,1,1,1,1,1,1
1,1,2,17,17,17,17,17,17,17,17,17,2,1,1,1,1,1,1,1,1,1,1,1,1,1,1,1,1,1,1,1,1,1,1,1,1,1,1,1,1,1,1
1,1,2,17,17,17,17,17,17,17,17,17,2,1,1,1,1,1,1,1,1,1,1,1,1,1,1,1,1,1,1,1,1,1,1,1,1,1,1,1,1,1,1
1,1,2,17,17,17,17,17,17,17,17,17,2,1,1,1,1,1,1,1,1,1,1,1,1,1,1,1,1,1,1,1,1,1,1,1,1,1,1,1,1,1,1
1,1,2,17,17,17,17,17,17,17,17,17,2,1,1,1,1,1,1,1,1,1,1,1,1,1,1,1,1,1,1,1,1,1,1,1,1,1,1,1,1,1,1
1,1,2,17,17,17,17,17,17,17,17,17,2,1,1,1,1,1,1,1,1,1,1,1,1,1,1,1,1,1,1,1,1,1,1,1,1,1,1,1,1,1,1
1,1,2,17,17,17,17,17,17,17,17,17,2,1,1,1,1,1,1,1,1,1,1,1,1,1,1,1,1,1,1,1,1,1,1,1,1,1,1,1,1,1,1
1,1,2,2,2,2,2,2,2,2,2,2,1,1,1,2,2,2,2,2,2,1,1,2,2,2,2,2,2,1,1,1,1,1,1,1,1,1,1,1,1,1,1
1,1,1,1,1,1,1,1,1,1,1,1,1,1,1,2,22,0,0,0,0,2,2,2,0,0,0,0,26,2,1,1,1,1,1,1,1,1,1,1,1,1,1
1,1,1,1,1,1,1,1,1,1,1,1,1,1,2,20,0,2,0,0,0,2,2,2,0,0,0,2,0,20,2,1,2,1,1,1,1,1,1,1,1,1,1
1,1,1,1,1,1,1,1,1,1,1,1,1,1,2,19,0,9,9,9,9,9,24,9,9,9,9,9,0,0,28,2,19,2,2,2,2,1,1,1,1,1,1
1,1,1,1,1,1,1,1,1,1,1,1,1,1,2,0,0,0,0,0,0,0,0,0,0,0,0,0,0,0,0,29,0,0,0,0,0,2,1,1,1,1,1
1,1,1,1,1,1,1,1,1,1,1,1,1,1,2,19,0,9,9,9,9,9,23,9,9,9,9,9,0,0,27,2,30,2,2,2,0,2,1,1,1,1,1
1,1,1,1,1,1,1,1,1,1,1,1,1,1,2,18,0,2,0,0,0,2,2,2,0,0,0,2,0,18,2,1,2,2,15,31,0,2,1,1,1,1,1
1,1,1,1,1,1,1,1,1,1,1,1,1,1,1,2,21,0,0,0,0,2,2,2,0,0,0,0,25,2,1,1,1,2,2,2,2,2,1,1,1,1,1
1,1,1,1,1,1,1,1,1,1,1,1,1,1,1,2,2,2,2,2,2,1,1,2,2,2,2,2,2,1,1,1,1,1,1,1,1,1,1,1,1,1,1
1,1,1,1,1,1,1,1,1,1,1,1,1,1,1,1,1,1,1,1,1,1,1,1,1,1,1,1,1,1,1,1,1,1,1,1,1,1,1,1,1,1,1
1,1,1,1,1,1,1,1,1,1,1,1,1,1,1,1,1,1,1,1,1,1,1,1,1,1,1,1,1,1,1,1,1,1,1,1,1,1,1,1,1,1,1
1,1,1,1,1,1,1,1,1,1,1,1,1,1,1,1,1,1,1,1,1,1,1,1,1,1,1,1,1,1,1,1,1,1,1,1,1,1,1,1,1,1,1
1,1,1,1,1,1,1,1,1,1,1,1,1,1,1,1,1,1,1,1,1,1,1,1,1,1,1,1,1,1,1,1,1,1,1,1,1,1,1,1,1,1,1
1,1,1,1,1,1,1,1,1,1,1,1,1,1,1,1,1,1,1,1,1,1,1,1,1,1,1,1,1,1,1,1,1,1,1,1,1,1,1,1,1,1,1
1,1,1,1,1,1,1,1,1,1,1,1,1,1,1,1,1,1,1,1,1,1,1,1,1,1,1,1,1,1,1,1,1,1,1,1,1,1,1,1,1,1,1
1,1,1,1,1,1,1,1,1,1,1,1,1,1,1,1,1,1,1,1,1,1,1,1,1,1,1,1,1,1,1,1,1,1,1,1,1,1,1,1,1,1,1
1,1,1,1,1,1,1,1,1,1,1,1,1,1,1,1,1,1,1,1,1,1,1,1,1,1,1,1,1,1,1,1,1,1,1,1,1,1,1,1,1,1,1
:endlayer
layer: 3
32,32,32,32,32,32,32,32,32,32,32,32,32,32,32,32,32,32,32,32,32,32,32,32,32,32,32,32,32,32,32,32,32,32,32,32,32,32,32,32,32,32,1
32,32,32,32,32,32,32,32,32,32,32,32,32,32,32,32,32,32,32,32,32,32,32,32,32,32,32,32,32,32,32,32,32,32,32,32,32,32,32,32,32,32,32
32,32,32,32,32,32,32,32,32,32,32,32,32,32,32,32,32,32,32,32,32,32,32,32,32,32,32,32,32,32,32,32,32,32,32,32,32,32,32,32,32,32,32
32,32,32,32,32,32,32,32,32,32,32,1,1,1,1,1,1,1,1,1,32,32,32,32,32,32,32,32,32,32,32,1,1,1,1,1,1,1,1,1,32,32,32
32,32,32,1,1,1,1,1,1,1,1,1,1,1,1,1,1,1,1,1,32,32,32,32,32,32,32,32,32,32,32,1,1,1,1,1,1,1,1,1,32,32,32
32,32,32,1,1,1,1,1,1,1,1,1,1,2,2,2,2,2,1,1,1,1,1,1,1,1,1,1,1,1,1,1,1,2,2,2,2,2,1,1,32,32,32
32,32,32,1,1,32,32,32,32,32,32,32,1,2,2,2,2,2,1,1,1,1,1,1,1,1,1,1,1,1,1,1,1,2,2,2,2,2,1,1,32,32,32
32,32,32,1,1,32,32,32,32,32,32,32,1,2,2,2,2,2,2,2,2,2,2,2,2,2,2,2,2,2,2,2,2,2,2,2,2,2,1,1,32,32,32
32,32,32,1,1,32,32,32,32,32,32,32,1,2,2,2,2,2,2,2,2,2,2,2,2,2,2,2,2,2,2,2,2,2,2,2,2,2,1,1,32,32,32
32,32,32,1,1,32,32,32,32,32,32,32,1,2,2,2,2,1,1,1,1,1,1,1,1,1,1,1,1,1,2,2,2,2,2,2,2,2,1,1,32,32,32
32,32,32,1,1,32,32,32,32,32,32,32,1,2,2,2,2,1,2,2,2,2,2,2,2,2,2,2,2,36,2,2,2,2,2,2,1,1,1,1,32,32,32
32,32,32,1,1,32,32,32,32,32,32,32,1,2,2,2,2,1,2,2,2,2,2,2,2,2,2,2,2,1,2,2,2,1,2,2,1,1,1,1,32,32,32
32,32,32,1,1,32,32,32,32,32,32,32,1,2,2,2,2,1,32,32,32,2,2,2,2,2,2,2,2,1,1,1,1,1,2,2,1,1,32,32,32,32,32
32,32,32,1,1,1,1,1,1,1,1,1,1,1,1,2,2,1,1,1,32,2,2,2,2,2,2,2,2,1,32,32,1,1,2,2,1,1,32,32,32,32,32
32,32,32,1,1,1,1,1,1,1,1,1,1,1,1,2,2,1,1,1,32,2,2,2,2,2,2,2,2,2,2,2,2,1,2,2,1,1,32,32,32,32,32
32,32,2,2,2,2,2,2,2,2,2,2,32,1,1,2,2,1,1,32,32,2,2,2,2,2,2,2,2,2,2,2,2,1,2,2,1,1,32,32,32,32,32
32,32,2,33,33,33,33,33,33,33,33,33,2,1,1,2,2,1,1,1,32,2,2,2,2,2,2,2,2,2,2,2,2,1,2,2,1,1,32,32,32,32,32
32,32,2,33,33,33,33,33,33,33,33,33,2,1,1,2,2,1,1,1,32,2,2,2,2,2,2,2,2,2,2,2,2,1,2,2,1,1,32,32,32,32,32
32,32,2,33,33,33,33,33,33,33,33,33,2,1,1,2,2,1,1,1,32,2,2,2,2,2,2,2,2,2,2,2,2,1,2,2,1,1,32,32,32,32,32
32,32,2,33,33,33,33,33,33,33,33,33,2,1,1,2,2,1,1,32,32,2,2,2,2,2,2,2,2,2,2,2,2,1,2,2,1,1,32,32,32,32,32
32,32,2,33,33,33,33,33,33,33,33,33,2,1,1,2,2,1,1,1,32,2,2,2,2,2,2,2,2,2,2,2,2,1,2,2,1,1,32,32,32,32,32
32,32,2,33,33,33,33,33,33,33,33,33,2,1,1,2,2,1,1,32,1,2,2,2,2,2,2,2,2,2,2,2,2,1,2,2,1,1,32,32,32,32,32
32,32,2,2,2,2,2,2,2,2,2,2,32,1,1,2,2,1,32,32,32,2,2,2,2,2,2,2,2,2,2,2,2,1,2,2,1,1,32,32,32,32,32
32,32,2,32,1,1,1,1,1,1,1,1,1,1,1,2,2,2,2,2,2,2,2,2,2,2,2,2,2,2,32,32,2,1,2,2,1,1,1,1,32,32,32
32,32,2,32,1,1,1,1,1,1,1,1,1,1,1,2,2,1,2,2,2,2,2,2,2,2,2,2,35,35,35,1,2,1,2,2,1,1,1,1,32,32,32
32,32,2,32,1,1,1,1,1,1,1,1,2,2,2,2,2,2,2,2,2,2,2,2,2,2,2,1,2,2,2,1,2,2,2,2,2,2,1,1,32,32,32
32,32,2,32,1,1,1,1,1,1,1,1,2,2,2,2,2,2,2,2,2,2,2,2,2,2,2,2,2,2,2,2,2,2,15,2,0,2,1,1,32,32,32
32,32,2,32,1,1,1,1,1,1,1,1,2,2,2,2,2,2,2,2,2,2,2,2,2,2,2,2,2,2,2,2,2,2,37,2,0,2,1,1,32,32,32
32,32,2,32,1,1,1,1,1,1,1,1,2,2,2,2,2,2,2,2,2,2,2,2,2,2,2,2,2,2,1,1,1,2,0,0,0,2,1,1,32,32,32
32,32,2,32,1,1,1,1,1,1,1,1,2,2,2,2,2,2,2,2,2,2,2,2,2,2,2,2,2,1,1,1,1,2,2,2,2,2,1,1,32,32,32
32,32,2,32,1,1,1,1,1,1,1,1,1,2,2,2,2,2,2,2,2,2,2,2,1,1,32,32,32,32,32,1,1,1,1,1,1,1,1,1,32,32,32
32,32,2,32,32,1,32,32,32,32,32,1,1,1,2,2,2,2,2,2,2,2,2,1,1,1,32,32,32,32,32,1,1,1,1,1,1,1,1,1,32,32,32
32,32,2,2,2,2,2,2,2,2,2,32,1,1,1,2,2,2,2,2,2,2,2,1,1,32,32,32,32,32,32,32,32,32,32,32,32,32,32,32,32,32,32
32,32,32,32,32,32,34,34,34,34,34,32,1,1,1,1,2,2,2,2,2,1,1,1,1,32,32,32,32,32,32,32,32,32,32,32,32,32,32,32,32,32,32
32,32,32,32,32,32,34,34,34,34,34,32,32,1,1,1,1,1,1,1,1,1,1,1,32,32,32,32,32,32,32,32,32,32,32,32,32,32,32,32,32,32,32
32,32,32,32,32,32,34,34,34,34,34,32,32,32,32,1,1,1,1,1,1,1,32,32,32,32,32,32,32,32,32,32,32,32,32,32,32,32,32,32,32,32,32
32,32,32,32,32,32,34,34,34,34,34,32,32,32,32,32,32,32,32,32,32,32,32,32,32,32,32,32,32,32,32,32,32,32,32,32,32,32,32,32,32,32,32
32,32,32,32,32,32,34,34,34,34,34,32,32,32,32,32,32,32,32,32,32,32,32,32,32,32,32,32,32,32,32,32,32,32,32,32,32,32,32,32,32,32,32
32,32,32,32,32,32,34,34,34,34,34,32,32,32,32,32,32,32,32,32,32,32,32,32,32,32,32,32,32,32,32,32,32,32,32,32,32,32,32,32,32,32,32
:endlayer
layer: 4
38,38,38,0,38,38,0,38,0,0,38,38,38,38,0,0,0,38,38,38,38,0,0,0,0,38,0,38,0,38,38,38,0,0,0,0,38,38,38,0,0,0,0
38,38,38,0,0,38,38,38,38,38,38,38,0,38,41,0,38,38,38,0,38,0,0,0,0,38,38,0,0,38,0,38,38,38,0,38,38,38,38,38,0,0,0
0,38,38,0,0,38,38,38,38,0,39,39,39,39,39,39,39,39,39,39,39,0,0,38,38,38,38,38,0,0,39,39,39,39,39,39,39,39,39,39,39,0,0
0,38,39,39,39,39,39,39,39,39,39,2,2,2,2,2,2,2,2,2,39,38,38,0,0,38,38,38,38,38,39,2,2,2,2,2,2,2,2,2,39,0,38
0,38,39,2,2,2,2,2,2,2,2,2,15,15,15,15,15,15,15,2,39,39,39,39,39,39,39,39,39,39,39,2,15,15,15,15,15,15,15,2,39,38,38
38,38,39,2,15,15,15,15,15,15,15,15,15,15,15,15,15,15,15,2,2,2,2,2,2,2,2,2,2,2,2,2,15,66,68,70,66,66,15,2,39,38,38
38,38,39,2,15,0,0,0,0,0,0,0,15,15,15,49,51,0,15,15,15,15,15,15,15,15,15,15,15,15,15,15,15,0,0,0,0,75,15,2,39,0,0
38,38,39,2,15,0,0,0,0,0,0,0,15,15,45,0,0,0,53,0,0,0,0,0,0,0,0,0,0,65,0,0,0,0,61,61,0,74,15,2,39,0,38
38,38,39,2,15,0,0,0,0,0,0,0,15,15,44,0,0,0,15,0,0,0,0,0,0,0,0,0,0,15,0,0,0,0,61,61,0,73,15,2,39,0,38
0,0,39,2,15,0,0,0,0,0,0,0,15,15,0,0,0,15,15,15,15,15,15,15,15,15,15,15,15,15,0,0,0,0,0,0,0,66,15,2,39,0,38
0,0,39,2,15,0,0,0,0,0,0,0,15,15,0,0,0,15,0,0,0,0,0,0,0,0,0,0,0,64,0,0,0,0,0,0,0,15,15,2,39,38,38
0,38,39,2,15,0,0,0,0,0,0,0,15,15,43,0,0,15,0,0,0,0,0,0,0,0,0,0,0,15,61,61,61,15,67,15,15,2,2,2,39,38,38
0,0,39,2,15,0,0,0,0,0,0,0,15,15,42,0,0,15,40,40,40,0,61,61,0,0,0,0,0,15,15,15,15,15,0,0,15,2,39,39,39,38,38
0,38,39,2,15,15,15,15,15,15,15,15,15,15,15,48,15,15,15,16,40,0,61,61,0,62,0,0,0,15,37,37,15,15,0,0,15,2,39,0,0,38,0
0,0,39,2,2,2,2,2,2,2,2,2,2,2,15,0,0,15,15,55,40,0,61,61,0,0,0,0,0,0,0,0,0,15,0,0,15,2,39,0,0,0,0
38,0,39,39,39,39,39,39,39,39,39,39,39,2,15,0,0,15,15,37,40,0,61,61,0,62,0,0,0,0,0,0,0,15,0,0,15,2,39,0,0,0,0
0,0,0,0,0,0,0,0,0,0,0,0,39,2,15,0,0,15,15,15,40,0,61,61,0,0,0,0,0,0,0,0,0,15,0,0,15,2,39,0,38,38,0
0,0,0,0,0,0,0,0,0,0,0,0,39,2,15,0,0,15,15,56,40,0,61,61,0,62,0,0,0,0,0,0,0,15,0,0,15,2,39,38,0,38,0
38,38,0,0,0,0,0,0,0,0,0,0,39,2,15,0,0,15,15,15,40,0,61,61,0,0,0,0,0,0,0,0,0,15,0,0,15,2,39,38,38,38,38
38,38,0,0,0,0,0,0,0,0,0,0,39,2,15,0,0,15,15,16,40,0,61,61,0,62,0,0,0,0,0,0,0,15,0,0,15,2,39,38,38,38,0
38,38,0,0,0,0,0,0,0,0,0,0,39,2,15,0,0,15,15,55,40,0,61,61,0,0,0,0,0,0,0,0,0,15,0,0,15,2,39,0,38,0,0
0,0,0,0,0,0,0,0,0,0,0,0,39,2,15,0,0,15,15,37,40,0,61,61,0,62,0,0,0,0,0,0,0,15,0,0,15,2,39,0,0,0,0
0,0,0,39,39,39,39,39,39,39,39,39,39,2,15,0,0,15,40,40,40,0,61,61,0,0,0,0,0,0,0,0,0,15,0,0,15,2,39,39,39,0,0
0,0,0,39,2,2,2,2,2,2,2,2,2,2,15,0,0,15,0,0,0,0,0,0,0,0,0,16,40,40,40,16,0,15,0,0,15,2,2,2,39,0,0
0,0,0,39,2,15,15,15,15,15,15,15,15,15,15,47,15,15,0,0,0,0,0,0,0,0,0,15,63,63,63,15,0,15,47,15,15,15,15,2,39,38,0
0,0,0,39,2,15,15,15,15,15,15,15,0,0,0,0,0,15,15,15,15,15,15,15,15,15,15,15,15,15,15,15,15,0,0,0,0,0,15,2,39,0,0
38,38,0,39,2,15,15,15,15,15,15,15,0,0,0,0,0,0,0,0,0,0,0,0,53,0,0,0,0,0,0,0,65,0,0,69,72,0,15,2,39,38,38
38,38,0,39,2,15,15,15,15,15,15,15,0,0,0,0,0,0,0,0,0,0,0,0,15,0,0,0,0,0,0,0,15,0,0,15,71,0,15,2,39,38,0
38,38,0,39,2,15,15,15,15,15,15,15,15,11,15,15,15,15,15,15,15,15,15,15,15,15,15,15,15,15,15,15,15,0,0,0,0,0,15,2,39,38,38
38,0,0,39,2,15,15,15,15,15,15,15,0,0,0,0,0,0,0,0,0,0,60,15,15,2,2,2,2,2,2,2,15,0,0,0,0,0,15,2,39,38,0
0,0,0,39,2,15,15,15,15,15,15,15,15,0,0,0,0,0,0,0,0,0,59,15,15,2,39,39,39,39,39,2,15,15,15,15,15,15,15,2,39,0,0
0,0,0,39,6,15,40,40,40,40,40,15,2,15,0,0,0,0,0,0,0,58,15,15,2,2,39,38,38,38,39,2,2,2,2,2,2,2,2,2,39,0,0
0,0,0,0,0,0,0,0,0,0,0,39,2,15,15,46,50,0,52,54,0,57,15,15,2,39,39,38,38,38,39,39,39,39,39,39,39,39,39,39,39,0,0
0,38,0,0,0,0,0,0,0,0,0,39,2,2,15,15,15,15,15,15,15,15,15,2,2,39,0,38,38,38,38,0,0,0,0,0,0,0,0,0,0,0,0
38,38,38,0,38,0,0,0,0,0,0,39,39,2,2,2,15,15,15,15,15,2,2,2,39,39,0,0,38,0,0,0,0,0,0,0,0,0,0,38,38,0,0
0,38,38,0,38,0,0,0,0,0,0,0,39,39,39,2,2,2,2,2,2,2,39,39,39,0,0,0,0,0,38,0,0,0,0,0,0,0,0,0,0,38,0
0,38,38,38,38,0,0,0,0,0,0,0,38,38,39,39,39,39,39,39,39,39,39,38,0,0,0,0,0,0,0,0,0,0,0,0,0,0,0,38,0,38,38
0,0,38,38,0,0,0,0,0,0,0,38,38,38,0,0,38,38,38,38,0,38,0,0,0,0,38,0,0,0,38,0,0,0,0,0,0,0,0,0,0,0,0
0,0,0,38,38,38,0,0,0,0,0,41,38,38,0,38,38,38,38,38,38,0,0,0,0,0,0,38,38,0,38,0,0,0,0,0,0,0,0,38,38,0,38
:endlayer
layer: 5
0,0,0,0,0,0,0,0,0,0,0,0,0,0,0,0,0,0,0,0,0,0,0,0,0,0,0,0,0,0,0,0,0,0,0,0,0,0,0,0,0,0,0
0,0,0,0,0,0,0,0,0,0,0,0,0,0,0,0,0,0,0,0,0,0,0,0,0,0,0,0,0,0,0,0,0,0,0,0,0,0,0,0,0,0,0
0,0,0,0,0,0,0,0,0,0,0,0,0,0,0,0,0,0,0,0,0,0,0,0,0,0,0,0,0,0,0,0,0,0,0,0,0,0,0,0,0,0,0
0,0,0,0,0,0,0,0,0,0,0,13,4,4,4,4,4,4,4,3,0,0,0,0,0,0,0,0,0,0,0,4,4,4,4,4,4,4,4,4,0,0,0
0,0,0,4,4,4,4,4,4,4,4,13,15,15,15,15,15,15,15,3,0,0,0,0,0,0,0,0,0,0,0,13,15,15,15,15,15,15,15,3,0,0,0
0,0,0,13,15,15,15,15,15,15,15,15,15,15,31,84,86,0,15,3,4,4,4,4,4,4,4,4,4,4,4,4,15,61,0,24,0,61,15,3,0,0,0
0,0,0,13,15,0,0,0,0,0,0,0,15,37,31,0,0,0,15,15,15,15,15,15,15,15,15,15,15,15,15,15,15,0,0,0,0,0,15,3,0,0,0
0,0,0,13,15,0,0,0,0,0,0,0,15,81,0,0,0,0,88,0,0,0,0,0,0,0,0,0,0,98,0,0,0,0,93,93,0,27,15,3,0,0,0
0,0,0,13,15,0,0,0,0,0,0,0,15,80,0,0,0,27,15,19,0,0,0,0,0,0,0,0,27,15,0,0,0,0,93,93,0,0,15,3,0,0,0
0,0,0,13,15,0,0,0,0,0,0,0,15,0,0,0,0,15,15,15,15,15,15,15,15,15,15,15,15,15,19,0,0,0,0,0,0,61,15,3,0,0,0
0,0,0,13,15,0,0,0,0,0,0,0,15,0,0,0,0,15,0,0,0,0,0,0,0,0,0,0,0,97,0,0,0,0,0,23,0,15,15,3,0,0,0
0,0,0,13,15,0,0,0,0,0,0,0,15,79,0,0,0,15,19,0,0,0,0,0,0,0,0,0,27,15,93,93,93,15,101,15,15,6,6,6,0,0,0
0,0,0,13,15,0,0,0,0,0,0,0,15,78,0,0,23,15,0,0,0,0,93,93,0,0,0,0,0,15,37,37,15,15,0,24,15,3,0,0,0,0,0
0,0,0,13,15,15,15,15,15,15,15,15,15,15,15,83,15,15,16,0,0,0,93,93,0,0,0,0,0,0,0,0,0,15,0,0,15,3,0,0,0,0,0
0,0,0,13,6,6,6,6,6,6,6,6,6,13,15,0,24,15,55,0,0,0,93,93,0,0,0,0,0,0,0,0,0,15,0,0,15,3,0,0,0,0,0
0,0,0,0,0,0,0,0,0,0,0,0,0,13,15,0,0,15,37,0,0,0,93,93,0,0,0,0,0,0,0,0,27,15,0,0,15,3,0,0,0,0,0
0,0,0,0,0,0,0,0,0,0,0,0,0,13,15,0,0,15,15,37,0,0,93,93,0,0,0,0,0,0,0,0,0,15,0,0,15,3,0,0,0,0,0
0,0,0,0,0,0,0,0,0,0,0,0,0,13,15,0,0,15,56,0,0,0,93,93,0,0,0,0,0,0,0,0,0,15,0,0,15,3,0,0,0,0,0
0,0,0,0,0,0,0,0,0,0,0,0,0,13,15,0,0,15,15,16,0,0,93,93,0,0,0,0,0,0,0,0,0,15,0,0,15,3,0,0,0,0,0
0,0,0,0,0,0,0,0,0,0,0,0,0,13,15,0,0,15,16,0,0,0,93,93,0,0,0,0,0,0,0,0,0,15,0,0,15,3,0,0,0,0,0
0,0,0,0,0,0,0,0,0,0,0,0,0,13,15,0,0,15,55,0,0,0,93,93,0,0,0,0,0,0,0,0,27,15,0,0,15,3,0,0,0,0,0
0,0,0,0,0,0,0,0,0,0,0,0,0,13,15,0,0,15,37,0,0,0,93,93,0,0,0,0,0,0,0,0,0,15,0,0,15,3,0,0,0,0,0
0,0,0,0,0,0,0,0,0,0,0,0,0,13,15,0,0,15,0,0,0,0,93,93,0,0,0,0,0,0,0,0,0,15,0,0,15,3,0,0,0,0,0
0,0,0,0,13,4,4,4,4,4,4,4,4,13,15,0,23,15,19,0,0,0,0,0,0,0,0,0,0,0,0,0,0,15,0,23,15,3,4,3,0,0,0
0,0,0,0,13,15,15,15,15,15,15,15,15,15,15,82,15,15,0,0,0,0,0,0,0,0,0,15,9,9,9,15,0,15,100,15,15,15,15,3,0,0,0
0,0,0,0,13,15,15,15,15,15,15,15,0,0,0,0,0,15,15,15,15,15,15,15,15,15,15,15,15,15,15,15,15,0,0,0,0,0,15,3,0,0,0
0,0,0,0,13,15,15,15,15,15,15,15,19,0,0,0,0,0,0,0,0,0,0,0,96,0,0,0,0,0,0,0,99,0,0,0,0,0,15,3,0,0,0
0,0,0,0,13,15,15,15,15,15,15,15,18,0,0,0,0,0,0,0,0,0,0,27,15,19,0,0,0,0,0,27,15,0,27,15,16,0,15,3,0,0,0
0,0,0,0,13,15,15,15,15,15,15,15,15,77,15,9,9,15,9,9,15,9,9,15,15,15,15,15,15,15,15,15,15,0,0,102,71,0,15,3,0,0,0
0,0,0,0,13,15,40,40,40,40,40,15,0,0,24,0,0,24,0,0,24,0,0,95,15,6,6,6,6,6,6,13,15,0,0,0,0,0,15,3,0,0,0
0,0,0,0,6,15,0,0,0,0,0,15,15,0,0,0,0,0,0,0,0,0,0,94,15,3,0,0,0,0,0,13,15,15,15,15,15,15,15,3,0,0,0
0,0,0,0,0,76,0,0,0,0,0,76,13,15,0,0,0,0,0,0,0,0,92,15,3,6,0,0,0,0,0,13,6,6,6,6,6,6,6,3,0,0,0
0,0,0,0,0,0,0,0,0,0,0,0,13,15,15,0,0,0,0,0,0,0,91,15,3,0,0,0,0,0,0,0,0,0,0,0,0,0,0,0,0,0,0
0,0,0,0,0,0,0,0,0,0,0,0,13,6,15,15,85,87,0,89,90,15,15,3,6,0,0,0,0,0,0,0,0,0,0,0,0,0,0,0,0,0,0
0,0,0,0,0,0,0,0,0,0,0,0,0,13,6,6,15,15,15,15,15,3,6,6,0,0,0,0,0,0,0,0,0,0,0,0,0,0,0,0,0,0,0
0,0,0,0,0,0,0,0,0,0,0,0,0,0,0,13,6,6,6,6,6,6,0,0,0,0,0,0,0,0,0,0,0,0,0,0,0,0,0,0,0,0,0
0,0,0,0,0,0,0,0,0,0,0,0,0,0,0,0,0,0,0,0,0,0,0,0,0,0,0,0,0,0,0,0,0,0,0,0,0,0,0,0,0,0,0
0,0,0,0,0,0,0,0,0,0,0,0,0,0,0,0,0,0,0,0,0,0,0,0,0,0,0,0,0,0,0,0,0,0,0,0,0,0,0,0,0,0,0
0,0,0,0,0,0,0,0,0,0,0,0,0,0,0,0,0,0,0,0,0,0,0,0,0,0,0,0,0,0,0,0,0,0,0,0,0,0,0,0,0,0,0
:endlayer
layer: 6
0,0,0,0,0,0,0,0,0,0,0,0,0,0,0,0,0,0,0,0,0,0,0,0,0,0,0,0,0,0,0,0,0,0,0,0,0,0,0,0,0,0,0
0,0,0,0,0,0,0,0,0,0,0,0,0,0,0,0,0,0,0,0,0,0,0,0,0,0,0,0,0,0,0,0,0,0,0,0,0,0,0,0,0,0,0
0,0,0,0,0,0,0,0,0,0,0,0,0,0,0,0,0,0,0,0,0,0,0,0,0,0,0,0,0,0,0,0,0,0,0,0,0,0,0,0,0,0,0
0,0,0,0,0,0,0,0,0,0,0,0,0,0,0,0,0,0,0,0,0,0,0,0,0,0,0,0,0,0,0,0,0,0,0,0,0,0,0,0,0,0,0
0,0,0,0,0,0,0,0,0,0,0,0,15,15,15,15,15,15,15,0,0,0,0,0,0,0,0,0,0,0,0,0,15,15,15,15,15,15,15,0,0,0,0
0,0,0,0,15,15,15,15,15,15,15,15,15,15,19,0,0,0,15,0,0,0,0,0,0,0,0,0,0,0,0,0,15,110,113,113,113,110,15,0,0,0,0
0,0,0,0,15,0,0,0,0,0,0,0,15,24,0,0,0,0,15,15,15,15,15,15,15,15,15,15,15,15,15,15,15,0,0,0,0,113,15,0,0,0,0
0,0,0,0,15,0,0,0,0,0,0,0,15,0,0,0,0,0,15,106,0,0,0,0,0,0,0,0,108,15,0,0,0,0,0,0,0,113,15,0,0,0,0
0,0,0,0,15,0,0,0,0,0,0,0,15,0,0,0,0,0,15,0,0,0,0,0,0,0,0,0,0,15,0,0,0,0,0,0,0,113,15,0,0,0,0
0,0,0,0,15,0,0,0,0,0,0,0,15,0,0,0,0,15,15,15,15,15,15,15,15,15,15,15,15,15,0,0,0,0,0,0,0,110,15,0,0,0,0
0,0,0,0,15,0,0,0,0,0,0,0,15,0,0,0,0,15,0,0,0,0,0,0,0,0,0,0,0,15,0,0,0,0,0,0,0,15,15,0,0,0,0
0,0,0,0,15,0,0,0,0,0,0,0,15,0,0,0,0,15,0,0,0,0,0,0,0,0,0,0,0,15,37,37,15,15,15,15,15,0,0,0,0,0,0
0,0,0,0,15,0,0,0,0,0,0,0,15,0,0,0,0,15,0,0,0,0,0,0,0,0,0,0,0,0,0,0,0,15,112,0,15,0,0,0,0,0,0
0,0,0,0,15,15,15,15,15,15,15,15,15,15,15,15,15,15,0,0,0,0,0,0,0,0,0,0,0,0,0,0,0,15,0,0,15,0,0,0,0,0,0
0,0,0,0,0,71,0,0,0,0,0,71,0,0,15,105,0,15,40,0,0,0,0,0,0,0,0,0,0,0,0,0,0,15,0,0,15,0,0,0,0,0,0
0,0,0,0,0,0,0,0,0,0,0,0,0,0,15,0,0,15,0,0,0,0,0,0,0,0,0,0,0,0,0,0,0,15,0,0,15,0,0,0,0,0,0
0,0,0,0,0,0,0,0,0,0,0,0,0,0,15,0,0,15,16,0,0,0,0,0,0,0,0,0,0,0,0,0,0,15,0,0,15,0,0,0,0,0,0
0,0,0,0,0,0,0,0,0,0,0,0,0,0,15,0,0,15,56,0,0,0,0,0,0,0,0,0,0,0,0,0,0,15,0,0,15,0,0,0,0,0,0
0,0,0,0,0,0,0,0,0,0,0,0,0,0,15,0,0,15,37,0,0,0,0,0,0,0,0,0,0,0,0,0,0,15,0,0,15,0,0,0,0,0,0
0,0,0,0,0,0,0,0,0,0,0,0,0,0,15,0,0,15,0,0,0,0,0,0,0,0,0,0,0,0,0,0,0,15,0,0,15,0,0,0,0,0,0
0,0,0,0,0,0,0,0,0,0,0,0,0,0,15,0,0,15,40,0,0,0,0,0,0,0,0,0,0,0,0,0,0,15,0,0,15,0,0,0,0,0,0
0,0,0,0,0,0,0,0,0,0,0,0,0,0,15,0,0,15,0,0,0,0,0,0,0,0,0,0,0,0,0,0,0,15,0,0,15,0,0,0,0,0,0
0,0,0,0,0,0,0,0,0,0,0,0,0,0,15,0,0,15,0,0,0,0,0,0,0,0,0,0,0,0,0,0,0,15,0,0,15,0,0,0,0,0,0
0,0,0,0,0,103,103,103,103,103,103,103,0,0,15,104,0,15,0,0,0,0,0,0,0,0,0,69,16,16,16,31,0,15,111,0,15,0,0,0,0,0,0
0,0,0,0,0,15,15,15,15,15,15,15,15,15,15,15,15,15,0,0,0,0,0,0,0,0,0,69,15,15,15,31,0,15,15,15,15,15,15,0,0,0,0
0,0,0,0,0,15,15,15,15,15,15,15,0,0,0,0,0,15,15,15,15,15,15,15,15,15,15,15,15,15,15,15,15,0,0,0,0,0,15,0,0,0,0
0,0,0,0,0,15,15,15,15,15,15,15,0,0,0,0,0,0,0,0,0,0,0,0,15,107,0,0,0,0,0,109,15,0,0,0,0,0,15,0,0,0,0
0,0,0,0,0,15,15,40,40,40,15,15,0,0,0,0,0,0,0,0,0,0,0,0,15,0,0,0,0,0,0,0,15,0,103,15,0,0,15,0,0,0,0
0,0,0,0,0,15,0,0,0,0,0,15,15,15,15,15,15,15,15,15,15,15,15,15,15,15,15,15,15,15,15,15,15,0,102,31,0,0,15,0,0,0,0
0,0,0,0,0,15,0,0,0,0,0,15,0,0,0,0,0,0,0,0,0,0,0,27,15,0,0,0,0,0,0,0,15,0,0,0,0,0,15,0,0,0,0
0,0,0,0,0,15,19,0,0,0,27,15,15,0,0,0,0,0,0,0,0,0,0,0,15,0,0,0,0,0,0,0,15,15,15,15,15,15,15,0,0,0,0
0,0,0,0,0,76,0,0,0,0,0,76,0,15,0,0,0,0,0,0,0,0,0,15,0,0,0,0,0,0,0,0,0,0,0,0,0,0,0,0,0,0,0
0,0,0,0,0,0,0,0,0,0,0,0,0,15,15,0,0,0,0,0,0,0,27,15,0,0,0,0,0,0,0,0,0,0,0,0,0,0,0,0,0,0,0
0,0,0,0,0,0,0,0,0,0,0,0,0,0,15,15,23,0,0,0,23,15,15,0,0,0,0,0,0,0,0,0,0,0,0,0,0,0,0,0,0,0,0
0,0,0,0,0,0,0,0,0,0,0,0,0,0,0,0,15,15,15,15,15,0,0,0,0,0,0,0,0,0,0,0,0,0,0,0,0,0,0,0,0,0,0
0,0,0,0,0,0,0,0,0,0,0,0,0,0,0,0,0,0,0,0,0,0,0,0,0,0,0,0,0,0,0,0,0,0,0,0,0,0,0,0,0,0,0
0,0,0,0,0,0,0,0,0,0,0,0,0,0,0,0,0,0,0,0,0,0,0,0,0,0,0,0,0,0,0,0,0,0,0,0,0,0,0,0,0,0,0
0,0,0,0,0,0,0,0,0,0,0,0,0,0,0,0,0,0,0,0,0,0,0,0,0,0,0,0,0,0,0,0,0,0,0,0,0,0,0,0,0,0,0
0,0,0,0,0,0,0,0,0,0,0,0,0,0,0,0,0,0,0,0,0,0,0,0,0,0,0,0,0,0,0,0,0,0,0,0,0,0,0,0,0,0,0
:endlayer
layer: 7
0,0,0,0,0,0,0,0,0,0,0,0,0,0,0,0,0,0,0,0,0,0,0,0,0,0,0,0,0,0,0,0,0,0,0,0,0,0,0,0,0,0,0
0,0,0,0,0,0,0,0,0,0,0,0,0,0,0,0,0,0,0,0,0,0,0,0,0,0,0,0,0,0,0,0,0,0,0,0,0,0,0,0,0,0,0
0,0,0,0,0,0,0,0,0,0,0,0,0,0,0,0,0,0,0,0,0,0,0,0,0,0,0,0,0,0,0,0,0,0,0,0,0,0,0,0,0,0,0
0,0,0,0,0,0,0,0,0,0,0,0,0,0,0,0,0,0,0,0,0,0,0,0,0,0,0,0,0,0,0,0,0,0,0,0,0,0,0,0,0,0,0
0,0,0,0,0,0,0,0,0,0,0,0,15,15,15,15,15,15,15,0,0,0,0,0,0,0,0,0,0,0,0,0,15,15,15,15,15,15,15,0,0,0,0
0,0,0,0,15,15,15,15,15,15,15,15,15,15,15,15,15,15,15,0,0,0,0,0,0,0,0,0,0,0,0,0,15,15,15,15,15,15,15,0,0,0,0
0,0,0,0,15,110,110,110,110,110,110,110,15,15,15,15,15,15,15,15,15,15,15,15,15,15,15,15,15,15,15,15,15,15,15,15,15,15,15,0,0,0,0
0,0,0,0,15,110,110,110,110,110,110,110,15,15,15,15,15,15,15,15,15,15,15,15,15,15,15,15,15,15,15,15,15,15,15,15,15,15,15,0,0,0,0
0,0,0,0,15,110,110,110,110,110,110,110,15,15,15,15,15,15,15,15,15,15,15,15,15,15,15,15,15,15,15,15,15,15,15,15,15,15,15,0,0,0,0
0,0,0,0,15,110,110,110,110,110,110,110,15,15,15,15,15,15,15,15,15,15,15,15,15,15,15,15,15,15,15,15,15,15,15,15,15,15,15,0,0,0,0
0,0,0,0,15,110,110,110,110,110,110,110,15,15,15,15,15,15,0,0,0,0,0,0,0,0,0,0,0,15,37,37,15,15,15,15,15,15,15,0,0,0,0
0,0,0,0,15,110,110,110,110,110,110,110,15,15,15,15,15,15,0,0,0,0,0,0,0,0,0,0,0,0,0,0,0,15,15,15,15,0,0,0,0,0,0
0,0,0,0,15,15,15,15,15,15,15,15,15,15,15,15,15,15,0,0,0,0,0,0,0,0,0,0,0,0,0,0,0,15,15,15,15,0,0,0,0,0,0
0,0,0,0,15,15,15,15,15,15,15,15,15,15,15,15,15,15,0,0,0,113,0,0,0,0,0,0,0,0,0,0,0,15,15,15,15,0,0,0,0,0,0
0,0,0,0,0,76,110,110,110,110,110,76,0,0,15,15,15,15,55,0,0,0,0,0,0,0,0,0,0,0,0,0,0,15,15,15,15,0,0,0,0,0,0
0,0,0,0,0,0,110,110,110,110,110,0,0,0,15,15,15,15,0,0,0,0,0,0,0,0,0,0,0,0,0,0,0,15,15,15,15,0,0,0,0,0,0
0,0,0,0,0,0,110,110,110,110,110,0,0,0,15,15,15,15,0,0,0,0,0,0,0,0,0,0,0,0,0,0,0,15,15,15,15,0,0,0,0,0,0
0,0,0,0,0,0,110,110,110,110,110,0,0,0,15,15,15,15,40,0,0,0,0,0,0,0,0,0,0,0,0,0,0,15,15,15,15,0,0,0,0,0,0
0,0,0,0,0,0,110,110,110,110,110,0,0,0,15,15,15,15,0,0,0,0,0,0,0,0,0,0,0,0,0,0,0,15,15,15,15,0,0,0,0,0,0
0,0,0,0,0,0,110,110,110,110,110,0,0,0,15,15,15,15,0,0,0,0,0,0,0,0,0,0,0,0,0,0,0,15,15,15,15,0,0,0,0,0,0
0,0,0,0,0,0,110,110,110,110,110,0,0,0,15,15,15,15,55,0,0,0,0,0,0,0,0,0,0,0,0,0,0,15,15,15,15,0,0,0,0,0,0
0,0,0,0,0,0,110,110,110,110,110,0,0,0,15,15,15,15,0,0,0,113,0,0,0,0,0,0,0,113,0,0,0,15,15,15,15,0,0,0,0,0,0
0,0,0,0,0,0,110,110,110,110,110,0,0,0,15,15,15,15,0,0,0,0,0,0,0,0,0,0,0,0,0,0,0,15,15,15,15,0,0,0,0,0,0
0,0,0,0,0,76,110,110,110,110,110,76,0,0,15,15,15,15,0,0,0,0,0,0,0,0,0,0,0,0,0,0,0,15,15,15,15,0,0,0,0,0,0
0,0,0,0,0,15,15,15,15,15,15,15,15,15,15,15,15,15,0,0,0,0,0,0,0,0,0,0,69,16,31,0,0,15,15,15,15,15,15,0,0,0,0
0,0,0,0,0,15,40,40,40,40,40,15,15,15,15,15,15,15,15,15,15,15,15,15,15,15,15,15,15,15,15,15,15,15,15,15,15,15,15,0,0,0,0
0,0,0,0,0,15,0,0,0,0,0,15,15,15,15,15,15,15,15,15,15,15,15,15,15,15,15,15,15,15,15,15,15,15,103,72,0,15,15,0,0,0,0
0,0,0,0,0,15,0,0,0,0,0,15,15,15,15,15,15,15,15,15,15,15,15,15,15,15,15,15,15,15,15,15,15,15,37,15,19,15,15,0,0,0,0
0,0,0,0,0,69,0,0,0,0,0,15,15,15,15,15,15,15,15,15,15,15,15,15,15,15,15,15,15,15,15,15,15,15,0,0,0,15,15,0,0,0,0
0,0,0,0,0,15,0,0,0,0,0,15,15,15,15,15,15,15,15,15,15,15,15,15,15,0,0,0,0,0,0,0,15,15,15,15,15,15,15,0,0,0,0
0,0,0,0,0,15,0,0,0,0,0,15,15,15,15,15,15,15,15,15,15,15,15,15,15,0,0,0,0,0,0,0,15,15,15,15,15,15,15,0,0,0,0
0,0,0,0,0,76,0,0,0,0,0,76,0,15,15,15,15,15,15,15,15,15,15,15,0,0,0,0,0,0,0,0,0,0,0,0,0,0,0,0,0,0,0
0,0,0,0,0,0,0,0,0,0,0,0,0,15,15,15,15,15,15,15,15,15,15,15,0,0,0,0,0,0,0,0,0,0,0,0,0,0,0,0,0,0,0
0,0,0,0,0,0,0,0,0,0,0,0,0,0,15,15,15,15,15,15,15,15,15,0,0,0,0,0,0,0,0,0,0,0,0,0,0,0,0,0,0,0,0
0,0,0,0,0,0,0,0,0,0,0,0,0,0,0,0,15,15,15,15,15,0,0,0,0,0,0,0,0,0,0,0,0,0,0,0,0,0,0,0,0,0,0
0,0,0,0,0,0,0,0,0,0,0,0,0,0,0,0,0,0,0,0,0,0,0,0,0,0,0,0,0,0,0,0,0,0,0,0,0,0,0,0,0,0,0
0,0,0,0,0,0,0,0,0,0,0,0,0,0,0,0,0,0,0,0,0,0,0,0,0,0,0,0,0,0,0,0,0,0,0,0,0,0,0,0,0,0,0
0,0,0,0,0,0,0,0,0,0,0,0,0,0,0,0,0,0,0,0,0,0,0,0,0,0,0,0,0,0,0,0,0,0,0,0,0,0,0,0,0,0,0
0,0,0,0,0,0,0,0,0,0,0,0,0,0,0,0,0,0,0,0,0,0,0,0,0,0,0,0,0,0,0,0,0,0,0,0,0,0,0,0,0,0,0
:endlayer
layer: 8
0,0,0,0,0,0,0,0,0,0,0,0,0,0,0,0,0,0,0,0,0,0,0,0,0,0,0,0,0,0,0,0,0,0,0,0,0,0,0,0,0,0,0
0,0,0,0,0,0,0,0,0,0,0,0,0,0,0,0,0,0,0,0,0,0,0,0,0,0,0,0,0,0,0,0,0,0,0,0,0,0,0,0,0,0,0
0,0,0,0,0,0,0,0,0,0,0,0,0,0,0,0,0,0,0,0,0,0,0,0,0,0,0,0,0,0,0,0,0,0,0,0,0,0,0,0,0,0,0
0,0,0,0,0,0,0,0,0,0,0,0,0,0,0,0,0,0,0,0,0,0,0,0,0,0,0,0,0,0,0,0,0,0,0,0,0,0,0,0,0,0,0
0,0,0,0,0,0,0,0,0,0,0,0,15,15,15,15,15,15,15,0,0,0,0,0,0,0,0,0,0,0,0,0,15,15,15,15,15,15,15,0,0,0,0
0,0,0,0,15,15,16,15,15,16,15,15,15,0,0,0,0,0,15,0,0,0,0,0,0,0,0,0,0,0,0,0,15,0,0,0,0,0,15,0,0,0,0
0,0,0,0,15,0,0,0,0,0,0,0,15,15,15,15,15,15,15,15,15,15,15,15,15,15,15,15,15,15,15,15,15,0,0,69,72,0,15,0,0,0,0
0,0,0,0,69,0,0,0,0,0,0,0,0,0,0,0,0,0,0,0,0,0,0,0,0,0,0,0,0,0,0,0,53,0,0,15,71,0,15,0,0,0,0
0,0,0,0,15,0,0,0,0,0,0,0,0,0,0,0,0,0,0,0,0,0,0,0,0,0,0,0,0,0,0,0,15,0,0,0,0,0,15,0,0,0,0
0,0,0,0,15,0,0,0,0,0,0,0,15,0,15,0,0,15,15,15,15,15,15,15,15,15,15,15,15,15,0,0,15,0,0,0,0,0,15,0,0,0,0
0,0,0,0,15,0,0,0,0,0,0,0,15,0,15,48,15,15,0,0,0,0,0,0,0,0,0,0,0,15,0,0,15,15,48,15,15,15,15,0,0,0,0
0,0,0,0,69,0,0,0,0,0,0,0,15,0,15,0,0,15,0,0,0,0,0,0,0,0,0,0,0,0,0,0,0,15,0,0,15,0,0,0,0,0,0
0,0,0,0,15,0,0,0,0,0,0,0,15,15,15,0,0,15,0,0,0,125,0,0,0,0,0,0,0,0,0,0,0,15,0,0,15,0,0,0,0,0,0
0,0,0,0,15,15,0,0,0,0,0,15,15,15,15,0,0,15,55,0,125,126,125,0,0,0,0,0,0,0,0,0,0,15,0,0,15,0,0,0,0,0,0
0,0,0,0,0,76,0,0,0,0,0,76,0,0,15,0,0,15,56,0,0,125,0,0,0,0,0,0,0,0,0,0,0,15,0,0,15,0,0,0,0,0,0
0,0,0,0,0,0,0,0,0,0,0,0,0,0,15,0,0,15,55,0,0,0,0,0,0,0,0,0,0,0,0,0,0,15,0,0,15,0,0,0,0,0,0
0,0,0,0,0,0,0,0,0,0,0,0,0,0,15,0,0,15,0,0,0,0,0,0,0,0,0,0,0,0,0,0,0,15,0,0,15,0,0,0,0,0,0
0,0,0,0,0,0,0,0,0,0,0,0,0,0,15,0,0,15,19,0,0,0,0,0,0,0,0,0,0,0,0,0,0,15,0,0,15,0,0,0,0,0,0
0,0,0,0,0,0,0,0,0,0,0,0,0,0,15,0,0,15,0,0,0,0,0,0,0,0,0,0,0,0,0,0,0,15,0,0,15,0,0,0,0,0,0
0,0,0,0,0,0,0,0,0,0,0,0,0,0,15,0,0,15,55,0,0,0,0,0,0,0,0,0,0,0,0,0,0,15,0,0,15,0,0,0,0,0,0
0,0,0,0,0,0,9,0,0,0,9,0,0,0,15,0,0,15,56,0,0,125,0,0,0,0,0,0,0,125,0,0,0,15,0,0,15,0,0,0,0,0,0
0,0,0,0,0,0,0,0,0,0,0,0,0,0,15,0,0,15,55,0,125,126,125,0,0,0,0,0,125,126,125,0,0,15,0,0,15,0,0,0,0,0,0
0,0,0,0,0,0,0,0,0,0,0,0,0,0,15,0,0,15,0,0,0,125,0,0,0,0,0,0,0,125,0,0,0,15,0,0,15,0,0,0,0,0,0
0,0,0,0,0,76,0,0,0,0,0,76,0,0,15,0,0,15,0,0,0,0,0,0,0,0,0,0,0,0,0,0,0,15,0,0,15,0,0,0,0,0,0
0,0,0,0,0,15,0,0,0,0,0,15,15,15,15,47,15,15,0,0,0,0,0,0,0,0,0,0,0,0,0,0,0,15,47,15,15,15,15,0,0,0,0
0,0,0,0,0,15,0,0,0,0,0,15,110,118,0,0,0,15,15,15,15,15,15,15,15,15,15,15,15,15,15,15,15,0,0,0,0,0,15,0,0,0,0
0,0,0,0,0,69,0,0,0,0,0,15,114,116,0,0,0,0,0,0,0,0,0,0,53,0,0,0,0,0,0,0,65,0,0,69,72,0,15,0,0,0,0
0,0,0,0,0,15,0,0,0,0,0,15,110,117,0,0,0,0,0,0,0,0,0,0,15,0,0,0,0,0,0,0,15,0,0,15,71,0,15,0,0,0,0
0,0,0,0,0,9,0,0,0,0,0,15,114,116,0,0,0,0,15,0,0,0,129,110,15,15,15,15,15,15,15,15,15,0,0,0,0,0,15,0,0,0,0
0,0,0,0,0,15,0,0,0,0,0,15,110,115,0,0,0,0,0,0,0,0,128,130,15,0,0,0,0,0,0,0,15,0,0,0,0,0,15,0,0,0,0
0,0,0,0,0,15,72,0,0,0,102,15,15,0,0,0,0,0,0,0,0,0,127,110,15,0,0,0,0,0,0,0,15,15,15,15,15,15,15,0,0,0,0
0,0,0,0,0,76,76,0,0,0,76,76,0,15,119,121,122,0,0,0,124,121,110,15,0,0,0,0,0,0,0,0,0,0,0,0,0,0,0,0,0,0,0
0,0,0,0,0,0,0,0,0,0,0,0,0,15,110,120,110,121,123,121,110,120,110,15,0,0,0,0,0,0,0,0,0,0,0,0,0,0,0,0,0,0,0
0,0,0,0,0,0,0,0,0,0,0,0,0,0,15,15,110,120,110,120,110,15,15,0,0,0,0,0,0,0,0,0,0,0,0,0,0,0,0,0,0,0,0
0,0,0,0,0,0,0,0,0,0,0,0,0,0,0,0,15,15,15,15,15,0,0,0,0,0,0,0,0,0,0,0,0,0,0,0,0,0,0,0,0,0,0
0,0,0,0,0,0,0,0,0,0,0,0,0,0,0,0,0,0,0,0,0,0,0,0,0,0,0,0,0,0,0,0,0,0,0,0,0,0,0,0,0,0,0
0,0,0,0,0,0,0,0,0,0,0,0,0,0,0,0,0,0,0,0,0,0,0,0,0,0,0,0,0,0,0,0,0,0,0,0,0,0,0,0,0,0,0
0,0,0,0,0,0,0,0,0,0,0,0,0,0,0,0,0,0,0,0,0,0,0,0,0,0,0,0,0,0,0,0,0,0,0,0,0,0,0,0,0,0,0
0,0,0,0,0,0,0,0,0,0,0,0,0,0,0,0,0,0,0,0,0,0,0,0,0,0,0,0,0,0,0,0,0,0,0,0,0,0,0,0,0,0,0
:endlayer
layer: 9
0,0,0,0,0,0,0,0,0,0,0,0,0,0,0,0,0,0,0,0,0,0,0,0,0,0,0,0,0,0,0,0,0,0,0,0,0,0,0,0,0,0,0
0,0,0,0,0,0,0,0,0,0,0,0,0,0,0,0,0,0,0,0,0,0,0,0,0,0,0,0,0,0,0,0,0,0,0,0,0,0,0,0,0,0,0
0,0,0,0,0,0,0,0,0,0,0,0,0,0,0,0,0,0,0,0,0,0,0,0,0,0,0,0,0,0,0,0,0,0,0,0,0,0,0,0,0,0,0
0,0,0,0,0,0,0,0,0,0,0,0,0,0,0,0,0,0,0,0,0,0,0,0,0,0,0,0,0,0,0,0,0,0,0,0,0,0,0,0,0,0,0
0,0,0,0,0,0,0,0,0,0,0,0,15,15,15,15,15,15,15,0,0,0,0,0,0,0,0,0,0,0,0,0,15,15,15,15,15,15,15,0,0,0,0
0,0,0,0,15,15,9,15,15,9,15,15,15,0,0,0,0,0,15,0,0,0,0,0,0,0,0,0,0,0,0,0,15,0,0,0,0,0,15,0,0,0,0
0,0,0,0,15,0,0,0,0,0,0,27,15,15,15,15,15,15,15,15,15,15,15,15,15,15,15,15,15,15,15,15,15,0,0,0,0,0,15,0,0,0,0
0,0,0,0,9,0,0,0,0,0,0,0,0,0,24,0,0,0,0,0,24,0,0,0,0,0,24,0,0,0,0,0,136,0,27,15,16,0,15,0,0,0,0
0,0,0,0,15,0,0,0,0,0,0,0,0,0,0,0,0,0,0,0,23,0,0,0,0,0,23,0,0,0,0,27,15,0,0,102,71,0,15,0,0,0,0
0,0,0,0,15,0,0,0,0,0,0,27,15,0,15,0,133,15,15,9,15,9,15,9,15,9,15,9,15,15,0,0,15,0,0,0,0,0,15,0,0,0,0
0,0,0,0,15,0,0,0,0,0,0,0,0,0,15,132,15,15,0,0,0,0,0,0,0,0,0,0,0,15,0,0,15,15,138,15,15,15,15,0,0,0,0
0,0,0,0,9,0,0,0,0,0,0,0,18,0,15,0,24,15,0,0,0,0,0,0,0,0,0,0,0,0,0,0,0,15,0,24,15,0,0,0,0,0,0
0,0,0,0,15,0,0,0,0,0,0,0,15,15,15,0,0,15,0,0,0,61,0,0,0,0,0,0,0,0,0,0,0,15,0,0,15,0,0,0,0,0,0
0,0,0,0,15,15,19,0,0,0,27,15,15,15,15,0,0,15,55,0,61,61,61,0,0,0,0,0,0,0,0,0,0,15,0,0,15,0,0,0,0,0,0
0,0,0,0,0,76,0,0,0,0,0,76,0,0,15,0,0,15,56,0,0,61,0,0,0,0,0,0,0,0,0,0,0,15,0,0,15,0,0,0,0,0,0
0,0,0,0,0,0,0,0,0,0,0,0,0,0,15,0,0,15,55,0,0,0,0,0,0,0,0,0,0,0,0,0,0,15,0,0,15,0,0,0,0,0,0
0,0,0,0,0,0,0,0,0,0,0,0,0,0,15,0,0,15,0,0,0,0,0,0,0,0,0,0,0,0,0,0,0,15,0,0,15,0,0,0,0,0,0
0,0,0,0,0,0,0,0,0,0,0,0,0,0,15,0,0,15,0,0,0,0,0,0,0,0,0,0,0,0,0,0,0,15,0,0,15,0,0,0,0,0,0
0,0,0,0,0,0,0,0,0,0,0,0,0,0,15,0,0,15,0,0,0,0,0,0,0,0,0,0,0,0,0,0,0,15,0,0,15,0,0,0,0,0,0
0,0,0,0,0,0,0,0,0,0,0,0,0,0,15,0,0,15,55,0,0,0,0,0,0,0,0,0,0,0,0,0,0,15,0,0,15,0,0,0,0,0,0
0,0,0,0,0,0,9,0,0,0,9,0,0,0,15,0,0,15,56,0,0,61,0,0,0,0,0,0,0,61,0,0,0,15,0,0,15,0,0,0,0,0,0
0,0,0,0,0,0,0,0,0,0,0,0,0,0,15,0,0,15,55,0,61,61,61,0,0,0,0,0,61,61,61,0,0,15,0,0,15,0,0,0,0,0,0
0,0,0,0,0,0,0,0,0,0,0,0,0,0,15,0,0,15,0,0,0,61,0,0,0,0,0,0,0,61,0,0,0,15,0,0,15,0,0,0,0,0,0
0,0,0,0,0,76,0,0,0,0,0,76,0,0,15,0,23,15,0,0,0,0,0,0,0,0,0,0,0,0,0,0,0,15,0,23,15,0,0,0,0,0,0
0,0,0,0,0,15,19,0,0,0,27,15,15,15,15,131,15,15,0,0,0,0,0,0,0,0,0,0,0,0,0,0,0,15,137,15,15,15,15,0,0,0,0
0,0,0,0,0,15,0,0,0,0,0,15,110,19,0,0,24,15,15,15,15,15,15,15,15,15,15,15,15,15,15,15,15,0,0,24,0,0,15,0,0,0,0
0,0,0,0,0,9,0,0,0,0,0,15,0,0,0,0,0,0,0,0,0,0,0,0,134,0,0,0,0,0,0,0,135,0,0,0,0,0,15,0,0,0,0
0,0,0,0,0,15,0,0,0,0,0,15,110,19,0,0,0,0,0,0,0,0,0,27,15,19,0,0,0,0,0,0,15,19,27,15,16,0,15,0,0,0,0
0,0,0,0,0,9,0,0,0,0,0,15,0,0,0,0,0,0,15,0,0,0,27,110,15,15,15,15,15,15,15,15,15,0,0,102,71,0,15,0,0,0,0
0,0,0,0,0,15,0,0,0,0,0,15,110,19,0,0,0,0,0,0,0,0,0,0,15,0,0,0,0,0,0,0,15,0,0,0,0,0,15,0,0,0,0
0,0,0,0,0,15,15,15,15,15,15,15,15,0,0,0,0,0,0,0,0,0,27,110,15,0,0,0,0,0,0,0,15,15,15,15,15,15,15,0,0,0,0
0,0,0,0,0,0,76,76,76,76,76,0,0,15,23,0,23,0,0,0,23,0,110,15,0,0,0,0,0,0,0,0,0,0,0,0,0,0,0,0,0,0,0
0,0,0,0,0,0,0,0,0,0,0,0,0,15,110,0,110,0,23,0,110,0,110,15,0,0,0,0,0,0,0,0,0,0,0,0,0,0,0,0,0,0,0
0,0,0,0,0,0,0,0,0,0,0,0,0,0,15,15,110,0,110,0,110,15,15,0,0,0,0,0,0,0,0,0,0,0,0,0,0,0,0,0,0,0,0
0,0,0,0,0,0,0,0,0,0,0,0,0,0,0,0,15,15,15,15,15,0,0,0,0,0,0,0,0,0,0,0,0,0,0,0,0,0,0,0,0,0,0
0,0,0,0,0,0,0,0,0,0,0,0,0,0,0,0,0,0,0,0,0,0,0,0,0,0,0,0,0,0,0,0,0,0,0,0,0,0,0,0,0,0,0
0,0,0,0,0,0,0,0,0,0,0,0,0,0,0,0,0,0,0,0,0,0,0,0,0,0,0,0,0,0,0,0,0,0,0,0,0,0,0,0,0,0,0
0,0,0,0,0,0,0,0,0,0,0,0,0,0,0,0,0,0,0,0,0,0,0,0,0,0,0,0,0,0,0,0,0,0,0,0,0,0,0,0,0,0,0
0,0,0,0,0,0,0,0,0,0,0,0,0,0,0,0,0,0,0,0,0,0,0,0,0,0,0,0,0,0,0,0,0,0,0,0,0,0,0,0,0,0,0
:endlayer
layer: 10
0,0,0,0,0,0,0,0,0,0,0,0,0,0,0,0,0,0,0,0,0,0,0,0,0,0,0,0,0,0,0,0,0,0,0,0,0,0,0,0,0,0,0
0,0,0,0,0,0,0,0,0,0,0,0,0,0,0,0,0,0,0,0,0,0,0,0,0,0,0,0,0,0,0,0,0,0,0,0,0,0,0,0,0,0,0
0,0,0,0,0,0,0,0,0,0,0,0,0,0,0,0,0,0,0,0,0,0,0,0,0,0,0,0,0,0,0,0,0,0,0,0,0,0,0,0,0,0,0
0,0,0,0,0,0,0,0,0,0,0,0,0,0,0,0,0,0,0,0,0,0,0,0,0,0,0,0,0,0,0,0,0,0,0,0,0,0,0,0,0,0,0
0,0,0,0,0,0,0,0,0,0,0,0,15,15,15,15,15,15,15,0,0,0,0,0,0,0,0,0,0,0,0,0,15,15,15,15,15,15,15,0,0,0,0
0,0,0,0,15,15,9,15,15,9,15,15,15,0,0,0,0,0,15,0,0,0,0,0,0,0,0,0,0,0,0,0,15,0,0,0,0,0,15,0,0,0,0
0,0,0,0,15,0,0,0,0,0,0,0,15,15,15,15,15,15,15,15,15,15,15,15,15,15,15,15,15,15,15,15,15,0,0,0,0,0,15,0,0,0,0
0,0,0,0,9,0,0,0,0,0,0,0,0,0,0,0,0,0,0,0,0,0,0,0,0,0,0,0,0,0,0,0,15,0,103,15,0,0,15,0,0,0,0
0,0,0,0,15,0,0,0,0,0,0,0,0,0,0,0,0,0,0,0,0,0,0,0,0,0,0,0,0,0,0,0,15,0,102,31,0,0,15,0,0,0,0
0,0,0,0,15,0,0,0,0,0,0,0,15,15,15,0,0,15,15,15,15,15,15,15,15,15,15,15,15,15,0,0,15,0,0,0,0,0,15,0,0,0,0
0,0,0,0,15,0,0,0,0,0,0,0,15,0,15,15,15,15,0,0,0,0,0,0,0,143,0,0,0,15,0,0,15,15,15,15,15,15,15,0,0,0,0
0,0,0,0,9,0,0,0,0,0,0,0,15,0,15,142,0,15,0,0,0,0,0,0,0,143,0,0,0,0,0,0,0,15,148,0,15,0,0,0,0,0,0
0,0,0,0,15,0,0,0,0,0,0,0,15,15,15,0,0,15,0,0,0,0,0,0,0,143,0,0,0,0,0,0,0,15,0,0,15,0,0,0,0,0,0
0,0,0,0,15,15,61,61,61,61,61,15,15,15,15,0,0,15,55,0,0,61,0,0,0,143,0,0,0,0,0,0,0,15,0,0,15,0,0,0,0,0,0
0,0,0,0,0,76,0,0,0,0,0,76,0,0,15,0,0,15,56,0,0,0,0,0,0,143,0,0,0,0,0,0,0,15,0,0,15,0,0,0,0,0,0
0,0,0,0,0,0,0,0,0,0,0,0,0,0,15,0,0,15,55,0,0,0,0,0,0,143,0,0,0,0,0,0,0,15,0,0,15,0,0,0,0,0,0
0,0,0,0,0,0,0,0,0,0,0,0,0,0,15,0,0,15,0,0,0,0,0,0,0,143,0,0,0,0,0,0,0,15,0,0,15,0,0,0,0,0,0
0,0,0,0,0,0,0,0,0,0,0,0,0,0,15,0,0,15,143,143,143,143,143,143,143,143,143,143,143,143,143,143,143,15,0,0,15,0,0,0,0,0,0
0,0,0,0,0,0,0,0,0,0,0,0,0,0,15,0,0,15,0,0,0,0,0,0,0,143,0,0,0,0,0,0,0,15,0,0,15,0,0,0,0,0,0
0,0,0,0,0,0,0,0,0,0,0,0,0,0,15,0,0,15,55,0,0,0,0,0,0,143,0,0,0,0,0,0,0,15,0,0,15,0,0,0,0,0,0
0,0,0,0,0,0,9,0,0,0,9,0,0,0,15,0,0,15,56,0,0,0,0,0,0,143,0,0,0,0,0,0,0,15,0,0,15,0,0,0,0,0,0
0,0,0,0,0,0,0,0,0,0,0,0,0,0,15,0,0,15,55,0,0,61,0,0,0,143,0,0,0,61,0,0,0,15,0,0,15,0,0,0,0,0,0
0,0,0,0,0,0,0,0,0,0,0,0,0,0,15,0,0,15,0,0,0,0,0,0,0,143,0,0,0,0,0,0,0,15,0,0,15,0,0,0,0,0,0
0,0,0,0,0,76,0,0,0,0,0,76,0,0,15,141,0,15,0,0,0,0,0,0,0,143,0,0,0,0,0,0,0,15,147,0,15,0,0,0,0,0,0
0,0,0,0,0,15,61,61,61,61,61,15,15,15,15,15,15,15,0,0,0,0,0,0,0,143,0,0,0,0,0,0,0,15,15,15,15,15,15,0,0,0,0
0,0,0,0,0,15,0,0,0,0,0,15,110,0,0,0,0,15,15,15,15,15,15,15,15,15,15,15,15,15,15,15,15,0,0,0,0,0,15,0,0,0,0
0,0,0,0,0,9,0,0,0,0,0,15,139,0,0,0,0,0,0,0,0,0,0,0,15,145,0,0,0,0,0,146,15,0,0,0,0,0,15,0,0,0,0
0,0,0,0,0,15,0,0,0,0,0,15,110,0,0,0,0,0,0,0,0,0,0,0,15,0,0,0,0,0,0,0,15,0,103,15,0,0,15,0,0,0,0
0,0,0,0,0,15,15,15,15,15,15,15,139,0,0,0,0,0,15,0,0,0,0,110,15,15,15,15,15,15,15,15,15,0,102,31,0,0,15,0,0,0,0
0,0,0,0,0,15,15,15,15,15,15,15,110,0,0,0,0,0,0,0,0,0,0,144,15,0,0,0,0,0,0,0,15,0,0,0,0,0,15,0,0,0,0
0,0,0,0,0,15,15,15,15,15,15,15,15,0,0,0,0,0,0,0,0,0,0,110,15,0,0,0,0,0,0,0,15,15,15,15,15,15,15,0,0,0,0
0,0,0,0,0,0,0,0,0,0,0,0,0,15,0,0,0,0,0,0,0,0,110,15,0,0,0,0,0,0,0,0,0,0,0,0,0,0,0,0,0,0,0
0,0,0,0,0,0,0,0,0,0,0,0,0,15,110,140,110,0,0,0,110,140,110,15,0,0,0,0,0,0,0,0,0,0,0,0,0,0,0,0,0,0,0
0,0,0,0,0,0,0,0,0,0,0,0,0,0,15,15,110,140,110,140,110,15,15,0,0,0,0,0,0,0,0,0,0,0,0,0,0,0,0,0,0,0,0
0,0,0,0,0,0,0,0,0,0,0,0,0,0,0,0,15,15,15,15,15,0,0,0,0,0,0,0,0,0,0,0,0,0,0,0,0,0,0,0,0,0,0
0,0,0,0,0,0,0,0,0,0,0,0,0,0,0,0,0,0,0,0,0,0,0,0,0,0,0,0,0,0,0,0,0,0,0,0,0,0,0,0,0,0,0
0,0,0,0,0,0,0,0,0,0,0,0,0,0,0,0,0,0,0,0,0,0,0,0,0,0,0,0,0,0,0,0,0,0,0,0,0,0,0,0,0,0,0
0,0,0,0,0,0,0,0,0,0,0,0,0,0,0,0,0,0,0,0,0,0,0,0,0,0,0,0,0,0,0,0,0,0,0,0,0,0,0,0,0,0,0
0,0,0,0,0,0,0,0,0,0,0,0,0,0,0,0,0,0,0,0,0,0,0,0,0,0,0,0,0,0,0,0,0,0,0,0,0,0,0,0,0,0,0
:endlayer
layer: 11
0,0,0,0,0,0,0,0,0,0,0,0,0,0,0,0,0,0,0,0,0,0,0,0,0,0,0,0,0,0,0,0,0,0,0,0,0,0,0,0,0,0,0
0,0,0,0,0,0,0,0,0,0,0,0,0,0,0,0,0,0,0,0,0,0,0,0,0,0,0,0,0,0,0,0,0,0,0,0,0,0,0,0,0,0,0
0,0,0,0,0,0,0,0,0,0,0,0,0,0,0,0,0,0,0,0,0,0,0,0,0,0,0,0,0,0,0,0,0,0,0,0,0,0,0,0,0,0,0
0,0,0,0,0,0,0,0,0,0,0,0,0,0,0,0,0,0,0,0,0,0,0,0,0,0,0,0,0,0,0,0,0,0,0,0,0,0,0,0,0,0,0
0,0,0,0,0,0,0,0,0,0,0,0,15,15,15,15,15,15,15,0,0,0,0,0,0,0,0,0,0,0,0,0,15,15,15,15,15,15,15,0,0,0,0
0,0,0,0,15,15,15,15,15,15,15,15,15,15,15,15,15,15,15,0,0,0,0,0,0,0,0,0,0,0,0,0,15,15,15,15,15,15,15,0,0,0,0
0,0,0,0,15,0,0,0,0,0,0,0,15,15,15,15,15,15,15,15,15,15,15,15,15,15,15,15,15,15,15,15,15,15,103,72,0,15,15,0,0,0,0
0,0,0,0,15,0,0,0,0,0,0,0,71,71,71,71,71,71,71,71,71,71,71,71,71,71,71,71,71,71,71,102,15,15,37,15,19,15,15,0,0,0,0
0,0,0,0,15,0,0,0,0,0,0,0,103,103,103,72,102,103,103,103,103,103,103,103,103,103,103,103,103,103,72,102,15,15,0,0,0,15,15,0,0,0,0
0,0,0,0,15,0,0,0,0,0,0,0,15,15,15,103,102,15,15,15,15,15,15,15,15,15,15,15,15,15,72,102,15,15,15,15,15,15,15,0,0,0,0
0,0,0,0,15,0,0,0,0,0,0,0,15,15,15,15,15,15,15,71,71,71,71,71,71,15,72,71,71,15,72,102,15,15,15,15,15,15,15,0,0,0,0
0,0,0,0,15,0,0,0,0,0,0,0,15,15,15,15,15,15,15,143,143,143,143,143,102,15,72,143,102,71,71,71,71,15,15,15,15,0,0,0,0,0,0
0,0,0,0,15,0,0,0,0,0,0,0,15,15,15,15,15,15,15,143,143,143,143,143,102,15,72,143,143,143,143,143,102,15,15,15,15,0,0,0,0,0,0
0,0,0,0,15,15,72,61,61,61,102,15,15,15,15,15,15,15,15,143,143,15,143,143,102,15,72,143,143,143,143,143,102,15,15,15,15,0,0,0,0,0,0
0,0,0,0,0,76,76,0,0,0,76,76,0,0,15,15,15,15,15,143,143,143,143,143,102,15,72,143,143,143,143,143,102,15,15,15,15,0,0,0,0,0,0
0,0,0,0,0,0,0,0,0,0,0,0,0,0,15,15,15,15,15,143,143,143,143,143,102,15,72,143,143,143,143,143,102,15,15,15,15,0,0,0,0,0,0
0,0,0,0,0,0,0,0,0,0,0,0,0,0,15,15,15,15,15,103,103,103,103,103,103,15,72,103,103,103,103,103,102,15,15,15,15,0,0,0,0,0,0
0,0,0,0,0,0,0,0,0,0,0,0,0,0,15,15,15,15,15,15,15,15,15,15,15,15,15,15,15,15,15,15,15,15,15,15,15,0,0,0,0,0,0
0,0,0,0,0,0,0,0,0,0,0,0,0,0,15,15,15,15,15,71,71,71,71,71,71,15,72,71,71,71,71,71,102,15,15,15,15,0,0,0,0,0,0
0,0,0,0,0,0,0,0,0,0,0,0,0,0,15,15,15,15,15,143,143,143,143,143,102,15,72,143,143,143,143,143,102,15,15,15,15,0,0,0,0,0,0
0,0,0,0,0,0,9,0,0,0,9,0,0,0,15,15,15,15,15,143,143,143,143,143,102,15,72,143,143,143,143,143,102,15,15,15,15,0,0,0,0,0,0
0,0,0,0,0,0,0,0,0,0,0,0,0,0,15,15,15,15,15,143,143,15,143,143,102,15,72,143,143,15,143,143,102,15,15,15,15,0,0,0,0,0,0
0,0,0,0,0,0,0,0,0,0,0,0,0,0,15,15,15,15,15,143,143,143,143,143,102,15,72,143,143,143,143,143,102,15,15,15,15,0,0,0,0,0,0
0,0,0,0,0,76,76,0,0,0,76,76,0,0,15,15,15,15,15,143,143,143,143,143,102,15,72,143,143,143,143,143,102,15,15,15,15,0,0,0,0,0,0
0,0,0,0,0,15,72,61,61,61,102,15,15,15,15,15,15,15,15,103,103,103,103,103,102,15,103,103,103,103,103,103,102,15,15,15,15,15,15,0,0,0,0
0,0,0,0,0,15,0,0,0,0,0,15,15,15,15,15,15,15,15,15,15,15,15,15,15,15,15,15,15,15,15,15,15,15,15,15,15,15,15,0,0,0,0
0,0,0,0,0,15,0,0,0,0,0,15,15,15,15,15,15,15,15,15,15,15,15,15,15,15,15,15,15,15,15,15,15,15,103,72,0,15,15,0,0,0,0
0,0,0,0,0,15,15,15,15,15,15,15,15,15,15,15,15,15,15,15,15,15,15,15,15,15,15,15,15,15,15,15,15,15,37,15,19,15,15,0,0,0,0
0,0,0,0,0,15,0,0,0,0,0,69,15,15,15,15,15,15,15,15,15,15,15,15,15,15,15,15,15,15,15,15,15,15,0,0,0,15,15,0,0,0,0
0,0,0,0,0,15,0,0,0,0,0,15,15,15,15,15,15,15,15,15,15,15,15,15,15,0,0,0,0,0,0,0,15,15,15,15,15,15,15,0,0,0,0
0,0,0,0,0,15,15,15,15,15,15,15,15,15,15,15,15,15,15,15,15,15,15,15,15,0,0,0,0,0,0,0,15,15,15,15,15,15,15,0,0,0,0
0,0,0,0,0,0,0,0,0,0,0,0,0,15,15,15,15,15,15,15,15,15,15,15,0,0,0,0,0,0,0,0,0,0,0,0,0,0,0,0,0,0,0
0,0,0,0,0,0,0,0,0,0,0,0,0,15,15,15,15,15,15,15,15,15,15,15,0,0,0,0,0,0,0,0,0,0,0,0,0,0,0,0,0,0,0
0,0,0,0,0,0,0,0,0,0,0,0,0,0,15,15,15,15,15,15,15,15,15,0,0,0,0,0,0,0,0,0,0,0,0,0,0,0,0,0,0,0,0
0,0,0,0,0,0,0,0,0,0,0,0,0,0,0,0,15,15,15,15,15,0,0,0,0,0,0,0,0,0,0,0,0,0,0,0,0,0,0,0,0,0,0
0,0,0,0,0,0,0,0,0,0,0,0,0,0,0,0,0,0,0,0,0,0,0,0,0,0,0,0,0,0,0,0,0,0,0,0,0,0,0,0,0,0,0
0,0,0,0,0,0,0,0,0,0,0,0,0,0,0,0,0,0,0,0,0,0,0,0,0,0,0,0,0,0,0,0,0,0,0,0,0,0,0,0,0,0,0
0,0,0,0,0,0,0,0,0,0,0,0,0,0,0,0,0,0,0,0,0,0,0,0,0,0,0,0,0,0,0,0,0,0,0,0,0,0,0,0,0,0,0
0,0,0,0,0,0,0,0,0,0,0,0,0,0,0,0,0,0,0,0,0,0,0,0,0,0,0,0,0,0,0,0,0,0,0,0,0,0,0,0,0,0,0
:endlayer
layer: 12
0,0,0,0,0,0,0,0,0,0,0,0,0,0,0,0,0,0,0,0,0,0,0,0,0,0,0,0,0,0,0,0,0,0,0,0,0,0,0,0,0,0,0
0,0,0,0,0,0,0,0,0,0,0,0,0,0,0,0,0,0,0,0,0,0,0,0,0,0,0,0,0,0,0,0,0,0,0,0,0,0,0,0,0,0,0
0,0,0,0,0,0,0,0,0,0,0,0,0,0,0,0,0,0,0,0,0,0,0,0,0,0,0,0,0,0,0,0,0,0,0,0,0,0,0,0,0,0,0
0,0,0,0,0,0,0,0,0,0,0,0,0,0,0,0,0,0,0,0,0,0,0,0,0,0,0,0,0,0,0,0,0,0,0,0,0,0,0,0,0,0,0
0,0,0,0,0,0,0,0,0,0,0,0,15,15,15,16,15,15,15,0,0,0,0,0,0,0,0,0,0,0,0,0,15,15,15,16,15,15,15,0,0,0,0
0,0,0,0,15,15,15,15,15,15,15,15,15,0,0,0,0,0,15,0,0,0,0,0,0,0,0,0,0,0,0,0,15,0,0,0,0,0,15,0,0,0,0
0,0,0,0,15,0,0,0,0,0,0,0,15,0,0,0,0,0,15,15,15,16,15,15,15,16,15,15,15,16,15,15,15,0,0,0,0,0,15,0,0,0,0
0,0,0,0,15,0,0,0,0,0,0,0,15,0,103,15,0,0,53,0,0,0,0,0,0,0,0,0,0,0,0,0,65,0,0,15,0,0,31,0,0,0,0
0,0,0,0,15,0,0,0,0,0,0,0,15,0,102,31,0,0,15,0,0,0,0,0,0,0,0,0,0,0,0,0,15,0,0,0,0,0,15,0,0,0,0
0,0,0,0,15,0,0,0,0,0,0,0,15,0,0,0,0,0,15,15,15,15,15,15,15,47,15,15,15,15,15,15,15,0,0,0,0,0,15,0,0,0,0
0,0,0,0,15,0,0,0,0,0,0,0,15,15,15,15,15,15,15,0,0,0,0,0,0,0,0,0,0,0,0,0,15,15,15,15,15,15,15,0,0,0,0
0,0,0,0,15,0,0,0,0,0,0,0,15,0,0,0,0,0,0,0,0,0,0,0,0,0,0,0,0,0,0,0,0,0,0,0,15,0,0,0,0,0,0
0,0,0,0,15,0,0,0,0,0,0,0,15,0,0,0,0,0,0,0,0,0,0,0,0,0,0,0,0,0,0,0,0,0,0,0,15,0,0,0,0,0,0
0,0,0,0,15,15,15,15,15,15,15,15,15,15,15,0,0,0,0,0,0,0,0,0,0,0,0,0,0,0,0,0,0,0,0,0,31,0,0,0,0,0,0
0,0,0,0,0,76,76,76,76,76,76,76,0,0,15,0,0,0,0,0,0,0,0,0,0,0,0,0,0,0,0,0,0,0,0,0,15,0,0,0,0,0,0
0,0,0,0,0,0,0,0,0,0,0,0,0,0,15,0,0,0,0,0,0,0,0,0,0,0,0,0,0,0,0,0,0,0,0,0,15,0,0,0,0,0,0
0,0,0,0,0,0,0,0,0,0,0,0,0,0,15,0,0,0,0,0,0,0,0,0,0,0,0,0,0,0,0,0,0,0,0,0,15,0,0,0,0,0,0
0,0,0,0,0,0,0,0,0,0,0,0,0,0,69,0,0,0,0,0,0,0,0,0,0,0,0,0,0,0,0,0,0,0,0,0,31,0,0,0,0,0,0
0,0,0,0,0,0,0,0,0,0,0,0,0,0,15,0,0,0,0,0,0,0,0,0,0,0,0,0,0,0,0,0,0,0,0,0,15,0,0,0,0,0,0
0,0,0,0,0,0,0,0,0,0,0,0,0,0,15,0,0,0,0,0,0,0,0,0,0,0,0,0,0,0,0,0,0,0,0,0,15,0,0,0,0,0,0
0,0,0,0,0,0,9,0,0,0,9,0,0,0,69,0,0,0,0,0,0,0,0,0,0,0,0,0,0,0,0,0,0,0,0,0,15,0,0,0,0,0,0
0,0,0,0,0,0,0,0,0,0,0,0,0,0,15,0,0,0,0,0,0,0,0,0,0,0,0,0,0,0,0,0,0,0,0,0,31,0,0,0,0,0,0
0,0,0,0,0,0,0,0,0,0,0,0,0,0,15,0,15,15,67,15,15,0,0,0,0,0,0,0,0,0,0,0,0,0,0,0,15,0,0,0,0,0,0
0,0,0,0,0,0,76,76,76,76,76,0,0,0,15,15,0,0,0,0,0,15,15,0,0,0,0,0,0,0,0,0,0,0,0,0,15,0,0,0,0,0,0
0,0,0,0,0,15,15,15,15,15,15,15,15,15,0,0,0,0,0,0,0,0,0,15,0,0,0,0,0,0,0,0,15,15,15,15,15,15,15,0,0,0,0
0,0,0,0,0,15,0,0,0,0,0,15,15,15,0,0,0,0,0,0,0,0,0,15,0,0,0,0,0,0,0,0,15,0,0,0,0,0,15,0,0,0,0
0,0,0,0,0,15,0,0,0,0,0,15,15,0,0,0,0,0,0,0,0,0,0,0,15,0,0,0,0,0,0,0,15,0,0,69,72,0,15,0,0,0,0
0,0,0,0,0,15,0,0,0,0,0,15,15,0,0,0,0,0,0,0,0,0,0,0,15,0,0,0,0,0,0,0,65,0,0,15,71,0,31,0,0,0,0
0,0,0,0,0,15,0,0,0,0,0,0,149,0,0,0,0,0,0,0,0,0,0,0,15,15,37,15,15,15,37,15,15,0,0,0,0,0,15,0,0,0,0
0,0,0,0,0,15,0,0,0,0,0,15,15,0,0,0,0,0,0,0,0,0,0,0,15,0,0,0,0,0,0,0,15,0,0,0,0,0,15,0,0,0,0
0,0,0,0,0,15,15,15,15,15,15,15,15,0,0,0,0,0,0,0,0,0,0,0,15,0,0,0,0,0,0,0,15,15,15,37,15,15,15,0,0,0,0
0,0,0,0,0,0,0,0,0,0,0,0,0,15,0,0,0,0,0,0,0,0,0,15,0,0,0,0,0,0,0,0,0,0,0,0,0,0,0,0,0,0,0
0,0,0,0,0,0,0,0,0,0,0,0,0,15,0,0,0,0,0,0,0,0,0,15,0,0,0,0,0,0,0,0,0,0,0,0,0,0,0,0,0,0,0
0,0,0,0,0,0,0,0,0,0,0,0,0,0,15,15,0,0,0,0,0,15,15,0,0,0,0,0,0,0,0,0,0,0,0,0,0,0,0,0,0,0,0
0,0,0,0,0,0,0,0,0,0,0,0,0,0,0,0,15,15,37,15,15,0,0,0,0,0,0,0,0,0,0,0,0,0,0,0,0,0,0,0,0,0,0
0,0,0,0,0,0,0,0,0,0,0,0,0,0,0,0,0,0,0,0,0,0,0,0,0,0,0,0,0,0,0,0,0,0,0,0,0,0,0,0,0,0,0
0,0,0,0,0,0,0,0,0,0,0,0,0,0,0,0,0,0,0,0,0,0,0,0,0,0,0,0,0,0,0,0,0,0,0,0,0,0,0,0,0,0,0
0,0,0,0,0,0,0,0,0,0,0,0,0,0,0,0,0,0,0,0,0,0,0,0,0,0,0,0,0,0,0,0,0,0,0,0,0,0,0,0,0,0,0
0,0,0,0,0,0,0,0,0,0,0,0,0,0,0,0,0,0,0,0,0,0,0,0,0,0,0,0,0,0,0,0,0,0,0,0,0,0,0,0,0,0,0
:endlayer
layer: 13
0,0,0,0,0,0,0,0,0,0,0,0,0,0,0,0,0,0,0,0,0,0,0,0,0,0,0,0,0,0,0,0,0,0,0,0,0,0,0,0,0,0,0
0,0,0,0,0,0,0,0,0,0,0,0,0,0,0,0,0,0,0,0,0,0,0,0,0,0,0,0,0,0,0,0,0,0,0,0,0,0,0,0,0,0,0
0,0,0,0,0,0,0,0,0,0,0,0,0,0,0,0,0,0,0,0,0,0,0,0,0,0,0,0,0,0,0,0,0,0,0,0,0,0,0,0,0,0,0
0,0,0,0,0,0,0,0,0,0,0,0,0,0,0,0,0,0,0,0,0,0,0,0,0,0,0,0,0,0,0,0,0,0,0,0,0,0,0,0,0,0,0
0,0,0,0,0,0,0,0,0,0,0,0,15,15,15,9,15,15,15,0,0,0,0,0,0,0,0,0,0,0,0,0,15,15,15,9,15,15,15,0,0,0,0
0,0,0,0,15,15,15,15,15,15,15,15,15,0,0,0,0,0,15,0,0,0,0,0,0,0,0,0,0,0,0,0,15,0,0,0,0,0,15,0,0,0,0
0,0,0,0,15,0,0,0,0,0,0,0,15,0,103,72,0,0,15,15,15,9,15,15,15,9,15,15,15,9,15,15,15,0,0,0,0,0,15,0,0,0,0
0,0,0,0,15,0,0,0,0,0,0,0,15,0,37,15,19,0,155,0,0,0,0,0,0,0,0,0,0,0,0,0,158,0,27,15,0,0,9,0,0,0,0
0,0,0,0,15,0,0,0,0,0,0,0,15,0,0,0,0,0,15,0,0,0,0,0,23,0,23,0,0,0,0,0,15,0,0,0,0,0,15,0,0,0,0
0,0,0,0,15,0,0,0,0,0,0,0,15,0,0,0,0,0,15,15,15,15,15,15,15,156,15,15,15,15,15,15,15,0,0,0,0,0,15,0,0,0,0
0,0,0,0,15,0,0,0,0,0,0,0,15,15,15,15,15,15,15,0,0,0,0,0,0,0,0,0,0,0,0,0,15,15,15,15,15,15,15,0,0,0,0
0,0,0,0,15,23,0,0,0,0,0,23,15,0,0,0,0,0,0,0,0,0,0,0,0,0,0,0,0,0,0,0,0,0,0,0,15,0,0,0,0,0,0
0,0,0,0,15,15,15,15,15,15,15,15,15,0,0,0,0,0,0,0,0,0,0,0,0,0,0,0,0,0,0,0,0,0,0,0,15,0,0,0,0,0,0
0,0,0,0,15,15,15,15,15,15,15,15,15,15,15,0,0,0,0,0,0,0,0,0,0,0,0,0,0,0,0,0,0,0,0,0,9,0,0,0,0,0,0
0,0,0,0,0,76,151,76,0,76,152,76,0,0,15,0,0,0,0,0,0,0,0,0,0,0,0,0,0,0,0,0,0,0,0,0,15,0,0,0,0,0,0
0,0,0,0,0,0,151,0,0,0,152,0,0,0,15,0,0,0,0,0,0,0,0,0,0,0,0,0,0,0,0,0,0,0,0,0,15,0,0,0,0,0,0
0,0,0,0,0,0,151,0,0,0,152,0,0,0,15,0,0,0,0,0,0,0,0,0,0,0,0,0,0,0,0,0,0,0,0,0,15,0,0,0,0,0,0
0,0,0,0,0,0,151,0,0,0,152,0,0,0,9,0,0,0,0,0,0,0,0,0,0,0,0,0,0,0,0,0,0,0,0,0,9,0,0,0,0,0,0
0,0,0,0,0,0,151,0,0,0,152,0,0,0,15,0,0,0,0,0,0,0,0,0,0,0,0,0,0,0,0,0,0,0,0,0,15,0,0,0,0,0,0
0,0,0,0,0,0,151,0,0,0,152,0,0,0,15,0,0,0,0,0,0,0,0,0,0,0,0,0,0,0,0,0,0,0,0,0,15,0,0,0,0,0,0
0,0,0,0,0,0,150,0,0,0,150,0,0,0,9,0,0,0,0,0,0,0,0,0,0,0,0,0,0,0,0,0,0,0,0,0,15,0,0,0,0,0,0
0,0,0,0,0,0,0,0,0,0,0,0,0,0,15,0,0,23,0,23,0,0,0,0,0,0,0,0,0,0,0,0,0,0,0,0,9,0,0,0,0,0,0
0,0,0,0,0,0,0,0,0,0,0,0,0,0,15,0,15,15,154,15,15,0,0,0,0,0,0,0,0,0,0,0,0,0,0,0,15,0,0,0,0,0,0
0,0,0,0,0,103,0,103,0,103,0,103,0,103,15,15,19,0,0,0,27,15,15,0,0,0,0,0,0,0,0,0,0,0,0,0,15,0,0,0,0,0,0
0,0,0,0,102,15,15,15,15,15,15,15,15,15,0,0,0,0,0,0,0,0,0,15,0,0,0,0,0,0,0,0,15,15,15,15,15,15,15,0,0,0,0
0,0,0,0,0,15,0,0,0,0,0,15,15,15,0,0,0,0,0,0,0,0,0,15,0,0,0,0,0,0,0,0,15,0,0,0,0,0,15,0,0,0,0
0,0,0,0,102,15,0,0,0,0,0,15,15,24,0,0,0,0,0,0,0,0,0,24,15,0,0,0,0,0,0,0,15,0,0,0,0,0,15,0,0,0,0
0,0,0,0,0,15,0,0,0,0,0,15,15,0,0,0,0,0,0,0,0,0,0,0,15,0,0,0,0,0,0,0,157,0,27,15,16,0,9,0,0,0,0
0,0,0,0,102,15,0,0,0,0,0,0,153,0,0,0,0,0,0,0,0,0,0,0,15,15,9,15,15,15,9,15,15,0,0,102,71,0,15,0,0,0,0
0,0,0,0,0,15,19,0,0,0,27,15,15,0,0,0,0,0,0,0,0,0,0,0,15,0,0,0,0,0,0,0,15,0,0,0,0,0,15,0,0,0,0
0,0,0,0,102,15,15,15,15,15,15,15,15,23,0,0,0,0,0,0,0,0,0,23,15,0,0,0,0,0,0,0,15,15,15,9,15,15,15,0,0,0,0
0,0,0,0,71,71,0,71,0,71,0,71,0,15,0,0,0,0,0,0,0,0,0,15,0,0,0,0,0,0,0,0,0,0,0,0,0,0,0,0,0,0,0
0,0,0,0,0,0,0,0,0,0,0,0,0,15,0,0,0,0,0,0,0,0,0,15,0,0,0,0,0,0,0,0,0,0,0,0,0,0,0,0,0,0,0
0,0,0,0,0,0,0,0,0,0,0,0,0,0,15,15,19,0,0,0,27,15,15,0,0,0,0,0,0,0,0,0,0,0,0,0,0,0,0,0,0,0,0
0,0,0,0,0,0,0,0,0,0,0,0,0,0,0,0,15,15,9,15,15,0,0,0,0,0,0,0,0,0,0,0,0,0,0,0,0,0,0,0,0,0,0
0,0,0,0,0,0,0,0,0,0,0,0,0,0,0,0,0,0,0,0,0,0,0,0,0,0,0,0,0,0,0,0,0,0,0,0,0,0,0,0,0,0,0
0,0,0,0,0,0,0,0,0,0,0,0,0,0,0,0,0,0,0,0,0,0,0,0,0,0,0,0,0,0,0,0,0,0,0,0,0,0,0,0,0,0,0
0,0,0,0,0,0,0,0,0,0,0,0,0,0,0,0,0,0,0,0,0,0,0,0,0,0,0,0,0,0,0,0,0,0,0,0,0,0,0,0,0,0,0
0,0,0,0,0,0,0,0,0,0,0,0,0,0,0,0,0,0,0,0,0,0,0,0,0,0,0,0,0,0,0,0,0,0,0,0,0,0,0,0,0,0,0
:endlayer
layer: 14
0,0,0,0,0,0,0,0,0,0,0,0,0,0,0,0,0,0,0,0,0,0,0,0,0,0,0,0,0,0,0,0,0,0,0,0,0,0,0,0,0,0,0
0,0,0,0,0,0,0,0,0,0,0,0,0,0,0,0,0,0,0,0,0,0,0,0,0,0,0,0,0,0,0,0,0,0,0,0,0,0,0,0,0,0,0
0,0,0,0,0,0,0,0,0,0,0,0,0,0,0,0,0,0,0,0,0,0,0,0,0,0,0,0,0,0,0,0,0,0,0,0,0,0,0,0,0,0,0
0,0,0,0,0,0,0,0,0,0,0,0,0,0,0,0,0,0,0,0,0,0,0,0,0,0,0,0,0,0,0,0,0,0,0,0,0,0,0,0,0,0,0
0,0,0,0,0,0,0,0,0,0,0,0,15,15,15,9,15,15,15,0,0,0,0,0,0,0,0,0,0,0,0,0,15,15,15,9,15,15,15,0,0,0,0
0,0,0,0,15,15,15,15,15,15,15,15,15,0,0,0,0,0,15,0,0,0,0,0,0,0,0,0,0,0,0,0,15,0,0,0,0,0,15,0,0,0,0
0,0,0,0,15,0,0,0,0,0,0,0,15,0,0,69,72,0,15,15,15,9,15,15,15,9,15,15,15,9,15,15,15,0,0,0,0,0,15,0,0,0,0
0,0,0,0,15,0,0,0,0,0,0,0,15,0,0,15,71,0,15,0,0,0,0,0,0,0,0,0,0,0,0,0,15,0,0,15,0,0,9,0,0,0,0
0,0,0,0,15,0,0,0,0,0,0,0,15,0,0,0,0,0,15,0,0,0,0,0,0,0,0,0,0,0,0,0,15,0,0,0,0,0,15,0,0,0,0
0,0,0,0,15,0,0,0,0,0,0,0,15,0,0,0,0,0,15,15,15,15,15,15,15,15,15,15,15,15,15,15,15,0,0,0,0,0,15,0,0,0,0
0,0,0,0,15,0,0,0,0,0,0,0,15,15,15,15,15,15,15,19,0,0,0,0,24,0,24,0,0,0,0,27,15,15,15,15,15,15,15,0,0,0,0
0,0,0,0,15,0,0,0,0,0,0,0,15,0,0,0,0,0,24,0,0,0,0,0,0,0,0,0,0,0,0,0,24,0,0,0,15,0,0,0,0,0,0
0,0,0,0,15,0,0,0,0,0,0,0,15,0,23,0,0,0,0,0,0,0,0,0,0,0,0,0,0,0,0,0,0,0,0,0,15,0,0,0,0,0,0
0,0,0,0,15,15,15,15,15,15,15,15,15,15,15,19,0,0,0,0,0,0,0,0,0,0,0,0,0,0,0,0,0,0,0,0,9,0,0,0,0,0,0
0,0,0,0,0,13,159,3,0,13,159,3,0,0,15,0,0,0,0,0,0,0,0,0,0,0,0,0,0,0,0,0,0,0,0,0,15,0,0,0,0,0,0
0,0,0,0,0,0,0,0,0,0,0,0,0,0,15,0,0,0,0,0,0,0,0,0,0,0,0,0,0,0,0,0,0,0,0,27,15,0,0,0,0,0,0
0,0,0,0,0,0,0,0,0,0,0,0,0,0,15,0,0,0,0,0,0,0,0,0,0,0,0,0,0,0,0,0,0,0,0,0,15,0,0,0,0,0,0
0,0,0,0,0,0,0,0,0,0,0,0,0,0,9,0,0,0,0,0,0,0,0,0,0,0,0,0,0,0,0,0,0,0,0,0,9,0,0,0,0,0,0
0,0,0,0,0,0,0,0,0,0,0,0,0,0,15,19,0,0,0,0,0,0,0,0,0,0,0,0,0,0,0,0,0,0,0,0,15,0,0,0,0,0,0
0,0,0,0,0,0,0,0,0,0,0,0,0,0,15,0,0,0,0,0,0,0,0,0,0,0,0,0,0,0,0,0,0,0,0,27,15,0,0,0,0,0,0
0,0,0,0,0,0,0,0,0,0,0,0,0,0,9,0,0,0,0,0,0,0,0,0,0,0,0,0,0,0,0,0,0,0,0,0,15,0,0,0,0,0,0
0,0,0,0,0,0,0,0,0,0,0,0,0,0,15,0,0,0,0,0,0,0,0,0,0,0,0,0,0,0,0,0,0,0,0,0,9,0,0,0,0,0,0
0,0,0,0,0,0,0,0,0,0,0,0,0,0,15,0,15,15,15,15,15,0,23,0,0,0,0,0,0,0,0,0,0,0,0,27,15,0,0,0,0,0,0
0,0,0,0,15,16,15,16,15,16,15,16,15,16,15,15,0,0,0,0,0,15,15,19,0,0,0,0,0,0,0,0,23,0,0,0,15,0,0,0,0,0,0
0,0,0,0,69,110,110,110,110,110,110,110,110,15,0,0,0,0,0,0,0,0,0,15,0,0,0,0,0,0,0,27,15,15,15,15,15,15,15,0,0,0,0
0,0,0,0,15,110,110,110,110,110,110,110,110,15,0,0,0,0,0,0,0,0,0,15,23,0,0,0,0,0,0,0,15,0,0,0,0,0,15,0,0,0,0
0,0,0,0,69,110,110,110,110,110,110,110,15,0,0,0,0,0,0,0,0,0,0,0,15,19,0,0,0,0,0,0,15,0,0,0,0,0,15,0,0,0,0
0,0,0,0,15,110,110,110,110,110,110,110,15,0,0,0,0,0,0,0,0,0,0,0,15,0,0,0,0,0,0,23,15,0,103,15,0,0,9,0,0,0,0
0,0,0,0,69,110,110,110,110,110,110,110,15,160,0,0,0,0,0,0,0,0,0,0,15,15,9,15,15,15,9,15,15,0,102,31,0,0,15,0,0,0,0
0,0,0,0,15,110,110,110,110,110,110,110,15,0,0,0,0,0,0,0,0,0,0,0,15,0,0,0,0,0,0,0,15,0,0,0,0,0,15,0,0,0,0
0,0,0,0,69,110,110,110,110,110,110,110,15,0,0,0,0,0,0,0,0,0,0,0,15,0,0,0,0,0,0,0,15,15,15,9,15,15,15,0,0,0,0
0,0,0,0,15,37,15,37,15,37,15,37,15,15,0,0,0,0,0,0,0,0,0,15,0,0,0,0,0,0,0,0,0,0,0,0,0,0,0,0,0,0,0
0,0,0,0,0,0,0,0,0,0,0,0,0,15,0,0,0,0,0,0,0,0,0,15,0,0,0,0,0,0,0,0,0,0,0,0,0,0,0,0,0,0,0
0,0,0,0,0,0,0,0,0,0,0,0,0,0,15,15,0,0,0,0,0,15,15,0,0,0,0,0,0,0,0,0,0,0,0,0,0,0,0,0,0,0,0
0,0,0,0,0,0,0,0,0,0,0,0,0,0,0,0,15,15,9,15,15,0,0,0,0,0,0,0,0,0,0,0,0,0,0,0,0,0,0,0,0,0,0
0,0,0,0,0,0,0,0,0,0,0,0,0,0,0,0,0,0,0,0,0,0,0,0,0,0,0,0,0,0,0,0,0,0,0,0,0,0,0,0,0,0,0
0,0,0,0,0,0,0,0,0,0,0,0,0,0,0,0,0,0,0,0,0,0,0,0,0,0,0,0,0,0,0,0,0,0,0,0,0,0,0,0,0,0,0
0,0,0,0,0,0,0,0,0,0,0,0,0,0,0,0,0,0,0,0,0,0,0,0,0,0,0,0,0,0,0,0,0,0,0,0,0,0,0,0,0,0,0
0,0,0,0,0,0,0,0,0,0,0,0,0,0,0,0,0,0,0,0,0,0,0,0,0,0,0,0,0,0,0,0,0,0,0,0,0,0,0,0,0,0,0
:endlayer
layer: 15
0,0,0,0,0,0,0,0,0,0,0,0,0,0,0,0,0,0,0,0,0,0,0,0,0,0,0,0,0,0,0,0,0,0,0,0,0,0,0,0,0,0,0
0,0,0,0,0,0,0,0,0,0,0,0,0,0,0,0,0,0,0,0,0,0,0,0,0,0,0,0,0,0,0,0,0,0,0,0,0,0,0,0,0,0,0
0,0,0,0,0,0,0,0,0,0,0,0,0,0,0,0,0,0,0,0,0,0,0,0,0,0,0,0,0,0,0,0,0,0,0,0,0,0,0,0,0,0,0
0,0,0,0,0,0,0,0,0,0,0,0,0,0,0,0,0,0,0,0,0,0,0,0,0,0,0,0,0,0,0,0,0,0,0,0,0,0,0,0,0,0,0
0,0,0,0,103,0,103,0,103,0,103,0,15,15,15,15,15,15,15,0,0,0,0,0,0,0,0,0,0,0,0,0,15,15,15,15,15,15,15,0,0,0,0
0,0,0,102,15,15,15,15,15,15,15,15,15,15,15,15,15,15,15,0,0,0,0,0,0,0,0,0,0,0,0,0,15,15,15,15,15,15,15,0,0,0,0
0,0,0,0,15,0,0,0,0,0,0,0,15,15,0,0,0,15,15,15,15,15,15,15,15,15,15,15,15,15,15,15,15,15,15,15,15,15,15,0,0,0,0
0,0,0,102,15,0,0,0,0,0,0,0,15,15,27,15,16,15,15,15,15,15,15,15,15,15,15,15,15,15,15,15,15,15,15,15,15,15,15,0,0,0,0
0,0,0,0,15,0,0,0,0,0,0,0,15,15,0,0,71,15,15,15,15,15,15,15,15,15,15,15,15,15,15,15,15,15,15,15,15,15,15,0,0,0,0
0,0,0,102,15,0,0,0,0,0,0,0,15,15,15,15,15,15,15,15,15,15,15,15,15,15,15,15,15,15,15,15,15,15,15,15,15,15,15,0,0,0,0
0,0,0,0,15,0,0,0,0,0,0,0,15,15,15,15,15,15,15,15,15,15,15,15,15,15,15,15,15,15,15,15,15,15,15,15,15,15,15,0,0,0,0
0,0,0,102,15,0,0,0,0,0,0,0,15,15,15,15,15,15,15,15,15,15,15,15,15,15,15,15,15,15,15,15,15,15,15,15,15,0,0,0,0,0,0
0,0,0,0,15,0,0,0,0,0,0,0,15,15,15,15,15,15,15,15,15,15,15,15,15,15,15,15,15,15,15,15,15,15,15,15,15,0,0,0,0,0,0
0,0,0,102,15,15,15,15,15,15,15,15,15,15,15,15,15,15,15,15,15,15,15,15,15,15,15,15,15,15,15,15,15,15,15,15,15,0,0,0,0,0,0
0,0,0,0,71,0,71,0,71,0,71,0,71,0,15,15,15,15,15,15,15,15,15,15,15,15,15,15,15,15,15,15,15,15,15,15,15,0,0,0,0,0,0
0,0,0,0,0,0,0,0,0,0,0,0,0,0,15,15,15,15,15,15,15,15,15,15,15,15,15,15,15,15,15,15,15,15,15,15,15,0,0,0,0,0,0
0,0,0,0,0,0,0,0,0,0,0,0,0,0,15,15,15,15,15,15,15,15,15,15,15,15,15,15,15,15,15,15,15,15,15,15,15,0,0,0,0,0,0
0,0,0,0,0,0,0,0,0,0,0,0,0,0,15,15,15,15,15,15,15,15,15,15,15,15,15,15,15,15,15,15,15,15,15,15,15,0,0,0,0,0,0
0,0,0,0,0,0,0,0,0,0,0,0,0,0,15,15,15,15,15,15,15,15,15,15,15,15,15,15,15,15,15,15,15,15,15,15,15,0,0,0,0,0,0
0,0,0,0,0,0,0,0,0,0,0,0,0,0,15,15,15,15,15,15,15,15,15,15,15,15,15,15,15,15,15,15,15,15,15,15,15,0,0,0,0,0,0
0,0,0,0,0,0,0,0,0,0,0,0,0,0,15,15,15,15,15,15,15,15,15,15,15,15,15,15,15,15,15,15,15,15,15,15,15,0,0,0,0,0,0
0,0,0,0,0,0,0,0,0,0,0,0,0,0,15,15,15,15,15,15,15,15,15,15,15,15,15,15,15,15,15,15,15,15,15,15,15,0,0,0,0,0,0
0,0,0,0,0,0,0,0,0,0,0,0,0,0,15,15,15,15,15,15,15,15,15,15,15,15,15,15,15,15,15,15,15,15,15,15,15,0,0,0,0,0,0
0,0,0,0,15,161,15,161,15,161,15,161,15,161,15,15,15,15,15,15,15,15,15,15,15,15,15,15,15,15,15,15,15,15,15,15,15,0,0,0,0,0,0
0,0,0,0,161,15,15,15,15,15,15,15,15,15,15,15,15,15,15,15,15,15,15,15,15,15,15,15,15,15,15,15,15,15,15,15,15,15,15,0,0,0,0
0,0,0,0,15,15,15,15,15,15,15,15,15,15,15,15,15,15,15,15,15,15,15,15,15,15,15,15,15,15,15,15,15,15,15,15,15,15,15,0,0,0,0
0,0,0,0,161,15,15,15,15,15,15,15,15,15,15,15,15,15,15,15,15,15,15,15,15,15,15,15,15,15,15,15,15,15,103,72,0,15,15,0,0,0,0
0,0,0,0,15,15,15,15,15,15,15,15,15,15,15,15,15,15,15,15,15,15,15,15,15,15,15,15,15,15,15,15,15,15,37,15,19,15,15,0,0,0,0
0,0,0,0,161,15,15,15,15,15,15,15,15,15,15,15,15,15,15,15,15,15,15,15,15,15,15,15,15,15,15,15,15,15,0,0,0,15,15,0,0,0,0
0,0,0,0,15,15,15,15,15,15,15,15,15,15,15,15,15,15,15,15,15,15,15,15,15,0,0,0,0,0,0,0,15,15,15,15,15,15,15,0,0,0,0
0,0,0,0,161,15,15,15,15,15,15,15,15,15,15,15,15,15,15,15,15,15,15,15,15,0,0,0,0,0,0,0,15,15,15,15,15,15,15,0,0,0,0
0,0,0,0,15,161,15,161,15,161,15,161,15,15,15,15,15,15,15,15,15,15,15,15,0,0,0,0,0,0,0,0,0,0,0,0,0,0,0,0,0,0,0
0,0,0,0,0,0,0,0,0,0,0,0,0,15,15,15,15,15,15,15,15,15,15,15,0,0,0,0,0,0,0,0,0,0,0,0,0,0,0,0,0,0,0
0,0,0,0,0,0,0,0,0,0,0,0,0,0,15,15,15,15,15,15,15,15,15,0,0,0,0,0,0,0,0,0,0,0,0,0,0,0,0,0,0,0,0
0,0,0,0,0,0,0,0,0,0,0,0,0,0,0,0,15,15,15,15,15,0,0,0,0,0,0,0,0,0,0,0,0,0,0,0,0,0,0,0,0,0,0
0,0,0,0,0,0,0,0,0,0,0,0,0,0,0,0,0,0,0,0,0,0,0,0,0,0,0,0,0,0,0,0,0,0,0,0,0,0,0,0,0,0,0
0,0,0,0,0,0,0,0,0,0,0,0,0,0,0,0,0,0,0,0,0,0,0,0,0,0,0,0,0,0,0,0,0,0,0,0,0,0,0,0,0,0,0
0,0,0,0,0,0,0,0,0,0,0,0,0,0,0,0,0,0,0,0,0,0,0,0,0,0,0,0,0,0,0,0,0,0,0,0,0,0,0,0,0,0,0
0,0,0,0,0,0,0,0,0,0,0,0,0,0,0,0,0,0,0,0,0,0,0,0,0,0,0,0,0,0,0,0,0,0,0,0,0,0,0,0,0,0,0
:endlayer
layer: 16
0,0,0,0,0,0,0,0,0,0,0,0,0,0,0,0,0,0,0,0,0,0,0,0,0,0,0,0,0,0,0,0,0,0,0,0,0,0,0,0,0,0,0
0,0,0,0,0,0,0,0,0,0,0,0,0,0,0,0,0,0,0,0,0,0,0,0,0,0,0,0,0,0,0,0,0,0,0,0,0,0,0,0,0,0,0
0,0,0,0,0,0,0,0,0,0,0,0,0,0,0,0,0,0,0,0,0,0,0,0,0,0,0,0,0,0,0,0,0,0,0,0,0,0,0,0,0,0,0
0,0,0,0,0,0,0,0,0,0,0,0,0,0,0,0,0,0,0,0,0,0,0,0,0,0,0,0,0,0,0,0,0,0,0,0,0,0,0,0,0,0,0
0,0,0,15,16,15,16,15,16,15,16,15,15,15,15,16,15,15,15,0,0,0,0,0,0,0,0,0,0,0,0,0,15,15,15,16,15,15,15,0,0,0,0
0,0,0,69,110,110,110,110,110,110,110,110,15,0,0,0,0,0,15,0,0,0,0,0,0,0,0,0,0,0,0,0,15,0,0,0,0,0,15,0,0,0,0
0,0,0,15,110,110,110,110,110,110,110,110,15,0,0,0,0,0,15,15,15,16,15,15,15,16,15,15,15,16,15,15,15,0,0,0,0,0,15,0,0,0,0
0,0,0,69,110,110,110,110,15,15,15,15,31,0,103,15,0,0,53,0,0,0,0,0,0,0,0,0,0,0,0,0,15,0,0,0,0,0,31,0,0,0,0
0,0,0,15,110,110,110,110,110,110,110,110,15,0,102,31,0,0,15,0,0,0,0,0,0,0,0,0,0,0,0,0,53,0,0,0,0,0,15,0,0,0,0
0,0,0,69,110,110,110,110,110,110,110,110,15,0,0,0,0,0,15,0,0,0,0,0,0,0,0,0,0,0,0,0,15,0,0,0,0,0,15,0,0,0,0
0,0,0,15,110,110,110,110,110,110,110,110,15,15,15,48,15,15,15,15,48,15,15,15,15,15,15,0,0,0,15,15,15,15,15,15,15,15,15,0,0,0,0
0,0,0,69,110,110,110,110,110,110,110,110,110,110,15,0,15,0,0,0,0,0,0,0,0,0,15,0,0,0,15,0,0,0,0,0,15,0,0,0,0,0,0
0,0,0,15,110,110,110,110,110,110,110,110,110,110,15,0,15,0,0,0,0,0,0,0,0,0,15,0,0,0,15,0,0,0,0,0,15,0,0,0,0,0,0
0,0,0,69,110,110,110,110,110,110,110,110,110,110,15,0,15,0,0,0,0,0,0,0,0,0,15,0,0,0,15,0,0,0,0,0,31,0,0,0,0,0,0
0,0,0,15,37,15,37,15,37,15,37,15,37,15,15,0,15,0,0,0,0,0,0,0,0,0,15,0,0,0,15,0,0,0,0,0,15,0,0,0,0,0,0
0,0,0,0,0,0,0,0,0,0,0,0,0,0,15,0,15,15,15,15,15,15,15,15,15,47,15,0,0,0,15,47,15,15,15,15,15,0,0,0,0,0,0
0,0,0,0,0,0,0,0,0,0,0,0,0,0,15,0,15,0,0,0,0,0,0,0,0,0,0,0,0,0,0,0,0,0,0,0,15,0,0,0,0,0,0
0,0,0,0,0,0,0,0,0,0,0,0,0,0,69,0,15,0,0,0,0,0,0,0,0,0,0,0,0,0,0,0,0,0,0,0,31,0,0,0,0,0,0
0,0,0,0,0,0,0,0,0,0,0,0,0,0,15,0,15,0,0,0,0,0,0,0,0,0,0,0,0,0,0,0,0,0,0,0,15,0,0,0,0,0,0
0,0,0,0,0,0,0,0,0,0,0,0,0,0,15,0,15,0,0,0,15,15,15,15,15,48,15,0,0,0,15,48,15,15,15,15,15,0,0,0,0,0,0
0,0,0,0,0,0,0,0,0,0,0,0,0,0,69,0,15,0,0,0,15,0,0,0,0,0,15,0,0,0,15,0,0,0,0,0,15,0,0,0,0,0,0
0,0,0,0,0,0,0,0,0,0,0,0,0,0,15,0,15,0,0,0,15,0,0,0,0,0,15,0,0,0,15,0,0,0,0,0,31,0,0,0,0,0,0
0,0,0,0,0,0,0,0,0,0,0,0,0,0,15,15,15,15,67,15,15,0,0,0,0,0,15,0,0,0,15,0,0,0,0,0,15,0,0,0,0,0,0
0,0,0,0,15,103,15,103,15,103,15,103,15,103,15,15,162,162,0,162,162,15,15,0,0,0,15,0,0,0,15,0,0,0,0,0,15,0,0,0,0,0,0
0,0,0,0,102,40,40,40,40,40,40,40,40,15,162,162,0,0,0,0,0,162,162,15,0,0,15,0,0,0,15,0,15,15,15,15,15,15,15,0,0,0,0
0,0,0,0,15,40,0,0,0,0,0,0,0,15,162,0,0,0,0,0,0,0,162,15,15,15,15,0,0,0,15,15,15,0,0,0,0,0,15,0,0,0,0
0,0,0,0,102,40,0,0,0,0,0,0,15,162,0,0,162,162,0,162,162,0,0,162,15,0,0,0,0,0,0,0,15,0,0,69,72,0,15,0,0,0,0
0,0,0,0,15,40,0,0,0,0,0,0,15,162,0,0,162,0,0,0,162,0,0,162,15,0,0,0,0,0,0,0,65,0,0,15,71,0,31,0,0,0,0
0,0,0,0,102,40,0,0,0,0,0,0,64,0,0,0,162,0,163,0,162,0,0,162,15,15,37,15,15,15,37,15,15,0,0,0,0,0,15,0,0,0,0
0,0,0,0,15,40,0,0,0,0,0,0,15,162,0,0,162,0,0,0,162,0,0,162,15,0,0,0,0,0,0,0,15,0,0,0,0,0,15,0,0,0,0
0,0,0,0,102,40,40,40,40,40,40,40,15,162,0,0,162,162,162,162,162,0,0,162,15,0,0,0,0,0,0,0,15,15,15,37,15,15,15,0,0,0,0
0,0,0,0,15,71,15,71,15,71,15,71,15,15,162,0,0,0,0,0,0,0,162,15,0,0,0,0,0,0,0,0,0,0,0,0,0,0,0,0,0,0,0
0,0,0,0,0,0,0,0,0,0,0,0,0,69,162,162,0,0,0,0,0,162,162,31,0,0,0,0,0,0,0,0,0,0,0,0,0,0,0,0,0,0,0
0,0,0,0,0,0,0,0,0,0,0,0,0,0,37,15,162,162,162,162,162,15,37,0,0,0,0,0,0,0,0,0,0,0,0,0,0,0,0,0,0,0,0
0,0,0,0,0,0,0,0,0,0,0,0,0,0,0,0,15,15,15,15,15,0,0,0,0,0,0,0,0,0,0,0,0,0,0,0,0,0,0,0,0,0,0
0,0,0,0,0,0,0,0,0,0,0,0,0,0,0,0,0,0,0,0,0,0,0,0,0,0,0,0,0,0,0,0,0,0,0,0,0,0,0,0,0,0,0
0,0,0,0,0,0,0,0,0,0,0,0,0,0,0,0,0,0,0,0,0,0,0,0,0,0,0,0,0,0,0,0,0,0,0,0,0,0,0,0,0,0,0
0,0,0,0,0,0,0,0,0,0,0,0,0,0,0,0,0,0,0,0,0,0,0,0,0,0,0,0,0,0,0,0,0,0,0,0,0,0,0,0,0,0,0
0,0,0,0,0,0,0,0,0,0,0,0,0,0,0,0,0,0,0,0,0,0,0,0,0,0,0,0,0,0,0,0,0,0,0,0,0,0,0,0,0,0,0
:endlayer
layer: 17
0,0,0,0,0,0,0,0,0,0,0,0,0,0,0,0,0,0,0,0,0,0,0,0,0,0,0,0,0,0,0,0,0,0,0,0,0,0,0,0,0,0,0
0,0,0,0,0,0,0,0,0,0,0,0,0,0,0,0,0,0,0,0,0,0,0,0,0,0,0,0,0,0,0,0,0,0,0,0,0,0,0,0,0,0,0
0,0,0,0,0,0,0,0,0,0,0,0,0,0,0,0,0,0,0,0,0,0,0,0,0,0,0,0,0,0,0,0,0,0,0,0,0,0,0,0,0,0,0
0,0,0,0,0,0,0,0,0,0,0,0,0,0,0,0,0,0,0,0,0,0,0,0,0,0,0,0,0,0,0,0,0,0,0,0,0,0,0,0,0,0,0
0,0,0,15,161,15,161,15,161,15,161,15,15,15,15,9,15,15,15,0,0,0,0,0,0,0,0,0,0,0,0,0,15,15,15,9,15,15,15,0,0,0,0
0,0,0,161,15,15,15,15,15,15,15,15,15,0,0,0,0,0,15,0,0,0,0,0,0,0,0,0,0,0,0,0,15,24,0,0,0,24,15,0,0,0,0
0,0,0,15,15,15,15,15,15,15,15,15,15,0,103,72,0,0,15,15,15,9,15,15,15,9,15,15,15,9,15,15,15,0,0,0,0,0,15,0,0,0,0
0,0,0,161,15,15,15,15,31,0,0,0,0,0,37,15,19,0,167,0,0,0,0,24,0,0,0,24,0,0,0,0,15,0,0,0,0,0,9,0,0,0,0
0,0,0,15,15,15,15,15,15,15,15,15,15,0,0,0,0,0,15,19,0,0,0,0,0,0,0,0,0,0,0,0,174,0,0,0,0,0,15,0,0,0,0
0,0,0,161,15,15,15,15,15,15,15,15,15,0,0,0,0,0,15,0,0,23,0,0,0,0,0,0,0,0,0,27,15,23,0,0,0,23,15,0,0,0,0
0,0,0,15,15,15,15,15,15,15,15,15,15,15,15,165,15,15,15,15,168,15,15,15,15,15,15,0,0,0,15,15,15,15,15,15,15,15,15,0,0,0,0
0,0,0,161,15,15,15,15,15,15,15,15,15,15,15,0,15,0,0,0,0,24,0,0,0,27,15,0,0,0,15,24,0,0,0,27,15,0,0,0,0,0,0
0,0,0,15,15,15,15,15,15,15,15,15,15,15,15,0,15,0,0,0,0,0,0,0,0,0,15,0,0,0,15,0,0,0,0,0,15,0,0,0,0,0,0
0,0,0,161,15,15,15,15,15,15,15,15,15,15,15,0,15,0,0,0,0,0,0,0,0,0,15,0,0,0,15,0,0,0,0,0,9,0,0,0,0,0,0
0,0,0,15,161,15,161,15,161,15,161,15,161,15,15,0,15,19,0,0,0,0,0,0,23,0,15,0,0,0,15,0,23,0,0,27,15,0,0,0,0,0,0
0,0,0,0,0,0,0,0,0,0,0,0,0,0,15,0,15,15,15,15,15,15,15,15,15,170,15,0,0,0,15,172,15,15,15,15,15,0,0,0,0,0,0
0,0,0,0,0,0,0,0,0,0,0,0,0,0,15,19,15,0,0,0,0,0,0,0,0,0,24,0,0,0,24,0,0,0,0,0,15,0,0,0,0,0,0
0,0,0,0,0,0,0,0,0,0,0,0,0,0,9,0,15,0,0,0,0,0,0,0,0,0,0,0,0,0,0,0,0,0,0,0,9,0,0,0,0,0,0
0,0,0,0,0,0,0,0,0,0,0,0,0,0,15,160,15,0,0,0,0,0,0,0,0,0,23,0,0,0,23,0,0,0,0,0,15,0,0,0,0,0,0
0,0,0,0,0,0,0,0,0,0,0,0,0,0,15,160,15,0,0,0,15,15,15,15,15,169,15,0,0,0,15,171,15,15,15,15,15,0,0,0,0,0,0
0,0,0,0,0,0,0,0,0,0,0,0,0,0,9,0,15,0,0,0,15,0,0,0,24,0,15,0,0,0,15,0,24,0,0,27,15,0,0,0,0,0,0
0,0,0,0,0,0,0,0,0,0,0,0,0,0,15,19,15,23,0,23,15,0,0,0,0,0,15,0,0,0,15,0,0,0,0,0,9,0,0,0,0,0,0
0,0,0,0,0,0,0,0,0,0,0,0,0,0,15,15,15,15,166,15,15,0,23,0,0,0,15,0,0,0,15,0,0,0,0,0,15,0,0,0,0,0,0
0,0,0,0,15,15,0,15,15,0,15,15,0,15,15,15,162,24,0,24,162,15,15,0,0,0,15,0,0,0,15,0,0,0,0,27,15,0,0,0,0,0,0
0,0,0,0,15,0,0,0,0,0,0,0,0,15,162,162,0,0,0,0,0,162,162,15,19,0,15,0,0,0,15,23,15,15,15,15,15,15,15,0,0,0,0
0,0,0,0,0,0,0,0,0,0,0,0,0,15,162,0,0,0,0,0,0,0,162,15,15,15,15,0,0,0,15,15,15,0,0,0,0,0,15,0,0,0,0
0,0,0,0,15,0,0,0,0,0,0,0,15,162,0,0,162,162,0,162,162,0,0,162,15,0,0,0,0,0,0,27,15,0,0,0,0,0,15,0,0,0,0
0,0,0,0,15,0,0,0,0,0,0,0,15,19,0,0,162,24,0,24,162,0,0,162,15,0,0,0,23,0,0,0,173,0,27,15,16,0,9,0,0,0,0
0,0,0,0,15,0,0,0,0,0,0,0,164,0,0,0,162,0,0,0,162,0,0,162,15,15,9,15,15,15,9,15,15,0,0,102,71,0,15,0,0,0,0
0,0,0,0,0,0,0,0,0,0,0,0,15,19,0,0,162,0,0,0,162,0,0,162,15,0,0,0,0,0,0,0,15,0,0,0,0,0,15,0,0,0,0
0,0,0,0,15,0,0,0,0,0,0,0,15,162,0,0,162,162,162,162,162,0,0,162,15,0,0,0,0,0,0,0,15,15,15,9,15,15,15,0,0,0,0
0,0,0,0,15,15,0,15,15,0,15,15,0,15,19,0,0,0,0,0,0,0,27,15,0,0,0,0,0,0,0,0,0,0,0,0,0,0,0,0,0,0,0
0,0,0,0,0,0,0,0,0,0,0,0,0,9,9,23,0,0,0,0,0,23,9,9,0,0,0,0,0,0,0,0,0,0,0,0,0,0,0,0,0,0,0
0,0,0,0,0,0,0,0,0,0,0,0,0,0,9,15,162,162,162,162,162,15,9,0,0,0,0,0,0,0,0,0,0,0,0,0,0,0,0,0,0,0,0
0,0,0,0,0,0,0,0,0,0,0,0,0,0,0,0,15,15,15,15,15,0,0,0,0,0,0,0,0,0,0,0,0,0,0,0,0,0,0,0,0,0,0
0,0,0,0,0,0,0,0,0,0,0,0,0,0,0,0,0,0,0,0,0,0,0,0,0,0,0,0,0,0,0,0,0,0,0,0,0,0,0,0,0,0,0
0,0,0,0,0,0,0,0,0,0,0,0,0,0,0,0,0,0,0,0,0,0,0,0,0,0,0,0,0,0,0,0,0,0,0,0,0,0,0,0,0,0,0
0,0,0,0,0,0,0,0,0,0,0,0,0,0,0,0,0,0,0,0,0,0,0,0,0,0,0,0,0,0,0,0,0,0,0,0,0,0,0,0,0,0,0
0,0,0,0,0,0,0,0,0,0,0,0,0,0,0,0,0,0,0,0,0,0,0,0,0,0,0,0,0,0,0,0,0,0,0,0,0,0,0,0,0,0,0
:endlayer
layer: 18
0,0,0,0,0,0,0,0,0,0,0,0,0,0,0,0,0,0,0,0,0,0,0,0,0,0,0,0,0,0,0,0,0,0,0,0,0,0,0,0,0,0,0
0,0,0,0,0,0,0,0,0,0,0,0,0,0,0,0,0,0,0,0,0,0,0,0,0,0,0,0,0,0,0,0,0,0,0,0,0,0,0,0,0,0,0
0,0,0,0,0,0,0,0,0,0,0,0,0,0,0,0,0,0,0,0,0,0,0,0,0,0,0,0,0,0,0,0,0,0,0,0,0,0,0,0,0,0,0
0,0,0,0,0,0,0,0,0,0,0,0,0,0,0,0,0,0,0,0,0,0,0,0,0,0,0,0,0,0,0,0,0,0,0,0,0,0,0,0,0,0,0
0,0,0,15,103,15,103,15,103,15,103,15,15,15,15,9,15,15,15,0,0,0,0,0,0,0,0,0,0,0,0,0,15,15,15,9,15,15,15,0,0,0,0
0,0,0,102,40,40,40,40,40,40,40,40,15,0,0,0,0,0,15,0,0,0,0,0,0,0,0,0,0,0,0,0,15,0,0,0,0,0,15,0,0,0,0
0,0,0,15,40,0,0,0,0,0,27,15,15,0,0,69,72,0,15,15,15,9,15,15,15,9,15,15,15,9,15,15,15,0,0,0,0,0,15,0,0,0,0
0,0,0,102,40,0,0,0,0,0,0,0,0,0,0,15,71,0,15,0,0,0,0,0,0,0,0,0,0,0,0,0,15,0,0,0,0,0,9,0,0,0,0
0,0,0,15,40,0,0,0,0,0,27,15,15,0,0,0,0,0,15,0,0,0,0,0,0,0,0,0,0,0,0,0,15,0,0,0,0,0,15,0,0,0,0
0,0,0,102,40,0,0,0,0,0,0,0,15,0,0,176,0,0,15,0,0,0,0,0,0,0,0,0,0,0,0,0,15,0,0,0,0,0,15,0,0,0,0
0,0,0,15,40,0,0,0,0,0,0,0,15,15,15,15,15,15,15,15,15,15,15,15,15,15,15,0,0,0,15,15,15,15,15,15,15,15,15,0,0,0,0
0,0,0,102,40,0,0,0,0,0,0,0,0,0,15,0,15,0,0,0,0,0,0,0,0,0,15,0,0,0,15,0,0,0,0,0,15,0,0,0,0,0,0
0,0,0,15,40,0,0,0,0,0,0,0,0,0,15,0,15,0,0,0,0,0,0,0,0,0,15,0,0,0,15,0,0,0,0,0,15,0,0,0,0,0,0
0,0,0,102,40,40,40,40,40,40,40,40,40,40,15,0,15,0,0,0,0,0,0,0,0,0,15,0,0,0,15,0,0,0,0,0,9,0,0,0,0,0,0
0,0,0,15,71,15,71,15,71,15,71,15,71,15,15,0,15,0,0,0,0,0,0,0,0,0,15,0,0,0,15,0,0,0,0,0,15,0,0,0,0,0,0
0,0,0,0,0,0,0,0,0,0,0,0,0,0,15,0,15,15,15,15,15,15,15,15,15,15,15,0,0,0,15,15,15,15,15,15,15,0,0,0,0,0,0
0,0,0,0,0,0,0,0,0,0,0,0,0,0,15,0,15,0,0,0,0,0,0,0,0,0,0,0,0,0,0,0,0,0,0,0,15,0,0,0,0,0,0
0,0,0,0,0,0,0,0,0,0,0,0,0,0,9,0,15,0,0,0,0,0,0,0,0,0,0,0,0,0,0,0,0,0,0,0,9,0,0,0,0,0,0
0,0,0,0,0,0,0,0,0,0,0,0,0,0,15,0,15,0,0,0,0,0,0,0,0,0,0,0,0,0,0,0,0,0,0,0,15,0,0,0,0,0,0
0,0,0,0,0,0,0,0,0,0,0,0,0,0,15,0,15,0,0,0,15,15,15,15,15,15,15,0,0,0,15,15,15,15,15,15,15,0,0,0,0,0,0
0,0,0,0,0,0,0,0,0,0,0,0,0,0,9,0,15,0,0,0,15,0,0,0,0,0,15,0,0,0,15,0,0,0,0,0,15,0,0,0,0,0,0
0,0,0,0,0,0,0,0,0,0,0,0,0,0,15,0,15,0,0,0,15,0,0,0,0,0,15,0,0,0,15,0,0,0,0,0,9,0,0,0,0,0,0
0,0,0,0,0,0,0,0,0,0,0,0,0,0,15,15,15,15,15,15,15,0,0,0,0,0,15,0,0,0,15,0,0,0,0,0,15,0,0,0,0,0,0
0,0,0,0,175,40,0,0,0,0,0,175,0,0,15,15,162,162,162,162,162,15,15,0,0,0,15,0,0,0,15,0,0,0,0,0,15,0,0,0,0,0,0
0,0,0,0,40,0,0,0,0,0,0,0,0,15,162,162,0,0,0,0,0,162,162,15,0,0,15,0,0,0,15,0,15,15,15,15,15,15,15,0,0,0,0
0,0,0,0,0,0,0,0,0,0,0,0,0,15,162,0,0,0,0,0,0,0,162,15,15,15,15,0,0,0,15,15,15,0,0,0,0,0,15,0,0,0,0
0,0,0,0,0,0,0,0,0,0,0,0,15,162,0,0,162,162,0,162,162,0,0,162,15,0,0,0,0,0,0,0,15,0,0,0,0,0,15,0,0,0,0
0,0,0,0,0,0,0,0,0,0,0,0,15,162,0,0,162,0,0,0,162,0,0,162,15,0,0,0,0,0,0,0,15,0,103,15,0,0,9,0,0,0,0
0,0,0,0,0,0,0,0,0,0,0,0,102,162,0,0,162,0,0,0,162,0,0,162,15,15,9,15,15,15,9,15,15,0,102,31,0,0,15,0,0,0,0
0,0,0,0,0,0,0,0,0,0,0,0,15,162,0,0,162,0,0,0,162,0,0,162,15,0,0,0,0,0,0,0,15,0,0,0,0,0,15,0,0,0,0
0,0,0,0,40,0,0,0,0,0,0,0,15,162,0,0,162,162,162,162,162,0,0,162,15,0,0,0,0,0,0,0,15,15,15,9,15,15,15,0,0,0,0
0,0,0,0,175,40,0,0,0,0,0,175,0,15,0,0,0,0,0,0,0,0,0,15,0,0,0,0,0,0,0,0,0,0,0,0,0,0,0,0,0,0,0
0,0,0,0,0,0,0,0,0,0,0,0,0,9,9,0,0,0,0,0,0,0,9,9,0,0,0,0,0,0,0,0,0,0,0,0,0,0,0,0,0,0,0
0,0,0,0,0,0,0,0,0,0,0,0,0,0,9,15,162,162,162,162,162,15,9,0,0,0,0,0,0,0,0,0,0,0,0,0,0,0,0,0,0,0,0
0,0,0,0,0,0,0,0,0,0,0,0,0,0,0,0,15,15,15,15,15,0,0,0,0,0,0,0,0,0,0,0,0,0,0,0,0,0,0,0,0,0,0
0,0,0,0,0,0,0,0,0,0,0,0,0,0,0,0,0,0,0,0,0,0,0,0,0,0,0,0,0,0,0,0,0,0,0,0,0,0,0,0,0,0,0
0,0,0,0,0,0,0,0,0,0,0,0,0,0,0,0,0,0,0,0,0,0,0,0,0,0,0,0,0,0,0,0,0,0,0,0,0,0,0,0,0,0,0
0,0,0,0,0,0,0,0,0,0,0,0,0,0,0,0,0,0,0,0,0,0,0,0,0,0,0,0,0,0,0,0,0,0,0,0,0,0,0,0,0,0,0
0,0,0,0,0,0,0,0,0,0,0,0,0,0,0,0,0,0,0,0,0,0,0,0,0,0,0,0,0,0,0,0,0,0,0,0,0,0,0,0,0,0,0
:endlayer
layer: 19
0,0,0,0,0,0,0,0,0,0,0,0,0,0,0,0,0,0,0,0,0,0,0,0,0,0,0,0,0,0,0,0,0,0,0,0,0,0,0,0,0,0,0
0,0,0,0,0,0,0,0,0,0,0,0,0,0,0,0,0,0,0,0,0,0,0,0,0,0,0,0,0,0,0,0,0,0,0,0,0,0,0,0,0,0,0
0,0,0,0,0,0,0,0,0,0,0,0,0,0,0,0,0,0,0,0,0,0,0,0,0,0,0,0,0,0,0,0,0,0,0,0,0,0,0,0,0,0,0
0,0,0,0,0,0,0,0,0,0,0,0,0,0,0,0,0,0,0,0,0,0,0,0,0,0,0,0,0,0,0,0,0,0,0,0,0,0,0,0,0,0,0
0,0,0,15,15,0,15,15,0,15,15,0,15,15,15,15,15,15,15,0,0,0,0,0,0,0,0,0,0,0,0,0,15,15,15,15,15,15,15,0,0,0,0
0,0,0,15,0,0,0,0,0,0,0,0,15,15,15,15,15,15,15,0,0,0,0,0,0,0,0,0,0,0,0,0,15,15,15,15,15,15,15,0,0,0,0
0,0,0,0,0,0,0,0,0,0,0,16,15,15,0,0,0,15,15,15,15,15,15,15,15,15,15,15,15,15,15,15,15,15,15,15,15,15,15,0,0,0,0
0,0,0,15,0,0,0,0,0,0,0,15,15,15,27,15,16,15,15,15,15,15,15,15,15,15,15,15,15,15,15,15,15,15,15,15,15,15,15,0,0,0,0
0,0,0,15,0,0,0,0,0,0,0,37,15,15,0,0,71,15,15,15,15,15,15,15,15,15,15,15,15,15,15,15,15,15,15,15,15,15,15,0,0,0,0
0,0,0,0,0,0,0,0,0,0,0,0,15,15,15,15,15,15,15,15,15,15,15,15,15,15,15,15,15,15,15,15,15,15,15,15,15,15,15,0,0,0,0
0,0,0,15,0,0,0,0,0,0,0,0,15,15,15,15,15,15,15,15,15,15,15,15,15,15,15,15,15,15,15,15,15,15,15,15,15,15,15,0,0,0,0
0,0,0,15,0,0,0,0,0,0,0,0,0,0,15,15,15,15,15,15,15,15,15,15,15,15,15,15,15,15,15,15,15,15,15,15,15,0,0,0,0,0,0
0,0,0,0,0,0,0,0,0,0,0,0,0,0,15,15,15,15,15,15,15,15,15,15,15,15,15,15,15,15,15,15,15,15,15,15,15,0,0,0,0,0,0
0,0,0,15,0,0,0,0,0,0,0,0,0,0,15,15,15,15,15,15,15,15,15,15,15,15,15,15,15,15,15,15,15,15,15,15,15,0,0,0,0,0,0
0,0,0,15,15,0,15,15,0,15,15,0,15,15,15,15,15,15,15,15,15,15,15,15,15,15,15,15,15,15,15,15,15,15,15,15,15,0,0,0,0,0,0
0,0,0,0,0,0,0,0,0,0,0,0,0,0,15,15,15,15,15,15,15,15,15,15,15,15,15,15,15,15,15,15,15,15,15,15,15,0,0,0,0,0,0
0,0,0,0,0,0,0,0,0,0,0,0,0,0,15,15,15,15,15,15,15,15,15,15,15,15,15,15,15,15,15,15,15,15,15,15,15,0,0,0,0,0,0
0,0,0,0,0,0,0,0,0,0,0,0,0,0,15,15,15,15,15,15,15,15,15,15,15,15,15,15,15,15,15,15,15,15,15,15,15,0,0,0,0,0,0
0,0,0,0,0,0,0,0,0,0,0,0,0,0,15,15,15,15,15,15,15,15,15,15,15,15,15,15,15,15,15,15,15,15,15,15,15,0,0,0,0,0,0
0,0,0,0,0,0,0,0,0,0,0,0,0,0,15,15,15,15,15,15,15,15,15,15,15,15,15,15,15,15,15,15,15,15,15,15,15,0,0,0,0,0,0
0,0,0,0,0,0,0,0,0,0,0,0,0,0,15,15,15,15,15,15,15,15,15,15,15,15,15,15,15,15,15,15,15,15,15,15,15,0,0,0,0,0,0
0,0,0,0,0,0,0,0,0,0,0,0,0,0,15,15,15,15,15,15,15,15,15,15,15,15,15,15,15,15,15,15,15,15,15,15,15,0,0,0,0,0,0
0,0,0,0,0,0,0,0,0,0,0,0,0,0,15,15,15,15,15,15,15,15,15,15,15,15,15,15,15,15,15,15,15,15,15,15,15,0,0,0,0,0,0
0,0,0,0,0,0,0,0,0,0,0,0,0,0,15,15,15,15,15,15,15,15,15,15,15,15,15,15,15,15,15,15,15,15,15,15,15,0,0,0,0,0,0
0,0,0,0,0,0,0,0,0,0,0,0,0,15,15,15,15,15,15,15,15,15,15,15,15,15,15,15,15,15,15,15,15,15,15,15,15,15,15,0,0,0,0
0,0,0,0,0,0,0,0,0,0,0,0,0,15,15,15,15,15,15,15,15,15,15,15,15,15,15,15,15,15,15,15,15,15,15,15,15,15,15,0,0,0,0
0,0,0,0,0,0,0,0,0,0,0,0,15,15,15,15,15,15,15,15,15,15,15,15,15,15,15,15,15,15,15,15,15,15,103,72,0,15,15,0,0,0,0
0,0,0,0,0,0,0,0,0,0,0,0,15,15,15,15,15,15,15,15,15,15,15,15,15,15,15,15,15,15,15,15,15,15,37,15,19,15,15,0,0,0,0
0,0,0,0,0,0,0,0,0,0,0,27,15,15,15,15,15,15,15,15,15,15,15,15,15,15,15,15,15,15,15,15,15,15,0,0,0,15,15,0,0,0,0
0,0,0,0,0,0,0,0,0,0,0,0,15,15,15,15,15,15,15,15,15,15,15,15,15,0,0,0,0,0,0,0,15,15,15,15,15,15,15,0,0,0,0
0,0,0,0,0,0,0,0,0,0,0,0,15,15,15,15,15,15,15,15,15,15,15,15,15,0,0,0,0,0,0,0,15,15,15,15,15,15,15,0,0,0,0
0,0,0,0,0,0,0,0,0,0,0,0,0,15,15,15,15,15,15,15,15,15,15,15,0,0,0,0,0,0,0,0,0,0,0,0,0,0,0,0,0,0,0
0,0,0,0,0,0,0,0,0,0,0,0,0,15,15,15,15,15,15,15,15,15,15,15,0,0,0,0,0,0,0,0,0,0,0,0,0,0,0,0,0,0,0
0,0,0,0,0,0,0,0,0,0,0,0,0,0,15,15,15,15,15,15,15,15,15,0,0,0,0,0,0,0,0,0,0,0,0,0,0,0,0,0,0,0,0
0,0,0,0,0,0,0,0,0,0,0,0,0,0,0,0,15,15,15,15,15,0,0,0,0,0,0,0,0,0,0,0,0,0,0,0,0,0,0,0,0,0,0
0,0,0,0,0,0,0,0,0,0,0,0,0,0,0,0,0,0,0,0,0,0,0,0,0,0,0,0,0,0,0,0,0,0,0,0,0,0,0,0,0,0,0
0,0,0,0,0,0,0,0,0,0,0,0,0,0,0,0,0,0,0,0,0,0,0,0,0,0,0,0,0,0,0,0,0,0,0,0,0,0,0,0,0,0,0
0,0,0,0,0,0,0,0,0,0,0,0,0,0,0,0,0,0,0,0,0,0,0,0,0,0,0,0,0,0,0,0,0,0,0,0,0,0,0,0,0,0,0
0,0,0,0,0,0,0,0,0,0,0,0,0,0,0,0,0,0,0,0,0,0,0,0,0,0,0,0,0,0,0,0,0,0,0,0,0,0,0,0,0,0,0
:endlayer
layer: 20
0,0,0,0,0,0,0,0,0,0,0,0,0,0,0,0,0,0,0,0,0,0,0,0,0,0,0,0,0,0,0,0,0,0,0,0,0,0,0,0,0,0,0
0,0,0,0,0,0,0,0,0,0,0,0,0,0,0,0,0,0,0,0,0,0,0,0,0,0,0,0,0,0,0,0,0,0,0,0,0,0,0,0,0,0,0
0,0,0,0,0,0,0,0,0,0,0,0,0,0,0,0,0,0,0,0,0,0,0,0,0,0,0,0,0,0,0,0,0,0,0,0,0,0,0,0,0,0,0
0,0,0,0,0,0,0,0,0,0,0,0,0,0,0,0,0,0,0,0,0,0,0,0,0,0,0,0,0,0,0,0,0,0,0,0,0,0,0,0,0,0,0
0,0,0,175,40,0,0,0,0,0,175,0,15,15,15,15,15,15,15,0,0,0,0,0,0,0,0,0,0,0,0,0,15,15,15,15,15,15,15,0,0,0,0
0,0,0,40,0,0,0,0,0,0,0,0,15,0,0,0,0,0,15,0,0,0,0,0,0,0,0,0,0,0,0,0,15,15,15,183,184,186,15,0,0,0,0
0,0,0,0,0,0,0,0,0,0,0,0,15,0,0,0,0,0,15,15,15,15,15,15,15,15,15,15,15,15,15,15,15,15,0,0,0,0,15,0,0,0,0
0,0,0,0,0,0,0,0,0,0,0,0,69,0,103,15,0,0,14,0,0,0,0,0,0,0,0,0,0,0,0,0,15,182,0,0,0,0,15,0,0,0,0
0,0,0,0,0,0,0,0,0,0,0,0,15,0,102,31,0,0,15,0,177,177,177,177,177,177,178,178,178,178,178,0,15,181,0,0,0,0,15,0,0,0,0
0,0,0,0,0,0,0,0,0,0,0,0,15,0,0,0,0,0,15,0,177,177,177,177,177,178,177,177,177,177,177,0,15,180,0,0,0,185,15,0,0,0,0
0,0,0,0,0,0,0,0,0,0,0,0,15,15,15,15,15,15,15,0,178,178,178,178,178,177,177,177,177,177,177,0,15,15,15,15,15,15,15,0,0,0,0
0,0,0,0,0,0,0,0,0,0,0,0,0,0,15,0,0,0,0,0,0,0,0,0,0,0,0,0,0,0,0,0,0,0,0,0,15,0,0,0,0,0,0
0,0,0,0,0,0,0,0,0,0,0,0,0,0,15,0,177,177,177,177,177,177,177,0,0,0,0,0,0,0,0,0,0,0,0,0,15,0,0,0,0,0,0
0,0,0,40,0,0,0,0,0,0,0,0,0,0,15,0,177,178,177,178,177,178,177,0,178,178,178,178,178,178,178,178,178,0,16,16,15,0,0,0,0,0,0
0,0,0,175,40,0,0,0,0,0,0,0,175,0,15,0,177,177,178,177,178,177,177,0,178,15,150,150,15,150,150,15,178,0,69,15,15,0,0,0,0,0,0
0,0,0,0,0,0,0,0,0,0,0,0,0,0,15,0,177,178,177,178,177,178,177,0,178,177,177,177,177,177,177,177,178,0,69,35,15,0,0,0,0,0,0
0,0,0,0,0,0,0,0,0,0,0,0,0,0,15,0,177,177,178,177,178,177,177,0,178,177,110,110,177,110,110,177,178,0,69,35,15,0,0,0,0,0,0
0,0,0,0,0,0,0,0,0,0,0,0,0,0,15,0,177,178,177,178,177,178,177,0,178,177,177,177,177,177,177,177,178,0,69,35,15,0,0,0,0,0,0
0,0,0,0,0,0,0,0,0,0,0,0,0,0,15,0,177,177,178,177,178,177,177,0,178,15,179,179,15,179,179,15,178,0,69,15,15,0,0,0,0,0,0
0,0,0,0,0,0,0,0,0,0,0,0,0,0,15,0,177,178,177,178,177,178,177,0,178,178,178,178,178,178,178,178,178,0,37,37,15,0,0,0,0,0,0
0,0,0,0,0,0,0,0,0,0,0,0,0,0,15,0,177,177,177,177,177,177,177,0,0,0,0,0,0,0,0,0,0,0,0,0,15,0,0,0,0,0,0
0,0,0,0,0,0,0,0,0,0,0,0,0,0,15,0,0,0,0,0,0,0,0,0,0,0,0,0,0,0,0,0,0,0,0,0,15,0,0,0,0,0,0
0,0,0,0,0,0,0,0,0,0,0,0,0,0,15,15,15,15,0,15,15,0,0,0,0,0,15,16,16,16,15,0,0,0,0,0,15,0,0,0,0,0,0
0,0,0,0,0,0,0,0,0,0,0,0,0,0,15,15,0,0,0,0,0,15,15,0,0,0,69,56,56,56,31,0,0,0,0,0,15,0,0,0,0,0,0
0,0,0,0,0,0,0,0,0,0,0,0,0,15,0,0,0,0,0,0,0,0,0,15,15,0,69,56,56,56,31,0,15,15,15,15,15,15,15,0,0,0,0
0,0,0,0,0,0,0,0,0,0,0,0,0,15,0,0,69,16,16,16,31,0,0,15,15,0,69,56,56,56,31,0,15,0,0,0,0,0,15,0,0,0,0
0,0,0,0,0,0,0,0,0,0,0,0,15,0,0,16,15,37,37,37,15,16,0,0,15,0,69,56,56,56,31,0,15,0,0,69,72,0,15,0,0,0,0
0,0,0,0,0,0,0,0,0,0,0,0,15,0,0,69,33,33,33,33,33,31,0,0,15,0,15,56,56,56,15,0,15,0,0,15,71,0,15,0,0,0,0
0,0,0,0,0,0,0,0,0,0,0,0,69,0,0,69,33,33,33,33,33,31,0,0,15,15,15,15,15,15,15,15,15,0,0,0,0,0,15,0,0,0,0
0,0,0,0,0,0,0,0,0,0,0,0,15,0,0,69,33,33,33,33,33,31,0,0,15,0,0,0,0,0,0,0,15,0,0,0,0,0,15,0,0,0,0
0,0,0,0,0,0,0,0,0,0,0,0,15,0,0,37,15,33,33,33,15,37,0,0,15,0,0,0,0,0,0,0,15,15,15,15,15,15,15,0,0,0,0
0,0,0,0,0,0,0,0,0,0,0,0,0,15,0,0,69,37,37,37,31,0,0,15,0,0,0,0,0,0,0,0,0,0,0,0,0,0,0,0,0,0,0
0,0,0,0,0,0,0,0,0,0,0,0,0,15,0,0,0,0,0,0,0,0,0,15,0,0,0,0,0,0,0,0,0,0,0,0,0,0,0,0,0,0,0
0,0,0,0,0,0,0,0,0,0,0,0,0,0,15,15,0,0,0,0,0,15,15,0,0,0,0,0,0,0,0,0,0,0,0,0,0,0,0,0,0,0,0
0,0,0,0,0,0,0,0,0,0,0,0,0,0,0,0,15,15,37,15,15,0,0,0,0,0,0,0,0,0,0,0,0,0,0,0,0,0,0,0,0,0,0
0,0,0,0,0,0,0,0,0,0,0,0,0,0,0,0,0,0,0,0,0,0,0,0,0,0,0,0,0,0,0,0,0,0,0,0,0,0,0,0,0,0,0
0,0,0,0,0,0,0,0,0,0,0,0,0,0,0,0,0,0,0,0,0,0,0,0,0,0,0,0,0,0,0,0,0,0,0,0,0,0,0,0,0,0,0
0,0,0,0,0,0,0,0,0,0,0,0,0,0,0,0,0,0,0,0,0,0,0,0,0,0,0,0,0,0,0,0,0,0,0,0,0,0,0,0,0,0,0
0,0,0,0,0,0,0,0,0,0,0,0,0,0,0,0,0,0,0,0,0,0,0,0,0,0,0,0,0,0,0,0,0,0,0,0,0,0,0,0,0,0,0
:endlayer
layer: 21
0,0,0,0,0,0,0,0,0,0,0,0,0,0,0,0,0,0,0,0,0,0,0,0,0,0,0,0,0,0,0,0,0,0,0,0,0,0,0,0,0,0,0
0,0,0,0,0,0,0,0,0,0,0,0,0,0,0,0,0,0,0,0,0,0,0,0,0,0,0,0,0,0,0,0,0,0,0,0,0,0,0,0,0,0,0
0,0,0,0,0,0,0,0,0,0,0,0,0,0,0,0,0,0,0,0,0,0,0,0,0,0,0,0,0,0,0,0,0,0,0,0,0,0,0,0,0,0,0
0,0,0,0,0,0,0,0,0,0,0,0,0,0,0,0,0,0,0,0,0,0,0,0,0,0,0,0,0,0,0,0,0,0,0,0,0,0,0,0,0,0,0
0,0,0,0,0,0,0,0,0,0,0,0,15,15,15,15,15,15,15,0,0,0,0,0,0,0,0,0,0,0,0,0,15,15,15,15,15,15,15,0,0,0,0
0,0,0,0,0,0,0,0,0,0,0,0,15,0,0,0,0,0,15,0,103,0,103,0,103,0,103,0,103,0,103,0,15,175,0,0,0,27,15,0,0,0,0
0,0,0,0,0,0,0,0,0,0,0,0,15,0,103,72,0,0,15,15,15,15,15,15,15,15,15,15,15,15,15,15,15,0,0,0,0,0,15,0,0,0,0
0,0,0,0,0,0,0,0,0,0,0,0,9,0,37,15,19,0,187,0,0,0,24,0,0,24,0,0,24,0,0,0,15,0,0,0,0,0,15,0,0,0,0
0,0,0,0,0,0,0,0,0,0,0,0,15,0,0,0,0,0,15,19,0,0,0,0,0,0,0,0,0,0,0,0,15,0,0,0,0,0,15,0,0,0,0
0,0,0,0,0,0,0,0,0,0,0,0,15,0,0,0,0,0,15,0,0,0,0,0,0,0,0,0,0,0,0,0,15,19,0,0,0,185,15,0,0,0,0
0,0,0,0,0,0,0,0,0,0,0,0,15,15,15,15,15,15,15,0,0,0,0,0,0,0,0,0,0,0,0,0,15,15,15,15,15,15,15,0,0,0,0
0,0,0,0,0,0,0,0,0,0,0,0,0,0,15,0,0,0,0,0,0,0,0,0,0,0,0,0,0,0,0,0,0,0,0,0,15,0,0,0,0,0,0
0,0,0,0,0,0,0,0,0,0,0,0,0,102,15,19,0,0,0,0,0,0,0,0,0,0,0,0,0,0,0,0,0,0,0,0,15,72,0,0,0,0,0
0,0,0,0,0,0,0,0,0,0,0,0,0,0,15,0,0,0,0,0,0,0,0,0,0,0,0,0,0,0,0,0,0,0,0,0,15,0,0,0,0,0,0
0,0,0,0,0,0,0,0,0,0,0,0,0,102,15,19,0,0,0,0,0,0,0,0,0,175,0,0,175,0,0,175,0,0,0,15,15,72,0,0,0,0,0
0,0,0,0,0,0,0,0,0,0,0,0,0,0,15,0,0,0,0,0,0,0,0,0,0,0,0,0,0,0,0,0,0,0,0,63,15,0,0,0,0,0,0
0,0,0,0,0,0,0,0,0,0,0,0,0,102,15,19,0,0,0,0,0,0,0,0,0,0,0,0,0,0,0,0,0,0,0,63,15,72,0,0,0,0,0
0,0,0,0,0,0,0,0,0,0,0,0,0,0,15,0,0,0,0,0,0,0,0,0,0,0,0,0,0,0,0,0,0,0,0,63,15,0,0,0,0,0,0
0,0,0,0,0,0,0,0,0,0,0,0,0,102,15,19,0,0,0,0,0,0,0,0,0,175,0,0,175,0,0,175,0,0,0,15,15,72,0,0,0,0,0
0,0,0,0,0,0,0,0,0,0,0,0,0,0,15,0,0,0,0,0,0,0,0,0,0,0,0,0,0,0,0,0,0,0,0,0,15,0,0,0,0,0,0
0,0,0,0,0,0,0,0,0,0,0,0,0,102,15,19,0,0,0,0,0,0,0,0,0,0,0,0,0,0,0,0,0,0,0,0,15,72,0,0,0,0,0
0,0,0,0,0,0,0,0,0,0,0,0,0,0,15,0,0,23,0,23,0,0,0,0,0,0,0,0,0,0,0,0,0,0,0,0,15,0,0,0,0,0,0
0,0,0,0,0,0,0,0,0,0,0,0,0,102,15,15,15,15,0,15,15,19,0,0,0,0,61,0,0,0,61,0,0,0,0,0,15,72,0,0,0,0,0
0,0,0,0,0,0,0,0,0,0,0,0,0,0,15,15,19,0,0,0,27,15,15,0,0,0,0,177,177,177,0,0,0,0,0,0,15,0,0,0,0,0,0
0,0,0,0,0,0,0,0,0,0,0,0,0,15,0,0,0,0,0,0,0,0,0,15,15,0,0,177,177,177,0,0,15,15,15,15,15,15,15,0,0,0,0
0,0,0,0,0,0,0,0,0,0,0,0,0,15,0,0,0,0,0,0,0,0,0,15,15,0,0,177,177,177,0,0,15,0,0,0,0,0,15,0,0,0,0
0,0,0,0,0,0,0,0,0,0,0,0,15,24,0,0,61,0,0,0,61,0,0,24,15,19,0,0,0,0,0,27,15,0,0,0,0,0,15,0,0,0,0
0,0,0,0,0,0,0,0,0,0,0,0,15,0,0,0,0,0,0,0,0,0,0,0,15,0,61,188,188,188,61,0,15,0,27,15,16,0,15,0,0,0,0
0,0,0,0,0,0,0,0,0,0,0,0,9,0,0,0,0,0,0,0,0,0,0,0,15,15,15,15,15,15,15,15,15,0,0,102,71,0,15,0,0,0,0
0,0,0,0,0,0,0,0,0,0,0,0,15,0,0,0,0,0,0,0,0,0,0,0,15,0,71,0,71,0,71,0,15,0,0,0,0,0,15,0,0,0,0
0,0,0,0,0,0,0,0,0,0,0,0,15,23,0,0,61,0,0,0,61,0,0,23,15,0,0,0,0,0,0,0,15,15,15,15,15,15,15,0,0,0,0
0,0,0,0,0,0,0,0,0,0,0,0,0,15,0,0,0,0,0,0,0,0,0,15,0,0,0,0,0,0,0,0,0,0,0,0,0,0,0,0,0,0,0
0,0,0,0,0,0,0,0,0,0,0,0,0,15,0,0,0,0,0,0,0,0,0,15,0,0,0,0,0,0,0,0,0,0,0,0,0,0,0,0,0,0,0
0,0,0,0,0,0,0,0,0,0,0,0,0,0,15,15,19,0,0,0,27,15,15,0,0,0,0,0,0,0,0,0,0,0,0,0,0,0,0,0,0,0,0
0,0,0,0,0,0,0,0,0,0,0,0,0,0,0,0,15,15,9,15,15,0,0,0,0,0,0,0,0,0,0,0,0,0,0,0,0,0,0,0,0,0,0
0,0,0,0,0,0,0,0,0,0,0,0,0,0,0,0,0,0,0,0,0,0,0,0,0,0,0,0,0,0,0,0,0,0,0,0,0,0,0,0,0,0,0
0,0,0,0,0,0,0,0,0,0,0,0,0,0,0,0,0,0,0,0,0,0,0,0,0,0,0,0,0,0,0,0,0,0,0,0,0,0,0,0,0,0,0
0,0,0,0,0,0,0,0,0,0,0,0,0,0,0,0,0,0,0,0,0,0,0,0,0,0,0,0,0,0,0,0,0,0,0,0,0,0,0,0,0,0,0
0,0,0,0,0,0,0,0,0,0,0,0,0,0,0,0,0,0,0,0,0,0,0,0,0,0,0,0,0,0,0,0,0,0,0,0,0,0,0,0,0,0,0
:endlayer
layer: 22
0,0,0,0,0,0,0,0,0,0,0,0,0,0,0,0,0,0,0,0,0,0,0,0,0,0,0,0,0,0,0,0,0,0,0,0,0,0,0,0,0,0,0
0,0,0,0,0,0,0,0,0,0,0,0,0,0,0,0,0,0,0,0,0,0,0,0,0,0,0,0,0,0,0,0,0,0,0,0,0,0,0,0,0,0,0
0,0,0,0,0,0,0,0,0,0,0,0,0,0,0,0,0,0,0,0,0,0,0,0,0,0,0,0,0,0,0,0,0,0,0,0,0,0,0,0,0,0,0
0,0,0,0,0,0,0,0,0,0,0,0,0,0,0,0,0,0,0,0,0,0,0,0,0,0,0,0,0,0,0,0,0,0,0,0,0,0,0,0,0,0,0
0,0,0,0,0,0,0,0,0,0,0,0,15,15,15,15,15,15,15,0,0,0,0,0,0,0,0,0,0,0,0,0,15,15,15,15,15,15,15,0,0,0,0
0,0,0,0,0,0,0,0,0,0,0,0,15,0,0,0,0,0,15,15,16,15,16,15,16,15,16,15,16,15,16,15,15,0,0,0,0,0,15,0,0,0,0
0,0,0,0,0,0,0,0,0,0,0,0,15,0,0,69,72,0,15,15,15,15,15,15,15,15,15,15,15,15,15,15,15,0,0,0,0,0,15,0,0,0,0
0,0,0,0,0,0,0,0,0,0,0,0,9,0,0,15,71,189,15,190,0,0,0,0,0,0,0,0,0,0,0,0,15,0,0,0,0,0,15,0,0,0,0
0,0,0,0,0,0,0,0,0,0,0,0,15,0,0,0,0,0,15,0,0,0,0,0,0,0,0,0,0,0,0,0,15,0,0,0,0,0,15,0,0,0,0
0,0,0,0,0,0,0,0,0,0,0,0,15,0,0,0,0,0,15,0,0,0,0,0,0,0,0,0,0,0,0,0,15,0,0,0,0,185,15,0,0,0,0
0,0,0,0,0,0,0,0,0,0,0,0,15,15,15,15,15,15,15,0,0,0,0,0,0,0,0,0,0,0,0,0,15,15,15,15,15,15,15,0,0,0,0
0,0,0,0,0,0,0,0,0,0,0,0,0,15,15,0,0,0,0,0,0,0,0,0,0,0,0,0,0,0,0,0,0,0,0,0,15,15,0,0,0,0,0
0,0,0,0,0,0,0,0,0,0,0,0,0,69,15,0,0,0,0,0,0,0,0,0,0,0,0,0,0,0,0,0,0,0,0,0,15,31,0,0,0,0,0
0,0,0,0,0,0,0,0,0,0,0,0,0,15,15,0,0,0,0,0,0,0,0,0,0,0,0,0,0,0,0,0,0,0,0,0,15,15,0,0,0,0,0
0,0,0,0,0,0,0,0,0,0,0,0,0,69,15,0,0,0,0,0,0,0,0,0,0,0,0,0,0,0,0,0,0,0,69,15,15,31,0,0,0,0,0
0,0,0,0,0,0,0,0,0,0,0,0,0,15,15,0,0,0,0,0,0,0,0,0,0,0,0,0,0,0,0,0,0,0,69,0,15,15,0,0,0,0,0
0,0,0,0,0,0,0,0,0,0,0,0,0,69,15,0,0,0,0,0,0,0,0,0,0,0,0,0,0,0,0,0,0,0,69,0,15,31,0,0,0,0,0
0,0,0,0,0,0,0,0,0,0,0,0,0,15,15,0,0,0,0,0,0,0,0,0,0,0,0,0,0,0,0,0,0,0,69,0,15,15,0,0,0,0,0
0,0,0,0,0,0,0,0,0,0,0,0,0,69,15,0,0,0,0,0,0,0,0,0,0,0,0,0,0,0,0,0,0,0,69,15,15,31,0,0,0,0,0
0,0,0,0,0,0,0,0,0,0,0,0,0,15,15,0,0,0,0,0,0,0,0,0,0,0,0,0,0,0,0,0,0,0,0,0,15,15,0,0,0,0,0
0,0,0,0,0,0,0,0,0,0,0,0,0,69,15,0,0,0,0,0,0,0,0,0,0,0,0,0,0,0,0,0,0,0,0,0,15,31,0,0,0,0,0
0,0,0,0,0,0,0,0,0,0,0,0,0,15,15,0,0,0,0,0,0,0,0,0,0,0,0,0,0,0,0,0,0,0,0,0,15,15,0,0,0,0,0
0,0,0,0,0,0,0,0,0,0,0,0,0,69,15,15,15,15,15,15,15,0,0,0,0,0,61,0,0,0,61,0,0,0,0,0,15,31,0,0,0,0,0
0,0,0,0,0,0,0,0,0,0,0,0,0,15,15,15,0,0,0,0,0,15,15,0,0,0,0,0,0,0,0,0,0,0,0,0,15,15,0,0,0,0,0
0,0,0,0,0,0,0,0,0,0,0,0,0,15,0,0,0,0,0,0,0,0,0,15,15,0,0,0,0,0,0,0,15,15,15,15,15,15,15,0,0,0,0
0,0,0,0,0,0,0,0,0,0,0,0,0,15,0,0,0,0,0,0,0,0,0,15,15,0,0,0,0,0,0,0,15,0,0,0,0,0,15,0,0,0,0
0,0,0,0,0,0,0,0,0,0,0,0,15,0,0,0,15,103,0,103,15,0,0,0,15,0,0,0,0,0,0,0,15,0,0,0,0,0,15,0,0,0,0
0,0,0,0,0,0,0,0,0,0,0,0,15,0,0,0,102,72,0,102,72,0,0,0,15,102,15,72,23,102,15,72,15,0,103,15,0,0,15,0,0,0,0
0,0,0,0,0,0,0,0,0,0,0,0,9,0,0,0,102,72,0,102,72,0,0,0,15,15,15,15,15,15,15,15,15,0,102,31,0,0,15,0,0,0,0
0,0,0,0,0,0,0,0,0,0,0,0,15,0,0,0,102,103,103,103,72,0,0,0,15,15,37,15,37,15,37,15,15,0,0,0,0,0,15,0,0,0,0
0,0,0,0,0,0,0,0,0,0,0,0,15,0,0,0,15,71,71,71,15,0,0,0,15,0,0,0,0,0,0,0,15,15,15,15,15,15,15,0,0,0,0
0,0,0,0,0,0,0,0,0,0,0,0,0,15,0,0,0,0,0,0,0,0,0,15,0,0,0,0,0,0,0,0,0,0,0,0,0,0,0,0,0,0,0
0,0,0,0,0,0,0,0,0,0,0,0,0,15,0,0,0,0,0,0,0,0,0,15,0,0,0,0,0,0,0,0,0,0,0,0,0,0,0,0,0,0,0
0,0,0,0,0,0,0,0,0,0,0,0,0,0,15,15,0,0,0,0,0,15,15,0,0,0,0,0,0,0,0,0,0,0,0,0,0,0,0,0,0,0,0
0,0,0,0,0,0,0,0,0,0,0,0,0,0,0,0,15,15,9,15,15,0,0,0,0,0,0,0,0,0,0,0,0,0,0,0,0,0,0,0,0,0,0
0,0,0,0,0,0,0,0,0,0,0,0,0,0,0,0,0,0,0,0,0,0,0,0,0,0,0,0,0,0,0,0,0,0,0,0,0,0,0,0,0,0,0
0,0,0,0,0,0,0,0,0,0,0,0,0,0,0,0,0,0,0,0,0,0,0,0,0,0,0,0,0,0,0,0,0,0,0,0,0,0,0,0,0,0,0
0,0,0,0,0,0,0,0,0,0,0,0,0,0,0,0,0,0,0,0,0,0,0,0,0,0,0,0,0,0,0,0,0,0,0,0,0,0,0,0,0,0,0
0,0,0,0,0,0,0,0,0,0,0,0,0,0,0,0,0,0,0,0,0,0,0,0,0,0,0,0,0,0,0,0,0,0,0,0,0,0,0,0,0,0,0
:endlayer
layer: 23
0,0,0,0,0,0,0,0,0,0,0,0,0,0,0,0,0,0,0,0,0,0,0,0,0,0,0,0,0,0,0,0,0,0,0,0,0,0,0,0,0,0,0
0,0,0,0,0,0,0,0,0,0,0,0,0,0,0,0,0,0,0,0,0,0,0,0,0,0,0,0,0,0,0,0,0,0,0,0,0,0,0,0,0,0,0
0,0,0,0,0,0,0,0,0,0,0,0,0,0,0,0,0,0,0,0,0,0,0,0,0,0,0,0,0,0,0,0,0,0,0,0,0,0,0,0,0,0,0
0,0,0,0,0,0,0,0,0,0,0,0,0,0,0,0,0,0,0,0,0,0,0,0,0,0,0,0,0,0,0,0,0,0,0,0,0,0,0,0,0,0,0
0,0,0,0,0,0,0,0,0,0,0,0,15,15,15,15,15,15,15,0,0,0,0,0,0,0,0,0,0,0,0,0,15,15,15,15,15,15,15,0,0,0,0
0,0,0,0,0,0,0,0,0,0,0,0,15,110,110,110,110,110,15,15,161,15,161,15,161,15,161,15,161,15,161,15,15,110,110,110,110,110,15,0,0,0,0
0,0,0,0,0,0,0,0,0,0,0,0,15,110,0,0,0,110,15,15,15,15,15,15,15,15,15,15,15,15,15,15,15,110,110,110,110,110,15,0,0,0,0
0,0,0,0,0,0,0,0,0,0,0,0,15,110,27,110,179,110,15,15,15,15,15,15,15,15,15,15,15,15,15,15,15,110,110,110,110,110,15,0,0,0,0
0,0,0,0,0,0,0,0,0,0,0,0,15,110,0,110,110,110,15,15,15,15,15,15,15,15,15,15,15,15,15,15,15,110,110,110,110,110,15,0,0,0,0
0,0,0,0,0,0,0,0,0,0,0,0,15,110,110,110,110,110,15,15,15,15,15,15,15,15,15,15,15,15,15,15,15,110,110,110,110,185,15,0,0,0,0
0,0,0,0,0,0,0,0,0,0,0,0,15,15,15,15,15,15,15,15,15,15,15,15,15,15,15,15,15,15,15,15,15,15,15,15,15,15,15,0,0,0,0
0,0,0,0,0,0,0,0,0,0,0,0,0,15,15,15,15,15,15,15,15,15,15,15,15,15,15,15,15,15,15,15,15,15,15,15,15,15,0,0,0,0,0
0,0,0,0,0,0,0,0,0,0,0,0,0,161,15,15,15,15,15,15,15,15,15,15,15,15,15,15,15,15,15,15,15,15,15,15,15,161,0,0,0,0,0
0,0,0,0,0,0,0,0,0,0,0,0,0,15,15,15,15,15,15,15,15,15,15,15,15,15,15,15,15,15,15,15,15,15,15,15,15,15,0,0,0,0,0
0,0,0,0,0,0,0,0,0,0,0,0,0,161,15,15,15,15,192,192,192,192,192,192,192,192,192,192,192,192,192,192,192,15,15,15,15,161,0,0,0,0,0
0,0,0,0,0,0,0,0,0,0,0,0,0,15,15,15,15,15,71,71,71,71,71,71,71,71,71,71,71,71,71,71,71,15,15,15,15,15,0,0,0,0,0
0,0,0,0,0,0,0,0,0,0,0,0,0,161,15,15,15,15,72,0,0,0,0,0,0,0,0,0,0,0,0,0,102,15,15,15,15,161,0,0,0,0,0
0,0,0,0,0,0,0,0,0,0,0,0,0,15,15,15,15,15,103,103,103,103,103,103,103,103,103,103,103,103,103,103,103,15,15,15,15,15,0,0,0,0,0
0,0,0,0,0,0,0,0,0,0,0,0,0,161,15,15,15,15,191,191,191,191,191,191,191,191,191,191,191,191,191,191,191,15,15,15,15,161,0,0,0,0,0
0,0,0,0,0,0,0,0,0,0,0,0,0,15,15,15,15,15,15,15,15,15,15,15,15,15,15,15,15,15,15,15,15,15,15,15,15,15,0,0,0,0,0
0,0,0,0,0,0,0,0,0,0,0,0,0,161,15,15,15,15,15,15,15,15,15,15,15,15,15,15,15,15,15,15,15,15,15,15,15,161,0,0,0,0,0
0,0,0,0,0,0,0,0,0,0,0,0,0,15,15,15,15,15,15,15,15,15,15,15,15,15,15,15,15,15,15,15,15,15,15,15,15,15,0,0,0,0,0
0,0,0,0,0,0,0,0,0,0,0,0,0,161,15,15,15,15,15,15,15,15,15,15,15,15,15,15,15,15,15,15,15,15,15,15,15,161,0,0,0,0,0
0,0,0,0,0,0,0,0,0,0,0,0,0,15,15,15,110,110,110,110,110,15,15,15,15,15,15,15,15,15,15,15,15,15,15,15,15,15,0,0,0,0,0
0,0,0,0,0,0,0,0,0,0,0,0,0,15,110,110,110,110,110,110,110,110,110,15,15,15,15,15,15,15,15,15,15,15,15,15,15,15,15,0,0,0,0
0,0,0,0,0,0,0,0,0,0,0,0,0,15,110,110,110,110,110,110,110,110,110,15,15,15,15,15,15,15,15,15,15,110,110,110,110,110,15,0,0,0,0
0,0,0,0,0,0,0,0,0,0,0,0,15,110,110,110,110,110,110,110,110,110,110,110,15,15,15,15,15,15,15,15,15,110,110,110,0,110,15,0,0,0,0
0,0,0,0,0,0,0,0,0,0,0,0,15,110,110,110,110,110,110,110,110,110,110,110,15,15,15,15,15,15,15,15,15,110,150,110,19,110,15,0,0,0,0
0,0,0,0,0,0,0,0,0,0,0,0,15,110,110,110,110,110,110,110,110,110,110,110,15,15,15,15,15,15,15,15,15,110,0,0,0,110,15,0,0,0,0
0,0,0,0,0,0,0,0,0,0,0,0,15,110,110,110,110,110,110,110,110,110,110,110,15,15,161,15,161,15,161,15,15,110,110,110,110,110,15,0,0,0,0
0,0,0,0,0,0,0,0,0,0,0,0,15,110,110,110,110,110,110,110,110,110,110,110,15,0,0,0,0,0,0,0,15,15,15,15,15,15,15,0,0,0,0
0,0,0,0,0,0,0,0,0,0,0,0,0,15,110,110,110,110,110,110,110,110,110,15,0,0,0,0,0,0,0,0,0,0,0,0,0,0,0,0,0,0,0
0,0,0,0,0,0,0,0,0,0,0,0,0,15,110,110,110,110,110,110,110,110,110,15,0,0,0,0,0,0,0,0,0,0,0,0,0,0,0,0,0,0,0
0,0,0,0,0,0,0,0,0,0,0,0,0,0,15,15,110,110,110,110,110,15,15,0,0,0,0,0,0,0,0,0,0,0,0,0,0,0,0,0,0,0,0
0,0,0,0,0,0,0,0,0,0,0,0,0,0,0,0,15,15,15,15,15,0,0,0,0,0,0,0,0,0,0,0,0,0,0,0,0,0,0,0,0,0,0
0,0,0,0,0,0,0,0,0,0,0,0,0,0,0,0,0,0,0,0,0,0,0,0,0,0,0,0,0,0,0,0,0,0,0,0,0,0,0,0,0,0,0
0,0,0,0,0,0,0,0,0,0,0,0,0,0,0,0,0,0,0,0,0,0,0,0,0,0,0,0,0,0,0,0,0,0,0,0,0,0,0,0,0,0,0
0,0,0,0,0,0,0,0,0,0,0,0,0,0,0,0,0,0,0,0,0,0,0,0,0,0,0,0,0,0,0,0,0,0,0,0,0,0,0,0,0,0,0
0,0,0,0,0,0,0,0,0,0,0,0,0,0,0,0,0,0,0,0,0,0,0,0,0,0,0,0,0,0,0,0,0,0,0,0,0,0,0,0,0,0,0
:endlayer
layer: 24
0,0,0,0,0,0,0,0,0,0,0,0,0,0,0,0,0,0,0,0,0,0,0,0,0,0,0,0,0,0,0,0,0,0,0,0,0,0,0,0,0,0,0
0,0,0,0,0,0,0,0,0,0,0,0,0,0,0,0,0,0,0,0,0,0,0,0,0,0,0,0,0,0,0,0,0,0,0,0,0,0,0,0,0,0,0
0,0,0,0,0,0,0,0,0,0,0,0,0,0,0,0,0,0,0,0,0,0,0,0,0,0,0,0,0,0,0,0,0,0,0,0,0,0,0,0,0,0,0
0,0,0,0,0,0,0,0,0,0,0,0,0,0,0,0,0,0,0,0,0,0,0,0,0,0,0,0,0,0,0,0,0,0,0,0,0,0,0,0,0,0,0
0,0,0,0,0,0,0,0,0,0,0,0,15,15,15,16,15,15,15,0,0,0,0,0,0,0,0,0,0,0,0,0,15,15,15,16,15,15,15,0,0,0,0
0,0,0,0,0,0,0,0,0,0,0,0,15,0,0,0,0,0,15,15,103,15,103,15,103,15,103,15,103,15,103,15,15,0,0,0,0,0,15,0,0,0,0
0,0,0,0,0,0,0,0,0,0,0,0,15,0,0,0,0,0,15,0,0,0,0,0,0,0,0,0,0,0,0,0,15,0,0,0,0,0,15,0,0,0,0
0,0,0,0,0,0,0,0,0,0,0,0,69,0,0,0,0,0,0,0,0,0,0,0,0,0,0,0,0,0,0,0,0,0,0,0,0,0,31,0,0,0,0
0,0,0,0,0,0,0,0,0,0,0,0,15,0,0,0,0,0,0,0,0,0,0,0,0,0,0,0,0,0,0,0,0,0,0,0,0,0,15,0,0,0,0
0,0,0,0,0,0,0,0,0,0,0,0,15,193,0,0,0,0,15,0,0,0,0,0,0,0,0,0,0,0,0,0,15,0,0,0,0,185,15,0,0,0,0
0,0,0,0,0,0,0,0,0,0,0,0,15,15,15,0,0,15,15,0,0,0,0,0,0,0,0,0,0,0,0,0,15,15,0,0,15,15,15,0,0,0,0
0,0,0,0,0,0,0,0,0,0,0,0,0,15,0,0,0,0,0,0,0,0,0,0,0,0,0,0,0,0,0,0,0,0,0,0,0,15,0,0,0,0,0
0,0,0,0,0,0,0,0,0,0,0,0,0,102,0,0,0,0,0,0,0,0,0,0,0,0,0,0,0,0,0,0,0,0,0,0,0,72,0,0,0,0,0
0,0,0,0,0,0,0,0,0,0,0,0,0,15,0,0,0,16,16,16,16,16,16,16,16,16,16,16,16,16,16,16,16,16,0,0,0,15,0,0,0,0,0
0,0,0,0,0,0,0,0,0,0,0,0,0,102,0,0,0,69,0,0,0,0,0,0,0,0,0,0,0,0,0,0,0,31,0,0,0,72,0,0,0,0,0
0,0,0,0,0,0,0,0,0,0,0,0,0,15,0,0,0,69,192,192,192,192,192,192,192,192,192,192,192,192,192,192,192,31,0,0,0,15,0,0,0,0,0
0,0,0,0,0,0,0,0,0,0,0,0,0,102,0,0,0,69,15,15,15,15,15,15,15,15,15,15,15,15,15,15,15,31,0,0,0,72,0,0,0,0,0
0,0,0,0,0,0,0,0,0,0,0,0,0,15,0,0,0,69,191,191,191,191,191,191,191,191,191,191,191,191,191,191,191,31,0,0,0,15,0,0,0,0,0
0,0,0,0,0,0,0,0,0,0,0,0,0,102,0,0,0,69,0,0,0,0,0,0,0,0,0,0,0,0,0,0,0,31,0,0,0,72,0,0,0,0,0
0,0,0,0,0,0,0,0,0,0,0,0,0,15,0,0,0,69,37,37,37,37,37,37,37,37,37,37,37,37,37,37,37,37,0,0,0,15,0,0,0,0,0
0,0,0,0,0,0,0,0,0,0,0,0,0,102,0,0,0,0,0,0,0,0,0,0,0,0,0,0,0,0,0,0,0,0,0,0,0,72,0,0,0,0,0
0,0,0,0,0,0,0,0,0,0,0,0,0,15,0,0,0,0,0,0,0,0,0,0,0,0,0,0,0,0,0,0,0,0,0,0,0,15,0,0,0,0,0
0,0,0,0,0,0,0,0,0,0,0,0,0,102,0,0,15,15,15,15,15,0,0,0,0,0,0,0,0,0,0,0,0,0,0,0,0,72,0,0,0,0,0
0,0,0,0,0,0,0,0,0,0,0,0,0,15,15,15,0,0,0,0,0,15,0,0,0,0,0,0,0,0,0,0,0,0,0,0,0,15,0,0,0,0,0
0,0,0,0,0,0,0,0,0,0,0,0,0,15,193,0,0,0,0,0,0,0,0,0,0,0,0,0,0,0,0,0,15,15,0,0,15,15,15,0,0,0,0
0,0,0,0,0,0,0,0,0,0,0,0,0,15,0,0,0,0,0,0,0,0,0,15,0,0,0,0,0,0,0,0,15,0,0,0,0,185,15,0,0,0,0
0,0,0,0,0,0,0,0,0,0,0,0,15,0,0,0,0,0,0,0,0,0,0,0,15,0,0,0,0,0,0,0,0,0,0,0,0,0,15,0,0,0,0
0,0,0,0,0,0,0,0,0,0,0,0,15,0,0,0,0,0,0,0,0,0,0,0,15,0,0,0,0,0,0,0,0,0,0,0,0,0,31,0,0,0,0
0,0,0,0,0,0,0,0,0,0,0,0,15,0,0,0,0,0,0,0,0,0,0,0,15,0,0,0,0,0,0,0,15,0,0,0,0,0,15,0,0,0,0
0,0,0,0,0,0,0,0,0,0,0,0,15,0,0,0,0,0,0,0,0,0,0,0,15,15,71,15,71,15,71,15,15,0,0,0,0,0,15,0,0,0,0
0,0,0,0,0,0,0,0,0,0,0,0,15,0,0,0,0,0,0,0,0,0,0,0,15,0,0,0,0,0,0,0,15,15,15,37,15,15,15,0,0,0,0
0,0,0,0,0,0,0,0,0,0,0,0,0,15,0,0,0,0,0,0,0,0,0,15,0,0,0,0,0,0,0,0,0,0,0,0,0,0,0,0,0,0,0
0,0,0,0,0,0,0,0,0,0,0,0,0,15,0,0,0,0,0,0,0,0,0,15,0,0,0,0,0,0,0,0,0,0,0,0,0,0,0,0,0,0,0
0,0,0,0,0,0,0,0,0,0,0,0,0,0,15,15,0,0,0,0,0,15,15,0,0,0,0,0,0,0,0,0,0,0,0,0,0,0,0,0,0,0,0
0,0,0,0,0,0,0,0,0,0,0,0,0,0,0,0,15,15,15,15,15,0,0,0,0,0,0,0,0,0,0,0,0,0,0,0,0,0,0,0,0,0,0
0,0,0,0,0,0,0,0,0,0,0,0,0,0,0,0,0,0,0,0,0,0,0,0,0,0,0,0,0,0,0,0,0,0,0,0,0,0,0,0,0,0,0
0,0,0,0,0,0,0,0,0,0,0,0,0,0,0,0,0,0,0,0,0,0,0,0,0,0,0,0,0,0,0,0,0,0,0,0,0,0,0,0,0,0,0
0,0,0,0,0,0,0,0,0,0,0,0,0,0,0,0,0,0,0,0,0,0,0,0,0,0,0,0,0,0,0,0,0,0,0,0,0,0,0,0,0,0,0
0,0,0,0,0,0,0,0,0,0,0,0,0,0,0,0,0,0,0,0,0,0,0,0,0,0,0,0,0,0,0,0,0,0,0,0,0,0,0,0,0,0,0
:endlayer
layer: 25
0,0,0,0,0,0,0,0,0,0,0,0,0,0,0,0,0,0,0,0,0,0,0,0,0,0,0,0,0,0,0,0,0,0,0,0,0,0,0,0,0,0,0
0,0,0,0,0,0,0,0,0,0,0,0,0,0,0,0,0,0,0,0,0,0,0,0,0,0,0,0,0,0,0,0,0,0,0,0,0,0,0,0,0,0,0
0,0,0,0,0,0,0,0,0,0,0,0,0,0,0,0,0,0,0,0,0,0,0,0,0,0,0,0,0,0,0,0,0,0,0,0,0,0,0,0,0,0,0
0,0,0,0,0,0,0,0,0,0,0,0,0,0,0,0,0,0,0,0,0,0,0,0,0,0,0,0,0,0,0,0,0,0,0,0,0,0,0,0,0,0,0
0,0,0,0,0,0,0,0,0,0,0,0,15,15,15,9,15,15,15,0,0,0,0,0,0,0,0,0,0,0,0,0,15,15,15,9,15,15,15,0,0,0,0
0,0,0,0,0,0,0,0,0,0,0,0,15,0,0,0,0,0,15,0,15,15,0,15,15,0,15,15,0,15,15,0,15,0,0,0,0,0,15,0,0,0,0
0,0,0,0,0,0,0,0,0,0,0,0,15,0,0,0,0,27,15,19,0,0,0,0,0,0,0,0,0,0,0,27,15,0,0,0,0,0,15,0,0,0,0
0,0,0,0,0,0,0,0,0,0,0,0,9,0,0,0,0,0,0,0,0,0,0,0,0,0,0,0,0,0,0,0,0,0,0,0,0,0,9,0,0,0,0
0,0,0,0,0,0,0,0,0,0,0,0,15,0,0,0,0,0,0,0,0,0,0,0,0,0,0,0,0,0,0,0,0,0,0,0,0,0,15,0,0,0,0
0,0,0,0,0,0,0,0,0,0,0,0,15,193,23,0,0,0,15,19,0,0,0,0,0,0,0,0,0,0,0,27,15,0,0,0,0,185,15,0,0,0,0
0,0,0,0,0,0,0,0,0,0,0,0,15,15,15,0,0,15,15,0,0,0,0,0,0,0,0,0,0,0,0,0,15,15,0,0,15,15,15,0,0,0,0
0,0,0,0,0,0,0,0,0,0,0,0,0,0,24,0,0,24,0,0,0,0,0,0,0,0,0,0,0,0,0,0,0,24,0,0,24,0,0,0,0,0,0
0,0,0,0,0,0,0,0,0,0,0,0,0,15,0,0,0,0,0,0,0,0,0,0,0,0,0,0,0,0,0,0,0,0,0,0,0,15,0,0,0,0,0
0,0,0,0,0,0,0,0,0,0,0,0,0,15,0,0,0,0,0,0,0,0,0,0,0,0,0,0,0,0,0,0,0,0,0,0,0,15,0,0,0,0,0
0,0,0,0,0,0,0,0,0,0,0,0,0,0,0,0,0,0,0,0,0,0,0,0,0,0,0,0,0,0,0,0,0,0,0,0,0,0,0,0,0,0,0
0,0,0,0,0,0,0,0,0,0,0,0,0,15,0,0,0,0,0,0,0,0,0,0,0,0,0,0,0,0,0,0,0,0,0,0,0,15,0,0,0,0,0
0,0,0,0,0,0,0,0,0,0,0,0,0,15,0,0,0,0,194,194,194,194,194,194,194,194,194,194,194,194,194,194,194,0,0,0,0,15,0,0,0,0,0
0,0,0,0,0,0,0,0,0,0,0,0,0,0,0,0,0,0,0,0,0,0,0,0,0,0,0,0,0,0,0,0,0,0,0,0,0,0,0,0,0,0,0
0,0,0,0,0,0,0,0,0,0,0,0,0,15,0,0,0,0,0,0,0,0,0,0,0,0,0,0,0,0,0,0,0,0,0,0,0,15,0,0,0,0,0
0,0,0,0,0,0,0,0,0,0,0,0,0,15,0,0,0,0,0,0,0,0,0,0,0,0,0,0,0,0,0,0,0,0,0,0,0,15,0,0,0,0,0
0,0,0,0,0,0,0,0,0,0,0,0,0,0,0,0,0,0,0,0,0,0,0,0,0,0,0,0,0,0,0,0,0,0,0,0,0,0,0,0,0,0,0
0,0,0,0,0,0,0,0,0,0,0,0,0,15,0,0,0,0,0,0,0,0,0,0,0,0,0,0,0,0,0,0,0,0,0,0,0,15,0,0,0,0,0
0,0,0,0,0,0,0,0,0,0,0,0,0,15,0,0,15,15,15,15,15,0,0,0,0,0,0,0,0,0,0,0,0,0,0,0,0,15,0,0,0,0,0
0,0,0,0,0,0,0,0,0,0,0,0,0,0,15,15,19,0,0,0,27,15,19,0,0,0,0,0,0,0,0,0,0,23,0,0,23,0,0,0,0,0,0
0,0,0,0,0,0,0,0,0,0,0,0,0,15,193,0,0,0,0,0,0,0,0,23,0,0,0,0,0,0,0,0,15,15,0,0,15,15,15,0,0,0,0
0,0,0,0,0,0,0,0,0,0,0,0,0,15,0,0,0,0,0,0,0,0,0,15,0,0,0,0,0,0,0,27,15,0,0,0,24,185,15,0,0,0,0
0,0,0,0,0,0,0,0,0,0,0,0,15,24,0,0,0,0,0,0,0,0,0,24,15,0,0,0,0,0,0,0,0,0,0,0,0,0,15,0,0,0,0
0,0,0,0,0,0,0,0,0,0,0,0,15,0,0,0,0,0,0,0,0,0,0,0,15,0,0,0,0,0,0,0,0,0,0,0,0,0,9,0,0,0,0
0,0,0,0,0,0,0,0,0,0,0,0,15,0,0,0,0,0,0,0,0,0,0,0,15,0,0,0,0,0,0,27,15,19,0,0,0,0,15,0,0,0,0
0,0,0,0,0,0,0,0,0,0,0,0,15,0,0,0,0,0,0,0,0,0,0,0,15,0,15,15,0,15,15,0,15,0,0,0,0,0,15,0,0,0,0
0,0,0,0,0,0,0,0,0,0,0,0,15,23,0,0,0,0,0,0,0,0,0,23,15,0,0,0,0,0,0,0,15,15,15,9,15,15,15,0,0,0,0
0,0,0,0,0,0,0,0,0,0,0,0,0,15,0,0,0,0,0,0,0,0,0,15,0,0,0,0,0,0,0,0,0,0,0,0,0,0,0,0,0,0,0
0,0,0,0,0,0,0,0,0,0,0,0,0,15,0,0,0,0,0,0,0,0,0,15,0,0,0,0,0,0,0,0,0,0,0,0,0,0,0,0,0,0,0
0,0,0,0,0,0,0,0,0,0,0,0,0,0,15,15,19,0,0,0,27,15,15,0,0,0,0,0,0,0,0,0,0,0,0,0,0,0,0,0,0,0,0
0,0,0,0,0,0,0,0,0,0,0,0,0,0,0,0,15,15,15,15,15,0,0,0,0,0,0,0,0,0,0,0,0,0,0,0,0,0,0,0,0,0,0
0,0,0,0,0,0,0,0,0,0,0,0,0,0,0,0,0,0,0,0,0,0,0,0,0,0,0,0,0,0,0,0,0,0,0,0,0,0,0,0,0,0,0
0,0,0,0,0,0,0,0,0,0,0,0,0,0,0,0,0,0,0,0,0,0,0,0,0,0,0,0,0,0,0,0,0,0,0,0,0,0,0,0,0,0,0
0,0,0,0,0,0,0,0,0,0,0,0,0,0,0,0,0,0,0,0,0,0,0,0,0,0,0,0,0,0,0,0,0,0,0,0,0,0,0,0,0,0,0
0,0,0,0,0,0,0,0,0,0,0,0,0,0,0,0,0,0,0,0,0,0,0,0,0,0,0,0,0,0,0,0,0,0,0,0,0,0,0,0,0,0,0
:endlayer
layer: 26
0,0,0,0,0,0,0,0,0,0,0,0,0,0,0,0,0,0,0,0,0,0,0,0,0,0,0,0,0,0,0,0,0,0,0,0,0,0,0,0,0,0,0
