# Ancient Warfare Structure Template File
# auto-generated structure file. created on: 4/14/2014 at: 15:42:35
# Lines beginning with # denote comments

header:
version=2.0
name=CivFarmBarnMOH
size=17,21,22
offset=4,2,17
:endheader

#### VALIDATION ####
validation:
type=ground
survival=false
worldGenEnabled=true
unique=false
preserveBlocks=false
selectionWeight=10
clusterValue=10
minDuplicateDistance=40
dimensionWhiteList=false
dimensionList=
biomeWhiteList=true
biomeList=highlands.meadow,bop.meadow,ebxl.meadow,field,orchard
leveling=3
fill=3
border=3
validTargetBlocks=clay,sand,lapis_ore,grass,lit_redstone_ore,stone,iron_ore,gravel,diamond_ore,stained_hardened_clay,dirt,coal_ore,gold_ore,redstone_ore
data:
:enddata
:endvalidation

#### LAYERS ####
layer: 0
1,1,1,1,1,1,1,1,1,1,1,1,1,1,1,1,1
1,1,1,1,1,1,1,1,1,1,1,1,1,1,1,1,1
1,1,1,1,1,1,1,1,1,1,1,1,1,1,1,1,1
1,1,1,1,1,1,1,1,1,1,1,1,1,1,1,1,1
1,1,1,1,1,1,1,1,1,1,1,1,1,1,1,1,1
1,1,1,1,1,1,1,1,1,1,1,1,1,1,1,1,1
1,1,1,1,1,1,1,1,1,1,1,1,1,1,1,1,1
1,1,1,1,1,1,1,1,1,1,1,1,1,1,1,1,1
1,1,1,1,1,1,1,1,1,1,1,1,1,1,1,1,1
1,1,1,1,1,1,1,1,1,1,1,1,1,1,1,1,1
1,1,1,1,1,1,1,1,1,1,1,1,1,1,1,1,1
1,1,1,1,1,1,1,1,1,1,1,1,1,1,1,1,1
1,1,1,1,1,1,1,1,1,1,1,1,1,1,1,1,1
1,1,1,1,1,1,1,1,1,1,1,1,1,1,1,1,1
1,1,1,1,1,1,1,1,1,1,1,1,1,1,1,1,1
1,1,1,1,1,1,1,1,1,1,1,1,1,1,1,1,1
1,1,1,1,1,1,1,1,1,1,1,1,1,1,1,1,1
1,1,1,1,1,1,1,1,1,1,1,1,1,1,1,1,1
1,1,1,1,1,1,1,1,1,1,1,1,1,1,1,1,1
1,1,1,1,1,1,1,1,1,1,1,1,1,1,1,1,1
1,1,1,1,1,1,1,1,1,1,1,1,1,1,1,1,1
1,1,1,1,1,1,1,1,1,1,1,1,1,1,1,1,1
:endlayer
layer: 1
2,2,2,2,2,2,2,2,2,2,2,2,2,2,2,2,2
2,2,2,2,2,2,2,2,2,2,2,2,2,2,2,2,2
2,2,2,2,2,2,2,2,2,2,2,2,2,2,2,2,2
2,2,2,2,2,2,2,2,2,2,2,2,2,2,2,2,2
2,2,2,2,4,4,4,4,4,4,4,4,4,2,2,2,2
2,2,2,2,4,4,4,4,4,4,4,4,4,2,2,2,2
2,2,2,2,5,6,6,6,6,6,6,6,5,2,2,2,2
2,2,3,3,6,3,3,3,3,6,6,6,6,3,3,2,2
2,2,3,3,6,3,3,3,3,3,6,6,6,3,3,2,2
2,2,3,3,6,3,3,3,3,3,3,3,6,3,3,2,2
2,2,3,3,6,3,3,3,3,3,3,3,6,3,3,2,2
2,2,3,3,6,3,3,3,3,3,3,3,6,3,3,2,2
2,2,3,3,6,3,3,3,3,3,3,3,6,3,3,2,2
2,2,3,3,6,3,3,3,3,3,3,3,6,3,3,2,2
2,2,3,3,6,3,3,3,3,3,3,3,6,3,3,2,2
2,2,3,3,6,3,3,3,3,3,3,3,6,3,3,2,2
2,2,2,2,5,6,6,6,6,6,6,6,5,2,2,2,2
2,2,2,2,1,2,4,4,4,2,1,1,1,2,2,2,2
2,2,2,2,2,4,4,4,2,2,2,2,2,2,2,2,2
2,2,2,2,4,2,4,4,2,4,2,2,2,2,2,2,2
2,2,2,2,2,2,4,4,4,2,2,2,2,2,2,2,2
2,2,2,2,2,2,4,4,2,2,2,2,2,2,2,2,2
:endlayer
layer: 2
0,0,0,0,0,7,7,0,0,0,0,0,0,0,0,0,0
0,0,7,8,8,8,8,8,8,8,8,8,8,7,0,7,0
0,0,0,7,7,7,7,0,0,0,0,7,0,0,7,7,0
0,0,7,7,7,7,7,0,0,0,0,0,7,0,0,0,0
0,0,0,0,0,0,0,0,0,0,0,0,0,7,7,7,7
0,0,0,0,0,0,0,0,0,0,0,0,0,7,0,0,0
0,8,8,10,5,11,13,15,11,11,11,11,5,10,8,8,0
0,8,0,0,11,0,0,0,0,16,17,17,11,0,0,8,0
7,8,0,0,11,0,0,0,8,8,17,17,11,0,0,8,0
0,8,0,0,11,0,0,0,0,0,0,0,11,0,0,8,0
7,8,0,0,11,0,0,0,8,8,8,8,11,0,0,8,0
0,8,0,0,5,0,0,0,0,0,0,18,5,0,0,8,7
0,8,0,0,11,0,0,0,8,8,8,8,11,0,0,8,7
0,8,0,0,11,0,0,0,0,0,0,3,11,0,0,8,0
0,8,0,0,11,0,0,0,8,8,8,8,11,0,0,8,0
0,8,0,0,11,0,0,0,0,0,0,19,11,0,0,8,0
0,8,8,9,5,6,12,14,6,6,6,6,5,9,8,8,0
0,7,0,7,3,0,0,0,0,0,3,18,18,0,0,0,0
7,0,7,7,0,0,0,0,0,0,7,7,7,7,0,7,0
7,7,7,0,0,0,0,0,0,0,0,7,7,7,7,0,0
0,7,7,0,7,0,0,0,0,0,0,7,7,7,7,0,0
0,7,7,0,0,0,0,0,0,0,0,0,7,7,0,7,0
:endlayer
layer: 3
0,0,0,0,0,0,0,0,0,0,0,0,0,0,0,0,0
0,0,0,0,0,0,0,0,0,0,0,0,0,0,0,0,0
0,0,0,0,0,0,0,0,0,0,0,0,0,0,0,0,0
0,0,0,0,0,0,0,0,0,0,0,0,0,0,0,0,0
0,0,0,0,0,0,0,0,0,0,0,0,0,0,0,0,0
0,0,0,0,0,22,0,0,22,0,0,0,0,0,0,0,0
0,8,0,0,5,17,24,26,17,17,17,17,5,0,0,8,0
0,0,0,0,17,0,0,0,0,0,16,17,17,0,0,0,0
0,0,0,0,17,0,0,0,8,0,17,17,17,0,0,0,0
0,0,0,0,20,0,0,0,0,0,0,0,20,0,0,0,0
0,0,0,0,17,0,0,0,8,0,8,0,17,0,0,0,0
0,0,0,0,5,0,0,0,0,0,0,0,5,0,0,0,0
0,0,0,0,17,0,0,0,8,0,8,0,17,0,0,0,0
0,0,0,0,20,0,0,0,0,0,0,0,20,0,0,0,0
0,0,0,0,17,0,0,0,8,0,8,0,17,0,0,0,0
0,0,0,0,17,0,0,0,0,0,0,0,17,0,0,0,0
0,8,0,0,5,17,23,25,17,20,20,17,5,0,0,8,0
0,0,0,0,0,21,0,0,21,0,0,3,18,0,0,0,0
0,0,0,0,0,0,0,0,0,0,0,0,0,0,0,0,0
0,0,0,0,0,0,0,0,0,0,0,0,0,0,0,0,0
0,0,0,0,0,0,0,0,0,0,0,0,0,0,0,0,0
0,0,0,0,0,0,0,0,0,0,0,0,0,0,0,0,0
:endlayer
layer: 4
0,0,0,0,0,0,0,0,0,0,0,0,0,0,0,0,0
0,0,0,0,0,0,0,0,0,0,0,0,0,0,0,0,0
0,0,0,0,0,0,0,0,0,0,0,0,0,0,0,0,0
0,0,0,0,0,0,0,0,0,0,0,0,0,0,0,0,0
0,0,0,0,0,0,0,0,0,0,0,0,0,0,0,0,0
0,0,0,0,22,0,0,0,0,0,0,0,22,0,0,0,0
0,20,16,27,5,17,17,17,17,17,17,17,5,28,0,8,0
0,20,16,0,17,21,0,0,0,0,0,0,17,0,0,0,0
0,20,16,0,17,0,0,0,8,29,17,30,17,0,0,0,0
0,20,16,0,17,0,0,0,0,0,0,29,17,0,0,0,0
0,20,16,0,17,0,0,0,8,0,8,0,17,0,0,0,0
0,20,16,0,5,28,0,0,0,0,0,0,5,0,0,0,0
0,20,16,0,17,0,0,0,8,0,8,0,17,0,0,0,0
0,20,16,0,17,0,0,0,0,0,0,0,17,0,0,0,0
0,20,16,0,17,0,0,0,8,0,8,0,17,0,0,0,0
0,20,16,0,17,28,0,0,0,0,0,29,17,0,0,0,0
0,20,16,27,5,17,17,17,17,17,17,17,5,28,0,8,0
0,0,0,0,21,0,0,0,0,0,0,3,21,0,0,0,0
0,0,0,0,0,0,0,0,0,0,0,0,0,0,0,0,0
0,0,0,0,0,0,0,0,0,0,0,0,0,0,0,0,0
0,0,0,0,0,0,0,0,0,0,0,0,0,0,0,0,0
0,0,0,0,0,0,0,0,0,0,0,0,0,0,0,0,0
:endlayer
layer: 5
0,0,0,0,0,0,0,0,0,0,0,0,0,0,0,0,0
0,0,0,0,0,0,0,0,0,0,0,0,0,0,0,0,0
0,0,0,0,0,0,0,0,0,0,0,0,0,0,0,0,0
0,0,0,0,0,0,0,0,0,0,0,0,0,0,0,0,0
0,0,0,0,0,0,0,0,0,0,0,0,0,0,0,0,0
0,0,0,16,0,0,0,0,0,0,0,0,0,31,0,0,0
0,0,0,16,5,5,5,5,5,5,5,5,5,31,20,20,0
0,0,0,16,5,17,17,17,17,0,0,0,5,31,20,20,0
0,0,0,16,5,17,17,17,17,17,17,0,5,31,20,20,0
0,0,0,16,5,17,17,17,17,17,17,30,5,31,20,20,0
0,0,0,16,5,17,17,17,17,17,17,17,5,31,20,20,0
0,0,0,16,5,17,17,17,17,17,17,17,5,31,20,20,0
0,0,0,16,5,17,17,17,17,17,17,17,5,31,20,20,0
0,0,0,16,5,17,17,17,17,17,17,17,5,31,20,20,0
0,0,0,16,5,17,17,17,17,17,17,17,5,31,20,20,0
0,0,0,16,5,17,17,17,17,17,17,17,5,31,20,20,0
0,0,0,16,5,5,5,5,5,5,5,5,5,31,20,20,0
0,0,0,16,0,0,0,0,0,0,0,0,0,31,0,0,0
0,0,0,0,0,0,0,0,8,0,0,0,0,0,0,0,0
0,0,0,0,0,0,0,0,0,0,0,0,0,0,0,0,0
0,0,0,0,0,0,0,0,0,0,0,0,0,0,0,0,0
0,0,0,0,0,0,0,0,0,0,0,0,0,0,0,0,0
:endlayer
layer: 6
0,0,0,0,0,0,0,0,0,0,0,0,0,0,0,0,0
0,0,0,0,0,0,0,0,0,0,0,0,0,0,0,0,0
0,0,0,0,0,0,0,0,0,0,0,0,0,0,0,0,0
0,0,0,0,0,0,0,0,0,0,0,0,0,0,0,0,0
0,0,0,0,0,0,0,0,0,0,0,0,0,0,0,0,0
0,0,0,0,17,30,30,30,30,30,30,30,17,0,0,0,0
0,0,0,0,17,17,17,5,17,5,17,17,17,0,0,0,0
0,0,0,0,17,0,0,3,0,0,0,0,17,0,0,0,0
0,0,0,0,17,0,0,0,0,0,0,0,17,0,0,0,0
0,0,0,0,17,0,3,0,0,3,0,0,17,0,0,0,0
0,0,0,0,17,0,3,0,0,0,3,0,17,0,0,0,0
0,0,0,0,17,0,3,0,3,3,3,0,17,0,0,0,0
0,0,0,0,17,0,3,0,3,3,0,0,17,0,0,0,0
0,0,0,0,17,0,0,0,0,3,3,0,17,0,0,0,0
0,0,0,0,17,0,3,0,0,0,0,0,17,0,0,0,0
0,0,0,0,17,0,3,0,0,3,0,0,17,0,0,0,0
0,0,0,0,17,17,17,5,20,5,17,17,17,0,0,0,0
0,0,0,0,17,32,32,32,20,32,32,32,17,0,0,0,0
0,0,0,0,0,0,0,0,8,0,0,0,0,0,0,0,0
0,0,0,0,0,0,0,0,0,0,0,0,0,0,0,0,0
0,0,0,0,0,0,0,0,0,0,0,0,0,0,0,0,0
0,0,0,0,0,0,0,0,0,0,0,0,0,0,0,0,0
:endlayer
layer: 7
0,0,0,0,0,0,0,0,0,0,0,0,0,0,0,0,0
0,0,0,0,0,0,0,0,0,0,0,0,0,0,0,0,0
0,0,0,0,0,0,0,0,0,0,0,0,0,0,0,0,0
0,0,0,0,0,0,0,0,0,0,0,0,0,0,0,0,0
0,0,0,0,0,0,0,0,0,0,0,0,0,0,0,0,0
0,0,0,0,16,0,0,0,0,0,0,0,31,0,0,0,0
0,0,0,0,16,17,17,5,17,5,17,17,31,0,0,0,0
0,0,0,0,16,21,0,3,0,0,0,21,31,0,0,0,0
0,0,0,0,16,0,0,0,0,0,0,0,31,0,0,0,0
0,0,0,0,16,0,0,0,0,3,0,0,31,0,0,0,0
0,0,0,0,16,0,3,0,0,0,0,0,31,0,0,0,0
0,0,0,0,16,0,3,0,3,3,0,0,31,0,0,0,0
0,0,0,0,16,0,3,0,3,0,0,0,31,0,0,0,0
0,0,0,0,16,0,0,0,0,0,0,0,31,0,0,0,0
0,0,0,0,16,0,3,0,0,0,0,0,31,0,0,0,0
0,0,0,0,16,22,0,0,0,3,0,22,31,0,0,0,0
0,0,0,0,16,17,17,5,0,5,17,17,31,0,0,0,0
0,0,0,0,16,0,0,0,0,0,0,0,31,0,0,0,0
0,0,0,0,0,0,0,0,8,0,0,0,0,0,0,0,0
0,0,0,0,0,0,0,0,0,0,0,0,0,0,0,0,0
0,0,0,0,0,0,0,0,0,0,0,0,0,0,0,0,0
0,0,0,0,0,0,0,0,0,0,0,0,0,0,0,0,0
:endlayer
layer: 8
0,0,0,0,0,0,0,0,0,0,0,0,0,0,0,0,0
0,0,0,0,0,0,0,0,0,0,0,0,0,0,0,0,0
0,0,0,0,0,0,0,0,0,0,0,0,0,0,0,0,0
0,0,0,0,0,0,0,0,0,0,0,0,0,0,0,0,0
0,0,0,0,0,0,0,0,0,0,0,0,0,0,0,0,0
0,0,0,0,0,17,0,0,0,0,0,17,0,0,0,0,0
0,0,0,0,0,17,17,17,0,17,17,17,0,0,0,0,0
0,0,0,0,0,17,0,0,0,0,0,17,0,0,0,0,0
0,0,0,0,0,17,0,0,0,0,0,17,0,0,0,0,0
0,0,0,0,0,17,0,0,0,0,0,17,0,0,0,0,0
0,0,0,0,0,17,33,0,0,0,0,17,0,0,0,0,0
0,0,0,0,0,17,3,0,3,3,0,17,0,0,0,0,0
0,0,0,0,0,17,0,0,3,0,0,17,0,0,0,0,0
0,0,0,0,0,17,0,0,0,0,0,17,0,0,0,0,0
0,0,0,0,0,17,0,0,0,0,0,17,0,0,0,0,0
0,0,0,0,0,17,0,0,0,0,0,17,0,0,0,0,0
0,0,0,0,0,17,17,17,0,17,17,17,0,0,0,0,0
0,0,0,0,0,17,0,0,0,0,0,17,0,0,0,0,0
0,0,0,0,0,0,0,0,8,0,0,0,0,0,0,0,0
0,0,0,0,0,0,0,0,0,0,0,0,0,0,0,0,0
0,0,0,0,0,0,0,0,0,0,0,0,0,0,0,0,0
0,0,0,0,0,0,0,0,0,0,0,0,0,0,0,0,0
:endlayer
layer: 9
0,0,0,0,0,0,0,0,0,0,0,0,0,0,0,0,0
0,0,0,0,0,0,0,0,0,0,0,0,0,0,0,0,0
0,0,0,0,0,0,0,0,0,0,0,0,0,0,0,0,0
0,0,0,0,0,0,0,0,0,0,0,0,0,0,0,0,0
0,0,0,0,0,0,0,0,0,0,0,0,0,0,0,0,0
0,0,0,0,0,16,0,0,0,0,0,31,0,0,0,0,0
0,0,0,0,0,16,17,17,5,17,17,31,0,0,0,0,0
0,0,0,0,0,16,34,0,0,0,35,31,0,0,0,0,0
0,0,0,0,0,16,34,0,0,0,35,31,0,0,0,0,0
0,0,0,0,0,16,34,0,0,0,35,31,0,0,0,0,0
0,0,0,0,0,16,34,0,0,0,35,31,0,0,0,0,0
0,0,0,0,0,16,34,0,0,0,35,31,0,0,0,0,0
0,0,0,0,0,16,34,0,0,0,35,31,0,0,0,0,0
0,0,0,0,0,16,34,0,0,0,35,31,0,0,0,0,0
0,0,0,0,0,16,34,0,0,0,35,31,0,0,0,0,0
0,0,0,0,0,16,34,0,0,0,35,31,0,0,0,0,0
0,0,0,0,0,16,17,17,5,17,17,31,0,0,0,0,0
0,0,0,0,0,16,0,0,8,0,0,31,0,0,0,0,0
0,0,0,0,0,0,0,0,8,0,0,0,0,0,0,0,0
0,0,0,0,0,0,0,0,0,0,0,0,0,0,0,0,0
0,0,0,0,0,0,0,0,0,0,0,0,0,0,0,0,0
0,0,0,0,0,0,0,0,0,0,0,0,0,0,0,0,0
:endlayer
layer: 10
0,0,0,0,0,0,0,0,0,0,0,0,0,0,0,0,0
0,0,0,0,0,0,0,0,0,0,0,0,0,0,0,0,0
0,0,0,0,0,0,0,0,0,0,0,0,0,0,0,0,0
0,0,0,0,0,0,0,0,0,0,0,0,0,0,0,0,0
0,0,0,0,0,0,0,0,0,0,0,0,0,0,0,0,0
0,0,0,0,0,0,16,17,0,17,31,0,0,0,0,0,0
0,0,0,0,0,0,16,17,17,17,31,0,0,0,0,0,0
0,0,0,0,0,0,16,17,0,17,31,0,0,0,0,0,0
0,0,0,0,0,0,16,17,0,17,31,0,0,0,0,0,0
0,0,0,0,0,0,16,17,0,17,31,0,0,0,0,0,0
0,0,0,0,0,0,16,17,0,17,31,0,0,0,0,0,0
0,0,0,0,0,0,16,17,0,17,31,0,0,0,0,0,0
0,0,0,0,0,0,16,17,0,17,31,0,0,0,0,0,0
0,0,0,0,0,0,16,17,0,17,31,0,0,0,0,0,0
0,0,0,0,0,0,16,17,0,17,31,0,0,0,0,0,0
0,0,0,0,0,0,16,17,0,17,31,0,0,0,0,0,0
0,0,0,0,0,0,16,17,17,17,31,0,0,0,0,0,0
0,0,0,0,0,0,16,17,21,17,31,0,0,0,0,0,0
0,0,0,0,0,0,0,0,8,0,0,0,0,0,0,0,0
0,0,0,0,0,0,0,0,0,0,0,0,0,0,0,0,0
0,0,0,0,0,0,0,0,0,0,0,0,0,0,0,0,0
0,0,0,0,0,0,0,0,0,0,0,0,0,0,0,0,0
:endlayer
layer: 11
0,0,0,0,0,0,0,0,0,0,0,0,0,0,0,0,0
0,0,0,0,0,0,0,0,0,0,0,0,0,0,0,0,0
0,0,0,0,0,0,0,0,0,0,0,0,0,0,0,0,0
0,0,0,0,0,0,0,0,0,0,0,0,0,0,0,0,0
0,0,0,0,0,0,0,0,36,0,0,0,0,0,0,0,0
0,0,0,0,0,0,0,0,36,0,0,0,0,0,0,0,0
0,0,0,0,0,0,0,0,36,0,0,0,0,0,0,0,0
0,0,0,0,0,0,0,0,36,0,0,0,0,0,0,0,0
0,0,0,0,0,0,0,0,36,0,0,0,0,0,0,0,0
0,0,0,0,0,0,0,0,36,0,0,0,0,0,0,0,0
0,0,0,0,0,0,0,0,30,0,0,0,0,0,0,0,0
0,0,0,0,0,0,0,0,17,0,0,0,0,0,0,0,0
0,0,0,0,0,0,0,0,32,0,0,0,0,0,0,0,0
0,0,0,0,0,0,0,0,36,0,0,0,0,0,0,0,0
0,0,0,0,0,0,0,0,36,0,0,0,0,0,0,0,0
0,0,0,0,0,0,0,0,36,0,0,0,0,0,0,0,0
0,0,0,0,0,0,0,0,36,0,0,0,0,0,0,0,0
0,0,0,0,0,0,0,0,36,0,0,0,0,0,0,0,0
0,0,0,0,0,0,0,0,36,0,0,0,0,0,0,0,0
0,0,0,0,0,0,0,0,0,0,0,0,0,0,0,0,0
0,0,0,0,0,0,0,0,0,0,0,0,0,0,0,0,0
0,0,0,0,0,0,0,0,0,0,0,0,0,0,0,0,0
:endlayer
layer: 12
0,0,0,0,0,0,0,0,0,0,0,0,0,0,0,0,0
0,0,0,0,0,0,0,0,0,0,0,0,0,0,0,0,0
0,0,0,0,0,0,0,0,0,0,0,0,0,0,0,0,0
0,0,0,0,0,0,0,0,0,0,0,0,0,0,0,0,0
0,0,0,0,0,0,0,0,0,0,0,0,0,0,0,0,0
0,0,0,0,0,0,0,0,0,0,0,0,0,0,0,0,0
0,0,0,0,0,0,0,0,0,0,0,0,0,0,0,0,0
0,0,0,0,0,0,0,0,0,0,0,0,0,0,0,0,0
0,0,0,0,0,0,0,0,0,0,0,0,0,0,0,0,0
0,0,0,0,0,0,0,0,0,0,0,0,0,0,0,0,0
0,0,0,0,0,0,0,0,0,0,0,0,0,0,0,0,0
0,0,0,0,0,0,0,0,37,0,0,0,0,0,0,0,0
0,0,0,0,0,0,0,0,0,0,0,0,0,0,0,0,0
0,0,0,0,0,0,0,0,0,0,0,0,0,0,0,0,0
0,0,0,0,0,0,0,0,0,0,0,0,0,0,0,0,0
0,0,0,0,0,0,0,0,0,0,0,0,0,0,0,0,0
0,0,0,0,0,0,0,0,0,0,0,0,0,0,0,0,0
0,0,0,0,0,0,0,0,0,0,0,0,0,0,0,0,0
0,0,0,0,0,0,0,0,0,0,0,0,0,0,0,0,0
0,0,0,0,0,0,0,0,0,0,0,0,0,0,0,0,0
0,0,0,0,0,0,0,0,0,0,0,0,0,0,0,0,0
0,0,0,0,0,0,0,0,0,0,0,0,0,0,0,0,0
:endlayer
layer: 13
0,0,0,0,0,0,0,0,0,0,0,0,0,0,0,0,0
0,0,0,0,0,0,0,0,0,0,0,0,0,0,0,0,0
0,0,0,0,0,0,0,0,0,0,0,0,0,0,0,0,0
0,0,0,0,0,0,0,0,0,0,0,0,0,0,0,0,0
0,0,0,0,0,0,0,0,0,0,0,0,0,0,0,0,0
0,0,0,0,0,0,0,0,0,0,0,0,0,0,0,0,0
0,0,0,0,0,0,0,0,0,0,0,0,0,0,0,0,0
0,0,0,0,0,0,0,0,0,0,0,0,0,0,0,0,0
0,0,0,0,0,0,0,0,0,0,0,0,0,0,0,0,0
0,0,0,0,0,0,0,0,0,0,0,0,0,0,0,0,0
0,0,0,0,0,0,0,0,0,0,0,0,0,0,0,0,0
0,0,0,0,0,0,0,0,0,0,0,0,0,0,0,0,0
0,0,0,0,0,0,0,0,0,0,0,0,0,0,0,0,0
0,0,0,0,0,0,0,0,0,0,0,0,0,0,0,0,0
0,0,0,0,0,0,0,0,0,0,0,0,0,0,0,0,0
0,0,0,0,0,0,0,0,0,0,0,0,0,0,0,0,0
0,0,0,0,0,0,0,0,0,0,0,0,0,0,0,0,0
0,0,0,0,0,0,0,0,0,0,0,0,0,0,0,0,0
0,0,0,0,0,0,0,0,0,0,0,0,0,0,0,0,0
0,0,0,0,0,0,0,0,0,0,0,0,0,0,0,0,0
0,0,0,0,0,0,0,0,0,0,0,0,0,0,0,0,0
0,0,0,0,0,0,0,0,0,0,0,0,0,0,0,0,0
:endlayer
layer: 14
0,0,0,0,0,0,0,0,0,0,0,0,0,0,0,0,0
0,0,0,0,0,0,0,0,0,0,0,0,0,0,0,0,0
0,0,0,0,0,0,0,0,0,0,0,0,0,0,0,0,0
0,0,0,0,0,0,0,0,0,0,0,0,0,0,0,0,0
0,0,0,0,0,0,0,0,0,0,0,0,0,0,0,0,0
0,0,0,0,0,0,0,0,0,0,0,0,0,0,0,0,0
0,0,0,0,0,0,0,0,0,0,0,0,0,0,0,0,0
0,0,0,0,0,0,0,0,0,0,0,0,0,0,0,0,0
0,0,0,0,0,0,0,0,0,0,0,0,0,0,0,0,0
0,0,0,0,0,0,0,0,0,0,0,0,0,0,0,0,0
0,0,0,0,0,0,0,0,0,0,0,0,0,0,0,0,0
0,0,0,0,0,0,0,0,0,0,0,0,0,0,0,0,0
0,0,0,0,0,0,0,0,0,0,0,0,0,0,0,0,0
0,0,0,0,0,0,0,0,0,0,0,0,0,0,0,0,0
0,0,0,0,0,0,0,0,0,0,0,0,0,0,0,0,0
0,0,0,0,0,0,0,0,0,0,0,0,0,0,0,0,0
0,0,0,0,0,0,0,0,0,0,0,0,0,0,0,0,0
0,0,0,0,0,0,0,0,0,0,0,0,0,0,0,0,0
0,0,0,0,0,0,0,0,0,0,0,0,0,0,0,0,0
0,0,0,0,0,0,0,0,0,0,0,0,0,0,0,0,0
0,0,0,0,0,0,0,0,0,0,0,0,0,0,0,0,0
0,0,0,0,0,0,0,0,0,0,0,0,0,0,0,0,0
:endlayer
layer: 15
0,0,0,0,0,0,0,0,0,0,0,0,0,0,0,0,0
0,0,0,0,0,0,0,0,0,0,0,0,0,0,0,0,0
0,0,0,0,0,0,0,0,0,0,0,0,0,0,0,0,0
0,0,0,0,0,0,0,0,0,0,0,0,0,0,0,0,0
0,0,0,0,0,0,0,0,0,0,0,0,0,0,0,0,0
0,0,0,0,0,0,0,0,0,0,0,0,0,0,0,0,0
0,0,0,0,0,0,0,0,0,0,0,0,0,0,0,0,0
0,0,0,0,0,0,0,0,0,0,0,0,0,0,0,0,0
0,0,0,0,0,0,0,0,0,0,0,0,0,0,0,0,0
0,0,0,0,0,0,0,0,0,0,0,0,0,0,0,0,0
0,0,0,0,0,0,0,0,0,0,0,0,0,0,0,0,0
0,0,0,0,0,0,0,0,0,0,0,0,0,0,0,0,0
0,0,0,0,0,0,0,0,0,0,0,0,0,0,0,0,0
0,0,0,0,0,0,0,0,0,0,0,0,0,0,0,0,0
0,0,0,0,0,0,0,0,0,0,0,0,0,0,0,0,0
0,0,0,0,0,0,0,0,0,0,0,0,0,0,0,0,0
0,0,0,0,0,0,0,0,0,0,0,0,0,0,0,0,0
0,0,0,0,0,0,0,0,0,0,0,0,0,0,0,0,0
0,0,0,0,0,0,0,0,0,0,0,0,0,0,0,0,0
0,0,0,0,0,0,0,0,0,0,0,0,0,0,0,0,0
0,0,0,0,0,0,0,0,0,0,0,0,0,0,0,0,0
0,0,0,0,0,0,0,0,0,0,0,0,0,0,0,0,0
:endlayer
layer: 16
0,0,0,0,0,0,0,0,0,0,0,0,0,0,0,0,0
0,0,0,0,0,0,0,0,0,0,0,0,0,0,0,0,0
0,0,0,0,0,0,0,0,0,0,0,0,0,0,0,0,0
0,0,0,0,0,0,0,0,0,0,0,0,0,0,0,0,0
0,0,0,0,0,0,0,0,0,0,0,0,0,0,0,0,0
0,0,0,0,0,0,0,0,0,0,0,0,0,0,0,0,0
0,0,0,0,0,0,0,0,0,0,0,0,0,0,0,0,0
0,0,0,0,0,0,0,0,0,0,0,0,0,0,0,0,0
0,0,0,0,0,0,0,0,0,0,0,0,0,0,0,0,0
0,0,0,0,0,0,0,0,0,0,0,0,0,0,0,0,0
0,0,0,0,0,0,0,0,0,0,0,0,0,0,0,0,0
0,0,0,0,0,0,0,0,0,0,0,0,0,0,0,0,0
0,0,0,0,0,0,0,0,0,0,0,0,0,0,0,0,0
0,0,0,0,0,0,0,0,0,0,0,0,0,0,0,0,0
0,0,0,0,0,0,0,0,0,0,0,0,0,0,0,0,0
0,0,0,0,0,0,0,0,0,0,0,0,0,0,0,0,0
0,0,0,0,0,0,0,0,0,0,0,0,0,0,0,0,0
0,0,0,0,0,0,0,0,0,0,0,0,0,0,0,0,0
0,0,0,0,0,0,0,0,0,0,0,0,0,0,0,0,0
0,0,0,0,0,0,0,0,0,0,0,0,0,0,0,0,0
0,0,0,0,0,0,0,0,0,0,0,0,0,0,0,0,0
0,0,0,0,0,0,0,0,0,0,0,0,0,0,0,0,0
:endlayer
layer: 17
0,0,0,0,0,0,0,0,0,0,0,0,0,0,0,0,0
0,0,0,0,0,0,0,0,0,0,0,0,0,0,0,0,0
0,0,0,0,0,0,0,0,0,0,0,0,0,0,0,0,0
0,0,0,0,0,0,0,0,0,0,0,0,0,0,0,0,0
0,0,0,0,0,0,0,0,0,0,0,0,0,0,0,0,0
0,0,0,0,0,0,0,0,0,0,0,0,0,0,0,0,0
0,0,0,0,0,0,0,0,0,0,0,0,0,0,0,0,0
0,0,0,0,0,0,0,0,0,0,0,0,0,0,0,0,0
0,0,0,0,0,0,0,0,0,0,0,0,0,0,0,0,0
0,0,0,0,0,0,0,0,0,0,0,0,0,0,0,0,0
0,0,0,0,0,0,0,0,0,0,0,0,0,0,0,0,0
0,0,0,0,0,0,0,0,0,0,0,0,0,0,0,0,0
0,0,0,0,0,0,0,0,0,0,0,0,0,0,0,0,0
0,0,0,0,0,0,0,0,0,0,0,0,0,0,0,0,0
0,0,0,0,0,0,0,0,0,0,0,0,0,0,0,0,0
0,0,0,0,0,0,0,0,0,0,0,0,0,0,0,0,0
0,0,0,0,0,0,0,0,0,0,0,0,0,0,0,0,0
0,0,0,0,0,0,0,0,0,0,0,0,0,0,0,0,0
0,0,0,0,0,0,0,0,0,0,0,0,0,0,0,0,0
0,0,0,0,0,0,0,0,0,0,0,0,0,0,0,0,0
0,0,0,0,0,0,0,0,0,0,0,0,0,0,0,0,0
0,0,0,0,0,0,0,0,0,0,0,0,0,0,0,0,0
:endlayer
layer: 18
0,0,0,0,0,0,0,0,0,0,0,0,0,0,0,0,0
0,0,0,0,0,0,0,0,0,0,0,0,0,0,0,0,0
0,0,0,0,0,0,0,0,0,0,0,0,0,0,0,0,0
0,0,0,0,0,0,0,0,0,0,0,0,0,0,0,0,0
0,0,0,0,0,0,0,0,0,0,0,0,0,0,0,0,0
0,0,0,0,0,0,0,0,0,0,0,0,0,0,0,0,0
0,0,0,0,0,0,0,0,0,0,0,0,0,0,0,0,0
0,0,0,0,0,0,0,0,0,0,0,0,0,0,0,0,0
0,0,0,0,0,0,0,0,0,0,0,0,0,0,0,0,0
0,0,0,0,0,0,0,0,0,0,0,0,0,0,0,0,0
0,0,0,0,0,0,0,0,0,0,0,0,0,0,0,0,0
0,0,0,0,0,0,0,0,0,0,0,0,0,0,0,0,0
0,0,0,0,0,0,0,0,0,0,0,0,0,0,0,0,0
0,0,0,0,0,0,0,0,0,0,0,0,0,0,0,0,0
0,0,0,0,0,0,0,0,0,0,0,0,0,0,0,0,0
0,0,0,0,0,0,0,0,0,0,0,0,0,0,0,0,0
0,0,0,0,0,0,0,0,0,0,0,0,0,0,0,0,0
0,0,0,0,0,0,0,0,0,0,0,0,0,0,0,0,0
0,0,0,0,0,0,0,0,0,0,0,0,0,0,0,0,0
0,0,0,0,0,0,0,0,0,0,0,0,0,0,0,0,0
0,0,0,0,0,0,0,0,0,0,0,0,0,0,0,0,0
0,0,0,0,0,0,0,0,0,0,0,0,0,0,0,0,0
:endlayer
layer: 19
0,0,0,0,0,0,0,0,0,0,0,0,0,0,0,0,0
0,0,0,0,0,0,0,0,0,0,0,0,0,0,0,0,0
0,0,0,0,0,0,0,0,0,0,0,0,0,0,0,0,0
0,0,0,0,0,0,0,0,0,0,0,0,0,0,0,0,0
0,0,0,0,0,0,0,0,0,0,0,0,0,0,0,0,0
0,0,0,0,0,0,0,0,0,0,0,0,0,0,0,0,0
0,0,0,0,0,0,0,0,0,0,0,0,0,0,0,0,0
0,0,0,0,0,0,0,0,0,0,0,0,0,0,0,0,0
0,0,0,0,0,0,0,0,0,0,0,0,0,0,0,0,0
0,0,0,0,0,0,0,0,0,0,0,0,0,0,0,0,0
0,0,0,0,0,0,0,0,0,0,0,0,0,0,0,0,0
0,0,0,0,0,0,0,0,0,0,0,0,0,0,0,0,0
0,0,0,0,0,0,0,0,0,0,0,0,0,0,0,0,0
0,0,0,0,0,0,0,0,0,0,0,0,0,0,0,0,0
0,0,0,0,0,0,0,0,0,0,0,0,0,0,0,0,0
0,0,0,0,0,0,0,0,0,0,0,0,0,0,0,0,0
0,0,0,0,0,0,0,0,0,0,0,0,0,0,0,0,0
0,0,0,0,0,0,0,0,0,0,0,0,0,0,0,0,0
0,0,0,0,0,0,0,0,0,0,0,0,0,0,0,0,0
0,0,0,0,0,0,0,0,0,0,0,0,0,0,0,0,0
0,0,0,0,0,0,0,0,0,0,0,0,0,0,0,0,0
0,0,0,0,0,0,0,0,0,0,0,0,0,0,0,0,0
:endlayer
layer: 20
0,0,0,0,0,0,0,0,0,0,0,0,0,0,0,0,0
0,0,0,0,0,0,0,0,0,0,0,0,0,0,0,0,0
0,0,0,0,0,0,0,0,0,0,0,0,0,0,0,0,0
0,0,0,0,0,0,0,0,0,0,0,0,0,0,0,0,0
0,0,0,0,0,0,0,0,0,0,0,0,0,0,0,0,0
0,0,0,0,0,0,0,0,0,0,0,0,0,0,0,0,0
0,0,0,0,0,0,0,0,0,0,0,0,0,0,0,0,0
0,0,0,0,0,0,0,0,0,0,0,0,0,0,0,0,0
0,0,0,0,0,0,0,0,0,0,0,0,0,0,0,0,0
0,0,0,0,0,0,0,0,0,0,0,0,0,0,0,0,0
0,0,0,0,0,0,0,0,0,0,0,0,0,0,0,0,0
0,0,0,0,0,0,0,0,0,0,0,0,0,0,0,0,0
0,0,0,0,0,0,0,0,0,0,0,0,0,0,0,0,0
0,0,0,0,0,0,0,0,0,0,0,0,0,0,0,0,0
0,0,0,0,0,0,0,0,0,0,0,0,0,0,0,0,0
0,0,0,0,0,0,0,0,0,0,0,0,0,0,0,0,0
0,0,0,0,0,0,0,0,0,0,0,0,0,0,0,0,0
0,0,0,0,0,0,0,0,0,0,0,0,0,0,0,0,0
0,0,0,0,0,0,0,0,0,0,0,0,0,0,0,0,0
0,0,0,0,0,0,0,0,0,0,0,0,0,0,0,0,0
0,0,0,0,0,0,0,0,0,0,0,0,0,0,0,0,0
0,0,0,0,0,0,0,0,0,0,0,0,0,0,0,0,0
:endlayer

#### RULES ####
rule:
plugin=vanillaBlocks
number=1
data:
tag:
TAG=10={
TAG=8=blockName{dirt}
TAG=3=meta{0}
TAG=3=buildPass{0}
}
:endtag
:enddata
:endrule

rule:
plugin=vanillaBlocks
number=2
data:
tag:
TAG=10={
TAG=8=blockName{grass}
TAG=3=meta{0}
TAG=3=buildPass{0}
}
:endtag
:enddata
:endrule

rule:
plugin=vanillaBlocks
number=3
data:
tag:
TAG=10={
TAG=8=blockName{hay_block}
TAG=3=meta{0}
TAG=3=buildPass{0}
}
:endtag
:enddata
:endrule

rule:
plugin=vanillaBlocks
number=4
data:
tag:
TAG=10={
TAG=8=blockName{gravel}
TAG=3=meta{0}
TAG=3=buildPass{1}
}
:endtag
:enddata
:endrule

rule:
plugin=vanillaBlocks
number=5
data:
tag:
TAG=10={
TAG=8=blockName{log}
TAG=3=meta{0}
TAG=3=buildPass{0}
}
:endtag
:enddata
:endrule

rule:
plugin=vanillaBlocks
number=6
data:
tag:
TAG=10={
TAG=8=blockName{cobblestone}
TAG=3=meta{0}
TAG=3=buildPass{0}
}
:endtag
:enddata
:endrule

rule:
plugin=vanillaBlocks
number=7
data:
tag:
TAG=10={
TAG=8=blockName{tallgrass}
TAG=3=meta{1}
TAG=3=buildPass{0}
}
:endtag
:enddata
:endrule

rule:
plugin=vanillaBlocks
number=8
data:
tag:
TAG=10={
TAG=8=blockName{fence}
TAG=3=meta{0}
TAG=3=buildPass{0}
}
:endtag
:enddata
:endrule

rule:
plugin=vanillaBlocks
number=9
data:
tag:
TAG=10={
TAG=8=blockName{fence_gate}
TAG=3=meta{2}
TAG=3=buildPass{0}
}
:endtag
:enddata
:endrule

rule:
plugin=vanillaBlocks
number=10
data:
tag:
TAG=10={
TAG=8=blockName{fence_gate}
TAG=3=meta{0}
TAG=3=buildPass{0}
}
:endtag
:enddata
:endrule

rule:
plugin=vanillaBlocks
number=11
data:
tag:
TAG=10={
TAG=8=blockName{stonebrick}
TAG=3=meta{0}
TAG=3=buildPass{0}
}
:endtag
:enddata
:endrule

rule:
plugin=vanillaDoors
number=12
data:
tag:
TAG=10={
TAG=1=sideFlag{9}
TAG=8=blockName{wooden_door}
TAG=3=meta{1}
TAG=3=buildPass{1}
}
:endtag
:enddata
:endrule

rule:
plugin=vanillaDoors
number=13
data:
tag:
TAG=10={
TAG=1=sideFlag{8}
TAG=8=blockName{wooden_door}
TAG=3=meta{3}
TAG=3=buildPass{1}
}
:endtag
:enddata
:endrule

rule:
plugin=vanillaDoors
number=14
data:
tag:
TAG=10={
TAG=1=sideFlag{8}
TAG=8=blockName{wooden_door}
TAG=3=meta{1}
TAG=3=buildPass{1}
}
:endtag
:enddata
:endrule

rule:
plugin=vanillaDoors
number=15
data:
tag:
TAG=10={
TAG=1=sideFlag{9}
TAG=8=blockName{wooden_door}
TAG=3=meta{3}
TAG=3=buildPass{1}
}
:endtag
:enddata
:endrule

rule:
plugin=vanillaBlocks
number=16
data:
tag:
TAG=10={
TAG=8=blockName{oak_stairs}
TAG=3=meta{0}
TAG=3=buildPass{0}
}
:endtag
:enddata
:endrule

rule:
plugin=vanillaBlocks
number=17
data:
tag:
TAG=10={
TAG=8=blockName{planks}
TAG=3=meta{0}
TAG=3=buildPass{0}
}
:endtag
:enddata
:endrule

rule:
plugin=vanillaBlocks
number=18
data:
tag:
TAG=10={
TAG=8=blockName{hay_block}
TAG=3=meta{4}
TAG=3=buildPass{0}
}
:endtag
:enddata
:endrule

rule:
plugin=vanillaInventory
number=19
data:
tag:
TAG=10={
TAG=3=lootLevel{0}
TAG=10=teData{
TAG=9=Items{
}
TAG=8=id{Chest}
}
TAG=8=blockName{chest}
TAG=3=meta{5}
TAG=3=buildPass{0}
}
:endtag
:enddata
:endrule

rule:
plugin=vanillaBlocks
number=20
data:
tag:
TAG=10={
TAG=8=blockName{wooden_slab}
TAG=3=meta{0}
TAG=3=buildPass{0}
}
:endtag
:enddata
:endrule

rule:
plugin=vanillaBlocks
number=21
data:
tag:
TAG=10={
TAG=8=blockName{torch}
TAG=3=meta{3}
TAG=3=buildPass{1}
}
:endtag
:enddata
:endrule

rule:
plugin=vanillaBlocks
number=22
data:
tag:
TAG=10={
TAG=8=blockName{torch}
TAG=3=meta{4}
TAG=3=buildPass{1}
}
:endtag
:enddata
:endrule

rule:
plugin=vanillaDoors
number=23
data:
tag:
TAG=10={
TAG=1=sideFlag{0}
TAG=8=blockName{wooden_door}
TAG=3=meta{2}
TAG=3=buildPass{1}
}
:endtag
:enddata
:endrule

rule:
plugin=vanillaDoors
number=24
data:
tag:
TAG=10={
TAG=1=sideFlag{0}
TAG=8=blockName{wooden_door}
TAG=3=meta{8}
TAG=3=buildPass{1}
}
:endtag
:enddata
:endrule

rule:
plugin=vanillaDoors
number=25
data:
tag:
TAG=10={
TAG=1=sideFlag{0}
TAG=8=blockName{wooden_door}
TAG=3=meta{8}
TAG=3=buildPass{1}
}
:endtag
:enddata
:endrule

rule:
plugin=vanillaDoors
number=26
data:
tag:
TAG=10={
TAG=1=sideFlag{0}
TAG=8=blockName{wooden_door}
TAG=3=meta{2}
TAG=3=buildPass{1}
}
:endtag
:enddata
:endrule

rule:
plugin=vanillaBlocks
number=27
data:
tag:
TAG=10={
TAG=8=blockName{wooden_slab}
TAG=3=meta{8}
TAG=3=buildPass{0}
}
:endtag
:enddata
:endrule

rule:
plugin=vanillaBlocks
number=28
data:
tag:
TAG=10={
TAG=8=blockName{torch}
TAG=3=meta{1}
TAG=3=buildPass{1}
}
:endtag
:enddata
:endrule

rule:
plugin=vanillaBlocks
number=29
data:
tag:
TAG=10={
TAG=8=blockName{torch}
TAG=3=meta{2}
TAG=3=buildPass{1}
}
:endtag
:enddata
:endrule

rule:
plugin=vanillaBlocks
number=30
data:
tag:
TAG=10={
TAG=8=blockName{oak_stairs}
TAG=3=meta{2}
TAG=3=buildPass{0}
}
:endtag
:enddata
:endrule

rule:
plugin=vanillaBlocks
number=31
data:
tag:
TAG=10={
TAG=8=blockName{oak_stairs}
TAG=3=meta{1}
TAG=3=buildPass{0}
}
:endtag
:enddata
:endrule

rule:
plugin=vanillaBlocks
number=32
data:
tag:
TAG=10={
TAG=8=blockName{oak_stairs}
TAG=3=meta{3}
TAG=3=buildPass{0}
}
:endtag
:enddata
:endrule

rule:
plugin=vanillaBlocks
number=33
data:
tag:
TAG=10={
TAG=8=blockName{hay_block}
TAG=3=meta{8}
TAG=3=buildPass{0}
}
:endtag
:enddata
:endrule

rule:
plugin=vanillaBlocks
number=34
data:
tag:
TAG=10={
TAG=8=blockName{oak_stairs}
TAG=3=meta{5}
TAG=3=buildPass{0}
}
:endtag
:enddata
:endrule

rule:
plugin=vanillaBlocks
number=35
data:
tag:
TAG=10={
TAG=8=blockName{oak_stairs}
TAG=3=meta{4}
TAG=3=buildPass{0}
}
:endtag
:enddata
:endrule

rule:
plugin=vanillaBlocks
number=36
data:
tag:
TAG=10={
TAG=8=blockName{stone_slab}
TAG=3=meta{2}
TAG=3=buildPass{0}
}
:endtag
:enddata
:endrule

rule:
plugin=vanillaBlocks
number=37
data:
tag:
TAG=10={
TAG=8=blockName{iron_bars}
TAG=3=meta{0}
TAG=3=buildPass{0}
}
:endtag
:enddata
:endrule

#### ENTITIES ####
