# Ancient Warfare Structure Template File
# auto-generated structure file. created on: 4/15/2014 at: 19:38:54
# Lines beginning with # denote comments

header:
version=2.0
name=CivNewFarmCowGentryMOH
size=23,30,41
offset=12,6,38
:endheader

#### VALIDATION ####
validation:
type=ground
survival=false
worldGenEnabled=true
unique=false
preserveBlocks=false
selectionWeight=10
clusterValue=10
minDuplicateDistance=40
dimensionWhiteList=false
dimensionList=
biomeWhiteList=true
biomeList=highlands.meadow,bop.meadow,ebxl.meadow,field,orchard
leveling=9
fill=5
border=5
validTargetBlocks=clay,lapis_ore,sand,grass,lit_redstone_ore,stone,iron_ore,gravel,diamond_ore,stained_hardened_clay,dirt,coal_ore,gold_ore,redstone_ore
data:
:enddata
:endvalidation

#### LAYERS ####
layer: 0
1,1,1,1,1,1,1,1,1,1,1,1,1,1,1,1,1,1,1,1,1,1,1
1,1,1,1,1,1,1,1,1,1,1,1,1,1,1,1,1,1,1,1,1,1,1
1,1,1,1,1,1,1,1,1,1,1,1,1,1,1,1,1,1,1,1,1,1,1
1,1,1,1,1,1,1,1,1,1,1,1,1,1,1,1,1,1,1,1,1,1,1
1,1,1,1,1,1,1,1,1,1,1,1,1,1,1,1,1,1,1,1,1,1,1
1,1,1,1,1,1,1,1,1,1,1,1,1,1,1,1,1,1,1,1,1,1,1
1,1,1,1,1,1,1,1,1,1,1,1,1,1,1,1,1,1,1,1,1,1,1
1,1,1,1,1,1,1,1,1,1,1,1,1,1,1,1,1,1,1,1,1,1,1
1,1,1,1,1,1,1,1,1,1,1,1,1,1,1,1,1,1,1,1,1,1,1
1,1,1,1,1,1,1,1,1,1,1,1,1,1,1,1,1,1,1,1,1,1,1
1,1,1,1,1,1,1,1,1,1,1,1,1,1,1,1,1,1,1,1,1,1,1
1,1,1,1,1,1,1,1,1,1,1,1,1,1,1,1,1,1,1,1,1,1,1
1,1,1,1,1,1,1,1,1,1,1,1,1,1,1,1,1,1,1,1,1,1,1
1,1,1,1,1,1,1,1,1,1,1,1,1,1,1,1,1,1,1,1,1,1,1
1,1,1,1,1,1,1,1,1,1,1,1,1,1,1,1,1,1,1,1,1,1,1
1,1,1,1,1,1,1,1,1,1,1,1,1,1,1,1,1,1,1,1,1,1,1
1,1,1,1,1,1,1,1,1,1,1,1,1,1,1,1,1,1,1,1,1,1,1
1,1,1,1,1,1,1,1,1,1,1,1,1,1,1,1,1,1,1,1,1,1,1
1,1,1,1,1,1,1,1,1,1,1,1,1,1,1,1,1,1,1,1,1,1,1
1,1,1,1,1,1,1,1,1,1,1,1,1,1,1,1,1,1,1,1,1,1,1
1,1,1,1,1,1,1,1,1,1,1,1,1,1,1,1,1,1,1,1,1,1,1
1,1,1,1,1,1,1,1,1,1,1,1,1,1,1,1,1,1,1,1,1,1,1
1,1,1,1,1,1,1,1,1,1,1,1,1,1,1,1,1,1,1,1,1,1,1
1,1,1,1,1,1,1,1,1,1,1,1,1,1,1,1,1,1,1,1,1,1,1
1,1,1,1,1,1,1,1,1,1,1,1,1,1,1,1,1,1,1,1,1,1,1
1,1,1,1,1,1,1,1,1,1,1,1,1,1,1,1,1,1,1,1,1,1,1
1,1,1,1,1,1,1,1,1,1,1,1,1,1,1,1,1,1,1,1,1,1,1
1,1,1,1,1,1,1,1,1,1,1,1,1,1,1,1,1,1,1,1,1,1,1
1,1,1,1,1,1,1,1,1,1,1,1,1,1,1,1,1,1,1,1,1,1,1
1,1,1,1,1,1,1,1,1,1,1,1,1,1,1,1,1,1,1,1,1,1,1
1,1,1,1,1,1,1,1,1,1,1,1,1,1,1,1,1,1,1,1,1,1,1
1,1,1,1,1,1,1,1,1,1,1,1,1,1,1,1,1,1,1,1,1,1,1
1,1,1,1,1,1,1,1,1,1,1,1,1,1,1,1,1,1,1,1,1,1,1
1,1,1,1,1,1,1,1,1,1,1,1,1,1,1,1,1,1,1,1,1,1,1
1,1,1,1,1,1,1,1,1,1,1,1,1,1,1,1,1,1,1,1,1,1,1
1,1,1,1,1,1,1,1,1,1,1,1,1,1,1,1,1,1,1,1,1,1,1
1,1,1,1,1,1,1,1,1,1,1,1,1,1,1,1,1,1,1,1,1,1,1
1,1,1,1,1,1,1,1,1,1,1,1,1,1,1,1,1,1,1,1,1,1,1
1,1,1,1,1,1,1,1,1,1,1,1,1,1,1,1,1,1,1,1,1,1,1
1,1,1,1,1,1,1,1,1,1,1,1,1,1,1,1,1,1,1,1,1,1,1
1,1,1,1,1,1,1,1,1,1,1,1,1,1,1,1,1,1,1,1,1,1,1
:endlayer
layer: 1
1,1,1,1,1,1,1,1,1,1,1,1,1,1,1,1,1,1,1,1,1,1,1
1,1,1,1,1,1,1,1,1,1,1,1,1,1,1,1,1,1,1,1,1,1,1
1,1,1,1,1,1,1,1,1,1,1,1,1,1,1,1,1,1,1,1,1,1,1
1,1,1,1,1,1,1,1,1,1,1,1,1,1,1,1,1,1,1,1,1,1,1
1,1,1,1,1,1,1,1,1,1,1,1,1,1,1,1,1,1,1,1,1,1,1
1,1,1,1,1,1,1,1,1,1,1,1,1,1,1,1,1,1,1,1,1,1,1
1,1,1,1,1,1,1,1,1,1,1,1,1,1,1,1,1,1,1,1,1,1,1
1,1,1,1,1,1,1,1,1,1,1,1,1,1,1,1,1,1,1,1,1,1,1
1,1,1,1,1,1,1,1,1,1,1,1,1,1,1,1,1,1,1,1,1,1,1
1,1,1,1,1,1,1,1,1,1,1,1,1,1,1,1,1,1,1,1,1,1,1
1,1,1,1,1,1,1,1,1,1,1,1,1,1,1,1,1,1,1,1,1,1,1
1,1,1,1,1,1,1,1,1,1,1,1,1,1,1,1,1,1,1,1,1,1,1
1,1,1,1,1,1,1,1,1,1,1,1,1,1,1,1,1,1,1,1,1,1,1
1,1,1,1,1,1,1,1,1,1,1,1,1,1,1,1,1,1,1,1,1,1,1
1,1,1,1,1,1,1,1,1,1,1,1,1,1,1,1,1,1,1,1,1,1,1
1,1,1,1,1,1,1,1,1,1,1,1,1,1,1,1,1,1,1,1,1,1,1
1,1,1,1,1,1,1,1,1,1,1,1,1,1,1,1,1,1,1,1,1,1,1
1,1,1,1,1,1,1,1,1,1,1,1,1,1,1,1,1,1,1,1,1,1,1
1,1,1,1,1,1,1,1,1,1,1,1,1,1,1,1,1,1,1,1,1,1,1
1,1,1,1,1,1,1,1,1,1,1,1,1,1,1,1,1,1,1,1,1,1,1
1,1,1,1,1,1,1,1,1,1,1,1,1,1,1,1,1,1,1,1,1,1,1
1,1,1,1,1,1,1,1,1,1,1,1,1,1,1,1,1,1,1,1,1,1,1
1,1,1,1,1,1,1,1,1,1,1,1,1,1,1,1,1,1,1,1,1,1,1
1,1,1,1,1,1,1,1,1,1,1,1,1,1,1,1,1,1,1,1,1,1,1
1,1,1,1,1,1,1,1,1,1,1,1,1,1,1,1,1,1,1,1,1,1,1
1,1,1,1,1,1,1,1,1,1,1,1,1,1,1,1,1,1,1,1,1,1,1
1,1,1,1,1,1,1,1,1,1,1,1,1,1,1,1,1,1,1,1,1,1,1
1,1,1,1,1,1,1,1,1,1,1,1,1,1,1,1,1,1,1,1,1,1,1
1,1,1,1,1,1,1,1,1,1,1,1,1,1,1,1,1,1,1,1,1,1,1
1,1,1,1,1,1,1,1,1,1,1,1,1,1,1,1,1,1,1,1,1,1,1
1,1,1,1,1,1,1,1,1,1,1,1,1,1,1,1,1,1,1,1,1,1,1
1,1,1,1,1,1,1,1,1,1,1,1,1,1,1,1,1,1,1,1,1,1,1
1,1,1,1,1,1,1,1,1,1,1,1,1,1,1,1,1,1,1,1,1,1,1
1,1,1,1,1,1,1,1,1,1,1,1,1,1,1,1,1,1,1,1,1,1,1
1,1,1,1,1,1,1,1,1,1,1,1,1,1,1,1,1,1,1,1,1,1,1
1,1,1,1,1,1,1,1,1,1,1,1,1,1,1,1,1,1,1,1,1,1,1
1,1,1,1,1,1,1,1,1,1,1,1,1,1,1,1,1,1,1,1,1,1,1
1,1,1,1,1,1,1,1,1,1,1,1,1,1,1,1,1,1,1,1,1,1,1
1,1,1,1,1,1,1,1,1,1,1,1,1,1,1,1,1,1,1,1,1,1,1
1,1,1,1,1,1,1,1,1,1,1,1,1,1,1,1,1,1,1,1,1,1,1
1,1,1,1,1,1,1,1,1,1,1,1,1,1,1,1,1,1,1,1,1,1,1
:endlayer
layer: 2
1,1,1,1,1,1,1,1,1,1,1,1,1,1,1,1,1,1,1,1,1,1,1
1,1,1,1,1,1,1,1,1,1,1,1,1,1,1,1,1,1,1,1,1,1,1
1,1,1,1,1,1,1,1,1,1,1,1,1,1,1,1,1,1,1,1,1,1,1
1,1,1,1,1,1,1,1,1,1,1,1,1,1,1,1,1,1,1,1,1,1,1
1,1,1,1,1,1,1,1,1,1,1,1,1,1,1,1,1,1,1,1,1,1,1
1,1,1,1,1,1,1,1,1,1,1,1,1,1,1,1,1,1,1,1,1,1,1
1,1,1,1,1,1,1,1,1,1,1,1,1,1,1,1,1,1,1,1,1,1,1
1,1,1,1,1,1,1,1,1,1,1,1,1,1,1,1,1,1,1,1,1,1,1
1,1,1,1,1,1,1,1,1,1,1,1,1,1,1,1,1,1,1,1,1,1,1
1,1,1,1,1,1,1,1,1,1,1,1,1,1,1,1,1,1,1,1,1,1,1
1,1,1,1,1,1,1,1,1,1,1,1,1,1,1,1,1,1,1,1,1,1,1
1,1,1,1,1,1,1,1,1,1,1,1,1,1,1,1,1,1,1,1,1,1,1
1,1,1,1,1,1,1,1,1,1,1,1,1,1,1,1,1,1,1,1,1,1,1
1,1,1,1,1,1,1,1,1,1,1,1,1,1,1,1,1,1,1,1,1,1,1
1,1,1,1,1,1,1,1,1,1,1,1,1,1,1,1,1,1,1,1,1,1,1
1,1,1,1,1,1,1,1,1,1,1,1,1,1,1,1,1,1,1,1,1,1,1
1,1,1,1,1,1,1,1,1,1,1,1,1,1,1,1,1,1,1,1,1,1,1
1,1,1,1,1,1,1,1,1,1,1,1,1,1,1,1,1,1,1,1,1,1,1
1,1,1,1,1,1,1,1,1,1,1,1,1,1,1,1,1,1,1,1,1,1,1
1,1,1,1,1,1,1,1,1,1,1,1,1,1,1,1,1,1,1,1,1,1,1
1,1,1,1,1,1,1,1,1,1,1,1,1,1,1,1,1,1,1,1,1,1,1
1,1,1,1,1,1,1,1,1,1,1,1,1,1,1,1,1,1,1,1,1,1,1
1,1,1,1,1,1,1,1,1,1,1,1,1,1,1,1,1,1,1,1,1,1,1
1,1,1,1,1,1,1,1,1,1,1,1,1,1,1,1,1,1,1,1,1,1,1
1,1,1,1,1,1,1,1,1,1,1,1,1,1,1,1,1,1,1,1,1,1,1
1,1,1,1,1,1,1,1,1,1,1,1,1,1,1,1,1,1,1,1,1,1,1
1,1,1,1,1,1,1,1,1,1,1,1,1,1,1,1,1,1,1,1,1,1,1
1,1,1,1,1,1,1,1,1,1,1,1,1,1,1,1,1,1,1,1,1,1,1
1,1,1,1,1,1,1,1,1,1,1,1,1,1,1,1,1,1,1,1,1,1,1
1,1,1,1,1,1,1,1,1,1,1,1,1,1,1,1,1,1,1,1,1,1,1
1,1,1,1,1,1,1,1,1,1,1,1,1,1,1,1,1,1,1,1,1,1,1
1,1,1,1,1,1,1,1,1,1,1,1,1,1,1,1,1,1,1,1,1,1,1
1,1,1,1,1,1,1,1,1,1,1,1,1,1,1,1,1,1,1,1,1,1,1
1,1,1,1,1,1,1,1,1,1,1,1,1,1,1,1,1,1,1,1,1,1,1
1,1,1,1,1,1,1,1,1,1,1,1,1,1,1,1,1,1,1,1,1,1,1
1,1,1,1,1,1,1,1,1,1,1,1,1,1,1,1,1,1,1,1,1,1,1
1,1,1,1,1,1,1,1,1,1,1,1,1,1,1,1,1,1,1,1,1,1,1
1,1,1,1,1,1,1,1,1,1,1,1,1,1,1,1,1,1,1,1,1,1,1
1,1,1,1,1,1,1,1,1,1,1,1,1,1,1,1,1,1,1,1,1,1,1
1,1,1,1,1,1,1,1,1,1,1,1,1,1,1,1,1,1,1,1,1,1,1
1,1,1,1,1,1,1,1,1,1,1,1,1,1,1,1,1,1,1,1,1,1,1
:endlayer
layer: 3
1,1,1,1,1,1,1,1,1,1,1,1,1,1,1,1,1,1,1,1,1,1,1
1,1,1,1,1,1,1,1,1,1,1,1,1,1,1,1,1,1,1,1,1,1,1
1,1,1,1,1,1,1,1,1,1,1,1,1,1,1,1,1,1,1,1,1,1,1
1,1,1,1,1,1,1,1,1,1,1,1,1,1,1,1,1,1,1,1,1,1,1
1,1,1,1,1,1,1,1,1,1,1,1,1,1,1,1,1,1,1,1,1,1,1
1,1,1,1,1,1,1,1,1,1,1,1,1,1,1,1,1,1,1,1,1,1,1
1,1,1,1,1,1,1,1,1,1,1,1,1,1,1,1,1,1,1,1,1,1,1
1,1,1,1,1,1,1,1,1,1,1,1,1,1,1,1,1,1,1,1,1,1,1
1,1,1,1,1,1,1,1,1,1,1,1,1,1,1,1,1,1,1,1,1,1,1
1,1,1,1,1,1,1,1,1,1,1,1,1,1,1,1,1,1,1,1,1,1,1
1,1,1,1,1,1,1,1,1,1,1,1,1,1,1,1,1,1,1,1,1,1,1
1,1,1,1,1,1,1,1,1,1,1,1,1,1,1,1,1,1,1,1,1,1,1
1,1,1,1,1,1,1,1,1,1,1,1,1,1,1,1,1,1,1,1,1,1,1
1,1,1,1,1,1,1,1,1,1,1,1,1,1,1,1,1,1,1,1,1,1,1
1,1,1,1,1,1,1,1,1,1,1,1,1,1,1,1,1,1,1,1,1,1,1
1,1,1,1,1,1,1,1,1,1,1,1,1,1,1,1,1,1,1,1,1,1,1
1,1,1,1,1,1,1,1,1,1,1,1,1,1,1,1,1,1,1,1,1,1,1
1,1,1,1,1,1,1,1,1,1,1,1,1,1,1,1,1,1,1,1,1,1,1
1,1,1,1,1,1,1,1,1,1,1,1,1,1,1,1,1,1,1,1,1,1,1
1,1,1,1,1,1,1,1,1,1,1,1,1,1,1,1,1,1,1,1,1,1,1
1,1,1,1,1,1,1,1,1,1,1,1,1,1,1,1,1,1,1,1,1,1,1
1,1,1,1,1,1,1,1,1,1,1,1,1,1,1,1,1,1,1,1,1,1,1
1,1,1,1,1,1,1,1,1,1,1,1,1,1,1,1,1,1,1,1,1,1,1
1,1,1,1,1,1,1,1,1,1,1,1,1,1,1,1,1,1,1,1,1,1,1
1,1,1,1,1,1,1,1,1,1,1,1,1,1,1,1,1,1,1,1,1,1,1
1,1,1,1,1,1,1,1,1,1,1,1,1,1,1,1,1,1,1,1,1,1,1
1,1,1,1,1,1,1,1,1,1,1,1,1,1,1,1,1,1,1,1,1,1,1
1,1,1,1,1,1,1,1,1,1,1,1,1,1,1,1,1,1,1,1,1,1,1
1,1,1,1,1,1,1,1,1,1,1,1,1,1,1,1,1,1,1,1,1,1,1
1,1,1,1,1,1,1,1,1,1,1,1,1,1,1,1,1,1,1,1,1,1,1
1,1,1,1,1,1,1,1,1,1,1,1,1,1,1,1,1,1,1,1,1,1,1
1,1,1,1,1,1,1,1,1,1,1,1,1,1,1,1,1,1,1,1,1,1,1
1,1,1,1,1,1,1,1,1,1,1,1,1,1,1,1,1,1,1,1,1,1,1
1,1,1,1,1,1,1,1,1,1,1,1,1,1,1,1,1,1,1,1,1,1,1
1,1,1,1,1,1,1,1,1,1,1,1,1,1,1,1,1,1,1,1,1,1,1
1,1,1,1,1,1,1,1,1,1,1,1,1,1,1,1,1,1,1,1,1,1,1
1,1,1,1,1,1,1,1,1,1,1,1,1,1,1,1,1,1,1,1,1,1,1
1,1,1,1,1,1,1,1,1,1,1,1,1,1,1,1,1,1,1,1,1,1,1
1,1,1,1,1,1,1,1,1,1,1,1,1,1,1,1,1,1,1,1,1,1,1
1,1,1,1,1,1,1,1,1,1,1,1,1,1,1,1,1,1,1,1,1,1,1
1,1,1,1,1,1,1,1,1,1,1,1,1,1,1,1,1,1,1,1,1,1,1
:endlayer
layer: 4
1,1,1,1,1,1,1,1,1,1,1,1,1,1,1,1,1,1,1,1,1,1,1
1,1,1,1,1,1,1,1,1,1,1,1,1,1,1,1,1,1,1,1,1,1,1
1,1,1,1,1,1,1,1,1,1,1,1,1,1,1,1,1,1,1,1,1,1,1
1,1,1,1,1,1,1,1,1,1,1,1,1,1,1,1,1,1,1,1,1,1,1
1,1,1,1,1,1,1,1,1,1,1,1,1,1,1,1,1,1,1,1,1,1,1
1,1,1,1,1,1,1,1,1,1,1,1,1,1,1,1,1,1,1,1,1,1,1
1,1,1,1,1,1,1,1,1,1,1,1,1,1,1,1,1,1,1,1,1,1,1
1,1,1,1,1,1,1,1,1,1,1,1,1,1,1,1,1,1,1,1,1,1,1
1,1,1,1,1,1,1,1,1,1,1,1,1,1,1,1,1,1,1,1,1,1,1
1,1,1,1,1,1,1,1,1,1,1,1,1,1,1,1,1,1,1,1,1,1,1
1,1,1,1,1,1,1,1,1,1,1,1,1,1,1,1,1,1,1,1,1,1,1
1,1,1,1,1,1,1,1,1,1,1,1,1,1,1,1,1,1,1,1,1,1,1
1,1,1,1,1,1,1,1,1,1,1,1,1,1,1,1,1,1,1,1,1,1,1
1,1,1,1,1,1,1,1,1,1,1,1,1,1,1,1,1,1,1,1,1,1,1
1,1,1,1,1,1,1,1,1,1,1,1,1,1,1,1,1,1,1,1,1,1,1
1,1,1,1,1,1,1,1,1,1,1,1,1,1,1,1,1,1,1,1,1,1,1
1,1,1,1,1,1,1,1,1,1,1,1,1,1,1,1,1,1,1,1,1,1,1
1,1,1,1,1,1,1,1,1,1,1,1,1,1,1,1,1,1,1,1,1,1,1
1,1,1,1,1,1,1,1,1,1,1,1,1,1,1,1,1,1,1,1,1,1,1
1,1,1,1,1,1,1,1,1,1,1,1,1,1,1,1,1,1,1,1,1,1,1
1,1,1,1,1,1,1,1,1,1,1,1,1,1,1,1,1,1,1,1,1,1,1
1,1,1,1,1,1,1,1,1,1,1,1,1,1,1,1,1,1,1,1,1,1,1
1,1,1,1,1,1,1,1,1,1,1,1,1,1,1,1,1,1,1,1,1,1,1
1,1,1,1,1,1,1,1,1,1,1,1,1,1,1,1,1,1,1,1,1,1,1
1,1,1,1,1,1,1,1,1,1,1,1,1,1,1,1,1,1,1,1,1,1,1
1,1,1,1,1,1,1,1,1,1,1,1,1,1,1,1,1,1,1,1,1,1,1
1,1,1,1,1,1,1,1,1,1,1,1,1,1,1,1,1,1,1,1,1,1,1
1,1,1,1,1,1,1,1,1,1,1,1,1,1,1,1,1,1,1,1,1,1,1
1,1,1,1,1,1,1,1,1,1,1,1,1,1,1,1,1,1,1,1,1,1,1
1,1,1,1,1,1,1,1,1,1,1,1,1,1,1,1,1,1,1,1,1,1,1
1,1,1,1,1,1,1,1,1,1,1,1,1,1,1,1,1,1,1,1,1,1,1
1,1,1,1,1,1,1,1,1,1,1,1,1,1,1,1,1,1,1,1,1,1,1
1,1,1,1,1,1,1,1,1,1,1,1,1,1,1,1,1,1,1,1,1,1,1
1,1,1,1,1,1,1,1,1,1,1,1,1,1,1,1,1,1,1,1,1,1,1
1,1,1,1,1,1,1,1,1,1,1,1,1,1,1,1,1,1,1,1,1,1,1
1,1,1,1,1,1,1,1,1,1,1,1,1,1,1,1,1,1,1,1,1,1,1
1,1,1,1,1,1,1,1,1,1,1,1,1,1,1,1,1,1,1,1,1,1,1
1,1,1,1,1,1,1,1,1,1,1,1,1,1,1,1,1,1,1,1,1,1,1
1,1,1,1,1,1,1,1,1,1,1,1,1,1,1,1,1,1,1,1,1,1,1
1,1,1,1,1,1,1,1,1,1,1,1,1,1,1,1,1,1,1,1,1,1,1
1,1,1,1,1,1,1,1,1,1,1,1,1,1,1,1,1,1,1,1,1,1,1
:endlayer
layer: 5
2,2,2,2,2,2,2,2,2,2,2,2,2,2,2,2,2,2,2,2,2,2,2
2,2,2,2,2,2,2,2,2,2,2,2,2,1,1,1,2,2,2,2,2,2,2
2,2,2,2,2,2,2,2,2,2,2,2,2,5,5,5,2,2,2,2,2,2,2
2,2,1,4,4,4,4,4,4,4,4,3,1,1,7,1,1,1,1,1,2,2,2
2,2,1,4,4,4,4,4,4,4,4,3,1,4,4,4,4,4,4,1,2,2,2
2,2,1,4,4,4,4,4,4,4,4,3,1,4,4,4,4,4,4,1,2,2,2
2,2,1,4,4,4,4,4,4,4,4,3,1,4,4,4,4,4,4,1,2,2,2
2,2,1,4,4,4,4,4,4,4,4,3,1,4,4,4,4,4,4,1,2,2,2
2,2,1,4,4,4,4,4,4,4,4,3,1,4,4,4,4,4,4,1,2,2,2
2,2,1,4,4,4,4,4,4,4,4,3,1,1,1,1,1,1,4,1,2,2,2
2,2,1,4,4,4,4,4,4,4,4,3,3,3,3,3,3,3,3,3,3,2,2
2,2,1,4,4,4,4,4,4,4,4,3,3,3,3,3,3,3,3,3,3,2,2
2,2,1,4,4,4,4,4,4,4,4,2,2,2,2,2,2,3,3,3,3,2,2
2,2,1,1,1,1,1,1,1,1,1,1,6,6,6,6,2,3,3,3,3,3,3
2,2,1,1,1,1,1,1,1,1,1,1,2,2,2,2,2,3,3,3,3,2,2
2,2,1,1,1,1,1,1,1,1,1,1,2,3,3,3,3,3,3,3,3,2,2
2,2,1,1,1,1,1,1,1,1,1,1,2,3,2,2,2,3,3,3,3,2,2
2,2,1,1,1,1,1,1,1,1,1,1,2,3,2,2,2,1,2,1,2,2,2
2,2,1,1,1,1,1,1,1,1,1,1,2,3,2,1,1,1,1,1,1,2,2
2,2,1,1,1,1,1,1,1,1,1,1,2,3,2,1,1,1,1,1,1,2,2
2,2,1,1,1,1,1,1,1,1,1,1,2,3,2,1,1,1,1,1,1,2,2
2,2,1,1,1,1,1,1,1,1,1,1,2,3,2,1,1,1,1,1,1,2,2
2,2,1,1,1,1,1,1,1,1,1,1,2,3,2,1,1,1,1,1,1,2,2
2,2,1,1,1,1,1,1,1,1,1,1,2,3,2,1,1,1,1,1,1,2,2
2,2,1,1,1,1,1,1,1,1,1,1,2,3,2,2,2,2,2,2,2,2,2
2,2,1,1,1,1,1,1,1,1,1,1,2,3,2,2,2,2,2,2,2,2,2
2,2,1,1,1,1,1,1,1,1,1,1,2,3,2,2,2,2,2,2,2,2,2
2,2,1,1,1,1,1,1,1,1,1,1,2,3,2,2,2,2,2,2,2,2,2
2,2,1,1,1,1,1,1,1,1,1,1,2,3,2,2,2,2,2,2,2,2,2
2,2,2,2,2,2,2,2,2,2,2,2,2,3,2,2,2,2,2,2,2,2,2
2,2,2,2,2,3,3,3,3,3,3,3,3,3,2,2,2,2,2,2,2,2,2
2,2,2,2,2,2,2,2,2,2,2,2,2,3,2,6,2,2,2,2,2,2,2
2,2,2,2,2,2,2,2,2,2,2,2,2,3,2,2,2,2,2,2,2,2,2
2,2,2,2,2,2,2,2,2,2,2,2,2,3,2,2,2,2,2,2,2,2,2
2,2,2,2,2,2,2,2,2,2,2,2,2,3,2,2,2,2,2,2,2,2,2
2,2,2,2,2,2,2,2,2,2,2,2,2,3,2,2,2,2,2,2,2,2,2
2,2,2,2,2,2,2,2,2,2,2,2,2,3,2,2,2,2,2,2,2,2,2
2,2,2,2,2,2,2,2,2,2,2,2,2,3,2,2,2,2,2,2,2,2,2
2,2,2,2,2,2,2,2,2,2,2,2,2,3,2,2,2,2,2,2,2,2,2
2,2,2,2,2,2,2,2,2,2,2,2,2,3,2,2,2,2,2,2,2,2,2
2,2,2,2,2,2,2,2,2,2,2,2,2,3,2,2,2,2,2,2,2,2,1
:endlayer
layer: 6
0,0,0,0,0,0,0,0,0,0,0,0,0,0,0,0,0,0,0,0,0,0,0
0,0,9,9,9,9,9,9,9,9,9,9,9,5,5,5,9,9,9,9,9,9,0
0,0,22,0,0,0,0,0,0,0,0,0,0,5,5,5,0,0,0,0,0,9,0
0,0,11,11,11,11,11,11,11,11,11,0,11,5,20,5,11,11,11,11,0,9,0
0,0,11,4,4,4,4,4,4,4,11,0,11,5,21,19,5,16,0,11,0,9,0
0,0,11,4,4,4,4,4,4,4,11,0,11,0,0,0,18,0,0,11,0,9,0
0,0,11,4,4,4,4,4,4,4,11,0,11,0,0,0,0,0,0,11,0,9,0
0,0,11,4,4,4,4,4,4,4,11,0,11,0,0,0,0,0,0,11,0,9,0
0,0,11,4,4,4,4,4,4,4,11,0,11,0,0,0,0,0,0,11,0,9,0
0,0,11,4,4,4,4,4,4,4,11,0,11,11,11,11,11,11,14,11,0,9,0
0,0,11,4,4,4,4,4,4,4,11,0,0,0,0,0,0,0,0,0,0,9,0
8,8,11,4,4,4,4,4,4,4,5,16,0,0,0,0,0,0,0,0,0,9,8
8,8,11,4,4,4,4,4,4,4,11,9,9,9,9,9,9,0,0,0,0,9,0
8,8,11,11,11,11,5,5,11,11,5,11,0,0,0,0,10,0,0,0,0,10,0
0,8,11,6,6,6,3,3,6,6,6,11,9,9,9,9,9,0,0,0,0,9,0
0,0,11,6,6,6,3,3,6,6,6,11,0,0,0,0,0,0,0,0,0,9,0
8,8,11,6,6,6,3,3,6,6,6,11,0,0,0,0,0,0,0,0,0,9,0
8,0,11,6,6,6,3,3,6,6,6,11,0,0,0,0,0,11,15,11,0,9,8
0,8,11,6,6,6,3,3,6,6,6,11,9,23,9,11,11,11,12,11,11,9,8
8,8,11,6,6,6,3,3,6,6,6,11,0,0,0,11,12,12,12,12,11,8,0
0,0,11,6,6,6,3,3,6,6,6,11,8,0,0,11,12,12,12,12,11,0,0
0,0,11,6,6,6,3,3,6,6,6,11,8,0,8,11,12,12,12,12,11,0,0
0,0,11,6,6,6,3,3,6,6,6,11,13,0,8,11,12,12,12,12,11,0,0
8,8,11,6,6,6,3,3,6,6,6,11,0,0,17,11,11,11,11,11,11,0,0
8,8,11,6,6,6,3,3,6,6,6,11,0,0,0,9,0,8,0,0,9,0,0
8,8,11,6,6,6,3,3,6,6,6,11,0,0,8,9,8,8,0,8,9,0,8
8,0,11,6,6,6,3,3,6,6,6,11,0,0,8,9,8,8,8,0,9,8,0
0,0,11,6,6,6,3,3,6,6,6,11,0,0,8,9,8,8,8,8,9,8,8
8,0,11,11,11,11,26,26,11,11,11,11,0,0,13,9,8,0,8,8,9,8,8
0,0,9,0,0,25,25,25,25,8,17,8,17,0,8,9,8,8,8,8,9,8,0
8,8,9,8,0,0,0,0,0,0,0,0,0,0,9,9,8,13,8,8,9,0,0
8,8,9,0,8,13,0,8,8,8,8,8,8,0,22,0,8,8,8,0,9,0,0
8,0,9,8,0,0,8,8,0,8,8,0,17,0,9,8,0,17,8,8,9,0,0
0,8,9,8,8,8,8,8,8,0,0,0,8,0,9,8,0,13,13,8,9,0,8
8,0,9,0,8,8,8,8,0,8,0,17,8,0,9,8,8,17,8,13,9,8,8
0,0,9,13,8,8,8,8,0,0,0,8,8,0,9,8,0,0,8,8,9,8,0
0,0,9,0,8,8,8,8,0,0,8,8,8,0,9,0,8,8,8,0,9,0,8
0,0,9,0,0,8,8,8,0,8,8,0,8,0,9,0,0,8,0,0,9,8,8
0,0,9,9,9,9,9,9,9,9,9,9,9,24,9,9,9,9,9,9,9,0,8
8,8,0,0,8,0,0,8,8,8,8,8,8,0,0,0,0,8,8,8,8,0,0
8,8,8,0,0,0,0,0,0,8,8,8,0,0,0,0,0,8,8,8,0,0,0
:endlayer
layer: 7
0,0,0,0,0,0,0,0,0,0,0,0,0,0,0,0,0,0,0,0,0,0,0
0,0,27,0,0,0,0,0,0,0,0,0,0,37,37,37,0,0,0,0,0,27,0
0,0,0,0,0,0,0,0,0,0,0,0,0,5,5,5,0,0,0,0,0,0,0
0,0,11,5,5,5,5,5,5,5,11,0,11,5,0,5,5,5,5,11,0,0,0
0,0,5,44,43,0,41,0,40,39,5,0,5,5,0,5,16,0,0,5,0,0,0
0,0,5,0,0,0,0,0,0,0,5,0,28,0,0,0,0,0,0,28,0,0,0
0,0,5,0,0,0,0,0,0,0,5,0,5,0,0,0,0,0,0,5,0,0,0
0,0,5,0,0,0,0,0,0,0,5,0,28,0,0,0,0,0,0,28,0,0,0
0,0,11,0,0,0,0,0,0,0,11,0,5,0,0,0,0,0,0,5,0,0,0
0,0,5,0,0,0,0,0,0,0,5,0,11,5,28,5,5,5,32,11,0,0,0
0,0,5,0,0,0,0,0,0,0,5,0,0,0,0,0,0,0,0,0,0,0,0
0,0,5,0,0,0,0,0,0,0,38,0,0,0,0,0,0,0,0,0,0,0,0
0,0,5,0,0,0,0,0,0,0,5,9,9,9,9,9,9,0,0,0,0,27,0
0,0,11,5,5,11,0,0,11,5,5,11,0,0,0,0,0,0,0,0,0,0,0
0,0,5,0,0,9,0,0,9,0,0,5,9,9,9,9,9,0,0,0,0,27,0
0,0,5,0,0,10,0,0,9,0,0,5,0,0,0,0,0,0,0,0,0,0,0
0,0,5,0,0,9,0,0,22,0,0,5,0,0,0,0,0,0,0,0,0,0,0
0,0,5,0,0,9,0,0,9,0,0,5,0,0,0,0,0,9,0,9,0,0,0
0,0,11,9,9,9,0,0,9,9,9,11,0,0,0,11,5,5,33,5,11,0,0
0,0,5,0,0,9,0,0,9,0,0,5,0,0,0,5,12,34,0,29,5,0,0
0,0,5,0,0,10,0,0,9,0,0,5,0,0,0,5,35,9,0,30,5,0,0
0,0,5,0,0,9,0,0,22,0,0,5,0,0,0,5,36,0,0,18,5,0,0
0,0,5,0,0,9,0,0,9,0,0,5,0,0,0,5,36,0,0,31,5,0,0
0,0,11,9,9,9,0,0,9,9,9,11,0,0,0,11,5,5,5,5,11,0,0
0,0,5,0,0,9,0,0,9,0,0,5,0,0,0,0,0,0,0,0,0,0,0
0,0,5,0,0,10,0,0,9,0,0,5,0,0,0,0,0,0,0,0,0,0,0
0,0,5,0,0,9,0,0,22,0,0,5,0,0,0,0,0,0,0,0,0,0,0
0,0,5,0,0,9,0,0,9,0,0,5,0,0,0,0,0,0,0,0,0,0,0
0,0,11,5,5,11,42,33,11,5,5,11,0,0,0,0,0,0,0,0,0,0,0
0,0,0,0,0,0,0,0,0,0,0,0,0,0,0,0,0,0,0,0,0,0,0
0,0,0,0,0,0,0,0,0,0,0,0,0,0,27,0,0,0,0,0,27,0,0
0,0,0,0,0,0,0,0,0,0,0,0,0,0,0,0,0,0,0,0,0,0,0
0,0,0,0,0,0,0,0,0,0,0,0,0,0,27,0,0,0,0,0,0,0,0
0,0,0,0,0,0,0,0,0,0,0,0,0,0,0,0,0,0,0,0,0,0,0
0,0,27,0,0,0,0,0,0,0,0,0,0,0,0,0,0,0,0,0,0,0,0
0,0,0,0,0,0,0,0,0,0,0,0,0,0,0,0,0,0,0,0,0,0,0
0,0,0,0,0,0,0,0,0,0,0,0,0,0,0,0,0,0,0,0,0,0,0
0,0,0,0,0,0,0,0,0,0,0,0,0,0,0,0,0,0,0,0,0,0,0
0,0,27,0,0,0,0,0,0,0,0,0,27,0,27,0,0,0,0,0,27,0,0
0,0,0,0,0,0,0,0,0,0,0,0,0,0,0,0,0,0,0,0,0,0,0
0,0,0,0,0,0,0,0,0,0,0,0,0,0,0,0,0,0,0,0,0,0,0
:endlayer
layer: 8
0,0,0,0,0,0,0,0,0,0,0,0,0,0,0,0,0,0,0,0,0,0,0
0,0,0,0,0,0,0,0,0,0,0,0,0,0,0,0,0,0,0,0,0,0,0
0,0,47,0,0,0,0,0,0,0,47,0,47,5,5,5,0,0,0,47,0,0,0
0,54,11,5,9,5,9,5,9,5,11,0,11,5,5,5,5,5,5,11,45,0,0
0,0,5,0,0,0,0,0,0,0,5,0,5,5,5,16,0,0,48,5,0,0,0
0,0,5,0,0,0,0,0,0,0,5,0,5,48,0,0,0,0,0,5,0,0,0
0,0,9,0,0,0,0,0,0,0,9,0,5,0,0,0,0,0,0,5,0,0,0
0,0,5,0,0,0,0,0,0,0,5,0,5,0,0,0,0,0,0,5,0,0,0
0,54,11,0,0,0,0,0,0,0,11,0,5,47,0,0,0,0,47,5,0,0,0
0,0,5,0,0,0,0,0,0,0,5,0,11,5,5,5,5,5,5,11,45,0,0
0,0,9,0,0,0,0,0,0,0,5,0,0,0,0,0,0,0,49,48,0,0,0
0,0,5,0,0,0,0,0,0,0,56,0,0,0,0,0,0,0,0,0,0,0,0
0,0,5,0,0,47,0,0,47,0,5,47,35,55,0,0,0,0,0,0,0,0,0
0,54,11,5,5,11,0,0,11,5,5,11,35,55,0,0,0,0,0,0,0,0,0
0,0,5,0,0,0,0,0,0,0,0,5,35,55,0,0,0,0,0,0,0,0,0
0,0,5,0,0,0,0,0,0,0,0,5,0,0,0,0,0,0,0,0,0,0,0
0,0,55,0,0,0,0,0,0,0,0,55,0,0,0,0,0,0,0,0,0,0,0
0,0,5,0,0,0,0,0,0,0,0,5,0,0,0,47,0,47,0,47,0,0,0
0,54,11,45,0,9,0,0,9,0,54,11,45,0,54,11,5,5,50,5,11,0,0
0,0,5,0,0,0,0,0,0,0,0,5,0,0,0,5,0,0,0,0,5,0,0
0,0,5,0,0,0,0,0,0,0,0,5,0,0,0,5,0,51,0,0,46,0,0
0,0,55,0,0,0,0,0,0,0,0,55,0,0,0,5,52,0,0,0,5,0,0
0,0,5,0,0,0,0,0,0,0,0,5,0,0,0,5,53,0,0,0,5,0,0
0,54,11,45,0,9,0,0,9,0,54,11,45,0,0,11,5,5,46,5,11,0,0
0,0,5,0,0,0,0,0,0,0,0,5,0,0,0,0,0,0,0,0,0,0,0
0,0,5,0,0,0,0,0,0,0,0,5,0,0,0,0,0,0,0,0,0,0,0
0,0,55,0,0,0,0,0,0,0,0,55,0,0,0,0,0,0,0,0,0,0,0
0,0,5,0,0,0,0,0,0,0,0,5,0,0,0,0,0,0,0,0,0,0,0
0,54,11,5,5,11,58,57,11,5,5,11,45,0,0,0,0,0,0,0,0,0,0
0,0,48,0,0,48,0,0,48,0,0,48,0,0,0,0,0,0,0,0,0,0,0
0,0,0,0,0,0,0,0,0,0,0,0,0,0,0,0,0,0,0,0,0,0,0
0,0,0,0,0,0,0,0,0,0,0,0,0,0,0,0,0,0,0,0,0,0,0
0,0,0,0,0,0,0,0,0,0,0,0,0,0,0,0,0,0,0,0,0,0,0
0,0,0,0,0,0,0,0,0,0,0,0,0,0,0,0,0,0,0,0,0,0,0
0,0,0,0,0,0,0,0,0,0,0,0,0,0,0,0,0,0,0,0,0,0,0
0,0,0,0,0,0,0,0,0,0,0,0,0,0,0,0,0,0,0,0,0,0,0
0,0,0,0,0,0,0,0,0,0,0,0,0,0,0,0,0,0,0,0,0,0,0
0,0,0,0,0,0,0,0,0,0,0,0,0,0,0,0,0,0,0,0,0,0,0
0,0,0,0,0,0,0,0,0,0,0,0,0,0,0,0,0,0,0,0,0,0,0
0,0,0,0,0,0,0,0,0,0,0,0,0,0,0,0,0,0,0,0,0,0,0
0,0,0,0,0,0,0,0,0,0,0,0,0,0,0,0,0,0,0,0,0,0,0
:endlayer
layer: 9
0,0,0,0,0,0,0,0,0,0,0,0,0,0,0,0,0,0,0,0,0,0,0
0,0,0,0,0,0,0,0,0,0,0,0,0,0,0,0,0,0,0,0,0,0,0
0,62,0,0,0,0,0,0,0,0,0,0,0,5,5,5,0,0,0,0,0,0,0
0,62,11,5,5,5,5,5,5,5,11,0,11,5,5,5,5,5,5,11,0,0,0
0,62,5,0,0,0,0,0,0,0,5,0,5,5,16,0,0,0,0,59,0,0,0
0,62,5,0,0,0,0,0,0,0,5,0,5,12,12,12,12,12,12,59,0,0,0
0,62,5,0,0,0,0,0,0,0,5,0,5,12,12,12,12,12,12,59,0,0,0
0,62,5,0,0,0,0,0,0,0,5,0,59,12,12,12,12,12,12,59,0,0,0
0,62,11,0,0,0,0,0,0,0,11,0,59,12,12,12,12,12,12,59,0,0,0
0,62,5,0,0,0,0,0,0,0,5,0,11,60,60,60,60,60,60,11,0,0,0
0,62,5,0,0,0,0,0,0,0,5,0,0,0,0,0,0,0,0,0,0,0,0
0,62,5,0,0,0,0,0,0,0,5,0,0,0,0,0,0,0,0,0,0,0,0
0,62,62,0,0,0,0,0,0,0,5,12,63,0,0,0,0,0,0,0,0,0,0
0,0,62,11,11,11,0,0,11,11,11,35,63,0,0,0,0,0,0,0,0,0,0
0,0,62,0,0,48,0,0,48,0,0,35,63,0,0,0,0,0,0,0,0,0,0
0,0,62,0,0,0,0,0,0,0,0,35,63,0,0,0,0,0,0,0,0,0,0
0,0,62,0,0,0,0,0,0,0,0,35,63,0,0,0,0,0,0,0,0,0,0
0,0,62,0,0,0,0,0,0,0,0,35,63,62,61,0,0,0,0,0,47,0,0
0,0,62,0,0,9,0,0,9,0,0,35,63,62,61,11,5,5,5,5,11,45,0
0,0,62,0,0,0,0,0,0,0,0,35,63,62,61,5,0,0,0,0,5,0,0
0,0,62,0,0,0,0,0,0,0,0,35,63,62,61,5,0,0,0,0,5,0,0
0,0,62,0,0,0,0,0,0,0,0,35,63,62,61,5,0,0,0,0,5,0,0
0,0,62,0,0,0,0,0,0,0,0,35,63,62,61,5,0,0,0,0,5,0,0
0,0,62,0,0,9,0,0,9,0,0,35,63,62,61,11,5,5,5,5,11,45,0
0,0,62,0,0,0,0,0,0,0,0,35,63,62,61,48,0,0,0,0,48,0,0
0,0,62,0,0,0,0,0,0,0,0,35,63,0,0,0,0,0,0,0,0,0,0
0,0,62,0,0,0,0,0,0,0,0,35,63,0,0,0,0,0,0,0,0,0,0
0,0,62,0,0,47,0,0,47,0,0,35,63,0,0,0,0,0,0,0,0,0,0
0,0,62,11,11,11,9,9,11,11,11,35,63,0,0,0,0,0,0,0,0,0,0
0,0,62,0,0,0,0,0,0,0,0,35,63,0,0,0,0,0,0,0,0,0,0
0,0,0,0,0,0,0,0,0,0,0,0,0,0,0,0,0,0,0,0,0,0,0
0,0,0,0,0,0,0,0,0,0,0,0,0,0,0,0,0,0,0,0,0,0,0
0,0,0,0,0,0,0,0,0,0,0,0,0,0,0,0,0,0,0,0,0,0,0
0,0,0,0,0,0,0,0,0,0,0,0,0,0,0,0,0,0,0,0,0,0,0
0,0,0,0,0,0,0,0,0,0,0,0,0,0,0,0,0,0,0,0,0,0,0
0,0,0,0,0,0,0,0,0,0,0,0,0,0,0,0,0,0,0,0,0,0,0
0,0,0,0,0,0,0,0,0,0,0,0,0,0,0,0,0,0,0,0,0,0,0
0,0,0,0,0,0,0,0,0,0,0,0,0,0,0,0,0,0,0,0,0,0,0
0,0,0,0,0,0,0,0,0,0,0,0,0,0,0,0,0,0,0,0,0,0,0
0,0,0,0,0,0,0,0,0,0,0,0,0,0,0,0,0,0,0,0,0,0,0
0,0,0,0,0,0,0,0,0,0,0,0,0,0,0,0,0,0,0,0,0,0,0
:endlayer
layer: 10
0,0,0,0,0,0,0,0,0,0,0,0,0,0,0,0,0,0,0,0,0,0,0
0,0,0,0,0,0,0,0,0,0,0,0,0,0,0,0,0,0,0,0,0,0,0
0,0,62,0,0,0,0,0,0,0,35,55,55,65,5,16,55,55,55,55,55,0,0
0,0,62,60,60,60,60,60,60,60,35,55,11,5,5,5,12,12,12,11,55,0,0
0,0,62,48,0,0,0,0,0,48,35,55,12,0,0,0,0,0,0,12,55,0,0
0,0,62,0,0,0,0,0,0,0,35,55,12,0,0,0,0,0,0,12,55,0,0
0,0,62,0,0,0,0,0,0,0,35,55,12,0,0,0,0,0,0,12,55,0,0
0,0,62,0,0,0,0,0,0,0,35,55,12,0,0,52,52,0,0,12,55,0,0
0,0,62,0,0,0,0,0,0,0,35,55,12,66,36,53,53,36,64,12,55,0,0
0,0,62,0,0,0,0,0,0,0,35,55,11,12,12,12,12,12,12,11,55,0,0
0,0,62,0,0,0,0,0,0,0,35,55,55,55,55,55,55,55,55,55,55,0,0
0,0,62,60,60,60,60,60,60,60,35,55,0,0,0,0,0,0,0,0,0,0,0
0,0,62,63,62,0,0,0,0,35,35,0,0,0,0,0,0,0,0,0,0,0,0
0,0,0,63,62,11,11,11,11,35,63,0,0,0,0,0,0,0,0,0,0,0,0
0,0,0,63,62,9,0,0,9,35,63,0,0,0,0,0,0,0,0,0,0,0,0
0,0,0,63,62,9,0,0,9,35,63,0,0,0,0,0,0,0,0,0,0,0,0
0,0,0,63,62,9,0,0,9,35,63,0,0,0,0,0,0,0,0,0,0,0,0
0,0,0,63,62,9,0,0,9,35,63,0,0,0,62,0,0,0,0,0,0,35,0
0,0,0,63,62,9,0,0,9,35,63,0,0,0,62,11,11,11,11,11,11,35,0
0,0,0,63,62,9,0,0,9,35,63,0,0,0,62,11,48,0,0,48,11,35,0
0,0,0,63,62,9,0,0,9,35,63,0,0,0,62,11,0,0,0,0,11,35,0
0,0,0,63,62,9,0,0,9,35,63,0,0,0,62,11,0,0,0,0,11,35,0
0,0,0,63,62,9,0,0,9,35,63,0,0,0,62,11,47,0,0,47,11,35,0
0,0,0,63,62,9,0,0,9,35,63,0,0,0,62,11,11,11,11,11,11,35,0
0,0,0,63,62,9,0,0,9,35,63,0,0,0,62,0,0,0,0,0,0,35,0
0,0,0,63,62,9,0,0,9,35,63,0,0,0,0,0,0,0,0,0,0,0,0
0,0,0,63,62,9,0,0,9,35,63,0,0,0,0,0,0,0,0,0,0,0,0
0,0,0,63,62,9,0,0,9,35,63,0,0,0,0,0,0,0,0,0,0,0,0
0,0,0,63,62,11,11,11,11,35,63,0,0,0,0,0,0,0,0,0,0,0,0
0,0,0,63,62,0,0,0,0,35,63,0,0,0,0,0,0,0,0,0,0,0,0
0,0,0,0,0,0,0,0,0,0,0,0,0,0,0,0,0,0,0,0,0,0,0
0,0,0,0,0,0,0,0,0,0,0,0,0,0,0,0,0,0,0,0,0,0,0
0,0,0,0,0,0,0,0,0,0,0,0,0,0,0,0,0,0,0,0,0,0,0
0,0,0,0,0,0,0,0,0,0,0,0,0,0,0,0,0,0,0,0,0,0,0
0,0,0,0,0,0,0,0,0,0,0,0,0,0,0,0,0,0,0,0,0,0,0
0,0,0,0,0,0,0,0,0,0,0,0,0,0,0,0,0,0,0,0,0,0,0
0,0,0,0,0,0,0,0,0,0,0,0,0,0,0,0,0,0,0,0,0,0,0
0,0,0,0,0,0,0,0,0,0,0,0,0,0,0,0,0,0,0,0,0,0,0
0,0,0,0,0,0,0,0,0,0,0,0,0,0,0,0,0,0,0,0,0,0,0
0,0,0,0,0,0,0,0,0,0,0,0,0,0,0,0,0,0,0,0,0,0,0
0,0,0,0,0,0,0,0,0,0,0,0,0,0,0,0,0,0,0,0,0,0,0
:endlayer
layer: 11
0,0,0,0,0,0,0,0,0,0,0,0,0,0,0,0,0,0,0,0,0,0,0
0,0,0,0,0,0,0,0,0,0,0,0,0,0,0,0,0,0,0,0,0,0,0
0,0,0,62,0,0,47,0,0,35,0,0,0,0,5,0,0,0,0,0,0,0,0
0,0,0,62,12,12,12,12,12,35,0,0,11,12,5,12,12,28,12,11,0,0,0
0,0,0,62,0,0,0,0,0,35,0,0,12,0,0,0,0,0,0,12,0,0,0
0,0,0,62,0,0,0,0,0,35,0,0,28,0,0,0,0,0,0,28,0,0,0
0,0,0,62,0,0,0,0,0,35,0,0,12,0,0,0,0,0,0,12,0,0,0
0,0,0,62,0,0,0,0,0,35,0,0,28,0,0,0,0,0,0,28,0,0,0
0,0,0,62,0,0,0,0,0,35,0,0,12,0,27,0,0,27,0,12,0,0,0
0,0,0,62,0,0,0,0,0,35,0,0,11,12,28,12,12,28,12,11,0,0,0
0,0,0,62,0,0,0,0,0,35,0,0,0,0,0,0,0,0,0,0,0,0,0
0,0,0,62,12,12,12,12,12,35,0,0,0,0,0,0,0,0,0,0,0,0,0
0,0,0,62,0,63,62,35,63,35,0,0,0,0,0,0,0,0,0,0,0,0,0
0,0,0,0,0,63,62,35,63,0,0,0,0,0,0,0,0,0,0,0,0,0,0
0,0,0,0,0,63,62,35,63,0,0,0,0,0,0,0,0,0,0,0,0,0,0
0,0,0,0,0,63,62,35,63,0,0,0,0,0,0,0,0,0,0,0,0,0,0
0,0,0,0,0,63,62,35,63,0,0,0,0,0,0,0,0,0,0,0,0,0,0
0,0,0,0,0,63,62,35,63,0,0,0,0,0,0,62,0,0,0,0,35,0,0
0,0,0,0,0,63,62,35,63,0,0,0,0,0,0,62,11,28,28,11,35,0,0
0,0,0,0,0,63,62,35,63,0,0,0,0,0,0,62,0,0,0,0,35,0,0
0,0,0,0,0,63,62,35,63,0,0,0,0,0,0,62,0,0,0,0,35,0,0
0,0,0,0,0,63,62,35,63,0,0,0,0,0,0,62,0,0,0,0,35,0,0
0,0,0,0,0,63,62,35,63,0,0,0,0,0,0,62,0,0,0,0,35,0,0
0,0,0,0,0,63,62,35,63,0,0,0,0,0,0,62,11,28,28,11,35,0,0
0,0,0,0,0,63,62,35,63,0,0,0,0,0,0,62,0,0,0,0,35,0,0
0,0,0,0,0,63,62,35,63,0,0,0,0,0,0,0,0,0,0,0,0,0,0
0,0,0,0,0,63,62,35,63,0,0,0,0,0,0,0,0,0,0,0,0,0,0
0,0,0,0,0,63,62,35,63,0,0,0,0,0,0,0,0,0,0,0,0,0,0
0,0,0,0,0,63,62,35,63,0,0,0,0,0,0,0,0,0,0,0,0,0,0
0,0,0,0,0,63,62,35,63,0,0,0,0,0,0,0,0,0,0,0,0,0,0
0,0,0,0,0,0,0,0,0,0,0,0,0,0,0,0,0,0,0,0,0,0,0
0,0,0,0,0,0,0,0,0,0,0,0,0,0,0,0,0,0,0,0,0,0,0
0,0,0,0,0,0,0,0,0,0,0,0,0,0,0,0,0,0,0,0,0,0,0
0,0,0,0,0,0,0,0,0,0,0,0,0,0,0,0,0,0,0,0,0,0,0
0,0,0,0,0,0,0,0,0,0,0,0,0,0,0,0,0,0,0,0,0,0,0
0,0,0,0,0,0,0,0,0,0,0,0,0,0,0,0,0,0,0,0,0,0,0
0,0,0,0,0,0,0,0,0,0,0,0,0,0,0,0,0,0,0,0,0,0,0
0,0,0,0,0,0,0,0,0,0,0,0,0,0,0,0,0,0,0,0,0,0,0
0,0,0,0,0,0,0,0,0,0,0,0,0,0,0,0,0,0,0,0,0,0,0
0,0,0,0,0,0,0,0,0,0,0,0,0,0,0,0,0,0,0,0,0,0,0
0,0,0,0,0,0,0,0,0,0,0,0,0,0,0,0,0,0,0,0,0,0,0
:endlayer
layer: 12
0,0,0,0,0,0,0,0,0,0,0,0,0,0,0,0,0,0,0,0,0,0,0
0,0,0,0,0,0,0,0,0,0,0,0,0,0,0,0,0,0,0,0,0,0,0
0,0,0,0,62,0,0,0,35,0,0,15,15,15,5,15,15,68,15,15,15,0,0
0,0,0,0,62,12,9,12,35,0,0,0,11,12,5,12,12,12,12,11,0,0,0
0,0,0,0,62,0,0,0,35,0,0,0,12,45,0,0,0,0,54,12,0,0,0
0,0,0,0,62,0,0,0,35,0,0,0,12,0,0,0,0,0,0,12,0,0,0
0,0,0,0,62,0,0,0,35,0,0,0,12,0,0,0,0,0,0,12,0,0,0
0,0,0,0,62,0,0,0,35,0,0,0,12,0,0,0,0,0,0,12,0,0,0
0,0,0,0,62,0,0,0,35,0,0,0,12,0,0,0,0,0,0,12,0,0,0
0,0,0,0,62,0,0,0,35,0,0,0,11,12,12,12,12,12,12,11,0,0,0
0,0,0,0,62,0,0,0,35,0,0,34,34,34,49,34,34,49,34,34,34,0,0
0,0,0,0,62,12,9,12,35,0,0,0,0,0,0,0,0,0,0,0,0,0,0
0,0,0,0,62,48,0,48,35,0,0,0,0,0,0,0,0,0,0,0,0,0,0
0,0,0,0,0,0,0,0,0,0,0,0,0,0,0,0,0,0,0,0,0,0,0
0,0,0,0,0,0,0,0,0,0,0,0,0,0,0,0,0,0,0,0,0,0,0
0,0,0,0,0,0,0,0,0,0,0,0,0,0,0,0,0,0,0,0,0,0,0
0,0,0,0,0,0,0,0,0,0,0,0,0,0,0,0,0,0,0,0,0,0,0
0,0,0,0,0,0,0,0,0,0,0,0,0,0,0,0,62,67,67,35,0,0,0
0,0,0,0,0,0,0,0,0,0,0,0,0,0,0,0,62,11,11,35,0,0,0
0,0,0,0,0,0,0,0,0,0,0,0,0,0,0,0,62,0,0,35,0,0,0
0,0,0,0,0,0,0,0,0,0,0,0,0,0,0,0,62,0,0,35,0,0,0
0,0,0,0,0,0,0,0,0,0,0,0,0,0,0,0,62,0,0,35,0,0,0
0,0,0,0,0,0,0,0,0,0,0,0,0,0,0,0,62,0,0,35,0,0,0
0,0,0,0,0,0,0,0,0,0,0,0,0,0,0,0,62,11,11,35,0,0,0
0,0,0,0,0,0,0,0,0,0,0,0,0,0,0,0,62,67,67,35,0,0,0
0,0,0,0,0,0,0,0,0,0,0,0,0,0,0,0,0,0,0,0,0,0,0
0,0,0,0,0,0,0,0,0,0,0,0,0,0,0,0,0,0,0,0,0,0,0
0,0,0,0,0,0,0,0,0,0,0,0,0,0,0,0,0,0,0,0,0,0,0
0,0,0,0,0,0,0,0,0,0,0,0,0,0,0,0,0,0,0,0,0,0,0
0,0,0,0,0,0,0,0,0,0,0,0,0,0,0,0,0,0,0,0,0,0,0
0,0,0,0,0,0,0,0,0,0,0,0,0,0,0,0,0,0,0,0,0,0,0
0,0,0,0,0,0,0,0,0,0,0,0,0,0,0,0,0,0,0,0,0,0,0
0,0,0,0,0,0,0,0,0,0,0,0,0,0,0,0,0,0,0,0,0,0,0
0,0,0,0,0,0,0,0,0,0,0,0,0,0,0,0,0,0,0,0,0,0,0
0,0,0,0,0,0,0,0,0,0,0,0,0,0,0,0,0,0,0,0,0,0,0
0,0,0,0,0,0,0,0,0,0,0,0,0,0,0,0,0,0,0,0,0,0,0
0,0,0,0,0,0,0,0,0,0,0,0,0,0,0,0,0,0,0,0,0,0,0
0,0,0,0,0,0,0,0,0,0,0,0,0,0,0,0,0,0,0,0,0,0,0
0,0,0,0,0,0,0,0,0,0,0,0,0,0,0,0,0,0,0,0,0,0,0
0,0,0,0,0,0,0,0,0,0,0,0,0,0,0,0,0,0,0,0,0,0,0
0,0,0,0,0,0,0,0,0,0,0,0,0,0,0,0,0,0,0,0,0,0,0
:endlayer
layer: 13
0,0,0,0,0,0,0,0,0,0,0,0,0,0,0,0,0,0,0,0,0,0,0
0,0,0,0,0,0,0,0,0,0,0,0,0,0,0,0,0,0,0,0,0,0,0
0,0,0,0,0,62,68,35,0,0,0,0,0,0,5,0,0,0,0,0,0,0,0
0,0,0,0,0,62,12,35,0,0,0,15,15,15,5,15,15,15,15,15,15,0,0
0,0,0,0,0,62,12,35,0,0,0,0,59,0,0,0,0,0,0,59,0,0,0
0,0,0,0,0,62,12,35,0,0,0,0,59,0,0,0,0,0,0,59,0,0,0
0,0,0,0,0,62,12,35,0,0,0,0,59,0,0,0,0,0,0,59,0,0,0
0,0,0,0,0,62,12,35,0,0,0,0,59,0,0,0,0,0,0,59,0,0,0
0,0,0,0,0,62,12,35,0,0,0,0,59,0,0,0,0,0,0,59,0,0,0
0,0,0,0,0,62,12,35,0,0,0,34,34,34,34,34,34,34,34,34,34,0,0
0,0,0,0,0,62,12,35,0,0,0,0,0,0,0,0,0,0,0,0,0,0,0
0,0,0,0,0,62,12,35,0,0,0,0,0,0,0,0,0,0,0,0,0,0,0
0,0,0,0,0,62,49,35,0,0,0,0,0,0,0,0,0,0,0,0,0,0,0
0,0,0,0,0,0,0,0,0,0,0,0,0,0,0,0,0,0,0,0,0,0,0
0,0,0,0,0,0,0,0,0,0,0,0,0,0,0,0,0,0,0,0,0,0,0
0,0,0,0,0,0,0,0,0,0,0,0,0,0,0,0,0,0,0,0,0,0,0
0,0,0,0,0,0,0,0,0,0,0,0,0,0,0,0,0,0,0,0,0,0,0
0,0,0,0,0,0,0,0,0,0,0,0,0,0,0,0,0,0,0,0,0,0,0
0,0,0,0,0,0,0,0,0,0,0,0,0,0,0,0,0,63,63,0,0,0,0
0,0,0,0,0,0,0,0,0,0,0,0,0,0,0,0,0,62,35,0,0,0,0
0,0,0,0,0,0,0,0,0,0,0,0,0,0,0,0,0,62,35,0,0,0,0
0,0,0,0,0,0,0,0,0,0,0,0,0,0,0,0,0,62,35,0,0,0,0
0,0,0,0,0,0,0,0,0,0,0,0,0,0,0,0,0,62,35,0,0,0,0
0,0,0,0,0,0,0,0,0,0,0,0,0,0,0,0,0,63,63,0,0,0,0
0,0,0,0,0,0,0,0,0,0,0,0,0,0,0,0,0,0,0,0,0,0,0
0,0,0,0,0,0,0,0,0,0,0,0,0,0,0,0,0,0,0,0,0,0,0
0,0,0,0,0,0,0,0,0,0,0,0,0,0,0,0,0,0,0,0,0,0,0
0,0,0,0,0,0,0,0,0,0,0,0,0,0,0,0,0,0,0,0,0,0,0
0,0,0,0,0,0,0,0,0,0,0,0,0,0,0,0,0,0,0,0,0,0,0
0,0,0,0,0,0,0,0,0,0,0,0,0,0,0,0,0,0,0,0,0,0,0
0,0,0,0,0,0,0,0,0,0,0,0,0,0,0,0,0,0,0,0,0,0,0
0,0,0,0,0,0,0,0,0,0,0,0,0,0,0,0,0,0,0,0,0,0,0
0,0,0,0,0,0,0,0,0,0,0,0,0,0,0,0,0,0,0,0,0,0,0
0,0,0,0,0,0,0,0,0,0,0,0,0,0,0,0,0,0,0,0,0,0,0
0,0,0,0,0,0,0,0,0,0,0,0,0,0,0,0,0,0,0,0,0,0,0
0,0,0,0,0,0,0,0,0,0,0,0,0,0,0,0,0,0,0,0,0,0,0
0,0,0,0,0,0,0,0,0,0,0,0,0,0,0,0,0,0,0,0,0,0,0
0,0,0,0,0,0,0,0,0,0,0,0,0,0,0,0,0,0,0,0,0,0,0
0,0,0,0,0,0,0,0,0,0,0,0,0,0,0,0,0,0,0,0,0,0,0
0,0,0,0,0,0,0,0,0,0,0,0,0,0,0,0,0,0,0,0,0,0,0
0,0,0,0,0,0,0,0,0,0,0,0,0,0,0,0,0,0,0,0,0,0,0
:endlayer
layer: 14
0,0,0,0,0,0,0,0,0,0,0,0,0,0,0,0,0,0,0,0,0,0,0
0,0,0,0,0,0,0,0,0,0,0,0,0,0,0,0,0,0,0,0,0,0,0
0,0,0,0,0,0,0,0,0,0,0,0,0,0,5,0,0,0,0,0,0,0,0
0,0,0,0,0,0,0,0,0,0,0,0,0,0,5,0,0,0,0,0,0,0,0
0,0,0,0,0,0,0,0,0,0,0,15,15,15,15,15,15,15,15,15,15,0,0
0,0,0,0,0,0,0,0,0,0,0,0,12,0,0,0,0,0,0,12,0,0,0
0,0,0,0,0,0,0,0,0,0,0,54,12,0,0,0,0,0,0,12,45,0,0
0,0,0,0,0,0,0,0,0,0,0,0,12,0,0,0,0,0,0,12,0,0,0
0,0,0,0,0,0,0,0,0,0,0,34,34,34,34,34,34,34,34,34,34,0,0
0,0,0,0,0,0,0,0,0,0,0,0,0,0,0,0,0,0,0,0,0,0,0
0,0,0,0,0,0,0,0,0,0,0,0,0,0,0,0,0,0,0,0,0,0,0
0,0,0,0,0,0,0,0,0,0,0,0,0,0,0,0,0,0,0,0,0,0,0
0,0,0,0,0,0,0,0,0,0,0,0,0,0,0,0,0,0,0,0,0,0,0
0,0,0,0,0,0,0,0,0,0,0,0,0,0,0,0,0,0,0,0,0,0,0
0,0,0,0,0,0,0,0,0,0,0,0,0,0,0,0,0,0,0,0,0,0,0
0,0,0,0,0,0,0,0,0,0,0,0,0,0,0,0,0,0,0,0,0,0,0
0,0,0,0,0,0,0,0,0,0,0,0,0,0,0,0,0,0,0,0,0,0,0
0,0,0,0,0,0,0,0,0,0,0,0,0,0,0,0,0,0,0,0,0,0,0
0,0,0,0,0,0,0,0,0,0,0,0,0,0,0,0,0,0,0,0,0,0,0
0,0,0,0,0,0,0,0,0,0,0,0,0,0,0,0,0,0,0,0,0,0,0
0,0,0,0,0,0,0,0,0,0,0,0,0,0,0,0,0,0,0,0,0,0,0
0,0,0,0,0,0,0,0,0,0,0,0,0,0,0,0,0,0,0,0,0,0,0
0,0,0,0,0,0,0,0,0,0,0,0,0,0,0,0,0,0,0,0,0,0,0
0,0,0,0,0,0,0,0,0,0,0,0,0,0,0,0,0,0,0,0,0,0,0
0,0,0,0,0,0,0,0,0,0,0,0,0,0,0,0,0,0,0,0,0,0,0
0,0,0,0,0,0,0,0,0,0,0,0,0,0,0,0,0,0,0,0,0,0,0
0,0,0,0,0,0,0,0,0,0,0,0,0,0,0,0,0,0,0,0,0,0,0
0,0,0,0,0,0,0,0,0,0,0,0,0,0,0,0,0,0,0,0,0,0,0
0,0,0,0,0,0,0,0,0,0,0,0,0,0,0,0,0,0,0,0,0,0,0
0,0,0,0,0,0,0,0,0,0,0,0,0,0,0,0,0,0,0,0,0,0,0
0,0,0,0,0,0,0,0,0,0,0,0,0,0,0,0,0,0,0,0,0,0,0
0,0,0,0,0,0,0,0,0,0,0,0,0,0,0,0,0,0,0,0,0,0,0
0,0,0,0,0,0,0,0,0,0,0,0,0,0,0,0,0,0,0,0,0,0,0
0,0,0,0,0,0,0,0,0,0,0,0,0,0,0,0,0,0,0,0,0,0,0
0,0,0,0,0,0,0,0,0,0,0,0,0,0,0,0,0,0,0,0,0,0,0
0,0,0,0,0,0,0,0,0,0,0,0,0,0,0,0,0,0,0,0,0,0,0
0,0,0,0,0,0,0,0,0,0,0,0,0,0,0,0,0,0,0,0,0,0,0
0,0,0,0,0,0,0,0,0,0,0,0,0,0,0,0,0,0,0,0,0,0,0
0,0,0,0,0,0,0,0,0,0,0,0,0,0,0,0,0,0,0,0,0,0,0
0,0,0,0,0,0,0,0,0,0,0,0,0,0,0,0,0,0,0,0,0,0,0
0,0,0,0,0,0,0,0,0,0,0,0,0,0,0,0,0,0,0,0,0,0,0
:endlayer
layer: 15
0,0,0,0,0,0,0,0,0,0,0,0,0,0,0,0,0,0,0,0,0,0,0
0,0,0,0,0,0,0,0,0,0,0,0,0,0,0,0,0,0,0,0,0,0,0
0,0,0,0,0,0,0,0,0,0,0,0,0,0,5,0,0,0,0,0,0,0,0
0,0,0,0,0,0,0,0,0,0,0,0,0,0,5,0,0,0,0,0,0,0,0
0,0,0,0,0,0,0,0,0,0,0,0,0,0,0,0,0,0,0,0,0,0,0
0,0,0,0,0,0,0,0,0,0,0,15,15,15,15,15,15,15,15,15,15,0,0
0,0,0,0,0,0,0,0,0,0,0,70,12,12,12,61,12,12,12,12,69,0,0
0,0,0,0,0,0,0,0,0,0,0,34,34,34,34,34,34,34,34,34,34,0,0
0,0,0,0,0,0,0,0,0,0,0,0,0,0,0,0,0,0,0,0,0,0,0
0,0,0,0,0,0,0,0,0,0,0,0,0,0,0,0,0,0,0,0,0,0,0
0,0,0,0,0,0,0,0,0,0,0,0,0,0,0,0,0,0,0,0,0,0,0
0,0,0,0,0,0,0,0,0,0,0,0,0,0,0,0,0,0,0,0,0,0,0
0,0,0,0,0,0,0,0,0,0,0,0,0,0,0,0,0,0,0,0,0,0,0
0,0,0,0,0,0,0,0,0,0,0,0,0,0,0,0,0,0,0,0,0,0,0
0,0,0,0,0,0,0,0,0,0,0,0,0,0,0,0,0,0,0,0,0,0,0
0,0,0,0,0,0,0,0,0,0,0,0,0,0,0,0,0,0,0,0,0,0,0
0,0,0,0,0,0,0,0,0,0,0,0,0,0,0,0,0,0,0,0,0,0,0
0,0,0,0,0,0,0,0,0,0,0,0,0,0,0,0,0,0,0,0,0,0,0
0,0,0,0,0,0,0,0,0,0,0,0,0,0,0,0,0,0,0,0,0,0,0
0,0,0,0,0,0,0,0,0,0,0,0,0,0,0,0,0,0,0,0,0,0,0
0,0,0,0,0,0,0,0,0,0,0,0,0,0,0,0,0,0,0,0,0,0,0
0,0,0,0,0,0,0,0,0,0,0,0,0,0,0,0,0,0,0,0,0,0,0
0,0,0,0,0,0,0,0,0,0,0,0,0,0,0,0,0,0,0,0,0,0,0
0,0,0,0,0,0,0,0,0,0,0,0,0,0,0,0,0,0,0,0,0,0,0
0,0,0,0,0,0,0,0,0,0,0,0,0,0,0,0,0,0,0,0,0,0,0
0,0,0,0,0,0,0,0,0,0,0,0,0,0,0,0,0,0,0,0,0,0,0
0,0,0,0,0,0,0,0,0,0,0,0,0,0,0,0,0,0,0,0,0,0,0
0,0,0,0,0,0,0,0,0,0,0,0,0,0,0,0,0,0,0,0,0,0,0
0,0,0,0,0,0,0,0,0,0,0,0,0,0,0,0,0,0,0,0,0,0,0
0,0,0,0,0,0,0,0,0,0,0,0,0,0,0,0,0,0,0,0,0,0,0
0,0,0,0,0,0,0,0,0,0,0,0,0,0,0,0,0,0,0,0,0,0,0
0,0,0,0,0,0,0,0,0,0,0,0,0,0,0,0,0,0,0,0,0,0,0
0,0,0,0,0,0,0,0,0,0,0,0,0,0,0,0,0,0,0,0,0,0,0
0,0,0,0,0,0,0,0,0,0,0,0,0,0,0,0,0,0,0,0,0,0,0
0,0,0,0,0,0,0,0,0,0,0,0,0,0,0,0,0,0,0,0,0,0,0
0,0,0,0,0,0,0,0,0,0,0,0,0,0,0,0,0,0,0,0,0,0,0
0,0,0,0,0,0,0,0,0,0,0,0,0,0,0,0,0,0,0,0,0,0,0
0,0,0,0,0,0,0,0,0,0,0,0,0,0,0,0,0,0,0,0,0,0,0
0,0,0,0,0,0,0,0,0,0,0,0,0,0,0,0,0,0,0,0,0,0,0
0,0,0,0,0,0,0,0,0,0,0,0,0,0,0,0,0,0,0,0,0,0,0
0,0,0,0,0,0,0,0,0,0,0,0,0,0,0,0,0,0,0,0,0,0,0
:endlayer
layer: 16
0,0,0,0,0,0,0,0,0,0,0,0,0,0,0,0,0,0,0,0,0,0,0
0,0,0,0,0,0,0,0,0,0,0,0,0,0,0,0,0,0,0,0,0,0,0
0,0,0,0,0,0,0,0,0,0,0,0,0,0,5,0,0,0,0,0,0,0,0
0,0,0,0,0,0,0,0,0,0,0,0,0,0,0,0,0,0,0,0,0,0,0
0,0,0,0,0,0,0,0,0,0,0,0,0,0,0,0,0,0,0,0,0,0,0
0,0,0,0,0,0,0,0,0,0,0,0,0,0,0,0,0,0,0,0,0,0,0
0,0,0,0,0,0,0,0,0,0,0,0,0,0,0,0,0,0,0,0,0,0,0
0,0,0,0,0,0,0,0,0,0,0,0,0,0,0,0,0,0,0,0,0,0,0
0,0,0,0,0,0,0,0,0,0,0,0,0,0,0,0,0,0,0,0,0,0,0
0,0,0,0,0,0,0,0,0,0,0,0,0,0,0,0,0,0,0,0,0,0,0
0,0,0,0,0,0,0,0,0,0,0,0,0,0,0,0,0,0,0,0,0,0,0
0,0,0,0,0,0,0,0,0,0,0,0,0,0,0,0,0,0,0,0,0,0,0
0,0,0,0,0,0,0,0,0,0,0,0,0,0,0,0,0,0,0,0,0,0,0
0,0,0,0,0,0,0,0,0,0,0,0,0,0,0,0,0,0,0,0,0,0,0
0,0,0,0,0,0,0,0,0,0,0,0,0,0,0,0,0,0,0,0,0,0,0
0,0,0,0,0,0,0,0,0,0,0,0,0,0,0,0,0,0,0,0,0,0,0
0,0,0,0,0,0,0,0,0,0,0,0,0,0,0,0,0,0,0,0,0,0,0
0,0,0,0,0,0,0,0,0,0,0,0,0,0,0,0,0,0,0,0,0,0,0
0,0,0,0,0,0,0,0,0,0,0,0,0,0,0,0,0,0,0,0,0,0,0
0,0,0,0,0,0,0,0,0,0,0,0,0,0,0,0,0,0,0,0,0,0,0
0,0,0,0,0,0,0,0,0,0,0,0,0,0,0,0,0,0,0,0,0,0,0
0,0,0,0,0,0,0,0,0,0,0,0,0,0,0,0,0,0,0,0,0,0,0
0,0,0,0,0,0,0,0,0,0,0,0,0,0,0,0,0,0,0,0,0,0,0
0,0,0,0,0,0,0,0,0,0,0,0,0,0,0,0,0,0,0,0,0,0,0
0,0,0,0,0,0,0,0,0,0,0,0,0,0,0,0,0,0,0,0,0,0,0
0,0,0,0,0,0,0,0,0,0,0,0,0,0,0,0,0,0,0,0,0,0,0
0,0,0,0,0,0,0,0,0,0,0,0,0,0,0,0,0,0,0,0,0,0,0
0,0,0,0,0,0,0,0,0,0,0,0,0,0,0,0,0,0,0,0,0,0,0
0,0,0,0,0,0,0,0,0,0,0,0,0,0,0,0,0,0,0,0,0,0,0
0,0,0,0,0,0,0,0,0,0,0,0,0,0,0,0,0,0,0,0,0,0,0
0,0,0,0,0,0,0,0,0,0,0,0,0,0,0,0,0,0,0,0,0,0,0
0,0,0,0,0,0,0,0,0,0,0,0,0,0,0,0,0,0,0,0,0,0,0
0,0,0,0,0,0,0,0,0,0,0,0,0,0,0,0,0,0,0,0,0,0,0
0,0,0,0,0,0,0,0,0,0,0,0,0,0,0,0,0,0,0,0,0,0,0
0,0,0,0,0,0,0,0,0,0,0,0,0,0,0,0,0,0,0,0,0,0,0
0,0,0,0,0,0,0,0,0,0,0,0,0,0,0,0,0,0,0,0,0,0,0
0,0,0,0,0,0,0,0,0,0,0,0,0,0,0,0,0,0,0,0,0,0,0
0,0,0,0,0,0,0,0,0,0,0,0,0,0,0,0,0,0,0,0,0,0,0
0,0,0,0,0,0,0,0,0,0,0,0,0,0,0,0,0,0,0,0,0,0,0
0,0,0,0,0,0,0,0,0,0,0,0,0,0,0,0,0,0,0,0,0,0,0
0,0,0,0,0,0,0,0,0,0,0,0,0,0,0,0,0,0,0,0,0,0,0
:endlayer
layer: 17
0,0,0,0,0,0,0,0,0,0,0,0,0,0,0,0,0,0,0,0,0,0,0
0,0,0,0,0,0,0,0,0,0,0,0,0,0,0,0,0,0,0,0,0,0,0
0,0,0,0,0,0,0,0,0,0,0,0,0,0,5,0,0,0,0,0,0,0,0
0,0,0,0,0,0,0,0,0,0,0,0,0,0,0,0,0,0,0,0,0,0,0
0,0,0,0,0,0,0,0,0,0,0,0,0,0,0,0,0,0,0,0,0,0,0
0,0,0,0,0,0,0,0,0,0,0,0,0,0,0,0,0,0,0,0,0,0,0
0,0,0,0,0,0,0,0,0,0,0,0,0,0,0,0,0,0,0,0,0,0,0
0,0,0,0,0,0,0,0,0,0,0,0,0,0,0,0,0,0,0,0,0,0,0
0,0,0,0,0,0,0,0,0,0,0,0,0,0,0,0,0,0,0,0,0,0,0
0,0,0,0,0,0,0,0,0,0,0,0,0,0,0,0,0,0,0,0,0,0,0
0,0,0,0,0,0,0,0,0,0,0,0,0,0,0,0,0,0,0,0,0,0,0
0,0,0,0,0,0,0,0,0,0,0,0,0,0,0,0,0,0,0,0,0,0,0
0,0,0,0,0,0,0,0,0,0,0,0,0,0,0,0,0,0,0,0,0,0,0
0,0,0,0,0,0,0,0,0,0,0,0,0,0,0,0,0,0,0,0,0,0,0
0,0,0,0,0,0,0,0,0,0,0,0,0,0,0,0,0,0,0,0,0,0,0
0,0,0,0,0,0,0,0,0,0,0,0,0,0,0,0,0,0,0,0,0,0,0
0,0,0,0,0,0,0,0,0,0,0,0,0,0,0,0,0,0,0,0,0,0,0
0,0,0,0,0,0,0,0,0,0,0,0,0,0,0,0,0,0,0,0,0,0,0
0,0,0,0,0,0,0,0,0,0,0,0,0,0,0,0,0,0,0,0,0,0,0
0,0,0,0,0,0,0,0,0,0,0,0,0,0,0,0,0,0,0,0,0,0,0
0,0,0,0,0,0,0,0,0,0,0,0,0,0,0,0,0,0,0,0,0,0,0
0,0,0,0,0,0,0,0,0,0,0,0,0,0,0,0,0,0,0,0,0,0,0
0,0,0,0,0,0,0,0,0,0,0,0,0,0,0,0,0,0,0,0,0,0,0
0,0,0,0,0,0,0,0,0,0,0,0,0,0,0,0,0,0,0,0,0,0,0
0,0,0,0,0,0,0,0,0,0,0,0,0,0,0,0,0,0,0,0,0,0,0
0,0,0,0,0,0,0,0,0,0,0,0,0,0,0,0,0,0,0,0,0,0,0
0,0,0,0,0,0,0,0,0,0,0,0,0,0,0,0,0,0,0,0,0,0,0
0,0,0,0,0,0,0,0,0,0,0,0,0,0,0,0,0,0,0,0,0,0,0
0,0,0,0,0,0,0,0,0,0,0,0,0,0,0,0,0,0,0,0,0,0,0
0,0,0,0,0,0,0,0,0,0,0,0,0,0,0,0,0,0,0,0,0,0,0
0,0,0,0,0,0,0,0,0,0,0,0,0,0,0,0,0,0,0,0,0,0,0
0,0,0,0,0,0,0,0,0,0,0,0,0,0,0,0,0,0,0,0,0,0,0
0,0,0,0,0,0,0,0,0,0,0,0,0,0,0,0,0,0,0,0,0,0,0
0,0,0,0,0,0,0,0,0,0,0,0,0,0,0,0,0,0,0,0,0,0,0
0,0,0,0,0,0,0,0,0,0,0,0,0,0,0,0,0,0,0,0,0,0,0
0,0,0,0,0,0,0,0,0,0,0,0,0,0,0,0,0,0,0,0,0,0,0
0,0,0,0,0,0,0,0,0,0,0,0,0,0,0,0,0,0,0,0,0,0,0
0,0,0,0,0,0,0,0,0,0,0,0,0,0,0,0,0,0,0,0,0,0,0
0,0,0,0,0,0,0,0,0,0,0,0,0,0,0,0,0,0,0,0,0,0,0
0,0,0,0,0,0,0,0,0,0,0,0,0,0,0,0,0,0,0,0,0,0,0
0,0,0,0,0,0,0,0,0,0,0,0,0,0,0,0,0,0,0,0,0,0,0
:endlayer
layer: 18
0,0,0,0,0,0,0,0,0,0,0,0,0,0,0,0,0,0,0,0,0,0,0
0,0,0,0,0,0,0,0,0,0,0,0,0,0,0,0,0,0,0,0,0,0,0
0,0,0,0,0,0,0,0,0,0,0,0,0,0,71,0,0,0,0,0,0,0,0
0,0,0,0,0,0,0,0,0,0,0,0,0,0,0,0,0,0,0,0,0,0,0
0,0,0,0,0,0,0,0,0,0,0,0,0,0,0,0,0,0,0,0,0,0,0
0,0,0,0,0,0,0,0,0,0,0,0,0,0,0,0,0,0,0,0,0,0,0
0,0,0,0,0,0,0,0,0,0,0,0,0,0,0,0,0,0,0,0,0,0,0
0,0,0,0,0,0,0,0,0,0,0,0,0,0,0,0,0,0,0,0,0,0,0
0,0,0,0,0,0,0,0,0,0,0,0,0,0,0,0,0,0,0,0,0,0,0
0,0,0,0,0,0,0,0,0,0,0,0,0,0,0,0,0,0,0,0,0,0,0
0,0,0,0,0,0,0,0,0,0,0,0,0,0,0,0,0,0,0,0,0,0,0
0,0,0,0,0,0,0,0,0,0,0,0,0,0,0,0,0,0,0,0,0,0,0
0,0,0,0,0,0,0,0,0,0,0,0,0,0,0,0,0,0,0,0,0,0,0
0,0,0,0,0,0,0,0,0,0,0,0,0,0,0,0,0,0,0,0,0,0,0
0,0,0,0,0,0,0,0,0,0,0,0,0,0,0,0,0,0,0,0,0,0,0
0,0,0,0,0,0,0,0,0,0,0,0,0,0,0,0,0,0,0,0,0,0,0
0,0,0,0,0,0,0,0,0,0,0,0,0,0,0,0,0,0,0,0,0,0,0
0,0,0,0,0,0,0,0,0,0,0,0,0,0,0,0,0,0,0,0,0,0,0
0,0,0,0,0,0,0,0,0,0,0,0,0,0,0,0,0,0,0,0,0,0,0
0,0,0,0,0,0,0,0,0,0,0,0,0,0,0,0,0,0,0,0,0,0,0
0,0,0,0,0,0,0,0,0,0,0,0,0,0,0,0,0,0,0,0,0,0,0
0,0,0,0,0,0,0,0,0,0,0,0,0,0,0,0,0,0,0,0,0,0,0
0,0,0,0,0,0,0,0,0,0,0,0,0,0,0,0,0,0,0,0,0,0,0
0,0,0,0,0,0,0,0,0,0,0,0,0,0,0,0,0,0,0,0,0,0,0
0,0,0,0,0,0,0,0,0,0,0,0,0,0,0,0,0,0,0,0,0,0,0
0,0,0,0,0,0,0,0,0,0,0,0,0,0,0,0,0,0,0,0,0,0,0
0,0,0,0,0,0,0,0,0,0,0,0,0,0,0,0,0,0,0,0,0,0,0
0,0,0,0,0,0,0,0,0,0,0,0,0,0,0,0,0,0,0,0,0,0,0
0,0,0,0,0,0,0,0,0,0,0,0,0,0,0,0,0,0,0,0,0,0,0
0,0,0,0,0,0,0,0,0,0,0,0,0,0,0,0,0,0,0,0,0,0,0
0,0,0,0,0,0,0,0,0,0,0,0,0,0,0,0,0,0,0,0,0,0,0
0,0,0,0,0,0,0,0,0,0,0,0,0,0,0,0,0,0,0,0,0,0,0
0,0,0,0,0,0,0,0,0,0,0,0,0,0,0,0,0,0,0,0,0,0,0
0,0,0,0,0,0,0,0,0,0,0,0,0,0,0,0,0,0,0,0,0,0,0
0,0,0,0,0,0,0,0,0,0,0,0,0,0,0,0,0,0,0,0,0,0,0
0,0,0,0,0,0,0,0,0,0,0,0,0,0,0,0,0,0,0,0,0,0,0
0,0,0,0,0,0,0,0,0,0,0,0,0,0,0,0,0,0,0,0,0,0,0
0,0,0,0,0,0,0,0,0,0,0,0,0,0,0,0,0,0,0,0,0,0,0
0,0,0,0,0,0,0,0,0,0,0,0,0,0,0,0,0,0,0,0,0,0,0
0,0,0,0,0,0,0,0,0,0,0,0,0,0,0,0,0,0,0,0,0,0,0
0,0,0,0,0,0,0,0,0,0,0,0,0,0,0,0,0,0,0,0,0,0,0
:endlayer
layer: 19
0,0,0,0,0,0,0,0,0,0,0,0,0,0,0,0,0,0,0,0,0,0,0
0,0,0,0,0,0,0,0,0,0,0,0,0,0,0,0,0,0,0,0,0,0,0
0,0,0,0,0,0,0,0,0,0,0,0,0,0,0,0,0,0,0,0,0,0,0
0,0,0,0,0,0,0,0,0,0,0,0,0,0,0,0,0,0,0,0,0,0,0
0,0,0,0,0,0,0,0,0,0,0,0,0,0,0,0,0,0,0,0,0,0,0
0,0,0,0,0,0,0,0,0,0,0,0,0,0,0,0,0,0,0,0,0,0,0
0,0,0,0,0,0,0,0,0,0,0,0,0,0,0,0,0,0,0,0,0,0,0
0,0,0,0,0,0,0,0,0,0,0,0,0,0,0,0,0,0,0,0,0,0,0
0,0,0,0,0,0,0,0,0,0,0,0,0,0,0,0,0,0,0,0,0,0,0
0,0,0,0,0,0,0,0,0,0,0,0,0,0,0,0,0,0,0,0,0,0,0
0,0,0,0,0,0,0,0,0,0,0,0,0,0,0,0,0,0,0,0,0,0,0
0,0,0,0,0,0,0,0,0,0,0,0,0,0,0,0,0,0,0,0,0,0,0
0,0,0,0,0,0,0,0,0,0,0,0,0,0,0,0,0,0,0,0,0,0,0
0,0,0,0,0,0,0,0,0,0,0,0,0,0,0,0,0,0,0,0,0,0,0
0,0,0,0,0,0,0,0,0,0,0,0,0,0,0,0,0,0,0,0,0,0,0
0,0,0,0,0,0,0,0,0,0,0,0,0,0,0,0,0,0,0,0,0,0,0
0,0,0,0,0,0,0,0,0,0,0,0,0,0,0,0,0,0,0,0,0,0,0
0,0,0,0,0,0,0,0,0,0,0,0,0,0,0,0,0,0,0,0,0,0,0
0,0,0,0,0,0,0,0,0,0,0,0,0,0,0,0,0,0,0,0,0,0,0
0,0,0,0,0,0,0,0,0,0,0,0,0,0,0,0,0,0,0,0,0,0,0
0,0,0,0,0,0,0,0,0,0,0,0,0,0,0,0,0,0,0,0,0,0,0
0,0,0,0,0,0,0,0,0,0,0,0,0,0,0,0,0,0,0,0,0,0,0
0,0,0,0,0,0,0,0,0,0,0,0,0,0,0,0,0,0,0,0,0,0,0
0,0,0,0,0,0,0,0,0,0,0,0,0,0,0,0,0,0,0,0,0,0,0
0,0,0,0,0,0,0,0,0,0,0,0,0,0,0,0,0,0,0,0,0,0,0
0,0,0,0,0,0,0,0,0,0,0,0,0,0,0,0,0,0,0,0,0,0,0
0,0,0,0,0,0,0,0,0,0,0,0,0,0,0,0,0,0,0,0,0,0,0
0,0,0,0,0,0,0,0,0,0,0,0,0,0,0,0,0,0,0,0,0,0,0
0,0,0,0,0,0,0,0,0,0,0,0,0,0,0,0,0,0,0,0,0,0,0
0,0,0,0,0,0,0,0,0,0,0,0,0,0,0,0,0,0,0,0,0,0,0
0,0,0,0,0,0,0,0,0,0,0,0,0,0,0,0,0,0,0,0,0,0,0
0,0,0,0,0,0,0,0,0,0,0,0,0,0,0,0,0,0,0,0,0,0,0
0,0,0,0,0,0,0,0,0,0,0,0,0,0,0,0,0,0,0,0,0,0,0
0,0,0,0,0,0,0,0,0,0,0,0,0,0,0,0,0,0,0,0,0,0,0
0,0,0,0,0,0,0,0,0,0,0,0,0,0,0,0,0,0,0,0,0,0,0
0,0,0,0,0,0,0,0,0,0,0,0,0,0,0,0,0,0,0,0,0,0,0
0,0,0,0,0,0,0,0,0,0,0,0,0,0,0,0,0,0,0,0,0,0,0
0,0,0,0,0,0,0,0,0,0,0,0,0,0,0,0,0,0,0,0,0,0,0
0,0,0,0,0,0,0,0,0,0,0,0,0,0,0,0,0,0,0,0,0,0,0
0,0,0,0,0,0,0,0,0,0,0,0,0,0,0,0,0,0,0,0,0,0,0
0,0,0,0,0,0,0,0,0,0,0,0,0,0,0,0,0,0,0,0,0,0,0
:endlayer
layer: 20
0,0,0,0,0,0,0,0,0,0,0,0,0,0,0,0,0,0,0,0,0,0,0
0,0,0,0,0,0,0,0,0,0,0,0,0,0,0,0,0,0,0,0,0,0,0
0,0,0,0,0,0,0,0,0,0,0,0,0,0,0,0,0,0,0,0,0,0,0
0,0,0,0,0,0,0,0,0,0,0,0,0,0,0,0,0,0,0,0,0,0,0
0,0,0,0,0,0,0,0,0,0,0,0,0,0,0,0,0,0,0,0,0,0,0
0,0,0,0,0,0,0,0,0,0,0,0,0,0,0,0,0,0,0,0,0,0,0
0,0,0,0,0,0,0,0,0,0,0,0,0,0,0,0,0,0,0,0,0,0,0
0,0,0,0,0,0,0,0,0,0,0,0,0,0,0,0,0,0,0,0,0,0,0
0,0,0,0,0,0,0,0,0,0,0,0,0,0,0,0,0,0,0,0,0,0,0
0,0,0,0,0,0,0,0,0,0,0,0,0,0,0,0,0,0,0,0,0,0,0
0,0,0,0,0,0,0,0,0,0,0,0,0,0,0,0,0,0,0,0,0,0,0
0,0,0,0,0,0,0,0,0,0,0,0,0,0,0,0,0,0,0,0,0,0,0
0,0,0,0,0,0,0,0,0,0,0,0,0,0,0,0,0,0,0,0,0,0,0
0,0,0,0,0,0,0,0,0,0,0,0,0,0,0,0,0,0,0,0,0,0,0
0,0,0,0,0,0,0,0,0,0,0,0,0,0,0,0,0,0,0,0,0,0,0
0,0,0,0,0,0,0,0,0,0,0,0,0,0,0,0,0,0,0,0,0,0,0
0,0,0,0,0,0,0,0,0,0,0,0,0,0,0,0,0,0,0,0,0,0,0
0,0,0,0,0,0,0,0,0,0,0,0,0,0,0,0,0,0,0,0,0,0,0
0,0,0,0,0,0,0,0,0,0,0,0,0,0,0,0,0,0,0,0,0,0,0
0,0,0,0,0,0,0,0,0,0,0,0,0,0,0,0,0,0,0,0,0,0,0
0,0,0,0,0,0,0,0,0,0,0,0,0,0,0,0,0,0,0,0,0,0,0
0,0,0,0,0,0,0,0,0,0,0,0,0,0,0,0,0,0,0,0,0,0,0
0,0,0,0,0,0,0,0,0,0,0,0,0,0,0,0,0,0,0,0,0,0,0
0,0,0,0,0,0,0,0,0,0,0,0,0,0,0,0,0,0,0,0,0,0,0
0,0,0,0,0,0,0,0,0,0,0,0,0,0,0,0,0,0,0,0,0,0,0
0,0,0,0,0,0,0,0,0,0,0,0,0,0,0,0,0,0,0,0,0,0,0
0,0,0,0,0,0,0,0,0,0,0,0,0,0,0,0,0,0,0,0,0,0,0
0,0,0,0,0,0,0,0,0,0,0,0,0,0,0,0,0,0,0,0,0,0,0
0,0,0,0,0,0,0,0,0,0,0,0,0,0,0,0,0,0,0,0,0,0,0
0,0,0,0,0,0,0,0,0,0,0,0,0,0,0,0,0,0,0,0,0,0,0
0,0,0,0,0,0,0,0,0,0,0,0,0,0,0,0,0,0,0,0,0,0,0
0,0,0,0,0,0,0,0,0,0,0,0,0,0,0,0,0,0,0,0,0,0,0
0,0,0,0,0,0,0,0,0,0,0,0,0,0,0,0,0,0,0,0,0,0,0
0,0,0,0,0,0,0,0,0,0,0,0,0,0,0,0,0,0,0,0,0,0,0
0,0,0,0,0,0,0,0,0,0,0,0,0,0,0,0,0,0,0,0,0,0,0
0,0,0,0,0,0,0,0,0,0,0,0,0,0,0,0,0,0,0,0,0,0,0
0,0,0,0,0,0,0,0,0,0,0,0,0,0,0,0,0,0,0,0,0,0,0
0,0,0,0,0,0,0,0,0,0,0,0,0,0,0,0,0,0,0,0,0,0,0
0,0,0,0,0,0,0,0,0,0,0,0,0,0,0,0,0,0,0,0,0,0,0
0,0,0,0,0,0,0,0,0,0,0,0,0,0,0,0,0,0,0,0,0,0,0
0,0,0,0,0,0,0,0,0,0,0,0,0,0,0,0,0,0,0,0,0,0,0
:endlayer
layer: 21
0,0,0,0,0,0,0,0,0,0,0,0,0,0,0,0,0,0,0,0,0,0,0
0,0,0,0,0,0,0,0,0,0,0,0,0,0,0,0,0,0,0,0,0,0,0
0,0,0,0,0,0,0,0,0,0,0,0,0,0,0,0,0,0,0,0,0,0,0
0,0,0,0,0,0,0,0,0,0,0,0,0,0,0,0,0,0,0,0,0,0,0
0,0,0,0,0,0,0,0,0,0,0,0,0,0,0,0,0,0,0,0,0,0,0
0,0,0,0,0,0,0,0,0,0,0,0,0,0,0,0,0,0,0,0,0,0,0
0,0,0,0,0,0,0,0,0,0,0,0,0,0,0,0,0,0,0,0,0,0,0
0,0,0,0,0,0,0,0,0,0,0,0,0,0,0,0,0,0,0,0,0,0,0
0,0,0,0,0,0,0,0,0,0,0,0,0,0,0,0,0,0,0,0,0,0,0
0,0,0,0,0,0,0,0,0,0,0,0,0,0,0,0,0,0,0,0,0,0,0
0,0,0,0,0,0,0,0,0,0,0,0,0,0,0,0,0,0,0,0,0,0,0
0,0,0,0,0,0,0,0,0,0,0,0,0,0,0,0,0,0,0,0,0,0,0
0,0,0,0,0,0,0,0,0,0,0,0,0,0,0,0,0,0,0,0,0,0,0
0,0,0,0,0,0,0,0,0,0,0,0,0,0,0,0,0,0,0,0,0,0,0
0,0,0,0,0,0,0,0,0,0,0,0,0,0,0,0,0,0,0,0,0,0,0
0,0,0,0,0,0,0,0,0,0,0,0,0,0,0,0,0,0,0,0,0,0,0
0,0,0,0,0,0,0,0,0,0,0,0,0,0,0,0,0,0,0,0,0,0,0
0,0,0,0,0,0,0,0,0,0,0,0,0,0,0,0,0,0,0,0,0,0,0
0,0,0,0,0,0,0,0,0,0,0,0,0,0,0,0,0,0,0,0,0,0,0
0,0,0,0,0,0,0,0,0,0,0,0,0,0,0,0,0,0,0,0,0,0,0
0,0,0,0,0,0,0,0,0,0,0,0,0,0,0,0,0,0,0,0,0,0,0
0,0,0,0,0,0,0,0,0,0,0,0,0,0,0,0,0,0,0,0,0,0,0
0,0,0,0,0,0,0,0,0,0,0,0,0,0,0,0,0,0,0,0,0,0,0
0,0,0,0,0,0,0,0,0,0,0,0,0,0,0,0,0,0,0,0,0,0,0
0,0,0,0,0,0,0,0,0,0,0,0,0,0,0,0,0,0,0,0,0,0,0
0,0,0,0,0,0,0,0,0,0,0,0,0,0,0,0,0,0,0,0,0,0,0
0,0,0,0,0,0,0,0,0,0,0,0,0,0,0,0,0,0,0,0,0,0,0
0,0,0,0,0,0,0,0,0,0,0,0,0,0,0,0,0,0,0,0,0,0,0
0,0,0,0,0,0,0,0,0,0,0,0,0,0,0,0,0,0,0,0,0,0,0
0,0,0,0,0,0,0,0,0,0,0,0,0,0,0,0,0,0,0,0,0,0,0
0,0,0,0,0,0,0,0,0,0,0,0,0,0,0,0,0,0,0,0,0,0,0
0,0,0,0,0,0,0,0,0,0,0,0,0,0,0,0,0,0,0,0,0,0,0
0,0,0,0,0,0,0,0,0,0,0,0,0,0,0,0,0,0,0,0,0,0,0
0,0,0,0,0,0,0,0,0,0,0,0,0,0,0,0,0,0,0,0,0,0,0
0,0,0,0,0,0,0,0,0,0,0,0,0,0,0,0,0,0,0,0,0,0,0
0,0,0,0,0,0,0,0,0,0,0,0,0,0,0,0,0,0,0,0,0,0,0
0,0,0,0,0,0,0,0,0,0,0,0,0,0,0,0,0,0,0,0,0,0,0
0,0,0,0,0,0,0,0,0,0,0,0,0,0,0,0,0,0,0,0,0,0,0
0,0,0,0,0,0,0,0,0,0,0,0,0,0,0,0,0,0,0,0,0,0,0
0,0,0,0,0,0,0,0,0,0,0,0,0,0,0,0,0,0,0,0,0,0,0
0,0,0,0,0,0,0,0,0,0,0,0,0,0,0,0,0,0,0,0,0,0,0
:endlayer
layer: 22
0,0,0,0,0,0,0,0,0,0,0,0,0,0,0,0,0,0,0,0,0,0,0
0,0,0,0,0,0,0,0,0,0,0,0,0,0,0,0,0,0,0,0,0,0,0
0,0,0,0,0,0,0,0,0,0,0,0,0,0,0,0,0,0,0,0,0,0,0
0,0,0,0,0,0,0,0,0,0,0,0,0,0,0,0,0,0,0,0,0,0,0
0,0,0,0,0,0,0,0,0,0,0,0,0,0,0,0,0,0,0,0,0,0,0
0,0,0,0,0,0,0,0,0,0,0,0,0,0,0,0,0,0,0,0,0,0,0
0,0,0,0,0,0,0,0,0,0,0,0,0,0,0,0,0,0,0,0,0,0,0
0,0,0,0,0,0,0,0,0,0,0,0,0,0,0,0,0,0,0,0,0,0,0
0,0,0,0,0,0,0,0,0,0,0,0,0,0,0,0,0,0,0,0,0,0,0
0,0,0,0,0,0,0,0,0,0,0,0,0,0,0,0,0,0,0,0,0,0,0
0,0,0,0,0,0,0,0,0,0,0,0,0,0,0,0,0,0,0,0,0,0,0
0,0,0,0,0,0,0,0,0,0,0,0,0,0,0,0,0,0,0,0,0,0,0
0,0,0,0,0,0,0,0,0,0,0,0,0,0,0,0,0,0,0,0,0,0,0
0,0,0,0,0,0,0,0,0,0,0,0,0,0,0,0,0,0,0,0,0,0,0
0,0,0,0,0,0,0,0,0,0,0,0,0,0,0,0,0,0,0,0,0,0,0
0,0,0,0,0,0,0,0,0,0,0,0,0,0,0,0,0,0,0,0,0,0,0
0,0,0,0,0,0,0,0,0,0,0,0,0,0,0,0,0,0,0,0,0,0,0
0,0,0,0,0,0,0,0,0,0,0,0,0,0,0,0,0,0,0,0,0,0,0
0,0,0,0,0,0,0,0,0,0,0,0,0,0,0,0,0,0,0,0,0,0,0
0,0,0,0,0,0,0,0,0,0,0,0,0,0,0,0,0,0,0,0,0,0,0
0,0,0,0,0,0,0,0,0,0,0,0,0,0,0,0,0,0,0,0,0,0,0
0,0,0,0,0,0,0,0,0,0,0,0,0,0,0,0,0,0,0,0,0,0,0
0,0,0,0,0,0,0,0,0,0,0,0,0,0,0,0,0,0,0,0,0,0,0
0,0,0,0,0,0,0,0,0,0,0,0,0,0,0,0,0,0,0,0,0,0,0
0,0,0,0,0,0,0,0,0,0,0,0,0,0,0,0,0,0,0,0,0,0,0
0,0,0,0,0,0,0,0,0,0,0,0,0,0,0,0,0,0,0,0,0,0,0
0,0,0,0,0,0,0,0,0,0,0,0,0,0,0,0,0,0,0,0,0,0,0
0,0,0,0,0,0,0,0,0,0,0,0,0,0,0,0,0,0,0,0,0,0,0
0,0,0,0,0,0,0,0,0,0,0,0,0,0,0,0,0,0,0,0,0,0,0
0,0,0,0,0,0,0,0,0,0,0,0,0,0,0,0,0,0,0,0,0,0,0
0,0,0,0,0,0,0,0,0,0,0,0,0,0,0,0,0,0,0,0,0,0,0
0,0,0,0,0,0,0,0,0,0,0,0,0,0,0,0,0,0,0,0,0,0,0
0,0,0,0,0,0,0,0,0,0,0,0,0,0,0,0,0,0,0,0,0,0,0
0,0,0,0,0,0,0,0,0,0,0,0,0,0,0,0,0,0,0,0,0,0,0
0,0,0,0,0,0,0,0,0,0,0,0,0,0,0,0,0,0,0,0,0,0,0
0,0,0,0,0,0,0,0,0,0,0,0,0,0,0,0,0,0,0,0,0,0,0
0,0,0,0,0,0,0,0,0,0,0,0,0,0,0,0,0,0,0,0,0,0,0
0,0,0,0,0,0,0,0,0,0,0,0,0,0,0,0,0,0,0,0,0,0,0
0,0,0,0,0,0,0,0,0,0,0,0,0,0,0,0,0,0,0,0,0,0,0
0,0,0,0,0,0,0,0,0,0,0,0,0,0,0,0,0,0,0,0,0,0,0
0,0,0,0,0,0,0,0,0,0,0,0,0,0,0,0,0,0,0,0,0,0,0
:endlayer
layer: 23
0,0,0,0,0,0,0,0,0,0,0,0,0,0,0,0,0,0,0,0,0,0,0
0,0,0,0,0,0,0,0,0,0,0,0,0,0,0,0,0,0,0,0,0,0,0
0,0,0,0,0,0,0,0,0,0,0,0,0,0,0,0,0,0,0,0,0,0,0
0,0,0,0,0,0,0,0,0,0,0,0,0,0,0,0,0,0,0,0,0,0,0
0,0,0,0,0,0,0,0,0,0,0,0,0,0,0,0,0,0,0,0,0,0,0
0,0,0,0,0,0,0,0,0,0,0,0,0,0,0,0,0,0,0,0,0,0,0
0,0,0,0,0,0,0,0,0,0,0,0,0,0,0,0,0,0,0,0,0,0,0
0,0,0,0,0,0,0,0,0,0,0,0,0,0,0,0,0,0,0,0,0,0,0
0,0,0,0,0,0,0,0,0,0,0,0,0,0,0,0,0,0,0,0,0,0,0
0,0,0,0,0,0,0,0,0,0,0,0,0,0,0,0,0,0,0,0,0,0,0
0,0,0,0,0,0,0,0,0,0,0,0,0,0,0,0,0,0,0,0,0,0,0
0,0,0,0,0,0,0,0,0,0,0,0,0,0,0,0,0,0,0,0,0,0,0
0,0,0,0,0,0,0,0,0,0,0,0,0,0,0,0,0,0,0,0,0,0,0
0,0,0,0,0,0,0,0,0,0,0,0,0,0,0,0,0,0,0,0,0,0,0
0,0,0,0,0,0,0,0,0,0,0,0,0,0,0,0,0,0,0,0,0,0,0
0,0,0,0,0,0,0,0,0,0,0,0,0,0,0,0,0,0,0,0,0,0,0
0,0,0,0,0,0,0,0,0,0,0,0,0,0,0,0,0,0,0,0,0,0,0
0,0,0,0,0,0,0,0,0,0,0,0,0,0,0,0,0,0,0,0,0,0,0
0,0,0,0,0,0,0,0,0,0,0,0,0,0,0,0,0,0,0,0,0,0,0
0,0,0,0,0,0,0,0,0,0,0,0,0,0,0,0,0,0,0,0,0,0,0
0,0,0,0,0,0,0,0,0,0,0,0,0,0,0,0,0,0,0,0,0,0,0
0,0,0,0,0,0,0,0,0,0,0,0,0,0,0,0,0,0,0,0,0,0,0
0,0,0,0,0,0,0,0,0,0,0,0,0,0,0,0,0,0,0,0,0,0,0
0,0,0,0,0,0,0,0,0,0,0,0,0,0,0,0,0,0,0,0,0,0,0
0,0,0,0,0,0,0,0,0,0,0,0,0,0,0,0,0,0,0,0,0,0,0
0,0,0,0,0,0,0,0,0,0,0,0,0,0,0,0,0,0,0,0,0,0,0
0,0,0,0,0,0,0,0,0,0,0,0,0,0,0,0,0,0,0,0,0,0,0
0,0,0,0,0,0,0,0,0,0,0,0,0,0,0,0,0,0,0,0,0,0,0
0,0,0,0,0,0,0,0,0,0,0,0,0,0,0,0,0,0,0,0,0,0,0
0,0,0,0,0,0,0,0,0,0,0,0,0,0,0,0,0,0,0,0,0,0,0
0,0,0,0,0,0,0,0,0,0,0,0,0,0,0,0,0,0,0,0,0,0,0
0,0,0,0,0,0,0,0,0,0,0,0,0,0,0,0,0,0,0,0,0,0,0
0,0,0,0,0,0,0,0,0,0,0,0,0,0,0,0,0,0,0,0,0,0,0
0,0,0,0,0,0,0,0,0,0,0,0,0,0,0,0,0,0,0,0,0,0,0
0,0,0,0,0,0,0,0,0,0,0,0,0,0,0,0,0,0,0,0,0,0,0
0,0,0,0,0,0,0,0,0,0,0,0,0,0,0,0,0,0,0,0,0,0,0
0,0,0,0,0,0,0,0,0,0,0,0,0,0,0,0,0,0,0,0,0,0,0
0,0,0,0,0,0,0,0,0,0,0,0,0,0,0,0,0,0,0,0,0,0,0
0,0,0,0,0,0,0,0,0,0,0,0,0,0,0,0,0,0,0,0,0,0,0
0,0,0,0,0,0,0,0,0,0,0,0,0,0,0,0,0,0,0,0,0,0,0
0,0,0,0,0,0,0,0,0,0,0,0,0,0,0,0,0,0,0,0,0,0,0
:endlayer
layer: 24
0,0,0,0,0,0,0,0,0,0,0,0,0,0,0,0,0,0,0,0,0,0,0
0,0,0,0,0,0,0,0,0,0,0,0,0,0,0,0,0,0,0,0,0,0,0
0,0,0,0,0,0,0,0,0,0,0,0,0,0,0,0,0,0,0,0,0,0,0
0,0,0,0,0,0,0,0,0,0,0,0,0,0,0,0,0,0,0,0,0,0,0
0,0,0,0,0,0,0,0,0,0,0,0,0,0,0,0,0,0,0,0,0,0,0
0,0,0,0,0,0,0,0,0,0,0,0,0,0,0,0,0,0,0,0,0,0,0
0,0,0,0,0,0,0,0,0,0,0,0,0,0,0,0,0,0,0,0,0,0,0
0,0,0,0,0,0,0,0,0,0,0,0,0,0,0,0,0,0,0,0,0,0,0
0,0,0,0,0,0,0,0,0,0,0,0,0,0,0,0,0,0,0,0,0,0,0
0,0,0,0,0,0,0,0,0,0,0,0,0,0,0,0,0,0,0,0,0,0,0
0,0,0,0,0,0,0,0,0,0,0,0,0,0,0,0,0,0,0,0,0,0,0
0,0,0,0,0,0,0,0,0,0,0,0,0,0,0,0,0,0,0,0,0,0,0
0,0,0,0,0,0,0,0,0,0,0,0,0,0,0,0,0,0,0,0,0,0,0
0,0,0,0,0,0,0,0,0,0,0,0,0,0,0,0,0,0,0,0,0,0,0
0,0,0,0,0,0,0,0,0,0,0,0,0,0,0,0,0,0,0,0,0,0,0
0,0,0,0,0,0,0,0,0,0,0,0,0,0,0,0,0,0,0,0,0,0,0
0,0,0,0,0,0,0,0,0,0,0,0,0,0,0,0,0,0,0,0,0,0,0
0,0,0,0,0,0,0,0,0,0,0,0,0,0,0,0,0,0,0,0,0,0,0
0,0,0,0,0,0,0,0,0,0,0,0,0,0,0,0,0,0,0,0,0,0,0
0,0,0,0,0,0,0,0,0,0,0,0,0,0,0,0,0,0,0,0,0,0,0
0,0,0,0,0,0,0,0,0,0,0,0,0,0,0,0,0,0,0,0,0,0,0
0,0,0,0,0,0,0,0,0,0,0,0,0,0,0,0,0,0,0,0,0,0,0
0,0,0,0,0,0,0,0,0,0,0,0,0,0,0,0,0,0,0,0,0,0,0
0,0,0,0,0,0,0,0,0,0,0,0,0,0,0,0,0,0,0,0,0,0,0
0,0,0,0,0,0,0,0,0,0,0,0,0,0,0,0,0,0,0,0,0,0,0
0,0,0,0,0,0,0,0,0,0,0,0,0,0,0,0,0,0,0,0,0,0,0
0,0,0,0,0,0,0,0,0,0,0,0,0,0,0,0,0,0,0,0,0,0,0
0,0,0,0,0,0,0,0,0,0,0,0,0,0,0,0,0,0,0,0,0,0,0
0,0,0,0,0,0,0,0,0,0,0,0,0,0,0,0,0,0,0,0,0,0,0
0,0,0,0,0,0,0,0,0,0,0,0,0,0,0,0,0,0,0,0,0,0,0
0,0,0,0,0,0,0,0,0,0,0,0,0,0,0,0,0,0,0,0,0,0,0
0,0,0,0,0,0,0,0,0,0,0,0,0,0,0,0,0,0,0,0,0,0,0
0,0,0,0,0,0,0,0,0,0,0,0,0,0,0,0,0,0,0,0,0,0,0
0,0,0,0,0,0,0,0,0,0,0,0,0,0,0,0,0,0,0,0,0,0,0
0,0,0,0,0,0,0,0,0,0,0,0,0,0,0,0,0,0,0,0,0,0,0
0,0,0,0,0,0,0,0,0,0,0,0,0,0,0,0,0,0,0,0,0,0,0
0,0,0,0,0,0,0,0,0,0,0,0,0,0,0,0,0,0,0,0,0,0,0
0,0,0,0,0,0,0,0,0,0,0,0,0,0,0,0,0,0,0,0,0,0,0
0,0,0,0,0,0,0,0,0,0,0,0,0,0,0,0,0,0,0,0,0,0,0
0,0,0,0,0,0,0,0,0,0,0,0,0,0,0,0,0,0,0,0,0,0,0
0,0,0,0,0,0,0,0,0,0,0,0,0,0,0,0,0,0,0,0,0,0,0
:endlayer
layer: 25
0,0,0,0,0,0,0,0,0,0,0,0,0,0,0,0,0,0,0,0,0,0,0
0,0,0,0,0,0,0,0,0,0,0,0,0,0,0,0,0,0,0,0,0,0,0
0,0,0,0,0,0,0,0,0,0,0,0,0,0,0,0,0,0,0,0,0,0,0
0,0,0,0,0,0,0,0,0,0,0,0,0,0,0,0,0,0,0,0,0,0,0
0,0,0,0,0,0,0,0,0,0,0,0,0,0,0,0,0,0,0,0,0,0,0
0,0,0,0,0,0,0,0,0,0,0,0,0,0,0,0,0,0,0,0,0,0,0
0,0,0,0,0,0,0,0,0,0,0,0,0,0,0,0,0,0,0,0,0,0,0
0,0,0,0,0,0,0,0,0,0,0,0,0,0,0,0,0,0,0,0,0,0,0
0,0,0,0,0,0,0,0,0,0,0,0,0,0,0,0,0,0,0,0,0,0,0
0,0,0,0,0,0,0,0,0,0,0,0,0,0,0,0,0,0,0,0,0,0,0
0,0,0,0,0,0,0,0,0,0,0,0,0,0,0,0,0,0,0,0,0,0,0
0,0,0,0,0,0,0,0,0,0,0,0,0,0,0,0,0,0,0,0,0,0,0
0,0,0,0,0,0,0,0,0,0,0,0,0,0,0,0,0,0,0,0,0,0,0
0,0,0,0,0,0,0,0,0,0,0,0,0,0,0,0,0,0,0,0,0,0,0
0,0,0,0,0,0,0,0,0,0,0,0,0,0,0,0,0,0,0,0,0,0,0
0,0,0,0,0,0,0,0,0,0,0,0,0,0,0,0,0,0,0,0,0,0,0
0,0,0,0,0,0,0,0,0,0,0,0,0,0,0,0,0,0,0,0,0,0,0
0,0,0,0,0,0,0,0,0,0,0,0,0,0,0,0,0,0,0,0,0,0,0
0,0,0,0,0,0,0,0,0,0,0,0,0,0,0,0,0,0,0,0,0,0,0
0,0,0,0,0,0,0,0,0,0,0,0,0,0,0,0,0,0,0,0,0,0,0
0,0,0,0,0,0,0,0,0,0,0,0,0,0,0,0,0,0,0,0,0,0,0
0,0,0,0,0,0,0,0,0,0,0,0,0,0,0,0,0,0,0,0,0,0,0
0,0,0,0,0,0,0,0,0,0,0,0,0,0,0,0,0,0,0,0,0,0,0
0,0,0,0,0,0,0,0,0,0,0,0,0,0,0,0,0,0,0,0,0,0,0
0,0,0,0,0,0,0,0,0,0,0,0,0,0,0,0,0,0,0,0,0,0,0
0,0,0,0,0,0,0,0,0,0,0,0,0,0,0,0,0,0,0,0,0,0,0
0,0,0,0,0,0,0,0,0,0,0,0,0,0,0,0,0,0,0,0,0,0,0
0,0,0,0,0,0,0,0,0,0,0,0,0,0,0,0,0,0,0,0,0,0,0
0,0,0,0,0,0,0,0,0,0,0,0,0,0,0,0,0,0,0,0,0,0,0
0,0,0,0,0,0,0,0,0,0,0,0,0,0,0,0,0,0,0,0,0,0,0
0,0,0,0,0,0,0,0,0,0,0,0,0,0,0,0,0,0,0,0,0,0,0
0,0,0,0,0,0,0,0,0,0,0,0,0,0,0,0,0,0,0,0,0,0,0
0,0,0,0,0,0,0,0,0,0,0,0,0,0,0,0,0,0,0,0,0,0,0
0,0,0,0,0,0,0,0,0,0,0,0,0,0,0,0,0,0,0,0,0,0,0
0,0,0,0,0,0,0,0,0,0,0,0,0,0,0,0,0,0,0,0,0,0,0
0,0,0,0,0,0,0,0,0,0,0,0,0,0,0,0,0,0,0,0,0,0,0
0,0,0,0,0,0,0,0,0,0,0,0,0,0,0,0,0,0,0,0,0,0,0
0,0,0,0,0,0,0,0,0,0,0,0,0,0,0,0,0,0,0,0,0,0,0
0,0,0,0,0,0,0,0,0,0,0,0,0,0,0,0,0,0,0,0,0,0,0
0,0,0,0,0,0,0,0,0,0,0,0,0,0,0,0,0,0,0,0,0,0,0
0,0,0,0,0,0,0,0,0,0,0,0,0,0,0,0,0,0,0,0,0,0,0
:endlayer
layer: 26
0,0,0,0,0,0,0,0,0,0,0,0,0,0,0,0,0,0,0,0,0,0,0
0,0,0,0,0,0,0,0,0,0,0,0,0,0,0,0,0,0,0,0,0,0,0
0,0,0,0,0,0,0,0,0,0,0,0,0,0,0,0,0,0,0,0,0,0,0
0,0,0,0,0,0,0,0,0,0,0,0,0,0,0,0,0,0,0,0,0,0,0
0,0,0,0,0,0,0,0,0,0,0,0,0,0,0,0,0,0,0,0,0,0,0
0,0,0,0,0,0,0,0,0,0,0,0,0,0,0,0,0,0,0,0,0,0,0
0,0,0,0,0,0,0,0,0,0,0,0,0,0,0,0,0,0,0,0,0,0,0
0,0,0,0,0,0,0,0,0,0,0,0,0,0,0,0,0,0,0,0,0,0,0
0,0,0,0,0,0,0,0,0,0,0,0,0,0,0,0,0,0,0,0,0,0,0
0,0,0,0,0,0,0,0,0,0,0,0,0,0,0,0,0,0,0,0,0,0,0
0,0,0,0,0,0,0,0,0,0,0,0,0,0,0,0,0,0,0,0,0,0,0
0,0,0,0,0,0,0,0,0,0,0,0,0,0,0,0,0,0,0,0,0,0,0
0,0,0,0,0,0,0,0,0,0,0,0,0,0,0,0,0,0,0,0,0,0,0
0,0,0,0,0,0,0,0,0,0,0,0,0,0,0,0,0,0,0,0,0,0,0
0,0,0,0,0,0,0,0,0,0,0,0,0,0,0,0,0,0,0,0,0,0,0
0,0,0,0,0,0,0,0,0,0,0,0,0,0,0,0,0,0,0,0,0,0,0
0,0,0,0,0,0,0,0,0,0,0,0,0,0,0,0,0,0,0,0,0,0,0
0,0,0,0,0,0,0,0,0,0,0,0,0,0,0,0,0,0,0,0,0,0,0
0,0,0,0,0,0,0,0,0,0,0,0,0,0,0,0,0,0,0,0,0,0,0
0,0,0,0,0,0,0,0,0,0,0,0,0,0,0,0,0,0,0,0,0,0,0
0,0,0,0,0,0,0,0,0,0,0,0,0,0,0,0,0,0,0,0,0,0,0
0,0,0,0,0,0,0,0,0,0,0,0,0,0,0,0,0,0,0,0,0,0,0
0,0,0,0,0,0,0,0,0,0,0,0,0,0,0,0,0,0,0,0,0,0,0
0,0,0,0,0,0,0,0,0,0,0,0,0,0,0,0,0,0,0,0,0,0,0
0,0,0,0,0,0,0,0,0,0,0,0,0,0,0,0,0,0,0,0,0,0,0
0,0,0,0,0,0,0,0,0,0,0,0,0,0,0,0,0,0,0,0,0,0,0
0,0,0,0,0,0,0,0,0,0,0,0,0,0,0,0,0,0,0,0,0,0,0
0,0,0,0,0,0,0,0,0,0,0,0,0,0,0,0,0,0,0,0,0,0,0
0,0,0,0,0,0,0,0,0,0,0,0,0,0,0,0,0,0,0,0,0,0,0
0,0,0,0,0,0,0,0,0,0,0,0,0,0,0,0,0,0,0,0,0,0,0
0,0,0,0,0,0,0,0,0,0,0,0,0,0,0,0,0,0,0,0,0,0,0
0,0,0,0,0,0,0,0,0,0,0,0,0,0,0,0,0,0,0,0,0,0,0
0,0,0,0,0,0,0,0,0,0,0,0,0,0,0,0,0,0,0,0,0,0,0
0,0,0,0,0,0,0,0,0,0,0,0,0,0,0,0,0,0,0,0,0,0,0
0,0,0,0,0,0,0,0,0,0,0,0,0,0,0,0,0,0,0,0,0,0,0
0,0,0,0,0,0,0,0,0,0,0,0,0,0,0,0,0,0,0,0,0,0,0
0,0,0,0,0,0,0,0,0,0,0,0,0,0,0,0,0,0,0,0,0,0,0
0,0,0,0,0,0,0,0,0,0,0,0,0,0,0,0,0,0,0,0,0,0,0
0,0,0,0,0,0,0,0,0,0,0,0,0,0,0,0,0,0,0,0,0,0,0
0,0,0,0,0,0,0,0,0,0,0,0,0,0,0,0,0,0,0,0,0,0,0
0,0,0,0,0,0,0,0,0,0,0,0,0,0,0,0,0,0,0,0,0,0,0
:endlayer
layer: 27
0,0,0,0,0,0,0,0,0,0,0,0,0,0,0,0,0,0,0,0,0,0,0
0,0,0,0,0,0,0,0,0,0,0,0,0,0,0,0,0,0,0,0,0,0,0
0,0,0,0,0,0,0,0,0,0,0,0,0,0,0,0,0,0,0,0,0,0,0
0,0,0,0,0,0,0,0,0,0,0,0,0,0,0,0,0,0,0,0,0,0,0
0,0,0,0,0,0,0,0,0,0,0,0,0,0,0,0,0,0,0,0,0,0,0
0,0,0,0,0,0,0,0,0,0,0,0,0,0,0,0,0,0,0,0,0,0,0
0,0,0,0,0,0,0,0,0,0,0,0,0,0,0,0,0,0,0,0,0,0,0
0,0,0,0,0,0,0,0,0,0,0,0,0,0,0,0,0,0,0,0,0,0,0
0,0,0,0,0,0,0,0,0,0,0,0,0,0,0,0,0,0,0,0,0,0,0
0,0,0,0,0,0,0,0,0,0,0,0,0,0,0,0,0,0,0,0,0,0,0
0,0,0,0,0,0,0,0,0,0,0,0,0,0,0,0,0,0,0,0,0,0,0
0,0,0,0,0,0,0,0,0,0,0,0,0,0,0,0,0,0,0,0,0,0,0
0,0,0,0,0,0,0,0,0,0,0,0,0,0,0,0,0,0,0,0,0,0,0
0,0,0,0,0,0,0,0,0,0,0,0,0,0,0,0,0,0,0,0,0,0,0
0,0,0,0,0,0,0,0,0,0,0,0,0,0,0,0,0,0,0,0,0,0,0
0,0,0,0,0,0,0,0,0,0,0,0,0,0,0,0,0,0,0,0,0,0,0
0,0,0,0,0,0,0,0,0,0,0,0,0,0,0,0,0,0,0,0,0,0,0
0,0,0,0,0,0,0,0,0,0,0,0,0,0,0,0,0,0,0,0,0,0,0
0,0,0,0,0,0,0,0,0,0,0,0,0,0,0,0,0,0,0,0,0,0,0
0,0,0,0,0,0,0,0,0,0,0,0,0,0,0,0,0,0,0,0,0,0,0
0,0,0,0,0,0,0,0,0,0,0,0,0,0,0,0,0,0,0,0,0,0,0
0,0,0,0,0,0,0,0,0,0,0,0,0,0,0,0,0,0,0,0,0,0,0
0,0,0,0,0,0,0,0,0,0,0,0,0,0,0,0,0,0,0,0,0,0,0
0,0,0,0,0,0,0,0,0,0,0,0,0,0,0,0,0,0,0,0,0,0,0
0,0,0,0,0,0,0,0,0,0,0,0,0,0,0,0,0,0,0,0,0,0,0
0,0,0,0,0,0,0,0,0,0,0,0,0,0,0,0,0,0,0,0,0,0,0
0,0,0,0,0,0,0,0,0,0,0,0,0,0,0,0,0,0,0,0,0,0,0
0,0,0,0,0,0,0,0,0,0,0,0,0,0,0,0,0,0,0,0,0,0,0
0,0,0,0,0,0,0,0,0,0,0,0,0,0,0,0,0,0,0,0,0,0,0
0,0,0,0,0,0,0,0,0,0,0,0,0,0,0,0,0,0,0,0,0,0,0
0,0,0,0,0,0,0,0,0,0,0,0,0,0,0,0,0,0,0,0,0,0,0
0,0,0,0,0,0,0,0,0,0,0,0,0,0,0,0,0,0,0,0,0,0,0
0,0,0,0,0,0,0,0,0,0,0,0,0,0,0,0,0,0,0,0,0,0,0
0,0,0,0,0,0,0,0,0,0,0,0,0,0,0,0,0,0,0,0,0,0,0
0,0,0,0,0,0,0,0,0,0,0,0,0,0,0,0,0,0,0,0,0,0,0
0,0,0,0,0,0,0,0,0,0,0,0,0,0,0,0,0,0,0,0,0,0,0
0,0,0,0,0,0,0,0,0,0,0,0,0,0,0,0,0,0,0,0,0,0,0
0,0,0,0,0,0,0,0,0,0,0,0,0,0,0,0,0,0,0,0,0,0,0
0,0,0,0,0,0,0,0,0,0,0,0,0,0,0,0,0,0,0,0,0,0,0
0,0,0,0,0,0,0,0,0,0,0,0,0,0,0,0,0,0,0,0,0,0,0
0,0,0,0,0,0,0,0,0,0,0,0,0,0,0,0,0,0,0,0,0,0,0
:endlayer
layer: 28
0,0,0,0,0,0,0,0,0,0,0,0,0,0,0,0,0,0,0,0,0,0,0
0,0,0,0,0,0,0,0,0,0,0,0,0,0,0,0,0,0,0,0,0,0,0
0,0,0,0,0,0,0,0,0,0,0,0,0,0,0,0,0,0,0,0,0,0,0
0,0,0,0,0,0,0,0,0,0,0,0,0,0,0,0,0,0,0,0,0,0,0
0,0,0,0,0,0,0,0,0,0,0,0,0,0,0,0,0,0,0,0,0,0,0
0,0,0,0,0,0,0,0,0,0,0,0,0,0,0,0,0,0,0,0,0,0,0
0,0,0,0,0,0,0,0,0,0,0,0,0,0,0,0,0,0,0,0,0,0,0
0,0,0,0,0,0,0,0,0,0,0,0,0,0,0,0,0,0,0,0,0,0,0
0,0,0,0,0,0,0,0,0,0,0,0,0,0,0,0,0,0,0,0,0,0,0
0,0,0,0,0,0,0,0,0,0,0,0,0,0,0,0,0,0,0,0,0,0,0
0,0,0,0,0,0,0,0,0,0,0,0,0,0,0,0,0,0,0,0,0,0,0
0,0,0,0,0,0,0,0,0,0,0,0,0,0,0,0,0,0,0,0,0,0,0
0,0,0,0,0,0,0,0,0,0,0,0,0,0,0,0,0,0,0,0,0,0,0
0,0,0,0,0,0,0,0,0,0,0,0,0,0,0,0,0,0,0,0,0,0,0
0,0,0,0,0,0,0,0,0,0,0,0,0,0,0,0,0,0,0,0,0,0,0
0,0,0,0,0,0,0,0,0,0,0,0,0,0,0,0,0,0,0,0,0,0,0
0,0,0,0,0,0,0,0,0,0,0,0,0,0,0,0,0,0,0,0,0,0,0
0,0,0,0,0,0,0,0,0,0,0,0,0,0,0,0,0,0,0,0,0,0,0
0,0,0,0,0,0,0,0,0,0,0,0,0,0,0,0,0,0,0,0,0,0,0
0,0,0,0,0,0,0,0,0,0,0,0,0,0,0,0,0,0,0,0,0,0,0
0,0,0,0,0,0,0,0,0,0,0,0,0,0,0,0,0,0,0,0,0,0,0
0,0,0,0,0,0,0,0,0,0,0,0,0,0,0,0,0,0,0,0,0,0,0
0,0,0,0,0,0,0,0,0,0,0,0,0,0,0,0,0,0,0,0,0,0,0
0,0,0,0,0,0,0,0,0,0,0,0,0,0,0,0,0,0,0,0,0,0,0
0,0,0,0,0,0,0,0,0,0,0,0,0,0,0,0,0,0,0,0,0,0,0
0,0,0,0,0,0,0,0,0,0,0,0,0,0,0,0,0,0,0,0,0,0,0
0,0,0,0,0,0,0,0,0,0,0,0,0,0,0,0,0,0,0,0,0,0,0
0,0,0,0,0,0,0,0,0,0,0,0,0,0,0,0,0,0,0,0,0,0,0
0,0,0,0,0,0,0,0,0,0,0,0,0,0,0,0,0,0,0,0,0,0,0
0,0,0,0,0,0,0,0,0,0,0,0,0,0,0,0,0,0,0,0,0,0,0
0,0,0,0,0,0,0,0,0,0,0,0,0,0,0,0,0,0,0,0,0,0,0
0,0,0,0,0,0,0,0,0,0,0,0,0,0,0,0,0,0,0,0,0,0,0
0,0,0,0,0,0,0,0,0,0,0,0,0,0,0,0,0,0,0,0,0,0,0
0,0,0,0,0,0,0,0,0,0,0,0,0,0,0,0,0,0,0,0,0,0,0
0,0,0,0,0,0,0,0,0,0,0,0,0,0,0,0,0,0,0,0,0,0,0
0,0,0,0,0,0,0,0,0,0,0,0,0,0,0,0,0,0,0,0,0,0,0
0,0,0,0,0,0,0,0,0,0,0,0,0,0,0,0,0,0,0,0,0,0,0
0,0,0,0,0,0,0,0,0,0,0,0,0,0,0,0,0,0,0,0,0,0,0
0,0,0,0,0,0,0,0,0,0,0,0,0,0,0,0,0,0,0,0,0,0,0
0,0,0,0,0,0,0,0,0,0,0,0,0,0,0,0,0,0,0,0,0,0,0
0,0,0,0,0,0,0,0,0,0,0,0,0,0,0,0,0,0,0,0,0,0,0
:endlayer
layer: 29
0,0,0,0,0,0,0,0,0,0,0,0,0,0,0,0,0,0,0,0,0,0,0
0,0,0,0,0,0,0,0,0,0,0,0,0,0,0,0,0,0,0,0,0,0,0
0,0,0,0,0,0,0,0,0,0,0,0,0,0,0,0,0,0,0,0,0,0,0
0,0,0,0,0,0,0,0,0,0,0,0,0,0,0,0,0,0,0,0,0,0,0
0,0,0,0,0,0,0,0,0,0,0,0,0,0,0,0,0,0,0,0,0,0,0
0,0,0,0,0,0,0,0,0,0,0,0,0,0,0,0,0,0,0,0,0,0,0
0,0,0,0,0,0,0,0,0,0,0,0,0,0,0,0,0,0,0,0,0,0,0
0,0,0,0,0,0,0,0,0,0,0,0,0,0,0,0,0,0,0,0,0,0,0
0,0,0,0,0,0,0,0,0,0,0,0,0,0,0,0,0,0,0,0,0,0,0
0,0,0,0,0,0,0,0,0,0,0,0,0,0,0,0,0,0,0,0,0,0,0
0,0,0,0,0,0,0,0,0,0,0,0,0,0,0,0,0,0,0,0,0,0,0
0,0,0,0,0,0,0,0,0,0,0,0,0,0,0,0,0,0,0,0,0,0,0
0,0,0,0,0,0,0,0,0,0,0,0,0,0,0,0,0,0,0,0,0,0,0
0,0,0,0,0,0,0,0,0,0,0,0,0,0,0,0,0,0,0,0,0,0,0
0,0,0,0,0,0,0,0,0,0,0,0,0,0,0,0,0,0,0,0,0,0,0
0,0,0,0,0,0,0,0,0,0,0,0,0,0,0,0,0,0,0,0,0,0,0
0,0,0,0,0,0,0,0,0,0,0,0,0,0,0,0,0,0,0,0,0,0,0
0,0,0,0,0,0,0,0,0,0,0,0,0,0,0,0,0,0,0,0,0,0,0
0,0,0,0,0,0,0,0,0,0,0,0,0,0,0,0,0,0,0,0,0,0,0
0,0,0,0,0,0,0,0,0,0,0,0,0,0,0,0,0,0,0,0,0,0,0
0,0,0,0,0,0,0,0,0,0,0,0,0,0,0,0,0,0,0,0,0,0,0
0,0,0,0,0,0,0,0,0,0,0,0,0,0,0,0,0,0,0,0,0,0,0
0,0,0,0,0,0,0,0,0,0,0,0,0,0,0,0,0,0,0,0,0,0,0
0,0,0,0,0,0,0,0,0,0,0,0,0,0,0,0,0,0,0,0,0,0,0
0,0,0,0,0,0,0,0,0,0,0,0,0,0,0,0,0,0,0,0,0,0,0
0,0,0,0,0,0,0,0,0,0,0,0,0,0,0,0,0,0,0,0,0,0,0
0,0,0,0,0,0,0,0,0,0,0,0,0,0,0,0,0,0,0,0,0,0,0
0,0,0,0,0,0,0,0,0,0,0,0,0,0,0,0,0,0,0,0,0,0,0
0,0,0,0,0,0,0,0,0,0,0,0,0,0,0,0,0,0,0,0,0,0,0
0,0,0,0,0,0,0,0,0,0,0,0,0,0,0,0,0,0,0,0,0,0,0
0,0,0,0,0,0,0,0,0,0,0,0,0,0,0,0,0,0,0,0,0,0,0
0,0,0,0,0,0,0,0,0,0,0,0,0,0,0,0,0,0,0,0,0,0,0
0,0,0,0,0,0,0,0,0,0,0,0,0,0,0,0,0,0,0,0,0,0,0
0,0,0,0,0,0,0,0,0,0,0,0,0,0,0,0,0,0,0,0,0,0,0
0,0,0,0,0,0,0,0,0,0,0,0,0,0,0,0,0,0,0,0,0,0,0
0,0,0,0,0,0,0,0,0,0,0,0,0,0,0,0,0,0,0,0,0,0,0
0,0,0,0,0,0,0,0,0,0,0,0,0,0,0,0,0,0,0,0,0,0,0
0,0,0,0,0,0,0,0,0,0,0,0,0,0,0,0,0,0,0,0,0,0,0
0,0,0,0,0,0,0,0,0,0,0,0,0,0,0,0,0,0,0,0,0,0,0
0,0,0,0,0,0,0,0,0,0,0,0,0,0,0,0,0,0,0,0,0,0,0
0,0,0,0,0,0,0,0,0,0,0,0,0,0,0,0,0,0,0,0,0,0,0
:endlayer

#### RULES ####
rule:
plugin=vanillaBlocks
number=1
data:
tag:
TAG=10={
TAG=8=blockName{dirt}
TAG=3=meta{0}
TAG=3=buildPass{0}
}
:endtag
:enddata
:endrule

rule:
plugin=vanillaBlocks
number=2
data:
tag:
TAG=10={
TAG=8=blockName{grass}
TAG=3=meta{0}
TAG=3=buildPass{0}
}
:endtag
:enddata
:endrule

rule:
plugin=vanillaBlocks
number=3
data:
tag:
TAG=10={
TAG=8=blockName{gravel}
TAG=3=meta{0}
TAG=3=buildPass{1}
}
:endtag
:enddata
:endrule

rule:
plugin=vanillaBlocks
number=4
data:
tag:
TAG=10={
TAG=8=blockName{cobblestone}
TAG=3=meta{0}
TAG=3=buildPass{0}
}
:endtag
:enddata
:endrule

rule:
plugin=vanillaBlocks
number=5
data:
tag:
TAG=10={
TAG=8=blockName{stonebrick}
TAG=3=meta{0}
TAG=3=buildPass{0}
}
:endtag
:enddata
:endrule

rule:
plugin=vanillaBlocks
number=6
data:
tag:
TAG=10={
TAG=8=blockName{hay_block}
TAG=3=meta{0}
TAG=3=buildPass{0}
}
:endtag
:enddata
:endrule

rule:
plugin=vanillaBlocks
number=7
data:
tag:
TAG=10={
TAG=8=blockName{netherrack}
TAG=3=meta{0}
TAG=3=buildPass{0}
}
:endtag
:enddata
:endrule

rule:
plugin=vanillaBlocks
number=8
data:
tag:
TAG=10={
TAG=8=blockName{tallgrass}
TAG=3=meta{1}
TAG=3=buildPass{0}
}
:endtag
:enddata
:endrule

rule:
plugin=vanillaBlocks
number=9
data:
tag:
TAG=10={
TAG=8=blockName{fence}
TAG=3=meta{0}
TAG=3=buildPass{0}
}
:endtag
:enddata
:endrule

rule:
plugin=vanillaBlocks
number=10
data:
tag:
TAG=10={
TAG=8=blockName{fence_gate}
TAG=3=meta{1}
TAG=3=buildPass{0}
}
:endtag
:enddata
:endrule

rule:
plugin=vanillaBlocks
number=11
data:
tag:
TAG=10={
TAG=8=blockName{log}
TAG=3=meta{0}
TAG=3=buildPass{0}
}
:endtag
:enddata
:endrule

rule:
plugin=vanillaBlocks
number=12
data:
tag:
TAG=10={
TAG=8=blockName{planks}
TAG=3=meta{0}
TAG=3=buildPass{0}
}
:endtag
:enddata
:endrule

rule:
plugin=vanillaBlocks
number=13
data:
tag:
TAG=10={
TAG=8=blockName{yellow_flower}
TAG=3=meta{0}
TAG=3=buildPass{1}
}
:endtag
:enddata
:endrule

rule:
plugin=vanillaDoors
number=14
data:
tag:
TAG=10={
TAG=1=sideFlag{8}
TAG=8=blockName{wooden_door}
TAG=3=meta{3}
TAG=3=buildPass{1}
}
:endtag
:enddata
:endrule

rule:
plugin=vanillaBlocks
number=15
data:
tag:
TAG=10={
TAG=8=blockName{oak_stairs}
TAG=3=meta{2}
TAG=3=buildPass{0}
}
:endtag
:enddata
:endrule

rule:
plugin=vanillaBlocks
number=16
data:
tag:
TAG=10={
TAG=8=blockName{stone_brick_stairs}
TAG=3=meta{1}
TAG=3=buildPass{0}
}
:endtag
:enddata
:endrule

rule:
plugin=vanillaBlocks
number=17
data:
tag:
TAG=10={
TAG=8=blockName{red_flower}
TAG=3=meta{0}
TAG=3=buildPass{1}
}
:endtag
:enddata
:endrule

rule:
plugin=vanillaBlocks
number=18
data:
tag:
TAG=10={
TAG=8=blockName{crafting_table}
TAG=3=meta{0}
TAG=3=buildPass{0}
}
:endtag
:enddata
:endrule

rule:
plugin=awAdvancedSpawner
number=19
data:
tag:
TAG=10={
TAG=10=teData{
TAG=9=Items{
}
TAG=8=id{Furnace}
TAG=2=BurnTime{0}
TAG=3=z{-25}
TAG=2=CookTime{0}
TAG=3=y{70}
TAG=3=x{324}
}
TAG=8=blockName{furnace}
TAG=3=meta{3}
TAG=3=buildPass{0}
}
:endtag
:enddata
:endrule

rule:
plugin=vanillaBlocks
number=20
data:
tag:
TAG=10={
TAG=8=blockName{fire}
TAG=3=meta{15}
TAG=3=buildPass{0}
}
:endtag
:enddata
:endrule

rule:
plugin=vanillaBlocks
number=21
data:
tag:
TAG=10={
TAG=8=blockName{stone_slab}
TAG=3=meta{0}
TAG=3=buildPass{0}
}
:endtag
:enddata
:endrule

rule:
plugin=vanillaBlocks
number=22
data:
tag:
TAG=10={
TAG=8=blockName{fence_gate}
TAG=3=meta{3}
TAG=3=buildPass{0}
}
:endtag
:enddata
:endrule

rule:
plugin=vanillaBlocks
number=23
data:
tag:
TAG=10={
TAG=8=blockName{fence_gate}
TAG=3=meta{4}
TAG=3=buildPass{0}
}
:endtag
:enddata
:endrule

rule:
plugin=vanillaBlocks
number=24
data:
tag:
TAG=10={
TAG=8=blockName{fence_gate}
TAG=3=meta{2}
TAG=3=buildPass{0}
}
:endtag
:enddata
:endrule

rule:
plugin=vanillaBlocks
number=25
data:
tag:
TAG=10={
TAG=8=blockName{stone_slab}
TAG=3=meta{3}
TAG=3=buildPass{0}
}
:endtag
:enddata
:endrule

rule:
plugin=vanillaBlocks
number=26
data:
tag:
TAG=10={
TAG=8=blockName{double_stone_slab}
TAG=3=meta{3}
TAG=3=buildPass{0}
}
:endtag
:enddata
:endrule

rule:
plugin=vanillaBlocks
number=27
data:
tag:
TAG=10={
TAG=8=blockName{torch}
TAG=3=meta{5}
TAG=3=buildPass{1}
}
:endtag
:enddata
:endrule

rule:
plugin=vanillaBlocks
number=28
data:
tag:
TAG=10={
TAG=8=blockName{glass_pane}
TAG=3=meta{0}
TAG=3=buildPass{0}
}
:endtag
:enddata
:endrule

rule:
plugin=vanillaInventory
number=29
data:
tag:
TAG=10={
TAG=3=lootLevel{0}
TAG=10=teData{
TAG=9=Items{
}
TAG=8=id{Chest}
}
TAG=8=blockName{chest}
TAG=3=meta{3}
TAG=3=buildPass{0}
}
:endtag
:enddata
:endrule

rule:
plugin=awAdvancedSpawner
number=30
data:
tag:
TAG=10={
TAG=10=teData{
TAG=9=Items{
}
TAG=8=id{Furnace}
TAG=2=BurnTime{0}
TAG=3=z{-29}
TAG=2=CookTime{0}
TAG=3=y{71}
TAG=3=x{340}
}
TAG=8=blockName{furnace}
TAG=3=meta{4}
TAG=3=buildPass{0}
}
:endtag
:enddata
:endrule

rule:
plugin=vanillaBlocks
number=31
data:
tag:
TAG=10={
TAG=8=blockName{cauldron}
TAG=3=meta{3}
TAG=3=buildPass{0}
}
:endtag
:enddata
:endrule

rule:
plugin=vanillaDoors
number=32
data:
tag:
TAG=10={
TAG=1=sideFlag{0}
TAG=8=blockName{wooden_door}
TAG=3=meta{8}
TAG=3=buildPass{1}
}
:endtag
:enddata
:endrule

rule:
plugin=vanillaDoors
number=33
data:
tag:
TAG=10={
TAG=1=sideFlag{8}
TAG=8=blockName{wooden_door}
TAG=3=meta{1}
TAG=3=buildPass{1}
}
:endtag
:enddata
:endrule

rule:
plugin=vanillaBlocks
number=34
data:
tag:
TAG=10={
TAG=8=blockName{oak_stairs}
TAG=3=meta{3}
TAG=3=buildPass{0}
}
:endtag
:enddata
:endrule

rule:
plugin=vanillaBlocks
number=35
data:
tag:
TAG=10={
TAG=8=blockName{oak_stairs}
TAG=3=meta{1}
TAG=3=buildPass{0}
}
:endtag
:enddata
:endrule

rule:
plugin=vanillaBlocks
number=36
data:
tag:
TAG=10={
TAG=8=blockName{bookshelf}
TAG=3=meta{0}
TAG=3=buildPass{0}
}
:endtag
:enddata
:endrule

rule:
plugin=vanillaBlocks
number=37
data:
tag:
TAG=10={
TAG=8=blockName{stone_brick_stairs}
TAG=3=meta{2}
TAG=3=buildPass{0}
}
:endtag
:enddata
:endrule

rule:
plugin=vanillaDoors
number=38
data:
tag:
TAG=10={
TAG=1=sideFlag{8}
TAG=8=blockName{wooden_door}
TAG=3=meta{0}
TAG=3=buildPass{1}
}
:endtag
:enddata
:endrule

rule:
plugin=vanillaInventory
number=39
data:
tag:
TAG=10={
TAG=3=lootLevel{0}
TAG=10=teData{
TAG=9=Items{
TAG=10={
TAG=2=id{334}
TAG=2=Damage{0}
TAG=1=Count{1}
TAG=1=Slot{10}
}
TAG=10={
TAG=2=id{334}
TAG=2=Damage{0}
TAG=1=Count{1}
TAG=1=Slot{15}
}
TAG=10={
TAG=2=id{334}
TAG=2=Damage{0}
TAG=1=Count{2}
TAG=1=Slot{16}
}
TAG=10={
TAG=2=id{334}
TAG=2=Damage{0}
TAG=1=Count{1}
TAG=1=Slot{19}
}
TAG=10={
TAG=2=id{334}
TAG=2=Damage{0}
TAG=1=Count{1}
TAG=1=Slot{20}
}
TAG=10={
TAG=2=id{334}
TAG=2=Damage{0}
TAG=1=Count{1}
TAG=1=Slot{21}
}
TAG=10={
TAG=2=id{334}
TAG=2=Damage{0}
TAG=1=Count{1}
TAG=1=Slot{22}
}
TAG=10={
TAG=2=id{334}
TAG=2=Damage{0}
TAG=1=Count{1}
TAG=1=Slot{23}
}
TAG=10={
TAG=2=id{334}
TAG=2=Damage{0}
TAG=1=Count{2}
TAG=1=Slot{24}
}
TAG=10={
TAG=2=id{334}
TAG=2=Damage{0}
TAG=1=Count{1}
TAG=1=Slot{25}
}
}
TAG=8=id{Chest}
}
TAG=8=blockName{chest}
TAG=3=meta{3}
TAG=3=buildPass{0}
}
:endtag
:enddata
:endrule

rule:
plugin=vanillaInventory
number=40
data:
tag:
TAG=10={
TAG=3=lootLevel{0}
TAG=10=teData{
TAG=9=Items{
TAG=10={
TAG=2=id{334}
TAG=2=Damage{0}
TAG=1=Count{1}
TAG=1=Slot{1}
}
TAG=10={
TAG=2=id{334}
TAG=2=Damage{0}
TAG=1=Count{1}
TAG=1=Slot{10}
}
TAG=10={
TAG=2=id{334}
TAG=2=Damage{0}
TAG=1=Count{1}
TAG=1=Slot{12}
}
TAG=10={
TAG=2=id{334}
TAG=2=Damage{0}
TAG=1=Count{1}
TAG=1=Slot{13}
}
TAG=10={
TAG=2=id{334}
TAG=2=Damage{0}
TAG=1=Count{1}
TAG=1=Slot{22}
}
TAG=10={
TAG=2=id{334}
TAG=2=Damage{0}
TAG=1=Count{1}
TAG=1=Slot{23}
}
}
TAG=8=id{Chest}
}
TAG=8=blockName{chest}
TAG=3=meta{3}
TAG=3=buildPass{0}
}
:endtag
:enddata
:endrule

rule:
plugin=vanillaInventory
number=41
data:
tag:
TAG=10={
TAG=3=lootLevel{0}
TAG=10=teData{
TAG=9=Items{
TAG=10={
TAG=2=id{335}
TAG=2=Damage{0}
TAG=1=Count{1}
TAG=1=Slot{10}
}
TAG=10={
TAG=2=id{335}
TAG=2=Damage{0}
TAG=1=Count{1}
TAG=1=Slot{12}
}
TAG=10={
TAG=2=id{335}
TAG=2=Damage{0}
TAG=1=Count{1}
TAG=1=Slot{14}
}
TAG=10={
TAG=2=id{335}
TAG=2=Damage{0}
TAG=1=Count{1}
TAG=1=Slot{16}
}
}
TAG=8=id{Chest}
}
TAG=8=blockName{chest}
TAG=3=meta{3}
TAG=3=buildPass{0}
}
:endtag
:enddata
:endrule

rule:
plugin=vanillaDoors
number=42
data:
tag:
TAG=10={
TAG=1=sideFlag{9}
TAG=8=blockName{wooden_door}
TAG=3=meta{1}
TAG=3=buildPass{1}
}
:endtag
:enddata
:endrule

rule:
plugin=vanillaInventory
number=43
data:
tag:
TAG=10={
TAG=3=lootLevel{0}
TAG=10=teData{
TAG=9=Items{
TAG=10={
TAG=2=id{363}
TAG=2=Damage{0}
TAG=1=Count{1}
TAG=1=Slot{11}
}
TAG=10={
TAG=2=id{363}
TAG=2=Damage{0}
TAG=1=Count{1}
TAG=1=Slot{13}
}
TAG=10={
TAG=2=id{363}
TAG=2=Damage{0}
TAG=1=Count{1}
TAG=1=Slot{14}
}
TAG=10={
TAG=2=id{363}
TAG=2=Damage{0}
TAG=1=Count{1}
TAG=1=Slot{15}
}
TAG=10={
TAG=2=id{363}
TAG=2=Damage{0}
TAG=1=Count{1}
TAG=1=Slot{20}
}
TAG=10={
TAG=2=id{363}
TAG=2=Damage{0}
TAG=1=Count{2}
TAG=1=Slot{24}
}
}
TAG=8=id{Chest}
}
TAG=8=blockName{chest}
TAG=3=meta{3}
TAG=3=buildPass{0}
}
:endtag
:enddata
:endrule

rule:
plugin=vanillaInventory
number=44
data:
tag:
TAG=10={
TAG=3=lootLevel{0}
TAG=10=teData{
TAG=9=Items{
TAG=10={
TAG=2=id{363}
TAG=2=Damage{0}
TAG=1=Count{1}
TAG=1=Slot{6}
}
TAG=10={
TAG=2=id{363}
TAG=2=Damage{0}
TAG=1=Count{1}
TAG=1=Slot{10}
}
TAG=10={
TAG=2=id{363}
TAG=2=Damage{0}
TAG=1=Count{1}
TAG=1=Slot{11}
}
TAG=10={
TAG=2=id{363}
TAG=2=Damage{0}
TAG=1=Count{1}
TAG=1=Slot{13}
}
TAG=10={
TAG=2=id{363}
TAG=2=Damage{0}
TAG=1=Count{1}
TAG=1=Slot{14}
}
TAG=10={
TAG=2=id{363}
TAG=2=Damage{0}
TAG=1=Count{1}
TAG=1=Slot{15}
}
}
TAG=8=id{Chest}
}
TAG=8=blockName{chest}
TAG=3=meta{3}
TAG=3=buildPass{0}
}
:endtag
:enddata
:endrule

rule:
plugin=vanillaBlocks
number=45
data:
tag:
TAG=10={
TAG=8=blockName{torch}
TAG=3=meta{1}
TAG=3=buildPass{1}
}
:endtag
:enddata
:endrule

rule:
plugin=vanillaBlocks
number=46
data:
tag:
TAG=10={
TAG=8=blockName{glass}
TAG=3=meta{0}
TAG=3=buildPass{0}
}
:endtag
:enddata
:endrule

rule:
plugin=vanillaBlocks
number=47
data:
tag:
TAG=10={
TAG=8=blockName{torch}
TAG=3=meta{4}
TAG=3=buildPass{1}
}
:endtag
:enddata
:endrule

rule:
plugin=vanillaBlocks
number=48
data:
tag:
TAG=10={
TAG=8=blockName{torch}
TAG=3=meta{3}
TAG=3=buildPass{1}
}
:endtag
:enddata
:endrule

rule:
plugin=vanillaBlocks
number=49
data:
tag:
TAG=10={
TAG=8=blockName{oak_stairs}
TAG=3=meta{7}
TAG=3=buildPass{0}
}
:endtag
:enddata
:endrule

rule:
plugin=vanillaDoors
number=50
data:
tag:
TAG=10={
TAG=1=sideFlag{0}
TAG=8=blockName{wooden_door}
TAG=3=meta{8}
TAG=3=buildPass{1}
}
:endtag
:enddata
:endrule

rule:
plugin=vanillaBlocks
number=51
data:
tag:
TAG=10={
TAG=8=blockName{stone_pressure_plate}
TAG=3=meta{0}
TAG=3=buildPass{0}
}
:endtag
:enddata
:endrule

rule:
plugin=vanillaBlocks
number=52
data:
tag:
TAG=10={
TAG=8=blockName{bed}
TAG=3=meta{0}
TAG=3=buildPass{0}
}
:endtag
:enddata
:endrule

rule:
plugin=vanillaBlocks
number=53
data:
tag:
TAG=10={
TAG=8=blockName{bed}
TAG=3=meta{8}
TAG=3=buildPass{0}
}
:endtag
:enddata
:endrule

rule:
plugin=vanillaBlocks
number=54
data:
tag:
TAG=10={
TAG=8=blockName{torch}
TAG=3=meta{2}
TAG=3=buildPass{1}
}
:endtag
:enddata
:endrule

rule:
plugin=vanillaBlocks
number=55
data:
tag:
TAG=10={
TAG=8=blockName{wooden_slab}
TAG=3=meta{0}
TAG=3=buildPass{0}
}
:endtag
:enddata
:endrule

rule:
plugin=vanillaDoors
number=56
data:
tag:
TAG=10={
TAG=1=sideFlag{0}
TAG=8=blockName{wooden_door}
TAG=3=meta{8}
TAG=3=buildPass{1}
}
:endtag
:enddata
:endrule

rule:
plugin=vanillaDoors
number=57
data:
tag:
TAG=10={
TAG=1=sideFlag{0}
TAG=8=blockName{wooden_door}
TAG=3=meta{8}
TAG=3=buildPass{1}
}
:endtag
:enddata
:endrule

rule:
plugin=vanillaDoors
number=58
data:
tag:
TAG=10={
TAG=1=sideFlag{0}
TAG=8=blockName{wooden_door}
TAG=3=meta{0}
TAG=3=buildPass{1}
}
:endtag
:enddata
:endrule

rule:
plugin=vanillaBlocks
number=59
data:
tag:
TAG=10={
TAG=8=blockName{log}
TAG=3=meta{8}
TAG=3=buildPass{0}
}
:endtag
:enddata
:endrule

rule:
plugin=vanillaBlocks
number=60
data:
tag:
TAG=10={
TAG=8=blockName{log}
TAG=3=meta{4}
TAG=3=buildPass{0}
}
:endtag
:enddata
:endrule

rule:
plugin=vanillaBlocks
number=61
data:
tag:
TAG=10={
TAG=8=blockName{wooden_slab}
TAG=3=meta{8}
TAG=3=buildPass{0}
}
:endtag
:enddata
:endrule

rule:
plugin=vanillaBlocks
number=62
data:
tag:
TAG=10={
TAG=8=blockName{oak_stairs}
TAG=3=meta{0}
TAG=3=buildPass{0}
}
:endtag
:enddata
:endrule

rule:
plugin=vanillaBlocks
number=63
data:
tag:
TAG=10={
TAG=8=blockName{stone_slab}
TAG=3=meta{2}
TAG=3=buildPass{0}
}
:endtag
:enddata
:endrule

rule:
plugin=vanillaInventory
number=64
data:
tag:
TAG=10={
TAG=3=lootLevel{0}
TAG=10=teData{
TAG=9=Items{
}
TAG=8=id{Chest}
}
TAG=8=blockName{chest}
TAG=3=meta{2}
TAG=3=buildPass{0}
}
:endtag
:enddata
:endrule

rule:
plugin=vanillaBlocks
number=65
data:
tag:
TAG=10={
TAG=8=blockName{stone_brick_stairs}
TAG=3=meta{0}
TAG=3=buildPass{0}
}
:endtag
:enddata
:endrule

rule:
plugin=vanillaInventory
number=66
data:
tag:
TAG=10={
TAG=3=lootLevel{0}
TAG=10=teData{
TAG=9=Items{
}
TAG=8=id{Chest}
}
TAG=8=blockName{chest}
TAG=3=meta{2}
TAG=3=buildPass{0}
}
:endtag
:enddata
:endrule

rule:
plugin=vanillaBlocks
number=67
data:
tag:
TAG=10={
TAG=8=blockName{stone_slab}
TAG=3=meta{10}
TAG=3=buildPass{0}
}
:endtag
:enddata
:endrule

rule:
plugin=vanillaBlocks
number=68
data:
tag:
TAG=10={
TAG=8=blockName{oak_stairs}
TAG=3=meta{6}
TAG=3=buildPass{0}
}
:endtag
:enddata
:endrule

rule:
plugin=vanillaBlocks
number=69
data:
tag:
TAG=10={
TAG=8=blockName{oak_stairs}
TAG=3=meta{5}
TAG=3=buildPass{0}
}
:endtag
:enddata
:endrule

rule:
plugin=vanillaBlocks
number=70
data:
tag:
TAG=10={
TAG=8=blockName{oak_stairs}
TAG=3=meta{4}
TAG=3=buildPass{0}
}
:endtag
:enddata
:endrule

rule:
plugin=vanillaBlocks
number=71
data:
tag:
TAG=10={
TAG=8=blockName{cobblestone_wall}
TAG=3=meta{0}
TAG=3=buildPass{0}
}
:endtag
:enddata
:endrule

#### ENTITIES ####
entity:
plugin=vanillaEntities
number=0
data:
position=11,6,12
tag:
TAG=10={
TAG=5=yOffset{0.0}
TAG=5=xOffset{0.775}
TAG=5=zOffset{0.775}
TAG=8=mobID{Chicken}
TAG=5=rotation{135.0}
}
:endtag
:enddata
:endentity

entity:
plugin=vanillaEntities
number=1
data:
position=16,6,14
tag:
TAG=10={
TAG=5=yOffset{0.0}
TAG=5=xOffset{0.22500002}
TAG=5=zOffset{0.225}
TAG=8=mobID{Chicken}
TAG=5=rotation{-45.0}
}
:endtag
:enddata
:endentity

entity:
plugin=vanillaEntities
number=2
data:
position=14,6,13
tag:
TAG=10={
TAG=5=yOffset{0.0}
TAG=5=xOffset{0.5879156}
TAG=5=zOffset{0.58074045}
TAG=8=mobID{Chicken}
TAG=5=rotation{125.352905}
}
:endtag
:enddata
:endentity

entity:
plugin=vanillaEntities
number=3
data:
position=15,6,12
tag:
TAG=10={
TAG=5=yOffset{0.0}
TAG=5=xOffset{0.4999957}
TAG=5=zOffset{0.775}
TAG=8=mobID{Chicken}
TAG=5=rotation{180.00017}
}
:endtag
:enddata
:endentity

entity:
plugin=vanillaEntities
number=4
data:
position=14,6,12
tag:
TAG=10={
TAG=5=yOffset{0.0}
TAG=5=xOffset{0.4998784}
TAG=5=zOffset{0.775}
TAG=8=mobID{Chicken}
TAG=5=rotation{180.00546}
}
:endtag
:enddata
:endentity

entity:
plugin=vanillaEntities
number=5
data:
position=20,6,2
tag:
TAG=10={
TAG=5=yOffset{0.0}
TAG=5=xOffset{0.40289444}
TAG=5=zOffset{0.5070143}
TAG=8=mobID{Chicken}
TAG=5=rotation{-91.23599}
}
:endtag
:enddata
:endentity

entity:
plugin=vanillaLogicEntity
number=6
data:
position=18,6,7
tag:
TAG=10={
TAG=10=entityData{
TAG=9=DropChances{
TAG=5=0{0.085}
TAG=5=1{0.085}
TAG=5=2{0.085}
TAG=5=3{0.085}
TAG=5=4{0.085}
}
TAG=3=Age{0}
TAG=9=Attributes{
TAG=10={
TAG=8=Name{generic.maxHealth}
TAG=6=Base{20.0}
}
TAG=10={
TAG=8=Name{generic.knockbackResistance}
TAG=6=Base{0.0}
}
TAG=10={
TAG=8=Name{generic.movementSpeed}
TAG=6=Base{0.5}
}
TAG=10={
TAG=8=Name{generic.followRange}
TAG=6=Base{16.0}
TAG=9=Modifiers{
TAG=10={
TAG=8=Name{Random spawn bonus}
TAG=4=UUIDLeast{-8408258205977228480}
TAG=3=Operation{1}
TAG=6=Amount{-0.0265679994553054}
TAG=4=UUIDMost{6784269518105035100}
}
}
}
}
TAG=9=Motion{
TAG=6={0.0}
TAG=6={-0.0784000015258789}
TAG=6={0.0}
}
TAG=8=CustomName{}
TAG=2=Health{19}
TAG=5=HealF{19.0}
TAG=1=CustomNameVisible{0}
TAG=3=Riches{0}
TAG=2=AttackTime{0}
TAG=2=Fire{-1}
TAG=1=Invulnerable{0}
TAG=2=DeathTime{0}
TAG=10=ForgeData{
TAG=1=MP|Init{1}
}
TAG=5=AbsorptionAmount{0.0}
TAG=9=Equipment{
TAG=10={
}
TAG=10={
}
TAG=10={
}
TAG=10={
}
TAG=10={
}
}
TAG=1=OnGround{1}
TAG=2=HurtTime{0}
TAG=3=Profession{385}
TAG=3=Dimension{0}
TAG=2=Air{300}
TAG=9=Pos{
TAG=6={327.08711609193494}
TAG=6={70.0}
TAG=6={-27.478492941753768}
}
TAG=1=CanPickUpLoot{0}
TAG=3=PortalCooldown{0}
TAG=1=PersistenceRequired{0}
TAG=1=Leashed{0}
TAG=5=FallDistance{0.0}
TAG=9=Rotation{
TAG=5={796.07294}
TAG=5={10.658722}
}
}
TAG=5=yOffset{0.0}
TAG=5=xOffset{0.47849298}
TAG=5=zOffset{0.08711609}
TAG=8=mobID{Villager}
TAG=5=rotation{166.07294}
}
:endtag
:enddata
:endentity

entity:
plugin=vanillaEntities
number=7
data:
position=7,6,2
tag:
TAG=10={
TAG=5=yOffset{0.0}
TAG=5=xOffset{0.5611355}
TAG=5=zOffset{0.4971742}
TAG=8=mobID{Chicken}
TAG=5=rotation{89.441}
}
:endtag
:enddata
:endentity

entity:
plugin=vanillaEntities
number=8
data:
position=9,7,15
tag:
TAG=10={
TAG=5=yOffset{0.0}
TAG=5=xOffset{0.66140956}
TAG=5=zOffset{0.24710236}
TAG=8=mobID{Cow}
TAG=5=rotation{-191.87097}
}
:endtag
:enddata
:endentity

entity:
plugin=vanillaEntities
number=9
data:
position=10,7,21
tag:
TAG=10={
TAG=5=yOffset{0.0}
TAG=5=xOffset{0.28668725}
TAG=5=zOffset{0.7573801}
TAG=8=mobID{Cow}
TAG=5=rotation{-15.62561}
}
:endtag
:enddata
:endentity

entity:
plugin=vanillaEntities
number=10
data:
position=10,7,26
tag:
TAG=10={
TAG=5=yOffset{0.0}
TAG=5=xOffset{0.37260962}
TAG=5=zOffset{0.76066506}
TAG=8=mobID{Cow}
TAG=5=rotation{-9.20874}
}
:endtag
:enddata
:endentity

entity:
plugin=vanillaLogicEntity
number=11
data:
position=8,7,20
tag:
TAG=10={
TAG=10=entityData{
TAG=9=DropChances{
TAG=5=0{0.085}
TAG=5=1{0.085}
TAG=5=2{0.085}
TAG=5=3{0.085}
TAG=5=4{0.085}
}
TAG=3=Age{0}
TAG=9=Attributes{
TAG=10={
TAG=8=Name{generic.maxHealth}
TAG=6=Base{20.0}
}
TAG=10={
TAG=8=Name{generic.knockbackResistance}
TAG=6=Base{0.0}
}
TAG=10={
TAG=8=Name{generic.movementSpeed}
TAG=6=Base{0.5}
}
TAG=10={
TAG=8=Name{generic.followRange}
TAG=6=Base{16.0}
TAG=9=Modifiers{
TAG=10={
TAG=8=Name{Random spawn bonus}
TAG=4=UUIDLeast{-8087293807664606245}
TAG=3=Operation{1}
TAG=6=Amount{-0.06017249187662506}
TAG=4=UUIDMost{-4500140290309469500}
}
}
}
}
TAG=9=Motion{
TAG=6={-5.8975567983212935E-18}
TAG=6={-0.0784000015258789}
TAG=6={0.0}
}
TAG=8=CustomName{}
TAG=2=Health{20}
TAG=5=HealF{20.0}
TAG=1=CustomNameVisible{0}
TAG=3=Riches{0}
TAG=2=AttackTime{0}
TAG=2=Fire{-1}
TAG=1=Invulnerable{0}
TAG=2=DeathTime{0}
TAG=10=ForgeData{
TAG=1=MP|Init{1}
}
TAG=5=AbsorptionAmount{0.0}
TAG=9=Equipment{
TAG=10={
}
TAG=10={
}
TAG=10={
}
TAG=10={
}
TAG=10={
}
}
TAG=1=OnGround{1}
TAG=2=HurtTime{0}
TAG=3=Profession{45}
TAG=3=Dimension{0}
TAG=2=Air{300}
TAG=9=Pos{
TAG=6={340.50011655644533}
TAG=6={71.0}
TAG=6={-17.07499998807905}
}
TAG=1=CanPickUpLoot{0}
TAG=3=PortalCooldown{0}
TAG=1=PersistenceRequired{0}
TAG=1=Leashed{0}
TAG=5=FallDistance{0.0}
TAG=9=Rotation{
TAG=5={-2340.0046}
TAG=5={0.0}
}
}
TAG=5=yOffset{0.0}
TAG=5=xOffset{0.07499999}
TAG=5=zOffset{0.5001165}
TAG=8=mobID{Villager}
TAG=5=rotation{-90.00464}
}
:endtag
:enddata
:endentity

entity:
plugin=vanillaLogicEntity
number=12
data:
position=7,7,19
tag:
TAG=10={
TAG=10=entityData{
TAG=9=DropChances{
TAG=5=0{0.085}
TAG=5=1{0.085}
TAG=5=2{0.085}
TAG=5=3{0.085}
TAG=5=4{0.085}
}
TAG=3=Age{0}
TAG=9=Attributes{
TAG=10={
TAG=8=Name{generic.maxHealth}
TAG=6=Base{20.0}
}
TAG=10={
TAG=8=Name{generic.knockbackResistance}
TAG=6=Base{0.0}
}
TAG=10={
TAG=8=Name{generic.movementSpeed}
TAG=6=Base{0.5}
}
TAG=10={
TAG=8=Name{generic.followRange}
TAG=6=Base{16.0}
TAG=9=Modifiers{
TAG=10={
TAG=8=Name{Random spawn bonus}
TAG=4=UUIDLeast{-6203357165734092366}
TAG=3=Operation{1}
TAG=6=Amount{0.0076310568371738136}
TAG=4=UUIDMost{7184420101561273678}
}
}
}
}
TAG=9=Motion{
TAG=6={0.0}
TAG=6={-0.0784000015258789}
TAG=6={0.0}
}
TAG=8=CustomName{}
TAG=2=Health{15}
TAG=5=HealF{15.0}
TAG=1=CustomNameVisible{0}
TAG=3=Riches{0}
TAG=2=AttackTime{0}
TAG=2=Fire{-1}
TAG=1=Invulnerable{0}
TAG=2=DeathTime{0}
TAG=10=ForgeData{
TAG=1=MP|Init{1}
}
TAG=5=AbsorptionAmount{0.0}
TAG=9=Equipment{
TAG=10={
}
TAG=10={
}
TAG=10={
}
TAG=10={
}
TAG=10={
}
}
TAG=1=OnGround{1}
TAG=2=HurtTime{0}
TAG=3=Profession{2435}
TAG=3=Dimension{0}
TAG=2=Air{300}
TAG=9=Pos{
TAG=6={339.6295440852085}
TAG=6={71.0}
TAG=6={-16.287403703891517}
}
TAG=1=CanPickUpLoot{0}
TAG=3=PortalCooldown{0}
TAG=1=PersistenceRequired{0}
TAG=1=Leashed{0}
TAG=5=FallDistance{0.0}
TAG=9=Rotation{
TAG=5={-2279.5525}
TAG=5={0.0}
}
}
TAG=5=yOffset{0.0}
TAG=5=xOffset{0.2874037}
TAG=5=zOffset{0.6295441}
TAG=8=mobID{Villager}
TAG=5=rotation{-29.55249}
}
:endtag
:enddata
:endentity

entity:
plugin=vanillaEntities
number=13
data:
position=3,7,20
tag:
TAG=10={
TAG=5=yOffset{0.0}
TAG=5=xOffset{0.66024864}
TAG=5=zOffset{0.22441167}
TAG=8=mobID{Cow}
TAG=5=rotation{-192.13623}
}
:endtag
:enddata
:endentity

entity:
plugin=vanillaEntities
number=14
data:
position=3,7,25
tag:
TAG=10={
TAG=5=yOffset{0.0}
TAG=5=xOffset{0.97403324}
TAG=5=zOffset{0.1004284}
TAG=8=mobID{Cow}
TAG=5=rotation{-218.00491}
}
:endtag
:enddata
:endentity

entity:
plugin=vanillaEntities
number=15
data:
position=1,6,28
tag:
TAG=10={
TAG=5=yOffset{0.0}
TAG=5=xOffset{0.46597004}
TAG=5=zOffset{0.73491997}
TAG=8=mobID{Cow}
TAG=5=rotation{-2.149231}
}
:endtag
:enddata
:endentity

entity:
plugin=vanillaEntities
number=16
data:
position=3,7,16
tag:
TAG=10={
TAG=5=yOffset{0.0}
TAG=5=xOffset{0.87339884}
TAG=5=zOffset{0.9743604}
TAG=8=mobID{Cow}
TAG=5=rotation{325.86093}
}
:endtag
:enddata
:endentity

entity:
plugin=vanillaEntities
number=17
data:
position=18,6,37
tag:
TAG=10={
TAG=5=yOffset{0.0}
TAG=5=xOffset{0.7594535}
TAG=5=zOffset{0.36477226}
TAG=8=mobID{Cow}
TAG=5=rotation{279.7456}
}
:endtag
:enddata
:endentity

