# Ancient Warfare Structure Template File
# auto-generated structure file. created on: 4/14/2014 at: 15:48:24
# Lines beginning with # denote comments

header:
version=2.0
name=CivFarmWindmillVerticalSailsMOH
size=19,34,19
offset=4,4,17
:endheader

#### VALIDATION ####
validation:
type=ground
survival=false
worldGenEnabled=true
unique=false
preserveBlocks=false
selectionWeight=10
clusterValue=10
minDuplicateDistance=40
dimensionWhiteList=false
dimensionList=
biomeWhiteList=true
biomeList=highlands.meadow,bop.meadow,ebxl.meadow,field,orchard
leveling=9
fill=5
border=5
validTargetBlocks=clay,sand,lapis_ore,grass,lit_redstone_ore,stone,gravel,iron_ore,diamond_ore,stained_hardened_clay,dirt,coal_ore,redstone_ore,gold_ore
data:
:enddata
:endvalidation

#### LAYERS ####
layer: 0
1,1,1,1,1,1,1,1,1,1,1,1,1,1,1,1,1,1,1
1,1,1,1,1,1,1,1,1,1,1,1,1,1,1,1,1,1,1
1,1,1,1,1,1,1,1,1,1,1,1,1,1,1,1,1,1,1
1,1,1,1,1,1,1,1,1,1,1,1,1,1,1,1,1,1,1
1,1,1,1,1,1,1,1,1,1,1,1,1,1,1,1,1,1,1
1,1,1,1,1,1,1,1,1,1,1,1,1,1,1,1,1,1,1
1,1,1,1,1,1,1,1,1,1,1,1,1,1,1,1,1,1,1
1,1,1,1,1,1,1,1,1,1,1,1,1,1,1,1,1,1,1
1,1,1,1,1,1,1,1,1,1,1,1,1,1,1,1,1,1,1
1,1,1,1,1,1,1,1,1,1,1,1,1,1,1,1,1,1,1
1,1,1,1,1,1,1,1,1,1,1,1,1,1,1,1,1,1,1
1,1,1,1,1,1,1,1,1,1,1,1,1,1,1,1,1,1,1
1,1,1,1,1,1,1,1,1,1,1,1,1,1,1,1,1,1,1
1,1,1,1,1,1,1,1,1,1,1,1,1,1,1,1,1,1,1
1,1,1,1,1,1,1,1,1,1,1,1,1,1,1,1,1,1,1
1,1,1,1,1,1,1,1,1,1,1,1,1,1,1,1,1,1,1
1,1,1,1,1,1,1,1,1,1,1,1,1,1,1,1,1,1,1
1,1,1,1,1,1,1,1,1,1,1,1,1,1,1,1,1,1,1
1,1,1,1,1,1,1,1,1,1,1,1,1,1,1,1,1,1,1
:endlayer
layer: 1
1,1,1,1,1,1,1,1,1,1,1,1,1,1,1,1,1,1,1
1,1,1,1,1,1,1,1,1,1,1,1,1,1,1,1,1,1,1
1,1,1,1,1,1,1,1,1,1,1,1,1,1,1,1,1,1,1
1,1,1,1,1,1,1,1,1,1,1,1,1,1,1,1,1,1,1
1,1,1,1,1,1,1,1,1,1,1,1,1,1,1,1,1,1,1
1,1,1,1,1,1,1,1,1,1,1,1,1,1,1,1,1,1,1
1,1,1,1,1,1,1,1,1,1,1,1,1,1,1,1,1,1,1
1,1,1,1,1,1,1,1,1,1,1,1,1,1,1,1,1,1,1
1,1,1,1,1,1,1,1,1,1,1,1,1,1,1,1,1,1,1
1,1,1,1,1,1,1,1,1,1,1,1,1,1,1,1,1,1,1
1,1,1,1,1,1,1,1,1,1,1,1,1,1,1,1,1,1,1
1,1,1,1,1,1,1,1,1,1,1,1,1,1,1,1,1,1,1
1,1,1,1,1,1,1,1,1,1,1,1,1,1,1,1,1,1,1
1,1,1,1,1,1,1,1,1,1,1,1,1,1,1,1,1,1,1
1,1,1,1,1,1,1,1,1,1,1,1,1,1,1,1,1,1,1
1,1,1,1,1,1,1,1,1,1,1,1,1,1,1,1,1,1,1
1,1,1,1,1,1,1,1,1,1,1,1,1,1,1,1,1,1,1
1,1,1,1,1,1,1,1,1,1,1,1,1,1,1,1,1,1,1
1,1,1,1,1,1,1,1,1,1,1,1,1,1,1,1,1,1,1
:endlayer
layer: 2
1,1,1,1,1,1,1,1,1,1,1,1,1,1,1,1,1,1,1
1,1,1,1,1,1,1,1,1,1,1,1,1,1,1,1,1,1,1
1,1,2,2,2,2,2,2,2,2,2,2,2,2,2,2,2,1,1
1,1,2,2,2,2,2,2,2,2,2,2,2,2,2,2,2,1,1
1,1,2,2,2,2,2,2,2,2,2,2,2,2,2,2,2,1,1
1,1,2,2,2,2,2,2,2,2,2,2,2,2,2,2,2,1,1
1,1,2,2,2,2,2,2,2,2,2,2,2,2,2,2,2,1,1
1,1,2,2,2,2,2,2,2,2,2,2,2,2,2,2,2,1,1
1,1,2,2,2,2,2,2,2,2,2,2,2,2,2,2,2,1,1
1,1,2,2,2,2,2,2,2,2,2,2,2,2,2,2,2,1,1
1,1,2,2,2,2,2,2,2,2,2,2,2,2,2,2,2,1,1
1,1,2,2,2,2,2,2,2,2,2,2,2,2,2,2,2,1,1
1,1,2,2,2,2,2,2,2,2,2,2,2,2,2,2,2,1,1
1,1,2,2,2,2,2,2,2,2,2,2,2,2,2,2,2,1,1
1,1,2,2,2,2,2,2,2,2,2,2,2,2,2,2,2,1,1
1,1,2,2,2,2,2,2,2,2,2,2,2,2,2,2,2,1,1
1,1,2,2,2,2,2,2,2,2,2,2,2,2,2,2,2,1,1
1,1,1,1,1,1,1,1,1,1,1,1,1,1,1,1,1,1,1
1,1,1,1,1,1,1,1,1,1,1,1,1,1,1,1,1,1,1
:endlayer
layer: 3
3,3,3,3,3,3,3,3,3,3,3,3,3,3,3,3,3,3,3
3,3,3,3,3,3,3,3,3,2,3,3,3,3,3,3,3,3,3
3,3,3,3,3,3,3,3,3,2,3,3,3,3,3,3,3,3,3
3,3,3,2,2,2,2,2,2,2,2,2,2,2,2,2,3,3,3
3,3,3,2,2,2,2,2,2,2,2,2,2,2,2,2,3,3,3
3,3,3,2,2,2,2,2,2,2,2,2,2,2,2,4,3,3,3
3,3,3,2,2,2,2,2,2,2,2,2,2,2,2,4,3,3,3
3,3,3,2,2,2,2,2,2,2,2,2,2,2,2,4,3,3,3
3,3,3,2,2,2,2,2,2,2,2,2,2,2,2,2,3,3,3
3,3,3,2,2,2,2,2,2,2,2,2,2,2,2,2,3,3,3
3,3,3,2,2,2,2,2,2,2,2,2,2,2,2,2,3,3,3
3,3,3,4,2,2,2,2,2,2,2,2,2,2,2,2,3,3,3
3,3,3,4,2,2,2,2,2,2,2,2,2,2,2,2,3,3,3
3,3,3,4,2,2,2,2,2,2,2,2,2,2,2,2,3,3,3
3,3,3,2,2,2,2,2,2,2,2,2,2,2,2,2,3,3,3
3,3,3,2,2,2,2,2,2,2,4,4,4,2,2,2,3,3,3
3,3,3,3,3,2,3,3,3,3,3,3,3,3,3,3,3,3,3
3,3,3,3,3,2,3,3,3,3,3,3,3,3,3,3,3,3,3
1,3,3,3,3,3,3,3,3,3,3,3,3,3,3,3,3,3,3
:endlayer
layer: 4
0,0,0,0,5,5,5,0,0,0,0,0,0,0,0,5,0,0,5
0,6,6,6,6,6,6,6,6,25,6,6,6,6,6,6,6,6,5
0,6,0,0,0,5,5,0,0,0,0,0,0,0,0,0,0,6,5
0,6,0,8,8,8,8,8,8,24,8,8,8,23,8,8,5,6,5
0,6,0,8,8,8,8,8,0,0,0,0,0,0,0,8,0,6,0
0,6,5,8,8,8,8,22,0,0,0,0,0,0,0,6,0,6,0
0,6,5,21,0,0,0,0,0,0,0,0,0,0,0,6,0,6,0
5,6,5,8,20,0,0,0,0,0,0,0,0,0,0,6,0,6,0
0,6,0,8,19,0,0,0,6,18,17,6,0,0,0,8,0,6,0
0,6,0,8,8,0,0,0,8,8,8,8,0,0,8,8,5,6,5
0,6,0,8,0,0,0,0,0,0,16,15,0,0,6,8,0,6,5
0,6,0,6,0,0,11,11,11,0,0,0,0,0,14,8,0,6,5
0,6,0,6,0,0,11,13,11,0,0,0,0,0,12,8,5,6,5
0,6,0,6,0,0,11,11,11,0,0,0,0,0,6,8,0,6,0
5,6,5,8,0,0,0,0,0,0,0,0,0,0,10,8,0,6,0
5,6,5,8,8,9,8,8,8,8,6,6,6,8,8,8,5,6,5
5,6,5,0,0,0,0,0,5,0,5,0,0,5,0,0,0,6,5
0,6,6,6,6,7,6,6,6,6,6,6,6,6,6,6,6,6,0
0,0,0,0,0,0,0,0,5,0,5,5,5,0,0,0,0,0,5
:endlayer
layer: 5
0,0,0,0,0,0,0,0,0,0,0,0,0,0,0,0,0,0,0
0,26,0,0,0,0,0,0,0,0,0,0,0,0,0,0,0,26,0
0,0,0,0,0,0,0,0,0,0,0,0,0,0,0,0,0,0,0
0,0,0,2,2,2,2,2,2,30,2,2,2,6,2,2,0,0,0
0,0,0,2,2,2,2,2,0,0,0,0,0,0,0,4,0,0,0
0,0,0,2,2,2,22,0,0,0,0,0,0,0,0,6,0,0,0
0,0,0,6,0,29,0,0,0,0,0,0,0,0,0,6,0,0,0
0,0,0,2,6,0,0,0,0,0,0,0,0,0,0,6,0,0,0
0,0,0,2,6,0,0,0,6,6,6,6,0,0,28,4,0,0,0
0,0,0,2,4,0,0,0,4,2,2,2,0,0,2,2,0,0,0
0,0,0,4,0,0,0,0,0,0,6,6,0,0,6,2,0,0,0
0,0,0,6,0,0,0,0,0,0,0,0,0,0,6,2,0,0,0
0,0,0,6,0,0,0,2,0,0,0,0,0,0,6,2,0,0,0
0,0,0,6,0,0,0,0,0,0,0,0,0,0,6,2,0,0,0
0,0,0,4,0,0,0,0,0,0,0,0,0,0,0,2,0,0,0
0,0,0,2,2,27,2,2,2,4,6,6,6,4,2,2,0,0,0
0,0,0,0,0,0,0,0,0,0,0,0,0,0,0,0,0,0,0
0,26,0,0,0,0,0,0,0,0,0,0,0,0,0,0,0,26,0
0,0,0,0,0,0,0,0,0,0,0,0,0,0,0,0,0,0,0
:endlayer
layer: 6
0,0,0,0,0,0,0,0,0,0,0,0,0,0,0,0,0,0,0
0,0,0,0,0,0,0,0,0,0,0,0,0,0,0,0,0,0,0
0,0,0,0,0,0,28,0,0,0,0,28,0,0,0,0,0,0,0
0,0,0,8,8,8,8,8,8,6,8,8,8,6,8,8,0,0,0
0,0,0,8,8,8,8,8,0,0,0,0,0,0,0,8,0,0,0
0,0,0,8,8,22,0,0,0,0,0,0,0,0,0,6,0,0,0
0,0,0,6,0,0,0,0,0,0,0,0,0,0,0,6,0,0,0
0,0,0,8,41,0,0,0,0,0,0,0,0,0,0,6,0,0,0
0,0,31,8,40,0,0,0,6,39,38,6,0,0,0,8,0,0,0
0,0,0,8,8,0,0,0,8,8,8,8,6,6,8,8,0,0,0
0,0,0,8,0,0,0,0,0,0,37,36,0,0,6,8,0,0,0
0,0,0,6,0,0,0,32,0,0,0,0,0,0,35,8,0,0,0
0,0,0,6,0,0,32,2,32,0,0,0,0,0,34,8,33,0,0
0,0,0,6,0,0,0,32,0,0,0,0,0,0,6,8,0,0,0
0,0,0,8,0,0,0,0,0,0,0,0,0,0,31,8,0,0,0
0,0,0,8,8,6,8,8,8,8,6,6,6,8,8,8,0,0,0
0,0,0,0,0,0,0,29,0,0,0,0,0,0,0,0,0,0,0
0,0,0,0,0,0,0,0,0,0,0,0,0,0,0,0,0,0,0
0,0,0,0,0,0,0,0,0,0,0,0,0,0,0,0,0,0,0
:endlayer
layer: 7
0,0,0,0,0,0,0,0,0,0,0,0,0,0,0,0,0,0,0
0,0,0,0,0,0,0,0,0,0,0,0,0,0,0,0,0,0,0
0,0,49,0,0,0,50,0,0,0,0,0,50,0,0,0,49,0,0
0,0,0,2,2,2,2,2,2,8,2,2,2,8,2,2,0,0,0
0,0,0,2,0,48,2,2,29,0,29,0,0,0,0,2,0,0,0
0,0,0,2,0,0,0,0,0,0,0,0,0,0,0,8,0,0,0
0,0,0,8,0,0,0,0,0,0,0,0,0,0,0,8,46,0,0
0,0,0,2,6,0,0,0,0,0,0,0,0,0,0,8,0,0,0
0,0,47,2,6,0,0,0,6,6,6,6,0,0,0,2,0,0,0
0,0,0,2,2,8,8,8,2,2,2,2,8,8,2,2,0,0,0
0,0,0,2,29,0,0,0,29,0,6,6,0,0,6,2,46,0,0
0,0,0,8,0,0,0,45,0,0,0,0,0,0,6,2,0,0,0
0,0,0,8,0,0,44,2,43,0,0,0,0,0,6,2,0,0,0
0,0,0,8,0,0,0,42,0,0,0,0,0,0,6,2,0,0,0
0,0,0,2,28,0,28,0,0,0,0,0,0,28,0,2,0,0,0
0,0,0,2,2,8,2,2,2,2,8,8,8,2,2,2,0,0,0
0,0,0,0,0,0,0,0,0,0,0,0,0,0,0,0,0,0,0
0,0,0,0,0,0,0,0,0,0,0,0,0,0,0,0,0,0,0
0,0,0,0,0,0,0,0,0,0,0,0,0,0,0,0,0,0,0
:endlayer
layer: 8
0,0,0,0,0,0,0,0,0,0,0,0,0,0,0,0,0,0,0
0,0,0,0,0,0,0,0,0,0,0,0,0,0,0,0,0,0,0
0,0,51,0,0,0,51,0,0,0,0,0,51,0,0,0,51,0,0
0,0,0,2,2,2,2,2,2,2,2,2,2,2,2,2,0,0,0
0,0,0,2,0,0,48,2,55,55,55,55,55,55,55,2,0,0,0
0,0,0,2,0,0,0,2,55,55,55,55,55,55,55,2,0,0,0
0,0,0,2,2,2,2,2,55,55,55,55,55,55,55,2,51,0,0
0,0,0,2,55,55,55,55,55,55,55,55,55,55,55,2,0,0,0
0,0,51,2,2,2,2,2,2,55,55,55,55,55,55,2,0,0,0
0,0,0,51,52,52,52,52,52,52,55,55,55,55,55,2,0,0,0
0,0,0,51,52,0,54,54,54,0,51,2,2,2,2,2,51,0,0
0,0,0,51,52,52,8,8,8,52,52,52,52,52,53,51,0,0,0
0,0,0,51,52,52,8,13,8,52,52,52,52,52,52,51,0,0,0
0,0,0,51,52,52,8,8,8,52,52,52,52,52,52,51,0,0,0
0,0,0,51,52,52,52,52,52,52,52,52,52,52,52,51,0,0,0
0,0,0,51,51,51,51,51,51,51,51,51,51,51,51,51,0,0,0
0,0,0,0,0,0,0,0,0,0,0,0,0,0,0,0,0,0,0
0,0,0,0,0,0,0,0,0,0,0,0,0,0,0,0,0,0,0
0,0,0,0,0,0,0,0,0,0,0,0,0,0,0,0,0,0,0
:endlayer
layer: 9
0,0,0,0,0,0,0,0,0,0,0,0,0,0,0,0,0,0,0
0,0,0,0,0,0,0,0,0,0,0,0,0,0,0,0,0,0,0
0,0,51,8,8,8,51,8,8,8,8,8,51,8,8,8,51,0,0
0,0,8,0,0,0,0,0,0,0,0,0,0,0,0,61,8,0,0
0,0,8,0,0,0,0,0,0,0,0,0,0,0,0,60,8,0,0
0,0,8,0,0,0,0,6,0,0,0,0,51,0,0,0,8,0,0
0,0,8,0,0,0,0,0,0,0,32,32,32,0,0,10,51,0,0
0,0,8,59,58,0,0,54,54,54,32,2,32,0,0,0,8,0,0
0,0,51,8,8,8,0,0,0,8,8,32,32,0,0,57,8,0,0
0,0,0,6,0,0,0,0,0,0,8,0,0,0,0,56,8,0,0
0,0,0,6,0,54,0,54,0,54,51,8,2,8,9,8,51,0,0
0,0,0,6,0,0,8,8,8,0,0,0,0,0,0,6,0,0,0
0,0,0,6,0,0,8,51,8,0,0,0,0,0,0,6,0,0,0
0,0,0,6,0,0,8,8,8,0,0,0,0,0,0,6,0,0,0
0,0,0,6,0,0,0,0,0,0,0,0,0,0,0,6,0,0,0
0,0,0,6,6,6,6,6,6,6,6,6,6,6,6,6,0,0,0
0,0,0,0,0,0,0,0,0,0,0,0,0,0,0,0,0,0,0
0,0,0,0,0,0,0,0,0,0,0,0,0,0,0,0,0,0,0
0,0,0,0,0,0,0,0,0,0,0,0,0,0,0,0,0,0,0
:endlayer
layer: 10
0,0,0,0,0,0,0,0,0,0,0,0,0,0,0,0,0,0,0
0,0,0,0,0,0,0,0,0,0,0,0,0,0,0,0,0,0,0
0,0,51,2,63,2,51,2,63,2,63,2,51,2,63,2,51,0,0
0,0,2,0,0,0,0,0,0,0,0,0,0,0,0,0,2,0,0
0,0,63,0,0,0,0,0,0,0,0,0,0,0,0,0,63,0,0
0,0,2,0,0,0,0,6,0,0,0,0,51,0,0,0,2,0,0
0,0,63,0,0,0,0,6,0,0,0,11,0,0,0,0,51,0,0
0,0,2,0,0,0,0,6,0,0,11,0,11,0,0,0,2,0,0
0,0,51,2,2,2,0,6,0,2,51,11,0,0,0,0,63,0,0
0,0,0,0,0,0,0,13,0,0,2,0,0,28,0,0,2,0,0
0,0,0,0,0,54,54,13,54,54,51,2,63,2,62,2,51,0,0
0,0,0,0,0,0,8,8,8,0,0,0,0,29,0,0,0,0,0
0,0,0,0,0,31,8,51,8,33,0,0,0,0,0,0,0,0,0
0,0,0,0,0,0,8,8,8,0,0,0,0,0,0,0,0,0,0
0,0,0,0,0,0,0,29,0,0,0,0,0,0,0,0,0,0,0
0,0,0,26,0,0,0,0,0,0,0,0,0,0,0,26,0,0,0
0,0,0,0,0,0,0,0,0,0,0,0,0,0,0,0,0,0,0
0,0,0,0,0,0,0,0,0,0,0,0,0,0,0,0,0,0,0
0,0,0,0,0,0,0,0,0,0,0,0,0,0,0,0,0,0,0
:endlayer
layer: 11
0,0,0,0,0,0,0,0,0,0,0,0,0,0,0,0,0,0,0
0,0,0,0,0,0,0,0,0,0,0,0,0,0,0,0,0,0,0
0,0,51,8,63,8,51,8,63,8,63,8,51,8,63,8,51,0,0
0,0,8,0,0,0,29,0,0,0,0,0,29,0,0,0,8,0,0
0,0,63,0,0,0,0,0,0,0,0,0,0,0,0,0,63,0,0
0,0,8,0,0,0,0,0,0,0,0,31,51,33,0,0,8,0,0
0,0,63,0,0,0,0,0,0,0,0,0,0,0,0,31,51,0,0
0,0,8,0,0,0,0,0,0,0,28,0,0,0,0,0,8,0,0
0,0,51,8,8,8,0,0,0,8,51,33,0,0,0,0,63,0,0
0,0,0,0,29,0,0,0,0,0,8,0,0,0,0,0,8,0,0
0,0,0,0,0,54,0,54,0,54,51,8,63,8,6,8,51,0,0
0,0,0,0,0,0,0,64,0,0,0,0,0,0,0,0,0,0,0
0,0,0,0,0,0,64,51,64,0,0,0,0,0,0,0,0,0,0
0,0,0,0,0,0,0,64,0,0,0,0,0,0,0,0,0,0,0
0,0,0,0,0,0,0,0,0,0,0,0,0,0,0,0,0,0,0
0,0,0,0,0,0,0,0,0,0,0,0,0,0,0,0,0,0,0
0,0,0,0,0,0,0,0,0,0,0,0,0,0,0,0,0,0,0
0,0,0,0,0,0,0,0,0,0,0,0,0,0,0,0,0,0,0
0,0,0,0,0,0,0,0,0,0,0,0,0,0,0,0,0,0,0
:endlayer
layer: 12
0,0,0,0,0,0,0,0,0,0,0,0,0,0,0,0,0,0,0
0,0,0,0,0,0,0,0,0,0,0,0,0,0,0,0,0,0,0
0,0,51,2,8,2,51,2,8,2,8,2,51,2,8,2,51,0,0
0,0,2,0,0,0,0,0,29,0,29,0,0,0,0,0,2,0,0
0,0,8,0,0,0,0,0,0,0,0,0,0,0,0,0,8,0,0
0,0,2,33,0,0,0,0,0,0,0,0,51,0,0,31,2,0,0
0,0,8,0,0,0,0,0,0,0,0,0,0,0,0,0,51,0,0
0,0,2,0,0,28,0,0,0,28,0,0,0,0,0,31,2,0,0
0,0,51,2,2,2,8,8,8,2,51,0,0,0,0,0,8,0,0
0,0,0,0,0,0,0,0,0,0,2,0,0,0,0,0,2,0,0
0,0,0,0,0,0,54,54,54,0,51,2,8,2,8,2,51,0,0
0,0,0,0,0,0,0,52,0,0,0,0,0,0,0,0,0,0,0
0,0,0,0,0,0,52,51,52,0,0,0,0,0,0,0,0,0,0
0,0,0,0,0,0,0,52,0,0,0,0,0,0,0,0,0,0,0
0,0,0,0,0,0,0,0,0,0,0,0,0,0,0,0,0,0,0
0,0,0,0,0,0,0,0,0,0,0,0,0,0,0,0,0,0,0
0,0,0,0,0,0,0,0,0,0,0,0,0,0,0,0,0,0,0
0,0,0,0,0,0,0,0,0,0,0,0,0,0,0,0,0,0,0
0,0,0,0,0,0,0,0,0,0,0,0,0,0,0,0,0,0,0
:endlayer
layer: 13
0,0,0,0,0,0,0,0,0,0,0,0,0,0,0,0,0,0,0
0,52,52,52,52,52,52,52,52,52,52,52,52,52,52,52,52,52,0
0,52,55,54,54,54,54,54,54,54,54,54,54,54,54,54,54,52,0
0,52,54,51,0,0,51,0,0,0,0,0,51,0,0,51,54,52,0
0,52,54,0,51,0,51,0,0,0,0,0,51,0,51,0,54,52,0
0,52,54,0,0,51,51,51,51,51,51,51,51,51,0,0,54,52,0
0,52,54,0,51,0,51,0,0,0,0,0,51,51,51,51,54,52,0
0,52,54,51,0,0,51,0,0,0,0,51,0,51,0,0,54,52,0
0,52,54,54,54,42,42,42,42,42,55,0,0,0,51,0,54,52,0
0,52,52,52,52,0,0,0,0,0,44,0,0,0,0,51,54,52,0
0,0,0,0,0,0,0,0,0,0,44,54,54,54,54,54,54,52,0
0,0,0,0,0,0,0,0,0,0,52,52,52,52,52,52,52,52,0
0,0,0,0,0,0,0,51,0,0,0,0,0,0,0,0,0,0,0
0,0,0,0,0,0,0,0,0,0,0,0,0,0,0,0,0,0,0
0,0,0,0,0,0,0,0,0,0,0,0,0,0,0,0,0,0,0
0,0,0,0,0,0,0,0,0,0,0,0,0,0,0,0,0,0,0
0,0,0,0,0,0,0,0,0,0,0,0,0,0,0,0,0,0,0
0,0,0,0,0,0,0,0,0,0,0,0,0,0,0,0,0,0,0
0,0,0,0,0,0,0,0,0,0,0,0,0,0,0,0,0,0,0
:endlayer
layer: 14
0,0,0,0,0,0,0,0,0,0,0,0,0,0,0,0,0,0,0
0,0,0,0,0,0,0,0,0,0,0,0,0,0,0,0,0,0,0
0,0,0,0,0,0,0,0,0,0,0,0,0,0,0,0,0,0,0
0,0,0,52,52,52,52,52,52,52,52,52,52,52,52,52,0,0,0
0,0,0,52,54,54,54,54,54,54,54,54,54,54,54,52,0,0,0
0,0,0,52,54,51,51,54,54,54,54,54,51,51,54,52,0,0,0
0,0,0,52,54,54,54,54,54,54,54,54,54,51,54,52,0,0,0
0,0,0,52,52,52,52,52,52,52,52,52,54,51,54,52,0,0,0
0,0,0,0,0,0,0,0,0,0,0,52,54,54,54,52,0,0,0
0,0,0,0,0,0,0,0,0,0,0,52,52,52,52,52,0,0,0
0,0,0,0,0,0,0,0,0,0,0,0,0,0,0,0,0,0,0
0,0,0,0,0,0,0,0,0,0,0,0,0,0,0,0,0,0,0
0,0,0,0,0,0,0,13,0,0,0,0,0,0,0,0,0,0,0
0,0,0,0,0,0,0,0,0,0,0,0,0,0,0,0,0,0,0
0,0,0,0,0,0,0,0,0,0,0,0,0,0,0,0,0,0,0
0,0,0,0,0,0,0,0,0,0,0,0,0,0,0,0,0,0,0
0,0,0,0,0,0,0,0,0,0,0,0,0,0,0,0,0,0,0
0,0,0,0,0,0,0,0,0,0,0,0,0,0,0,0,0,0,0
0,0,0,0,0,0,0,0,0,0,0,0,0,0,0,0,0,0,0
:endlayer
layer: 15
0,0,0,0,0,0,0,0,0,0,0,0,0,0,0,0,0,0,0
0,0,0,0,0,0,0,0,0,0,0,0,0,0,0,0,0,0,0
0,0,0,0,0,0,0,0,0,0,0,0,0,0,0,0,0,0,0
0,0,0,0,0,0,0,0,0,0,0,0,0,0,0,0,0,0,0
0,0,0,0,0,0,0,0,0,0,0,0,0,0,0,0,0,0,0
0,0,0,0,0,52,52,52,52,52,52,52,52,52,0,0,0,0,0
0,0,0,0,0,0,0,0,0,0,0,0,0,52,0,0,0,0,0
0,0,0,0,0,0,0,0,0,0,0,0,0,52,0,0,0,0,0
0,0,0,0,0,0,0,0,0,0,0,0,0,0,0,0,0,0,0
0,0,0,0,6,6,0,0,0,0,6,0,0,0,0,0,0,0,0
0,0,0,0,0,6,6,0,0,6,6,0,0,0,0,0,0,0,0
0,0,0,0,0,0,6,6,6,6,0,0,0,0,0,0,0,0,0
0,0,0,0,0,0,6,4,6,0,0,0,0,0,0,0,0,0,0
0,0,0,0,0,6,6,6,6,0,0,0,0,0,0,0,0,0,0
0,0,0,0,6,6,0,0,6,6,0,0,0,0,0,0,0,0,0
0,0,0,0,6,0,0,0,0,6,6,0,0,0,0,0,0,0,0
0,0,0,0,0,0,0,0,0,0,0,0,0,0,0,0,0,0,0
0,0,0,0,0,0,0,0,0,0,0,0,0,0,0,0,0,0,0
0,0,0,0,0,0,0,0,0,0,0,0,0,0,0,0,0,0,0
:endlayer
layer: 16
0,0,0,0,0,0,0,0,0,0,0,0,0,0,0,0,0,0,0
0,0,0,0,0,0,0,0,0,0,0,0,0,0,0,0,0,0,0
0,0,0,0,0,0,0,0,0,0,0,0,0,0,0,0,0,0,0
0,0,0,0,0,0,0,0,0,0,0,0,0,0,0,0,0,0,0
0,0,0,0,0,0,0,0,0,0,0,0,0,0,0,0,0,0,0
0,0,0,0,0,0,0,0,0,0,0,0,0,0,0,0,0,0,0
0,0,0,0,0,0,0,0,0,0,0,0,0,0,0,0,0,0,0
0,0,0,0,0,0,0,0,0,0,0,0,0,0,0,0,0,0,0
0,0,0,0,0,0,0,0,0,0,0,0,0,0,0,0,0,0,0
0,0,0,0,65,0,0,0,0,0,65,0,0,0,0,0,0,0,0
0,0,0,0,0,65,0,0,0,65,0,0,0,0,0,0,0,0,0
0,0,0,0,0,0,65,0,65,0,0,0,0,0,0,0,0,0,0
0,0,0,0,0,0,0,51,0,0,0,0,0,0,0,0,0,0,0
0,0,0,0,0,0,65,0,65,0,0,0,0,0,0,0,0,0,0
0,0,0,0,0,65,0,0,0,65,0,0,0,0,0,0,0,0,0
0,0,0,0,65,0,0,0,0,0,65,0,0,0,0,0,0,0,0
0,0,0,0,0,0,0,0,0,0,0,0,0,0,0,0,0,0,0
0,0,0,0,0,0,0,0,0,0,0,0,0,0,0,0,0,0,0
0,0,0,0,0,0,0,0,0,0,0,0,0,0,0,0,0,0,0
:endlayer
layer: 17
0,0,0,0,0,0,0,0,0,0,0,0,0,0,0,0,0,0,0
0,0,0,0,0,0,0,0,0,0,0,0,0,0,0,0,0,0,0
0,0,0,0,0,0,0,0,0,0,0,0,0,0,0,0,0,0,0
0,0,0,0,0,0,0,0,0,0,0,0,0,0,0,0,0,0,0
0,0,0,0,0,0,0,0,0,0,0,0,0,0,0,0,0,0,0
0,0,0,0,0,0,0,0,0,0,0,0,0,0,0,0,0,0,0
0,0,0,0,0,0,0,0,0,0,0,0,0,0,0,0,0,0,0
0,0,0,0,0,0,0,0,0,0,0,0,0,0,0,0,0,0,0
0,0,0,0,0,0,0,0,0,0,0,0,0,0,0,0,0,0,0
0,0,0,0,65,0,0,0,0,0,65,0,0,0,0,0,0,0,0
0,0,0,0,0,65,0,0,0,65,0,0,0,0,0,0,0,0,0
0,0,0,0,0,0,65,0,65,0,0,0,0,0,0,0,0,0,0
0,0,0,0,0,0,0,51,0,0,0,0,0,0,0,0,0,0,0
0,0,0,0,0,0,65,0,65,0,0,0,0,0,0,0,0,0,0
0,0,0,0,0,65,0,0,0,65,0,0,0,0,0,0,0,0,0
0,0,0,0,65,0,0,0,0,0,65,0,0,0,0,0,0,0,0
0,0,0,0,0,0,0,0,0,0,0,0,0,0,0,0,0,0,0
0,0,0,0,0,0,0,0,0,0,0,0,0,0,0,0,0,0,0
0,0,0,0,0,0,0,0,0,0,0,0,0,0,0,0,0,0,0
:endlayer
layer: 18
0,0,0,0,0,0,0,0,0,0,0,0,0,0,0,0,0,0,0
0,0,0,0,0,0,0,0,0,0,0,0,0,0,0,0,0,0,0
0,0,0,0,0,0,0,0,0,0,0,0,0,0,0,0,0,0,0
0,0,0,0,0,0,0,0,0,0,0,0,0,0,0,0,0,0,0
0,0,0,0,0,0,0,0,0,0,0,0,0,0,0,0,0,0,0
0,0,0,0,0,0,0,0,0,0,0,0,0,0,0,0,0,0,0
0,0,0,0,0,0,0,0,0,0,0,0,0,0,0,0,0,0,0
0,0,0,0,0,0,0,0,0,0,0,0,0,0,0,0,0,0,0
0,0,0,0,0,0,0,0,0,0,0,0,0,0,0,0,0,0,0
0,0,0,0,65,0,0,0,0,0,65,0,0,0,0,0,0,0,0
0,0,0,0,0,65,0,0,0,65,0,0,0,0,0,0,0,0,0
0,0,0,0,0,0,65,0,65,0,0,0,0,0,0,0,0,0,0
0,0,0,0,0,0,0,51,0,0,0,0,0,0,0,0,0,0,0
0,0,0,0,0,0,65,0,65,0,0,0,0,0,0,0,0,0,0
0,0,0,0,0,65,0,0,0,65,0,0,0,0,0,0,0,0,0
0,0,0,0,65,0,0,0,0,0,65,0,0,0,0,0,0,0,0
0,0,0,0,0,0,0,0,0,0,0,0,0,0,0,0,0,0,0
0,0,0,0,0,0,0,0,0,0,0,0,0,0,0,0,0,0,0
0,0,0,0,0,0,0,0,0,0,0,0,0,0,0,0,0,0,0
:endlayer
layer: 19
0,0,0,0,0,0,0,0,0,0,0,0,0,0,0,0,0,0,0
0,0,0,0,0,0,0,0,0,0,0,0,0,0,0,0,0,0,0
0,0,0,0,0,0,0,0,0,0,0,0,0,0,0,0,0,0,0
0,0,0,0,0,0,0,0,0,0,0,0,0,0,0,0,0,0,0
0,0,0,0,0,0,0,0,0,0,0,0,0,0,0,0,0,0,0
0,0,0,0,0,0,0,0,0,0,0,0,0,0,0,0,0,0,0
0,0,0,0,0,0,0,0,0,0,0,0,0,0,0,0,0,0,0
0,0,0,0,0,0,0,0,0,0,0,0,0,0,0,0,0,0,0
0,0,0,0,0,0,0,0,0,0,0,0,0,0,0,0,0,0,0
0,0,0,0,6,6,0,0,0,0,6,0,0,0,0,0,0,0,0
0,0,0,0,0,6,6,0,0,6,6,0,0,0,0,0,0,0,0
0,0,0,0,0,0,6,6,6,6,0,0,0,0,0,0,0,0,0
0,0,0,0,0,0,6,4,6,0,0,0,0,0,0,0,0,0,0
0,0,0,0,0,6,6,6,6,0,0,0,0,0,0,0,0,0,0
0,0,0,0,6,6,0,0,6,6,0,0,0,0,0,0,0,0,0
0,0,0,0,6,0,0,0,0,6,6,0,0,0,0,0,0,0,0
0,0,0,0,0,0,0,0,0,0,0,0,0,0,0,0,0,0,0
0,0,0,0,0,0,0,0,0,0,0,0,0,0,0,0,0,0,0
0,0,0,0,0,0,0,0,0,0,0,0,0,0,0,0,0,0,0
:endlayer
layer: 20
0,0,0,0,0,0,0,0,0,0,0,0,0,0,0,0,0,0,0
0,0,0,0,0,0,0,0,0,0,0,0,0,0,0,0,0,0,0
0,0,0,0,0,0,0,0,0,0,0,0,0,0,0,0,0,0,0
0,0,0,0,0,0,0,0,0,0,0,0,0,0,0,0,0,0,0
0,0,0,0,0,0,0,0,0,0,0,0,0,0,0,0,0,0,0
0,0,0,0,0,0,0,0,0,0,0,0,0,0,0,0,0,0,0
0,0,0,0,0,0,0,0,0,0,0,0,0,0,0,0,0,0,0
0,0,0,0,0,0,0,0,0,0,0,0,0,0,0,0,0,0,0
0,0,0,0,0,0,0,0,0,0,0,0,0,0,0,0,0,0,0
0,0,0,0,65,0,0,0,0,0,65,0,0,0,0,0,0,0,0
0,0,0,0,0,65,0,0,0,65,0,0,0,0,0,0,0,0,0
0,0,0,0,0,0,65,0,65,0,0,0,0,0,0,0,0,0,0
0,0,0,0,0,0,0,51,0,0,0,0,0,0,0,0,0,0,0
0,0,0,0,0,0,65,0,65,0,0,0,0,0,0,0,0,0,0
0,0,0,0,0,65,0,0,0,65,0,0,0,0,0,0,0,0,0
0,0,0,0,65,0,0,0,0,0,65,0,0,0,0,0,0,0,0
0,0,0,0,0,0,0,0,0,0,0,0,0,0,0,0,0,0,0
0,0,0,0,0,0,0,0,0,0,0,0,0,0,0,0,0,0,0
0,0,0,0,0,0,0,0,0,0,0,0,0,0,0,0,0,0,0
:endlayer
layer: 21
0,0,0,0,0,0,0,0,0,0,0,0,0,0,0,0,0,0,0
0,0,0,0,0,0,0,0,0,0,0,0,0,0,0,0,0,0,0
0,0,0,0,0,0,0,0,0,0,0,0,0,0,0,0,0,0,0
0,0,0,0,0,0,0,0,0,0,0,0,0,0,0,0,0,0,0
0,0,0,0,0,0,0,0,0,0,0,0,0,0,0,0,0,0,0
0,0,0,0,0,0,0,0,0,0,0,0,0,0,0,0,0,0,0
0,0,0,0,0,0,0,0,0,0,0,0,0,0,0,0,0,0,0
0,0,0,0,0,0,0,0,0,0,0,0,0,0,0,0,0,0,0
0,0,0,0,0,0,0,0,0,0,0,0,0,0,0,0,0,0,0
0,0,0,0,65,0,0,0,0,0,65,0,0,0,0,0,0,0,0
0,0,0,0,0,65,0,0,0,65,0,0,0,0,0,0,0,0,0
0,0,0,0,0,0,65,0,65,0,0,0,0,0,0,0,0,0,0
0,0,0,0,0,0,0,51,0,0,0,0,0,0,0,0,0,0,0
0,0,0,0,0,0,65,0,65,0,0,0,0,0,0,0,0,0,0
0,0,0,0,0,65,0,0,0,65,0,0,0,0,0,0,0,0,0
0,0,0,0,65,0,0,0,0,0,65,0,0,0,0,0,0,0,0
0,0,0,0,0,0,0,0,0,0,0,0,0,0,0,0,0,0,0
0,0,0,0,0,0,0,0,0,0,0,0,0,0,0,0,0,0,0
0,0,0,0,0,0,0,0,0,0,0,0,0,0,0,0,0,0,0
:endlayer
layer: 22
0,0,0,0,0,0,0,0,0,0,0,0,0,0,0,0,0,0,0
0,0,0,0,0,0,0,0,0,0,0,0,0,0,0,0,0,0,0
0,0,0,0,0,0,0,0,0,0,0,0,0,0,0,0,0,0,0
0,0,0,0,0,0,0,0,0,0,0,0,0,0,0,0,0,0,0
0,0,0,0,0,0,0,0,0,0,0,0,0,0,0,0,0,0,0
0,0,0,0,0,0,0,0,0,0,0,0,0,0,0,0,0,0,0
0,0,0,0,0,0,0,0,0,0,0,0,0,0,0,0,0,0,0
0,0,0,0,0,0,0,0,0,0,0,0,0,0,0,0,0,0,0
0,0,0,0,0,0,0,0,0,0,0,0,0,0,0,0,0,0,0
0,0,0,0,65,0,0,0,0,0,65,0,0,0,0,0,0,0,0
0,0,0,0,0,65,0,0,0,65,0,0,0,0,0,0,0,0,0
0,0,0,0,0,0,65,0,65,0,0,0,0,0,0,0,0,0,0
0,0,0,0,0,0,0,51,0,0,0,0,0,0,0,0,0,0,0
0,0,0,0,0,0,65,0,65,0,0,0,0,0,0,0,0,0,0
0,0,0,0,0,65,0,0,0,65,0,0,0,0,0,0,0,0,0
0,0,0,0,65,0,0,0,0,0,65,0,0,0,0,0,0,0,0
0,0,0,0,0,0,0,0,0,0,0,0,0,0,0,0,0,0,0
0,0,0,0,0,0,0,0,0,0,0,0,0,0,0,0,0,0,0
0,0,0,0,0,0,0,0,0,0,0,0,0,0,0,0,0,0,0
:endlayer
layer: 23
0,0,0,0,0,0,0,0,0,0,0,0,0,0,0,0,0,0,0
0,0,0,0,0,0,0,0,0,0,0,0,0,0,0,0,0,0,0
0,0,0,0,0,0,0,0,0,0,0,0,0,0,0,0,0,0,0
0,0,0,0,0,0,0,0,0,0,0,0,0,0,0,0,0,0,0
0,0,0,0,0,0,0,0,0,0,0,0,0,0,0,0,0,0,0
0,0,0,0,0,0,0,0,0,0,0,0,0,0,0,0,0,0,0
0,0,0,0,0,0,0,0,0,0,0,0,0,0,0,0,0,0,0
0,0,0,0,0,0,0,0,0,0,0,0,0,0,0,0,0,0,0
0,0,0,0,0,0,0,0,0,0,0,0,0,0,0,0,0,0,0
0,0,0,0,6,6,0,0,0,0,6,0,0,0,0,0,0,0,0
0,0,0,0,0,6,6,0,0,6,6,0,0,0,0,0,0,0,0
0,0,0,0,0,0,6,6,6,6,0,0,0,0,0,0,0,0,0
0,0,0,0,0,0,6,4,6,0,0,0,0,0,0,0,0,0,0
0,0,0,0,0,6,6,6,6,0,0,0,0,0,0,0,0,0,0
0,0,0,0,6,6,0,0,6,6,0,0,0,0,0,0,0,0,0
0,0,0,0,6,0,0,0,0,6,6,0,0,0,0,0,0,0,0
0,0,0,0,0,0,0,0,0,0,0,0,0,0,0,0,0,0,0
0,0,0,0,0,0,0,0,0,0,0,0,0,0,0,0,0,0,0
0,0,0,0,0,0,0,0,0,0,0,0,0,0,0,0,0,0,0
:endlayer
layer: 24
0,0,0,0,0,0,0,0,0,0,0,0,0,0,0,0,0,0,0
0,0,0,0,0,0,0,0,0,0,0,0,0,0,0,0,0,0,0
0,0,0,0,0,0,0,0,0,0,0,0,0,0,0,0,0,0,0
0,0,0,0,0,0,0,0,0,0,0,0,0,0,0,0,0,0,0
0,0,0,0,0,0,0,0,0,0,0,0,0,0,0,0,0,0,0
0,0,0,0,0,0,0,0,0,0,0,0,0,0,0,0,0,0,0
0,0,0,0,0,0,0,0,0,0,0,0,0,0,0,0,0,0,0
0,0,0,0,0,0,0,0,0,0,0,0,0,0,0,0,0,0,0
0,0,0,0,0,0,0,0,0,0,0,0,0,0,0,0,0,0,0
0,0,0,0,65,0,0,0,0,0,65,0,0,0,0,0,0,0,0
0,0,0,0,0,65,0,0,0,65,0,0,0,0,0,0,0,0,0
0,0,0,0,0,0,65,0,65,0,0,0,0,0,0,0,0,0,0
0,0,0,0,0,0,0,51,0,0,0,0,0,0,0,0,0,0,0
0,0,0,0,0,0,65,0,65,0,0,0,0,0,0,0,0,0,0
0,0,0,0,0,65,0,0,0,65,0,0,0,0,0,0,0,0,0
0,0,0,0,65,0,0,0,0,0,65,0,0,0,0,0,0,0,0
0,0,0,0,0,0,0,0,0,0,0,0,0,0,0,0,0,0,0
0,0,0,0,0,0,0,0,0,0,0,0,0,0,0,0,0,0,0
0,0,0,0,0,0,0,0,0,0,0,0,0,0,0,0,0,0,0
:endlayer
layer: 25
0,0,0,0,0,0,0,0,0,0,0,0,0,0,0,0,0,0,0
0,0,0,0,0,0,0,0,0,0,0,0,0,0,0,0,0,0,0
0,0,0,0,0,0,0,0,0,0,0,0,0,0,0,0,0,0,0
0,0,0,0,0,0,0,0,0,0,0,0,0,0,0,0,0,0,0
0,0,0,0,0,0,0,0,0,0,0,0,0,0,0,0,0,0,0
0,0,0,0,0,0,0,0,0,0,0,0,0,0,0,0,0,0,0
0,0,0,0,0,0,0,0,0,0,0,0,0,0,0,0,0,0,0
0,0,0,0,0,0,0,0,0,0,0,0,0,0,0,0,0,0,0
0,0,0,0,0,0,0,0,0,0,0,0,0,0,0,0,0,0,0
0,0,0,0,65,0,0,0,0,0,65,0,0,0,0,0,0,0,0
0,0,0,0,0,65,0,0,0,65,0,0,0,0,0,0,0,0,0
0,0,0,0,0,0,65,0,65,0,0,0,0,0,0,0,0,0,0
0,0,0,0,0,0,0,51,0,0,0,0,0,0,0,0,0,0,0
0,0,0,0,0,0,65,0,65,0,0,0,0,0,0,0,0,0,0
0,0,0,0,0,65,0,0,0,65,0,0,0,0,0,0,0,0,0
0,0,0,0,65,0,0,0,0,0,65,0,0,0,0,0,0,0,0
0,0,0,0,0,0,0,0,0,0,0,0,0,0,0,0,0,0,0
0,0,0,0,0,0,0,0,0,0,0,0,0,0,0,0,0,0,0
0,0,0,0,0,0,0,0,0,0,0,0,0,0,0,0,0,0,0
:endlayer
layer: 26
0,0,0,0,0,0,0,0,0,0,0,0,0,0,0,0,0,0,0
0,0,0,0,0,0,0,0,0,0,0,0,0,0,0,0,0,0,0
0,0,0,0,0,0,0,0,0,0,0,0,0,0,0,0,0,0,0
0,0,0,0,0,0,0,0,0,0,0,0,0,0,0,0,0,0,0
0,0,0,0,0,0,0,0,0,0,0,0,0,0,0,0,0,0,0
0,0,0,0,0,0,0,0,0,0,0,0,0,0,0,0,0,0,0
0,0,0,0,0,0,0,0,0,0,0,0,0,0,0,0,0,0,0
0,0,0,0,0,0,0,0,0,0,0,0,0,0,0,0,0,0,0
0,0,0,0,0,0,0,0,0,0,0,0,0,0,0,0,0,0,0
0,0,0,0,65,0,0,0,0,0,65,0,0,0,0,0,0,0,0
0,0,0,0,0,65,0,0,0,65,0,0,0,0,0,0,0,0,0
0,0,0,0,0,0,65,0,65,0,0,0,0,0,0,0,0,0,0
0,0,0,0,0,0,0,51,0,0,0,0,0,0,0,0,0,0,0
0,0,0,0,0,0,65,0,65,0,0,0,0,0,0,0,0,0,0
0,0,0,0,0,65,0,0,0,65,0,0,0,0,0,0,0,0,0
0,0,0,0,65,0,0,0,0,0,65,0,0,0,0,0,0,0,0
0,0,0,0,0,0,0,0,0,0,0,0,0,0,0,0,0,0,0
0,0,0,0,0,0,0,0,0,0,0,0,0,0,0,0,0,0,0
0,0,0,0,0,0,0,0,0,0,0,0,0,0,0,0,0,0,0
:endlayer
layer: 27
0,0,0,0,0,0,0,0,0,0,0,0,0,0,0,0,0,0,0
0,0,0,0,0,0,0,0,0,0,0,0,0,0,0,0,0,0,0
0,0,0,0,0,0,0,0,0,0,0,0,0,0,0,0,0,0,0
0,0,0,0,0,0,0,0,0,0,0,0,0,0,0,0,0,0,0
0,0,0,0,0,0,0,0,0,0,0,0,0,0,0,0,0,0,0
0,0,0,0,0,0,0,0,0,0,0,0,0,0,0,0,0,0,0
0,0,0,0,0,0,0,0,0,0,0,0,0,0,0,0,0,0,0
0,0,0,0,0,0,0,0,0,0,0,0,0,0,0,0,0,0,0
0,0,0,0,0,0,0,0,0,0,0,0,0,0,0,0,0,0,0
0,0,0,0,52,0,0,0,0,0,52,0,0,0,0,0,0,0,0
0,0,0,0,0,52,0,0,0,52,0,0,0,0,0,0,0,0,0
0,0,0,0,0,0,52,0,52,0,0,0,0,0,0,0,0,0,0
0,0,0,0,0,0,0,4,0,0,0,0,0,0,0,0,0,0,0
0,0,0,0,0,0,52,0,52,0,0,0,0,0,0,0,0,0,0
0,0,0,0,0,52,0,0,0,52,0,0,0,0,0,0,0,0,0
0,0,0,0,52,0,0,0,0,0,52,0,0,0,0,0,0,0,0
0,0,0,0,0,0,0,0,0,0,0,0,0,0,0,0,0,0,0
0,0,0,0,0,0,0,0,0,0,0,0,0,0,0,0,0,0,0
0,0,0,0,0,0,0,0,0,0,0,0,0,0,0,0,0,0,0
:endlayer
layer: 28
0,0,0,0,0,0,0,0,0,0,0,0,0,0,0,0,0,0,0
0,0,0,0,0,0,0,0,0,0,0,0,0,0,0,0,0,0,0
0,0,0,0,0,0,0,0,0,0,0,0,0,0,0,0,0,0,0
0,0,0,0,0,0,0,0,0,0,0,0,0,0,0,0,0,0,0
0,0,0,0,0,0,0,0,0,0,0,0,0,0,0,0,0,0,0
0,0,0,0,0,0,0,0,0,0,0,0,0,0,0,0,0,0,0
0,0,0,0,0,0,0,0,0,0,0,0,0,0,0,0,0,0,0
0,0,0,0,0,0,0,0,0,0,0,0,0,0,0,0,0,0,0
0,0,0,0,0,0,0,0,0,0,0,0,0,0,0,0,0,0,0
0,0,0,0,0,0,0,0,0,0,0,0,0,0,0,0,0,0,0
0,0,0,0,0,0,0,0,0,0,0,0,0,0,0,0,0,0,0
0,0,0,0,0,0,0,0,0,0,0,0,0,0,0,0,0,0,0
0,0,0,0,0,0,0,0,0,0,0,0,0,0,0,0,0,0,0
0,0,0,0,0,0,0,0,0,0,0,0,0,0,0,0,0,0,0
0,0,0,0,0,0,0,0,0,0,0,0,0,0,0,0,0,0,0
0,0,0,0,0,0,0,0,0,0,0,0,0,0,0,0,0,0,0
0,0,0,0,0,0,0,0,0,0,0,0,0,0,0,0,0,0,0
0,0,0,0,0,0,0,0,0,0,0,0,0,0,0,0,0,0,0
0,0,0,0,0,0,0,0,0,0,0,0,0,0,0,0,0,0,0
:endlayer
layer: 29
0,0,0,0,0,0,0,0,0,0,0,0,0,0,0,0,0,0,0
0,0,0,0,0,0,0,0,0,0,0,0,0,0,0,0,0,0,0
0,0,0,0,0,0,0,0,0,0,0,0,0,0,0,0,0,0,0
0,0,0,0,0,0,0,0,0,0,0,0,0,0,0,0,0,0,0
0,0,0,0,0,0,0,0,0,0,0,0,0,0,0,0,0,0,0
0,0,0,0,0,0,0,0,0,0,0,0,0,0,0,0,0,0,0
0,0,0,0,0,0,0,0,0,0,0,0,0,0,0,0,0,0,0
0,0,0,0,0,0,0,0,0,0,0,0,0,0,0,0,0,0,0
0,0,0,0,0,0,0,0,0,0,0,0,0,0,0,0,0,0,0
0,0,0,0,0,0,0,0,0,0,0,0,0,0,0,0,0,0,0
0,0,0,0,0,0,0,0,0,0,0,0,0,0,0,0,0,0,0
0,0,0,0,0,0,0,0,0,0,0,0,0,0,0,0,0,0,0
0,0,0,0,0,0,0,0,0,0,0,0,0,0,0,0,0,0,0
0,0,0,0,0,0,0,0,0,0,0,0,0,0,0,0,0,0,0
0,0,0,0,0,0,0,0,0,0,0,0,0,0,0,0,0,0,0
0,0,0,0,0,0,0,0,0,0,0,0,0,0,0,0,0,0,0
0,0,0,0,0,0,0,0,0,0,0,0,0,0,0,0,0,0,0
0,0,0,0,0,0,0,0,0,0,0,0,0,0,0,0,0,0,0
0,0,0,0,0,0,0,0,0,0,0,0,0,0,0,0,0,0,0
:endlayer
layer: 30
0,0,0,0,0,0,0,0,0,0,0,0,0,0,0,0,0,0,0
0,0,0,0,0,0,0,0,0,0,0,0,0,0,0,0,0,0,0
0,0,0,0,0,0,0,0,0,0,0,0,0,0,0,0,0,0,0
0,0,0,0,0,0,0,0,0,0,0,0,0,0,0,0,0,0,0
0,0,0,0,0,0,0,0,0,0,0,0,0,0,0,0,0,0,0
0,0,0,0,0,0,0,0,0,0,0,0,0,0,0,0,0,0,0
0,0,0,0,0,0,0,0,0,0,0,0,0,0,0,0,0,0,0
0,0,0,0,0,0,0,0,0,0,0,0,0,0,0,0,0,0,0
0,0,0,0,0,0,0,0,0,0,0,0,0,0,0,0,0,0,0
0,0,0,0,0,0,0,0,0,0,0,0,0,0,0,0,0,0,0
0,0,0,0,0,0,0,0,0,0,0,0,0,0,0,0,0,0,0
0,0,0,0,0,0,0,0,0,0,0,0,0,0,0,0,0,0,0
0,0,0,0,0,0,0,0,0,0,0,0,0,0,0,0,0,0,0
0,0,0,0,0,0,0,0,0,0,0,0,0,0,0,0,0,0,0
0,0,0,0,0,0,0,0,0,0,0,0,0,0,0,0,0,0,0
0,0,0,0,0,0,0,0,0,0,0,0,0,0,0,0,0,0,0
0,0,0,0,0,0,0,0,0,0,0,0,0,0,0,0,0,0,0
0,0,0,0,0,0,0,0,0,0,0,0,0,0,0,0,0,0,0
0,0,0,0,0,0,0,0,0,0,0,0,0,0,0,0,0,0,0
:endlayer
layer: 31
0,0,0,0,0,0,0,0,0,0,0,0,0,0,0,0,0,0,0
0,0,0,0,0,0,0,0,0,0,0,0,0,0,0,0,0,0,0
0,0,0,0,0,0,0,0,0,0,0,0,0,0,0,0,0,0,0
0,0,0,0,0,0,0,0,0,0,0,0,0,0,0,0,0,0,0
0,0,0,0,0,0,0,0,0,0,0,0,0,0,0,0,0,0,0
0,0,0,0,0,0,0,0,0,0,0,0,0,0,0,0,0,0,0
0,0,0,0,0,0,0,0,0,0,0,0,0,0,0,0,0,0,0
0,0,0,0,0,0,0,0,0,0,0,0,0,0,0,0,0,0,0
0,0,0,0,0,0,0,0,0,0,0,0,0,0,0,0,0,0,0
0,0,0,0,0,0,0,0,0,0,0,0,0,0,0,0,0,0,0
0,0,0,0,0,0,0,0,0,0,0,0,0,0,0,0,0,0,0
0,0,0,0,0,0,0,0,0,0,0,0,0,0,0,0,0,0,0
0,0,0,0,0,0,0,0,0,0,0,0,0,0,0,0,0,0,0
0,0,0,0,0,0,0,0,0,0,0,0,0,0,0,0,0,0,0
0,0,0,0,0,0,0,0,0,0,0,0,0,0,0,0,0,0,0
0,0,0,0,0,0,0,0,0,0,0,0,0,0,0,0,0,0,0
0,0,0,0,0,0,0,0,0,0,0,0,0,0,0,0,0,0,0
0,0,0,0,0,0,0,0,0,0,0,0,0,0,0,0,0,0,0
0,0,0,0,0,0,0,0,0,0,0,0,0,0,0,0,0,0,0
:endlayer
layer: 32
0,0,0,0,0,0,0,0,0,0,0,0,0,0,0,0,0,0,0
0,0,0,0,0,0,0,0,0,0,0,0,0,0,0,0,0,0,0
0,0,0,0,0,0,0,0,0,0,0,0,0,0,0,0,0,0,0
0,0,0,0,0,0,0,0,0,0,0,0,0,0,0,0,0,0,0
0,0,0,0,0,0,0,0,0,0,0,0,0,0,0,0,0,0,0
0,0,0,0,0,0,0,0,0,0,0,0,0,0,0,0,0,0,0
0,0,0,0,0,0,0,0,0,0,0,0,0,0,0,0,0,0,0
0,0,0,0,0,0,0,0,0,0,0,0,0,0,0,0,0,0,0
0,0,0,0,0,0,0,0,0,0,0,0,0,0,0,0,0,0,0
0,0,0,0,0,0,0,0,0,0,0,0,0,0,0,0,0,0,0
0,0,0,0,0,0,0,0,0,0,0,0,0,0,0,0,0,0,0
0,0,0,0,0,0,0,0,0,0,0,0,0,0,0,0,0,0,0
0,0,0,0,0,0,0,0,0,0,0,0,0,0,0,0,0,0,0
0,0,0,0,0,0,0,0,0,0,0,0,0,0,0,0,0,0,0
0,0,0,0,0,0,0,0,0,0,0,0,0,0,0,0,0,0,0
0,0,0,0,0,0,0,0,0,0,0,0,0,0,0,0,0,0,0
0,0,0,0,0,0,0,0,0,0,0,0,0,0,0,0,0,0,0
0,0,0,0,0,0,0,0,0,0,0,0,0,0,0,0,0,0,0
0,0,0,0,0,0,0,0,0,0,0,0,0,0,0,0,0,0,0
:endlayer
layer: 33
0,0,0,0,0,0,0,0,0,0,0,0,0,0,0,0,0,0,0
0,0,0,0,0,0,0,0,0,0,0,0,0,0,0,0,0,0,0
0,0,0,0,0,0,0,0,0,0,0,0,0,0,0,0,0,0,0
0,0,0,0,0,0,0,0,0,0,0,0,0,0,0,0,0,0,0
0,0,0,0,0,0,0,0,0,0,0,0,0,0,0,0,0,0,0
0,0,0,0,0,0,0,0,0,0,0,0,0,0,0,0,0,0,0
0,0,0,0,0,0,0,0,0,0,0,0,0,0,0,0,0,0,0
0,0,0,0,0,0,0,0,0,0,0,0,0,0,0,0,0,0,0
0,0,0,0,0,0,0,0,0,0,0,0,0,0,0,0,0,0,0
0,0,0,0,0,0,0,0,0,0,0,0,0,0,0,0,0,0,0
0,0,0,0,0,0,0,0,0,0,0,0,0,0,0,0,0,0,0
0,0,0,0,0,0,0,0,0,0,0,0,0,0,0,0,0,0,0
0,0,0,0,0,0,0,0,0,0,0,0,0,0,0,0,0,0,0
0,0,0,0,0,0,0,0,0,0,0,0,0,0,0,0,0,0,0
0,0,0,0,0,0,0,0,0,0,0,0,0,0,0,0,0,0,0
0,0,0,0,0,0,0,0,0,0,0,0,0,0,0,0,0,0,0
0,0,0,0,0,0,0,0,0,0,0,0,0,0,0,0,0,0,0
0,0,0,0,0,0,0,0,0,0,0,0,0,0,0,0,0,0,0
0,0,0,0,0,0,0,0,0,0,0,0,0,0,0,0,0,0,0
:endlayer

#### RULES ####
rule:
plugin=vanillaBlocks
number=1
data:
tag:
TAG=10={
TAG=8=blockName{dirt}
TAG=3=meta{0}
TAG=3=buildPass{0}
}
:endtag
:enddata
:endrule

rule:
plugin=vanillaBlocks
number=2
data:
tag:
TAG=10={
TAG=8=blockName{cobblestone}
TAG=3=meta{0}
TAG=3=buildPass{0}
}
:endtag
:enddata
:endrule

rule:
plugin=vanillaBlocks
number=3
data:
tag:
TAG=10={
TAG=8=blockName{grass}
TAG=3=meta{0}
TAG=3=buildPass{0}
}
:endtag
:enddata
:endrule

rule:
plugin=vanillaBlocks
number=4
data:
tag:
TAG=10={
TAG=8=blockName{double_stone_slab}
TAG=3=meta{0}
TAG=3=buildPass{0}
}
:endtag
:enddata
:endrule

rule:
plugin=vanillaBlocks
number=5
data:
tag:
TAG=10={
TAG=8=blockName{tallgrass}
TAG=3=meta{1}
TAG=3=buildPass{0}
}
:endtag
:enddata
:endrule

rule:
plugin=vanillaBlocks
number=6
data:
tag:
TAG=10={
TAG=8=blockName{fence}
TAG=3=meta{0}
TAG=3=buildPass{0}
}
:endtag
:enddata
:endrule

rule:
plugin=vanillaBlocks
number=7
data:
tag:
TAG=10={
TAG=8=blockName{fence_gate}
TAG=3=meta{2}
TAG=3=buildPass{0}
}
:endtag
:enddata
:endrule

rule:
plugin=vanillaBlocks
number=8
data:
tag:
TAG=10={
TAG=8=blockName{stonebrick}
TAG=3=meta{0}
TAG=3=buildPass{0}
}
:endtag
:enddata
:endrule

rule:
plugin=vanillaDoors
number=9
data:
tag:
TAG=10={
TAG=1=sideFlag{8}
TAG=8=blockName{wooden_door}
TAG=3=meta{3}
TAG=3=buildPass{1}
}
:endtag
:enddata
:endrule

rule:
plugin=vanillaBlocks
number=10
data:
tag:
TAG=10={
TAG=8=blockName{crafting_table}
TAG=3=meta{0}
TAG=3=buildPass{0}
}
:endtag
:enddata
:endrule

rule:
plugin=vanillaBlocks
number=11
data:
tag:
TAG=10={
TAG=8=blockName{stone_slab}
TAG=3=meta{0}
TAG=3=buildPass{0}
}
:endtag
:enddata
:endrule

rule:
plugin=vanillaInventory
number=12
data:
tag:
TAG=10={
TAG=3=lootLevel{0}
TAG=10=teData{
TAG=9=Items{
TAG=10={
TAG=2=id{295}
TAG=2=Damage{0}
TAG=1=Count{1}
TAG=1=Slot{1}
}
TAG=10={
TAG=2=id{295}
TAG=2=Damage{0}
TAG=1=Count{1}
TAG=1=Slot{3}
}
TAG=10={
TAG=2=id{295}
TAG=2=Damage{0}
TAG=1=Count{1}
TAG=1=Slot{8}
}
TAG=10={
TAG=2=id{295}
TAG=2=Damage{0}
TAG=1=Count{1}
TAG=1=Slot{10}
}
TAG=10={
TAG=2=id{295}
TAG=2=Damage{0}
TAG=1=Count{1}
TAG=1=Slot{11}
}
TAG=10={
TAG=2=id{295}
TAG=2=Damage{0}
TAG=1=Count{1}
TAG=1=Slot{14}
}
TAG=10={
TAG=2=id{295}
TAG=2=Damage{0}
TAG=1=Count{1}
TAG=1=Slot{15}
}
TAG=10={
TAG=2=id{295}
TAG=2=Damage{0}
TAG=1=Count{1}
TAG=1=Slot{16}
}
TAG=10={
TAG=2=id{295}
TAG=2=Damage{0}
TAG=1=Count{1}
TAG=1=Slot{20}
}
TAG=10={
TAG=2=id{295}
TAG=2=Damage{0}
TAG=1=Count{1}
TAG=1=Slot{22}
}
TAG=10={
TAG=2=id{295}
TAG=2=Damage{0}
TAG=1=Count{1}
TAG=1=Slot{23}
}
}
TAG=8=id{Chest}
}
TAG=8=blockName{chest}
TAG=3=meta{4}
TAG=3=buildPass{0}
}
:endtag
:enddata
:endrule

rule:
plugin=vanillaBlocks
number=13
data:
tag:
TAG=10={
TAG=8=blockName{iron_block}
TAG=3=meta{0}
TAG=3=buildPass{0}
}
:endtag
:enddata
:endrule

rule:
plugin=vanillaInventory
number=14
data:
tag:
TAG=10={
TAG=3=lootLevel{0}
TAG=10=teData{
TAG=9=Items{
TAG=10={
TAG=2=id{295}
TAG=2=Damage{0}
TAG=1=Count{1}
TAG=1=Slot{2}
}
TAG=10={
TAG=2=id{295}
TAG=2=Damage{0}
TAG=1=Count{1}
TAG=1=Slot{10}
}
TAG=10={
TAG=2=id{295}
TAG=2=Damage{0}
TAG=1=Count{1}
TAG=1=Slot{13}
}
TAG=10={
TAG=2=id{295}
TAG=2=Damage{0}
TAG=1=Count{1}
TAG=1=Slot{18}
}
TAG=10={
TAG=2=id{295}
TAG=2=Damage{0}
TAG=1=Count{1}
TAG=1=Slot{22}
}
TAG=10={
TAG=2=id{295}
TAG=2=Damage{0}
TAG=1=Count{1}
TAG=1=Slot{26}
}
}
TAG=8=id{Chest}
}
TAG=8=blockName{chest}
TAG=3=meta{4}
TAG=3=buildPass{0}
}
:endtag
:enddata
:endrule

rule:
plugin=vanillaInventory
number=15
data:
tag:
TAG=10={
TAG=3=lootLevel{0}
TAG=10=teData{
TAG=9=Items{
}
TAG=8=id{Chest}
}
TAG=8=blockName{chest}
TAG=3=meta{3}
TAG=3=buildPass{0}
}
:endtag
:enddata
:endrule

rule:
plugin=vanillaInventory
number=16
data:
tag:
TAG=10={
TAG=3=lootLevel{0}
TAG=10=teData{
TAG=9=Items{
}
TAG=8=id{Chest}
}
TAG=8=blockName{chest}
TAG=3=meta{3}
TAG=3=buildPass{0}
}
:endtag
:enddata
:endrule

rule:
plugin=vanillaInventory
number=17
data:
tag:
TAG=10={
TAG=3=lootLevel{0}
TAG=10=teData{
TAG=9=Items{
TAG=10={
TAG=2=id{295}
TAG=2=Damage{0}
TAG=1=Count{1}
TAG=1=Slot{1}
}
TAG=10={
TAG=2=id{295}
TAG=2=Damage{0}
TAG=1=Count{1}
TAG=1=Slot{12}
}
TAG=10={
TAG=2=id{295}
TAG=2=Damage{0}
TAG=1=Count{1}
TAG=1=Slot{13}
}
TAG=10={
TAG=2=id{295}
TAG=2=Damage{0}
TAG=1=Count{1}
TAG=1=Slot{14}
}
TAG=10={
TAG=2=id{295}
TAG=2=Damage{0}
TAG=1=Count{1}
TAG=1=Slot{15}
}
TAG=10={
TAG=2=id{295}
TAG=2=Damage{0}
TAG=1=Count{1}
TAG=1=Slot{16}
}
TAG=10={
TAG=2=id{295}
TAG=2=Damage{0}
TAG=1=Count{1}
TAG=1=Slot{19}
}
TAG=10={
TAG=2=id{295}
TAG=2=Damage{0}
TAG=1=Count{1}
TAG=1=Slot{24}
}
TAG=10={
TAG=2=id{295}
TAG=2=Damage{0}
TAG=1=Count{2}
TAG=1=Slot{25}
}
}
TAG=8=id{Chest}
}
TAG=8=blockName{chest}
TAG=3=meta{2}
TAG=3=buildPass{0}
}
:endtag
:enddata
:endrule

rule:
plugin=vanillaInventory
number=18
data:
tag:
TAG=10={
TAG=3=lootLevel{0}
TAG=10=teData{
TAG=9=Items{
TAG=10={
TAG=2=id{295}
TAG=2=Damage{0}
TAG=1=Count{1}
TAG=1=Slot{1}
}
TAG=10={
TAG=2=id{295}
TAG=2=Damage{0}
TAG=1=Count{1}
TAG=1=Slot{2}
}
TAG=10={
TAG=2=id{295}
TAG=2=Damage{0}
TAG=1=Count{1}
TAG=1=Slot{4}
}
TAG=10={
TAG=2=id{295}
TAG=2=Damage{0}
TAG=1=Count{1}
TAG=1=Slot{6}
}
TAG=10={
TAG=2=id{295}
TAG=2=Damage{0}
TAG=1=Count{1}
TAG=1=Slot{10}
}
TAG=10={
TAG=2=id{295}
TAG=2=Damage{0}
TAG=1=Count{1}
TAG=1=Slot{13}
}
TAG=10={
TAG=2=id{295}
TAG=2=Damage{0}
TAG=1=Count{1}
TAG=1=Slot{14}
}
TAG=10={
TAG=2=id{295}
TAG=2=Damage{0}
TAG=1=Count{1}
TAG=1=Slot{15}
}
TAG=10={
TAG=2=id{295}
TAG=2=Damage{0}
TAG=1=Count{2}
TAG=1=Slot{16}
}
TAG=10={
TAG=2=id{295}
TAG=2=Damage{0}
TAG=1=Count{1}
TAG=1=Slot{19}
}
TAG=10={
TAG=2=id{295}
TAG=2=Damage{0}
TAG=1=Count{1}
TAG=1=Slot{24}
}
TAG=10={
TAG=2=id{295}
TAG=2=Damage{0}
TAG=1=Count{1}
TAG=1=Slot{25}
}
}
TAG=8=id{Chest}
}
TAG=8=blockName{chest}
TAG=3=meta{2}
TAG=3=buildPass{0}
}
:endtag
:enddata
:endrule

rule:
plugin=vanillaInventory
number=19
data:
tag:
TAG=10={
TAG=3=lootLevel{0}
TAG=10=teData{
TAG=9=Items{
TAG=10={
TAG=2=id{296}
TAG=2=Damage{0}
TAG=1=Count{1}
TAG=1=Slot{6}
}
TAG=10={
TAG=2=id{296}
TAG=2=Damage{0}
TAG=1=Count{1}
TAG=1=Slot{13}
}
TAG=10={
TAG=2=id{296}
TAG=2=Damage{0}
TAG=1=Count{1}
TAG=1=Slot{14}
}
TAG=10={
TAG=2=id{296}
TAG=2=Damage{0}
TAG=1=Count{1}
TAG=1=Slot{15}
}
TAG=10={
TAG=2=id{296}
TAG=2=Damage{0}
TAG=1=Count{1}
TAG=1=Slot{16}
}
TAG=10={
TAG=2=id{296}
TAG=2=Damage{0}
TAG=1=Count{1}
TAG=1=Slot{21}
}
TAG=10={
TAG=2=id{296}
TAG=2=Damage{0}
TAG=1=Count{1}
TAG=1=Slot{26}
}
}
TAG=8=id{Chest}
}
TAG=8=blockName{chest}
TAG=3=meta{5}
TAG=3=buildPass{0}
}
:endtag
:enddata
:endrule

rule:
plugin=vanillaInventory
number=20
data:
tag:
TAG=10={
TAG=3=lootLevel{0}
TAG=10=teData{
TAG=9=Items{
TAG=10={
TAG=2=id{296}
TAG=2=Damage{0}
TAG=1=Count{1}
TAG=1=Slot{1}
}
TAG=10={
TAG=2=id{296}
TAG=2=Damage{0}
TAG=1=Count{1}
TAG=1=Slot{2}
}
TAG=10={
TAG=2=id{296}
TAG=2=Damage{0}
TAG=1=Count{1}
TAG=1=Slot{4}
}
TAG=10={
TAG=2=id{296}
TAG=2=Damage{0}
TAG=1=Count{1}
TAG=1=Slot{8}
}
TAG=10={
TAG=2=id{296}
TAG=2=Damage{0}
TAG=1=Count{1}
TAG=1=Slot{10}
}
TAG=10={
TAG=2=id{296}
TAG=2=Damage{0}
TAG=1=Count{2}
TAG=1=Slot{12}
}
TAG=10={
TAG=2=id{296}
TAG=2=Damage{0}
TAG=1=Count{1}
TAG=1=Slot{13}
}
TAG=10={
TAG=2=id{296}
TAG=2=Damage{0}
TAG=1=Count{1}
TAG=1=Slot{14}
}
TAG=10={
TAG=2=id{296}
TAG=2=Damage{0}
TAG=1=Count{1}
TAG=1=Slot{15}
}
TAG=10={
TAG=2=id{296}
TAG=2=Damage{0}
TAG=1=Count{1}
TAG=1=Slot{16}
}
}
TAG=8=id{Chest}
}
TAG=8=blockName{chest}
TAG=3=meta{5}
TAG=3=buildPass{0}
}
:endtag
:enddata
:endrule

rule:
plugin=vanillaBlocks
number=21
data:
tag:
TAG=10={
TAG=8=blockName{stone_brick_stairs}
TAG=3=meta{0}
TAG=3=buildPass{0}
}
:endtag
:enddata
:endrule

rule:
plugin=vanillaBlocks
number=22
data:
tag:
TAG=10={
TAG=8=blockName{stone_stairs}
TAG=3=meta{1}
TAG=3=buildPass{0}
}
:endtag
:enddata
:endrule

rule:
plugin=vanillaBlocks
number=23
data:
tag:
TAG=10={
TAG=8=blockName{stone_brick_stairs}
TAG=3=meta{2}
TAG=3=buildPass{0}
}
:endtag
:enddata
:endrule

rule:
plugin=vanillaDoors
number=24
data:
tag:
TAG=10={
TAG=1=sideFlag{8}
TAG=8=blockName{wooden_door}
TAG=3=meta{1}
TAG=3=buildPass{1}
}
:endtag
:enddata
:endrule

rule:
plugin=vanillaBlocks
number=25
data:
tag:
TAG=10={
TAG=8=blockName{fence_gate}
TAG=3=meta{0}
TAG=3=buildPass{0}
}
:endtag
:enddata
:endrule

rule:
plugin=vanillaBlocks
number=26
data:
tag:
TAG=10={
TAG=8=blockName{torch}
TAG=3=meta{5}
TAG=3=buildPass{1}
}
:endtag
:enddata
:endrule

rule:
plugin=vanillaDoors
number=27
data:
tag:
TAG=10={
TAG=1=sideFlag{0}
TAG=8=blockName{wooden_door}
TAG=3=meta{8}
TAG=3=buildPass{1}
}
:endtag
:enddata
:endrule

rule:
plugin=vanillaBlocks
number=28
data:
tag:
TAG=10={
TAG=8=blockName{torch}
TAG=3=meta{4}
TAG=3=buildPass{1}
}
:endtag
:enddata
:endrule

rule:
plugin=vanillaBlocks
number=29
data:
tag:
TAG=10={
TAG=8=blockName{torch}
TAG=3=meta{3}
TAG=3=buildPass{1}
}
:endtag
:enddata
:endrule

rule:
plugin=vanillaDoors
number=30
data:
tag:
TAG=10={
TAG=1=sideFlag{0}
TAG=8=blockName{wooden_door}
TAG=3=meta{8}
TAG=3=buildPass{1}
}
:endtag
:enddata
:endrule

rule:
plugin=vanillaBlocks
number=31
data:
tag:
TAG=10={
TAG=8=blockName{torch}
TAG=3=meta{2}
TAG=3=buildPass{1}
}
:endtag
:enddata
:endrule

rule:
plugin=vanillaBlocks
number=32
data:
tag:
TAG=10={
TAG=8=blockName{stone}
TAG=3=meta{0}
TAG=3=buildPass{0}
}
:endtag
:enddata
:endrule

rule:
plugin=vanillaBlocks
number=33
data:
tag:
TAG=10={
TAG=8=blockName{torch}
TAG=3=meta{1}
TAG=3=buildPass{1}
}
:endtag
:enddata
:endrule

rule:
plugin=vanillaInventory
number=34
data:
tag:
TAG=10={
TAG=3=lootLevel{0}
TAG=10=teData{
TAG=9=Items{
}
TAG=8=id{Chest}
}
TAG=8=blockName{chest}
TAG=3=meta{4}
TAG=3=buildPass{0}
}
:endtag
:enddata
:endrule

rule:
plugin=vanillaInventory
number=35
data:
tag:
TAG=10={
TAG=3=lootLevel{0}
TAG=10=teData{
TAG=9=Items{
}
TAG=8=id{Chest}
}
TAG=8=blockName{chest}
TAG=3=meta{4}
TAG=3=buildPass{0}
}
:endtag
:enddata
:endrule

rule:
plugin=vanillaInventory
number=36
data:
tag:
TAG=10={
TAG=3=lootLevel{0}
TAG=10=teData{
TAG=9=Items{
}
TAG=8=id{Chest}
}
TAG=8=blockName{chest}
TAG=3=meta{3}
TAG=3=buildPass{0}
}
:endtag
:enddata
:endrule

rule:
plugin=vanillaInventory
number=37
data:
tag:
TAG=10={
TAG=3=lootLevel{0}
TAG=10=teData{
TAG=9=Items{
}
TAG=8=id{Chest}
}
TAG=8=blockName{chest}
TAG=3=meta{3}
TAG=3=buildPass{0}
}
:endtag
:enddata
:endrule

rule:
plugin=vanillaInventory
number=38
data:
tag:
TAG=10={
TAG=3=lootLevel{0}
TAG=10=teData{
TAG=9=Items{
TAG=10={
TAG=2=id{296}
TAG=2=Damage{0}
TAG=1=Count{1}
TAG=1=Slot{15}
}
TAG=10={
TAG=2=id{296}
TAG=2=Damage{0}
TAG=1=Count{1}
TAG=1=Slot{21}
}
TAG=10={
TAG=2=id{296}
TAG=2=Damage{0}
TAG=1=Count{1}
TAG=1=Slot{22}
}
TAG=10={
TAG=2=id{296}
TAG=2=Damage{0}
TAG=1=Count{1}
TAG=1=Slot{24}
}
TAG=10={
TAG=2=id{296}
TAG=2=Damage{0}
TAG=1=Count{1}
TAG=1=Slot{25}
}
}
TAG=8=id{Chest}
}
TAG=8=blockName{chest}
TAG=3=meta{2}
TAG=3=buildPass{0}
}
:endtag
:enddata
:endrule

rule:
plugin=vanillaInventory
number=39
data:
tag:
TAG=10={
TAG=3=lootLevel{0}
TAG=10=teData{
TAG=9=Items{
TAG=10={
TAG=2=id{296}
TAG=2=Damage{0}
TAG=1=Count{1}
TAG=1=Slot{2}
}
}
TAG=8=id{Chest}
}
TAG=8=blockName{chest}
TAG=3=meta{2}
TAG=3=buildPass{0}
}
:endtag
:enddata
:endrule

rule:
plugin=vanillaInventory
number=40
data:
tag:
TAG=10={
TAG=3=lootLevel{0}
TAG=10=teData{
TAG=9=Items{
}
TAG=8=id{Chest}
}
TAG=8=blockName{chest}
TAG=3=meta{5}
TAG=3=buildPass{0}
}
:endtag
:enddata
:endrule

rule:
plugin=vanillaInventory
number=41
data:
tag:
TAG=10={
TAG=3=lootLevel{0}
TAG=10=teData{
TAG=9=Items{
}
TAG=8=id{Chest}
}
TAG=8=blockName{chest}
TAG=3=meta{5}
TAG=3=buildPass{0}
}
:endtag
:enddata
:endrule

rule:
plugin=vanillaBlocks
number=42
data:
tag:
TAG=10={
TAG=8=blockName{oak_stairs}
TAG=3=meta{3}
TAG=3=buildPass{0}
}
:endtag
:enddata
:endrule

rule:
plugin=vanillaBlocks
number=43
data:
tag:
TAG=10={
TAG=8=blockName{oak_stairs}
TAG=3=meta{1}
TAG=3=buildPass{0}
}
:endtag
:enddata
:endrule

rule:
plugin=vanillaBlocks
number=44
data:
tag:
TAG=10={
TAG=8=blockName{oak_stairs}
TAG=3=meta{0}
TAG=3=buildPass{0}
}
:endtag
:enddata
:endrule

rule:
plugin=vanillaBlocks
number=45
data:
tag:
TAG=10={
TAG=8=blockName{oak_stairs}
TAG=3=meta{2}
TAG=3=buildPass{0}
}
:endtag
:enddata
:endrule

rule:
plugin=vanillaBlocks
number=46
data:
tag:
TAG=10={
TAG=8=blockName{oak_stairs}
TAG=3=meta{5}
TAG=3=buildPass{0}
}
:endtag
:enddata
:endrule

rule:
plugin=vanillaBlocks
number=47
data:
tag:
TAG=10={
TAG=8=blockName{oak_stairs}
TAG=3=meta{4}
TAG=3=buildPass{0}
}
:endtag
:enddata
:endrule

rule:
plugin=vanillaBlocks
number=48
data:
tag:
TAG=10={
TAG=8=blockName{stone_stairs}
TAG=3=meta{0}
TAG=3=buildPass{0}
}
:endtag
:enddata
:endrule

rule:
plugin=vanillaBlocks
number=49
data:
tag:
TAG=10={
TAG=8=blockName{wooden_slab}
TAG=3=meta{8}
TAG=3=buildPass{0}
}
:endtag
:enddata
:endrule

rule:
plugin=vanillaBlocks
number=50
data:
tag:
TAG=10={
TAG=8=blockName{oak_stairs}
TAG=3=meta{6}
TAG=3=buildPass{0}
}
:endtag
:enddata
:endrule

rule:
plugin=vanillaBlocks
number=51
data:
tag:
TAG=10={
TAG=8=blockName{log}
TAG=3=meta{0}
TAG=3=buildPass{0}
}
:endtag
:enddata
:endrule

rule:
plugin=vanillaBlocks
number=52
data:
tag:
TAG=10={
TAG=8=blockName{stone_slab}
TAG=3=meta{2}
TAG=3=buildPass{0}
}
:endtag
:enddata
:endrule

rule:
plugin=vanillaBlocks
number=53
data:
tag:
TAG=10={
TAG=8=blockName{stone_stairs}
TAG=3=meta{3}
TAG=3=buildPass{0}
}
:endtag
:enddata
:endrule

rule:
plugin=vanillaBlocks
number=54
data:
tag:
TAG=10={
TAG=8=blockName{planks}
TAG=3=meta{0}
TAG=3=buildPass{0}
}
:endtag
:enddata
:endrule

rule:
plugin=vanillaBlocks
number=55
data:
tag:
TAG=10={
TAG=8=blockName{double_stone_slab}
TAG=3=meta{2}
TAG=3=buildPass{0}
}
:endtag
:enddata
:endrule

rule:
plugin=vanillaInventory
number=56
data:
tag:
TAG=10={
TAG=3=lootLevel{0}
TAG=10=teData{
TAG=9=Items{
}
TAG=8=id{Chest}
}
TAG=8=blockName{chest}
TAG=3=meta{4}
TAG=3=buildPass{0}
}
:endtag
:enddata
:endrule

rule:
plugin=vanillaInventory
number=57
data:
tag:
TAG=10={
TAG=3=lootLevel{0}
TAG=10=teData{
TAG=9=Items{
}
TAG=8=id{Chest}
}
TAG=8=blockName{chest}
TAG=3=meta{4}
TAG=3=buildPass{0}
}
:endtag
:enddata
:endrule

rule:
plugin=vanillaInventory
number=58
data:
tag:
TAG=10={
TAG=3=lootLevel{0}
TAG=10=teData{
TAG=9=Items{
}
TAG=8=id{Chest}
}
TAG=8=blockName{chest}
TAG=3=meta{2}
TAG=3=buildPass{0}
}
:endtag
:enddata
:endrule

rule:
plugin=vanillaInventory
number=59
data:
tag:
TAG=10={
TAG=3=lootLevel{0}
TAG=10=teData{
TAG=9=Items{
}
TAG=8=id{Chest}
}
TAG=8=blockName{chest}
TAG=3=meta{2}
TAG=3=buildPass{0}
}
:endtag
:enddata
:endrule

rule:
plugin=vanillaInventory
number=60
data:
tag:
TAG=10={
TAG=3=lootLevel{0}
TAG=10=teData{
TAG=9=Items{
}
TAG=8=id{Chest}
}
TAG=8=blockName{chest}
TAG=3=meta{4}
TAG=3=buildPass{0}
}
:endtag
:enddata
:endrule

rule:
plugin=vanillaInventory
number=61
data:
tag:
TAG=10={
TAG=3=lootLevel{0}
TAG=10=teData{
TAG=9=Items{
}
TAG=8=id{Chest}
}
TAG=8=blockName{chest}
TAG=3=meta{4}
TAG=3=buildPass{0}
}
:endtag
:enddata
:endrule

rule:
plugin=vanillaDoors
number=62
data:
tag:
TAG=10={
TAG=1=sideFlag{0}
TAG=8=blockName{wooden_door}
TAG=3=meta{8}
TAG=3=buildPass{1}
}
:endtag
:enddata
:endrule

rule:
plugin=vanillaBlocks
number=63
data:
tag:
TAG=10={
TAG=8=blockName{glass_pane}
TAG=3=meta{0}
TAG=3=buildPass{0}
}
:endtag
:enddata
:endrule

rule:
plugin=vanillaBlocks
number=64
data:
tag:
TAG=10={
TAG=8=blockName{stone_slab}
TAG=3=meta{5}
TAG=3=buildPass{0}
}
:endtag
:enddata
:endrule

rule:
plugin=vanillaBlocks
number=65
data:
tag:
TAG=10={
TAG=8=blockName{wool}
TAG=3=meta{0}
TAG=3=buildPass{0}
}
:endtag
:enddata
:endrule

#### ENTITIES ####
entity:
plugin=vanillaLogicEntity
number=0
data:
position=14,5,14
tag:
TAG=10={
TAG=10=entityData{
TAG=9=DropChances{
TAG=5=0{0.085}
TAG=5=1{0.085}
TAG=5=2{0.085}
TAG=5=3{0.085}
TAG=5=4{0.085}
}
TAG=3=Age{0}
TAG=9=Attributes{
TAG=10={
TAG=8=Name{generic.maxHealth}
TAG=6=Base{20.0}
}
TAG=10={
TAG=8=Name{generic.knockbackResistance}
TAG=6=Base{0.0}
}
TAG=10={
TAG=8=Name{generic.movementSpeed}
TAG=6=Base{0.5}
}
TAG=10={
TAG=8=Name{generic.followRange}
TAG=6=Base{16.0}
TAG=9=Modifiers{
TAG=10={
TAG=8=Name{Random spawn bonus}
TAG=4=UUIDLeast{-7122707650022727850}
TAG=3=Operation{1}
TAG=6=Amount{-0.056218180615617}
TAG=4=UUIDMost{6911370851418654730}
}
}
}
}
TAG=9=Motion{
TAG=6={0.0}
TAG=6={-0.0784000015258789}
TAG=6={0.0}
}
TAG=8=CustomName{}
TAG=2=Health{20}
TAG=5=HealF{20.0}
TAG=1=CustomNameVisible{0}
TAG=3=Riches{0}
TAG=2=AttackTime{0}
TAG=2=Fire{-1}
TAG=1=Invulnerable{0}
TAG=2=DeathTime{0}
TAG=10=ForgeData{
TAG=1=MP|Init{1}
}
TAG=5=AbsorptionAmount{0.0}
TAG=9=Equipment{
TAG=10={
}
TAG=10={
}
TAG=10={
}
TAG=10={
}
TAG=10={
}
}
TAG=1=OnGround{1}
TAG=2=HurtTime{0}
TAG=3=Profession{2435}
TAG=3=Dimension{0}
TAG=2=Air{300}
TAG=9=Pos{
TAG=6={349.92262542548815}
TAG=6={69.0}
TAG=6={-79.64941673320787}
}
TAG=1=CanPickUpLoot{0}
TAG=3=PortalCooldown{0}
TAG=1=PersistenceRequired{0}
TAG=1=Leashed{0}
TAG=5=FallDistance{0.0}
TAG=9=Rotation{
TAG=5={793.6119}
TAG=5={0.0}
}
}
TAG=5=yOffset{0.0}
TAG=5=xOffset{0.07737458}
TAG=5=zOffset{0.64941674}
TAG=8=mobID{Villager}
TAG=5=rotation{253.61188}
}
:endtag
:enddata
:endentity

entity:
plugin=vanillaLogicEntity
number=1
data:
position=9,4,16
tag:
TAG=10={
TAG=10=entityData{
TAG=9=DropChances{
TAG=5=0{0.085}
TAG=5=1{0.085}
TAG=5=2{0.085}
TAG=5=3{0.085}
TAG=5=4{0.085}
}
TAG=3=Age{0}
TAG=9=Attributes{
TAG=10={
TAG=8=Name{generic.maxHealth}
TAG=6=Base{20.0}
}
TAG=10={
TAG=8=Name{generic.knockbackResistance}
TAG=6=Base{0.0}
}
TAG=10={
TAG=8=Name{generic.movementSpeed}
TAG=6=Base{0.5}
}
TAG=10={
TAG=8=Name{generic.followRange}
TAG=6=Base{16.0}
TAG=9=Modifiers{
TAG=10={
TAG=8=Name{Random spawn bonus}
TAG=4=UUIDLeast{-5195608287676030770}
TAG=3=Operation{1}
TAG=6=Amount{0.05180532977931144}
TAG=4=UUIDMost{-7309911048367747237}
}
}
}
}
TAG=9=Motion{
TAG=6={0.0}
TAG=6={-0.0784000015258789}
TAG=6={0.0}
}
TAG=8=CustomName{}
TAG=2=Health{19}
TAG=5=HealF{19.0}
TAG=1=CustomNameVisible{0}
TAG=3=Riches{0}
TAG=2=AttackTime{0}
TAG=2=Fire{-1}
TAG=1=Invulnerable{0}
TAG=2=DeathTime{0}
TAG=10=ForgeData{
TAG=1=MP|Init{1}
}
TAG=5=AbsorptionAmount{0.0}
TAG=9=Equipment{
TAG=10={
}
TAG=10={
}
TAG=10={
}
TAG=10={
}
TAG=10={
}
}
TAG=1=OnGround{1}
TAG=2=HurtTime{0}
TAG=3=Profession{44}
TAG=3=Dimension{0}
TAG=2=Air{300}
TAG=9=Pos{
TAG=6={354.74641078021665}
TAG=6={68.0}
TAG=6={-81.51736461889031}
}
TAG=1=CanPickUpLoot{0}
TAG=3=PortalCooldown{0}
TAG=1=PersistenceRequired{0}
TAG=1=Leashed{0}
TAG=5=FallDistance{0.0}
TAG=9=Rotation{
TAG=5={1168.284}
TAG=5={-10.941333}
}
}
TAG=5=yOffset{0.0}
TAG=5=xOffset{0.2535892}
TAG=5=zOffset{0.5173646}
TAG=8=mobID{Villager}
TAG=5=rotation{268.28406}
}
:endtag
:enddata
:endentity

