# Ancient Warfare Structure Template File
# auto-generated structure file. created on: 4/15/2014 at: 19:59:41
# Lines beginning with # denote comments

header:
version=2.0
name=CivFarmChickenPeasantMOH
size=15,19,12
offset=4,2,9
:endheader

#### VALIDATION ####
validation:
type=ground
survival=false
worldGenEnabled=true
unique=false
preserveBlocks=false
selectionWeight=10
clusterValue=10
minDuplicateDistance=40
dimensionWhiteList=false
dimensionList=
biomeWhiteList=true
biomeList=highlands.meadow,bop.meadow,ebxl.meadow,field,orchard
leveling=9
fill=5
border=5
validTargetBlocks=clay,lapis_ore,sand,grass,lit_redstone_ore,stone,iron_ore,gravel,diamond_ore,stained_hardened_clay,dirt,coal_ore,gold_ore,redstone_ore
data:
:enddata
:endvalidation

#### LAYERS ####
layer: 0
1,1,1,1,1,1,1,1,1,1,1,1,1,1,1
1,1,1,1,1,1,1,1,1,1,1,1,1,1,1
1,1,1,1,1,1,1,1,1,1,1,1,1,1,1
1,1,1,1,1,1,1,1,1,1,1,1,1,1,1
1,1,1,1,1,1,1,1,1,1,1,1,1,1,1
1,1,1,1,1,1,1,1,1,1,1,1,1,1,1
1,1,1,1,1,1,1,1,1,1,1,1,1,1,1
1,1,1,1,1,1,1,1,1,1,1,1,1,1,1
1,1,1,1,1,1,1,1,1,1,1,1,1,1,1
1,1,1,1,1,1,1,1,1,1,1,1,1,1,1
1,1,1,1,1,1,1,1,1,1,1,1,1,1,1
1,1,1,1,1,1,1,1,1,1,1,1,1,1,1
:endlayer
layer: 1
2,2,2,2,2,2,2,2,2,2,2,2,2,2,2
2,2,2,2,2,2,2,2,2,2,2,2,2,2,2
2,2,3,3,3,3,3,3,4,4,3,4,4,2,2
2,2,3,5,3,3,3,3,4,3,3,3,4,2,2
2,2,3,5,3,3,3,3,4,3,3,3,4,2,2
2,2,3,5,3,3,3,3,3,3,3,3,6,2,2
2,2,3,5,3,3,3,3,3,3,3,0,3,2,2
2,2,3,5,3,3,3,3,3,3,3,3,3,2,2
2,2,3,7,3,3,3,3,3,3,3,3,3,2,2
2,2,3,3,3,3,3,3,6,3,3,3,6,2,2
2,2,2,2,2,2,2,2,2,2,2,2,2,2,2
2,2,2,2,2,2,2,2,2,2,2,2,2,2,2
:endlayer
layer: 2
0,0,0,0,0,0,0,0,0,0,0,0,0,0,0
0,0,0,0,0,0,0,0,0,0,0,0,0,0,0
0,0,6,8,6,8,9,8,6,10,10,10,6,0,0
0,0,8,0,8,0,0,0,10,0,11,0,10,0,0
0,0,8,0,8,0,0,0,10,0,0,0,10,0,0
0,0,8,0,8,0,0,0,12,0,0,0,10,0,0
0,0,8,0,13,0,0,0,10,0,0,14,10,0,0
0,0,8,0,8,7,0,0,10,0,3,3,10,0,0
0,0,8,0,8,5,0,0,10,0,15,3,10,0,0
0,0,6,8,6,8,9,8,6,10,10,10,6,0,0
0,0,0,0,0,0,0,0,0,0,0,0,0,0,0
0,0,0,0,0,0,0,0,0,0,0,0,0,0,0
:endlayer
layer: 3
0,0,0,0,0,0,0,0,0,0,0,0,0,0,0
0,0,0,0,0,0,0,0,16,0,0,0,16,0,0
0,0,6,8,6,0,0,0,6,10,8,10,6,0,0
0,0,8,0,8,0,0,0,10,0,0,0,10,17,0
0,0,8,0,8,0,0,0,10,0,0,0,10,0,0
0,0,8,0,8,0,0,0,18,0,0,0,8,0,0
0,0,8,0,0,0,0,0,10,0,0,0,8,0,0
0,0,8,0,8,0,0,0,10,0,3,14,10,0,0
0,0,8,0,8,5,0,0,10,0,0,3,10,17,0
0,0,6,8,6,0,0,0,6,10,8,10,6,0,0
0,0,0,0,0,0,0,0,19,0,0,0,19,0,0
0,0,0,0,0,0,0,0,0,0,0,0,0,0,0
:endlayer
layer: 4
0,0,0,0,0,0,0,0,0,0,0,0,0,0,0
0,0,16,0,0,0,0,0,0,0,0,0,0,0,0
0,20,6,8,6,0,0,0,6,10,10,10,6,0,0
0,0,8,0,0,0,0,0,10,0,0,20,10,0,0
0,0,8,0,0,0,0,0,10,17,0,0,10,0,0
0,0,8,0,0,0,0,20,10,0,0,0,10,0,0
0,0,8,0,0,0,0,0,10,0,0,0,10,0,0
0,0,8,0,0,0,0,0,10,0,3,0,10,0,0
0,0,8,0,0,0,0,0,10,17,21,0,10,0,0
0,20,6,8,6,0,0,0,6,10,10,10,6,0,0
0,0,19,0,0,0,0,0,0,0,0,0,0,0,0
0,0,0,0,0,0,0,0,0,0,0,0,0,0,0
:endlayer
layer: 5
0,0,0,0,0,0,0,0,0,0,0,0,0,0,0
0,22,23,24,0,0,0,0,0,0,0,0,0,25,0
0,22,23,8,26,26,26,26,26,26,26,26,26,25,0
0,22,23,0,10,3,3,3,3,3,3,3,6,25,0
0,22,23,0,10,3,3,3,3,3,3,3,6,25,0
0,22,23,0,10,3,3,3,3,3,3,3,6,25,0
0,22,23,0,10,3,3,3,3,3,3,0,6,25,0
0,22,23,0,10,3,3,3,3,3,3,0,6,25,0
0,22,23,0,10,3,3,3,3,21,0,0,6,25,0
0,22,23,8,26,26,26,26,26,26,26,26,26,25,0
0,22,23,24,0,0,0,0,0,0,0,0,0,25,0
0,0,0,0,0,0,0,0,0,0,0,0,0,0,0
:endlayer
layer: 6
0,0,0,0,0,0,0,0,0,0,0,0,0,0,0
0,0,0,23,0,0,0,0,0,0,0,0,25,0,0
0,0,0,23,10,10,10,10,10,10,10,10,25,0,0
0,0,0,23,10,27,0,28,0,0,29,0,25,0,0
0,0,0,23,10,0,0,0,0,0,30,0,25,0,0
0,0,0,23,10,31,32,0,0,0,8,8,25,0,0
0,0,0,23,10,31,32,0,0,0,8,0,25,0,0
0,0,0,23,10,0,0,0,0,8,8,0,25,0,0
0,0,0,23,10,33,0,0,0,0,0,0,25,0,0
0,0,0,23,10,10,10,10,10,10,10,10,25,0,0
0,0,0,23,0,0,0,0,0,0,0,0,25,0,0
0,0,0,0,0,0,0,0,0,0,0,0,0,0,0
:endlayer
layer: 7
0,0,0,0,0,0,0,0,0,0,0,0,0,0,0
0,0,0,0,23,0,0,0,0,0,0,25,0,0,0
0,0,0,0,23,10,10,8,8,10,10,25,0,0,0
0,0,0,0,23,19,0,0,0,0,0,25,0,0,0
0,0,0,0,23,0,0,0,0,0,0,25,0,0,0
0,0,0,0,23,0,0,0,0,0,0,25,0,0,0
0,0,0,0,23,0,0,0,0,0,0,25,0,0,0
0,0,0,0,23,0,0,0,0,0,0,25,0,0,0
0,0,0,0,23,16,0,0,0,0,16,25,0,0,0
0,0,0,0,23,10,10,8,8,10,10,25,0,0,0
0,0,0,0,23,0,0,0,0,0,0,25,0,0,0
0,0,0,0,0,0,0,0,0,0,0,0,0,0,0
:endlayer
layer: 8
0,0,0,0,0,0,0,0,0,0,0,0,0,0,0
0,0,0,0,0,23,0,16,16,0,25,0,0,0,0
0,0,0,0,0,23,10,10,10,10,25,0,0,0,0
0,0,0,0,0,23,0,0,0,19,25,0,0,0,0
0,0,0,0,0,23,0,0,0,0,25,0,0,0,0
0,0,0,0,0,23,0,0,0,0,25,0,0,0,0
0,0,0,0,0,23,0,0,0,0,25,0,0,0,0
0,0,0,0,0,23,0,0,0,0,25,0,0,0,0
0,0,0,0,0,23,0,0,0,0,25,0,0,0,0
0,0,0,0,0,23,10,10,10,10,25,0,0,0,0
0,0,0,0,0,23,0,19,19,0,25,0,0,0,0
0,0,0,0,0,0,0,0,0,0,0,0,0,0,0
:endlayer
layer: 9
0,0,0,0,0,0,0,0,0,0,0,0,0,0,0
0,0,0,0,0,0,34,23,25,34,0,0,0,0,0
0,0,0,0,0,0,34,23,25,34,0,0,0,0,0
0,0,0,0,0,0,34,23,25,34,0,0,0,0,0
0,0,0,0,0,0,34,23,25,34,0,0,0,0,0
0,0,0,0,0,0,34,23,25,34,0,0,0,0,0
0,0,0,0,0,0,34,23,25,34,0,0,0,0,0
0,0,0,0,0,0,34,23,25,34,0,0,0,0,0
0,0,0,0,0,0,34,23,25,34,0,0,0,0,0
0,0,0,0,0,0,34,23,25,34,0,0,0,0,0
0,0,0,0,0,0,34,23,25,34,0,0,0,0,0
0,0,0,0,0,0,0,0,0,0,0,0,0,0,0
:endlayer
layer: 10
0,0,0,0,0,0,0,0,0,0,0,0,0,0,0
0,0,0,0,0,0,0,0,0,0,0,0,0,0,0
0,0,0,0,0,0,0,0,0,0,0,0,0,0,0
0,0,0,0,0,0,0,0,0,0,0,0,0,0,0
0,0,0,0,0,0,0,0,0,0,0,0,0,0,0
0,0,0,0,0,0,0,0,0,0,0,0,0,0,0
0,0,0,0,0,0,0,0,0,0,0,0,0,0,0
0,0,0,0,0,0,0,0,0,0,0,0,0,0,0
0,0,0,0,0,0,0,0,0,0,0,0,0,0,0
0,0,0,0,0,0,0,0,0,0,0,0,0,0,0
0,0,0,0,0,0,0,0,0,0,0,0,0,0,0
0,0,0,0,0,0,0,0,0,0,0,0,0,0,0
:endlayer
layer: 11
0,0,0,0,0,0,0,0,0,0,0,0,0,0,0
0,0,0,0,0,0,0,0,0,0,0,0,0,0,0
0,0,0,0,0,0,0,0,0,0,0,0,0,0,0
0,0,0,0,0,0,0,0,0,0,0,0,0,0,0
0,0,0,0,0,0,0,0,0,0,0,0,0,0,0
0,0,0,0,0,0,0,0,0,0,0,0,0,0,0
0,0,0,0,0,0,0,0,0,0,0,0,0,0,0
0,0,0,0,0,0,0,0,0,0,0,0,0,0,0
0,0,0,0,0,0,0,0,0,0,0,0,0,0,0
0,0,0,0,0,0,0,0,0,0,0,0,0,0,0
0,0,0,0,0,0,0,0,0,0,0,0,0,0,0
0,0,0,0,0,0,0,0,0,0,0,0,0,0,0
:endlayer
layer: 12
0,0,0,0,0,0,0,0,0,0,0,0,0,0,0
0,0,0,0,0,0,0,0,0,0,0,0,0,0,0
0,0,0,0,0,0,0,0,0,0,0,0,0,0,0
0,0,0,0,0,0,0,0,0,0,0,0,0,0,0
0,0,0,0,0,0,0,0,0,0,0,0,0,0,0
0,0,0,0,0,0,0,0,0,0,0,0,0,0,0
0,0,0,0,0,0,0,0,0,0,0,0,0,0,0
0,0,0,0,0,0,0,0,0,0,0,0,0,0,0
0,0,0,0,0,0,0,0,0,0,0,0,0,0,0
0,0,0,0,0,0,0,0,0,0,0,0,0,0,0
0,0,0,0,0,0,0,0,0,0,0,0,0,0,0
0,0,0,0,0,0,0,0,0,0,0,0,0,0,0
:endlayer
layer: 13
0,0,0,0,0,0,0,0,0,0,0,0,0,0,0
0,0,0,0,0,0,0,0,0,0,0,0,0,0,0
0,0,0,0,0,0,0,0,0,0,0,0,0,0,0
0,0,0,0,0,0,0,0,0,0,0,0,0,0,0
0,0,0,0,0,0,0,0,0,0,0,0,0,0,0
0,0,0,0,0,0,0,0,0,0,0,0,0,0,0
0,0,0,0,0,0,0,0,0,0,0,0,0,0,0
0,0,0,0,0,0,0,0,0,0,0,0,0,0,0
0,0,0,0,0,0,0,0,0,0,0,0,0,0,0
0,0,0,0,0,0,0,0,0,0,0,0,0,0,0
0,0,0,0,0,0,0,0,0,0,0,0,0,0,0
0,0,0,0,0,0,0,0,0,0,0,0,0,0,0
:endlayer
layer: 14
0,0,0,0,0,0,0,0,0,0,0,0,0,0,0
0,0,0,0,0,0,0,0,0,0,0,0,0,0,0
0,0,0,0,0,0,0,0,0,0,0,0,0,0,0
0,0,0,0,0,0,0,0,0,0,0,0,0,0,0
0,0,0,0,0,0,0,0,0,0,0,0,0,0,0
0,0,0,0,0,0,0,0,0,0,0,0,0,0,0
0,0,0,0,0,0,0,0,0,0,0,0,0,0,0
0,0,0,0,0,0,0,0,0,0,0,0,0,0,0
0,0,0,0,0,0,0,0,0,0,0,0,0,0,0
0,0,0,0,0,0,0,0,0,0,0,0,0,0,0
0,0,0,0,0,0,0,0,0,0,0,0,0,0,0
0,0,0,0,0,0,0,0,0,0,0,0,0,0,0
:endlayer
layer: 15
0,0,0,0,0,0,0,0,0,0,0,0,0,0,0
0,0,0,0,0,0,0,0,0,0,0,0,0,0,0
0,0,0,0,0,0,0,0,0,0,0,0,0,0,0
0,0,0,0,0,0,0,0,0,0,0,0,0,0,0
0,0,0,0,0,0,0,0,0,0,0,0,0,0,0
0,0,0,0,0,0,0,0,0,0,0,0,0,0,0
0,0,0,0,0,0,0,0,0,0,0,0,0,0,0
0,0,0,0,0,0,0,0,0,0,0,0,0,0,0
0,0,0,0,0,0,0,0,0,0,0,0,0,0,0
0,0,0,0,0,0,0,0,0,0,0,0,0,0,0
0,0,0,0,0,0,0,0,0,0,0,0,0,0,0
0,0,0,0,0,0,0,0,0,0,0,0,0,0,0
:endlayer
layer: 16
0,0,0,0,0,0,0,0,0,0,0,0,0,0,0
0,0,0,0,0,0,0,0,0,0,0,0,0,0,0
0,0,0,0,0,0,0,0,0,0,0,0,0,0,0
0,0,0,0,0,0,0,0,0,0,0,0,0,0,0
0,0,0,0,0,0,0,0,0,0,0,0,0,0,0
0,0,0,0,0,0,0,0,0,0,0,0,0,0,0
0,0,0,0,0,0,0,0,0,0,0,0,0,0,0
0,0,0,0,0,0,0,0,0,0,0,0,0,0,0
0,0,0,0,0,0,0,0,0,0,0,0,0,0,0
0,0,0,0,0,0,0,0,0,0,0,0,0,0,0
0,0,0,0,0,0,0,0,0,0,0,0,0,0,0
0,0,0,0,0,0,0,0,0,0,0,0,0,0,0
:endlayer
layer: 17
0,0,0,0,0,0,0,0,0,0,0,0,0,0,0
0,0,0,0,0,0,0,0,0,0,0,0,0,0,0
0,0,0,0,0,0,0,0,0,0,0,0,0,0,0
0,0,0,0,0,0,0,0,0,0,0,0,0,0,0
0,0,0,0,0,0,0,0,0,0,0,0,0,0,0
0,0,0,0,0,0,0,0,0,0,0,0,0,0,0
0,0,0,0,0,0,0,0,0,0,0,0,0,0,0
0,0,0,0,0,0,0,0,0,0,0,0,0,0,0
0,0,0,0,0,0,0,0,0,0,0,0,0,0,0
0,0,0,0,0,0,0,0,0,0,0,0,0,0,0
0,0,0,0,0,0,0,0,0,0,0,0,0,0,0
0,0,0,0,0,0,0,0,0,0,0,0,0,0,0
:endlayer
layer: 18
0,0,0,0,0,0,0,0,0,0,0,0,0,0,0
0,0,0,0,0,0,0,0,0,0,0,0,0,0,0
0,0,0,0,0,0,0,0,0,0,0,0,0,0,0
0,0,0,0,0,0,0,0,0,0,0,0,0,0,0
0,0,0,0,0,0,0,0,0,0,0,0,0,0,0
0,0,0,0,0,0,0,0,0,0,0,0,0,0,0
0,0,0,0,0,0,0,0,0,0,0,0,0,0,0
0,0,0,0,0,0,0,0,0,0,0,0,0,0,0
0,0,0,0,0,0,0,0,0,0,0,0,0,0,0
0,0,0,0,0,0,0,0,0,0,0,0,0,0,0
0,0,0,0,0,0,0,0,0,0,0,0,0,0,0
0,0,0,0,0,0,0,0,0,0,0,0,0,0,0
:endlayer

#### RULES ####
rule:
plugin=vanillaBlocks
number=1
data:
tag:
TAG=10={
TAG=8=blockName{stone}
TAG=3=meta{0}
TAG=3=buildPass{0}
}
:endtag
:enddata
:endrule

rule:
plugin=vanillaBlocks
number=2
data:
tag:
TAG=10={
TAG=8=blockName{grass}
TAG=3=meta{0}
TAG=3=buildPass{0}
}
:endtag
:enddata
:endrule

rule:
plugin=vanillaBlocks
number=3
data:
tag:
TAG=10={
TAG=8=blockName{cobblestone}
TAG=3=meta{0}
TAG=3=buildPass{0}
}
:endtag
:enddata
:endrule

rule:
plugin=vanillaBlocks
number=4
data:
tag:
TAG=10={
TAG=8=blockName{dirt}
TAG=3=meta{0}
TAG=3=buildPass{0}
}
:endtag
:enddata
:endrule

rule:
plugin=vanillaBlocks
number=5
data:
tag:
TAG=10={
TAG=8=blockName{hay_block}
TAG=3=meta{0}
TAG=3=buildPass{0}
}
:endtag
:enddata
:endrule

rule:
plugin=vanillaBlocks
number=6
data:
tag:
TAG=10={
TAG=8=blockName{log}
TAG=3=meta{0}
TAG=3=buildPass{0}
}
:endtag
:enddata
:endrule

rule:
plugin=vanillaBlocks
number=7
data:
tag:
TAG=10={
TAG=8=blockName{hay_block}
TAG=3=meta{8}
TAG=3=buildPass{0}
}
:endtag
:enddata
:endrule

rule:
plugin=vanillaBlocks
number=8
data:
tag:
TAG=10={
TAG=8=blockName{fence}
TAG=3=meta{0}
TAG=3=buildPass{0}
}
:endtag
:enddata
:endrule

rule:
plugin=vanillaBlocks
number=9
data:
tag:
TAG=10={
TAG=8=blockName{fence_gate}
TAG=3=meta{0}
TAG=3=buildPass{0}
}
:endtag
:enddata
:endrule

rule:
plugin=vanillaBlocks
number=10
data:
tag:
TAG=10={
TAG=8=blockName{stonebrick}
TAG=3=meta{0}
TAG=3=buildPass{0}
}
:endtag
:enddata
:endrule

rule:
plugin=vanillaBlocks
number=11
data:
tag:
TAG=10={
TAG=8=blockName{crafting_table}
TAG=3=meta{0}
TAG=3=buildPass{0}
}
:endtag
:enddata
:endrule

rule:
plugin=vanillaDoors
number=12
data:
tag:
TAG=10={
TAG=1=sideFlag{8}
TAG=8=blockName{wooden_door}
TAG=3=meta{0}
TAG=3=buildPass{1}
}
:endtag
:enddata
:endrule

rule:
plugin=vanillaBlocks
number=13
data:
tag:
TAG=10={
TAG=8=blockName{fence_gate}
TAG=3=meta{1}
TAG=3=buildPass{0}
}
:endtag
:enddata
:endrule

rule:
plugin=vanillaBlocks
number=14
data:
tag:
TAG=10={
TAG=8=blockName{stone_stairs}
TAG=3=meta{2}
TAG=3=buildPass{0}
}
:endtag
:enddata
:endrule

rule:
plugin=vanillaInventory
number=15
data:
tag:
TAG=10={
TAG=3=lootLevel{0}
TAG=10=teData{
TAG=9=Items{
}
TAG=8=id{Chest}
}
TAG=8=blockName{chest}
TAG=3=meta{4}
TAG=3=buildPass{0}
}
:endtag
:enddata
:endrule

rule:
plugin=vanillaBlocks
number=16
data:
tag:
TAG=10={
TAG=8=blockName{torch}
TAG=3=meta{4}
TAG=3=buildPass{1}
}
:endtag
:enddata
:endrule

rule:
plugin=vanillaBlocks
number=17
data:
tag:
TAG=10={
TAG=8=blockName{torch}
TAG=3=meta{1}
TAG=3=buildPass{1}
}
:endtag
:enddata
:endrule

rule:
plugin=vanillaDoors
number=18
data:
tag:
TAG=10={
TAG=1=sideFlag{0}
TAG=8=blockName{wooden_door}
TAG=3=meta{8}
TAG=3=buildPass{1}
}
:endtag
:enddata
:endrule

rule:
plugin=vanillaBlocks
number=19
data:
tag:
TAG=10={
TAG=8=blockName{torch}
TAG=3=meta{3}
TAG=3=buildPass{1}
}
:endtag
:enddata
:endrule

rule:
plugin=vanillaBlocks
number=20
data:
tag:
TAG=10={
TAG=8=blockName{torch}
TAG=3=meta{2}
TAG=3=buildPass{1}
}
:endtag
:enddata
:endrule

rule:
plugin=vanillaBlocks
number=21
data:
tag:
TAG=10={
TAG=8=blockName{stone_stairs}
TAG=3=meta{1}
TAG=3=buildPass{0}
}
:endtag
:enddata
:endrule

rule:
plugin=vanillaBlocks
number=22
data:
tag:
TAG=10={
TAG=8=blockName{wooden_slab}
TAG=3=meta{0}
TAG=3=buildPass{0}
}
:endtag
:enddata
:endrule

rule:
plugin=vanillaBlocks
number=23
data:
tag:
TAG=10={
TAG=8=blockName{oak_stairs}
TAG=3=meta{0}
TAG=3=buildPass{0}
}
:endtag
:enddata
:endrule

rule:
plugin=vanillaBlocks
number=24
data:
tag:
TAG=10={
TAG=8=blockName{wooden_slab}
TAG=3=meta{8}
TAG=3=buildPass{0}
}
:endtag
:enddata
:endrule

rule:
plugin=vanillaBlocks
number=25
data:
tag:
TAG=10={
TAG=8=blockName{oak_stairs}
TAG=3=meta{1}
TAG=3=buildPass{0}
}
:endtag
:enddata
:endrule

rule:
plugin=vanillaBlocks
number=26
data:
tag:
TAG=10={
TAG=8=blockName{log}
TAG=3=meta{4}
TAG=3=buildPass{0}
}
:endtag
:enddata
:endrule

rule:
plugin=vanillaInventory
number=27
data:
tag:
TAG=10={
TAG=3=lootLevel{0}
TAG=10=teData{
TAG=9=Items{
}
TAG=8=id{Chest}
}
TAG=8=blockName{chest}
TAG=3=meta{5}
TAG=3=buildPass{0}
}
:endtag
:enddata
:endrule

rule:
plugin=vanillaBlocks
number=28
data:
tag:
TAG=10={
TAG=8=blockName{oak_stairs}
TAG=3=meta{3}
TAG=3=buildPass{0}
}
:endtag
:enddata
:endrule

rule:
plugin=vanillaBlocks
number=29
data:
tag:
TAG=10={
TAG=8=blockName{bed}
TAG=3=meta{10}
TAG=3=buildPass{0}
}
:endtag
:enddata
:endrule

rule:
plugin=vanillaBlocks
number=30
data:
tag:
TAG=10={
TAG=8=blockName{bed}
TAG=3=meta{2}
TAG=3=buildPass{0}
}
:endtag
:enddata
:endrule

rule:
plugin=vanillaBlocks
number=31
data:
tag:
TAG=10={
TAG=8=blockName{bed}
TAG=3=meta{9}
TAG=3=buildPass{0}
}
:endtag
:enddata
:endrule

rule:
plugin=vanillaBlocks
number=32
data:
tag:
TAG=10={
TAG=8=blockName{bed}
TAG=3=meta{1}
TAG=3=buildPass{0}
}
:endtag
:enddata
:endrule

rule:
plugin=vanillaInventory
number=33
data:
tag:
TAG=10={
TAG=3=lootLevel{0}
TAG=10=teData{
TAG=9=Items{
TAG=10={
TAG=2=id{344}
TAG=2=Damage{0}
TAG=1=Count{1}
TAG=1=Slot{12}
}
TAG=10={
TAG=2=id{349}
TAG=2=Damage{0}
TAG=1=Count{3}
TAG=1=Slot{17}
}
}
TAG=8=id{Chest}
}
TAG=8=blockName{chest}
TAG=3=meta{2}
TAG=3=buildPass{0}
}
:endtag
:enddata
:endrule

rule:
plugin=vanillaBlocks
number=34
data:
tag:
TAG=10={
TAG=8=blockName{stone_slab}
TAG=3=meta{2}
TAG=3=buildPass{0}
}
:endtag
:enddata
:endrule

#### ENTITIES ####
entity:
plugin=vanillaEntities
number=0
data:
position=2,2,4
tag:
TAG=10={
TAG=5=yOffset{0.0}
TAG=5=xOffset{0.775}
TAG=5=zOffset{0.50011957}
TAG=8=mobID{Chicken}
TAG=5=rotation{90.00539}
}
:endtag
:enddata
:endentity

entity:
plugin=vanillaEntities
number=1
data:
position=3,2,2
tag:
TAG=10={
TAG=5=yOffset{0.0}
TAG=5=xOffset{0.50011826}
TAG=5=zOffset{0.775}
TAG=8=mobID{Chicken}
TAG=5=rotation{-180.00531}
}
:endtag
:enddata
:endentity

entity:
plugin=vanillaEntities
number=2
data:
position=3,2,6
tag:
TAG=10={
TAG=5=yOffset{0.0}
TAG=5=xOffset{0.50015986}
TAG=5=zOffset{0.16119844}
TAG=8=mobID{Chicken}
TAG=5=rotation{0.031188965}
}
:endtag
:enddata
:endentity

entity:
plugin=vanillaEntities
number=3
data:
position=4,2,8
tag:
TAG=10={
TAG=5=yOffset{0.0}
TAG=5=xOffset{0.225}
TAG=5=zOffset{0.69401133}
TAG=8=mobID{Chicken}
TAG=5=rotation{-198.57983}
}
:endtag
:enddata
:endentity

entity:
plugin=vanillaEntities
number=4
data:
position=2,2,8
tag:
TAG=10={
TAG=5=yOffset{0.0}
TAG=5=xOffset{0.7}
TAG=5=zOffset{0.4999857}
TAG=8=mobID{Chicken}
TAG=5=rotation{-270.00412}
}
:endtag
:enddata
:endentity

entity:
plugin=vanillaEntities
number=5
data:
position=3,2,6
tag:
TAG=10={
TAG=5=yOffset{0.0}
TAG=5=xOffset{0.49466854}
TAG=5=zOffset{0.84397775}
TAG=8=mobID{Chicken}
TAG=5=rotation{180.96338}
}
:endtag
:enddata
:endentity

