# Ancient Warfare Structure Template File
# auto-generated structure file. created on: 4/14/2014 at: 16:0:34
# Lines beginning with # denote comments

header:
version=2.0
name=CivFarmMelonPeasantMOH
size=23,19,16
offset=16,2,13
:endheader

#### VALIDATION ####
validation:
type=ground
survival=false
worldGenEnabled=true
unique=false
preserveBlocks=false
selectionWeight=10
clusterValue=10
minDuplicateDistance=40
dimensionWhiteList=false
dimensionList=
biomeWhiteList=true
biomeList=highlands.meadow,bop.meadow,ebxl.meadow,field,orchard
leveling=9
fill=5
border=5
validTargetBlocks=clay,lapis_ore,sand,grass,lit_redstone_ore,stone,gravel,iron_ore,diamond_ore,stained_hardened_clay,dirt,coal_ore,redstone_ore,gold_ore
data:
:enddata
:endvalidation

#### LAYERS ####
layer: 0
1,1,1,1,1,1,1,1,1,1,1,1,1,1,1,1,1,1,1,1,1,1,1
1,1,1,1,1,1,1,1,1,1,1,1,1,1,1,1,1,1,1,1,1,1,1
1,1,1,1,1,1,1,1,1,1,1,1,1,1,1,1,1,1,1,1,1,1,1
1,1,1,1,1,1,1,1,1,1,1,1,1,1,1,1,1,1,1,1,1,1,1
1,1,1,1,1,1,1,1,1,1,1,1,1,1,1,1,1,1,1,1,1,1,1
1,1,1,1,1,1,1,1,1,1,1,1,1,1,1,1,1,1,1,1,1,1,1
1,1,1,1,1,1,1,1,1,1,1,1,1,1,1,1,1,1,1,1,1,1,1
1,1,1,1,1,1,1,1,1,1,1,1,1,1,1,1,1,1,1,1,1,1,1
1,1,1,1,1,1,1,1,1,1,1,1,1,1,1,1,1,1,1,1,1,1,1
1,1,1,1,1,1,1,1,1,1,1,1,1,1,1,1,1,1,1,1,1,1,1
1,1,1,1,1,1,1,1,1,1,1,1,1,1,1,1,1,1,1,1,1,1,1
1,1,1,1,1,1,1,1,1,1,1,1,1,1,1,1,1,1,1,1,1,1,1
1,1,1,1,1,1,1,1,1,1,1,1,1,1,1,1,1,1,1,1,1,1,1
1,1,1,1,1,1,1,1,1,1,1,1,1,1,1,1,1,1,1,1,1,1,1
1,1,1,1,1,1,1,1,1,1,1,1,1,1,1,1,1,1,1,1,1,1,1
1,1,1,1,1,1,1,1,1,1,1,1,1,1,1,1,1,1,1,1,1,1,1
:endlayer
layer: 1
2,2,2,2,2,2,2,2,2,2,2,2,2,2,2,2,2,2,2,2,2,2,2
2,2,2,2,2,2,3,2,2,2,2,2,2,2,2,2,2,2,2,2,2,2,2
2,2,2,2,2,2,3,2,2,2,1,1,1,1,1,1,1,1,1,1,1,2,2
2,2,6,1,7,1,3,1,7,6,1,1,1,1,1,1,1,1,1,1,1,2,2
2,2,6,1,7,1,3,1,7,6,1,1,1,1,1,1,1,1,1,1,1,2,2
2,2,6,1,7,1,3,1,7,6,1,1,1,1,1,1,1,1,1,1,1,2,2
2,2,6,1,7,1,3,1,7,6,1,1,1,1,1,1,1,1,1,1,1,2,2
2,2,6,1,7,1,3,1,7,6,1,1,1,1,1,1,1,1,1,1,1,2,2
2,2,6,1,7,1,3,1,7,6,6,6,6,5,4,1,1,1,1,1,1,2,2
2,2,6,1,7,1,3,1,7,7,7,7,7,4,1,1,1,1,1,1,1,2,2
2,2,6,1,7,1,3,3,1,1,1,1,1,1,1,1,1,1,1,1,1,2,2
2,2,6,1,7,1,3,3,3,3,3,3,3,3,3,1,1,1,1,1,1,2,2
2,2,2,2,2,2,2,2,2,2,2,2,3,3,1,1,1,1,1,1,1,2,2
2,2,2,7,2,2,1,8,2,2,8,2,3,2,2,2,1,2,1,2,2,2,2
2,2,2,1,2,2,2,2,2,2,1,2,3,3,3,3,3,3,3,2,2,2,2
2,2,2,2,2,2,2,2,2,2,2,2,2,2,2,2,3,3,3,2,2,2,2
:endlayer
layer: 2
9,0,9,9,9,9,0,9,9,9,9,9,9,0,9,9,9,9,11,0,0,0,0
9,9,9,9,9,9,0,0,0,9,9,9,9,0,9,9,9,9,9,0,9,0,0
9,16,16,16,16,16,15,16,16,16,5,5,5,5,5,5,5,5,5,5,5,9,9
9,16,0,14,13,14,0,14,13,0,5,10,10,10,10,10,10,10,10,10,5,9,9
9,16,0,14,13,14,0,14,13,0,5,10,10,10,10,10,10,10,10,10,5,0,0
0,16,0,14,13,14,0,14,13,0,5,10,10,10,10,10,10,10,10,10,5,0,0
0,16,0,14,13,14,0,14,13,0,5,10,10,10,10,10,10,10,10,10,5,0,0
0,16,0,14,13,14,0,14,13,0,5,5,5,5,5,5,10,10,10,10,5,0,0
0,16,0,14,13,14,0,14,13,0,0,0,0,5,5,5,10,10,10,10,5,0,0
9,16,0,14,13,14,0,14,13,13,13,13,13,5,5,5,10,10,10,10,5,0,0
9,16,0,14,13,14,0,0,14,14,14,14,14,5,5,5,10,10,10,10,5,9,9
0,16,0,14,13,14,0,0,0,0,0,0,0,5,5,5,10,10,10,10,5,9,9
9,16,16,16,16,16,16,16,16,16,16,16,15,5,5,5,5,10,5,5,5,9,9
9,0,0,17,0,0,18,17,0,0,17,0,0,0,0,0,5,12,5,0,9,9,9
0,0,0,18,0,0,0,0,0,0,18,0,0,0,0,0,0,0,0,9,9,9,0
0,0,0,0,0,0,0,0,0,0,0,0,0,0,0,0,0,0,0,0,0,0,0
:endlayer
layer: 3
0,0,0,0,0,0,0,0,0,0,0,0,0,0,0,0,0,0,0,0,0,0,0
0,0,0,0,0,0,0,0,0,0,0,0,0,0,0,0,0,0,0,0,0,0,0
0,35,0,0,0,35,0,35,0,0,5,19,19,19,19,5,19,19,19,19,5,0,0
0,0,0,0,0,0,0,0,0,0,19,33,0,0,30,19,10,10,10,10,19,0,0
0,0,0,0,0,0,0,0,0,0,19,34,32,0,0,19,0,0,12,12,19,0,0
0,0,0,0,0,0,0,0,0,0,19,34,32,0,0,29,0,0,16,16,19,0,0
0,0,0,0,0,0,0,0,0,0,19,33,0,0,0,19,0,0,20,20,19,0,0
0,0,0,0,0,0,0,0,0,0,5,19,19,19,19,5,19,25,19,19,5,0,0
0,0,0,0,0,0,0,0,0,0,0,0,0,19,31,19,26,0,0,21,19,0,0
0,0,0,0,0,0,0,0,0,0,0,0,0,19,0,19,27,0,0,22,19,0,0
0,0,0,0,0,0,0,0,0,0,0,0,0,19,0,19,28,0,0,23,19,0,0
0,0,0,0,0,0,0,0,0,0,0,0,0,19,0,0,0,0,0,24,19,0,0
0,35,0,0,0,0,35,0,0,0,0,35,0,5,19,19,19,25,19,19,5,0,0
0,0,0,0,0,0,0,0,0,0,0,0,0,0,0,0,16,0,16,0,0,0,0
0,0,0,0,0,0,0,0,0,0,0,0,0,0,0,0,0,0,0,0,0,0,0
0,0,0,0,0,0,0,0,0,0,0,0,0,0,0,0,0,0,0,0,0,0,0
:endlayer
layer: 4
0,0,0,0,0,0,0,0,0,0,0,0,0,0,0,0,0,0,0,0,0,0,0
0,0,0,0,0,0,0,0,0,0,0,0,0,0,0,0,0,0,0,0,0,0,0
0,0,0,0,0,0,0,0,0,0,5,19,19,19,19,5,19,19,19,19,5,0,0
0,0,0,0,0,0,0,0,0,0,19,35,0,0,0,19,33,33,33,33,19,0,0
0,0,0,0,0,0,0,0,0,0,19,0,0,0,0,19,0,0,0,0,19,0,0
0,0,0,0,0,0,0,0,0,0,19,0,0,0,0,39,0,0,36,36,19,0,0
0,0,0,0,0,0,0,0,0,0,19,35,0,0,0,19,0,0,0,0,19,0,0
0,0,0,0,0,0,0,0,0,0,5,19,19,19,19,5,19,37,19,19,5,0,0
0,0,0,0,0,0,0,0,0,0,0,0,0,19,40,19,0,0,0,0,19,0,0
0,0,0,0,0,0,0,0,0,0,0,0,0,19,0,19,28,0,0,0,19,0,0
0,0,0,0,0,0,0,0,0,0,0,0,0,19,0,19,0,0,0,0,19,0,0
0,0,0,0,0,0,0,0,0,0,0,0,0,19,0,0,0,0,0,0,19,0,0
0,0,0,0,0,0,0,0,0,0,0,0,0,5,19,19,19,38,19,19,5,0,0
0,0,0,0,0,0,0,0,0,0,0,0,0,0,0,0,16,0,16,0,0,0,0
0,0,0,0,0,0,0,0,0,0,0,0,0,0,0,0,0,0,0,0,0,0,0
0,0,0,0,0,0,0,0,0,0,0,0,0,0,0,0,0,0,0,0,0,0,0
:endlayer
layer: 5
0,0,0,0,0,0,0,0,0,0,0,0,0,0,0,0,0,0,0,0,0,0,0
0,0,0,0,0,0,0,0,0,0,42,0,0,0,0,0,0,0,0,0,42,0,0
0,0,0,0,0,0,0,0,0,45,5,19,19,19,19,5,19,19,19,19,5,41,0
0,0,0,0,0,0,0,0,0,0,19,0,0,0,0,19,33,33,33,33,19,0,0
0,0,0,0,0,0,0,0,0,0,19,0,0,0,0,19,0,0,0,0,19,0,0
0,0,0,0,0,0,0,0,0,0,19,0,0,0,45,19,0,0,0,0,19,0,0
0,0,0,0,0,0,0,0,0,0,19,0,0,0,0,19,42,0,0,42,19,0,0
0,0,0,0,0,0,0,0,0,45,5,19,19,19,19,5,19,19,19,19,5,0,0
0,0,0,0,0,0,0,0,0,0,43,0,0,19,46,19,28,0,0,0,19,0,0
0,0,0,0,0,0,0,0,0,0,0,0,0,19,0,19,0,0,0,0,19,0,0
0,0,0,0,0,0,0,0,0,0,0,0,0,19,0,19,0,0,0,0,19,0,0
0,0,0,0,0,0,0,0,0,0,0,0,0,19,0,0,0,0,0,0,19,0,0
0,0,0,0,0,0,0,0,0,0,0,0,45,5,19,19,19,19,19,19,5,41,0
0,0,0,0,0,0,0,0,0,0,0,0,0,43,0,0,44,40,44,0,43,0,0
0,0,0,0,0,0,0,0,0,0,0,0,0,0,0,0,0,0,0,0,0,0,0
0,0,0,0,0,0,0,0,0,0,0,0,0,0,0,0,0,0,0,0,0,0,0
:endlayer
layer: 6
0,0,0,0,0,0,0,0,0,0,0,0,0,0,0,0,0,0,0,0,0,0,0
0,0,0,0,0,0,0,0,0,20,20,20,20,20,20,20,20,20,20,20,20,47,0
0,0,0,0,0,0,0,0,0,0,5,5,5,5,5,5,5,5,5,5,5,48,0
0,0,0,0,0,0,0,0,0,0,5,10,10,10,10,10,10,10,10,10,5,48,0
0,0,0,0,0,0,0,0,0,0,5,10,10,10,10,10,10,10,10,10,5,48,0
0,0,0,0,0,0,0,0,0,0,5,10,10,10,10,10,10,10,10,10,5,48,0
0,0,0,0,0,0,0,0,0,0,5,10,10,10,10,10,10,10,10,10,5,48,0
0,0,0,0,0,0,0,0,0,0,5,5,5,5,5,5,0,49,5,5,5,48,0
0,0,0,0,0,0,0,0,0,12,12,12,51,19,43,5,0,0,0,43,5,48,0
0,0,0,0,0,0,0,0,0,0,0,0,51,19,0,5,0,0,0,0,5,48,0
0,0,0,0,0,0,0,0,0,0,0,0,51,19,0,5,0,0,0,0,5,48,0
0,0,0,0,0,0,0,0,0,0,0,0,51,19,42,5,42,0,0,42,5,48,0
0,0,0,0,0,0,0,0,0,0,0,0,51,5,4,5,5,5,5,5,5,48,0
0,0,0,0,0,0,0,0,0,0,0,0,44,51,44,47,47,50,47,47,47,48,0
0,0,0,0,0,0,0,0,0,0,0,0,0,0,0,0,0,0,0,0,0,0,0
0,0,0,0,0,0,0,0,0,0,0,0,0,0,0,0,0,0,0,0,0,0,0
:endlayer
layer: 7
0,0,0,0,0,0,0,0,0,0,0,0,0,0,0,0,0,0,0,0,0,0,0
0,0,0,0,0,0,0,0,0,0,0,0,0,0,0,0,0,0,0,0,0,0,0
0,0,0,0,0,0,0,0,0,20,20,20,20,20,20,20,20,20,20,20,47,0,0
0,0,0,0,0,0,0,0,0,0,5,16,16,16,16,16,5,16,16,5,48,0,0
0,0,0,0,0,0,0,0,0,0,52,0,34,32,0,0,0,0,0,16,48,0,0
0,0,0,0,0,0,0,0,0,0,52,0,0,0,0,0,0,0,0,16,48,0,0
0,0,0,0,0,0,0,0,0,0,5,16,16,16,16,16,0,0,0,16,48,0,0
0,0,0,0,0,0,0,0,0,12,12,12,12,51,12,10,0,0,16,5,48,0,0
0,0,0,0,0,0,0,0,0,0,0,0,0,51,10,10,0,0,0,0,48,0,0
0,0,0,0,0,0,0,0,0,0,0,0,0,51,10,10,0,0,0,0,48,0,0
0,0,0,0,0,0,0,0,0,0,0,0,0,51,10,10,0,0,0,0,48,0,0
0,0,0,0,0,0,0,0,0,0,0,0,0,51,10,10,0,0,0,0,48,0,0
0,0,0,0,0,0,0,0,0,0,0,0,0,51,10,5,52,52,52,5,48,0,0
0,0,0,0,0,0,0,0,0,0,0,0,0,0,51,0,0,0,0,0,48,0,0
0,0,0,0,0,0,0,0,0,0,0,0,0,0,0,0,0,0,0,0,0,0,0
0,0,0,0,0,0,0,0,0,0,0,0,0,0,0,0,0,0,0,0,0,0,0
:endlayer
layer: 8
0,0,0,0,0,0,0,0,0,0,0,0,0,0,0,0,0,0,0,0,0,0,0
0,0,0,0,0,0,0,0,0,0,0,0,0,0,0,0,0,0,0,0,0,0,0
0,0,0,0,0,0,0,0,0,0,0,0,0,0,0,0,0,0,0,0,0,0,0
0,0,0,0,0,0,0,0,0,20,20,20,20,20,20,20,20,20,20,47,0,0,0
0,0,0,0,0,0,0,0,0,53,5,0,0,0,0,0,0,0,0,48,0,0,0
0,0,0,0,0,0,0,0,0,53,5,41,0,0,0,0,0,0,0,48,0,0,0
0,0,0,0,0,0,0,0,0,12,12,12,12,12,12,10,0,0,0,48,0,0,0
0,0,0,0,0,0,0,0,0,0,0,0,0,0,51,10,0,0,0,48,0,0,0
0,0,0,0,0,0,0,0,0,0,0,0,0,0,51,10,0,0,0,48,0,0,0
0,0,0,0,0,0,0,0,0,0,0,0,0,0,0,52,0,0,0,48,0,0,0
0,0,0,0,0,0,0,0,0,0,0,0,0,0,51,10,0,0,0,48,0,0,0
0,0,0,0,0,0,0,0,0,0,0,0,0,0,0,52,0,0,0,48,0,0,0
0,0,0,0,0,0,0,0,0,0,0,0,0,0,51,10,5,5,5,48,0,0,0
0,0,0,0,0,0,0,0,0,0,0,0,0,0,0,51,40,53,53,48,0,0,0
0,0,0,0,0,0,0,0,0,0,0,0,0,0,0,0,0,0,0,0,0,0,0
0,0,0,0,0,0,0,0,0,0,0,0,0,0,0,0,0,0,0,0,0,0,0
:endlayer
layer: 9
0,0,0,0,0,0,0,0,0,0,0,0,0,0,0,0,0,0,0,0,0,0,0
0,0,0,0,0,0,0,0,0,0,0,0,0,0,0,0,0,0,0,0,0,0,0
0,0,0,0,0,0,0,0,0,0,0,0,0,0,0,0,0,0,0,0,0,0,0
0,0,0,0,0,0,0,0,0,0,0,0,0,0,0,0,0,0,0,0,0,0,0
0,0,0,0,0,0,0,0,0,0,47,20,20,20,20,20,20,20,47,0,0,0,0
0,0,0,0,0,0,0,0,0,0,47,12,12,12,12,51,10,10,48,0,0,0,0
0,0,0,0,0,0,0,0,0,0,0,0,0,0,0,51,10,10,48,0,0,0,0
0,0,0,0,0,0,0,0,0,0,0,0,0,0,0,51,10,10,48,0,0,0,0
0,0,0,0,0,0,0,0,0,0,0,0,0,0,0,51,10,10,48,0,0,0,0
0,0,0,0,0,0,0,0,0,0,0,0,0,0,44,51,10,10,48,0,0,0,0
0,0,0,0,0,0,0,0,0,0,0,0,0,0,0,51,10,10,48,0,0,0,0
0,0,0,0,0,0,0,0,0,0,0,0,0,0,44,51,10,10,48,0,0,0,0
0,0,0,0,0,0,0,0,0,0,0,0,0,0,0,12,12,12,12,0,0,0,0
0,0,0,0,0,0,0,0,0,0,0,0,0,0,0,0,0,0,0,0,0,0,0
0,0,0,0,0,0,0,0,0,0,0,0,0,0,0,0,0,0,0,0,0,0,0
0,0,0,0,0,0,0,0,0,0,0,0,0,0,0,0,0,0,0,0,0,0,0
:endlayer
layer: 10
0,0,0,0,0,0,0,0,0,0,0,0,0,0,0,0,0,0,0,0,0,0,0
0,0,0,0,0,0,0,0,0,0,0,0,0,0,0,0,0,0,0,0,0,0,0
0,0,0,0,0,0,0,0,0,0,0,0,0,0,0,0,0,0,0,0,0,0,0
0,0,0,0,0,0,0,0,0,0,0,0,0,0,0,0,0,0,0,0,0,0,0
0,0,0,0,0,0,0,0,0,0,0,0,0,0,0,0,0,0,0,0,0,0,0
0,0,0,0,0,0,0,0,0,0,0,0,0,0,0,0,20,20,0,0,0,0,0
0,0,0,0,0,0,0,0,0,0,0,0,0,0,0,0,51,48,0,0,0,0,0
0,0,0,0,0,0,0,0,0,0,0,0,0,0,0,0,51,48,0,0,0,0,0
0,0,0,0,0,0,0,0,0,0,0,0,0,0,0,0,51,48,0,0,0,0,0
0,0,0,0,0,0,0,0,0,0,0,0,0,0,0,0,51,48,0,0,0,0,0
0,0,0,0,0,0,0,0,0,0,0,0,0,0,0,0,51,48,0,0,0,0,0
0,0,0,0,0,0,0,0,0,0,0,0,0,0,0,0,12,12,0,0,0,0,0
0,0,0,0,0,0,0,0,0,0,0,0,0,0,0,0,0,0,0,0,0,0,0
0,0,0,0,0,0,0,0,0,0,0,0,0,0,0,0,0,0,0,0,0,0,0
0,0,0,0,0,0,0,0,0,0,0,0,0,0,0,0,0,0,0,0,0,0,0
0,0,0,0,0,0,0,0,0,0,0,0,0,0,0,0,0,0,0,0,0,0,0
:endlayer
layer: 11
0,0,0,0,0,0,0,0,0,0,0,0,0,0,0,0,0,0,0,0,0,0,0
0,0,0,0,0,0,0,0,0,0,0,0,0,0,0,0,0,0,0,0,0,0,0
0,0,0,0,0,0,0,0,0,0,0,0,0,0,0,0,0,0,0,0,0,0,0
0,0,0,0,0,0,0,0,0,0,0,0,0,0,0,0,0,0,0,0,0,0,0
0,0,0,0,0,0,0,0,0,0,0,0,0,0,0,0,0,0,0,0,0,0,0
0,0,0,0,0,0,0,0,0,0,0,0,0,0,0,0,0,0,0,0,0,0,0
0,0,0,0,0,0,0,0,0,0,0,0,0,0,0,0,0,0,0,0,0,0,0
0,0,0,0,0,0,0,0,0,0,0,0,0,0,0,0,0,0,0,0,0,0,0
0,0,0,0,0,0,0,0,0,0,0,0,0,0,0,0,0,0,0,0,0,0,0
0,0,0,0,0,0,0,0,0,0,0,0,0,0,0,0,0,0,0,0,0,0,0
0,0,0,0,0,0,0,0,0,0,0,0,0,0,0,0,0,0,0,0,0,0,0
0,0,0,0,0,0,0,0,0,0,0,0,0,0,0,0,0,0,0,0,0,0,0
0,0,0,0,0,0,0,0,0,0,0,0,0,0,0,0,0,0,0,0,0,0,0
0,0,0,0,0,0,0,0,0,0,0,0,0,0,0,0,0,0,0,0,0,0,0
0,0,0,0,0,0,0,0,0,0,0,0,0,0,0,0,0,0,0,0,0,0,0
0,0,0,0,0,0,0,0,0,0,0,0,0,0,0,0,0,0,0,0,0,0,0
:endlayer
layer: 12
0,0,0,0,0,0,0,0,0,0,0,0,0,0,0,0,0,0,0,0,0,0,0
0,0,0,0,0,0,0,0,0,0,0,0,0,0,0,0,0,0,0,0,0,0,0
0,0,0,0,0,0,0,0,0,0,0,0,0,0,0,0,0,0,0,0,0,0,0
0,0,0,0,0,0,0,0,0,0,0,0,0,0,0,0,0,0,0,0,0,0,0
0,0,0,0,0,0,0,0,0,0,0,0,0,0,0,0,0,0,0,0,0,0,0
0,0,0,0,0,0,0,0,0,0,0,0,0,0,0,0,0,0,0,0,0,0,0
0,0,0,0,0,0,0,0,0,0,0,0,0,0,0,0,0,0,0,0,0,0,0
0,0,0,0,0,0,0,0,0,0,0,0,0,0,0,0,0,0,0,0,0,0,0
0,0,0,0,0,0,0,0,0,0,0,0,0,0,0,0,0,0,0,0,0,0,0
0,0,0,0,0,0,0,0,0,0,0,0,0,0,0,0,0,0,0,0,0,0,0
0,0,0,0,0,0,0,0,0,0,0,0,0,0,0,0,0,0,0,0,0,0,0
0,0,0,0,0,0,0,0,0,0,0,0,0,0,0,0,0,0,0,0,0,0,0
0,0,0,0,0,0,0,0,0,0,0,0,0,0,0,0,0,0,0,0,0,0,0
0,0,0,0,0,0,0,0,0,0,0,0,0,0,0,0,0,0,0,0,0,0,0
0,0,0,0,0,0,0,0,0,0,0,0,0,0,0,0,0,0,0,0,0,0,0
0,0,0,0,0,0,0,0,0,0,0,0,0,0,0,0,0,0,0,0,0,0,0
:endlayer
layer: 13
0,0,0,0,0,0,0,0,0,0,0,0,0,0,0,0,0,0,0,0,0,0,0
0,0,0,0,0,0,0,0,0,0,0,0,0,0,0,0,0,0,0,0,0,0,0
0,0,0,0,0,0,0,0,0,0,0,0,0,0,0,0,0,0,0,0,0,0,0
0,0,0,0,0,0,0,0,0,0,0,0,0,0,0,0,0,0,0,0,0,0,0
0,0,0,0,0,0,0,0,0,0,0,0,0,0,0,0,0,0,0,0,0,0,0
0,0,0,0,0,0,0,0,0,0,0,0,0,0,0,0,0,0,0,0,0,0,0
0,0,0,0,0,0,0,0,0,0,0,0,0,0,0,0,0,0,0,0,0,0,0
0,0,0,0,0,0,0,0,0,0,0,0,0,0,0,0,0,0,0,0,0,0,0
0,0,0,0,0,0,0,0,0,0,0,0,0,0,0,0,0,0,0,0,0,0,0
0,0,0,0,0,0,0,0,0,0,0,0,0,0,0,0,0,0,0,0,0,0,0
0,0,0,0,0,0,0,0,0,0,0,0,0,0,0,0,0,0,0,0,0,0,0
0,0,0,0,0,0,0,0,0,0,0,0,0,0,0,0,0,0,0,0,0,0,0
0,0,0,0,0,0,0,0,0,0,0,0,0,0,0,0,0,0,0,0,0,0,0
0,0,0,0,0,0,0,0,0,0,0,0,0,0,0,0,0,0,0,0,0,0,0
0,0,0,0,0,0,0,0,0,0,0,0,0,0,0,0,0,0,0,0,0,0,0
0,0,0,0,0,0,0,0,0,0,0,0,0,0,0,0,0,0,0,0,0,0,0
:endlayer
layer: 14
0,0,0,0,0,0,0,0,0,0,0,0,0,0,0,0,0,0,0,0,0,0,0
0,0,0,0,0,0,0,0,0,0,0,0,0,0,0,0,0,0,0,0,0,0,0
0,0,0,0,0,0,0,0,0,0,0,0,0,0,0,0,0,0,0,0,0,0,0
0,0,0,0,0,0,0,0,0,0,0,0,0,0,0,0,0,0,0,0,0,0,0
0,0,0,0,0,0,0,0,0,0,0,0,0,0,0,0,0,0,0,0,0,0,0
0,0,0,0,0,0,0,0,0,0,0,0,0,0,0,0,0,0,0,0,0,0,0
0,0,0,0,0,0,0,0,0,0,0,0,0,0,0,0,0,0,0,0,0,0,0
0,0,0,0,0,0,0,0,0,0,0,0,0,0,0,0,0,0,0,0,0,0,0
0,0,0,0,0,0,0,0,0,0,0,0,0,0,0,0,0,0,0,0,0,0,0
0,0,0,0,0,0,0,0,0,0,0,0,0,0,0,0,0,0,0,0,0,0,0
0,0,0,0,0,0,0,0,0,0,0,0,0,0,0,0,0,0,0,0,0,0,0
0,0,0,0,0,0,0,0,0,0,0,0,0,0,0,0,0,0,0,0,0,0,0
0,0,0,0,0,0,0,0,0,0,0,0,0,0,0,0,0,0,0,0,0,0,0
0,0,0,0,0,0,0,0,0,0,0,0,0,0,0,0,0,0,0,0,0,0,0
0,0,0,0,0,0,0,0,0,0,0,0,0,0,0,0,0,0,0,0,0,0,0
0,0,0,0,0,0,0,0,0,0,0,0,0,0,0,0,0,0,0,0,0,0,0
:endlayer
layer: 15
0,0,0,0,0,0,0,0,0,0,0,0,0,0,0,0,0,0,0,0,0,0,0
0,0,0,0,0,0,0,0,0,0,0,0,0,0,0,0,0,0,0,0,0,0,0
0,0,0,0,0,0,0,0,0,0,0,0,0,0,0,0,0,0,0,0,0,0,0
0,0,0,0,0,0,0,0,0,0,0,0,0,0,0,0,0,0,0,0,0,0,0
0,0,0,0,0,0,0,0,0,0,0,0,0,0,0,0,0,0,0,0,0,0,0
0,0,0,0,0,0,0,0,0,0,0,0,0,0,0,0,0,0,0,0,0,0,0
0,0,0,0,0,0,0,0,0,0,0,0,0,0,0,0,0,0,0,0,0,0,0
0,0,0,0,0,0,0,0,0,0,0,0,0,0,0,0,0,0,0,0,0,0,0
0,0,0,0,0,0,0,0,0,0,0,0,0,0,0,0,0,0,0,0,0,0,0
0,0,0,0,0,0,0,0,0,0,0,0,0,0,0,0,0,0,0,0,0,0,0
0,0,0,0,0,0,0,0,0,0,0,0,0,0,0,0,0,0,0,0,0,0,0
0,0,0,0,0,0,0,0,0,0,0,0,0,0,0,0,0,0,0,0,0,0,0
0,0,0,0,0,0,0,0,0,0,0,0,0,0,0,0,0,0,0,0,0,0,0
0,0,0,0,0,0,0,0,0,0,0,0,0,0,0,0,0,0,0,0,0,0,0
0,0,0,0,0,0,0,0,0,0,0,0,0,0,0,0,0,0,0,0,0,0,0
0,0,0,0,0,0,0,0,0,0,0,0,0,0,0,0,0,0,0,0,0,0,0
:endlayer
layer: 16
0,0,0,0,0,0,0,0,0,0,0,0,0,0,0,0,0,0,0,0,0,0,0
0,0,0,0,0,0,0,0,0,0,0,0,0,0,0,0,0,0,0,0,0,0,0
0,0,0,0,0,0,0,0,0,0,0,0,0,0,0,0,0,0,0,0,0,0,0
0,0,0,0,0,0,0,0,0,0,0,0,0,0,0,0,0,0,0,0,0,0,0
0,0,0,0,0,0,0,0,0,0,0,0,0,0,0,0,0,0,0,0,0,0,0
0,0,0,0,0,0,0,0,0,0,0,0,0,0,0,0,0,0,0,0,0,0,0
0,0,0,0,0,0,0,0,0,0,0,0,0,0,0,0,0,0,0,0,0,0,0
0,0,0,0,0,0,0,0,0,0,0,0,0,0,0,0,0,0,0,0,0,0,0
0,0,0,0,0,0,0,0,0,0,0,0,0,0,0,0,0,0,0,0,0,0,0
0,0,0,0,0,0,0,0,0,0,0,0,0,0,0,0,0,0,0,0,0,0,0
0,0,0,0,0,0,0,0,0,0,0,0,0,0,0,0,0,0,0,0,0,0,0
0,0,0,0,0,0,0,0,0,0,0,0,0,0,0,0,0,0,0,0,0,0,0
0,0,0,0,0,0,0,0,0,0,0,0,0,0,0,0,0,0,0,0,0,0,0
0,0,0,0,0,0,0,0,0,0,0,0,0,0,0,0,0,0,0,0,0,0,0
0,0,0,0,0,0,0,0,0,0,0,0,0,0,0,0,0,0,0,0,0,0,0
0,0,0,0,0,0,0,0,0,0,0,0,0,0,0,0,0,0,0,0,0,0,0
:endlayer
layer: 17
0,0,0,0,0,0,0,0,0,0,0,0,0,0,0,0,0,0,0,0,0,0,0
0,0,0,0,0,0,0,0,0,0,0,0,0,0,0,0,0,0,0,0,0,0,0
0,0,0,0,0,0,0,0,0,0,0,0,0,0,0,0,0,0,0,0,0,0,0
0,0,0,0,0,0,0,0,0,0,0,0,0,0,0,0,0,0,0,0,0,0,0
0,0,0,0,0,0,0,0,0,0,0,0,0,0,0,0,0,0,0,0,0,0,0
0,0,0,0,0,0,0,0,0,0,0,0,0,0,0,0,0,0,0,0,0,0,0
0,0,0,0,0,0,0,0,0,0,0,0,0,0,0,0,0,0,0,0,0,0,0
0,0,0,0,0,0,0,0,0,0,0,0,0,0,0,0,0,0,0,0,0,0,0
0,0,0,0,0,0,0,0,0,0,0,0,0,0,0,0,0,0,0,0,0,0,0
0,0,0,0,0,0,0,0,0,0,0,0,0,0,0,0,0,0,0,0,0,0,0
0,0,0,0,0,0,0,0,0,0,0,0,0,0,0,0,0,0,0,0,0,0,0
0,0,0,0,0,0,0,0,0,0,0,0,0,0,0,0,0,0,0,0,0,0,0
0,0,0,0,0,0,0,0,0,0,0,0,0,0,0,0,0,0,0,0,0,0,0
0,0,0,0,0,0,0,0,0,0,0,0,0,0,0,0,0,0,0,0,0,0,0
0,0,0,0,0,0,0,0,0,0,0,0,0,0,0,0,0,0,0,0,0,0,0
0,0,0,0,0,0,0,0,0,0,0,0,0,0,0,0,0,0,0,0,0,0,0
:endlayer
layer: 18
0,0,0,0,0,0,0,0,0,0,0,0,0,0,0,0,0,0,0,0,0,0,0
0,0,0,0,0,0,0,0,0,0,0,0,0,0,0,0,0,0,0,0,0,0,0
0,0,0,0,0,0,0,0,0,0,0,0,0,0,0,0,0,0,0,0,0,0,0
0,0,0,0,0,0,0,0,0,0,0,0,0,0,0,0,0,0,0,0,0,0,0
0,0,0,0,0,0,0,0,0,0,0,0,0,0,0,0,0,0,0,0,0,0,0
0,0,0,0,0,0,0,0,0,0,0,0,0,0,0,0,0,0,0,0,0,0,0
0,0,0,0,0,0,0,0,0,0,0,0,0,0,0,0,0,0,0,0,0,0,0
0,0,0,0,0,0,0,0,0,0,0,0,0,0,0,0,0,0,0,0,0,0,0
0,0,0,0,0,0,0,0,0,0,0,0,0,0,0,0,0,0,0,0,0,0,0
0,0,0,0,0,0,0,0,0,0,0,0,0,0,0,0,0,0,0,0,0,0,0
0,0,0,0,0,0,0,0,0,0,0,0,0,0,0,0,0,0,0,0,0,0,0
0,0,0,0,0,0,0,0,0,0,0,0,0,0,0,0,0,0,0,0,0,0,0
0,0,0,0,0,0,0,0,0,0,0,0,0,0,0,0,0,0,0,0,0,0,0
0,0,0,0,0,0,0,0,0,0,0,0,0,0,0,0,0,0,0,0,0,0,0
0,0,0,0,0,0,0,0,0,0,0,0,0,0,0,0,0,0,0,0,0,0,0
0,0,0,0,0,0,0,0,0,0,0,0,0,0,0,0,0,0,0,0,0,0,0
:endlayer

#### RULES ####
rule:
plugin=vanillaBlocks
number=1
data:
tag:
TAG=10={
TAG=8=blockName{dirt}
TAG=3=meta{0}
TAG=3=buildPass{0}
}
:endtag
:enddata
:endrule

rule:
plugin=vanillaBlocks
number=2
data:
tag:
TAG=10={
TAG=8=blockName{grass}
TAG=3=meta{0}
TAG=3=buildPass{0}
}
:endtag
:enddata
:endrule

rule:
plugin=vanillaBlocks
number=3
data:
tag:
TAG=10={
TAG=8=blockName{gravel}
TAG=3=meta{0}
TAG=3=buildPass{1}
}
:endtag
:enddata
:endrule

rule:
plugin=vanillaBlocks
number=4
data:
tag:
TAG=10={
TAG=8=blockName{log}
TAG=3=meta{4}
TAG=3=buildPass{0}
}
:endtag
:enddata
:endrule

rule:
plugin=vanillaBlocks
number=5
data:
tag:
TAG=10={
TAG=8=blockName{log}
TAG=3=meta{0}
TAG=3=buildPass{0}
}
:endtag
:enddata
:endrule

rule:
plugin=vanillaBlocks
number=6
data:
tag:
TAG=10={
TAG=8=blockName{water}
TAG=3=meta{0}
TAG=3=buildPass{1}
}
:endtag
:enddata
:endrule

rule:
plugin=vanillaBlocks
number=7
data:
tag:
TAG=10={
TAG=8=blockName{farmland}
TAG=3=meta{7}
TAG=3=buildPass{0}
}
:endtag
:enddata
:endrule

rule:
plugin=vanillaBlocks
number=8
data:
tag:
TAG=10={
TAG=8=blockName{farmland}
TAG=3=meta{0}
TAG=3=buildPass{0}
}
:endtag
:enddata
:endrule

rule:
plugin=vanillaBlocks
number=9
data:
tag:
TAG=10={
TAG=8=blockName{tallgrass}
TAG=3=meta{1}
TAG=3=buildPass{0}
}
:endtag
:enddata
:endrule

rule:
plugin=vanillaBlocks
number=10
data:
tag:
TAG=10={
TAG=8=blockName{planks}
TAG=3=meta{0}
TAG=3=buildPass{0}
}
:endtag
:enddata
:endrule

rule:
plugin=vanillaBlocks
number=11
data:
tag:
TAG=10={
TAG=8=blockName{red_flower}
TAG=3=meta{0}
TAG=3=buildPass{1}
}
:endtag
:enddata
:endrule

rule:
plugin=vanillaBlocks
number=12
data:
tag:
TAG=10={
TAG=8=blockName{oak_stairs}
TAG=3=meta{3}
TAG=3=buildPass{0}
}
:endtag
:enddata
:endrule

rule:
plugin=vanillaBlocks
number=13
data:
tag:
TAG=10={
TAG=8=blockName{melon_stem}
TAG=3=meta{7}
TAG=3=buildPass{0}
}
:endtag
:enddata
:endrule

rule:
plugin=vanillaBlocks
number=14
data:
tag:
TAG=10={
TAG=8=blockName{melon_block}
TAG=3=meta{0}
TAG=3=buildPass{0}
}
:endtag
:enddata
:endrule

rule:
plugin=vanillaBlocks
number=15
data:
tag:
TAG=10={
TAG=8=blockName{fence_gate}
TAG=3=meta{2}
TAG=3=buildPass{0}
}
:endtag
:enddata
:endrule

rule:
plugin=vanillaBlocks
number=16
data:
tag:
TAG=10={
TAG=8=blockName{fence}
TAG=3=meta{0}
TAG=3=buildPass{0}
}
:endtag
:enddata
:endrule

rule:
plugin=vanillaBlocks
number=17
data:
tag:
TAG=10={
TAG=8=blockName{pumpkin_stem}
TAG=3=meta{7}
TAG=3=buildPass{0}
}
:endtag
:enddata
:endrule

rule:
plugin=vanillaBlocks
number=18
data:
tag:
TAG=10={
TAG=8=blockName{pumpkin}
TAG=3=meta{0}
TAG=3=buildPass{0}
}
:endtag
:enddata
:endrule

rule:
plugin=vanillaBlocks
number=19
data:
tag:
TAG=10={
TAG=8=blockName{stonebrick}
TAG=3=meta{0}
TAG=3=buildPass{0}
}
:endtag
:enddata
:endrule

rule:
plugin=vanillaBlocks
number=20
data:
tag:
TAG=10={
TAG=8=blockName{oak_stairs}
TAG=3=meta{2}
TAG=3=buildPass{0}
}
:endtag
:enddata
:endrule

rule:
plugin=vanillaInventory
number=21
data:
tag:
TAG=10={
TAG=3=lootLevel{0}
TAG=10=teData{
TAG=9=Items{
TAG=10={
TAG=2=id{362}
TAG=2=Damage{0}
TAG=1=Count{1}
TAG=1=Slot{0}
}
TAG=10={
TAG=2=id{362}
TAG=2=Damage{0}
TAG=1=Count{1}
TAG=1=Slot{2}
}
TAG=10={
TAG=2=id{362}
TAG=2=Damage{0}
TAG=1=Count{1}
TAG=1=Slot{3}
}
TAG=10={
TAG=2=id{362}
TAG=2=Damage{0}
TAG=1=Count{1}
TAG=1=Slot{4}
}
TAG=10={
TAG=2=id{362}
TAG=2=Damage{0}
TAG=1=Count{1}
TAG=1=Slot{5}
}
TAG=10={
TAG=2=id{362}
TAG=2=Damage{0}
TAG=1=Count{1}
TAG=1=Slot{6}
}
TAG=10={
TAG=2=id{362}
TAG=2=Damage{0}
TAG=1=Count{1}
TAG=1=Slot{11}
}
TAG=10={
TAG=2=id{362}
TAG=2=Damage{0}
TAG=1=Count{1}
TAG=1=Slot{18}
}
TAG=10={
TAG=2=id{362}
TAG=2=Damage{0}
TAG=1=Count{1}
TAG=1=Slot{23}
}
}
TAG=8=id{Chest}
}
TAG=8=blockName{chest}
TAG=3=meta{4}
TAG=3=buildPass{0}
}
:endtag
:enddata
:endrule

rule:
plugin=vanillaInventory
number=22
data:
tag:
TAG=10={
TAG=3=lootLevel{0}
TAG=10=teData{
TAG=9=Items{
TAG=10={
TAG=2=id{362}
TAG=2=Damage{0}
TAG=1=Count{1}
TAG=1=Slot{2}
}
TAG=10={
TAG=2=id{362}
TAG=2=Damage{0}
TAG=1=Count{1}
TAG=1=Slot{5}
}
TAG=10={
TAG=2=id{362}
TAG=2=Damage{0}
TAG=1=Count{1}
TAG=1=Slot{8}
}
TAG=10={
TAG=2=id{362}
TAG=2=Damage{0}
TAG=1=Count{1}
TAG=1=Slot{10}
}
TAG=10={
TAG=2=id{362}
TAG=2=Damage{0}
TAG=1=Count{1}
TAG=1=Slot{12}
}
TAG=10={
TAG=2=id{362}
TAG=2=Damage{0}
TAG=1=Count{1}
TAG=1=Slot{23}
}
TAG=10={
TAG=2=id{362}
TAG=2=Damage{0}
TAG=1=Count{1}
TAG=1=Slot{26}
}
}
TAG=8=id{Chest}
}
TAG=8=blockName{chest}
TAG=3=meta{4}
TAG=3=buildPass{0}
}
:endtag
:enddata
:endrule

rule:
plugin=vanillaBlocks
number=23
data:
tag:
TAG=10={
TAG=8=blockName{crafting_table}
TAG=3=meta{0}
TAG=3=buildPass{0}
}
:endtag
:enddata
:endrule

rule:
plugin=vanillaBlocks
number=24
data:
tag:
TAG=10={
TAG=8=blockName{oak_stairs}
TAG=3=meta{4}
TAG=3=buildPass{0}
}
:endtag
:enddata
:endrule

rule:
plugin=vanillaDoors
number=25
data:
tag:
TAG=10={
TAG=1=sideFlag{8}
TAG=8=blockName{wooden_door}
TAG=3=meta{3}
TAG=3=buildPass{1}
}
:endtag
:enddata
:endrule

rule:
plugin=vanillaInventory
number=26
data:
tag:
TAG=10={
TAG=3=lootLevel{0}
TAG=10=teData{
TAG=9=Items{
TAG=10={
TAG=2=id{360}
TAG=2=Damage{0}
TAG=1=Count{1}
TAG=1=Slot{0}
}
TAG=10={
TAG=2=id{360}
TAG=2=Damage{0}
TAG=1=Count{1}
TAG=1=Slot{1}
}
TAG=10={
TAG=2=id{360}
TAG=2=Damage{0}
TAG=1=Count{1}
TAG=1=Slot{7}
}
TAG=10={
TAG=2=id{360}
TAG=2=Damage{0}
TAG=1=Count{1}
TAG=1=Slot{8}
}
TAG=10={
TAG=2=id{360}
TAG=2=Damage{0}
TAG=1=Count{1}
TAG=1=Slot{9}
}
TAG=10={
TAG=2=id{360}
TAG=2=Damage{0}
TAG=1=Count{1}
TAG=1=Slot{10}
}
TAG=10={
TAG=2=id{360}
TAG=2=Damage{0}
TAG=1=Count{1}
TAG=1=Slot{16}
}
TAG=10={
TAG=2=id{360}
TAG=2=Damage{0}
TAG=1=Count{1}
TAG=1=Slot{17}
}
TAG=10={
TAG=2=id{360}
TAG=2=Damage{0}
TAG=1=Count{1}
TAG=1=Slot{18}
}
TAG=10={
TAG=2=id{360}
TAG=2=Damage{0}
TAG=1=Count{1}
TAG=1=Slot{19}
}
TAG=10={
TAG=2=id{360}
TAG=2=Damage{0}
TAG=1=Count{1}
TAG=1=Slot{25}
}
TAG=10={
TAG=2=id{360}
TAG=2=Damage{0}
TAG=1=Count{1}
TAG=1=Slot{26}
}
}
TAG=8=id{Chest}
}
TAG=8=blockName{chest}
TAG=3=meta{3}
TAG=3=buildPass{0}
}
:endtag
:enddata
:endrule

rule:
plugin=awAdvancedSpawner
number=27
data:
tag:
TAG=10={
TAG=10=teData{
TAG=9=Items{
TAG=10={
TAG=2=id{263}
TAG=2=Damage{0}
TAG=1=Count{1}
TAG=1=Slot{1}
}
TAG=10={
TAG=2=id{366}
TAG=2=Damage{0}
TAG=1=Count{1}
TAG=1=Slot{2}
}
}
TAG=8=id{Furnace}
TAG=2=BurnTime{0}
TAG=3=z{82}
TAG=2=CookTime{0}
TAG=3=y{70}
TAG=3=x{329}
}
TAG=8=blockName{furnace}
TAG=3=meta{5}
TAG=3=buildPass{0}
}
:endtag
:enddata
:endrule

rule:
plugin=vanillaBlocks
number=28
data:
tag:
TAG=10={
TAG=8=blockName{stone_brick_stairs}
TAG=3=meta{3}
TAG=3=buildPass{0}
}
:endtag
:enddata
:endrule

rule:
plugin=vanillaDoors
number=29
data:
tag:
TAG=10={
TAG=1=sideFlag{8}
TAG=8=blockName{wooden_door}
TAG=3=meta{0}
TAG=3=buildPass{1}
}
:endtag
:enddata
:endrule

rule:
plugin=vanillaInventory
number=30
data:
tag:
TAG=10={
TAG=3=lootLevel{0}
TAG=10=teData{
TAG=9=Items{
}
TAG=8=id{Chest}
}
TAG=8=blockName{chest}
TAG=3=meta{3}
TAG=3=buildPass{0}
}
:endtag
:enddata
:endrule

rule:
plugin=vanillaInventory
number=31
data:
tag:
TAG=10={
TAG=3=lootLevel{0}
TAG=10=teData{
TAG=9=Items{
TAG=10={
TAG=2=id{272}
TAG=2=Damage{0}
TAG=1=Count{1}
TAG=1=Slot{18}
}
TAG=10={
TAG=2=id{352}
TAG=2=Damage{0}
TAG=1=Count{16}
TAG=1=Slot{26}
}
}
TAG=8=id{Chest}
}
TAG=8=blockName{chest}
TAG=3=meta{3}
TAG=3=buildPass{0}
}
:endtag
:enddata
:endrule

rule:
plugin=vanillaBlocks
number=32
data:
tag:
TAG=10={
TAG=8=blockName{bed}
TAG=3=meta{1}
TAG=3=buildPass{0}
}
:endtag
:enddata
:endrule

rule:
plugin=vanillaBlocks
number=33
data:
tag:
TAG=10={
TAG=8=blockName{bookshelf}
TAG=3=meta{0}
TAG=3=buildPass{0}
}
:endtag
:enddata
:endrule

rule:
plugin=vanillaBlocks
number=34
data:
tag:
TAG=10={
TAG=8=blockName{bed}
TAG=3=meta{9}
TAG=3=buildPass{0}
}
:endtag
:enddata
:endrule

rule:
plugin=vanillaBlocks
number=35
data:
tag:
TAG=10={
TAG=8=blockName{torch}
TAG=3=meta{5}
TAG=3=buildPass{1}
}
:endtag
:enddata
:endrule

rule:
plugin=vanillaBlocks
number=36
data:
tag:
TAG=10={
TAG=8=blockName{wooden_pressure_plate}
TAG=3=meta{0}
TAG=3=buildPass{0}
}
:endtag
:enddata
:endrule

rule:
plugin=vanillaDoors
number=37
data:
tag:
TAG=10={
TAG=1=sideFlag{0}
TAG=8=blockName{wooden_door}
TAG=3=meta{8}
TAG=3=buildPass{1}
}
:endtag
:enddata
:endrule

rule:
plugin=vanillaDoors
number=38
data:
tag:
TAG=10={
TAG=1=sideFlag{0}
TAG=8=blockName{wooden_door}
TAG=3=meta{8}
TAG=3=buildPass{1}
}
:endtag
:enddata
:endrule

rule:
plugin=vanillaDoors
number=39
data:
tag:
TAG=10={
TAG=1=sideFlag{0}
TAG=8=blockName{wooden_door}
TAG=3=meta{8}
TAG=3=buildPass{1}
}
:endtag
:enddata
:endrule

rule:
plugin=vanillaBlocks
number=40
data:
tag:
TAG=10={
TAG=8=blockName{wooden_slab}
TAG=3=meta{8}
TAG=3=buildPass{0}
}
:endtag
:enddata
:endrule

rule:
plugin=vanillaBlocks
number=41
data:
tag:
TAG=10={
TAG=8=blockName{torch}
TAG=3=meta{1}
TAG=3=buildPass{1}
}
:endtag
:enddata
:endrule

rule:
plugin=vanillaBlocks
number=42
data:
tag:
TAG=10={
TAG=8=blockName{torch}
TAG=3=meta{4}
TAG=3=buildPass{1}
}
:endtag
:enddata
:endrule

rule:
plugin=vanillaBlocks
number=43
data:
tag:
TAG=10={
TAG=8=blockName{torch}
TAG=3=meta{3}
TAG=3=buildPass{1}
}
:endtag
:enddata
:endrule

rule:
plugin=vanillaBlocks
number=44
data:
tag:
TAG=10={
TAG=8=blockName{wooden_slab}
TAG=3=meta{0}
TAG=3=buildPass{0}
}
:endtag
:enddata
:endrule

rule:
plugin=vanillaBlocks
number=45
data:
tag:
TAG=10={
TAG=8=blockName{torch}
TAG=3=meta{2}
TAG=3=buildPass{1}
}
:endtag
:enddata
:endrule

rule:
plugin=vanillaInventory
number=46
data:
tag:
TAG=10={
TAG=3=lootLevel{0}
TAG=10=teData{
TAG=9=Items{
}
TAG=8=id{Chest}
}
TAG=8=blockName{chest}
TAG=3=meta{3}
TAG=3=buildPass{0}
}
:endtag
:enddata
:endrule

rule:
plugin=vanillaBlocks
number=47
data:
tag:
TAG=10={
TAG=8=blockName{stone_slab}
TAG=3=meta{2}
TAG=3=buildPass{0}
}
:endtag
:enddata
:endrule

rule:
plugin=vanillaBlocks
number=48
data:
tag:
TAG=10={
TAG=8=blockName{oak_stairs}
TAG=3=meta{1}
TAG=3=buildPass{0}
}
:endtag
:enddata
:endrule

rule:
plugin=vanillaBlocks
number=49
data:
tag:
TAG=10={
TAG=8=blockName{stone_brick_stairs}
TAG=3=meta{0}
TAG=3=buildPass{0}
}
:endtag
:enddata
:endrule

rule:
plugin=vanillaBlocks
number=50
data:
tag:
TAG=10={
TAG=8=blockName{lit_pumpkin}
TAG=3=meta{3}
TAG=3=buildPass{0}
}
:endtag
:enddata
:endrule

rule:
plugin=vanillaBlocks
number=51
data:
tag:
TAG=10={
TAG=8=blockName{oak_stairs}
TAG=3=meta{0}
TAG=3=buildPass{0}
}
:endtag
:enddata
:endrule

rule:
plugin=vanillaBlocks
number=52
data:
tag:
TAG=10={
TAG=8=blockName{glass_pane}
TAG=3=meta{0}
TAG=3=buildPass{0}
}
:endtag
:enddata
:endrule

rule:
plugin=vanillaBlocks
number=53
data:
tag:
TAG=10={
TAG=8=blockName{stone_slab}
TAG=3=meta{10}
TAG=3=buildPass{0}
}
:endtag
:enddata
:endrule

#### ENTITIES ####
