# Ancient Warfare Structure Template File
# auto-generated structure file. created on: 4/14/2014 at: 17:30:22
# Lines beginning with # denote comments

header:
version=2.0
name=CivFarmChickenGentryMOH
size=21,22,39
offset=8,2,37
:endheader

#### VALIDATION ####
validation:
type=ground
survival=false
worldGenEnabled=true
unique=false
preserveBlocks=false
selectionWeight=10
clusterValue=10
minDuplicateDistance=40
dimensionWhiteList=false
dimensionList=
biomeWhiteList=true
biomeList=highlands.meadow,bop.meadow,ebxl.meadow,field,orchard
leveling=9
fill=5
border=5
validTargetBlocks=clay,lapis_ore,sand,grass,lit_redstone_ore,stone,gravel,iron_ore,diamond_ore,stained_hardened_clay,dirt,coal_ore,gold_ore,redstone_ore
data:
:enddata
:endvalidation

#### LAYERS ####
layer: 0
1,1,1,1,1,1,1,1,1,1,1,1,1,1,1,1,1,1,1,1,1
1,1,1,1,1,1,1,1,1,1,1,1,1,1,1,1,1,1,1,1,1
1,1,1,1,1,1,1,1,1,1,1,1,1,1,1,1,1,1,1,1,1
1,1,1,1,1,1,1,1,1,1,1,1,1,1,1,1,1,1,1,1,1
1,1,1,1,1,1,1,1,1,1,1,1,2,1,1,1,1,1,1,1,1
1,1,1,1,1,1,1,1,1,1,1,1,1,1,1,1,1,1,1,1,1
1,1,1,1,1,1,1,1,1,1,1,1,1,1,1,1,1,1,1,1,1
1,1,1,1,1,1,1,1,1,1,1,1,1,1,1,1,1,1,1,1,1
1,1,1,1,1,1,1,1,1,1,1,1,1,1,1,1,1,1,1,1,1
1,1,1,1,1,1,1,1,1,1,1,1,1,1,1,1,1,1,1,1,1
1,1,1,1,1,1,1,1,1,1,1,1,1,1,1,1,1,1,1,1,1
1,1,1,1,1,1,1,1,1,1,1,1,1,1,1,1,1,1,1,1,1
1,1,1,1,1,1,1,1,1,1,1,1,1,1,1,1,1,1,1,1,1
1,1,1,1,1,1,1,1,1,1,1,1,1,1,1,1,1,1,1,1,1
1,1,1,1,1,1,1,1,1,1,1,1,1,1,1,1,1,1,1,1,1
1,1,1,1,1,1,1,1,1,1,1,1,1,1,1,1,1,1,1,1,1
1,1,1,1,1,1,1,1,1,1,1,1,1,1,1,1,1,1,1,1,1
1,1,1,1,1,1,1,1,1,1,1,1,1,1,1,1,1,1,1,1,1
1,1,1,1,1,1,1,1,1,1,1,1,1,1,1,1,2,1,1,1,1
1,1,1,1,1,1,1,1,1,1,1,1,1,1,1,1,1,1,1,1,1
1,1,1,1,1,1,1,1,1,1,1,1,1,1,1,1,1,1,1,1,1
1,1,1,1,1,1,1,1,1,1,1,1,1,1,1,1,1,1,1,1,1
1,1,1,1,1,1,1,1,1,1,1,1,1,1,1,1,1,1,1,1,1
1,1,1,1,1,1,1,1,1,1,1,1,1,1,1,1,1,1,1,1,1
1,1,1,1,3,3,3,3,3,3,3,3,3,3,3,3,3,1,1,1,1
1,1,1,1,1,4,4,4,4,4,4,4,4,4,4,4,3,1,1,1,1
1,1,1,1,1,4,4,4,4,4,4,4,4,4,4,4,3,1,1,1,1
1,1,1,1,1,4,4,4,4,4,4,4,4,4,4,4,3,1,1,1,1
1,1,1,1,1,4,4,4,4,4,4,4,4,4,4,4,3,1,1,1,1
1,1,1,1,1,4,4,4,4,4,4,4,4,4,4,4,3,1,1,1,1
1,1,1,1,1,4,4,4,4,4,4,4,4,4,4,4,3,1,1,1,1
1,1,1,1,1,4,4,4,4,4,4,4,4,4,4,4,3,1,1,1,1
1,1,1,1,1,4,4,4,4,4,4,4,4,4,4,4,3,1,1,1,1
1,1,1,1,1,4,4,4,4,4,4,4,4,4,4,4,3,1,1,1,1
1,1,1,1,3,3,3,3,3,3,3,3,3,3,3,3,3,1,1,1,1
1,1,1,1,1,1,1,1,1,1,1,1,1,1,1,1,1,1,1,1,1
1,1,1,1,1,1,1,1,1,1,1,1,1,1,1,1,1,1,1,1,1
1,1,1,1,1,1,1,1,1,1,1,1,1,1,1,1,1,1,1,1,1
1,1,1,1,1,1,1,1,1,1,1,1,1,1,1,1,1,1,1,1,1
:endlayer
layer: 1
5,5,5,5,5,5,5,5,5,5,5,5,5,5,5,5,5,5,5,5,5
5,5,5,5,5,5,5,5,5,5,5,5,5,5,5,5,5,5,5,5,5
5,5,4,4,4,4,4,4,4,4,4,4,4,4,4,4,4,4,4,5,5
5,5,4,1,5,5,5,5,5,5,1,5,5,5,5,5,5,1,4,5,5
5,5,4,5,2,5,4,5,2,5,4,5,2,5,4,5,2,5,4,5,5
5,5,4,5,2,5,4,5,2,5,4,5,2,5,4,5,2,5,4,5,5
5,5,4,5,2,5,4,5,2,5,4,5,2,5,4,5,2,5,4,5,5
5,5,4,5,2,5,4,5,2,5,4,5,2,5,4,5,2,5,4,5,5
5,5,4,5,2,5,4,5,2,5,4,5,2,5,4,5,2,5,4,5,5
5,5,4,5,2,5,4,5,2,5,4,5,2,5,4,5,2,5,4,5,5
5,5,4,5,2,5,4,5,2,5,4,5,2,5,4,5,2,5,4,5,5
5,5,4,5,2,5,4,5,2,5,4,5,2,5,4,5,2,5,4,5,5
5,5,4,5,2,5,4,5,2,5,4,5,2,5,4,5,2,5,4,5,5
5,5,4,5,2,5,4,5,2,5,4,5,2,5,4,5,2,5,4,5,5
5,5,4,5,2,5,4,5,2,5,4,5,2,5,4,5,2,5,4,5,5
5,5,4,5,2,5,4,5,2,5,4,5,2,5,4,5,2,5,4,5,5
5,5,4,5,2,5,4,5,2,5,4,5,2,5,4,5,2,5,4,5,5
5,5,4,5,2,5,4,5,2,5,4,5,2,5,4,5,2,5,4,5,5
5,5,4,5,2,5,4,5,2,5,4,5,2,5,4,5,2,5,4,5,5
5,5,4,1,5,5,4,5,5,5,4,5,5,5,4,5,5,1,4,5,5
5,5,4,4,4,4,4,4,4,4,4,4,4,4,4,4,4,4,4,5,5
5,5,4,5,5,5,5,5,5,5,5,5,5,5,5,5,5,5,4,5,5
5,5,4,5,5,8,8,8,8,8,5,5,5,8,9,8,5,5,4,5,5
5,5,4,5,5,5,5,5,5,5,5,5,5,5,5,5,5,5,4,5,5
5,5,4,5,3,3,3,3,3,3,3,3,3,3,3,3,3,5,4,5,5
5,5,6,5,3,4,4,4,4,4,4,4,4,4,4,4,3,5,6,5,5
5,5,6,5,3,4,4,4,4,4,4,4,4,4,4,4,3,5,6,5,5
5,5,6,5,3,4,4,4,4,4,4,4,4,4,4,4,3,5,6,5,5
5,5,6,5,3,4,4,4,4,4,4,4,4,4,4,4,3,1,6,5,5
5,5,6,5,3,4,4,4,4,4,4,4,4,4,4,4,7,1,6,5,5
5,5,6,5,3,4,4,4,4,4,4,4,4,4,4,4,3,1,6,5,5
5,5,6,5,3,4,4,4,4,4,4,4,4,4,4,4,3,5,6,5,5
5,5,6,5,3,4,4,4,4,4,4,4,4,4,4,4,3,5,6,5,5
5,5,6,5,3,4,4,4,4,4,4,4,4,4,4,4,3,5,6,5,5
5,5,6,5,3,3,3,3,3,3,3,3,3,3,3,3,3,5,6,5,5
5,5,6,6,6,6,6,6,6,6,6,6,6,6,6,6,6,6,6,5,5
5,5,6,6,6,6,6,6,6,6,6,6,6,6,6,6,6,6,6,5,5
5,5,5,5,5,5,5,5,5,6,6,6,5,5,5,5,5,5,5,5,5
5,5,5,5,5,5,5,5,5,6,6,6,5,5,5,5,5,5,5,5,5
:endlayer
layer: 2
0,0,0,0,0,10,10,10,0,0,10,0,10,0,10,10,10,10,0,10,10
0,11,11,11,11,11,11,11,11,11,11,11,11,11,11,11,11,11,11,11,10
10,11,0,0,0,0,0,0,0,0,0,0,0,0,0,0,0,0,0,11,0
10,11,0,4,11,11,11,11,11,11,24,11,11,11,11,11,11,4,0,11,10
10,11,0,11,0,11,0,11,0,11,25,11,0,11,0,11,0,11,0,11,0
0,11,0,11,0,11,0,11,0,11,0,11,0,11,0,11,0,11,0,11,10
10,11,0,11,0,11,0,11,0,11,0,11,0,11,0,11,0,11,0,11,10
0,11,0,11,0,11,0,11,0,11,0,11,0,11,0,11,0,11,0,11,0
10,11,0,11,0,11,0,11,0,11,0,11,0,11,0,11,0,11,0,11,10
10,11,0,11,0,11,0,11,0,11,0,11,0,11,0,11,0,11,0,11,10
10,11,0,11,0,11,0,11,0,11,0,11,0,11,0,11,0,11,0,11,10
0,11,0,11,0,11,0,11,0,11,0,11,0,11,0,11,0,11,0,11,10
10,11,0,11,0,11,0,11,0,11,0,11,0,11,0,11,0,11,0,11,0
10,11,0,11,0,11,0,11,0,11,0,11,0,11,0,11,0,11,0,11,0
10,11,0,11,0,11,0,11,0,11,0,11,0,11,0,11,0,11,0,11,0
0,11,0,11,0,11,0,11,0,11,0,11,0,11,0,11,0,11,0,11,10
10,11,0,11,0,11,0,11,0,11,0,11,0,11,0,11,0,11,0,11,10
0,11,0,11,0,11,0,11,0,11,0,11,0,11,0,11,0,11,0,11,10
0,11,0,11,0,11,0,11,0,11,0,11,0,11,0,11,0,11,0,11,0
10,11,0,4,12,11,0,11,12,11,0,11,12,11,0,11,12,4,0,11,0
0,11,0,0,0,0,0,0,0,0,0,0,0,0,0,0,0,0,0,11,0
10,11,0,0,11,11,11,11,11,11,12,11,11,11,11,11,11,0,0,11,10
0,11,0,0,11,28,28,28,28,28,0,0,0,15,15,15,11,0,0,11,10
0,11,0,0,11,0,0,0,0,0,0,0,0,0,0,0,11,0,0,11,10
0,11,12,11,13,3,3,3,3,3,3,3,21,3,3,3,13,11,12,11,10
0,0,0,0,3,37,35,0,32,29,3,0,0,0,0,16,3,0,0,0,0
10,10,0,0,3,0,0,0,0,0,26,0,0,0,0,17,3,0,0,0,0
10,10,0,0,3,38,0,0,0,0,3,23,0,0,0,3,3,0,0,10,0
10,10,0,0,3,0,0,0,0,0,3,24,0,0,0,18,3,3,0,0,0
10,10,0,0,13,39,36,0,33,30,3,24,0,0,0,18,14,3,0,10,10
0,0,0,0,3,3,3,3,3,3,3,24,0,0,0,18,3,3,0,10,10
0,0,0,0,3,34,34,34,0,31,0,0,0,0,0,3,3,0,0,10,0
0,0,0,0,3,11,11,11,0,0,0,0,0,0,0,19,3,0,0,0,0
0,0,0,0,3,23,23,23,0,0,0,0,22,20,0,16,3,0,0,10,0
0,10,0,0,13,3,3,3,3,13,27,13,3,3,3,3,13,0,0,10,0
10,0,0,0,0,0,0,0,0,0,0,0,0,0,0,0,0,0,0,10,10
10,10,0,0,0,0,0,0,0,0,0,0,0,0,0,0,0,0,0,10,0
10,11,10,10,10,10,0,0,11,0,0,0,11,0,0,10,0,10,10,11,0
10,10,0,10,10,10,10,0,0,0,0,0,0,0,0,10,10,0,0,10,0
:endlayer
layer: 3
0,0,0,0,0,0,0,0,0,0,0,0,0,0,0,0,0,0,0,0,0
0,40,0,0,0,0,0,0,0,0,0,0,0,0,0,0,0,0,0,40,0
0,0,0,0,0,0,0,0,0,0,0,0,0,0,0,0,0,0,0,0,0
0,0,0,4,11,11,11,11,11,11,24,11,11,11,11,11,11,4,0,0,0
0,0,0,11,0,11,0,11,0,11,25,11,0,11,0,11,0,11,0,0,0
0,0,0,11,0,11,0,11,0,11,0,11,0,11,0,11,0,11,0,0,0
0,0,0,11,0,11,0,11,0,11,0,11,0,11,0,11,0,11,0,0,0
0,0,0,11,0,11,0,11,0,11,0,11,0,11,0,11,0,11,0,0,0
0,0,0,11,0,11,0,11,0,11,0,11,0,11,0,11,0,11,0,0,0
0,0,0,11,0,11,0,11,0,11,0,11,0,11,0,11,0,11,0,0,0
0,0,0,11,0,11,0,11,0,11,0,11,0,11,0,11,0,11,0,0,0
0,0,0,11,0,11,0,11,0,11,0,11,0,11,0,11,0,11,0,0,0
0,0,0,11,0,11,0,11,0,11,0,11,0,11,0,11,0,11,0,0,0
0,0,0,11,0,11,0,11,0,11,0,11,0,11,0,11,0,11,0,0,0
0,0,0,11,0,11,0,11,0,11,0,11,0,11,0,11,0,11,0,0,0
0,0,0,11,0,11,0,11,0,11,0,11,0,11,0,11,0,11,0,0,0
0,0,0,11,0,11,0,11,0,11,0,11,0,11,0,11,0,11,0,0,0
0,0,0,11,0,11,0,11,0,11,0,11,0,11,0,11,0,11,0,0,0
0,0,0,11,0,11,0,11,0,11,0,11,0,11,0,11,0,11,0,0,0
0,0,0,4,0,11,0,11,0,11,0,11,0,11,0,11,0,4,0,0,0
0,0,0,0,0,0,0,0,0,0,0,0,0,0,0,0,0,0,0,0,0
0,0,0,0,40,0,0,40,0,40,0,40,0,40,0,0,40,0,0,0,0
0,0,0,0,0,0,0,0,0,0,0,0,0,0,0,0,0,0,0,0,0
0,0,0,0,0,0,0,0,0,0,0,0,0,0,0,0,0,0,0,0,0
0,40,0,40,13,3,3,3,3,3,3,3,44,3,3,3,13,40,0,40,0
0,0,0,0,3,48,48,48,48,48,3,0,0,0,0,0,3,0,0,0,0
0,0,0,0,3,0,0,0,0,0,46,0,0,0,0,0,3,0,0,0,0
0,0,0,0,45,0,0,0,0,0,3,0,0,0,0,3,3,0,0,0,0
0,0,0,0,3,0,0,0,0,0,3,23,0,0,0,0,41,3,0,0,0
0,0,0,0,13,48,48,48,48,48,3,24,0,0,0,0,42,3,0,0,0
0,0,0,0,3,3,3,3,3,3,3,24,0,0,0,0,43,3,0,0,0
0,0,0,0,3,0,0,0,0,0,0,0,0,0,0,3,3,0,0,0,0
0,0,0,0,45,50,49,49,0,0,0,0,0,0,0,0,3,0,0,0,0
0,0,0,0,3,0,0,0,0,0,0,0,0,0,0,0,3,0,0,0,0
0,0,0,0,13,3,3,3,45,13,47,13,45,3,3,3,13,0,0,0,0
0,0,0,0,0,0,0,0,0,0,0,0,0,0,0,0,0,0,0,0,0
0,0,0,0,0,0,0,0,0,0,0,0,0,0,0,0,0,0,0,0,0
0,40,0,0,0,0,0,0,40,0,0,0,40,0,0,0,0,0,0,40,0
0,0,0,0,0,0,0,0,0,0,0,0,0,0,0,0,0,0,0,0,0
:endlayer
layer: 4
0,0,0,0,0,0,0,0,0,0,0,0,0,0,0,0,0,0,0,0,0
0,0,0,0,0,0,0,0,0,0,0,0,0,0,0,0,0,0,0,0,0
0,0,0,52,0,0,0,0,0,0,0,0,0,0,0,0,0,52,0,0,0
0,0,54,4,11,11,11,11,11,11,24,11,11,11,11,11,11,4,51,0,0
0,0,0,11,0,0,0,0,0,0,25,0,0,0,0,0,0,11,0,0,0
0,0,0,11,0,0,0,0,0,0,0,0,0,0,0,0,0,11,0,0,0
0,0,0,11,0,0,0,0,0,0,0,0,0,0,0,0,0,11,0,0,0
0,0,0,11,0,0,0,0,0,0,0,0,0,0,0,0,0,11,0,0,0
0,0,0,11,0,0,0,0,0,0,0,0,0,0,0,0,0,11,0,0,0
0,0,0,11,0,0,0,0,0,0,0,0,0,0,0,0,0,11,0,0,0
0,0,0,11,0,0,0,0,0,0,0,0,0,0,0,0,0,11,0,0,0
0,0,0,11,0,40,0,40,0,40,0,40,0,40,0,40,0,11,0,0,0
0,0,0,11,0,0,0,0,0,0,0,0,0,0,0,0,0,11,0,0,0
0,0,0,11,0,0,0,0,0,0,0,0,0,0,0,0,0,11,0,0,0
0,0,0,11,0,0,0,0,0,0,0,0,0,0,0,0,0,11,0,0,0
0,0,0,11,0,0,0,0,0,0,0,0,0,0,0,0,0,11,0,0,0
0,0,0,11,0,0,0,0,0,0,0,0,0,0,0,0,0,11,0,0,0
0,0,0,11,0,0,0,0,0,0,0,0,0,0,0,0,0,11,0,0,0
0,0,0,11,0,0,0,0,0,0,0,0,0,0,0,0,0,11,0,0,0
0,0,54,4,51,40,0,40,0,40,0,40,0,40,0,40,54,4,51,0,0
0,0,0,53,0,0,0,0,0,0,0,0,0,0,0,0,0,53,0,0,0
0,0,0,0,0,0,0,0,0,0,0,0,0,0,0,0,0,0,0,0,0
0,0,0,0,0,0,0,0,0,0,0,0,0,0,0,0,0,0,0,0,0
0,0,0,48,0,0,0,0,0,0,0,0,0,0,0,0,0,48,0,0,0
0,0,0,48,13,3,3,3,3,3,3,3,3,3,3,3,13,48,0,0,0
0,0,0,48,3,61,59,0,57,55,3,51,0,0,0,53,3,48,0,0,0
0,0,0,48,3,0,0,0,0,0,3,0,0,0,0,0,3,48,0,0,0
0,0,0,48,3,51,0,0,0,54,3,0,0,0,0,3,3,48,0,0,0
0,0,0,48,3,0,0,0,0,0,3,0,0,0,0,0,53,3,0,0,0
0,0,0,48,13,62,60,0,58,56,3,23,0,0,0,0,0,3,0,0,0
0,0,0,48,3,3,3,3,3,3,3,24,0,0,0,0,52,3,0,0,0
0,0,0,48,3,0,0,0,0,0,53,0,0,0,0,3,3,48,0,0,0
0,0,0,48,3,51,0,0,0,0,0,0,0,0,0,0,3,48,0,0,0
0,0,0,48,3,0,0,0,0,0,0,0,0,0,0,52,3,48,0,0,0
0,0,0,48,13,3,3,3,3,13,3,13,3,3,3,3,13,48,0,0,0
0,0,0,48,0,0,0,0,0,53,48,53,0,0,0,0,0,48,0,0,0
0,0,0,0,0,0,0,0,0,0,0,0,0,0,0,0,0,0,0,0,0
0,0,0,0,0,0,0,0,0,0,0,0,0,0,0,0,0,0,0,0,0
0,0,0,0,0,0,0,0,0,0,0,0,0,0,0,0,0,0,0,0,0
:endlayer
layer: 5
0,0,0,0,0,0,0,0,0,0,0,0,0,0,0,0,0,0,0,0,0
0,0,0,0,0,0,0,0,0,0,0,0,0,0,0,0,0,0,0,0,0
0,0,0,0,0,0,0,0,0,0,0,0,0,0,0,0,0,0,0,0,0
0,0,0,11,0,0,0,0,0,0,24,0,0,0,0,0,0,11,0,0,0
0,0,0,0,0,0,0,0,0,0,25,0,0,0,0,0,0,0,0,0,0
0,0,0,0,0,0,0,0,0,0,0,0,0,0,0,0,0,0,0,0,0
0,0,0,0,0,0,0,0,0,0,0,0,0,0,0,0,0,0,0,0,0
0,0,0,0,0,0,0,0,0,0,0,0,0,0,0,0,0,0,0,0,0
0,0,0,0,0,0,0,0,0,0,0,0,0,0,0,0,0,0,0,0,0
0,0,0,0,0,0,0,0,0,0,0,0,0,0,0,0,0,0,0,0,0
0,0,0,0,0,0,0,0,0,0,0,0,0,0,0,0,0,0,0,0,0
0,0,0,11,0,0,0,0,0,0,0,0,0,0,0,0,0,11,0,0,0
0,0,0,0,0,0,0,0,0,0,0,0,0,0,0,0,0,0,0,0,0
0,0,0,0,0,0,0,0,0,0,0,0,0,0,0,0,0,0,0,0,0
0,0,0,0,0,0,0,0,0,0,0,0,0,0,0,0,0,0,0,0,0
0,0,0,0,0,0,0,0,0,0,0,0,0,0,0,0,0,0,0,0,0
0,0,0,0,0,0,0,0,0,0,0,0,0,0,0,0,0,0,0,0,0
0,0,0,0,0,0,0,0,0,0,0,0,0,0,0,0,0,0,0,0,0
0,0,0,0,0,0,0,0,0,0,0,0,0,0,0,0,0,0,0,0,0
0,0,0,11,0,0,0,0,0,0,0,0,0,0,0,0,0,11,0,0,0
0,0,0,0,0,0,0,0,0,0,0,0,0,0,0,0,0,0,0,0,0
0,0,0,0,0,0,0,0,0,0,0,0,0,0,0,0,0,0,0,0,0
0,0,0,0,0,0,0,0,0,0,0,0,0,0,0,0,0,0,0,0,0
0,0,0,0,67,0,0,0,0,0,0,0,0,0,0,0,63,0,0,0,0
0,0,0,0,67,64,64,64,64,64,64,64,64,64,64,64,63,0,0,0,0
0,0,0,0,67,0,0,0,0,0,24,0,0,0,0,0,63,0,0,0,0
0,0,0,0,67,0,0,0,0,0,24,0,0,0,0,0,63,0,0,0,0
0,0,0,0,67,0,0,0,0,0,24,0,0,0,0,65,3,0,0,0,0
0,0,0,0,67,0,0,0,0,0,24,0,0,0,0,65,0,3,51,0,0
0,0,0,0,67,0,0,0,0,0,24,0,0,0,0,65,0,3,0,0,0
0,0,0,0,67,24,24,24,24,24,24,23,0,0,0,65,0,3,51,0,0
0,0,0,0,67,0,0,0,0,0,66,24,0,0,0,65,3,0,0,0,0
0,0,0,0,67,0,0,0,0,0,66,24,0,0,0,0,63,0,0,0,0
0,0,0,0,67,0,0,0,0,0,66,24,0,0,0,0,63,0,0,0,0
0,0,0,0,67,64,64,64,64,13,64,13,64,64,64,64,63,0,0,0,0
0,0,0,0,67,0,0,0,0,0,0,0,0,0,0,0,63,0,0,0,0
0,0,0,0,0,0,0,0,0,0,0,0,0,0,0,0,0,0,0,0,0
0,0,0,0,0,0,0,0,0,0,0,0,0,0,0,0,0,0,0,0,0
0,0,0,0,0,0,0,0,0,0,0,0,0,0,0,0,0,0,0,0,0
:endlayer
layer: 6
0,0,0,0,0,0,0,0,0,0,0,0,0,0,0,0,0,0,0,0,0
0,0,0,0,0,0,0,0,0,0,0,0,0,0,0,0,0,0,0,0,0
0,0,0,0,0,0,0,0,0,0,0,0,0,0,0,0,0,0,0,0,0
0,0,0,24,23,23,23,23,23,24,24,24,23,23,23,23,23,24,0,0,0
0,0,0,67,24,0,0,0,0,0,25,0,0,0,0,0,24,63,0,0,0
0,0,0,67,0,0,0,0,0,0,0,0,0,0,0,0,0,63,0,0,0
0,0,0,67,0,0,0,0,0,0,0,0,0,0,0,0,0,63,0,0,0
0,0,0,67,0,0,0,0,0,0,0,0,0,0,0,0,0,63,0,0,0
0,0,0,67,0,0,0,0,0,0,0,0,0,0,0,0,0,63,0,0,0
0,0,0,67,0,0,0,0,0,0,0,0,0,0,0,0,0,63,0,0,0
0,0,0,67,0,0,0,0,0,0,0,0,0,0,0,0,0,63,0,0,0
0,0,0,67,0,0,0,0,0,0,0,0,0,0,0,0,0,63,0,0,0
0,0,0,67,0,0,0,0,0,0,0,0,0,0,0,0,0,63,0,0,0
0,0,0,67,0,0,0,0,0,0,0,0,0,0,0,0,0,63,0,0,0
0,0,0,67,0,0,0,0,0,0,0,0,0,0,0,0,0,63,0,0,0
0,0,0,67,0,0,0,0,0,0,0,0,0,0,0,0,0,63,0,0,0
0,0,0,67,0,0,0,0,0,0,0,0,0,0,0,0,0,63,0,0,0
0,0,0,67,0,0,0,0,0,0,0,0,0,0,0,0,0,63,0,0,0
0,0,0,67,24,0,0,0,0,0,0,0,0,0,0,0,24,63,0,0,0
0,0,0,24,34,34,34,34,34,34,34,34,34,34,34,34,34,24,0,0,0
0,0,0,0,0,0,0,0,0,0,0,0,0,0,0,0,0,0,0,0,0
0,0,0,0,0,0,0,0,0,0,0,0,0,0,0,0,0,0,0,0,0
0,0,0,0,0,0,0,0,0,0,0,0,0,0,0,0,0,0,0,0,0
0,0,0,0,0,67,0,0,0,0,0,0,0,0,0,63,0,0,0,0,0
0,0,0,0,0,67,71,71,71,71,71,71,71,71,71,63,0,0,0,0,0
0,0,0,0,0,67,24,24,24,24,24,24,24,24,24,63,0,0,0,0,0
0,0,0,0,0,67,24,24,24,24,24,24,24,24,24,24,0,0,0,0,0
0,0,0,0,0,67,24,24,24,24,24,0,24,24,24,24,0,0,0,0,0
0,0,0,0,0,67,24,24,24,24,24,0,24,24,24,24,69,0,0,0,0
0,0,0,0,0,67,24,24,24,24,24,0,24,24,24,24,3,68,0,0,0
0,0,0,0,0,67,24,24,24,24,24,0,24,24,24,24,70,0,0,0,0
0,0,0,0,0,67,24,24,24,24,24,23,24,24,24,24,0,0,0,0,0
0,0,0,0,0,67,24,24,24,24,24,24,24,24,24,24,0,0,0,0,0
0,0,0,0,0,67,24,24,24,24,24,24,24,24,24,63,0,0,0,0,0
0,0,0,0,0,67,71,71,71,71,71,71,71,71,71,63,0,0,0,0,0
0,0,0,0,0,67,0,0,0,0,0,0,0,0,0,63,0,0,0,0,0
0,0,0,0,0,0,0,0,0,0,0,0,0,0,0,0,0,0,0,0,0
0,0,0,0,0,0,0,0,0,0,0,0,0,0,0,0,0,0,0,0,0
0,0,0,0,0,0,0,0,0,0,0,0,0,0,0,0,0,0,0,0,0
:endlayer
layer: 7
0,0,0,0,0,0,0,0,0,0,0,0,0,0,0,0,0,0,0,0,0
0,0,0,0,0,0,0,0,0,0,0,0,0,0,0,0,0,0,0,0,0
0,0,0,0,0,0,0,0,0,0,0,0,0,0,0,0,0,0,0,0,0
0,0,0,40,0,0,0,0,0,24,24,24,0,0,0,0,0,40,0,0,0
0,0,0,0,67,23,23,23,23,24,25,24,23,23,23,23,63,0,0,0,0
0,0,0,0,67,24,0,0,0,0,0,0,0,0,0,24,63,0,0,0,0
0,0,0,0,67,0,0,0,0,0,0,0,0,0,0,0,63,0,0,0,0
0,0,0,0,67,0,0,0,0,0,0,0,0,0,0,0,63,0,0,0,0
0,0,0,0,67,0,0,0,0,0,0,0,0,0,0,0,63,0,0,0,0
0,0,0,0,67,0,0,0,0,0,0,0,0,0,0,0,63,0,0,0,0
0,0,0,0,67,0,0,0,0,0,0,0,0,0,0,0,63,0,0,0,0
0,0,0,0,67,0,0,0,0,0,0,0,0,0,0,0,63,0,0,0,0
0,0,0,0,67,0,0,0,0,0,0,0,0,0,0,0,63,0,0,0,0
0,0,0,0,67,0,0,0,0,0,0,0,0,0,0,0,63,0,0,0,0
0,0,0,0,67,0,0,0,0,0,0,0,0,0,0,0,63,0,0,0,0
0,0,0,0,67,0,0,0,0,0,0,0,0,0,0,0,63,0,0,0,0
0,0,0,0,67,0,0,0,0,0,0,0,0,0,0,0,63,0,0,0,0
0,0,0,0,67,24,0,0,0,0,0,0,0,0,0,24,63,0,0,0,0
0,0,0,0,67,34,34,34,34,34,34,34,34,34,34,34,63,0,0,0,0
0,0,0,40,0,0,0,0,0,0,0,0,0,0,0,0,0,40,0,0,0
0,0,0,0,0,0,0,0,0,0,0,0,0,0,0,0,0,0,0,0,0
0,0,0,0,0,0,0,0,0,0,0,0,0,0,0,0,0,0,0,0,0
0,0,0,0,0,0,0,0,0,0,0,0,0,0,0,0,0,0,0,0,0
0,0,0,0,0,0,67,0,0,0,0,0,0,0,63,0,0,0,0,0,0
0,0,0,0,0,0,67,24,24,24,24,24,24,24,63,0,0,0,0,0,0
0,0,0,0,0,0,67,24,0,0,0,0,0,24,63,0,0,0,0,0,0
0,0,0,0,0,0,67,24,0,0,0,0,0,24,24,24,0,0,0,0,0
0,0,0,0,0,0,67,24,74,0,0,0,0,0,72,24,0,0,0,0,0
0,0,0,0,0,0,67,24,78,77,0,0,0,76,73,24,0,0,0,0,0
0,0,0,0,0,0,67,24,78,77,0,0,0,0,74,24,3,0,0,0,0
0,0,0,0,0,0,67,24,74,0,0,0,0,76,73,24,0,0,0,0,0
0,0,0,0,0,0,67,24,0,0,0,0,0,0,75,24,0,0,0,0,0
0,0,0,0,0,0,67,24,0,0,0,0,0,24,24,24,0,0,0,0,0
0,0,0,0,0,0,67,24,0,0,0,0,0,24,63,0,0,0,0,0,0
0,0,0,0,0,0,67,24,24,24,24,24,24,24,63,0,0,0,0,0,0
0,0,0,0,0,0,67,0,0,0,0,0,0,0,63,0,0,0,0,0,0
0,0,0,0,0,0,0,0,0,0,0,0,0,0,0,0,0,0,0,0,0
0,0,0,0,0,0,0,0,0,0,0,0,0,0,0,0,0,0,0,0,0
0,0,0,0,0,0,0,0,0,0,0,0,0,0,0,0,0,0,0,0,0
:endlayer
layer: 8
0,0,0,0,0,0,0,0,0,0,0,0,0,0,0,0,0,0,0,0,0
0,0,0,0,0,0,0,0,0,0,0,0,0,0,0,0,0,0,0,0,0
0,0,0,0,0,0,0,0,0,0,0,0,0,0,0,0,0,0,0,0,0
0,0,0,0,0,0,0,0,0,24,24,24,0,0,0,0,0,0,0,0,0
0,0,0,0,0,0,0,0,0,24,25,24,0,0,0,0,0,0,0,0,0
0,0,0,0,0,23,23,23,23,23,23,23,23,23,23,63,0,0,0,0,0
0,0,0,0,0,67,24,24,24,24,24,24,24,24,24,63,0,0,0,0,0
0,0,0,0,0,67,24,24,24,24,24,24,24,24,24,63,0,0,0,0,0
0,0,0,0,0,67,24,24,24,24,24,24,24,24,24,63,0,0,0,0,0
0,0,0,0,0,67,24,24,24,24,24,24,24,24,24,63,0,0,0,0,0
0,0,0,0,0,67,24,24,24,24,24,24,24,24,24,63,0,0,0,0,0
0,0,0,0,0,67,24,24,24,24,24,24,24,24,24,63,0,0,0,0,0
0,0,0,0,0,67,24,24,24,24,24,24,24,24,24,63,0,0,0,0,0
0,0,0,0,0,67,24,24,24,24,24,24,24,24,24,63,0,0,0,0,0
0,0,0,0,0,67,24,24,24,24,24,24,24,24,24,63,0,0,0,0,0
0,0,0,0,0,67,24,24,24,24,24,24,24,24,24,63,0,0,0,0,0
0,0,0,0,0,67,24,24,24,24,24,24,24,24,24,63,0,0,0,0,0
0,0,0,0,0,67,34,34,34,34,34,34,34,34,34,34,0,0,0,0,0
0,0,0,0,0,0,0,0,0,0,0,0,0,0,0,0,0,0,0,0,0
0,0,0,0,0,0,0,0,0,0,0,0,0,0,0,0,0,0,0,0,0
0,0,0,0,0,0,0,0,0,0,0,0,0,0,0,0,0,0,0,0,0
0,0,0,0,0,0,0,0,0,0,0,0,0,0,0,0,0,0,0,0,0
0,0,0,0,0,0,0,0,0,0,0,0,0,0,0,0,0,0,0,0,0
0,0,0,0,0,0,0,67,0,0,0,0,0,63,0,0,0,0,0,0,0
0,0,0,0,0,0,0,67,24,24,45,24,24,63,0,0,0,0,0,0,0
0,0,0,0,0,0,0,67,0,0,0,0,0,63,0,0,0,0,0,0,0
0,0,0,0,0,0,0,67,0,0,0,0,0,24,24,24,0,0,0,0,0
0,0,0,0,0,0,0,67,40,0,0,0,0,0,0,45,0,0,0,0,0
0,0,0,0,0,0,0,67,0,0,0,0,0,0,0,45,0,0,0,0,0
0,0,0,0,0,0,0,67,0,0,0,0,0,0,40,24,3,0,0,0,0
0,0,0,0,0,0,0,67,40,0,0,0,0,0,0,45,0,0,0,0,0
0,0,0,0,0,0,0,67,0,0,0,0,0,0,0,45,0,0,0,0,0
0,0,0,0,0,0,0,67,0,0,0,0,0,24,24,24,0,0,0,0,0
0,0,0,0,0,0,0,67,0,0,0,0,0,63,0,0,0,0,0,0,0
0,0,0,0,0,0,0,67,24,24,45,24,24,63,0,0,0,0,0,0,0
0,0,0,0,0,0,0,67,0,0,0,0,0,63,0,0,0,0,0,0,0
0,0,0,0,0,0,0,0,0,0,0,0,0,0,0,0,0,0,0,0,0
0,0,0,0,0,0,0,0,0,0,0,0,0,0,0,0,0,0,0,0,0
0,0,0,0,0,0,0,0,0,0,0,0,0,0,0,0,0,0,0,0,0
:endlayer
layer: 9
0,0,0,0,0,0,0,0,0,0,0,0,0,0,0,0,0,0,0,0,0
0,0,0,0,0,0,0,0,0,0,0,0,0,0,0,0,0,0,0,0,0
0,0,0,0,0,0,0,0,0,0,0,0,0,0,0,0,0,0,0,0,0
0,0,0,0,0,0,0,0,0,0,24,0,0,0,0,0,0,0,0,0,0
0,0,0,0,0,0,0,0,0,0,0,0,0,0,0,0,0,0,0,0,0
0,0,0,0,0,0,0,0,0,0,0,0,0,0,0,0,0,0,0,0,0
0,0,0,0,0,0,0,0,0,0,0,0,0,0,0,0,0,0,0,0,0
0,0,0,0,0,0,0,0,0,0,0,0,0,0,0,0,0,0,0,0,0
0,0,0,0,0,0,0,0,0,0,0,0,0,0,0,0,0,0,0,0,0
0,0,0,0,0,0,0,0,0,0,40,0,0,0,0,0,0,0,0,0,0
0,0,0,0,0,0,0,0,0,0,0,0,0,0,0,0,0,0,0,0,0
0,0,0,0,0,0,0,0,0,0,0,0,0,0,0,0,0,0,0,0,0
0,0,0,0,0,0,0,0,0,0,0,0,0,0,0,0,0,0,0,0,0
0,0,0,0,0,0,0,0,0,0,0,0,0,0,0,0,0,0,0,0,0
0,0,0,0,0,0,0,0,0,0,0,0,0,0,0,0,0,0,0,0,0
0,0,0,0,0,0,0,0,0,0,0,0,0,0,0,0,0,0,0,0,0
0,0,0,0,0,0,0,0,0,0,40,0,0,0,0,0,0,0,0,0,0
0,0,0,0,0,0,0,0,0,0,0,0,0,0,0,0,0,0,0,0,0
0,0,0,0,0,0,0,0,0,0,0,0,0,0,0,0,0,0,0,0,0
0,0,0,0,0,0,0,0,0,0,0,0,0,0,0,0,0,0,0,0,0
0,0,0,0,0,0,0,0,0,0,0,0,0,0,0,0,0,0,0,0,0
0,0,0,0,0,0,0,0,0,0,0,0,0,0,0,0,0,0,0,0,0
0,0,0,0,0,0,0,0,0,0,0,0,0,0,0,0,0,0,0,0,0
0,0,0,0,0,0,0,0,67,0,0,0,63,0,0,0,0,0,0,0,0
0,0,0,0,0,0,0,0,67,24,45,24,63,0,0,0,0,0,0,0,0
0,0,0,0,0,0,0,0,67,53,0,53,63,0,0,0,0,0,0,0,0
0,0,0,0,0,0,0,0,67,0,0,0,24,24,24,24,0,0,0,0,0
0,0,0,0,0,0,0,0,67,0,0,0,0,0,0,45,0,0,0,0,0
0,0,0,0,0,0,0,0,67,0,0,0,0,0,0,45,0,0,0,0,0
0,0,0,0,0,0,0,0,67,0,0,0,0,0,0,24,3,0,0,0,0
0,0,0,0,0,0,0,0,67,0,0,0,0,0,0,45,0,0,0,0,0
0,0,0,0,0,0,0,0,67,0,0,0,0,0,0,45,0,0,0,0,0
0,0,0,0,0,0,0,0,67,0,0,0,24,24,45,24,0,0,0,0,0
0,0,0,0,0,0,0,0,67,52,0,52,63,0,0,0,0,0,0,0,0
0,0,0,0,0,0,0,0,67,24,45,24,63,0,0,0,0,0,0,0,0
0,0,0,0,0,0,0,0,67,0,0,0,63,0,0,0,0,0,0,0,0
0,0,0,0,0,0,0,0,0,0,0,0,0,0,0,0,0,0,0,0,0
0,0,0,0,0,0,0,0,0,0,0,0,0,0,0,0,0,0,0,0,0
0,0,0,0,0,0,0,0,0,0,0,0,0,0,0,0,0,0,0,0,0
:endlayer
layer: 10
0,0,0,0,0,0,0,0,0,0,0,0,0,0,0,0,0,0,0,0,0
0,0,0,0,0,0,0,0,0,0,0,0,0,0,0,0,0,0,0,0,0
0,0,0,0,0,0,0,0,0,0,0,0,0,0,0,0,0,0,0,0,0
0,0,0,0,0,0,0,0,0,0,40,0,0,0,0,0,0,0,0,0,0
0,0,0,0,0,0,0,0,0,0,0,0,0,0,0,0,0,0,0,0,0
0,0,0,0,0,0,0,0,0,0,0,0,0,0,0,0,0,0,0,0,0
0,0,0,0,0,0,0,0,0,0,0,0,0,0,0,0,0,0,0,0,0
0,0,0,0,0,0,0,0,0,0,0,0,0,0,0,0,0,0,0,0,0
0,0,0,0,0,0,0,0,0,0,0,0,0,0,0,0,0,0,0,0,0
0,0,0,0,0,0,0,0,0,0,0,0,0,0,0,0,0,0,0,0,0
0,0,0,0,0,0,0,0,0,0,0,0,0,0,0,0,0,0,0,0,0
0,0,0,0,0,0,0,0,0,0,0,0,0,0,0,0,0,0,0,0,0
0,0,0,0,0,0,0,0,0,0,0,0,0,0,0,0,0,0,0,0,0
0,0,0,0,0,0,0,0,0,0,0,0,0,0,0,0,0,0,0,0,0
0,0,0,0,0,0,0,0,0,0,0,0,0,0,0,0,0,0,0,0,0
0,0,0,0,0,0,0,0,0,0,0,0,0,0,0,0,0,0,0,0,0
0,0,0,0,0,0,0,0,0,0,0,0,0,0,0,0,0,0,0,0,0
0,0,0,0,0,0,0,0,0,0,0,0,0,0,0,0,0,0,0,0,0
0,0,0,0,0,0,0,0,0,0,0,0,0,0,0,0,0,0,0,0,0
0,0,0,0,0,0,0,0,0,0,0,0,0,0,0,0,0,0,0,0,0
0,0,0,0,0,0,0,0,0,0,0,0,0,0,0,0,0,0,0,0,0
0,0,0,0,0,0,0,0,0,0,0,0,0,0,0,0,0,0,0,0,0
0,0,0,0,0,0,0,0,0,0,0,0,0,0,0,0,0,0,0,0,0
0,0,0,0,0,0,0,0,0,67,79,63,0,0,0,0,0,0,0,0,0
0,0,0,0,0,0,0,0,0,67,24,63,0,0,0,0,0,0,0,0,0
0,0,0,0,0,0,0,0,0,67,24,63,67,0,0,0,63,0,0,0,0
0,0,0,0,0,0,0,0,0,67,24,63,67,24,24,24,63,0,0,0,0
0,0,0,0,0,0,0,0,0,67,24,63,67,0,0,24,63,0,0,0,0
0,0,0,0,0,0,0,0,0,67,24,63,67,0,0,24,63,0,0,0,0
0,0,0,0,0,0,0,0,0,67,24,63,67,0,0,24,64,0,0,0,0
0,0,0,0,0,0,0,0,0,67,24,63,67,0,0,24,63,0,0,0,0
0,0,0,0,0,0,0,0,0,67,24,63,67,0,0,24,63,0,0,0,0
0,0,0,0,0,0,0,0,0,67,24,63,67,24,24,24,63,0,0,0,0
0,0,0,0,0,0,0,0,0,67,24,63,67,0,0,0,63,0,0,0,0
0,0,0,0,0,0,0,0,0,67,24,63,0,0,0,0,0,0,0,0,0
0,0,0,0,0,0,0,0,0,67,80,63,0,0,0,0,0,0,0,0,0
0,0,0,0,0,0,0,0,0,0,0,0,0,0,0,0,0,0,0,0,0
0,0,0,0,0,0,0,0,0,0,0,0,0,0,0,0,0,0,0,0,0
0,0,0,0,0,0,0,0,0,0,0,0,0,0,0,0,0,0,0,0,0
:endlayer
layer: 11
0,0,0,0,0,0,0,0,0,0,0,0,0,0,0,0,0,0,0,0,0
0,0,0,0,0,0,0,0,0,0,0,0,0,0,0,0,0,0,0,0,0
0,0,0,0,0,0,0,0,0,0,0,0,0,0,0,0,0,0,0,0,0
0,0,0,0,0,0,0,0,0,0,0,0,0,0,0,0,0,0,0,0,0
0,0,0,0,0,0,0,0,0,0,0,0,0,0,0,0,0,0,0,0,0
0,0,0,0,0,0,0,0,0,0,0,0,0,0,0,0,0,0,0,0,0
0,0,0,0,0,0,0,0,0,0,0,0,0,0,0,0,0,0,0,0,0
0,0,0,0,0,0,0,0,0,0,0,0,0,0,0,0,0,0,0,0,0
0,0,0,0,0,0,0,0,0,0,0,0,0,0,0,0,0,0,0,0,0
0,0,0,0,0,0,0,0,0,0,0,0,0,0,0,0,0,0,0,0,0
0,0,0,0,0,0,0,0,0,0,0,0,0,0,0,0,0,0,0,0,0
0,0,0,0,0,0,0,0,0,0,0,0,0,0,0,0,0,0,0,0,0
0,0,0,0,0,0,0,0,0,0,0,0,0,0,0,0,0,0,0,0,0
0,0,0,0,0,0,0,0,0,0,0,0,0,0,0,0,0,0,0,0,0
0,0,0,0,0,0,0,0,0,0,0,0,0,0,0,0,0,0,0,0,0
0,0,0,0,0,0,0,0,0,0,0,0,0,0,0,0,0,0,0,0,0
0,0,0,0,0,0,0,0,0,0,0,0,0,0,0,0,0,0,0,0,0
0,0,0,0,0,0,0,0,0,0,0,0,0,0,0,0,0,0,0,0,0
0,0,0,0,0,0,0,0,0,0,0,0,0,0,0,0,0,0,0,0,0
0,0,0,0,0,0,0,0,0,0,0,0,0,0,0,0,0,0,0,0,0
0,0,0,0,0,0,0,0,0,0,0,0,0,0,0,0,0,0,0,0,0
0,0,0,0,0,0,0,0,0,0,0,0,0,0,0,0,0,0,0,0,0
0,0,0,0,0,0,0,0,0,0,0,0,0,0,0,0,0,0,0,0,0
0,0,0,0,0,0,0,0,0,0,40,0,0,0,0,0,0,0,0,0,0
0,0,0,0,0,0,0,0,0,0,0,0,0,0,0,0,0,0,0,0,0
0,0,0,0,0,0,0,0,0,0,0,0,0,67,79,63,0,0,0,0,0
0,0,0,0,0,0,0,0,0,0,0,0,0,67,24,63,0,0,0,0,0
0,0,0,0,0,0,0,0,0,0,0,0,0,67,24,63,0,0,0,0,0
0,0,0,0,0,0,0,0,0,0,0,0,0,67,24,63,0,0,0,0,0
0,0,0,0,0,0,0,0,0,0,0,0,0,67,24,63,64,0,0,0,0
0,0,0,0,0,0,0,0,0,0,0,0,0,67,24,63,0,0,0,0,0
0,0,0,0,0,0,0,0,0,0,0,0,0,67,24,63,0,0,0,0,0
0,0,0,0,0,0,0,0,0,0,0,0,0,67,24,63,0,0,0,0,0
0,0,0,0,0,0,0,0,0,0,0,0,0,67,80,63,0,0,0,0,0
0,0,0,0,0,0,0,0,0,0,0,0,0,0,0,0,0,0,0,0,0
0,0,0,0,0,0,0,0,0,0,40,0,0,0,0,0,0,0,0,0,0
0,0,0,0,0,0,0,0,0,0,0,0,0,0,0,0,0,0,0,0,0
0,0,0,0,0,0,0,0,0,0,0,0,0,0,0,0,0,0,0,0,0
0,0,0,0,0,0,0,0,0,0,0,0,0,0,0,0,0,0,0,0,0
:endlayer
layer: 12
0,0,0,0,0,0,0,0,0,0,0,0,0,0,0,0,0,0,0,0,0
0,0,0,0,0,0,0,0,0,0,0,0,0,0,0,0,0,0,0,0,0
0,0,0,0,0,0,0,0,0,0,0,0,0,0,0,0,0,0,0,0,0
0,0,0,0,0,0,0,0,0,0,0,0,0,0,0,0,0,0,0,0,0
0,0,0,0,0,0,0,0,0,0,0,0,0,0,0,0,0,0,0,0,0
0,0,0,0,0,0,0,0,0,0,0,0,0,0,0,0,0,0,0,0,0
0,0,0,0,0,0,0,0,0,0,0,0,0,0,0,0,0,0,0,0,0
0,0,0,0,0,0,0,0,0,0,0,0,0,0,0,0,0,0,0,0,0
0,0,0,0,0,0,0,0,0,0,0,0,0,0,0,0,0,0,0,0,0
0,0,0,0,0,0,0,0,0,0,0,0,0,0,0,0,0,0,0,0,0
0,0,0,0,0,0,0,0,0,0,0,0,0,0,0,0,0,0,0,0,0
0,0,0,0,0,0,0,0,0,0,0,0,0,0,0,0,0,0,0,0,0
0,0,0,0,0,0,0,0,0,0,0,0,0,0,0,0,0,0,0,0,0
0,0,0,0,0,0,0,0,0,0,0,0,0,0,0,0,0,0,0,0,0
0,0,0,0,0,0,0,0,0,0,0,0,0,0,0,0,0,0,0,0,0
0,0,0,0,0,0,0,0,0,0,0,0,0,0,0,0,0,0,0,0,0
0,0,0,0,0,0,0,0,0,0,0,0,0,0,0,0,0,0,0,0,0
0,0,0,0,0,0,0,0,0,0,0,0,0,0,0,0,0,0,0,0,0
0,0,0,0,0,0,0,0,0,0,0,0,0,0,0,0,0,0,0,0,0
0,0,0,0,0,0,0,0,0,0,0,0,0,0,0,0,0,0,0,0,0
0,0,0,0,0,0,0,0,0,0,0,0,0,0,0,0,0,0,0,0,0
0,0,0,0,0,0,0,0,0,0,0,0,0,0,0,0,0,0,0,0,0
0,0,0,0,0,0,0,0,0,0,0,0,0,0,0,0,0,0,0,0,0
0,0,0,0,0,0,0,0,0,0,0,0,0,0,0,0,0,0,0,0,0
0,0,0,0,0,0,0,0,0,0,0,0,0,0,0,0,0,0,0,0,0
0,0,0,0,0,0,0,0,0,0,0,0,0,0,0,0,0,0,0,0,0
0,0,0,0,0,0,0,0,0,0,0,0,0,0,0,0,0,0,0,0,0
0,0,0,0,0,0,0,0,0,0,0,0,0,0,0,0,0,0,0,0,0
0,0,0,0,0,0,0,0,0,0,0,0,0,0,0,0,0,0,0,0,0
0,0,0,0,0,0,0,0,0,0,0,0,0,0,0,0,81,0,0,0,0
0,0,0,0,0,0,0,0,0,0,0,0,0,0,0,0,0,0,0,0,0
0,0,0,0,0,0,0,0,0,0,0,0,0,0,0,0,0,0,0,0,0
0,0,0,0,0,0,0,0,0,0,0,0,0,0,0,0,0,0,0,0,0
0,0,0,0,0,0,0,0,0,0,0,0,0,0,0,0,0,0,0,0,0
0,0,0,0,0,0,0,0,0,0,0,0,0,0,0,0,0,0,0,0,0
0,0,0,0,0,0,0,0,0,0,0,0,0,0,0,0,0,0,0,0,0
0,0,0,0,0,0,0,0,0,0,0,0,0,0,0,0,0,0,0,0,0
0,0,0,0,0,0,0,0,0,0,0,0,0,0,0,0,0,0,0,0,0
0,0,0,0,0,0,0,0,0,0,0,0,0,0,0,0,0,0,0,0,0
:endlayer
layer: 13
0,0,0,0,0,0,0,0,0,0,0,0,0,0,0,0,0,0,0,0,0
0,0,0,0,0,0,0,0,0,0,0,0,0,0,0,0,0,0,0,0,0
0,0,0,0,0,0,0,0,0,0,0,0,0,0,0,0,0,0,0,0,0
0,0,0,0,0,0,0,0,0,0,0,0,0,0,0,0,0,0,0,0,0
0,0,0,0,0,0,0,0,0,0,0,0,0,0,0,0,0,0,0,0,0
0,0,0,0,0,0,0,0,0,0,0,0,0,0,0,0,0,0,0,0,0
0,0,0,0,0,0,0,0,0,0,0,0,0,0,0,0,0,0,0,0,0
0,0,0,0,0,0,0,0,0,0,0,0,0,0,0,0,0,0,0,0,0
0,0,0,0,0,0,0,0,0,0,0,0,0,0,0,0,0,0,0,0,0
0,0,0,0,0,0,0,0,0,0,0,0,0,0,0,0,0,0,0,0,0
0,0,0,0,0,0,0,0,0,0,0,0,0,0,0,0,0,0,0,0,0
0,0,0,0,0,0,0,0,0,0,0,0,0,0,0,0,0,0,0,0,0
0,0,0,0,0,0,0,0,0,0,0,0,0,0,0,0,0,0,0,0,0
0,0,0,0,0,0,0,0,0,0,0,0,0,0,0,0,0,0,0,0,0
0,0,0,0,0,0,0,0,0,0,0,0,0,0,0,0,0,0,0,0,0
0,0,0,0,0,0,0,0,0,0,0,0,0,0,0,0,0,0,0,0,0
0,0,0,0,0,0,0,0,0,0,0,0,0,0,0,0,0,0,0,0,0
0,0,0,0,0,0,0,0,0,0,0,0,0,0,0,0,0,0,0,0,0
0,0,0,0,0,0,0,0,0,0,0,0,0,0,0,0,0,0,0,0,0
0,0,0,0,0,0,0,0,0,0,0,0,0,0,0,0,0,0,0,0,0
0,0,0,0,0,0,0,0,0,0,0,0,0,0,0,0,0,0,0,0,0
0,0,0,0,0,0,0,0,0,0,0,0,0,0,0,0,0,0,0,0,0
0,0,0,0,0,0,0,0,0,0,0,0,0,0,0,0,0,0,0,0,0
0,0,0,0,0,0,0,0,0,0,0,0,0,0,0,0,0,0,0,0,0
0,0,0,0,0,0,0,0,0,0,0,0,0,0,0,0,0,0,0,0,0
0,0,0,0,0,0,0,0,0,0,0,0,0,0,0,0,0,0,0,0,0
0,0,0,0,0,0,0,0,0,0,0,0,0,0,0,0,0,0,0,0,0
0,0,0,0,0,0,0,0,0,0,0,0,0,0,0,0,0,0,0,0,0
0,0,0,0,0,0,0,0,0,0,0,0,0,0,0,0,0,0,0,0,0
0,0,0,0,0,0,0,0,0,0,0,0,0,0,0,0,0,0,0,0,0
0,0,0,0,0,0,0,0,0,0,0,0,0,0,0,0,0,0,0,0,0
0,0,0,0,0,0,0,0,0,0,0,0,0,0,0,0,0,0,0,0,0
0,0,0,0,0,0,0,0,0,0,0,0,0,0,0,0,0,0,0,0,0
0,0,0,0,0,0,0,0,0,0,0,0,0,0,0,0,0,0,0,0,0
0,0,0,0,0,0,0,0,0,0,0,0,0,0,0,0,0,0,0,0,0
0,0,0,0,0,0,0,0,0,0,0,0,0,0,0,0,0,0,0,0,0
0,0,0,0,0,0,0,0,0,0,0,0,0,0,0,0,0,0,0,0,0
0,0,0,0,0,0,0,0,0,0,0,0,0,0,0,0,0,0,0,0,0
0,0,0,0,0,0,0,0,0,0,0,0,0,0,0,0,0,0,0,0,0
:endlayer
layer: 14
0,0,0,0,0,0,0,0,0,0,0,0,0,0,0,0,0,0,0,0,0
0,0,0,0,0,0,0,0,0,0,0,0,0,0,0,0,0,0,0,0,0
0,0,0,0,0,0,0,0,0,0,0,0,0,0,0,0,0,0,0,0,0
0,0,0,0,0,0,0,0,0,0,0,0,0,0,0,0,0,0,0,0,0
0,0,0,0,0,0,0,0,0,0,0,0,0,0,0,0,0,0,0,0,0
0,0,0,0,0,0,0,0,0,0,0,0,0,0,0,0,0,0,0,0,0
0,0,0,0,0,0,0,0,0,0,0,0,0,0,0,0,0,0,0,0,0
0,0,0,0,0,0,0,0,0,0,0,0,0,0,0,0,0,0,0,0,0
0,0,0,0,0,0,0,0,0,0,0,0,0,0,0,0,0,0,0,0,0
0,0,0,0,0,0,0,0,0,0,0,0,0,0,0,0,0,0,0,0,0
0,0,0,0,0,0,0,0,0,0,0,0,0,0,0,0,0,0,0,0,0
0,0,0,0,0,0,0,0,0,0,0,0,0,0,0,0,0,0,0,0,0
0,0,0,0,0,0,0,0,0,0,0,0,0,0,0,0,0,0,0,0,0
0,0,0,0,0,0,0,0,0,0,0,0,0,0,0,0,0,0,0,0,0
0,0,0,0,0,0,0,0,0,0,0,0,0,0,0,0,0,0,0,0,0
0,0,0,0,0,0,0,0,0,0,0,0,0,0,0,0,0,0,0,0,0
0,0,0,0,0,0,0,0,0,0,0,0,0,0,0,0,0,0,0,0,0
0,0,0,0,0,0,0,0,0,0,0,0,0,0,0,0,0,0,0,0,0
0,0,0,0,0,0,0,0,0,0,0,0,0,0,0,0,0,0,0,0,0
0,0,0,0,0,0,0,0,0,0,0,0,0,0,0,0,0,0,0,0,0
0,0,0,0,0,0,0,0,0,0,0,0,0,0,0,0,0,0,0,0,0
0,0,0,0,0,0,0,0,0,0,0,0,0,0,0,0,0,0,0,0,0
0,0,0,0,0,0,0,0,0,0,0,0,0,0,0,0,0,0,0,0,0
0,0,0,0,0,0,0,0,0,0,0,0,0,0,0,0,0,0,0,0,0
0,0,0,0,0,0,0,0,0,0,0,0,0,0,0,0,0,0,0,0,0
0,0,0,0,0,0,0,0,0,0,0,0,0,0,0,0,0,0,0,0,0
0,0,0,0,0,0,0,0,0,0,0,0,0,0,0,0,0,0,0,0,0
0,0,0,0,0,0,0,0,0,0,0,0,0,0,0,0,0,0,0,0,0
0,0,0,0,0,0,0,0,0,0,0,0,0,0,0,0,0,0,0,0,0
0,0,0,0,0,0,0,0,0,0,0,0,0,0,0,0,0,0,0,0,0
0,0,0,0,0,0,0,0,0,0,0,0,0,0,0,0,0,0,0,0,0
0,0,0,0,0,0,0,0,0,0,0,0,0,0,0,0,0,0,0,0,0
0,0,0,0,0,0,0,0,0,0,0,0,0,0,0,0,0,0,0,0,0
0,0,0,0,0,0,0,0,0,0,0,0,0,0,0,0,0,0,0,0,0
0,0,0,0,0,0,0,0,0,0,0,0,0,0,0,0,0,0,0,0,0
0,0,0,0,0,0,0,0,0,0,0,0,0,0,0,0,0,0,0,0,0
0,0,0,0,0,0,0,0,0,0,0,0,0,0,0,0,0,0,0,0,0
0,0,0,0,0,0,0,0,0,0,0,0,0,0,0,0,0,0,0,0,0
0,0,0,0,0,0,0,0,0,0,0,0,0,0,0,0,0,0,0,0,0
:endlayer
layer: 15
0,0,0,0,0,0,0,0,0,0,0,0,0,0,0,0,0,0,0,0,0
0,0,0,0,0,0,0,0,0,0,0,0,0,0,0,0,0,0,0,0,0
0,0,0,0,0,0,0,0,0,0,0,0,0,0,0,0,0,0,0,0,0
0,0,0,0,0,0,0,0,0,0,0,0,0,0,0,0,0,0,0,0,0
0,0,0,0,0,0,0,0,0,0,0,0,0,0,0,0,0,0,0,0,0
0,0,0,0,0,0,0,0,0,0,0,0,0,0,0,0,0,0,0,0,0
0,0,0,0,0,0,0,0,0,0,0,0,0,0,0,0,0,0,0,0,0
0,0,0,0,0,0,0,0,0,0,0,0,0,0,0,0,0,0,0,0,0
0,0,0,0,0,0,0,0,0,0,0,0,0,0,0,0,0,0,0,0,0
0,0,0,0,0,0,0,0,0,0,0,0,0,0,0,0,0,0,0,0,0
0,0,0,0,0,0,0,0,0,0,0,0,0,0,0,0,0,0,0,0,0
0,0,0,0,0,0,0,0,0,0,0,0,0,0,0,0,0,0,0,0,0
0,0,0,0,0,0,0,0,0,0,0,0,0,0,0,0,0,0,0,0,0
0,0,0,0,0,0,0,0,0,0,0,0,0,0,0,0,0,0,0,0,0
0,0,0,0,0,0,0,0,0,0,0,0,0,0,0,0,0,0,0,0,0
0,0,0,0,0,0,0,0,0,0,0,0,0,0,0,0,0,0,0,0,0
0,0,0,0,0,0,0,0,0,0,0,0,0,0,0,0,0,0,0,0,0
0,0,0,0,0,0,0,0,0,0,0,0,0,0,0,0,0,0,0,0,0
0,0,0,0,0,0,0,0,0,0,0,0,0,0,0,0,0,0,0,0,0
0,0,0,0,0,0,0,0,0,0,0,0,0,0,0,0,0,0,0,0,0
0,0,0,0,0,0,0,0,0,0,0,0,0,0,0,0,0,0,0,0,0
0,0,0,0,0,0,0,0,0,0,0,0,0,0,0,0,0,0,0,0,0
0,0,0,0,0,0,0,0,0,0,0,0,0,0,0,0,0,0,0,0,0
0,0,0,0,0,0,0,0,0,0,0,0,0,0,0,0,0,0,0,0,0
0,0,0,0,0,0,0,0,0,0,0,0,0,0,0,0,0,0,0,0,0
0,0,0,0,0,0,0,0,0,0,0,0,0,0,0,0,0,0,0,0,0
0,0,0,0,0,0,0,0,0,0,0,0,0,0,0,0,0,0,0,0,0
0,0,0,0,0,0,0,0,0,0,0,0,0,0,0,0,0,0,0,0,0
0,0,0,0,0,0,0,0,0,0,0,0,0,0,0,0,0,0,0,0,0
0,0,0,0,0,0,0,0,0,0,0,0,0,0,0,0,0,0,0,0,0
0,0,0,0,0,0,0,0,0,0,0,0,0,0,0,0,0,0,0,0,0
0,0,0,0,0,0,0,0,0,0,0,0,0,0,0,0,0,0,0,0,0
0,0,0,0,0,0,0,0,0,0,0,0,0,0,0,0,0,0,0,0,0
0,0,0,0,0,0,0,0,0,0,0,0,0,0,0,0,0,0,0,0,0
0,0,0,0,0,0,0,0,0,0,0,0,0,0,0,0,0,0,0,0,0
0,0,0,0,0,0,0,0,0,0,0,0,0,0,0,0,0,0,0,0,0
0,0,0,0,0,0,0,0,0,0,0,0,0,0,0,0,0,0,0,0,0
0,0,0,0,0,0,0,0,0,0,0,0,0,0,0,0,0,0,0,0,0
0,0,0,0,0,0,0,0,0,0,0,0,0,0,0,0,0,0,0,0,0
:endlayer
layer: 16
0,0,0,0,0,0,0,0,0,0,0,0,0,0,0,0,0,0,0,0,0
0,0,0,0,0,0,0,0,0,0,0,0,0,0,0,0,0,0,0,0,0
0,0,0,0,0,0,0,0,0,0,0,0,0,0,0,0,0,0,0,0,0
0,0,0,0,0,0,0,0,0,0,0,0,0,0,0,0,0,0,0,0,0
0,0,0,0,0,0,0,0,0,0,0,0,0,0,0,0,0,0,0,0,0
0,0,0,0,0,0,0,0,0,0,0,0,0,0,0,0,0,0,0,0,0
0,0,0,0,0,0,0,0,0,0,0,0,0,0,0,0,0,0,0,0,0
0,0,0,0,0,0,0,0,0,0,0,0,0,0,0,0,0,0,0,0,0
0,0,0,0,0,0,0,0,0,0,0,0,0,0,0,0,0,0,0,0,0
0,0,0,0,0,0,0,0,0,0,0,0,0,0,0,0,0,0,0,0,0
0,0,0,0,0,0,0,0,0,0,0,0,0,0,0,0,0,0,0,0,0
0,0,0,0,0,0,0,0,0,0,0,0,0,0,0,0,0,0,0,0,0
0,0,0,0,0,0,0,0,0,0,0,0,0,0,0,0,0,0,0,0,0
0,0,0,0,0,0,0,0,0,0,0,0,0,0,0,0,0,0,0,0,0
0,0,0,0,0,0,0,0,0,0,0,0,0,0,0,0,0,0,0,0,0
0,0,0,0,0,0,0,0,0,0,0,0,0,0,0,0,0,0,0,0,0
0,0,0,0,0,0,0,0,0,0,0,0,0,0,0,0,0,0,0,0,0
0,0,0,0,0,0,0,0,0,0,0,0,0,0,0,0,0,0,0,0,0
0,0,0,0,0,0,0,0,0,0,0,0,0,0,0,0,0,0,0,0,0
0,0,0,0,0,0,0,0,0,0,0,0,0,0,0,0,0,0,0,0,0
0,0,0,0,0,0,0,0,0,0,0,0,0,0,0,0,0,0,0,0,0
0,0,0,0,0,0,0,0,0,0,0,0,0,0,0,0,0,0,0,0,0
0,0,0,0,0,0,0,0,0,0,0,0,0,0,0,0,0,0,0,0,0
0,0,0,0,0,0,0,0,0,0,0,0,0,0,0,0,0,0,0,0,0
0,0,0,0,0,0,0,0,0,0,0,0,0,0,0,0,0,0,0,0,0
0,0,0,0,0,0,0,0,0,0,0,0,0,0,0,0,0,0,0,0,0
0,0,0,0,0,0,0,0,0,0,0,0,0,0,0,0,0,0,0,0,0
0,0,0,0,0,0,0,0,0,0,0,0,0,0,0,0,0,0,0,0,0
0,0,0,0,0,0,0,0,0,0,0,0,0,0,0,0,0,0,0,0,0
0,0,0,0,0,0,0,0,0,0,0,0,0,0,0,0,0,0,0,0,0
0,0,0,0,0,0,0,0,0,0,0,0,0,0,0,0,0,0,0,0,0
0,0,0,0,0,0,0,0,0,0,0,0,0,0,0,0,0,0,0,0,0
0,0,0,0,0,0,0,0,0,0,0,0,0,0,0,0,0,0,0,0,0
0,0,0,0,0,0,0,0,0,0,0,0,0,0,0,0,0,0,0,0,0
0,0,0,0,0,0,0,0,0,0,0,0,0,0,0,0,0,0,0,0,0
0,0,0,0,0,0,0,0,0,0,0,0,0,0,0,0,0,0,0,0,0
0,0,0,0,0,0,0,0,0,0,0,0,0,0,0,0,0,0,0,0,0
0,0,0,0,0,0,0,0,0,0,0,0,0,0,0,0,0,0,0,0,0
0,0,0,0,0,0,0,0,0,0,0,0,0,0,0,0,0,0,0,0,0
:endlayer
layer: 17
0,0,0,0,0,0,0,0,0,0,0,0,0,0,0,0,0,0,0,0,0
0,0,0,0,0,0,0,0,0,0,0,0,0,0,0,0,0,0,0,0,0
0,0,0,0,0,0,0,0,0,0,0,0,0,0,0,0,0,0,0,0,0
0,0,0,0,0,0,0,0,0,0,0,0,0,0,0,0,0,0,0,0,0
0,0,0,0,0,0,0,0,0,0,0,0,0,0,0,0,0,0,0,0,0
0,0,0,0,0,0,0,0,0,0,0,0,0,0,0,0,0,0,0,0,0
0,0,0,0,0,0,0,0,0,0,0,0,0,0,0,0,0,0,0,0,0
0,0,0,0,0,0,0,0,0,0,0,0,0,0,0,0,0,0,0,0,0
0,0,0,0,0,0,0,0,0,0,0,0,0,0,0,0,0,0,0,0,0
0,0,0,0,0,0,0,0,0,0,0,0,0,0,0,0,0,0,0,0,0
0,0,0,0,0,0,0,0,0,0,0,0,0,0,0,0,0,0,0,0,0
0,0,0,0,0,0,0,0,0,0,0,0,0,0,0,0,0,0,0,0,0
0,0,0,0,0,0,0,0,0,0,0,0,0,0,0,0,0,0,0,0,0
0,0,0,0,0,0,0,0,0,0,0,0,0,0,0,0,0,0,0,0,0
0,0,0,0,0,0,0,0,0,0,0,0,0,0,0,0,0,0,0,0,0
0,0,0,0,0,0,0,0,0,0,0,0,0,0,0,0,0,0,0,0,0
0,0,0,0,0,0,0,0,0,0,0,0,0,0,0,0,0,0,0,0,0
0,0,0,0,0,0,0,0,0,0,0,0,0,0,0,0,0,0,0,0,0
0,0,0,0,0,0,0,0,0,0,0,0,0,0,0,0,0,0,0,0,0
0,0,0,0,0,0,0,0,0,0,0,0,0,0,0,0,0,0,0,0,0
0,0,0,0,0,0,0,0,0,0,0,0,0,0,0,0,0,0,0,0,0
0,0,0,0,0,0,0,0,0,0,0,0,0,0,0,0,0,0,0,0,0
0,0,0,0,0,0,0,0,0,0,0,0,0,0,0,0,0,0,0,0,0
0,0,0,0,0,0,0,0,0,0,0,0,0,0,0,0,0,0,0,0,0
0,0,0,0,0,0,0,0,0,0,0,0,0,0,0,0,0,0,0,0,0
0,0,0,0,0,0,0,0,0,0,0,0,0,0,0,0,0,0,0,0,0
0,0,0,0,0,0,0,0,0,0,0,0,0,0,0,0,0,0,0,0,0
0,0,0,0,0,0,0,0,0,0,0,0,0,0,0,0,0,0,0,0,0
0,0,0,0,0,0,0,0,0,0,0,0,0,0,0,0,0,0,0,0,0
0,0,0,0,0,0,0,0,0,0,0,0,0,0,0,0,0,0,0,0,0
0,0,0,0,0,0,0,0,0,0,0,0,0,0,0,0,0,0,0,0,0
0,0,0,0,0,0,0,0,0,0,0,0,0,0,0,0,0,0,0,0,0
0,0,0,0,0,0,0,0,0,0,0,0,0,0,0,0,0,0,0,0,0
0,0,0,0,0,0,0,0,0,0,0,0,0,0,0,0,0,0,0,0,0
0,0,0,0,0,0,0,0,0,0,0,0,0,0,0,0,0,0,0,0,0
0,0,0,0,0,0,0,0,0,0,0,0,0,0,0,0,0,0,0,0,0
0,0,0,0,0,0,0,0,0,0,0,0,0,0,0,0,0,0,0,0,0
0,0,0,0,0,0,0,0,0,0,0,0,0,0,0,0,0,0,0,0,0
0,0,0,0,0,0,0,0,0,0,0,0,0,0,0,0,0,0,0,0,0
:endlayer
layer: 18
0,0,0,0,0,0,0,0,0,0,0,0,0,0,0,0,0,0,0,0,0
0,0,0,0,0,0,0,0,0,0,0,0,0,0,0,0,0,0,0,0,0
0,0,0,0,0,0,0,0,0,0,0,0,0,0,0,0,0,0,0,0,0
0,0,0,0,0,0,0,0,0,0,0,0,0,0,0,0,0,0,0,0,0
0,0,0,0,0,0,0,0,0,0,0,0,0,0,0,0,0,0,0,0,0
0,0,0,0,0,0,0,0,0,0,0,0,0,0,0,0,0,0,0,0,0
0,0,0,0,0,0,0,0,0,0,0,0,0,0,0,0,0,0,0,0,0
0,0,0,0,0,0,0,0,0,0,0,0,0,0,0,0,0,0,0,0,0
0,0,0,0,0,0,0,0,0,0,0,0,0,0,0,0,0,0,0,0,0
0,0,0,0,0,0,0,0,0,0,0,0,0,0,0,0,0,0,0,0,0
0,0,0,0,0,0,0,0,0,0,0,0,0,0,0,0,0,0,0,0,0
0,0,0,0,0,0,0,0,0,0,0,0,0,0,0,0,0,0,0,0,0
0,0,0,0,0,0,0,0,0,0,0,0,0,0,0,0,0,0,0,0,0
0,0,0,0,0,0,0,0,0,0,0,0,0,0,0,0,0,0,0,0,0
0,0,0,0,0,0,0,0,0,0,0,0,0,0,0,0,0,0,0,0,0
0,0,0,0,0,0,0,0,0,0,0,0,0,0,0,0,0,0,0,0,0
0,0,0,0,0,0,0,0,0,0,0,0,0,0,0,0,0,0,0,0,0
0,0,0,0,0,0,0,0,0,0,0,0,0,0,0,0,0,0,0,0,0
0,0,0,0,0,0,0,0,0,0,0,0,0,0,0,0,0,0,0,0,0
0,0,0,0,0,0,0,0,0,0,0,0,0,0,0,0,0,0,0,0,0
0,0,0,0,0,0,0,0,0,0,0,0,0,0,0,0,0,0,0,0,0
0,0,0,0,0,0,0,0,0,0,0,0,0,0,0,0,0,0,0,0,0
0,0,0,0,0,0,0,0,0,0,0,0,0,0,0,0,0,0,0,0,0
0,0,0,0,0,0,0,0,0,0,0,0,0,0,0,0,0,0,0,0,0
0,0,0,0,0,0,0,0,0,0,0,0,0,0,0,0,0,0,0,0,0
0,0,0,0,0,0,0,0,0,0,0,0,0,0,0,0,0,0,0,0,0
0,0,0,0,0,0,0,0,0,0,0,0,0,0,0,0,0,0,0,0,0
0,0,0,0,0,0,0,0,0,0,0,0,0,0,0,0,0,0,0,0,0
0,0,0,0,0,0,0,0,0,0,0,0,0,0,0,0,0,0,0,0,0
0,0,0,0,0,0,0,0,0,0,0,0,0,0,0,0,0,0,0,0,0
0,0,0,0,0,0,0,0,0,0,0,0,0,0,0,0,0,0,0,0,0
0,0,0,0,0,0,0,0,0,0,0,0,0,0,0,0,0,0,0,0,0
0,0,0,0,0,0,0,0,0,0,0,0,0,0,0,0,0,0,0,0,0
0,0,0,0,0,0,0,0,0,0,0,0,0,0,0,0,0,0,0,0,0
0,0,0,0,0,0,0,0,0,0,0,0,0,0,0,0,0,0,0,0,0
0,0,0,0,0,0,0,0,0,0,0,0,0,0,0,0,0,0,0,0,0
0,0,0,0,0,0,0,0,0,0,0,0,0,0,0,0,0,0,0,0,0
0,0,0,0,0,0,0,0,0,0,0,0,0,0,0,0,0,0,0,0,0
0,0,0,0,0,0,0,0,0,0,0,0,0,0,0,0,0,0,0,0,0
:endlayer
layer: 19
0,0,0,0,0,0,0,0,0,0,0,0,0,0,0,0,0,0,0,0,0
0,0,0,0,0,0,0,0,0,0,0,0,0,0,0,0,0,0,0,0,0
0,0,0,0,0,0,0,0,0,0,0,0,0,0,0,0,0,0,0,0,0
0,0,0,0,0,0,0,0,0,0,0,0,0,0,0,0,0,0,0,0,0
0,0,0,0,0,0,0,0,0,0,0,0,0,0,0,0,0,0,0,0,0
0,0,0,0,0,0,0,0,0,0,0,0,0,0,0,0,0,0,0,0,0
0,0,0,0,0,0,0,0,0,0,0,0,0,0,0,0,0,0,0,0,0
0,0,0,0,0,0,0,0,0,0,0,0,0,0,0,0,0,0,0,0,0
0,0,0,0,0,0,0,0,0,0,0,0,0,0,0,0,0,0,0,0,0
0,0,0,0,0,0,0,0,0,0,0,0,0,0,0,0,0,0,0,0,0
0,0,0,0,0,0,0,0,0,0,0,0,0,0,0,0,0,0,0,0,0
0,0,0,0,0,0,0,0,0,0,0,0,0,0,0,0,0,0,0,0,0
0,0,0,0,0,0,0,0,0,0,0,0,0,0,0,0,0,0,0,0,0
0,0,0,0,0,0,0,0,0,0,0,0,0,0,0,0,0,0,0,0,0
0,0,0,0,0,0,0,0,0,0,0,0,0,0,0,0,0,0,0,0,0
0,0,0,0,0,0,0,0,0,0,0,0,0,0,0,0,0,0,0,0,0
0,0,0,0,0,0,0,0,0,0,0,0,0,0,0,0,0,0,0,0,0
0,0,0,0,0,0,0,0,0,0,0,0,0,0,0,0,0,0,0,0,0
0,0,0,0,0,0,0,0,0,0,0,0,0,0,0,0,0,0,0,0,0
0,0,0,0,0,0,0,0,0,0,0,0,0,0,0,0,0,0,0,0,0
0,0,0,0,0,0,0,0,0,0,0,0,0,0,0,0,0,0,0,0,0
0,0,0,0,0,0,0,0,0,0,0,0,0,0,0,0,0,0,0,0,0
0,0,0,0,0,0,0,0,0,0,0,0,0,0,0,0,0,0,0,0,0
0,0,0,0,0,0,0,0,0,0,0,0,0,0,0,0,0,0,0,0,0
0,0,0,0,0,0,0,0,0,0,0,0,0,0,0,0,0,0,0,0,0
0,0,0,0,0,0,0,0,0,0,0,0,0,0,0,0,0,0,0,0,0
0,0,0,0,0,0,0,0,0,0,0,0,0,0,0,0,0,0,0,0,0
0,0,0,0,0,0,0,0,0,0,0,0,0,0,0,0,0,0,0,0,0
0,0,0,0,0,0,0,0,0,0,0,0,0,0,0,0,0,0,0,0,0
0,0,0,0,0,0,0,0,0,0,0,0,0,0,0,0,0,0,0,0,0
0,0,0,0,0,0,0,0,0,0,0,0,0,0,0,0,0,0,0,0,0
0,0,0,0,0,0,0,0,0,0,0,0,0,0,0,0,0,0,0,0,0
0,0,0,0,0,0,0,0,0,0,0,0,0,0,0,0,0,0,0,0,0
0,0,0,0,0,0,0,0,0,0,0,0,0,0,0,0,0,0,0,0,0
0,0,0,0,0,0,0,0,0,0,0,0,0,0,0,0,0,0,0,0,0
0,0,0,0,0,0,0,0,0,0,0,0,0,0,0,0,0,0,0,0,0
0,0,0,0,0,0,0,0,0,0,0,0,0,0,0,0,0,0,0,0,0
0,0,0,0,0,0,0,0,0,0,0,0,0,0,0,0,0,0,0,0,0
0,0,0,0,0,0,0,0,0,0,0,0,0,0,0,0,0,0,0,0,0
:endlayer
layer: 20
0,0,0,0,0,0,0,0,0,0,0,0,0,0,0,0,0,0,0,0,0
0,0,0,0,0,0,0,0,0,0,0,0,0,0,0,0,0,0,0,0,0
0,0,0,0,0,0,0,0,0,0,0,0,0,0,0,0,0,0,0,0,0
0,0,0,0,0,0,0,0,0,0,0,0,0,0,0,0,0,0,0,0,0
0,0,0,0,0,0,0,0,0,0,0,0,0,0,0,0,0,0,0,0,0
0,0,0,0,0,0,0,0,0,0,0,0,0,0,0,0,0,0,0,0,0
0,0,0,0,0,0,0,0,0,0,0,0,0,0,0,0,0,0,0,0,0
0,0,0,0,0,0,0,0,0,0,0,0,0,0,0,0,0,0,0,0,0
0,0,0,0,0,0,0,0,0,0,0,0,0,0,0,0,0,0,0,0,0
0,0,0,0,0,0,0,0,0,0,0,0,0,0,0,0,0,0,0,0,0
0,0,0,0,0,0,0,0,0,0,0,0,0,0,0,0,0,0,0,0,0
0,0,0,0,0,0,0,0,0,0,0,0,0,0,0,0,0,0,0,0,0
0,0,0,0,0,0,0,0,0,0,0,0,0,0,0,0,0,0,0,0,0
0,0,0,0,0,0,0,0,0,0,0,0,0,0,0,0,0,0,0,0,0
0,0,0,0,0,0,0,0,0,0,0,0,0,0,0,0,0,0,0,0,0
0,0,0,0,0,0,0,0,0,0,0,0,0,0,0,0,0,0,0,0,0
0,0,0,0,0,0,0,0,0,0,0,0,0,0,0,0,0,0,0,0,0
0,0,0,0,0,0,0,0,0,0,0,0,0,0,0,0,0,0,0,0,0
0,0,0,0,0,0,0,0,0,0,0,0,0,0,0,0,0,0,0,0,0
0,0,0,0,0,0,0,0,0,0,0,0,0,0,0,0,0,0,0,0,0
0,0,0,0,0,0,0,0,0,0,0,0,0,0,0,0,0,0,0,0,0
0,0,0,0,0,0,0,0,0,0,0,0,0,0,0,0,0,0,0,0,0
0,0,0,0,0,0,0,0,0,0,0,0,0,0,0,0,0,0,0,0,0
0,0,0,0,0,0,0,0,0,0,0,0,0,0,0,0,0,0,0,0,0
0,0,0,0,0,0,0,0,0,0,0,0,0,0,0,0,0,0,0,0,0
0,0,0,0,0,0,0,0,0,0,0,0,0,0,0,0,0,0,0,0,0
0,0,0,0,0,0,0,0,0,0,0,0,0,0,0,0,0,0,0,0,0
0,0,0,0,0,0,0,0,0,0,0,0,0,0,0,0,0,0,0,0,0
0,0,0,0,0,0,0,0,0,0,0,0,0,0,0,0,0,0,0,0,0
0,0,0,0,0,0,0,0,0,0,0,0,0,0,0,0,0,0,0,0,0
0,0,0,0,0,0,0,0,0,0,0,0,0,0,0,0,0,0,0,0,0
0,0,0,0,0,0,0,0,0,0,0,0,0,0,0,0,0,0,0,0,0
0,0,0,0,0,0,0,0,0,0,0,0,0,0,0,0,0,0,0,0,0
0,0,0,0,0,0,0,0,0,0,0,0,0,0,0,0,0,0,0,0,0
0,0,0,0,0,0,0,0,0,0,0,0,0,0,0,0,0,0,0,0,0
0,0,0,0,0,0,0,0,0,0,0,0,0,0,0,0,0,0,0,0,0
0,0,0,0,0,0,0,0,0,0,0,0,0,0,0,0,0,0,0,0,0
0,0,0,0,0,0,0,0,0,0,0,0,0,0,0,0,0,0,0,0,0
0,0,0,0,0,0,0,0,0,0,0,0,0,0,0,0,0,0,0,0,0
:endlayer
layer: 21
0,0,0,0,0,0,0,0,0,0,0,0,0,0,0,0,0,0,0,0,0
0,0,0,0,0,0,0,0,0,0,0,0,0,0,0,0,0,0,0,0,0
0,0,0,0,0,0,0,0,0,0,0,0,0,0,0,0,0,0,0,0,0
0,0,0,0,0,0,0,0,0,0,0,0,0,0,0,0,0,0,0,0,0
0,0,0,0,0,0,0,0,0,0,0,0,0,0,0,0,0,0,0,0,0
0,0,0,0,0,0,0,0,0,0,0,0,0,0,0,0,0,0,0,0,0
0,0,0,0,0,0,0,0,0,0,0,0,0,0,0,0,0,0,0,0,0
0,0,0,0,0,0,0,0,0,0,0,0,0,0,0,0,0,0,0,0,0
0,0,0,0,0,0,0,0,0,0,0,0,0,0,0,0,0,0,0,0,0
0,0,0,0,0,0,0,0,0,0,0,0,0,0,0,0,0,0,0,0,0
0,0,0,0,0,0,0,0,0,0,0,0,0,0,0,0,0,0,0,0,0
0,0,0,0,0,0,0,0,0,0,0,0,0,0,0,0,0,0,0,0,0
0,0,0,0,0,0,0,0,0,0,0,0,0,0,0,0,0,0,0,0,0
0,0,0,0,0,0,0,0,0,0,0,0,0,0,0,0,0,0,0,0,0
0,0,0,0,0,0,0,0,0,0,0,0,0,0,0,0,0,0,0,0,0
0,0,0,0,0,0,0,0,0,0,0,0,0,0,0,0,0,0,0,0,0
0,0,0,0,0,0,0,0,0,0,0,0,0,0,0,0,0,0,0,0,0
0,0,0,0,0,0,0,0,0,0,0,0,0,0,0,0,0,0,0,0,0
0,0,0,0,0,0,0,0,0,0,0,0,0,0,0,0,0,0,0,0,0
0,0,0,0,0,0,0,0,0,0,0,0,0,0,0,0,0,0,0,0,0
0,0,0,0,0,0,0,0,0,0,0,0,0,0,0,0,0,0,0,0,0
0,0,0,0,0,0,0,0,0,0,0,0,0,0,0,0,0,0,0,0,0
0,0,0,0,0,0,0,0,0,0,0,0,0,0,0,0,0,0,0,0,0
0,0,0,0,0,0,0,0,0,0,0,0,0,0,0,0,0,0,0,0,0
0,0,0,0,0,0,0,0,0,0,0,0,0,0,0,0,0,0,0,0,0
0,0,0,0,0,0,0,0,0,0,0,0,0,0,0,0,0,0,0,0,0
0,0,0,0,0,0,0,0,0,0,0,0,0,0,0,0,0,0,0,0,0
0,0,0,0,0,0,0,0,0,0,0,0,0,0,0,0,0,0,0,0,0
0,0,0,0,0,0,0,0,0,0,0,0,0,0,0,0,0,0,0,0,0
0,0,0,0,0,0,0,0,0,0,0,0,0,0,0,0,0,0,0,0,0
0,0,0,0,0,0,0,0,0,0,0,0,0,0,0,0,0,0,0,0,0
0,0,0,0,0,0,0,0,0,0,0,0,0,0,0,0,0,0,0,0,0
0,0,0,0,0,0,0,0,0,0,0,0,0,0,0,0,0,0,0,0,0
0,0,0,0,0,0,0,0,0,0,0,0,0,0,0,0,0,0,0,0,0
0,0,0,0,0,0,0,0,0,0,0,0,0,0,0,0,0,0,0,0,0
0,0,0,0,0,0,0,0,0,0,0,0,0,0,0,0,0,0,0,0,0
0,0,0,0,0,0,0,0,0,0,0,0,0,0,0,0,0,0,0,0,0
0,0,0,0,0,0,0,0,0,0,0,0,0,0,0,0,0,0,0,0,0
0,0,0,0,0,0,0,0,0,0,0,0,0,0,0,0,0,0,0,0,0
:endlayer

#### RULES ####
rule:
plugin=vanillaBlocks
number=1
data:
tag:
TAG=10={
TAG=8=blockName{dirt}
TAG=3=meta{0}
TAG=3=buildPass{0}
}
:endtag
:enddata
:endrule

rule:
plugin=vanillaBlocks
number=2
data:
tag:
TAG=10={
TAG=8=blockName{hay_block}
TAG=3=meta{0}
TAG=3=buildPass{0}
}
:endtag
:enddata
:endrule

rule:
plugin=vanillaBlocks
number=3
data:
tag:
TAG=10={
TAG=8=blockName{stonebrick}
TAG=3=meta{0}
TAG=3=buildPass{0}
}
:endtag
:enddata
:endrule

rule:
plugin=vanillaBlocks
number=4
data:
tag:
TAG=10={
TAG=8=blockName{cobblestone}
TAG=3=meta{0}
TAG=3=buildPass{0}
}
:endtag
:enddata
:endrule

rule:
plugin=vanillaBlocks
number=5
data:
tag:
TAG=10={
TAG=8=blockName{grass}
TAG=3=meta{0}
TAG=3=buildPass{0}
}
:endtag
:enddata
:endrule

rule:
plugin=vanillaBlocks
number=6
data:
tag:
TAG=10={
TAG=8=blockName{gravel}
TAG=3=meta{0}
TAG=3=buildPass{1}
}
:endtag
:enddata
:endrule

rule:
plugin=vanillaBlocks
number=7
data:
tag:
TAG=10={
TAG=8=blockName{netherrack}
TAG=3=meta{0}
TAG=3=buildPass{0}
}
:endtag
:enddata
:endrule

rule:
plugin=vanillaBlocks
number=8
data:
tag:
TAG=10={
TAG=8=blockName{farmland}
TAG=3=meta{0}
TAG=3=buildPass{0}
}
:endtag
:enddata
:endrule

rule:
plugin=vanillaBlocks
number=9
data:
tag:
TAG=10={
TAG=8=blockName{farmland}
TAG=3=meta{2}
TAG=3=buildPass{0}
}
:endtag
:enddata
:endrule

rule:
plugin=vanillaBlocks
number=10
data:
tag:
TAG=10={
TAG=8=blockName{tallgrass}
TAG=3=meta{1}
TAG=3=buildPass{0}
}
:endtag
:enddata
:endrule

rule:
plugin=vanillaBlocks
number=11
data:
tag:
TAG=10={
TAG=8=blockName{fence}
TAG=3=meta{0}
TAG=3=buildPass{0}
}
:endtag
:enddata
:endrule

rule:
plugin=vanillaBlocks
number=12
data:
tag:
TAG=10={
TAG=8=blockName{fence_gate}
TAG=3=meta{2}
TAG=3=buildPass{0}
}
:endtag
:enddata
:endrule

rule:
plugin=vanillaBlocks
number=13
data:
tag:
TAG=10={
TAG=8=blockName{log}
TAG=3=meta{0}
TAG=3=buildPass{0}
}
:endtag
:enddata
:endrule

rule:
plugin=vanillaBlocks
number=14
data:
tag:
TAG=10={
TAG=8=blockName{fire}
TAG=3=meta{15}
TAG=3=buildPass{0}
}
:endtag
:enddata
:endrule

rule:
plugin=vanillaBlocks
number=15
data:
tag:
TAG=10={
TAG=8=blockName{potatoes}
TAG=3=meta{7}
TAG=3=buildPass{1}
}
:endtag
:enddata
:endrule

rule:
plugin=vanillaBlocks
number=16
data:
tag:
TAG=10={
TAG=8=blockName{wooden_slab}
TAG=3=meta{9}
TAG=3=buildPass{0}
}
:endtag
:enddata
:endrule

rule:
plugin=vanillaBlocks
number=17
data:
tag:
TAG=10={
TAG=8=blockName{crafting_table}
TAG=3=meta{0}
TAG=3=buildPass{0}
}
:endtag
:enddata
:endrule

rule:
plugin=vanillaBlocks
number=18
data:
tag:
TAG=10={
TAG=8=blockName{stone_slab}
TAG=3=meta{0}
TAG=3=buildPass{0}
}
:endtag
:enddata
:endrule

rule:
plugin=vanillaBlocks
number=19
data:
tag:
TAG=10={
TAG=8=blockName{cauldron}
TAG=3=meta{3}
TAG=3=buildPass{0}
}
:endtag
:enddata
:endrule

rule:
plugin=vanillaInventory
number=20
data:
tag:
TAG=10={
TAG=3=lootLevel{0}
TAG=10=teData{
TAG=9=Items{
}
TAG=8=id{Chest}
}
TAG=8=blockName{chest}
TAG=3=meta{3}
TAG=3=buildPass{0}
}
:endtag
:enddata
:endrule

rule:
plugin=vanillaDoors
number=21
data:
tag:
TAG=10={
TAG=1=sideFlag{8}
TAG=8=blockName{wooden_door}
TAG=3=meta{1}
TAG=3=buildPass{1}
}
:endtag
:enddata
:endrule

rule:
plugin=vanillaInventory
number=22
data:
tag:
TAG=10={
TAG=3=lootLevel{0}
TAG=10=teData{
TAG=9=Items{
}
TAG=8=id{Chest}
}
TAG=8=blockName{chest}
TAG=3=meta{3}
TAG=3=buildPass{0}
}
:endtag
:enddata
:endrule

rule:
plugin=vanillaBlocks
number=23
data:
tag:
TAG=10={
TAG=8=blockName{oak_stairs}
TAG=3=meta{2}
TAG=3=buildPass{0}
}
:endtag
:enddata
:endrule

rule:
plugin=vanillaBlocks
number=24
data:
tag:
TAG=10={
TAG=8=blockName{planks}
TAG=3=meta{0}
TAG=3=buildPass{0}
}
:endtag
:enddata
:endrule

rule:
plugin=vanillaBlocks
number=25
data:
tag:
TAG=10={
TAG=8=blockName{ladder}
TAG=3=meta{3}
TAG=3=buildPass{1}
}
:endtag
:enddata
:endrule

rule:
plugin=vanillaDoors
number=26
data:
tag:
TAG=10={
TAG=1=sideFlag{8}
TAG=8=blockName{wooden_door}
TAG=3=meta{0}
TAG=3=buildPass{1}
}
:endtag
:enddata
:endrule

rule:
plugin=vanillaDoors
number=27
data:
tag:
TAG=10={
TAG=1=sideFlag{8}
TAG=8=blockName{wooden_door}
TAG=3=meta{3}
TAG=3=buildPass{1}
}
:endtag
:enddata
:endrule

rule:
plugin=vanillaBlocks
number=28
data:
tag:
TAG=10={
TAG=8=blockName{carrots}
TAG=3=meta{7}
TAG=3=buildPass{1}
}
:endtag
:enddata
:endrule

rule:
plugin=vanillaInventory
number=29
data:
tag:
TAG=10={
TAG=3=lootLevel{0}
TAG=10=teData{
TAG=9=Items{
}
TAG=8=id{Chest}
}
TAG=8=blockName{chest}
TAG=3=meta{3}
TAG=3=buildPass{0}
}
:endtag
:enddata
:endrule

rule:
plugin=vanillaInventory
number=30
data:
tag:
TAG=10={
TAG=3=lootLevel{0}
TAG=10=teData{
TAG=9=Items{
}
TAG=8=id{Chest}
}
TAG=8=blockName{chest}
TAG=3=meta{3}
TAG=3=buildPass{0}
}
:endtag
:enddata
:endrule

rule:
plugin=vanillaInventory
number=31
data:
tag:
TAG=10={
TAG=3=lootLevel{0}
TAG=10=teData{
TAG=9=Items{
}
TAG=8=id{Chest}
}
TAG=8=blockName{chest}
TAG=3=meta{3}
TAG=3=buildPass{0}
}
:endtag
:enddata
:endrule

rule:
plugin=vanillaInventory
number=32
data:
tag:
TAG=10={
TAG=3=lootLevel{0}
TAG=10=teData{
TAG=9=Items{
}
TAG=8=id{Chest}
}
TAG=8=blockName{chest}
TAG=3=meta{3}
TAG=3=buildPass{0}
}
:endtag
:enddata
:endrule

rule:
plugin=vanillaInventory
number=33
data:
tag:
TAG=10={
TAG=3=lootLevel{0}
TAG=10=teData{
TAG=9=Items{
}
TAG=8=id{Chest}
}
TAG=8=blockName{chest}
TAG=3=meta{3}
TAG=3=buildPass{0}
}
:endtag
:enddata
:endrule

rule:
plugin=vanillaBlocks
number=34
data:
tag:
TAG=10={
TAG=8=blockName{oak_stairs}
TAG=3=meta{3}
TAG=3=buildPass{0}
}
:endtag
:enddata
:endrule

rule:
plugin=vanillaInventory
number=35
data:
tag:
TAG=10={
TAG=3=lootLevel{0}
TAG=10=teData{
TAG=9=Items{
}
TAG=8=id{Chest}
}
TAG=8=blockName{chest}
TAG=3=meta{3}
TAG=3=buildPass{0}
}
:endtag
:enddata
:endrule

rule:
plugin=vanillaInventory
number=36
data:
tag:
TAG=10={
TAG=3=lootLevel{0}
TAG=10=teData{
TAG=9=Items{
}
TAG=8=id{Chest}
}
TAG=8=blockName{chest}
TAG=3=meta{3}
TAG=3=buildPass{0}
}
:endtag
:enddata
:endrule

rule:
plugin=vanillaInventory
number=37
data:
tag:
TAG=10={
TAG=3=lootLevel{0}
TAG=10=teData{
TAG=9=Items{
}
TAG=8=id{Chest}
}
TAG=8=blockName{chest}
TAG=3=meta{3}
TAG=3=buildPass{0}
}
:endtag
:enddata
:endrule

rule:
plugin=vanillaInventory
number=38
data:
tag:
TAG=10={
TAG=3=lootLevel{0}
TAG=10=teData{
TAG=9=Items{
}
TAG=8=id{Chest}
}
TAG=8=blockName{chest}
TAG=3=meta{5}
TAG=3=buildPass{0}
}
:endtag
:enddata
:endrule

rule:
plugin=vanillaInventory
number=39
data:
tag:
TAG=10={
TAG=3=lootLevel{0}
TAG=10=teData{
TAG=9=Items{
}
TAG=8=id{Chest}
}
TAG=8=blockName{chest}
TAG=3=meta{3}
TAG=3=buildPass{0}
}
:endtag
:enddata
:endrule

rule:
plugin=vanillaBlocks
number=40
data:
tag:
TAG=10={
TAG=8=blockName{torch}
TAG=3=meta{5}
TAG=3=buildPass{1}
}
:endtag
:enddata
:endrule

rule:
plugin=awAdvancedSpawner
number=41
data:
tag:
TAG=10={
TAG=10=teData{
TAG=9=Items{
}
TAG=8=id{Furnace}
TAG=2=BurnTime{0}
TAG=3=z{-196}
TAG=2=CookTime{0}
TAG=3=y{67}
TAG=3=x{225}
}
TAG=8=blockName{furnace}
TAG=3=meta{3}
TAG=3=buildPass{0}
}
:endtag
:enddata
:endrule

rule:
plugin=vanillaBlocks
number=42
data:
tag:
TAG=10={
TAG=8=blockName{iron_bars}
TAG=3=meta{0}
TAG=3=buildPass{0}
}
:endtag
:enddata
:endrule

rule:
plugin=awAdvancedSpawner
number=43
data:
tag:
TAG=10={
TAG=10=teData{
TAG=9=Items{
}
TAG=8=id{Furnace}
TAG=2=BurnTime{0}
TAG=3=z{-196}
TAG=2=CookTime{0}
TAG=3=y{67}
TAG=3=x{227}
}
TAG=8=blockName{furnace}
TAG=3=meta{4}
TAG=3=buildPass{0}
}
:endtag
:enddata
:endrule

rule:
plugin=vanillaDoors
number=44
data:
tag:
TAG=10={
TAG=1=sideFlag{0}
TAG=8=blockName{wooden_door}
TAG=3=meta{8}
TAG=3=buildPass{1}
}
:endtag
:enddata
:endrule

rule:
plugin=vanillaBlocks
number=45
data:
tag:
TAG=10={
TAG=8=blockName{glass_pane}
TAG=3=meta{0}
TAG=3=buildPass{0}
}
:endtag
:enddata
:endrule

rule:
plugin=vanillaDoors
number=46
data:
tag:
TAG=10={
TAG=1=sideFlag{0}
TAG=8=blockName{wooden_door}
TAG=3=meta{8}
TAG=3=buildPass{1}
}
:endtag
:enddata
:endrule

rule:
plugin=vanillaDoors
number=47
data:
tag:
TAG=10={
TAG=1=sideFlag{0}
TAG=8=blockName{wooden_door}
TAG=3=meta{8}
TAG=3=buildPass{1}
}
:endtag
:enddata
:endrule

rule:
plugin=vanillaBlocks
number=48
data:
tag:
TAG=10={
TAG=8=blockName{wooden_slab}
TAG=3=meta{8}
TAG=3=buildPass{0}
}
:endtag
:enddata
:endrule

rule:
plugin=vanillaBlocks
number=49
data:
tag:
TAG=10={
TAG=8=blockName{wooden_pressure_plate}
TAG=3=meta{0}
TAG=3=buildPass{0}
}
:endtag
:enddata
:endrule

rule:
plugin=vanillaBlocks
number=50
data:
tag:
TAG=10={
TAG=8=blockName{wooden_pressure_plate}
TAG=3=meta{1}
TAG=3=buildPass{0}
}
:endtag
:enddata
:endrule

rule:
plugin=vanillaBlocks
number=51
data:
tag:
TAG=10={
TAG=8=blockName{torch}
TAG=3=meta{1}
TAG=3=buildPass{1}
}
:endtag
:enddata
:endrule

rule:
plugin=vanillaBlocks
number=52
data:
tag:
TAG=10={
TAG=8=blockName{torch}
TAG=3=meta{4}
TAG=3=buildPass{1}
}
:endtag
:enddata
:endrule

rule:
plugin=vanillaBlocks
number=53
data:
tag:
TAG=10={
TAG=8=blockName{torch}
TAG=3=meta{3}
TAG=3=buildPass{1}
}
:endtag
:enddata
:endrule

rule:
plugin=vanillaBlocks
number=54
data:
tag:
TAG=10={
TAG=8=blockName{torch}
TAG=3=meta{2}
TAG=3=buildPass{1}
}
:endtag
:enddata
:endrule

rule:
plugin=vanillaInventory
number=55
data:
tag:
TAG=10={
TAG=3=lootLevel{0}
TAG=10=teData{
TAG=9=Items{
}
TAG=8=id{Chest}
}
TAG=8=blockName{chest}
TAG=3=meta{3}
TAG=3=buildPass{0}
}
:endtag
:enddata
:endrule

rule:
plugin=vanillaInventory
number=56
data:
tag:
TAG=10={
TAG=3=lootLevel{0}
TAG=10=teData{
TAG=9=Items{
}
TAG=8=id{Chest}
}
TAG=8=blockName{chest}
TAG=3=meta{3}
TAG=3=buildPass{0}
}
:endtag
:enddata
:endrule

rule:
plugin=vanillaInventory
number=57
data:
tag:
TAG=10={
TAG=3=lootLevel{0}
TAG=10=teData{
TAG=9=Items{
}
TAG=8=id{Chest}
}
TAG=8=blockName{chest}
TAG=3=meta{3}
TAG=3=buildPass{0}
}
:endtag
:enddata
:endrule

rule:
plugin=vanillaInventory
number=58
data:
tag:
TAG=10={
TAG=3=lootLevel{0}
TAG=10=teData{
TAG=9=Items{
}
TAG=8=id{Chest}
}
TAG=8=blockName{chest}
TAG=3=meta{3}
TAG=3=buildPass{0}
}
:endtag
:enddata
:endrule

rule:
plugin=vanillaInventory
number=59
data:
tag:
TAG=10={
TAG=3=lootLevel{0}
TAG=10=teData{
TAG=9=Items{
}
TAG=8=id{Chest}
}
TAG=8=blockName{chest}
TAG=3=meta{3}
TAG=3=buildPass{0}
}
:endtag
:enddata
:endrule

rule:
plugin=vanillaInventory
number=60
data:
tag:
TAG=10={
TAG=3=lootLevel{0}
TAG=10=teData{
TAG=9=Items{
}
TAG=8=id{Chest}
}
TAG=8=blockName{chest}
TAG=3=meta{3}
TAG=3=buildPass{0}
}
:endtag
:enddata
:endrule

rule:
plugin=vanillaInventory
number=61
data:
tag:
TAG=10={
TAG=3=lootLevel{0}
TAG=10=teData{
TAG=9=Items{
}
TAG=8=id{Chest}
}
TAG=8=blockName{chest}
TAG=3=meta{3}
TAG=3=buildPass{0}
}
:endtag
:enddata
:endrule

rule:
plugin=vanillaInventory
number=62
data:
tag:
TAG=10={
TAG=3=lootLevel{0}
TAG=10=teData{
TAG=9=Items{
}
TAG=8=id{Chest}
}
TAG=8=blockName{chest}
TAG=3=meta{3}
TAG=3=buildPass{0}
}
:endtag
:enddata
:endrule

rule:
plugin=vanillaBlocks
number=63
data:
tag:
TAG=10={
TAG=8=blockName{oak_stairs}
TAG=3=meta{1}
TAG=3=buildPass{0}
}
:endtag
:enddata
:endrule

rule:
plugin=vanillaBlocks
number=64
data:
tag:
TAG=10={
TAG=8=blockName{stonebrick}
TAG=3=meta{3}
TAG=3=buildPass{0}
}
:endtag
:enddata
:endrule

rule:
plugin=vanillaBlocks
number=65
data:
tag:
TAG=10={
TAG=8=blockName{stone_brick_stairs}
TAG=3=meta{0}
TAG=3=buildPass{0}
}
:endtag
:enddata
:endrule

rule:
plugin=vanillaBlocks
number=66
data:
tag:
TAG=10={
TAG=8=blockName{log}
TAG=3=meta{8}
TAG=3=buildPass{0}
}
:endtag
:enddata
:endrule

rule:
plugin=vanillaBlocks
number=67
data:
tag:
TAG=10={
TAG=8=blockName{oak_stairs}
TAG=3=meta{0}
TAG=3=buildPass{0}
}
:endtag
:enddata
:endrule

rule:
plugin=vanillaBlocks
number=68
data:
tag:
TAG=10={
TAG=8=blockName{stone_brick_stairs}
TAG=3=meta{1}
TAG=3=buildPass{0}
}
:endtag
:enddata
:endrule

rule:
plugin=vanillaBlocks
number=69
data:
tag:
TAG=10={
TAG=8=blockName{stone_brick_stairs}
TAG=3=meta{2}
TAG=3=buildPass{0}
}
:endtag
:enddata
:endrule

rule:
plugin=vanillaBlocks
number=70
data:
tag:
TAG=10={
TAG=8=blockName{stone_brick_stairs}
TAG=3=meta{3}
TAG=3=buildPass{0}
}
:endtag
:enddata
:endrule

rule:
plugin=vanillaBlocks
number=71
data:
tag:
TAG=10={
TAG=8=blockName{log}
TAG=3=meta{4}
TAG=3=buildPass{0}
}
:endtag
:enddata
:endrule

rule:
plugin=vanillaBlocks
number=72
data:
tag:
TAG=10={
TAG=8=blockName{trapped_chest}
TAG=3=meta{3}
TAG=3=buildPass{0}
}
:endtag
:enddata
:endrule

rule:
plugin=vanillaBlocks
number=73
data:
tag:
TAG=10={
TAG=8=blockName{bed}
TAG=3=meta{11}
TAG=3=buildPass{0}
}
:endtag
:enddata
:endrule

rule:
plugin=vanillaBlocks
number=74
data:
tag:
TAG=10={
TAG=8=blockName{planks}
TAG=3=meta{2}
TAG=3=buildPass{0}
}
:endtag
:enddata
:endrule

rule:
plugin=vanillaBlocks
number=75
data:
tag:
TAG=10={
TAG=8=blockName{trapped_chest}
TAG=3=meta{4}
TAG=3=buildPass{0}
}
:endtag
:enddata
:endrule

rule:
plugin=vanillaBlocks
number=76
data:
tag:
TAG=10={
TAG=8=blockName{bed}
TAG=3=meta{3}
TAG=3=buildPass{0}
}
:endtag
:enddata
:endrule

rule:
plugin=vanillaBlocks
number=77
data:
tag:
TAG=10={
TAG=8=blockName{bed}
TAG=3=meta{1}
TAG=3=buildPass{0}
}
:endtag
:enddata
:endrule

rule:
plugin=vanillaBlocks
number=78
data:
tag:
TAG=10={
TAG=8=blockName{bed}
TAG=3=meta{9}
TAG=3=buildPass{0}
}
:endtag
:enddata
:endrule

rule:
plugin=vanillaBlocks
number=79
data:
tag:
TAG=10={
TAG=8=blockName{oak_stairs}
TAG=3=meta{6}
TAG=3=buildPass{0}
}
:endtag
:enddata
:endrule

rule:
plugin=vanillaBlocks
number=80
data:
tag:
TAG=10={
TAG=8=blockName{oak_stairs}
TAG=3=meta{7}
TAG=3=buildPass{0}
}
:endtag
:enddata
:endrule

rule:
plugin=vanillaBlocks
number=81
data:
tag:
TAG=10={
TAG=8=blockName{cobblestone_wall}
TAG=3=meta{0}
TAG=3=buildPass{0}
}
:endtag
:enddata
:endrule

#### ENTITIES ####
entity:
plugin=vanillaEntities
number=0
data:
position=16,2,3
tag:
TAG=10={
TAG=5=yOffset{0.0}
TAG=5=xOffset{0.85}
TAG=5=zOffset{0.775}
TAG=8=mobID{Chicken}
TAG=5=rotation{135.47029}
}
:endtag
:enddata
:endentity

entity:
plugin=vanillaEntities
number=1
data:
position=13,2,3
tag:
TAG=10={
TAG=5=yOffset{0.0}
TAG=5=xOffset{0.22500002}
TAG=5=zOffset{0.775}
TAG=8=mobID{Chicken}
TAG=5=rotation{225.0}
}
:endtag
:enddata
:endentity

entity:
plugin=vanillaEntities
number=2
data:
position=15,2,3
tag:
TAG=10={
TAG=5=yOffset{0.0}
TAG=5=xOffset{0.775}
TAG=5=zOffset{0.775}
TAG=8=mobID{Chicken}
TAG=5=rotation{135.0}
}
:endtag
:enddata
:endentity

entity:
plugin=vanillaEntities
number=3
data:
position=16,2,3
tag:
TAG=10={
TAG=5=yOffset{0.0}
TAG=5=xOffset{0.34784353}
TAG=5=zOffset{0.775}
TAG=8=mobID{Chicken}
TAG=5=rotation{-170.16449}
}
:endtag
:enddata
:endentity

entity:
plugin=vanillaEntities
number=4
data:
position=17,2,4
tag:
TAG=10={
TAG=5=yOffset{0.0}
TAG=5=xOffset{0.22500002}
TAG=5=zOffset{0.49999467}
TAG=8=mobID{Chicken}
TAG=5=rotation{270.00024}
}
:endtag
:enddata
:endentity

entity:
plugin=vanillaEntities
number=5
data:
position=16,2,4
tag:
TAG=10={
TAG=5=yOffset{0.0}
TAG=5=xOffset{0.45591486}
TAG=5=zOffset{0.6357811}
TAG=8=mobID{Chicken}
TAG=5=rotation{-145.34338}
}
:endtag
:enddata
:endentity

entity:
plugin=vanillaEntities
number=6
data:
position=16,2,5
tag:
TAG=10={
TAG=5=yOffset{0.0}
TAG=5=xOffset{0.5064586}
TAG=5=zOffset{0.5266967}
TAG=8=mobID{Chicken}
TAG=5=rotation{-181.45221}
}
:endtag
:enddata
:endentity

entity:
plugin=vanillaEntities
number=7
data:
position=16,2,10
tag:
TAG=10={
TAG=5=yOffset{0.0}
TAG=5=xOffset{0.5005187}
TAG=5=zOffset{0.5194783}
TAG=8=mobID{Chicken}
TAG=5=rotation{179.87978}
}
:endtag
:enddata
:endentity

entity:
plugin=vanillaEntities
number=8
data:
position=12,2,3
tag:
TAG=10={
TAG=5=yOffset{0.0}
TAG=5=xOffset{0.49988317}
TAG=5=zOffset{0.775}
TAG=8=mobID{Chicken}
TAG=5=rotation{180.00523}
}
:endtag
:enddata
:endentity

entity:
plugin=vanillaEntities
number=9
data:
position=9,2,3
tag:
TAG=10={
TAG=5=yOffset{0.0}
TAG=5=xOffset{0.775}
TAG=5=zOffset{0.775}
TAG=8=mobID{Chicken}
TAG=5=rotation{135.0}
}
:endtag
:enddata
:endentity

entity:
plugin=vanillaEntities
number=10
data:
position=4,2,3
tag:
TAG=10={
TAG=5=yOffset{0.0}
TAG=5=xOffset{0.656021}
TAG=5=zOffset{0.775}
TAG=8=mobID{Chicken}
TAG=5=rotation{172.67805}
}
:endtag
:enddata
:endentity

entity:
plugin=vanillaEntities
number=11
data:
position=7,2,3
tag:
TAG=10={
TAG=5=yOffset{0.0}
TAG=5=xOffset{0.775}
TAG=5=zOffset{0.775}
TAG=8=mobID{Chicken}
TAG=5=rotation{135.0}
}
:endtag
:enddata
:endentity

entity:
plugin=vanillaEntities
number=12
data:
position=5,2,3
tag:
TAG=10={
TAG=5=yOffset{0.0}
TAG=5=xOffset{0.22500002}
TAG=5=zOffset{0.775}
TAG=8=mobID{Chicken}
TAG=5=rotation{225.0}
}
:endtag
:enddata
:endentity

entity:
plugin=vanillaEntities
number=13
data:
position=4,2,3
tag:
TAG=10={
TAG=5=yOffset{0.0}
TAG=5=xOffset{0.14999998}
TAG=5=zOffset{0.775}
TAG=8=mobID{Chicken}
TAG=5=rotation{220.71135}
}
:endtag
:enddata
:endentity

entity:
plugin=vanillaEntities
number=14
data:
position=8,2,3
tag:
TAG=10={
TAG=5=yOffset{0.0}
TAG=5=xOffset{0.49987918}
TAG=5=zOffset{0.775}
TAG=8=mobID{Chicken}
TAG=5=rotation{180.00543}
}
:endtag
:enddata
:endentity

entity:
plugin=vanillaEntities
number=15
data:
position=9,2,3
tag:
TAG=10={
TAG=5=yOffset{0.0}
TAG=5=xOffset{0.22500002}
TAG=5=zOffset{0.775}
TAG=8=mobID{Chicken}
TAG=5=rotation{224.99998}
}
:endtag
:enddata
:endentity

entity:
plugin=vanillaEntities
number=16
data:
position=11,2,3
tag:
TAG=10={
TAG=5=yOffset{0.0}
TAG=5=xOffset{0.775}
TAG=5=zOffset{0.775}
TAG=8=mobID{Chicken}
TAG=5=rotation{135.0}
}
:endtag
:enddata
:endentity

entity:
plugin=vanillaEntities
number=17
data:
position=3,2,6
tag:
TAG=10={
TAG=5=yOffset{0.0}
TAG=5=xOffset{0.775}
TAG=5=zOffset{0.50011736}
TAG=8=mobID{Chicken}
TAG=5=rotation{90.00527}
}
:endtag
:enddata
:endentity

entity:
plugin=vanillaEntities
number=18
data:
position=3,2,4
tag:
TAG=10={
TAG=5=yOffset{0.0}
TAG=5=xOffset{0.775}
TAG=5=zOffset{0.49862385}
TAG=8=mobID{Chicken}
TAG=5=rotation{89.93526}
}
:endtag
:enddata
:endentity

entity:
plugin=vanillaEntities
number=19
data:
position=7,2,4
tag:
TAG=10={
TAG=5=yOffset{0.0}
TAG=5=xOffset{0.775}
TAG=5=zOffset{0.49988467}
TAG=8=mobID{Chicken}
TAG=5=rotation{-270.0052}
}
:endtag
:enddata
:endentity

entity:
plugin=vanillaEntities
number=20
data:
position=4,2,4
tag:
TAG=10={
TAG=5=yOffset{0.0}
TAG=5=xOffset{0.51812226}
TAG=5=zOffset{0.57765156}
TAG=8=mobID{Chicken}
TAG=5=rotation{-183.39163}
}
:endtag
:enddata
:endentity

entity:
plugin=vanillaEntities
number=21
data:
position=3,2,5
tag:
TAG=10={
TAG=5=yOffset{0.0}
TAG=5=xOffset{0.775}
TAG=5=zOffset{0.051049434}
TAG=8=mobID{Chicken}
TAG=5=rotation{136.83768}
}
:endtag
:enddata
:endentity

entity:
plugin=vanillaEntities
number=22
data:
position=8,2,4
tag:
TAG=10={
TAG=5=yOffset{0.0}
TAG=5=xOffset{0.500111}
TAG=5=zOffset{0.55479187}
TAG=8=mobID{Chicken}
TAG=5=rotation{-180.0224}
}
:endtag
:enddata
:endentity

entity:
plugin=vanillaEntities
number=23
data:
position=10,2,4
tag:
TAG=10={
TAG=5=yOffset{0.0}
TAG=5=xOffset{0.500003}
TAG=5=zOffset{0.5573036}
TAG=8=mobID{Chicken}
TAG=5=rotation{-180.00049}
}
:endtag
:enddata
:endentity

entity:
plugin=vanillaEntities
number=24
data:
position=12,2,7
tag:
TAG=10={
TAG=5=yOffset{0.0}
TAG=5=xOffset{0.49998116}
TAG=5=zOffset{0.532314}
TAG=8=mobID{Chicken}
TAG=5=rotation{-179.9956}
}
:endtag
:enddata
:endentity

entity:
plugin=vanillaEntities
number=25
data:
position=13,2,17
tag:
TAG=10={
TAG=5=yOffset{0.0}
TAG=5=xOffset{0.22500002}
TAG=5=zOffset{0.49999952}
TAG=8=mobID{Chicken}
TAG=5=rotation{270.00003}
}
:endtag
:enddata
:endentity

entity:
plugin=vanillaEntities
number=26
data:
position=17,2,13
tag:
TAG=10={
TAG=5=yOffset{0.0}
TAG=5=xOffset{0.3}
TAG=5=zOffset{0.4999943}
TAG=8=mobID{Chicken}
TAG=5=rotation{270.00165}
}
:endtag
:enddata
:endentity

entity:
plugin=vanillaEntities
number=27
data:
position=17,2,12
tag:
TAG=10={
TAG=5=yOffset{0.0}
TAG=5=xOffset{0.22500002}
TAG=5=zOffset{0.5000005}
TAG=8=mobID{Chicken}
TAG=5=rotation{-90.000015}
}
:endtag
:enddata
:endentity

entity:
plugin=vanillaEntities
number=28
data:
position=16,2,16
tag:
TAG=10={
TAG=5=yOffset{0.0}
TAG=5=xOffset{0.5426522}
TAG=5=zOffset{0.5900042}
TAG=8=mobID{Chicken}
TAG=5=rotation{-192.02417}
}
:endtag
:enddata
:endentity

entity:
plugin=vanillaEntities
number=29
data:
position=4,2,12
tag:
TAG=10={
TAG=5=yOffset{0.0}
TAG=5=xOffset{0.507134}
TAG=5=zOffset{0.8093084}
TAG=8=mobID{Chicken}
TAG=5=rotation{180.00073}
}
:endtag
:enddata
:endentity

entity:
plugin=vanillaEntities
number=30
data:
position=9,2,13
tag:
TAG=10={
TAG=5=yOffset{0.0}
TAG=5=xOffset{0.22500002}
TAG=5=zOffset{0.49946427}
TAG=8=mobID{Chicken}
TAG=5=rotation{270.0251}
}
:endtag
:enddata
:endentity

entity:
plugin=vanillaEntities
number=31
data:
position=12,2,18
tag:
TAG=10={
TAG=5=yOffset{0.0}
TAG=5=xOffset{0.5007836}
TAG=5=zOffset{0.44190145}
TAG=8=mobID{Chicken}
TAG=5=rotation{0.15637207}
}
:endtag
:enddata
:endentity

entity:
plugin=vanillaEntities
number=32
data:
position=4,2,11
tag:
TAG=10={
TAG=5=yOffset{0.0}
TAG=5=xOffset{0.37334907}
TAG=5=zOffset{0.43582088}
TAG=8=mobID{Chicken}
TAG=5=rotation{189.55646}
}
:endtag
:enddata
:endentity

entity:
plugin=vanillaLogicEntity
number=33
data:
position=2,2,23
tag:
TAG=10={
TAG=10=entityData{
TAG=9=DropChances{
TAG=5=0{0.085}
TAG=5=1{0.085}
TAG=5=2{0.085}
TAG=5=3{0.085}
TAG=5=4{0.085}
}
TAG=3=Age{0}
TAG=9=Attributes{
TAG=10={
TAG=8=Name{generic.maxHealth}
TAG=6=Base{20.0}
}
TAG=10={
TAG=8=Name{generic.knockbackResistance}
TAG=6=Base{0.0}
}
TAG=10={
TAG=8=Name{generic.movementSpeed}
TAG=6=Base{0.5}
}
TAG=10={
TAG=8=Name{generic.followRange}
TAG=6=Base{16.0}
TAG=9=Modifiers{
TAG=10={
TAG=8=Name{Random spawn bonus}
TAG=4=UUIDLeast{-5596453183755396320}
TAG=3=Operation{1}
TAG=6=Amount{-0.006193224427511125}
TAG=4=UUIDMost{2734287054531609555}
}
}
}
}
TAG=9=Motion{
TAG=6={0.04133426724665279}
TAG=6={-0.0784000015258789}
TAG=6={-0.0247102121206062}
}
TAG=8=CustomName{}
TAG=2=Health{20}
TAG=5=HealF{20.0}
TAG=1=CustomNameVisible{0}
TAG=3=Riches{0}
TAG=2=AttackTime{0}
TAG=2=Fire{-1}
TAG=1=Invulnerable{0}
TAG=2=DeathTime{0}
TAG=10=ForgeData{
TAG=1=MP|Init{1}
}
TAG=5=AbsorptionAmount{0.0}
TAG=9=Equipment{
TAG=10={
}
TAG=10={
}
TAG=10={
}
TAG=10={
}
TAG=10={
}
}
TAG=1=OnGround{1}
TAG=2=HurtTime{0}
TAG=3=Profession{44}
TAG=3=Dimension{0}
TAG=2=Air{300}
TAG=9=Pos{
TAG=6={220.37846995866366}
TAG=6={66.0}
TAG=6={-181.5371697744253}
}
TAG=1=CanPickUpLoot{0}
TAG=3=PortalCooldown{0}
TAG=1=PersistenceRequired{0}
TAG=1=Leashed{0}
TAG=5=FallDistance{0.0}
TAG=9=Rotation{
TAG=5={-1560.8738}
TAG=5={0.0}
}
}
TAG=5=yOffset{0.0}
TAG=5=xOffset{0.53716975}
TAG=5=zOffset{0.37846994}
TAG=8=mobID{Villager}
TAG=5=rotation{-30.87378}
}
:endtag
:enddata
:endentity

entity:
plugin=vanillaEntities
number=34
data:
position=9,2,11
tag:
TAG=10={
TAG=5=yOffset{0.0}
TAG=5=xOffset{0.22500002}
TAG=5=zOffset{0.49988297}
TAG=8=mobID{Chicken}
TAG=5=rotation{270.00525}
}
:endtag
:enddata
:endentity

entity:
plugin=vanillaEntities
number=35
data:
position=8,2,16
tag:
TAG=10={
TAG=5=yOffset{0.0}
TAG=5=xOffset{0.41977698}
TAG=5=zOffset{0.41398346}
TAG=8=mobID{Chicken}
TAG=5=rotation{324.3419}
}
:endtag
:enddata
:endentity

entity:
plugin=vanillaLogicEntity
number=36
data:
position=5,2,32
tag:
TAG=10={
TAG=10=entityData{
TAG=9=DropChances{
TAG=5=0{0.085}
TAG=5=1{0.085}
TAG=5=2{0.085}
TAG=5=3{0.085}
TAG=5=4{0.085}
}
TAG=3=Age{0}
TAG=9=Attributes{
TAG=10={
TAG=8=Name{generic.maxHealth}
TAG=6=Base{20.0}
}
TAG=10={
TAG=8=Name{generic.knockbackResistance}
TAG=6=Base{0.0}
}
TAG=10={
TAG=8=Name{generic.movementSpeed}
TAG=6=Base{0.5}
}
TAG=10={
TAG=8=Name{generic.followRange}
TAG=6=Base{16.0}
TAG=9=Modifiers{
TAG=10={
TAG=8=Name{Random spawn bonus}
TAG=4=UUIDLeast{-4993138084840671435}
TAG=3=Operation{1}
TAG=6=Amount{-0.006178422409951753}
TAG=4=UUIDMost{1111821232161113282}
}
}
}
}
TAG=9=Motion{
TAG=6={0.0}
TAG=6={-0.0784000015258789}
TAG=6={0.0}
}
TAG=8=CustomName{}
TAG=2=Health{20}
TAG=5=HealF{20.0}
TAG=1=CustomNameVisible{0}
TAG=3=Riches{0}
TAG=2=AttackTime{0}
TAG=2=Fire{-1}
TAG=1=Invulnerable{0}
TAG=2=DeathTime{0}
TAG=10=ForgeData{
TAG=1=MP|Init{1}
}
TAG=5=AbsorptionAmount{0.0}
TAG=9=Equipment{
TAG=10={
}
TAG=10={
}
TAG=10={
}
TAG=10={
}
TAG=10={
}
}
TAG=1=OnGround{1}
TAG=2=HurtTime{0}
TAG=3=Profession{2435}
TAG=3=Dimension{0}
TAG=2=Air{300}
TAG=9=Pos{
TAG=6={229.07499998807907}
TAG=6={66.5}
TAG=6={-184.50000498525498}
}
TAG=1=CanPickUpLoot{0}
TAG=3=PortalCooldown{0}
TAG=1=PersistenceRequired{0}
TAG=1=Leashed{0}
TAG=5=FallDistance{0.0}
TAG=9=Rotation{
TAG=5={2790.0002}
TAG=5={0.0}
}
}
TAG=5=yOffset{0.5}
TAG=5=xOffset{0.500005}
TAG=5=zOffset{0.07499999}
TAG=8=mobID{Villager}
TAG=5=rotation{2.4414062E-4}
}
:endtag
:enddata
:endentity

