# Ancient Warfare Structure Template File
# auto-generated structure file. created on: 4/16/2014 at: 5:48:30
# Lines beginning with # denote comments

header:
version=2.0
name=CivLightHouseMOH
size=10,38,15
offset=7,0,14
:endheader

#### VALIDATION ####
validation:
type=ground
survival=false
worldGenEnabled=true
unique=false
preserveBlocks=false
selectionWeight=30
clusterValue=10
minDuplicateDistance=120
dimensionWhiteList=false
dimensionList=
biomeWhiteList=true
biomeList=beach
leveling=9
fill=6
border=6
validTargetBlocks=water,sand,flowing_water,tile.grass,tile.sand,tile.clay,tile.dirt,tile.stone,tile.gravel,tile.sandStone,tile.oreIron,tile.oreCoal
data:
:enddata
:endvalidation

#### LAYERS ####
layer: 0
2,2,2,2,2,2,2,2,2,2
2,2,2,2,2,2,2,2,2,2
2,2,2,2,2,2,2,2,2,2
2,2,2,2,2,2,2,2,2,2
2,2,2,2,2,2,2,2,2,2
2,2,2,2,2,2,2,2,2,2
2,2,2,2,2,2,2,2,2,2
2,2,2,2,2,2,2,2,2,2
2,2,2,2,2,2,2,2,2,2
2,2,2,2,2,2,2,2,2,2
2,2,2,2,2,2,2,2,2,2
2,2,2,2,2,2,2,2,2,2
2,2,2,2,2,2,2,2,2,2
2,2,2,2,2,2,2,2,2,2
2,2,2,2,2,2,2,2,2,2
:endlayer
layer: 1
3,3,3,3,3,3,3,3,3,3
3,3,3,3,3,3,3,3,3,3
3,3,3,3,3,3,3,3,3,3
3,3,3,3,3,3,3,3,3,3
3,3,3,3,3,3,3,3,3,3
3,3,3,3,3,3,3,3,3,3
3,3,3,3,3,3,3,3,3,3
3,3,3,3,3,3,3,3,3,3
3,3,3,3,3,3,3,3,3,3
3,3,3,3,3,3,3,3,3,3
2,3,3,3,3,3,3,3,3,2
2,3,3,3,3,3,3,3,3,2
2,3,3,3,3,3,3,3,3,2
2,3,3,3,3,3,6,0,0,0
2,3,3,3,3,2,2,0,0,0
:endlayer
layer: 2
3,3,4,4,4,4,3,3,3,3
3,4,0,0,0,0,4,3,3,3
3,4,0,0,0,0,4,3,3,3
3,4,0,0,0,0,4,3,3,3
3,4,0,0,0,0,4,3,3,3
4,0,0,0,0,0,3,3,3,3
4,0,0,0,0,0,3,3,3,3
3,3,3,3,3,3,3,3,3,3
3,3,3,3,3,3,3,3,3,3
3,3,3,3,3,3,3,3,3,3
0,3,3,3,3,3,3,3,3,0
0,3,3,3,3,3,3,3,3,0
0,3,3,3,3,3,3,3,3,0
0,3,3,3,3,6,0,0,0,0
0,3,3,3,3,0,0,0,0,0
:endlayer
layer: 3
0,0,5,5,5,5,5,5,0,0
0,5,0,0,0,0,4,3,5,0
5,4,0,0,0,0,4,3,3,5
5,4,0,0,0,0,4,3,3,5
5,4,0,0,0,0,4,11,11,5
5,0,0,0,0,0,0,0,0,5
5,0,0,0,0,0,0,0,0,5
5,0,0,0,0,0,0,0,0,5
0,5,0,0,0,0,0,0,5,0
0,9,5,5,19,19,5,5,9,0
0,9,0,0,0,0,0,0,9,0
0,9,0,0,0,0,0,0,9,0
0,9,0,0,0,9,9,9,9,0
0,9,0,0,0,0,0,0,0,0
0,9,9,9,9,0,0,0,0,0
:endlayer
layer: 4
0,0,5,5,5,5,4,5,0,0
0,5,0,0,0,0,4,3,5,0
5,4,0,0,0,0,4,3,3,5
4,4,0,0,0,0,4,11,11,5
5,4,0,0,0,0,4,0,0,5
5,0,0,0,0,0,0,0,0,5
5,0,0,0,0,0,0,0,0,8
5,0,0,0,0,0,0,0,0,5
0,5,0,0,0,0,0,0,5,0
0,0,5,5,20,20,5,5,0,0
0,0,0,0,0,0,0,0,0,0
0,0,0,0,0,0,0,0,0,0
0,0,0,0,0,0,0,0,0,0
0,0,0,0,0,0,0,0,0,0
0,0,0,0,0,0,0,0,0,0
:endlayer
layer: 5
0,0,5,5,5,5,4,5,0,0
0,5,3,3,3,6,0,0,5,0
5,4,3,3,3,6,0,0,0,5
4,4,3,3,3,3,3,0,0,5
5,4,4,4,4,4,4,0,0,5
5,13,0,0,0,0,0,0,14,5
5,0,0,0,0,0,0,0,0,8
5,0,0,0,0,0,0,0,0,5
0,5,0,0,0,0,0,0,5,0
0,0,5,5,21,21,5,5,0,0
0,0,0,0,0,0,0,0,0,0
0,0,0,0,0,0,0,0,0,0
0,0,0,0,0,0,0,0,0,0
0,0,0,0,0,0,0,0,0,0
0,0,0,0,0,0,0,0,0,0
:endlayer
layer: 6
0,0,5,5,5,5,5,5,0,0
0,5,0,0,0,0,0,0,5,0
5,3,0,0,0,0,0,0,0,5
5,3,0,0,3,3,0,0,0,5
5,3,12,12,3,0,0,0,0,5
5,0,0,0,0,0,0,0,0,5
5,0,0,0,0,0,0,0,0,5
5,0,0,0,0,0,0,0,0,5
0,5,0,0,0,0,0,0,5,0
0,0,5,5,5,5,5,5,0,0
0,0,0,0,0,0,0,0,0,0
0,0,0,0,0,0,0,0,0,0
0,0,0,0,0,0,0,0,0,0
0,0,0,0,0,0,0,0,0,0
0,0,0,0,0,0,0,0,0,0
:endlayer
layer: 7
0,0,5,5,5,5,5,5,0,0
0,5,0,0,0,7,0,0,5,0
5,3,0,0,0,0,0,0,0,5
5,3,0,0,0,0,0,0,0,5
5,3,0,0,3,0,0,0,0,5
5,3,12,12,3,0,0,0,0,5
5,3,3,3,0,0,0,0,0,5
5,3,3,3,0,0,0,0,0,5
0,5,3,3,0,0,0,0,5,0
0,0,5,5,5,5,5,5,0,0
0,0,0,0,0,0,0,0,0,0
0,0,0,0,0,0,0,0,0,0
0,0,0,0,0,0,0,0,0,0
0,0,0,0,0,0,0,0,0,0
0,0,0,0,0,0,0,0,0,0
:endlayer
layer: 8
0,0,4,4,4,4,4,4,0,0
0,4,0,0,0,0,0,5,4,0
4,5,0,0,0,0,0,5,5,4
4,5,0,0,0,0,0,0,5,4
4,5,0,0,0,0,0,0,5,4
4,5,0,0,3,0,0,0,5,4
4,5,0,0,3,0,0,0,5,4
4,5,5,0,16,0,0,5,5,4
0,4,5,5,5,5,5,5,4,0
0,0,4,4,4,4,4,4,0,0
0,0,0,0,0,0,0,0,0,0
0,0,0,0,0,0,0,0,0,0
0,0,0,0,0,0,0,0,0,0
0,0,0,0,0,0,0,0,0,0
0,0,0,0,0,0,0,0,0,0
:endlayer
layer: 9
0,0,0,0,0,0,0,0,0,0
0,0,5,5,5,5,5,5,0,0
0,5,5,0,0,0,0,5,5,0
0,5,0,0,0,0,0,0,5,0
0,5,13,0,0,0,0,0,5,0
0,5,0,0,3,3,0,0,5,0
0,5,0,0,3,3,3,3,5,0
0,5,5,0,0,16,3,5,5,0
0,0,5,5,5,5,5,5,0,0
0,0,0,0,0,0,0,0,0,0
0,0,0,0,0,0,0,0,0,0
0,0,0,0,0,0,0,0,0,0
0,0,0,0,0,0,0,0,0,0
0,0,0,0,0,0,0,0,0,0
0,0,0,0,0,0,0,0,0,0
:endlayer
layer: 10
0,0,0,0,0,0,0,0,0,0
0,0,5,5,5,8,5,5,0,0
0,5,5,0,0,0,0,5,5,0
0,5,0,0,0,0,0,0,5,0
0,8,0,0,0,0,0,0,5,0
0,5,0,0,3,3,3,11,8,0
0,5,0,0,3,3,0,0,5,0
0,5,5,0,7,0,0,5,5,0
0,0,5,5,8,5,5,5,0,0
0,0,0,0,0,0,0,0,0,0
0,0,0,0,0,0,0,0,0,0
0,0,0,0,0,0,0,0,0,0
0,0,0,0,0,0,0,0,0,0
0,0,0,0,0,0,0,0,0,0
0,0,0,0,0,0,0,0,0,0
:endlayer
layer: 11
0,0,0,0,0,0,0,0,0,0
0,0,5,5,5,8,5,5,0,0
0,5,5,3,3,3,3,5,5,0
0,5,0,3,3,3,3,3,5,0
0,8,0,3,3,3,3,11,5,0
0,5,0,3,3,3,3,0,8,0
0,5,0,3,3,3,0,0,5,0
0,5,5,0,0,0,0,5,5,0
0,0,5,5,8,5,5,5,0,0
0,0,0,0,0,0,0,0,0,0
0,0,0,0,0,0,0,0,0,0
0,0,0,0,0,0,0,0,0,0
0,0,0,0,0,0,0,0,0,0
0,0,0,0,0,0,0,0,0,0
0,0,0,0,0,0,0,0,0,0
:endlayer
layer: 12
0,0,0,0,0,0,0,0,0,0
0,0,5,5,5,5,5,5,0,0
0,5,5,0,0,0,0,5,5,0
0,5,3,0,0,0,0,0,5,0
0,5,3,0,0,3,3,0,5,0
0,5,3,0,0,16,3,0,5,0
0,5,3,3,3,3,0,0,5,0
0,5,5,3,3,3,0,5,5,0
0,0,5,5,5,5,5,5,0,0
0,0,0,0,0,0,0,0,0,0
0,0,0,0,0,0,0,0,0,0
0,0,0,0,0,0,0,0,0,0
0,0,0,0,0,0,0,0,0,0
0,0,0,0,0,0,0,0,0,0
0,0,0,0,0,0,0,0,0,0
:endlayer
layer: 13
0,0,0,0,0,0,0,0,0,0
0,0,5,5,5,5,5,5,0,0
0,5,5,0,0,7,0,5,5,0
0,5,3,0,0,0,0,0,5,0
0,5,3,0,0,6,0,14,5,0
0,5,3,0,0,0,0,0,5,0
0,5,3,3,3,3,3,0,5,0
0,5,5,3,3,3,3,5,5,0
0,0,5,5,5,5,5,5,0,0
0,0,0,0,0,0,0,0,0,0
0,0,0,0,0,0,0,0,0,0
0,0,0,0,0,0,0,0,0,0
0,0,0,0,0,0,0,0,0,0
0,0,0,0,0,0,0,0,0,0
0,0,0,0,0,0,0,0,0,0
:endlayer
layer: 14
0,0,0,0,0,0,0,0,0,0
0,0,4,4,4,4,4,4,0,0
0,4,4,5,5,5,5,4,4,0
0,4,5,5,3,3,5,5,4,0
0,4,5,3,6,0,0,5,4,0
0,4,5,3,0,17,0,5,4,0
0,4,5,5,3,3,5,5,4,0
0,4,4,5,5,5,5,4,4,0
0,0,4,4,4,4,4,4,0,0
0,0,0,0,0,0,0,0,0,0
0,0,0,0,0,0,0,0,0,0
0,0,0,0,0,0,0,0,0,0
0,0,0,0,0,0,0,0,0,0
0,0,0,0,0,0,0,0,0,0
0,0,0,0,0,0,0,0,0,0
:endlayer
layer: 15
0,0,0,0,0,0,0,0,0,0
0,0,0,0,0,0,0,0,0,0
0,0,4,5,5,5,5,4,0,0
0,0,5,5,4,4,5,5,0,0
0,0,5,0,0,0,7,5,0,0
0,0,5,0,16,0,0,5,0,0
0,0,5,5,3,3,5,5,0,0
0,0,4,5,5,5,5,4,0,0
0,0,0,0,0,0,0,0,0,0
0,0,0,0,0,0,0,0,0,0
0,0,0,0,0,0,0,0,0,0
0,0,0,0,0,0,0,0,0,0
0,0,0,0,0,0,0,0,0,0
0,0,0,0,0,0,0,0,0,0
0,0,0,0,0,0,0,0,0,0
:endlayer
layer: 16
0,0,0,0,0,0,0,0,0,0
0,0,0,0,0,0,0,0,0,0
0,0,4,5,8,5,5,4,0,0
0,0,5,5,0,4,5,5,0,0
0,0,5,0,0,0,3,8,0,0
0,0,8,0,0,16,3,5,0,0
0,0,5,5,4,4,5,5,0,0
0,0,4,5,5,4,5,4,0,0
0,0,0,0,0,0,0,0,0,0
0,0,0,0,0,0,0,0,0,0
0,0,0,0,0,0,0,0,0,0
0,0,0,0,0,0,0,0,0,0
0,0,0,0,0,0,0,0,0,0
0,0,0,0,0,0,0,0,0,0
0,0,0,0,0,0,0,0,0,0
:endlayer
layer: 17
0,0,0,0,0,0,0,0,0,0
0,0,0,0,0,0,0,0,0,0
0,0,4,5,8,5,5,4,0,0
0,0,5,5,0,4,5,5,0,0
0,0,5,0,0,4,0,8,0,0
0,0,8,0,0,0,0,5,0,0
0,0,5,5,17,0,5,5,0,0
0,0,4,5,5,8,5,4,0,0
0,0,0,0,0,0,0,0,0,0
0,0,0,0,0,0,0,0,0,0
0,0,0,0,0,0,0,0,0,0
0,0,0,0,0,0,0,0,0,0
0,0,0,0,0,0,0,0,0,0
0,0,0,0,0,0,0,0,0,0
0,0,0,0,0,0,0,0,0,0
:endlayer
layer: 18
0,0,0,0,0,0,0,0,0,0
0,0,0,0,0,0,0,0,0,0
0,0,4,5,5,5,5,4,0,0
0,0,5,5,3,3,5,5,0,0
0,0,5,3,6,0,7,5,0,0
0,0,5,3,0,0,0,5,0,0
0,0,5,3,3,3,5,5,0,0
0,0,4,5,5,5,5,4,0,0
0,0,0,0,0,0,0,0,0,0
0,0,0,0,0,0,0,0,0,0
0,0,0,0,0,0,0,0,0,0
0,0,0,0,0,0,0,0,0,0
0,0,0,0,0,0,0,0,0,0
0,0,0,0,0,0,0,0,0,0
0,0,0,0,0,0,0,0,0,0
:endlayer
layer: 19
0,0,0,0,0,0,0,0,0,0
0,0,0,0,0,0,0,0,0,0
0,0,4,5,5,5,5,4,0,0
0,0,5,5,3,3,5,5,0,0
0,0,5,0,0,0,0,5,0,0
0,0,5,0,4,4,4,5,0,0
0,0,5,0,0,18,5,5,0,0
0,0,4,5,5,5,5,4,0,0
0,0,0,0,0,0,0,0,0,0
0,0,0,0,0,0,0,0,0,0
0,0,0,0,0,0,0,0,0,0
0,0,0,0,0,0,0,0,0,0
0,0,0,0,0,0,0,0,0,0
0,0,0,0,0,0,0,0,0,0
0,0,0,0,0,0,0,0,0,0
:endlayer
layer: 20
0,0,0,0,0,0,0,0,0,0
0,0,0,0,0,0,0,0,0,0
0,0,4,5,5,5,5,4,0,0
0,0,5,5,3,3,5,5,0,0
0,0,5,0,0,0,0,5,0,0
0,0,5,13,0,0,0,5,0,0
0,0,5,0,0,18,5,5,0,0
0,0,4,5,5,5,5,4,0,0
0,0,0,0,0,0,0,0,0,0
0,0,0,0,0,0,0,0,0,0
0,0,0,0,0,0,0,0,0,0
0,0,0,0,0,0,0,0,0,0
0,0,0,0,0,0,0,0,0,0
0,0,0,0,0,0,0,0,0,0
0,0,0,0,0,0,0,0,0,0
:endlayer
layer: 21
0,0,0,0,0,0,0,0,0,0
0,0,0,0,0,0,0,0,0,0
0,0,4,5,5,5,5,4,0,0
0,0,5,5,3,3,5,5,0,0
0,0,5,0,0,0,0,5,0,0
0,0,5,0,0,0,14,5,0,0
0,0,5,0,0,18,5,5,0,0
0,0,4,5,5,5,5,4,0,0
0,0,0,0,0,0,0,0,0,0
0,0,0,0,0,0,0,0,0,0
0,0,0,0,0,0,0,0,0,0
0,0,0,0,0,0,0,0,0,0
0,0,0,0,0,0,0,0,0,0
0,0,0,0,0,0,0,0,0,0
0,0,0,0,0,0,0,0,0,0
:endlayer
layer: 22
0,0,0,0,0,0,0,0,0,0
0,0,0,0,0,0,0,0,0,0
0,0,4,4,4,4,4,4,0,0
0,0,4,4,4,4,4,4,0,0
0,0,4,4,4,4,4,4,0,0
0,0,4,4,4,4,4,4,0,0
0,0,4,4,4,18,4,4,0,0
0,0,4,4,4,4,4,4,0,0
0,0,0,0,0,0,0,0,0,0
0,0,0,0,0,0,0,0,0,0
0,0,0,0,0,0,0,0,0,0
0,0,0,0,0,0,0,0,0,0
0,0,0,0,0,0,0,0,0,0
0,0,0,0,0,0,0,0,0,0
0,0,0,0,0,0,0,0,0,0
:endlayer
layer: 23
0,0,0,0,0,0,0,0,0,0
0,0,0,0,0,0,0,0,0,0
0,0,9,9,9,9,9,9,0,0
0,0,9,0,0,0,0,9,0,0
0,0,9,0,15,15,0,9,0,0
0,0,9,0,15,15,0,9,0,0
0,0,9,0,0,0,0,9,0,0
0,0,9,9,9,9,9,9,0,0
0,0,0,0,0,0,0,0,0,0
0,0,0,0,0,0,0,0,0,0
0,0,0,0,0,0,0,0,0,0
0,0,0,0,0,0,0,0,0,0
0,0,0,0,0,0,0,0,0,0
0,0,0,0,0,0,0,0,0,0
0,0,0,0,0,0,0,0,0,0
:endlayer
layer: 24
0,0,0,0,0,0,0,0,0,0
0,0,0,0,0,0,0,0,0,0
0,0,9,0,0,0,0,9,0,0
0,0,0,0,0,0,0,0,0,0
0,0,0,0,15,15,0,0,0,0
0,0,0,0,15,15,0,0,0,0
0,0,0,0,0,0,0,0,0,0
0,0,9,0,0,0,0,9,0,0
0,0,0,0,0,0,0,0,0,0
0,0,0,0,0,0,0,0,0,0
0,0,0,0,0,0,0,0,0,0
0,0,0,0,0,0,0,0,0,0
0,0,0,0,0,0,0,0,0,0
0,0,0,0,0,0,0,0,0,0
0,0,0,0,0,0,0,0,0,0
:endlayer
layer: 25
0,0,0,0,0,0,0,0,0,0
0,0,0,0,0,0,0,0,0,0
0,0,9,0,0,0,0,9,0,0
0,0,0,0,0,0,0,0,0,0
0,0,0,0,15,15,0,0,0,0
0,0,0,0,15,15,0,0,0,0
0,0,0,0,0,0,0,0,0,0
0,0,9,0,0,0,0,9,0,0
0,0,0,0,0,0,0,0,0,0
0,0,0,0,0,0,0,0,0,0
0,0,0,0,0,0,0,0,0,0
0,0,0,0,0,0,0,0,0,0
0,0,0,0,0,0,0,0,0,0
0,0,0,0,0,0,0,0,0,0
0,0,0,0,0,0,0,0,0,0
:endlayer
layer: 26
0,0,0,0,0,0,0,0,0,0
0,0,0,0,0,0,0,0,0,0
0,0,10,10,10,10,10,10,0,0
0,0,10,0,0,0,0,10,0,0
0,0,10,0,15,15,0,10,0,0
0,0,10,0,15,15,0,10,0,0
0,0,10,0,0,0,0,10,0,0
0,0,10,10,10,10,10,10,0,0
0,0,0,0,0,0,0,0,0,0
0,0,0,0,0,0,0,0,0,0
0,0,0,0,0,0,0,0,0,0
0,0,0,0,0,0,0,0,0,0
0,0,0,0,0,0,0,0,0,0
0,0,0,0,0,0,0,0,0,0
0,0,0,0,0,0,0,0,0,0
:endlayer
layer: 27
0,0,0,0,0,0,0,0,0,0
0,0,0,0,0,0,0,0,0,0
0,0,0,0,0,0,0,0,0,0
0,0,0,10,10,10,10,0,0,0
0,0,0,10,15,15,10,0,0,0
0,0,0,10,15,15,10,0,0,0
0,0,0,10,10,10,10,0,0,0
0,0,0,0,0,0,0,0,0,0
0,0,0,0,0,0,0,0,0,0
0,0,0,0,0,0,0,0,0,0
0,0,0,0,0,0,0,0,0,0
0,0,0,0,0,0,0,0,0,0
0,0,0,0,0,0,0,0,0,0
0,0,0,0,0,0,0,0,0,0
0,0,0,0,0,0,0,0,0,0
:endlayer
layer: 28
0,0,0,0,0,0,0,0,0,0
0,0,0,0,0,0,0,0,0,0
0,0,0,0,0,0,0,0,0,0
0,0,0,0,0,0,0,0,0,0
0,0,0,0,10,10,0,0,0,0
0,0,0,0,10,10,0,0,0,0
0,0,0,0,0,0,0,0,0,0
0,0,0,0,0,0,0,0,0,0
0,0,0,0,0,0,0,0,0,0
0,0,0,0,0,0,0,0,0,0
0,0,0,0,0,0,0,0,0,0
0,0,0,0,0,0,0,0,0,0
0,0,0,0,0,0,0,0,0,0
0,0,0,0,0,0,0,0,0,0
0,0,0,0,0,0,0,0,0,0
:endlayer
layer: 29
0,0,0,0,0,0,0,0,0,0
0,0,0,0,0,0,0,0,0,0
0,0,0,0,0,0,0,0,0,0
0,0,0,0,0,0,0,0,0,0
0,0,0,0,0,0,0,0,0,0
0,0,0,0,0,0,0,0,0,0
0,0,0,0,0,0,0,0,0,0
0,0,0,0,0,0,0,0,0,0
0,0,0,0,0,0,0,0,0,0
0,0,0,0,0,0,0,0,0,0
0,0,0,0,0,0,0,0,0,0
0,0,0,0,0,0,0,0,0,0
0,0,0,0,0,0,0,0,0,0
0,0,0,0,0,0,0,0,0,0
0,0,0,0,0,0,0,0,0,0
:endlayer
layer: 30
0,0,0,0,0,0,0,0,0,0
0,0,0,0,0,0,0,0,0,0
0,0,0,0,0,0,0,0,0,0
0,0,0,0,0,0,0,0,0,0
0,0,0,0,0,0,0,0,0,0
0,0,0,0,0,0,0,0,0,0
0,0,0,0,0,0,0,0,0,0
0,0,0,0,0,0,0,0,0,0
0,0,0,0,0,0,0,0,0,0
0,0,0,0,0,0,0,0,0,0
0,0,0,0,0,0,0,0,0,0
0,0,0,0,0,0,0,0,0,0
0,0,0,0,0,0,0,0,0,0
0,0,0,0,0,0,0,0,0,0
0,0,0,0,0,0,0,0,0,0
:endlayer
layer: 31
0,0,0,0,0,0,0,0,0,0
0,0,0,0,0,0,0,0,0,0
0,0,0,0,0,0,0,0,0,0
0,0,0,0,0,0,0,0,0,0
0,0,0,0,0,0,0,0,0,0
0,0,0,0,0,0,0,0,0,0
0,0,0,0,0,0,0,0,0,0
0,0,0,0,0,0,0,0,0,0
0,0,0,0,0,0,0,0,0,0
0,0,0,0,0,0,0,0,0,0
0,0,0,0,0,0,0,0,0,0
0,0,0,0,0,0,0,0,0,0
0,0,0,0,0,0,0,0,0,0
0,0,0,0,0,0,0,0,0,0
0,0,0,0,0,0,0,0,0,0
:endlayer
layer: 32
0,0,0,0,0,0,0,0,0,0
0,0,0,0,0,0,0,0,0,0
0,0,0,0,0,0,0,0,0,0
0,0,0,0,0,0,0,0,0,0
0,0,0,0,0,0,0,0,0,0
0,0,0,0,0,0,0,0,0,0
0,0,0,0,0,0,0,0,0,0
0,0,0,0,0,0,0,0,0,0
0,0,0,0,0,0,0,0,0,0
0,0,0,0,0,0,0,0,0,0
0,0,0,0,0,0,0,0,0,0
0,0,0,0,0,0,0,0,0,0
0,0,0,0,0,0,0,0,0,0
0,0,0,0,0,0,0,0,0,0
0,0,0,0,0,0,0,0,0,0
:endlayer
layer: 33
0,0,0,0,0,0,0,0,0,0
0,0,0,0,0,0,0,0,0,0
0,0,0,0,0,0,0,0,0,0
0,0,0,0,0,0,0,0,0,0
0,0,0,0,0,0,0,0,0,0
0,0,0,0,0,0,0,0,0,0
0,0,0,0,0,0,0,0,0,0
0,0,0,0,0,0,0,0,0,0
0,0,0,0,0,0,0,0,0,0
0,0,0,0,0,0,0,0,0,0
0,0,0,0,0,0,0,0,0,0
0,0,0,0,0,0,0,0,0,0
0,0,0,0,0,0,0,0,0,0
0,0,0,0,0,0,0,0,0,0
0,0,0,0,0,0,0,0,0,0
:endlayer
layer: 34
0,0,0,0,0,0,0,0,0,0
0,0,0,0,0,0,0,0,0,0
0,0,0,0,0,0,0,0,0,0
0,0,0,0,0,0,0,0,0,0
0,0,0,0,0,0,0,0,0,0
0,0,0,0,0,0,0,0,0,0
0,0,0,0,0,0,0,0,0,0
0,0,0,0,0,0,0,0,0,0
0,0,0,0,0,0,0,0,0,0
0,0,0,0,0,0,0,0,0,0
0,0,0,0,0,0,0,0,0,0
0,0,0,0,0,0,0,0,0,0
0,0,0,0,0,0,0,0,0,0
0,0,0,0,0,0,0,0,0,0
0,0,0,0,0,0,0,0,0,0
:endlayer
layer: 35
0,0,0,0,0,0,0,0,0,0
0,0,0,0,0,0,0,0,0,0
0,0,0,0,0,0,0,0,0,0
0,0,0,0,0,0,0,0,0,0
0,0,0,0,0,0,0,0,0,0
0,0,0,0,0,0,0,0,0,0
0,0,0,0,0,0,0,0,0,0
0,0,0,0,0,0,0,0,0,0
0,0,0,0,0,0,0,0,0,0
0,0,0,0,0,0,0,0,0,0
0,0,0,0,0,0,0,0,0,0
0,0,0,0,0,0,0,0,0,0
0,0,0,0,0,0,0,0,0,0
0,0,0,0,0,0,0,0,0,0
0,0,0,0,0,0,0,0,0,0
:endlayer
layer: 36
0,0,0,0,0,0,0,0,0,0
0,0,0,0,0,0,0,0,0,0
0,0,0,0,0,0,0,0,0,0
0,0,0,0,0,0,0,0,0,0
0,0,0,0,0,0,0,0,0,0
0,0,0,0,0,0,0,0,0,0
0,0,0,0,0,0,0,0,0,0
0,0,0,0,0,0,0,0,0,0
0,0,0,0,0,0,0,0,0,0
0,0,0,0,0,0,0,0,0,0
0,0,0,0,0,0,0,0,0,0
0,0,0,0,0,0,0,0,0,0
0,0,0,0,0,0,0,0,0,0
0,0,0,0,0,0,0,0,0,0
0,0,0,0,0,0,0,0,0,0
:endlayer
layer: 37
0,0,0,0,0,0,0,0,0,0
0,0,0,0,0,0,0,0,0,0
0,0,0,0,0,0,0,0,0,0
0,0,0,0,0,0,0,0,0,0
0,0,0,0,0,0,0,0,0,0
0,0,0,0,0,0,0,0,0,0
0,0,0,0,0,0,0,0,0,0
0,0,0,0,0,0,0,0,0,0
0,0,0,0,0,0,0,0,0,0
0,0,0,0,0,0,0,0,0,0
0,0,0,0,0,0,0,0,0,0
0,0,0,0,0,0,0,0,0,0
0,0,0,0,0,0,0,0,0,0
0,0,0,0,0,0,0,0,0,0
0,0,0,0,0,0,0,0,0,0
:endlayer

#### RULES ####
rule:
plugin=vanillaBlocks
number=2
data:
tag:
TAG=10={
TAG=8=blockName{stone}
TAG=3=meta{0}
TAG=3=buildPass{0}
}
:endtag
:enddata
:endrule

rule:
plugin=vanillaBlocks
number=3
data:
tag:
TAG=10={
TAG=8=blockName{cobblestone}
TAG=3=meta{0}
TAG=3=buildPass{0}
}
:endtag
:enddata
:endrule

rule:
plugin=vanillaBlocks
number=4
data:
tag:
TAG=10={
TAG=8=blockName{stonebrick}
TAG=3=meta{0}
TAG=3=buildPass{0}
}
:endtag
:enddata
:endrule

rule:
plugin=vanillaBlocks
number=5
data:
tag:
TAG=10={
TAG=8=blockName{stonebrick}
TAG=3=meta{2}
TAG=3=buildPass{0}
}
:endtag
:enddata
:endrule

rule:
plugin=vanillaBlocks
number=6
data:
tag:
TAG=10={
TAG=8=blockName{stone_stairs}
TAG=3=meta{1}
TAG=3=buildPass{0}
}
:endtag
:enddata
:endrule

rule:
plugin=vanillaBlocks
number=7
data:
tag:
TAG=10={
TAG=8=blockName{torch}
TAG=3=meta{3}
TAG=3=buildPass{1}
}
:endtag
:enddata
:endrule

rule:
plugin=vanillaBlocks
number=8
data:
tag:
TAG=10={
TAG=8=blockName{glass}
TAG=3=meta{0}
TAG=3=buildPass{0}
}
:endtag
:enddata
:endrule

rule:
plugin=vanillaBlocks
number=9
data:
tag:
TAG=10={
TAG=8=blockName{fence}
TAG=3=meta{0}
TAG=3=buildPass{0}
}
:endtag
:enddata
:endrule

rule:
plugin=vanillaBlocks
number=10
data:
tag:
TAG=10={
TAG=8=blockName{double_stone_slab}
TAG=3=meta{0}
TAG=3=buildPass{0}
}
:endtag
:enddata
:endrule

rule:
plugin=vanillaBlocks
number=11
data:
tag:
TAG=10={
TAG=8=blockName{stone_stairs}
TAG=3=meta{3}
TAG=3=buildPass{0}
}
:endtag
:enddata
:endrule

rule:
plugin=vanillaBlocks
number=12
data:
tag:
TAG=10={
TAG=8=blockName{stone_stairs}
TAG=3=meta{2}
TAG=3=buildPass{0}
}
:endtag
:enddata
:endrule

rule:
plugin=vanillaBlocks
number=13
data:
tag:
TAG=10={
TAG=8=blockName{torch}
TAG=3=meta{1}
TAG=3=buildPass{1}
}
:endtag
:enddata
:endrule

rule:
plugin=vanillaBlocks
number=14
data:
tag:
TAG=10={
TAG=8=blockName{torch}
TAG=3=meta{2}
TAG=3=buildPass{1}
}
:endtag
:enddata
:endrule

rule:
plugin=vanillaBlocks
number=15
data:
tag:
TAG=10={
TAG=8=blockName{glowstone}
TAG=3=meta{0}
TAG=3=buildPass{0}
}
:endtag
:enddata
:endrule

rule:
plugin=vanillaBlocks
number=16
data:
tag:
TAG=10={
TAG=8=blockName{stone_stairs}
TAG=3=meta{0}
TAG=3=buildPass{0}
}
:endtag
:enddata
:endrule

rule:
plugin=vanillaBlocks
number=17
data:
tag:
TAG=10={
TAG=8=blockName{torch}
TAG=3=meta{4}
TAG=3=buildPass{1}
}
:endtag
:enddata
:endrule

rule:
plugin=vanillaBlocks
number=18
data:
tag:
TAG=10={
TAG=8=blockName{ladder}
TAG=3=meta{4}
TAG=3=buildPass{1}
}
:endtag
:enddata
:endrule

rule:
plugin=vanillaDoors
number=19
data:
tag:
TAG=10={
TAG=1=sideFlag{0}
TAG=8=blockName{iron_door}
TAG=3=meta{3}
TAG=3=buildPass{1}
}
:endtag
:enddata
:endrule

rule:
plugin=vanillaDoors
number=20
data:
tag:
TAG=10={
TAG=1=sideFlag{0}
TAG=8=blockName{iron_door}
TAG=3=meta{8}
TAG=3=buildPass{1}
}
:endtag
:enddata
:endrule

rule:
plugin=vanillaBlocks
number=21
data:
tag:
TAG=10={
TAG=8=blockName{lever}
TAG=3=meta{7}
TAG=3=buildPass{1}
}
:endtag
:enddata
:endrule

#### ENTITIES ####
