# Ancient Warfare Structure Template File
# auto-generated structure file. created on: 4/21/2014 at: 6:44:3
# Lines beginning with # denote comments

header:
version=2.0
name=CivMerchantPrinceManorHostileMOH
size=64,43,47
offset=48,4,43
:endheader

#### VALIDATION ####
validation:
type=ground
survival=false
worldGenEnabled=true
unique=true
preserveBlocks=false
selectionWeight=40
clusterValue=34
minDuplicateDistance=1
dimensionWhiteList=false
dimensionList=
biomeWhiteList=true
biomeList=ebxl.meadow,field,autumn hills,bop.scrubland,forested field,highlands_woodlands,highlands.meadow,bop.shrubland,orchard,heathland,bop.meadow
leveling=9
fill=6
border=6
validTargetBlocks=clay,lapis_ore,sand,grass,lit_redstone_ore,stone,gravel,iron_ore,diamond_ore,stained_hardened_clay,dirt,coal_ore,redstone_ore,gold_ore
data:
:enddata
:endvalidation

#### LAYERS ####
layer: 0
1,1,1,1,1,1,1,1,1,1,1,1,1,1,1,1,1,1,1,1,1,1,1,1,1,1,1,1,1,1,1,1,1,1,1,1,1,1,1,1,1,1,1,1,1,1,1,1,1,1,1,1,1,1,1,1,1,1,1,1,1,1,1,1
1,1,1,1,1,1,1,1,1,1,1,1,1,1,1,1,1,1,1,1,1,1,1,1,1,1,1,1,1,1,1,1,1,1,1,1,1,1,1,1,1,1,1,1,1,1,1,1,1,1,1,1,1,1,1,1,1,1,1,1,1,1,1,1
1,1,1,1,1,1,1,1,1,1,1,1,1,1,1,1,1,1,1,1,1,1,1,1,1,1,1,1,1,1,1,1,1,1,1,1,1,1,1,1,1,1,1,1,1,1,1,1,1,1,1,1,1,1,1,1,1,1,1,1,1,1,1,1
1,1,1,1,1,1,1,1,1,1,1,1,1,1,1,1,1,1,1,1,1,1,1,1,1,1,1,1,1,1,1,1,1,1,1,1,1,1,1,1,1,1,1,1,1,1,1,1,1,1,1,1,1,1,1,1,1,1,1,1,1,1,1,1
1,1,1,1,1,1,1,1,1,1,1,1,1,1,1,1,1,1,1,1,1,1,1,1,1,1,1,1,1,1,1,1,1,1,1,1,1,1,1,1,1,1,1,1,1,1,1,1,1,1,1,1,1,1,1,1,1,1,1,1,1,1,1,1
1,1,1,1,1,1,1,1,1,1,1,1,1,1,1,1,1,1,1,1,1,1,1,1,1,1,1,1,1,1,1,1,1,1,1,1,1,1,1,1,1,1,1,1,1,1,1,1,1,1,1,1,1,1,1,1,1,1,1,1,1,1,1,1
1,1,1,1,1,1,1,1,1,1,1,1,1,1,1,1,1,1,1,1,1,1,1,1,1,1,1,1,1,1,1,1,1,1,1,1,1,1,1,1,1,1,1,1,1,1,1,1,1,1,1,1,1,1,1,1,1,1,1,1,1,1,1,1
1,1,1,1,1,1,1,1,1,1,1,1,1,1,1,1,1,1,1,1,1,1,1,1,1,1,1,1,1,1,1,1,1,1,1,1,1,1,1,1,1,1,1,1,1,1,1,1,1,1,1,1,1,1,1,1,1,1,1,1,1,1,1,1
1,1,1,1,1,1,1,1,1,1,1,1,1,1,1,1,1,1,1,1,1,1,1,1,1,1,1,1,1,1,1,1,1,1,1,1,1,1,1,1,1,1,1,1,1,1,1,1,1,1,1,1,1,1,1,1,1,1,1,1,1,1,1,1
1,1,1,1,1,1,1,1,1,1,1,1,1,1,1,1,1,1,1,1,1,1,1,1,1,1,1,1,1,1,1,1,1,1,1,1,1,1,1,1,1,1,1,1,1,1,1,1,1,1,1,1,1,1,1,1,1,1,1,1,1,1,1,1
1,1,1,1,1,1,1,1,1,1,1,1,1,1,1,1,1,1,1,1,1,1,1,1,1,1,1,1,1,1,1,1,1,1,1,1,1,1,1,1,1,1,1,1,1,1,1,1,1,1,1,1,1,1,1,1,1,1,1,1,1,1,1,1
1,1,1,1,1,1,1,1,1,1,1,1,1,1,1,1,1,1,1,1,1,1,1,1,1,1,1,1,1,1,1,1,1,1,1,1,1,1,1,1,1,1,1,1,1,1,1,1,1,1,1,1,1,1,1,1,1,1,1,1,1,1,1,1
1,1,1,1,1,1,1,1,1,1,1,1,1,1,1,1,1,1,1,1,1,1,1,1,1,1,1,1,1,1,1,1,1,1,1,1,1,1,1,1,1,1,1,1,1,1,1,1,1,1,1,1,1,1,1,1,1,1,1,1,1,1,1,1
1,1,1,1,1,1,1,1,1,1,1,1,1,1,1,1,1,1,1,1,1,1,1,1,1,1,1,1,1,1,1,1,1,1,1,1,1,1,1,1,1,1,1,1,1,1,1,1,1,1,1,1,1,1,1,1,1,1,1,1,1,1,1,1
1,1,1,1,1,1,1,1,1,1,1,1,1,1,1,1,1,1,1,1,1,1,1,1,1,1,1,1,1,1,1,1,1,1,1,1,1,1,1,1,1,1,1,1,1,1,1,1,1,1,1,1,1,1,1,1,1,1,1,1,1,1,1,1
1,1,1,1,1,1,1,1,1,1,1,1,1,1,1,1,1,1,1,1,1,1,1,1,1,1,1,1,1,1,1,1,1,1,1,1,1,1,1,1,1,1,1,1,1,1,1,1,1,1,1,1,1,1,1,1,1,1,1,1,1,1,1,1
1,1,1,1,1,1,1,1,1,1,1,1,1,1,1,1,1,1,1,1,1,1,1,1,1,1,1,1,1,1,1,1,1,1,1,1,1,1,1,1,1,1,1,1,1,1,1,1,1,1,1,1,1,1,1,1,1,1,1,1,1,1,1,1
1,1,1,1,1,1,1,1,1,1,1,1,1,1,1,1,1,1,1,1,1,1,1,1,1,1,1,1,1,1,1,1,1,1,1,1,1,1,1,1,1,1,1,1,1,1,1,1,1,1,1,1,1,1,1,1,1,1,1,1,1,1,1,1
1,1,1,1,1,1,1,1,1,1,1,1,1,1,1,1,1,1,1,1,1,1,1,1,1,1,1,1,1,1,1,1,1,1,1,1,1,1,1,1,1,1,1,1,1,1,1,1,1,1,1,1,1,1,1,1,1,1,1,1,1,1,1,1
1,1,1,1,1,1,1,1,1,1,1,1,1,1,1,1,1,1,1,1,1,1,1,1,1,1,1,1,1,1,1,1,1,1,1,1,1,1,1,1,1,1,1,1,1,1,1,1,1,1,1,1,1,1,1,1,1,1,1,1,1,1,1,1
1,1,1,1,1,1,1,1,1,1,1,1,1,1,1,1,1,1,1,1,1,1,1,1,1,1,1,1,1,1,1,1,1,1,1,1,1,1,1,1,1,1,1,1,1,1,1,1,1,1,1,1,1,1,1,1,1,1,1,1,1,1,1,1
1,1,1,1,1,1,1,1,1,1,1,1,1,1,1,1,1,1,1,1,1,1,1,1,1,1,1,1,1,1,1,1,1,1,1,1,1,1,1,1,1,1,1,1,1,1,1,1,1,1,1,1,1,1,1,1,1,1,1,1,1,1,1,1
1,1,1,1,1,1,1,1,1,1,1,1,1,1,1,1,1,1,1,1,1,1,1,1,1,1,1,1,1,1,1,1,1,1,1,1,1,1,1,1,1,1,1,1,1,1,1,1,1,1,1,1,1,1,1,1,1,1,1,1,1,1,1,1
1,1,1,1,1,1,1,1,1,1,1,1,1,1,1,1,1,1,1,1,1,1,1,1,1,1,1,1,1,1,1,1,1,1,1,1,1,1,1,1,1,1,1,1,1,1,1,1,1,1,1,1,1,1,1,1,1,1,1,1,1,1,1,1
1,1,1,1,1,1,1,1,1,1,1,1,1,1,1,1,1,1,1,1,1,1,1,1,1,1,1,1,1,1,1,1,1,1,1,1,1,1,1,1,1,1,1,1,1,1,1,1,1,1,1,1,1,1,1,1,1,1,1,1,1,1,1,1
1,1,1,1,1,1,1,1,1,1,1,1,1,1,1,1,1,1,1,1,1,1,1,1,1,1,1,1,1,1,1,1,1,1,1,1,1,1,1,1,1,1,1,1,1,1,1,1,1,1,1,1,1,1,1,1,1,1,1,1,1,1,1,1
1,1,1,1,1,1,1,1,1,1,1,1,1,1,1,1,1,1,1,1,1,1,1,1,1,1,1,1,1,1,1,1,1,1,1,1,1,1,1,1,1,1,1,1,1,1,1,1,1,1,1,1,1,1,1,1,1,1,1,1,1,1,1,1
1,1,1,1,1,1,1,1,1,1,1,1,1,1,1,1,1,1,1,1,1,1,1,1,1,1,1,1,1,1,1,1,1,1,1,1,1,1,1,1,1,1,1,1,1,1,1,1,1,1,1,1,1,1,1,1,1,1,1,1,1,1,1,1
1,1,1,1,1,1,1,1,1,1,1,1,1,1,1,1,1,1,1,1,1,1,1,1,1,1,1,1,1,1,1,1,1,1,1,1,1,1,1,1,1,1,1,1,1,1,1,1,1,1,1,1,1,1,1,1,1,1,1,1,1,1,1,1
1,1,1,1,1,1,1,1,1,1,1,1,1,1,1,1,1,1,1,1,1,1,1,1,1,1,1,1,1,1,1,1,1,1,1,1,1,1,1,1,1,1,1,1,1,1,1,1,1,1,1,1,1,1,1,1,1,1,1,1,1,1,1,1
1,1,1,1,1,1,1,1,1,1,1,1,1,1,1,1,1,1,1,1,1,1,1,1,1,1,1,1,1,1,1,1,1,1,1,1,1,1,1,1,1,1,1,1,1,1,1,1,1,1,1,1,1,1,1,1,1,1,1,1,1,1,1,1
1,1,1,1,1,1,1,1,1,1,1,1,1,1,1,1,1,1,1,1,1,1,1,1,1,1,1,1,1,1,1,1,1,1,1,1,1,1,1,1,1,1,1,1,1,1,1,1,1,1,1,1,1,1,1,1,1,1,1,1,1,1,1,1
1,1,1,1,1,1,1,1,1,1,1,1,1,1,1,1,1,1,1,1,1,1,1,1,1,1,1,1,1,1,1,1,1,1,1,1,1,1,1,1,1,1,1,1,1,1,1,1,1,1,1,1,1,1,1,1,1,1,1,1,1,1,1,1
1,1,1,1,1,1,1,1,1,1,1,1,1,1,1,1,1,1,1,1,1,1,1,1,1,1,1,1,1,1,1,1,1,1,1,1,1,1,1,1,1,1,1,1,1,1,1,1,1,1,1,1,1,1,1,1,1,1,1,1,1,1,1,1
1,1,1,1,1,1,1,1,1,1,1,1,1,1,1,1,1,1,1,1,1,1,1,1,1,1,1,1,1,1,1,1,1,1,1,1,1,1,1,1,1,1,1,1,1,1,1,1,1,1,1,1,1,1,1,1,1,1,1,1,1,1,1,1
1,1,1,1,1,1,1,1,1,1,1,1,1,1,1,1,1,1,1,1,1,1,1,1,1,1,1,1,1,1,1,1,1,1,1,1,1,1,1,1,1,1,1,1,1,1,1,1,1,1,1,1,1,1,1,1,1,1,1,1,1,1,1,1
1,1,1,1,1,1,1,1,1,1,1,1,1,1,1,1,1,1,1,1,1,1,1,1,1,1,1,1,1,1,1,1,1,1,1,1,1,1,1,1,1,1,1,1,1,1,1,1,1,1,1,1,1,1,1,1,1,1,1,1,1,1,1,1
1,1,1,1,1,1,1,1,1,1,1,1,1,1,1,1,1,1,1,1,1,1,1,1,1,1,1,1,1,1,1,1,1,1,1,1,1,1,1,1,1,1,1,1,1,1,1,1,1,1,1,1,1,1,1,1,1,1,1,1,1,1,1,1
1,1,1,1,1,1,1,1,1,1,1,1,1,1,1,1,1,1,1,1,1,1,1,1,1,1,1,1,1,1,1,1,1,1,1,1,1,1,1,1,1,1,1,1,1,1,1,1,1,1,1,1,1,1,1,1,1,1,1,1,1,1,1,1
1,1,1,1,1,1,1,1,1,1,1,1,1,1,1,1,1,1,1,1,1,1,1,1,1,1,1,1,1,1,1,1,1,1,1,1,1,1,1,1,1,1,1,1,1,1,1,1,1,1,1,1,1,1,1,1,1,1,1,1,1,1,1,1
1,1,1,1,1,1,1,1,1,1,1,1,1,1,1,1,1,1,1,1,1,1,1,1,1,1,1,1,1,1,1,1,1,1,1,1,1,1,1,1,1,1,1,1,1,1,1,1,1,1,1,1,1,1,1,1,1,1,1,1,1,1,1,1
1,1,1,1,1,1,1,1,1,1,1,1,1,1,1,1,1,1,1,1,1,1,1,1,1,1,1,1,1,1,1,1,1,1,1,1,1,1,1,1,1,1,1,1,1,1,1,1,1,1,1,1,1,1,1,1,1,1,1,1,1,1,1,1
1,1,1,1,1,1,1,1,1,1,1,1,1,1,1,1,1,1,1,1,1,1,1,1,1,1,1,1,1,1,1,1,1,1,1,1,1,1,1,1,1,1,1,1,1,1,1,1,1,1,1,1,1,1,1,1,1,1,1,1,1,1,1,1
1,1,1,1,1,1,1,1,1,1,1,1,1,1,1,1,1,1,1,1,1,1,1,1,1,1,1,1,1,1,1,1,1,1,1,1,1,1,1,1,1,1,1,1,1,1,1,1,1,1,1,1,1,1,1,1,1,1,1,1,1,1,1,1
1,1,1,1,1,1,1,1,1,1,1,1,1,1,1,1,1,1,1,1,1,1,1,1,1,1,1,1,1,1,1,1,1,1,1,1,1,1,1,1,1,1,1,1,1,1,1,1,1,1,1,1,1,1,1,1,1,1,1,1,1,1,1,1
1,1,1,1,1,1,1,1,1,1,1,1,1,1,1,1,1,1,1,1,1,1,1,1,1,1,1,1,1,1,1,1,1,1,1,1,1,1,1,1,1,1,1,1,1,1,1,1,1,1,1,1,1,1,1,1,1,1,1,1,1,1,1,1
1,1,1,1,1,1,1,1,1,1,1,1,1,1,1,1,1,1,1,1,1,1,1,1,1,1,1,1,1,1,1,1,1,1,1,1,1,1,1,1,1,1,1,1,1,1,1,1,1,1,1,1,1,1,1,1,1,1,1,1,1,1,1,1
:endlayer
layer: 1
1,1,1,1,1,1,1,1,1,1,1,1,1,1,1,1,1,1,1,1,1,1,1,1,1,1,1,1,1,1,1,1,1,1,1,1,1,1,1,1,1,1,1,1,1,1,1,1,1,1,1,1,1,1,1,1,1,1,1,1,1,1,1,1
1,1,1,1,1,1,1,1,1,1,1,1,1,1,1,1,1,1,1,1,1,1,1,1,1,1,1,1,1,1,1,1,1,1,1,1,1,1,1,1,1,1,1,1,1,1,1,1,1,1,1,1,1,1,1,1,1,1,1,1,1,1,1,1
1,1,1,1,1,1,1,1,1,1,1,1,1,1,1,1,1,1,1,1,1,1,1,1,1,1,1,1,1,1,1,1,1,1,1,1,1,1,1,1,1,1,1,1,1,1,1,1,1,1,1,1,1,1,1,1,1,1,1,2,2,2,1,1
1,1,1,1,1,1,1,1,1,1,1,1,1,1,1,1,1,1,1,1,1,1,1,1,1,1,1,1,1,1,1,1,1,1,1,1,1,1,1,1,1,1,1,1,1,1,1,1,1,1,1,1,1,1,1,1,1,1,1,2,2,2,1,1
1,1,1,1,1,1,1,1,1,1,1,1,1,1,1,1,1,1,1,1,1,1,1,1,1,1,1,1,1,1,1,1,1,1,1,1,1,1,1,1,1,1,1,1,1,1,1,1,1,1,1,1,1,1,1,1,1,1,1,2,2,2,1,1
1,1,1,1,1,1,1,1,1,1,1,1,1,1,1,1,1,1,1,1,1,1,1,1,1,1,1,1,1,1,1,1,1,1,1,1,1,1,1,1,1,1,1,1,1,1,1,1,1,1,1,1,1,1,1,1,1,1,1,2,2,2,1,1
1,1,1,1,1,1,1,1,1,1,1,1,1,1,1,1,1,1,1,1,1,1,1,1,1,1,1,1,1,1,1,1,1,1,1,1,1,1,1,1,1,1,1,1,1,1,1,1,1,1,1,1,1,1,1,1,1,1,1,2,2,2,1,1
1,1,1,1,1,1,1,1,1,1,1,1,1,1,1,1,1,1,1,1,1,1,1,1,1,1,1,1,1,1,1,1,1,1,1,1,1,1,1,1,1,1,1,1,1,1,1,1,1,1,1,1,1,1,1,1,1,1,1,2,2,2,1,1
1,1,1,1,1,1,1,1,1,1,1,1,1,1,1,1,1,1,1,1,1,1,1,1,1,1,1,1,1,1,1,1,1,1,1,1,1,1,1,1,1,1,1,1,1,1,1,1,1,1,1,1,1,1,1,1,1,1,1,2,2,2,1,1
1,1,1,1,1,1,1,1,1,1,1,1,1,1,1,1,1,1,1,1,1,1,1,1,1,1,1,1,1,1,1,1,1,1,1,1,1,1,1,1,1,1,1,1,1,1,1,1,1,1,1,1,1,1,1,1,1,1,1,2,2,2,1,1
1,1,1,1,1,1,1,1,1,1,1,1,1,1,1,1,1,1,1,1,1,1,1,1,1,1,1,1,1,1,1,1,1,1,1,1,1,1,1,1,1,1,1,1,1,1,1,1,1,1,1,1,1,1,1,1,1,1,1,2,2,2,1,1
1,1,1,1,1,1,1,1,1,1,1,1,1,1,1,1,1,1,1,1,1,1,1,1,1,1,1,1,1,1,1,1,1,1,1,1,1,1,1,1,1,1,1,1,1,1,1,1,1,1,1,1,1,1,1,1,1,1,1,2,2,2,1,1
1,1,1,1,1,1,1,1,1,1,1,1,1,1,1,1,1,1,1,1,1,1,1,1,1,1,1,1,1,1,1,1,1,1,1,1,1,1,1,1,1,1,1,1,1,1,1,1,1,1,1,1,1,1,1,1,1,1,1,2,2,2,1,1
1,1,1,1,1,1,1,1,1,1,1,1,1,1,1,1,1,1,1,1,1,1,1,1,1,1,1,1,1,1,1,1,1,1,1,1,1,1,1,1,1,1,1,1,1,1,1,1,1,1,1,1,1,1,1,1,1,1,1,2,2,2,1,1
1,1,1,1,1,1,1,1,1,1,1,1,1,1,1,1,1,1,1,1,1,1,1,1,1,1,1,1,1,1,1,1,1,1,1,1,1,1,1,1,1,1,1,1,1,1,1,1,1,1,1,1,1,1,1,1,1,1,1,2,2,2,1,1
1,1,1,1,1,1,1,1,1,1,1,1,1,1,1,1,1,1,1,1,1,1,1,1,1,1,1,1,1,1,1,1,1,1,1,1,1,1,1,1,1,1,1,1,1,1,1,1,1,1,1,1,1,1,1,1,1,1,1,2,2,2,1,1
1,1,1,1,1,1,1,1,1,1,1,1,1,1,1,1,1,1,1,1,1,1,1,1,1,1,1,1,1,1,1,1,1,1,1,1,1,1,1,1,1,1,1,1,1,1,1,1,1,1,1,1,1,1,1,1,1,1,1,2,2,2,1,1
1,1,1,1,1,1,1,1,1,1,1,1,1,1,1,1,1,1,1,1,1,1,1,1,1,1,1,1,1,1,1,1,1,1,1,1,1,1,1,1,1,1,1,1,1,1,1,1,1,1,1,1,1,1,1,1,1,1,1,2,2,2,1,1
1,1,1,1,1,1,1,1,1,1,1,1,1,1,1,1,1,1,1,1,1,1,1,1,1,1,1,1,1,1,1,1,1,1,1,1,1,1,1,1,1,1,1,1,1,1,1,1,1,1,1,1,1,1,1,1,1,1,1,2,2,2,1,1
1,1,1,1,1,1,1,1,1,1,1,1,1,1,1,1,1,1,1,1,1,1,1,1,1,1,1,1,1,1,1,1,1,1,1,1,1,1,1,1,1,1,1,1,1,1,1,1,1,1,1,1,1,1,1,1,1,1,1,2,2,2,1,1
1,1,1,1,1,1,1,1,1,1,1,1,1,1,1,1,1,1,1,1,1,1,1,1,1,1,1,1,1,1,1,1,1,1,1,1,1,1,1,1,1,1,1,1,1,1,1,1,1,1,1,1,1,1,1,1,1,1,1,2,2,2,1,1
1,1,1,1,1,1,1,1,1,1,1,1,1,1,1,1,1,1,1,1,1,1,1,1,1,1,1,1,1,1,1,1,1,1,1,1,1,1,1,1,1,1,1,1,1,1,1,1,1,1,1,1,1,1,1,1,1,1,1,2,2,2,1,1
1,1,1,1,1,1,1,1,1,1,1,1,1,1,1,1,1,1,1,1,1,1,1,1,1,1,1,1,1,1,1,1,1,1,1,1,1,1,1,1,1,1,1,1,1,1,1,1,1,1,1,1,1,1,1,1,1,1,1,2,2,2,1,1
1,1,1,1,1,1,1,1,1,1,1,1,1,1,1,1,1,1,1,1,1,1,1,1,1,1,1,1,1,1,1,1,1,1,1,1,1,1,1,1,1,1,1,1,1,1,1,1,1,1,1,1,1,1,1,1,1,1,1,2,2,2,1,1
1,1,1,1,1,1,1,1,1,1,1,1,1,1,1,1,1,1,1,1,1,1,1,1,1,1,1,1,1,1,1,1,1,1,1,1,1,1,1,1,1,1,1,1,1,1,1,1,1,1,1,1,1,1,1,1,1,1,1,2,2,2,1,1
1,1,1,1,1,1,1,1,1,1,1,1,1,1,1,1,1,1,1,1,1,1,1,1,1,1,1,1,1,1,1,1,1,1,1,1,1,1,1,1,1,1,1,1,1,1,1,1,1,1,1,1,1,1,1,1,1,1,1,2,2,2,1,1
1,1,1,1,1,1,1,1,1,1,1,1,1,1,1,1,1,1,1,1,1,1,1,1,1,1,1,1,1,1,1,1,1,1,1,1,1,1,1,1,1,1,1,1,1,1,1,1,1,1,1,1,1,1,1,1,1,1,1,2,2,2,1,1
1,1,1,1,1,1,1,1,1,1,1,1,1,1,1,1,1,1,1,1,1,1,1,1,1,1,1,1,1,1,1,1,1,1,1,1,1,1,1,1,1,1,1,1,1,1,1,1,1,1,1,1,1,1,1,1,1,1,1,2,2,2,1,1
1,1,1,1,1,1,1,1,1,1,1,1,1,1,1,1,1,1,1,1,1,1,1,1,1,1,1,1,1,1,1,1,1,1,1,1,1,1,1,1,1,1,1,1,1,1,1,1,1,1,1,1,1,1,1,1,1,1,1,2,2,2,1,1
1,1,1,1,1,1,1,1,1,1,1,1,1,1,1,1,1,1,1,1,1,1,1,1,1,1,1,1,1,1,1,1,1,1,1,1,1,1,1,1,1,1,1,1,1,1,1,1,1,1,1,1,1,1,1,1,1,1,1,2,2,2,1,1
1,1,1,1,1,1,1,1,1,1,1,1,1,1,1,1,1,1,1,1,1,1,1,1,1,1,1,1,1,1,1,1,1,1,1,1,1,1,1,1,1,1,1,1,1,1,1,1,1,1,1,1,1,1,1,1,1,1,1,2,2,2,1,1
1,1,1,1,1,1,1,1,1,1,1,1,1,1,1,1,1,1,1,1,1,1,1,1,1,1,1,1,1,1,1,1,1,1,1,1,1,1,1,1,1,1,1,1,1,1,1,1,1,1,1,1,1,1,1,1,1,1,1,2,2,2,1,1
1,1,1,1,1,1,1,1,1,1,1,1,1,1,1,1,1,1,1,1,1,1,1,1,1,1,1,1,1,1,1,1,1,1,1,1,1,1,1,1,1,1,1,1,1,1,1,1,1,1,1,1,1,1,1,1,1,1,1,2,2,2,1,1
1,1,1,1,1,1,1,1,1,1,1,1,1,1,1,1,1,1,1,1,1,1,1,1,1,1,1,1,1,1,1,1,1,1,1,1,1,1,1,1,1,1,1,1,1,1,1,1,1,1,1,1,1,1,1,1,1,1,1,2,2,2,1,1
1,1,1,1,1,1,1,1,1,1,1,1,1,1,1,1,1,1,1,1,1,1,1,1,1,1,1,1,1,1,1,1,1,1,1,1,1,1,1,1,1,1,1,1,1,1,1,1,1,1,1,1,1,1,1,1,1,1,1,2,2,2,1,1
1,1,1,1,1,1,1,1,1,1,1,1,1,1,1,1,1,1,1,1,1,1,1,1,1,1,1,1,1,1,1,1,1,1,1,1,1,1,1,1,1,1,1,1,1,1,1,1,1,1,1,1,1,1,1,1,1,1,1,2,2,2,1,1
1,1,1,1,1,1,1,1,1,1,1,1,1,1,1,1,1,1,1,1,1,1,1,1,1,1,1,1,1,1,1,1,1,1,1,1,1,1,1,1,1,1,1,1,1,1,1,1,1,1,1,1,1,1,1,1,1,1,1,2,2,2,1,1
1,1,1,1,1,1,1,1,1,1,1,1,1,1,1,1,1,1,1,1,1,1,1,1,1,1,1,1,1,1,1,1,1,1,1,1,1,1,1,1,1,1,1,1,1,1,1,1,1,1,1,1,1,1,1,1,1,1,1,2,2,2,1,1
1,1,1,1,1,1,1,1,1,1,1,1,1,1,1,1,1,1,1,1,1,1,1,1,1,1,1,1,1,1,1,1,1,1,1,1,1,1,1,1,1,1,1,1,1,1,1,1,1,1,1,1,1,1,1,1,1,1,1,2,2,2,1,1
1,1,1,1,1,1,1,1,1,1,1,1,1,1,1,1,1,1,1,1,1,1,1,1,1,1,1,1,1,1,1,1,1,1,1,1,1,1,1,1,1,1,1,1,1,1,1,1,1,1,1,1,1,1,1,1,1,1,1,2,2,2,1,1
1,1,1,1,1,1,1,1,1,1,1,1,1,1,1,1,1,1,1,1,1,1,1,1,1,1,1,1,1,1,1,1,1,1,1,1,1,1,1,1,1,1,1,1,1,1,1,1,1,1,1,1,1,1,1,1,1,1,1,1,1,1,1,1
1,1,1,1,1,1,1,1,1,1,1,1,1,1,1,1,1,1,1,1,1,1,1,1,1,1,1,1,1,1,1,1,1,1,1,1,1,1,1,1,1,1,1,1,1,1,1,1,1,1,1,1,1,1,1,1,1,1,1,1,1,1,1,1
1,1,1,1,1,1,1,1,1,1,1,1,1,1,1,1,1,1,1,1,1,1,1,1,1,1,1,1,1,1,1,1,1,1,1,1,1,1,1,1,1,1,1,1,1,1,1,1,1,1,1,1,1,1,1,1,1,1,1,1,1,1,1,1
1,1,1,1,1,1,1,1,1,1,1,1,1,1,1,1,1,1,1,1,1,1,1,1,1,1,1,1,1,1,1,1,1,1,1,1,1,1,1,1,1,1,1,1,1,1,1,1,1,1,1,1,1,1,1,1,1,1,1,1,1,1,1,1
1,1,1,1,1,1,1,1,1,1,1,1,1,1,1,1,1,1,1,1,1,1,1,1,1,1,1,1,1,1,1,1,1,1,1,1,1,1,1,1,1,1,1,1,1,1,1,1,1,1,1,1,1,1,1,1,1,1,1,1,1,1,1,1
1,1,1,1,1,1,1,1,1,1,1,1,1,1,1,1,1,1,1,1,1,1,1,1,1,1,1,1,1,1,1,1,1,1,1,1,1,1,1,1,1,1,1,1,1,1,1,1,1,1,1,1,1,1,1,1,1,1,1,1,1,1,1,1
1,1,1,1,1,1,1,1,1,1,1,1,1,1,1,1,1,1,1,1,1,1,1,1,1,1,1,1,1,1,1,1,1,1,1,1,1,1,1,1,1,1,1,1,1,1,1,1,1,1,1,1,1,1,1,1,1,1,1,1,1,1,1,1
:endlayer
layer: 2
1,1,1,1,1,1,1,1,1,1,1,1,1,1,1,1,1,1,1,1,1,1,1,1,1,1,1,1,1,1,1,1,1,1,1,1,1,1,1,1,1,1,1,1,1,1,1,1,1,1,1,1,1,1,1,1,1,1,1,1,1,1,1,1
1,1,1,1,1,1,1,1,1,1,1,1,1,1,1,1,1,1,1,1,1,1,1,1,1,1,1,1,1,1,1,1,1,1,1,1,1,1,1,1,1,1,1,1,1,1,1,1,1,1,1,1,1,1,1,1,1,1,1,1,1,1,1,1
1,1,2,2,2,2,2,2,2,2,2,2,2,2,2,2,2,2,2,2,2,2,2,2,2,2,2,2,2,2,2,2,2,2,2,2,2,2,2,2,2,2,2,2,2,2,2,2,2,2,2,2,2,2,2,2,2,2,2,2,2,2,1,1
1,1,2,2,2,2,2,2,2,2,2,2,2,2,2,2,2,2,2,2,2,2,2,2,2,2,2,2,2,2,2,2,2,2,2,2,2,2,2,2,2,2,2,2,2,2,2,2,2,2,2,2,2,2,2,2,2,2,2,2,2,2,1,1
1,1,2,2,2,2,2,2,2,2,2,2,2,2,2,2,2,2,2,2,2,2,2,2,2,2,2,2,2,2,2,2,2,2,2,2,2,2,2,2,2,2,2,2,2,2,2,2,2,2,2,2,2,2,2,2,2,2,2,2,2,2,1,1
1,1,2,2,2,2,1,1,1,1,1,1,1,1,1,1,1,1,1,1,1,1,1,1,1,1,1,1,1,1,1,1,1,1,1,1,1,1,1,1,1,1,1,1,1,1,1,1,1,1,1,1,1,1,1,1,1,1,2,2,2,2,1,1
1,1,2,2,2,2,1,1,1,1,1,1,1,1,1,1,1,1,1,1,1,1,1,1,1,1,1,1,1,1,1,1,1,1,1,1,1,1,1,1,1,1,1,1,1,1,1,1,1,1,1,1,1,1,1,1,1,1,2,2,2,2,1,1
1,1,2,2,2,2,1,1,1,1,1,1,1,1,1,1,1,1,1,1,1,1,1,1,1,1,1,1,1,1,1,1,1,1,1,1,1,1,1,1,1,1,1,1,1,1,1,1,1,1,1,1,1,1,1,1,1,1,2,2,2,2,1,1
1,1,2,2,2,2,1,1,1,1,1,1,1,1,1,1,1,1,1,1,1,1,1,1,1,1,1,1,1,1,1,1,1,1,1,1,1,1,1,1,1,1,1,1,1,1,1,1,1,1,1,1,1,1,1,1,1,1,2,2,2,2,1,1
1,1,2,2,2,2,1,1,1,1,1,1,1,1,1,1,1,1,1,1,1,1,1,1,1,1,1,1,1,1,1,1,1,0,1,1,1,1,1,1,1,1,1,1,1,1,1,1,1,1,1,1,1,1,1,1,1,1,2,2,2,2,1,1
1,1,2,2,2,2,1,1,1,1,1,1,1,1,1,1,1,1,1,1,1,1,1,1,1,1,1,1,1,1,1,1,1,1,1,1,1,1,1,1,1,1,1,1,1,1,1,1,1,1,1,1,1,1,1,1,1,1,2,2,2,2,1,1
1,1,2,2,2,2,1,1,1,1,1,1,1,1,1,1,1,1,1,1,1,1,1,1,1,1,1,1,1,1,1,1,1,1,1,1,1,1,1,1,1,1,1,1,1,1,1,1,1,1,1,1,1,1,1,1,1,1,2,2,2,2,1,1
1,1,2,2,2,2,1,1,1,1,1,1,1,1,1,1,1,1,1,1,1,1,1,1,1,1,1,1,1,1,1,1,1,1,1,1,1,1,1,1,1,1,1,1,1,1,1,1,1,1,1,1,1,1,1,1,1,1,2,2,2,2,1,1
1,1,2,2,2,2,1,1,1,1,1,1,1,1,1,1,1,1,1,1,1,1,1,1,1,1,1,1,1,1,1,1,1,1,1,1,1,1,1,1,1,1,1,1,1,1,1,1,1,1,1,1,1,1,1,1,1,1,2,2,2,2,1,1
1,1,2,2,2,2,1,1,1,1,1,1,1,1,1,1,1,1,1,1,1,1,1,1,1,1,1,1,1,1,1,1,1,1,1,1,1,1,1,1,1,1,1,1,1,1,1,1,1,1,1,1,1,1,1,1,1,1,2,2,2,2,1,1
1,1,2,2,2,2,1,1,1,1,1,1,1,1,1,1,1,1,1,1,1,1,1,1,1,1,1,1,1,1,1,1,1,1,1,1,1,1,1,1,1,1,1,1,1,1,1,1,1,1,1,1,1,1,1,1,1,1,2,2,2,2,1,1
1,1,2,2,2,2,1,1,1,1,1,1,1,1,1,1,1,1,1,1,1,1,1,1,1,1,1,1,1,1,1,1,1,1,1,1,1,1,1,1,1,1,1,1,1,1,1,1,1,1,1,1,1,1,1,1,1,1,2,2,2,2,1,1
1,1,2,2,2,2,1,1,1,1,1,1,1,1,1,1,1,1,1,1,1,1,1,1,1,1,1,1,1,1,1,1,1,1,1,1,1,1,1,1,1,1,1,1,1,1,1,1,1,1,1,1,1,1,1,1,1,1,2,2,2,2,1,1
1,1,2,2,2,2,1,1,1,1,1,1,1,1,1,1,1,1,1,1,1,1,1,1,1,1,1,1,1,1,1,1,1,3,1,1,1,1,1,1,1,1,1,1,1,1,1,1,1,1,1,1,1,1,1,1,1,1,2,2,2,2,1,1
1,1,2,2,2,2,1,1,1,1,1,1,1,1,1,1,1,1,1,1,1,1,1,1,1,1,1,1,1,1,1,1,1,1,1,1,1,1,1,1,1,1,1,1,1,1,1,1,1,1,1,1,1,1,1,1,1,1,2,2,2,2,1,1
1,1,2,2,2,2,1,1,1,1,1,1,1,1,1,1,1,1,1,1,1,1,1,1,1,1,1,1,1,1,1,1,1,1,1,1,1,1,1,1,1,1,1,1,1,1,1,1,1,1,1,1,1,1,1,1,1,1,2,2,2,2,1,1
1,1,2,2,2,2,1,1,1,1,1,1,1,1,1,1,1,1,1,1,1,1,1,1,1,1,1,1,1,1,1,1,1,1,1,1,1,1,1,1,1,1,1,1,1,1,1,1,1,1,1,1,1,1,1,1,1,1,2,2,2,2,1,1
1,1,2,2,2,2,1,1,1,1,1,1,1,1,1,1,1,1,1,1,1,1,1,1,1,1,1,1,1,1,1,1,1,1,1,1,1,1,1,1,1,1,1,1,1,1,1,1,1,1,1,1,1,1,1,1,1,1,2,2,2,2,1,1
1,1,2,2,2,2,1,1,1,1,1,1,1,1,1,1,1,1,1,1,1,1,1,1,1,1,1,1,1,1,1,1,1,1,1,1,1,1,1,1,1,1,1,1,1,1,1,1,1,1,1,1,1,1,1,1,1,1,2,2,2,2,1,1
1,1,2,2,2,2,1,1,1,1,1,1,1,1,1,1,1,1,1,1,1,1,1,1,1,1,1,1,1,1,1,1,1,1,1,1,1,1,1,1,1,1,1,1,1,1,1,1,1,1,1,1,1,1,1,1,1,1,2,2,2,2,1,1
1,1,2,2,2,2,1,1,1,1,1,1,1,1,1,1,1,1,1,1,1,1,1,1,1,1,1,1,1,1,1,1,1,1,1,1,1,1,1,1,1,1,1,1,1,1,1,1,1,1,1,1,1,1,1,1,1,1,2,2,2,2,1,1
1,1,2,2,2,2,1,1,1,1,1,1,1,1,1,1,1,1,1,1,1,1,1,1,1,1,1,1,1,1,1,1,1,1,1,1,1,1,1,1,1,1,1,1,1,1,1,1,1,1,1,1,1,1,1,1,1,1,2,2,2,2,1,1
1,1,2,2,2,2,1,1,1,1,1,1,1,1,1,1,1,1,1,1,1,1,1,1,1,1,1,1,1,1,1,1,1,1,1,1,1,1,1,1,1,1,1,1,1,1,1,1,1,1,1,1,1,1,1,1,1,1,2,2,2,2,1,1
1,1,2,2,2,2,1,1,1,1,1,1,1,1,1,1,1,1,1,1,1,1,1,1,1,1,1,1,1,1,1,1,1,1,1,1,1,1,1,1,1,1,1,1,1,1,1,1,1,1,1,1,1,1,1,1,1,1,2,2,2,2,1,1
1,1,2,2,2,2,1,1,1,1,1,1,1,1,1,1,1,1,1,1,1,1,1,1,1,1,1,1,1,1,1,1,1,1,1,1,1,1,1,1,1,1,1,1,1,1,1,1,1,1,1,1,1,1,1,1,1,1,2,2,2,2,1,1
1,1,2,2,2,2,1,1,1,1,1,1,1,1,1,1,1,1,1,1,1,1,1,1,1,1,1,1,1,1,1,1,1,1,1,1,1,1,1,1,1,1,1,1,1,1,1,1,1,1,1,1,1,1,1,1,1,1,2,2,2,2,1,1
1,1,2,2,2,2,1,1,1,1,1,1,1,1,1,1,1,1,1,1,1,1,1,1,1,1,1,1,1,1,1,1,1,1,1,1,1,1,1,1,1,1,1,1,1,1,1,1,1,1,1,1,1,1,1,1,1,1,2,2,2,2,1,1
1,1,2,2,2,2,1,1,1,1,1,1,1,1,1,1,1,1,1,1,1,1,1,1,1,1,1,1,1,1,1,1,1,1,1,1,1,1,1,1,1,1,1,1,1,1,1,1,1,1,1,1,1,1,1,1,1,1,2,2,2,2,1,1
1,1,2,2,2,2,1,1,1,1,1,1,1,1,1,1,1,1,1,1,1,1,1,1,1,1,1,1,1,1,1,1,1,1,1,1,1,1,1,1,1,1,1,1,1,1,1,1,1,1,1,1,1,1,1,1,1,1,2,2,2,2,1,1
1,1,2,2,2,2,1,1,1,1,1,1,1,1,1,1,1,1,1,1,1,1,1,1,1,1,1,1,1,1,1,1,1,1,1,1,1,1,1,1,1,1,1,1,1,1,1,1,1,1,1,1,1,1,1,1,1,1,2,2,2,2,1,1
1,1,2,2,2,2,1,1,1,1,1,1,1,1,1,1,1,1,1,1,1,1,1,1,1,1,1,1,1,1,1,1,1,1,1,1,1,1,1,1,1,1,1,1,1,1,1,1,1,1,1,1,1,1,1,1,1,1,2,2,2,2,1,1
1,1,2,2,2,2,1,1,1,1,1,1,1,1,1,1,1,1,1,1,1,1,1,1,1,1,1,1,1,1,1,1,1,1,1,1,1,1,1,1,1,1,1,1,1,1,1,1,1,1,1,1,1,1,1,1,1,1,2,2,2,2,1,1
1,1,2,2,2,2,1,1,1,1,1,1,1,1,1,1,1,1,1,1,1,1,1,1,1,1,1,1,1,1,1,1,1,1,1,1,1,1,1,1,1,1,1,1,1,1,1,1,1,1,1,1,1,1,1,1,1,1,2,2,2,2,1,1
1,1,2,2,2,2,1,1,1,1,1,1,1,1,1,1,1,1,1,1,1,1,1,1,1,1,1,1,1,1,1,1,1,1,1,1,1,1,1,1,1,1,1,1,1,1,1,1,1,1,1,1,1,1,1,1,1,1,2,2,2,2,1,1
1,1,2,2,2,2,1,1,1,1,1,1,1,1,1,1,1,1,1,1,1,1,1,1,1,1,1,1,1,1,1,1,1,1,1,1,1,1,1,1,1,1,1,1,1,1,1,1,1,1,1,1,1,1,1,1,1,1,2,2,2,2,1,1
1,1,2,2,2,2,1,1,1,1,1,1,1,1,1,1,1,1,1,1,1,1,1,1,1,1,1,1,1,1,1,1,1,1,1,1,1,1,1,1,1,1,1,1,1,1,1,1,1,1,1,1,1,1,1,1,1,1,1,1,1,1,1,1
1,1,2,2,2,2,1,1,1,1,1,1,1,1,1,1,1,1,1,1,1,1,1,1,1,1,1,1,1,1,1,1,1,1,1,1,1,1,1,1,1,1,1,1,1,1,1,1,1,1,1,1,1,1,1,1,1,1,1,1,1,1,1,1
1,1,2,2,2,2,1,1,1,1,1,1,1,1,1,1,1,1,1,1,1,1,1,1,1,1,1,1,1,1,1,1,1,1,1,1,1,1,1,1,1,1,1,1,1,1,1,1,1,1,1,1,1,1,1,1,1,1,1,1,1,1,1,1
1,1,1,1,1,1,1,1,1,1,1,1,1,1,1,1,1,1,1,1,1,1,1,1,1,1,1,1,1,1,1,1,1,1,1,1,1,1,1,1,1,1,1,1,1,1,1,1,1,1,1,1,1,1,1,1,1,1,1,1,1,1,1,1
1,1,1,1,1,1,1,1,1,1,1,1,1,1,1,1,1,1,1,1,1,1,1,1,1,1,1,1,1,1,1,1,1,1,1,1,1,1,1,1,1,1,1,1,1,1,1,1,1,1,1,1,1,1,1,1,1,1,1,1,1,1,1,1
1,1,1,1,1,1,1,1,1,1,1,1,1,1,1,1,1,1,1,1,1,1,1,1,1,1,1,1,1,1,1,1,1,1,1,1,1,1,1,1,1,1,1,1,1,1,1,1,1,1,1,1,1,1,1,1,1,1,1,1,1,1,1,1
1,1,1,1,1,1,1,1,1,1,1,1,1,1,1,1,1,1,1,1,1,1,1,1,1,1,1,1,1,1,1,1,1,1,1,1,1,1,1,1,1,1,1,1,1,1,1,1,1,1,1,1,1,1,1,1,1,1,1,1,1,1,1,1
:endlayer
layer: 3
4,4,4,4,4,4,4,4,4,4,4,4,4,4,4,4,4,4,4,4,4,4,4,4,4,4,4,4,4,4,4,4,4,4,4,4,4,4,4,4,4,4,4,4,4,4,4,4,4,4,4,4,4,4,4,4,4,4,4,4,4,4,4,4
4,4,4,4,1,4,4,1,4,4,1,4,4,1,4,4,1,4,4,1,4,4,1,4,4,1,4,4,1,4,4,1,4,4,1,4,4,1,4,4,1,4,4,1,4,4,1,4,4,1,4,4,1,4,4,1,4,4,1,4,4,1,4,4
4,4,2,2,2,2,2,2,2,2,2,2,2,2,2,2,2,2,2,2,2,2,2,2,2,2,2,2,2,2,2,2,2,2,2,2,2,2,2,2,2,2,2,2,2,2,2,2,2,2,2,2,2,2,2,2,2,2,2,2,2,2,1,4
4,1,2,2,2,2,2,2,2,2,2,2,2,2,2,2,2,2,2,2,2,2,2,2,2,2,2,2,2,2,2,2,2,2,2,2,2,2,2,2,2,2,2,2,2,2,2,2,2,2,2,2,2,2,2,2,2,2,2,2,2,2,4,4
4,4,2,2,2,2,2,2,2,2,2,2,2,2,2,2,2,2,2,2,2,2,2,2,2,2,2,2,2,2,2,2,2,2,2,2,2,2,2,2,2,2,2,2,2,2,2,2,2,2,2,2,2,2,2,2,2,2,2,2,2,2,4,4
4,4,2,2,2,2,1,1,1,1,1,1,1,1,1,1,1,1,1,1,1,1,1,1,1,1,1,3,3,3,3,3,3,3,1,1,1,1,1,1,1,1,1,1,1,1,1,1,1,1,1,1,1,1,1,1,1,1,2,2,2,2,1,4
4,1,2,2,2,2,1,1,1,1,1,1,1,1,1,1,1,1,1,1,1,1,1,1,1,1,1,3,3,3,3,3,3,3,1,1,1,1,1,1,1,1,1,1,1,1,1,1,1,1,1,1,1,1,1,1,1,1,2,2,2,2,4,4
4,4,2,2,2,2,1,1,1,1,1,1,1,1,1,1,1,1,1,1,1,1,1,1,1,1,1,3,3,3,3,3,3,3,1,1,1,1,1,1,1,1,1,1,1,1,1,1,1,1,1,1,1,1,1,1,1,1,2,2,2,2,4,4
4,4,2,2,2,2,1,1,1,1,1,1,1,1,1,1,1,1,1,1,1,1,1,1,1,1,1,3,3,3,3,3,3,3,1,1,1,1,1,1,1,1,1,1,1,1,1,1,1,1,1,1,1,1,1,1,1,1,2,2,2,2,1,4
4,1,2,2,2,2,1,1,1,1,1,1,1,1,1,1,1,1,1,1,1,1,1,1,1,1,1,3,3,3,3,3,3,3,1,1,1,1,1,1,1,1,1,1,1,1,1,1,1,1,1,1,1,1,1,1,1,1,2,2,2,2,4,4
4,4,2,2,2,2,1,1,1,1,1,1,1,1,1,1,1,1,1,1,1,1,1,1,1,1,1,3,3,3,3,3,3,3,1,1,1,1,1,1,1,1,1,1,1,1,1,1,1,1,1,1,1,1,1,1,1,1,2,2,2,2,4,4
4,4,2,2,2,2,1,1,1,1,1,1,1,1,1,1,1,1,1,1,1,1,1,1,1,1,1,3,3,3,3,3,3,3,1,1,1,1,1,1,1,1,1,1,1,1,1,1,1,1,1,1,1,1,1,1,1,1,2,2,2,2,1,4
4,1,2,2,2,2,1,1,1,1,1,1,1,1,1,1,1,1,1,1,1,1,1,1,1,1,1,3,3,3,3,3,3,3,1,1,1,1,1,1,1,1,1,1,1,1,1,1,1,1,1,1,1,1,1,1,1,1,2,2,2,2,4,4
4,4,2,2,2,2,1,1,1,1,1,1,1,1,1,1,1,1,1,1,1,1,1,1,1,1,1,3,3,3,3,3,3,3,1,1,1,1,1,1,1,1,1,1,1,1,1,1,1,1,1,1,1,1,1,1,1,1,2,2,2,2,4,4
4,4,2,2,2,2,1,1,1,1,1,1,1,1,1,1,1,1,1,1,1,1,1,1,1,1,1,3,3,3,3,3,3,3,1,1,1,1,1,1,1,1,1,1,1,1,1,1,1,1,1,1,1,1,1,1,1,1,2,2,2,2,1,4
4,1,2,2,2,2,1,1,1,1,1,1,1,1,1,1,1,1,1,1,1,1,1,1,1,1,1,3,3,3,3,3,3,3,1,1,1,1,1,1,1,1,1,1,1,1,1,1,1,1,1,1,1,1,1,1,1,1,2,2,2,2,4,4
4,4,2,2,2,2,1,1,1,1,1,1,1,1,1,1,1,1,1,1,1,1,1,1,1,1,1,3,3,3,3,3,3,3,1,1,1,1,1,1,1,1,1,1,1,1,1,1,1,1,1,1,1,1,1,1,1,1,2,2,2,2,4,4
4,1,2,2,2,2,1,1,1,1,1,1,1,1,1,1,1,1,1,1,1,1,1,1,1,1,1,3,3,3,3,3,3,3,1,1,1,1,1,1,1,1,1,1,1,1,1,1,1,1,1,1,1,1,1,1,1,1,2,2,2,2,1,4
4,4,2,2,2,2,1,1,1,1,1,1,1,1,1,1,1,1,1,1,1,1,1,1,1,1,1,3,3,3,3,3,3,3,1,1,1,1,1,1,1,1,1,1,1,1,1,1,1,1,1,1,1,1,1,1,1,1,2,2,2,2,4,4
4,4,2,2,2,2,1,1,1,1,1,1,1,1,1,1,1,1,1,1,1,1,1,1,1,1,1,3,3,3,3,3,3,3,1,1,1,1,1,1,1,1,1,1,1,1,1,1,1,1,1,1,1,1,1,1,1,1,2,2,2,2,4,4
4,1,2,2,2,2,1,1,1,1,1,1,1,1,1,1,1,1,1,1,1,1,1,1,1,1,1,3,3,3,3,3,3,3,1,1,1,1,1,1,1,1,1,1,1,1,1,1,1,1,1,1,1,1,1,1,1,1,2,2,2,2,1,4
4,4,2,2,2,2,1,1,1,1,1,1,1,1,1,1,1,1,1,1,1,1,1,1,1,1,1,3,3,3,3,3,3,3,1,1,1,1,1,1,1,1,1,1,1,1,1,1,1,1,1,1,1,1,1,1,1,1,2,2,2,2,4,4
4,4,2,2,2,2,1,1,1,1,1,1,1,1,1,1,1,1,1,1,1,1,1,1,1,1,1,3,3,3,3,3,3,3,1,1,1,1,1,1,1,1,1,1,1,1,1,1,1,1,1,1,1,1,1,1,1,1,2,2,2,2,4,4
4,1,2,2,2,2,1,1,1,1,1,1,1,1,1,1,1,1,1,1,1,1,1,1,1,1,1,3,3,3,3,3,3,3,1,1,1,1,1,1,1,1,1,1,1,1,1,1,1,1,1,1,1,1,1,1,1,1,2,2,2,2,1,4
4,4,2,2,2,2,1,1,1,1,1,1,1,1,1,1,1,1,1,1,1,1,1,1,1,1,1,3,3,3,3,3,3,3,1,1,1,1,1,1,1,1,1,1,1,1,1,1,1,1,1,1,1,1,1,1,1,1,2,2,2,2,4,4
4,4,2,2,2,2,1,1,1,1,3,3,3,3,3,3,3,1,3,3,3,3,3,3,3,3,1,3,3,3,3,3,3,3,1,1,1,1,1,1,1,1,1,1,1,1,1,1,1,1,1,1,1,1,1,1,1,1,2,2,2,2,4,4
4,1,2,2,2,2,1,1,1,1,3,3,3,3,3,3,3,1,3,3,3,3,3,3,3,3,1,3,3,3,3,3,3,3,1,1,1,1,1,1,1,1,1,1,1,1,1,1,1,1,1,1,1,1,1,1,1,1,2,2,2,2,1,4
4,4,2,2,2,2,1,1,1,1,3,3,3,3,3,3,3,1,3,3,3,3,3,3,3,3,1,3,3,3,3,3,3,3,1,1,1,1,1,1,1,1,1,1,1,1,1,1,1,1,1,1,1,1,1,1,1,1,2,2,2,2,4,4
4,4,2,2,2,2,1,1,1,1,4,4,4,3,4,4,4,1,3,3,3,3,3,3,3,3,1,3,3,3,3,3,3,3,1,1,1,1,1,1,1,1,1,1,1,1,1,1,1,1,1,1,1,1,1,1,1,1,2,2,2,2,4,4
4,1,2,2,2,2,1,1,1,3,3,3,3,3,3,3,3,1,3,3,3,3,3,3,3,3,1,3,3,3,3,3,3,3,1,1,1,1,1,1,1,1,1,1,1,1,1,1,1,1,1,1,1,1,1,1,1,1,2,2,2,2,1,4
4,4,2,2,2,2,1,1,1,3,3,3,3,3,3,3,3,1,3,3,3,3,3,3,3,3,1,3,3,3,3,3,3,3,1,1,1,1,1,1,1,1,1,1,1,1,1,1,1,1,1,1,1,1,1,1,1,1,2,2,2,2,4,4
4,4,2,2,2,2,1,1,1,3,3,3,3,3,3,3,3,1,3,3,3,3,3,3,3,3,1,3,3,3,3,3,3,3,1,1,1,1,1,1,1,1,1,1,1,1,1,1,1,1,1,1,1,1,1,1,1,1,2,2,2,2,4,4
4,1,2,2,2,2,1,1,1,3,3,3,3,3,3,3,3,1,3,3,1,1,1,1,1,3,1,3,3,3,3,3,3,3,1,1,1,1,1,1,1,1,1,1,1,1,1,1,1,1,1,1,1,1,1,1,1,1,2,2,2,2,1,4
4,4,2,2,2,2,1,1,1,3,3,3,3,3,3,3,3,1,3,3,3,3,1,1,1,3,1,3,3,3,3,3,3,3,1,1,1,1,1,1,1,1,1,1,1,1,1,1,1,1,1,1,1,1,1,1,1,1,2,2,2,2,4,4
4,4,2,2,2,2,1,1,1,3,3,3,3,1,1,1,3,1,3,3,3,3,4,1,1,3,1,3,3,3,3,3,3,3,1,1,1,1,1,1,1,1,1,1,1,1,1,1,1,1,1,1,1,1,1,1,1,1,2,2,2,2,4,4
4,1,2,2,2,2,1,1,1,3,3,3,3,1,1,1,3,1,3,3,3,3,1,1,1,3,1,3,3,3,3,3,3,3,1,1,1,1,1,1,1,1,1,1,1,1,1,1,1,1,1,1,1,1,1,1,1,1,2,2,2,2,1,4
4,4,2,2,2,2,1,1,1,3,3,3,3,3,1,1,1,1,3,3,3,3,3,4,1,3,1,3,3,3,3,3,3,3,1,1,1,1,1,1,1,1,1,1,1,1,1,1,1,1,1,1,1,1,1,1,1,1,2,2,2,2,4,4
4,4,2,2,2,2,1,1,1,3,3,3,3,3,1,1,1,1,3,3,3,3,1,3,3,3,1,3,3,3,3,3,3,3,1,1,1,1,1,1,1,1,1,1,1,1,1,1,1,1,1,1,1,1,1,1,1,1,2,2,2,2,4,4
4,1,2,2,2,2,1,1,1,3,3,3,3,3,4,1,1,1,3,3,3,3,1,3,3,3,1,3,3,3,3,3,3,3,1,1,1,1,1,1,1,1,1,1,1,1,1,1,1,1,1,1,1,1,1,1,1,1,2,2,2,2,1,4
4,4,2,2,2,2,1,1,1,3,3,3,3,3,3,1,1,1,3,3,3,3,1,3,3,3,1,3,3,3,3,3,3,3,1,1,1,1,1,1,1,1,1,1,1,1,1,1,1,1,1,1,1,1,1,1,1,1,2,2,2,2,4,4
4,4,2,2,2,2,1,1,1,1,1,1,1,1,4,1,1,1,1,1,4,4,1,1,1,1,1,3,3,3,3,3,3,3,1,1,4,1,4,4,1,4,4,1,4,4,1,1,1,1,1,1,4,4,1,4,4,1,4,4,1,4,4,4
4,1,2,2,2,2,1,1,1,1,2,2,2,2,2,2,1,4,4,4,1,4,4,1,4,4,4,3,3,3,3,3,3,3,4,4,4,4,4,4,4,4,4,5,5,5,1,1,1,1,1,1,4,4,4,4,4,4,4,4,4,4,4,4
4,4,2,2,2,2,1,1,1,1,2,2,2,2,2,2,1,4,4,4,4,4,4,4,4,4,4,3,3,3,3,3,3,3,4,4,4,4,4,4,4,4,4,5,5,5,4,1,1,1,1,4,5,5,5,4,4,4,4,4,4,4,4,4
4,4,4,1,4,4,1,4,4,4,1,4,4,4,1,4,4,4,4,4,4,4,4,4,4,4,4,5,5,5,5,5,5,5,4,4,4,4,4,4,4,4,4,5,5,5,4,1,1,1,1,4,5,5,5,4,4,4,4,4,4,4,4,4
4,4,4,4,4,4,4,4,4,4,4,4,4,4,4,4,4,4,4,4,4,4,4,4,4,4,4,5,5,5,5,5,5,5,5,5,5,5,5,5,5,5,5,5,5,5,5,5,5,5,5,5,5,5,5,4,4,4,4,4,4,4,4,4
4,4,4,4,4,4,4,4,4,4,4,4,4,4,4,4,4,4,4,4,4,4,4,4,4,4,4,5,5,5,5,5,5,5,5,5,5,5,5,5,5,5,5,5,5,5,5,5,5,5,5,5,5,5,5,4,4,4,4,4,4,4,4,4
4,4,4,4,4,4,4,4,4,4,4,4,4,4,4,4,4,4,4,4,4,4,4,4,4,4,4,5,5,5,5,5,5,5,5,5,5,5,5,5,5,5,5,5,5,5,5,5,5,5,5,5,5,5,5,4,4,4,4,4,4,4,4,4
:endlayer
layer: 4
0,6,0,6,0,0,0,0,6,6,6,0,0,0,6,6,6,0,0,0,0,0,0,6,6,0,0,0,0,0,0,0,0,6,0,6,6,0,0,0,6,6,0,6,0,0,0,6,6,6,0,0,0,0,6,6,6,0,0,6,0,6,6,0
0,0,6,6,2,0,0,2,6,6,2,0,0,2,0,0,2,6,0,2,0,0,2,6,6,2,0,0,2,0,0,2,0,6,2,6,6,2,0,0,2,6,0,2,0,0,2,6,6,2,0,0,2,0,6,2,6,0,2,0,6,2,6,0
0,0,2,2,2,2,2,2,2,2,2,2,2,2,2,2,2,2,2,2,2,2,2,2,2,2,2,2,2,2,2,2,2,2,2,2,2,2,2,2,2,2,2,2,2,2,2,2,2,2,2,2,2,2,2,2,2,2,2,2,2,2,2,0
0,2,2,2,2,2,2,2,2,2,2,2,2,2,2,2,2,2,2,2,2,2,2,2,2,2,2,2,2,2,2,2,2,2,2,2,2,2,2,2,2,2,2,2,2,2,2,2,2,2,2,2,2,2,2,2,2,2,2,2,2,2,6,6
6,0,2,2,2,2,2,2,2,2,2,2,2,2,2,2,2,2,2,2,2,2,2,2,2,2,2,2,2,2,2,2,2,2,2,2,2,2,2,2,2,2,2,2,2,2,2,2,2,2,2,2,2,2,2,2,2,2,2,2,2,2,6,0
6,0,2,2,2,2,3,3,3,3,3,3,3,3,3,3,3,3,3,3,3,3,3,3,3,3,3,3,3,3,3,3,3,3,3,3,3,3,3,3,3,3,3,3,3,3,3,3,3,3,3,3,3,3,3,3,3,3,2,2,2,2,2,6
6,2,2,2,2,2,1,1,1,1,1,1,1,1,1,1,1,1,1,1,1,1,1,1,1,1,1,3,3,3,3,3,3,3,1,1,1,1,1,1,1,1,1,1,1,1,1,1,1,1,1,1,1,1,1,1,3,3,2,2,2,2,6,6
6,6,2,2,2,2,1,1,1,1,1,1,1,1,1,1,1,1,1,1,1,1,1,1,1,1,1,3,3,3,3,3,3,3,1,1,1,1,1,1,1,1,1,1,1,1,1,1,1,1,1,1,1,1,1,1,3,3,2,2,2,2,0,6
6,0,2,2,2,5,5,5,1,1,1,1,1,1,1,1,1,1,1,1,1,1,1,1,1,1,1,3,3,3,3,3,3,3,1,1,1,1,1,1,1,1,1,1,1,1,1,1,1,1,1,1,1,1,1,1,3,3,2,2,2,2,2,0
0,2,2,2,2,5,5,5,1,1,1,1,1,1,1,1,1,1,1,1,1,1,1,1,1,1,1,3,3,3,3,3,3,3,1,1,1,1,1,1,1,1,1,1,1,1,1,1,1,1,1,1,1,1,1,1,3,3,2,2,2,2,0,0
0,0,2,2,2,5,5,5,1,1,1,1,1,1,1,1,1,1,1,1,1,1,1,1,1,1,1,3,3,3,3,3,3,3,1,1,1,1,1,1,1,1,1,1,1,1,1,1,1,1,1,1,1,1,1,1,3,3,2,2,2,2,0,0
0,0,2,2,2,5,5,5,1,1,1,1,1,1,1,1,1,1,1,1,1,1,1,1,1,1,1,3,3,3,3,3,3,3,1,1,1,1,1,1,1,1,1,1,1,1,1,1,1,1,1,1,1,1,1,1,3,3,2,2,2,2,2,6
6,2,2,2,2,5,5,5,1,1,1,1,1,1,1,1,1,1,1,1,1,1,1,1,1,1,1,3,3,3,3,3,3,3,1,1,1,1,1,1,1,1,1,1,1,1,1,1,1,1,1,1,1,1,1,1,3,3,2,2,2,2,6,6
6,6,2,2,2,5,5,5,1,1,1,1,1,1,1,1,1,1,1,1,1,1,1,1,1,1,1,3,3,3,3,3,3,3,1,1,1,1,1,1,1,1,1,1,1,1,1,1,1,1,1,1,1,1,1,1,3,3,2,2,2,2,6,0
6,6,2,2,2,5,5,5,1,1,1,1,1,1,1,1,1,1,1,1,1,1,1,1,1,1,1,3,3,3,3,3,3,3,1,1,1,1,1,1,1,1,1,1,1,1,1,1,1,1,1,1,1,1,1,1,3,3,2,2,2,2,2,0
6,2,2,2,2,5,5,5,1,1,1,1,1,1,1,1,1,1,1,1,1,1,1,1,1,1,1,3,3,3,3,3,3,3,1,1,1,1,1,1,1,1,1,1,1,1,1,1,1,1,1,1,1,1,1,1,1,1,2,2,2,2,0,0
0,0,2,2,2,2,4,4,5,1,4,4,1,4,4,1,4,4,1,4,4,1,4,4,1,3,3,3,3,3,3,3,3,3,3,3,1,4,4,1,4,4,1,4,4,1,4,4,1,4,4,1,1,1,1,1,1,4,2,2,2,2,0,0
0,2,2,2,2,5,5,5,5,4,4,4,4,4,4,4,4,4,4,4,4,4,4,4,4,3,3,3,3,3,3,3,3,3,3,3,4,4,4,4,4,4,4,4,4,4,4,4,4,4,4,4,4,4,4,4,4,5,2,2,2,2,2,0
6,0,2,2,2,5,5,5,5,4,4,4,4,4,4,4,4,4,4,4,4,4,4,4,1,3,3,3,3,3,3,3,3,3,3,3,1,4,4,4,4,4,4,4,4,4,4,4,4,4,4,4,4,4,4,4,4,5,2,2,2,2,6,6
0,0,2,2,2,5,5,5,5,4,4,4,4,4,4,4,4,4,4,4,4,4,4,4,1,3,3,3,3,3,3,3,3,3,3,3,1,4,4,4,4,4,4,4,4,4,4,4,4,4,4,4,4,4,4,4,4,5,2,2,2,2,6,6
0,2,2,2,2,2,4,5,5,4,4,4,4,4,4,4,4,4,4,4,4,4,4,4,4,3,2,13,13,13,13,13,13,13,2,3,4,4,4,4,4,4,4,4,4,4,4,4,4,4,4,4,4,4,4,4,4,5,2,2,2,2,2,0
0,0,2,2,2,2,1,5,5,1,4,4,1,4,4,1,4,4,1,4,4,1,4,4,1,3,2,0,0,0,0,0,0,0,2,3,1,4,4,1,4,4,1,4,4,1,4,4,1,4,4,1,4,4,4,4,4,5,2,2,2,2,0,0
6,6,2,2,2,2,1,5,5,5,5,5,5,5,5,5,5,5,5,5,5,5,5,5,5,3,7,0,0,0,0,0,0,0,9,3,5,5,5,5,5,5,5,5,5,5,5,5,5,5,5,5,5,5,5,5,5,5,2,2,2,2,0,0
0,2,2,2,2,2,1,5,5,5,5,5,5,5,5,5,5,5,5,5,5,5,5,5,5,3,7,0,0,0,0,0,0,0,9,3,5,5,5,5,5,5,5,5,5,5,5,5,5,5,5,5,5,5,5,5,5,5,2,2,2,2,2,0
6,0,2,2,2,2,2,2,2,2,2,2,2,2,2,2,2,2,2,2,2,2,2,2,2,2,14,0,0,0,0,0,0,15,14,2,2,2,2,2,2,2,2,2,2,2,2,2,2,2,2,2,2,2,2,2,2,2,2,2,2,2,0,0
0,0,2,2,2,2,2,2,2,26,0,14,14,14,23,14,21,8,0,0,0,0,0,18,8,8,2,0,0,0,0,0,0,15,2,8,8,8,8,8,8,8,8,8,8,8,8,8,8,8,8,2,2,2,2,2,2,2,2,2,2,2,0,0
0,2,2,2,2,2,2,2,2,27,0,0,0,0,0,0,0,8,0,0,0,0,0,0,0,0,2,0,0,0,0,0,0,15,2,8,8,8,8,8,8,8,8,8,8,8,8,8,8,8,8,2,2,2,2,2,2,2,2,2,2,2,2,6
0,0,2,2,2,2,2,2,2,8,0,0,0,0,0,0,0,8,0,0,0,0,0,0,0,0,2,0,0,0,0,0,0,0,2,8,8,8,8,8,8,8,8,8,8,8,8,8,8,8,8,2,2,2,2,2,2,2,2,2,2,2,6,6
0,0,2,2,2,2,2,2,2,8,18,18,18,0,22,22,22,8,0,0,0,0,0,0,0,0,2,0,0,0,0,0,0,0,2,8,8,8,8,8,8,8,8,8,8,8,8,8,8,8,8,2,2,2,2,2,2,2,2,2,2,2,0,0
0,2,2,2,2,2,2,2,2,0,0,0,0,0,0,0,0,8,0,0,0,0,0,0,0,0,2,0,0,0,0,0,0,0,2,8,8,12,12,12,12,12,12,12,8,8,8,8,8,8,8,2,2,2,2,2,2,2,2,2,2,2,2,0
6,6,2,2,2,2,2,2,2,0,0,0,0,0,0,0,0,8,0,0,0,0,0,0,0,0,2,0,0,0,0,0,0,0,2,8,8,12,12,12,12,12,12,12,8,8,8,8,8,8,8,2,2,2,2,2,2,2,2,2,2,2,0,0
0,6,2,2,2,2,2,2,2,8,0,0,0,0,0,0,0,8,0,0,0,0,0,0,8,16,2,0,0,0,0,0,0,0,2,8,8,12,12,12,12,12,12,12,8,8,8,8,8,8,8,2,2,2,2,2,2,2,2,2,2,2,0,0
6,2,2,2,2,2,2,2,2,24,0,0,0,0,0,0,0,8,8,20,8,8,8,8,8,0,2,0,0,0,0,0,0,0,2,8,8,12,12,12,12,12,12,12,8,8,8,8,8,8,8,2,2,2,2,2,2,2,2,2,2,2,2,0
0,0,2,2,2,2,2,2,2,0,0,0,0,0,0,0,0,8,0,0,0,8,8,8,8,0,2,0,0,0,0,0,0,0,2,8,8,12,12,12,12,12,12,12,8,8,8,8,8,8,8,2,2,2,2,2,2,2,2,2,2,2,6,6
6,0,2,2,2,2,2,2,2,2,0,0,2,2,2,2,2,8,0,0,0,0,18,8,8,0,2,0,0,0,0,0,0,0,2,8,8,8,8,8,8,8,8,8,8,8,8,8,8,8,8,2,2,2,2,2,2,2,2,2,2,2,6,6
0,2,2,2,2,2,2,2,2,2,0,0,2,2,8,2,2,8,0,0,0,8,8,8,8,0,2,0,0,0,0,0,0,0,2,8,8,8,8,8,8,8,8,8,8,8,8,8,8,8,8,2,2,2,2,2,2,2,2,2,2,2,2,6
0,0,2,2,2,2,2,2,2,0,0,0,0,2,2,2,8,8,0,0,0,19,0,18,8,0,2,0,0,0,0,0,0,0,2,8,2,8,8,8,8,8,8,8,8,8,8,8,8,8,8,2,2,2,2,2,2,2,2,2,2,2,6,6
0,0,2,2,2,2,2,2,2,0,0,0,0,0,2,8,8,8,0,0,0,8,8,8,8,0,2,0,0,0,0,0,0,0,2,8,2,2,2,2,2,8,8,8,8,8,8,8,8,8,8,2,2,2,2,2,2,2,2,2,2,2,6,0
0,2,2,2,2,2,2,2,2,28,0,0,0,0,24,8,8,8,0,0,0,0,8,0,0,0,2,0,0,0,0,0,0,0,2,8,2,2,2,2,2,8,8,8,8,8,8,8,8,8,8,2,2,2,2,2,2,2,2,2,2,2,2,6
0,0,2,2,2,2,2,2,2,2,25,0,0,0,0,8,8,8,0,0,0,0,8,0,0,0,2,0,0,0,0,0,0,0,2,8,10,11,11,11,11,11,11,11,11,10,2,2,2,2,2,2,2,2,2,2,2,2,2,2,2,2,0,0
6,6,2,2,2,2,2,2,2,2,11,11,11,11,11,11,8,10,11,11,11,11,11,11,11,10,2,2,0,0,0,0,0,2,2,10,0,2,0,6,2,0,0,2,0,0,2,2,2,2,2,2,6,0,2,0,0,2,0,0,2,0,0,6
6,2,2,2,2,2,2,2,2,8,2,2,2,2,2,2,2,13,6,0,2,0,0,2,0,13,13,13,0,0,0,0,0,13,13,13,0,6,6,6,0,0,0,0,0,0,2,2,2,2,2,2,6,6,0,0,0,0,0,0,0,0,6,6
6,0,2,2,2,2,2,2,10,2,2,2,2,2,2,2,10,6,6,0,0,0,0,6,0,17,0,0,0,0,0,0,0,0,0,6,6,6,6,6,0,0,0,0,0,0,9,2,2,2,2,7,0,0,0,0,6,6,6,0,6,6,6,6
6,0,0,2,0,0,2,0,6,6,2,0,6,0,2,0,0,0,0,0,0,0,0,6,6,6,6,0,0,0,0,0,0,0,0,6,6,6,6,6,0,0,0,0,0,0,9,2,2,2,2,7,0,0,0,6,6,6,6,0,0,6,6,6
0,6,0,6,6,0,0,29,0,6,6,6,6,0,0,0,6,6,6,0,0,0,6,0,0,0,0,0,0,0,0,0,0,0,0,0,0,0,0,0,0,0,0,0,0,0,0,0,0,0,0,0,0,0,0,0,6,6,6,0,0,6,6,6
0,0,0,0,6,0,0,0,0,6,6,6,6,6,0,0,6,6,0,6,0,0,0,0,0,0,0,0,0,0,0,0,0,0,0,0,0,0,0,0,0,0,0,0,0,0,0,0,0,0,0,0,0,0,0,6,6,0,0,0,0,0,0,0
0,0,6,6,0,6,0,0,6,0,6,6,0,0,0,0,6,6,6,6,0,0,0,0,0,0,0,0,0,0,0,0,0,0,0,0,0,0,0,0,0,0,0,0,0,0,0,0,0,0,0,0,0,0,0,6,6,6,0,0,0,0,0,0
:endlayer
layer: 5
0,0,0,0,0,0,0,0,0,0,0,0,0,0,0,0,0,0,0,0,0,0,0,0,0,0,0,0,0,0,0,0,0,0,0,0,0,0,0,0,0,0,0,0,0,0,0,0,0,0,0,0,0,0,0,0,0,0,0,0,0,0,0,0
0,0,0,0,2,0,0,2,0,0,2,0,0,2,0,0,2,0,0,2,0,0,2,0,0,2,0,0,2,0,0,2,0,0,2,0,0,2,0,0,2,0,0,2,0,0,2,0,0,2,0,0,2,0,0,2,0,0,2,0,0,2,0,0
0,0,2,2,2,2,2,2,2,2,2,2,2,2,2,2,2,2,2,2,2,2,2,2,2,2,2,2,2,2,2,2,2,2,2,2,2,2,2,2,2,2,2,2,2,2,2,2,2,2,2,2,2,2,2,2,2,2,2,2,2,2,2,0
0,2,2,2,2,2,2,2,2,2,2,2,2,2,2,2,2,2,2,2,2,2,2,2,2,2,2,2,2,2,2,2,2,2,2,2,2,2,2,2,2,2,2,2,2,2,2,2,2,2,2,2,2,2,2,2,2,2,2,2,2,2,0,0
0,0,2,2,2,2,2,2,2,2,2,2,2,2,2,2,2,2,2,2,2,2,2,2,2,2,2,2,2,2,2,2,2,2,2,2,2,2,2,2,2,2,2,2,2,2,2,2,2,2,2,2,2,2,2,2,2,2,2,2,2,2,0,0
0,0,2,2,2,2,3,3,3,3,3,3,3,3,3,3,3,3,3,3,3,3,3,3,3,3,3,3,3,3,3,3,3,3,3,3,3,3,3,3,3,3,3,3,3,3,3,3,3,3,3,3,3,3,3,3,3,3,2,2,2,2,2,0
0,2,2,2,2,2,5,5,5,4,4,4,4,1,4,4,4,4,4,4,4,4,4,4,4,3,3,3,3,3,3,3,3,3,3,3,4,4,4,4,4,4,4,4,4,4,4,1,4,4,4,4,4,4,4,4,5,3,2,2,2,2,0,0
0,0,2,2,2,2,5,5,5,4,4,4,4,4,4,4,4,4,4,4,4,4,4,4,4,3,3,3,3,3,3,3,3,3,3,3,4,4,4,4,4,4,4,4,4,4,4,4,4,4,4,4,4,4,4,4,5,3,2,2,2,2,0,0
0,0,2,2,2,5,5,5,5,4,4,4,4,4,4,4,4,4,4,4,4,4,4,4,4,3,3,3,3,3,3,3,3,3,3,3,4,4,4,4,4,4,4,4,4,4,4,4,4,4,4,4,4,4,4,1,5,5,2,2,2,2,2,0
0,2,2,2,2,5,5,5,5,4,4,4,4,4,4,4,4,4,4,4,4,4,4,4,1,3,3,3,3,3,3,3,3,3,3,3,1,4,4,4,4,4,4,4,4,4,4,4,4,4,4,4,4,4,4,4,5,5,2,2,2,2,0,0
0,0,2,2,2,5,5,5,5,4,4,4,4,4,4,4,4,4,4,4,4,4,4,4,1,3,3,3,3,3,3,3,3,3,3,3,1,4,4,4,4,4,4,4,4,4,4,4,4,4,4,4,4,4,4,4,5,5,2,2,2,2,0,0
0,0,2,2,2,5,5,5,5,4,4,4,4,4,4,4,4,4,4,4,4,4,4,4,4,3,3,3,3,3,3,3,3,3,3,3,4,4,4,4,4,4,4,4,4,4,4,4,4,4,4,4,4,4,4,1,5,5,2,2,2,2,2,0
0,2,2,2,2,5,5,5,5,4,4,4,4,4,4,4,4,4,4,4,4,4,4,4,4,3,3,3,3,3,3,3,3,3,3,3,4,4,4,4,4,4,4,4,4,4,4,4,4,4,4,4,4,4,4,4,5,5,2,2,2,2,0,0
0,0,2,2,2,5,5,5,5,4,4,4,4,1,4,4,4,4,4,4,4,4,4,4,4,3,3,3,3,3,3,3,3,3,3,3,4,4,4,4,4,4,4,4,4,4,4,1,4,4,4,4,4,4,4,4,5,5,2,2,2,2,0,0
0,0,2,2,2,5,5,5,5,4,4,4,4,4,4,4,4,4,4,4,4,4,1,4,1,3,3,3,3,3,3,3,3,3,3,3,1,4,1,4,4,4,4,4,4,4,4,4,4,4,4,4,4,4,4,4,3,5,2,2,2,2,2,0
0,2,2,2,2,5,5,5,5,5,5,5,5,5,5,5,5,5,5,5,5,5,5,5,5,3,3,3,3,3,3,3,3,3,3,3,5,5,5,5,5,5,5,5,5,5,5,5,5,5,5,5,5,5,5,5,5,5,2,2,2,2,0,0
0,0,2,2,2,13,13,13,13,10,0,0,10,0,0,10,0,0,10,0,0,10,0,0,10,13,13,13,13,13,13,13,13,13,13,13,10,0,0,10,0,0,10,0,0,10,0,0,10,0,0,10,2,2,2,2,2,13,2,2,2,2,0,0
0,2,2,2,2,0,0,0,0,0,0,0,0,0,0,0,0,0,0,0,0,0,0,0,0,0,0,0,0,0,0,0,0,0,0,0,0,0,0,0,0,0,0,0,0,0,0,0,0,0,0,0,0,0,0,0,0,0,2,2,2,2,2,0
0,0,2,2,2,0,0,0,0,0,0,0,0,0,0,0,0,0,0,0,0,0,0,0,10,22,0,0,0,0,0,0,0,0,0,18,10,0,0,0,0,0,0,0,0,0,0,0,0,0,0,0,0,0,0,0,0,0,2,2,2,2,0,0
0,0,2,2,2,0,0,0,0,0,0,0,0,0,0,0,0,0,0,0,0,0,0,0,10,22,0,0,0,0,0,0,0,0,0,18,10,0,0,0,0,0,0,0,0,0,0,0,0,0,0,0,0,0,0,0,0,0,2,2,2,2,0,0
0,2,2,2,2,30,30,0,0,0,0,0,0,0,0,0,0,0,0,0,0,0,0,0,0,0,0,0,0,0,0,0,0,0,0,0,0,0,0,0,0,0,0,0,0,0,0,0,0,0,0,0,0,0,0,0,0,0,2,2,2,2,2,0
0,0,2,2,2,2,2,0,0,10,0,0,10,0,0,10,0,0,10,0,0,10,0,0,10,0,2,0,0,0,0,0,0,0,2,0,10,0,0,10,0,0,10,0,0,10,0,0,10,0,0,10,0,0,0,0,0,0,2,2,2,2,0,0
0,0,2,2,2,2,2,0,0,0,0,0,0,0,0,0,0,0,0,0,0,0,0,0,0,0,0,0,0,0,0,0,0,0,0,0,0,0,0,0,0,0,0,0,0,0,0,0,0,0,0,0,0,0,0,0,0,0,2,2,2,2,0,0
0,2,2,2,2,2,2,0,0,0,0,0,0,0,0,0,0,0,0,0,0,0,0,0,0,0,0,0,0,0,0,0,0,0,35,0,0,0,0,0,0,0,0,0,0,0,0,0,0,0,0,0,0,0,0,0,0,0,2,2,2,2,2,0
0,0,2,2,2,2,2,2,2,2,2,2,2,2,2,2,2,2,2,2,2,2,2,2,2,2,14,0,0,0,0,0,0,15,14,2,2,2,2,2,2,2,2,2,2,2,2,2,2,2,2,2,2,2,2,30,30,30,2,2,2,2,0,0
0,0,2,2,2,2,2,2,2,0,0,42,42,42,0,0,0,8,0,0,0,0,0,0,18,8,2,0,0,0,0,0,0,15,2,8,0,0,0,0,0,0,0,0,0,8,0,0,0,0,0,2,2,2,2,2,2,2,2,2,2,2,0,0
0,2,2,2,2,2,2,2,2,0,0,0,0,0,0,0,0,8,0,0,0,0,0,0,0,0,2,0,0,0,0,0,0,15,2,8,0,0,0,0,0,0,0,0,0,8,0,0,0,0,0,2,2,2,2,2,2,2,2,2,2,2,2,0
0,0,2,2,2,2,2,2,2,8,0,0,0,0,0,0,0,8,0,0,0,0,0,0,0,0,2,0,0,0,0,0,0,0,2,8,0,0,0,0,0,0,0,0,0,8,0,0,0,0,0,2,2,2,2,2,2,2,2,2,2,2,0,0
0,0,2,2,2,2,2,2,2,8,18,18,18,0,22,22,22,8,0,0,0,0,0,0,0,0,2,0,0,0,0,0,0,0,2,8,8,8,34,8,8,8,8,8,8,8,0,0,0,0,0,2,2,2,2,2,2,2,2,2,2,2,0,0
0,2,2,2,2,2,2,2,2,43,0,0,0,0,0,0,0,8,0,0,0,0,0,0,0,0,2,0,0,0,0,0,0,0,2,8,8,0,0,0,0,0,0,0,32,8,0,0,0,0,0,2,2,2,2,2,2,2,2,2,2,2,2,0
0,0,2,2,2,2,2,2,2,44,0,0,0,0,0,0,0,8,0,0,0,0,0,0,0,0,2,0,0,0,0,0,0,0,2,8,8,0,0,0,0,0,0,0,0,8,0,0,0,0,0,2,2,2,2,2,2,2,2,2,2,2,0,0
0,0,2,2,2,2,2,2,2,24,0,0,0,0,0,0,0,8,0,0,0,0,0,0,8,36,2,0,0,0,0,0,0,0,2,8,24,0,0,0,0,0,0,0,0,8,0,0,0,0,0,2,2,2,2,2,2,2,2,2,2,2,0,0
0,2,2,2,2,2,2,2,2,0,0,0,0,0,0,0,0,8,8,39,8,8,8,8,8,0,2,0,0,0,0,0,0,0,2,8,0,0,0,0,0,0,0,0,0,8,0,0,0,0,0,2,2,2,2,2,2,2,2,2,2,2,2,0
0,0,2,2,2,2,2,2,2,0,0,0,0,0,0,0,0,8,0,0,0,8,8,8,8,0,2,0,0,0,0,0,0,0,2,8,8,0,0,0,0,0,0,0,0,31,0,0,0,0,0,2,2,2,2,2,2,2,2,2,2,2,0,0
0,0,2,2,2,2,2,2,2,2,0,0,2,8,8,8,2,8,0,0,0,0,0,18,8,0,2,0,0,0,0,0,0,0,2,8,8,0,0,0,0,0,0,0,33,8,0,0,0,0,0,2,2,2,2,2,2,2,2,2,2,2,0,0
0,2,2,2,2,2,2,2,2,2,0,0,2,8,8,8,2,8,0,0,0,8,8,8,8,0,2,0,0,0,0,0,0,0,2,8,8,8,0,0,0,0,0,0,0,8,0,0,0,0,0,2,2,2,2,2,2,2,2,2,2,2,2,0
0,0,2,2,2,2,2,2,2,0,0,0,0,8,8,8,8,8,0,0,0,38,0,0,18,0,2,0,0,0,0,0,0,0,2,8,8,8,0,0,0,0,0,0,0,8,2,2,2,2,2,2,2,2,2,2,2,2,2,2,2,2,0,0
0,0,2,2,2,2,2,2,2,0,0,0,0,0,24,0,0,8,0,0,0,8,8,8,8,0,2,0,0,0,0,0,0,0,2,8,8,8,8,8,8,0,0,0,0,8,2,2,2,2,2,2,2,2,2,2,2,2,2,2,2,2,0,0
0,2,2,2,2,2,2,2,2,0,0,0,0,0,0,0,40,8,0,0,0,0,8,0,0,0,2,0,0,0,0,0,0,0,2,8,8,22,0,0,0,0,0,0,0,8,2,2,2,2,2,2,2,2,2,2,2,2,2,2,2,2,2,0
0,0,2,2,2,2,2,2,2,2,0,0,0,0,0,0,41,8,0,0,0,0,8,0,0,37,2,0,0,0,0,0,0,0,2,8,10,11,11,11,11,11,11,11,11,10,2,2,2,2,2,2,2,2,2,2,2,2,2,2,2,2,0,0
0,0,2,2,2,2,2,2,2,2,11,11,11,11,11,11,2,10,11,11,11,11,11,11,11,10,2,14,0,0,0,0,0,14,2,10,0,2,0,0,2,0,0,2,0,0,2,2,2,2,2,2,0,0,2,0,0,2,0,0,2,0,0,0
0,2,2,2,2,2,2,2,2,8,2,2,2,2,2,2,2,0,0,0,2,0,0,2,0,0,0,0,0,0,0,0,0,0,0,0,0,0,0,0,0,0,0,0,0,0,2,2,2,2,2,2,0,0,0,0,0,0,0,0,0,0,0,0
0,0,2,2,2,2,2,2,10,2,2,2,2,2,2,2,10,0,0,0,0,0,0,0,0,0,0,0,0,0,0,0,0,0,0,0,0,0,0,0,0,0,0,0,0,0,0,9,2,2,7,0,0,0,0,0,0,0,0,0,0,0,0,0
0,0,0,2,0,0,2,0,0,0,2,0,0,0,2,0,0,0,0,0,0,0,0,0,0,0,0,0,0,0,0,0,0,0,0,0,0,0,0,0,0,0,0,0,0,0,0,9,2,2,7,0,0,0,0,0,0,0,0,0,0,0,0,0
0,0,0,0,0,0,0,0,0,0,0,0,0,0,0,0,0,0,0,0,0,0,0,0,0,0,0,0,0,0,0,0,0,0,0,0,0,0,0,0,0,0,0,0,0,0,0,0,0,0,0,0,0,0,0,0,0,0,0,0,0,0,0,0
0,0,0,0,0,0,0,0,0,0,0,0,0,0,0,0,0,0,0,0,0,0,0,0,0,0,0,0,0,0,0,0,0,0,0,0,0,0,0,0,0,0,0,0,0,0,0,0,0,0,0,0,0,0,0,0,0,0,0,0,0,0,0,0
0,0,0,0,0,0,0,0,0,0,0,0,0,0,0,0,0,0,0,0,0,0,0,0,0,0,0,0,0,0,0,0,0,0,0,0,0,0,0,0,0,0,0,0,0,0,0,0,0,0,0,0,0,0,0,0,0,0,0,0,0,0,0,0
:endlayer
layer: 6
0,0,0,0,0,0,0,0,0,0,0,0,0,0,0,0,0,0,0,0,0,0,0,0,0,0,0,0,0,0,0,0,0,0,0,0,0,0,0,0,0,0,0,0,0,0,0,0,0,0,0,0,0,0,0,0,0,0,0,0,0,0,0,0
0,0,0,0,2,0,0,2,0,0,2,0,0,2,0,0,2,0,0,2,0,0,2,0,0,2,0,0,2,0,0,2,0,0,2,0,0,2,0,0,2,0,0,2,0,0,2,0,0,2,0,0,2,0,0,2,0,0,2,0,0,2,0,0
0,0,2,2,2,2,2,2,2,2,2,2,2,2,2,2,2,2,2,2,2,2,2,2,2,2,2,2,2,2,2,2,2,2,2,2,2,2,2,2,2,2,2,2,2,2,2,2,2,2,2,2,2,2,2,2,2,2,2,2,2,2,2,0
0,2,2,2,2,2,2,2,2,2,2,2,2,2,2,2,2,2,2,2,2,2,2,2,2,2,2,2,2,2,2,2,2,2,2,2,2,2,2,2,2,2,2,2,2,2,2,2,2,2,2,2,2,2,2,2,2,2,2,2,2,2,0,0
0,0,2,2,2,2,2,2,2,2,2,2,2,2,2,2,2,2,2,2,2,2,2,2,2,2,2,2,2,2,2,2,2,2,2,2,2,2,2,2,2,2,2,2,2,2,2,2,2,2,2,2,2,2,2,2,2,2,2,2,2,2,0,0
0,0,2,2,2,2,2,2,10,0,0,0,0,0,0,0,0,0,0,0,0,0,10,0,10,0,0,0,0,2,2,2,0,0,0,0,10,0,10,0,0,0,0,0,0,0,0,0,0,0,0,0,0,0,0,0,10,2,2,2,2,2,2,0
0,2,2,2,2,2,2,2,0,0,0,0,0,10,0,0,0,0,0,0,0,0,0,0,0,0,0,0,0,2,2,2,0,0,0,0,0,0,0,0,0,0,0,0,0,0,0,10,0,0,0,0,0,0,0,0,0,2,2,2,2,2,0,0
0,0,2,2,2,13,13,13,0,0,0,0,0,0,0,0,0,0,0,0,0,0,0,0,0,0,0,0,0,13,13,13,0,0,0,0,0,0,0,0,0,0,0,0,0,0,0,0,0,0,0,0,0,0,0,0,0,13,2,2,2,2,0,0
0,0,2,2,2,0,0,0,0,0,0,0,0,0,0,0,0,0,0,0,0,0,0,0,0,0,0,0,0,0,0,0,0,0,0,0,0,0,0,0,0,0,0,0,0,0,0,0,0,0,0,0,0,0,0,10,0,0,2,2,2,2,2,0
0,2,2,2,2,0,0,0,0,0,0,0,0,0,0,0,0,0,0,0,0,0,0,0,10,22,0,0,0,0,0,0,0,0,0,18,10,0,0,0,0,0,0,0,0,0,0,0,0,0,0,0,0,0,0,0,0,0,2,2,2,2,0,0
0,0,2,2,2,0,0,0,0,0,0,0,0,0,0,0,0,0,0,0,0,0,0,0,10,22,0,0,0,0,0,0,0,0,0,18,10,0,0,0,0,0,0,0,0,0,0,0,0,0,0,0,0,0,0,0,0,0,2,2,2,2,0,0
0,0,2,2,2,0,0,0,0,0,0,0,0,0,0,0,0,0,0,0,0,0,0,0,0,0,0,0,0,0,0,0,0,0,0,0,0,0,0,0,0,0,0,0,0,0,0,0,0,0,0,0,0,0,0,10,0,0,2,2,2,2,2,0
0,2,2,2,2,0,0,0,0,0,0,0,0,0,0,0,0,0,0,0,0,0,0,0,0,0,0,0,0,0,0,0,0,0,0,0,0,0,0,0,0,0,0,0,0,0,0,0,0,0,0,0,0,0,0,0,0,0,2,2,2,2,0,0
0,0,2,2,2,0,0,0,0,0,0,0,0,10,0,0,0,0,0,0,0,0,0,0,0,0,0,0,0,0,0,0,0,0,0,0,0,0,0,0,0,0,0,0,0,0,0,10,0,0,0,0,0,0,0,0,0,0,2,2,2,2,0,0
0,0,2,2,2,0,0,0,10,0,0,0,0,0,0,0,0,0,0,0,0,0,10,0,10,0,0,0,0,0,0,0,0,0,0,0,10,0,10,0,0,0,0,0,0,0,0,0,0,0,0,0,0,0,0,0,10,0,2,2,2,2,2,0
0,2,2,2,2,0,0,0,0,0,0,0,0,0,0,0,0,0,0,0,0,0,0,0,0,0,0,0,0,0,0,0,0,0,0,0,0,0,0,0,0,0,0,0,0,0,0,0,0,0,0,0,0,0,0,0,0,0,2,2,2,2,0,0
0,0,2,2,2,0,0,0,0,10,10,10,10,10,10,10,10,10,10,10,10,10,10,10,10,0,0,0,0,0,0,0,0,0,0,0,10,10,10,10,10,10,10,10,10,10,10,10,10,10,10,10,0,0,0,0,0,0,2,2,2,2,0,0
0,2,2,2,2,0,0,0,0,10,8,8,8,8,8,8,8,8,8,8,8,10,8,8,10,0,0,0,0,0,0,0,0,0,0,0,10,8,8,10,8,8,8,8,8,8,8,8,8,8,8,10,0,0,0,0,0,0,2,2,2,2,2,0
0,0,2,2,2,0,0,0,0,10,8,8,8,8,8,8,8,8,8,8,8,8,8,8,22,0,0,0,0,0,0,0,0,0,0,0,18,8,8,8,8,8,8,8,8,8,8,8,8,8,8,10,0,0,0,0,0,0,2,2,2,2,0,0
0,0,2,2,2,0,0,0,0,10,8,8,8,8,8,8,8,8,8,8,8,8,8,8,22,0,0,0,0,0,0,0,0,0,0,0,18,8,8,8,8,8,8,8,8,8,8,8,8,8,8,10,0,0,0,0,0,0,2,2,2,2,0,0
0,2,2,2,2,0,0,0,0,10,8,8,8,8,8,8,8,8,8,8,8,10,8,8,10,0,0,0,0,0,0,0,0,0,0,0,10,8,8,10,8,8,8,8,8,8,8,8,8,8,8,10,0,0,0,0,0,0,2,2,2,2,2,0
0,0,2,2,2,30,30,0,0,10,10,10,10,10,10,10,10,10,10,10,10,10,10,10,10,0,48,0,0,0,0,0,0,0,48,0,10,10,10,10,10,10,10,10,10,10,10,10,10,10,10,10,0,0,0,0,0,0,2,2,2,2,0,0
0,0,2,2,2,2,2,0,0,0,0,0,0,0,0,0,0,0,0,0,0,0,0,0,0,0,0,0,0,0,0,0,0,0,0,0,0,0,0,0,0,0,0,0,0,0,0,0,0,0,0,0,0,0,0,0,0,0,2,2,2,2,0,0
0,2,2,2,2,2,2,0,0,0,0,0,0,0,0,0,0,0,0,0,0,0,0,0,0,0,0,0,0,0,0,0,0,0,35,0,0,0,0,0,0,0,0,0,0,0,0,0,0,0,0,0,0,0,0,0,0,0,2,2,2,2,2,0
0,0,2,2,2,2,2,2,2,2,2,2,2,2,2,2,2,2,2,2,2,2,2,2,2,2,14,0,0,0,0,0,0,15,14,2,2,2,2,2,2,2,2,2,2,2,45,2,2,2,2,2,2,2,2,0,0,0,2,2,2,2,0,0
0,0,2,2,2,2,2,2,2,0,0,0,0,0,0,0,0,8,0,0,0,0,0,0,0,18,2,0,0,0,0,0,0,15,2,8,0,0,0,0,0,0,0,0,0,8,0,0,0,0,0,2,2,2,2,30,30,30,2,2,2,2,0,0
0,2,2,2,2,2,2,2,2,0,0,0,0,0,0,0,0,8,0,0,0,0,0,0,0,0,2,0,0,0,0,0,0,15,2,8,0,0,0,0,0,0,0,0,0,8,0,0,0,0,0,2,2,2,2,2,2,2,2,2,2,2,2,0
0,0,2,2,2,2,2,2,2,8,0,0,0,0,0,0,0,8,0,0,0,0,0,0,0,0,2,0,0,0,0,0,0,0,2,8,0,0,0,0,37,0,0,0,0,8,0,0,0,0,0,2,2,2,2,2,2,2,2,2,2,2,0,0
0,0,2,2,2,2,2,2,2,8,18,18,18,22,22,22,22,8,0,0,0,0,0,0,0,33,2,0,0,0,0,0,0,0,2,8,8,8,47,8,8,8,8,8,8,8,0,0,0,0,0,2,2,2,2,2,2,2,2,2,2,2,0,0
0,2,2,2,2,2,2,2,2,8,0,32,0,0,0,0,0,8,0,0,0,0,0,0,0,0,2,0,0,0,0,0,0,0,2,8,8,0,0,0,0,0,0,0,0,8,0,0,0,0,0,2,2,2,2,2,2,2,2,2,2,2,2,0
0,0,2,2,2,2,2,2,2,24,0,0,0,0,0,0,0,8,0,0,0,0,0,0,0,0,2,0,0,0,0,0,0,0,2,8,24,0,0,0,0,0,0,0,0,8,0,0,0,0,0,2,2,2,2,2,2,2,2,2,2,2,0,0
0,0,2,2,2,2,2,2,2,0,0,0,0,0,0,0,0,8,0,0,0,0,0,0,8,8,2,0,0,0,0,0,0,0,2,8,0,0,0,0,0,0,0,0,0,8,0,0,0,0,0,2,2,2,2,2,2,2,2,2,2,2,0,0
0,2,2,2,2,2,2,2,2,0,0,0,0,0,0,0,0,8,8,8,8,8,8,8,8,8,2,0,0,0,0,0,0,0,2,8,0,0,0,0,0,0,0,0,0,8,0,0,0,0,0,2,2,2,2,2,2,2,2,2,2,2,2,0
0,0,2,2,2,2,2,2,2,0,0,0,0,0,0,0,0,8,32,0,0,8,8,8,8,8,2,0,0,0,0,0,0,0,2,8,8,0,0,0,0,0,0,0,0,46,0,0,0,0,0,2,2,2,2,2,2,2,2,2,2,2,0,0
0,0,2,2,2,2,2,2,2,2,0,0,2,8,8,8,2,8,0,0,0,0,0,0,18,8,2,0,0,0,0,0,0,33,2,8,8,0,0,0,0,0,0,0,0,8,0,0,0,0,0,2,2,2,2,2,2,2,2,2,2,2,0,0
0,2,2,2,2,2,2,2,2,2,0,0,2,8,8,8,2,8,0,0,0,8,8,8,8,8,2,0,0,0,0,0,0,0,2,8,8,8,0,0,0,0,0,0,0,8,0,0,0,0,0,2,2,2,2,2,2,2,2,2,2,2,2,0
0,0,2,2,2,2,2,2,2,0,0,0,0,8,24,8,8,8,0,0,0,8,0,0,0,18,2,0,0,0,0,0,0,0,2,8,8,8,0,0,0,0,0,0,0,8,2,2,2,2,2,2,2,2,2,2,2,2,2,2,2,2,0,0
0,0,2,2,2,2,2,2,2,0,0,0,0,0,0,0,0,8,0,0,33,8,8,8,8,8,2,0,0,0,0,0,0,0,2,8,24,8,8,8,8,0,0,0,0,8,2,2,2,2,2,2,2,2,2,2,2,2,2,2,2,2,0,0
0,2,2,2,2,2,2,2,2,0,0,0,0,0,0,0,0,8,0,0,0,0,8,0,0,0,2,0,0,0,0,0,0,0,2,8,0,0,0,0,0,0,0,0,0,8,2,2,2,2,2,2,2,2,2,2,2,2,2,2,2,2,2,0
0,0,2,2,2,2,2,2,2,2,0,0,0,0,0,0,0,8,0,0,0,0,8,0,0,0,2,0,0,0,0,0,0,0,2,8,10,11,11,11,11,11,11,11,11,10,2,2,2,2,2,2,2,2,2,2,2,2,2,2,2,2,0,0
0,0,2,2,2,2,2,2,2,2,11,11,11,11,11,11,2,10,11,11,11,11,11,11,11,10,2,14,0,0,0,0,0,14,2,10,0,2,0,0,2,0,0,2,0,0,2,2,2,2,2,2,0,0,2,0,0,2,0,0,2,0,0,0
0,2,2,2,2,2,2,2,2,8,2,2,2,2,2,2,2,0,0,0,2,0,0,2,0,0,32,0,0,0,0,0,0,0,32,0,0,0,0,0,0,0,0,0,0,0,0,2,13,13,2,0,0,0,0,0,0,0,0,0,0,0,0,0
0,0,2,2,2,2,2,2,10,2,2,2,2,2,2,2,10,0,0,0,0,0,0,0,0,0,0,0,0,0,0,0,0,0,0,0,0,0,0,0,0,0,0,0,0,0,0,0,0,0,0,0,0,0,0,0,0,0,0,0,0,0,0,0
0,0,0,2,0,0,2,0,0,0,2,0,0,0,2,0,0,0,0,0,0,0,0,0,0,0,0,0,0,0,0,0,0,0,0,0,0,0,0,0,0,0,0,0,0,0,0,0,0,0,0,0,0,0,0,0,0,0,0,0,0,0,0,0
0,0,0,0,0,0,0,0,0,0,0,0,0,0,0,0,0,0,0,0,0,0,0,0,0,0,0,0,0,0,0,0,0,0,0,0,0,0,0,0,0,0,0,0,0,0,0,0,0,0,0,0,0,0,0,0,0,0,0,0,0,0,0,0
0,0,0,0,0,0,0,0,0,0,0,0,0,0,0,0,0,0,0,0,0,0,0,0,0,0,0,0,0,0,0,0,0,0,0,0,0,0,0,0,0,0,0,0,0,0,0,0,0,0,0,0,0,0,0,0,0,0,0,0,0,0,0,0
0,0,0,0,0,0,0,0,0,0,0,0,0,0,0,0,0,0,0,0,0,0,0,0,0,0,0,0,0,0,0,0,0,0,0,0,0,0,0,0,0,0,0,0,0,0,0,0,0,0,0,0,0,0,0,0,0,0,0,0,0,0,0,0
:endlayer
layer: 7
0,0,0,0,0,0,0,0,0,0,0,0,0,0,0,0,0,0,0,0,0,0,0,0,0,0,0,0,0,0,0,0,0,0,0,0,0,0,0,0,0,0,0,0,0,0,0,0,0,0,0,0,0,0,0,0,0,0,0,0,0,0,0,0
0,0,0,0,30,0,0,30,0,0,30,0,0,30,0,0,30,0,0,30,0,0,30,0,0,30,0,0,30,0,0,30,0,0,30,0,0,30,0,0,30,0,0,30,0,0,30,0,0,30,0,0,30,0,0,30,0,0,30,0,0,30,0,0
0,0,2,2,2,2,2,2,2,2,2,2,2,2,2,2,2,2,2,2,2,2,2,2,2,2,2,2,2,2,2,2,2,2,2,2,2,2,2,2,2,2,2,2,2,2,2,2,2,2,2,2,2,2,2,2,2,2,2,2,2,2,7,0
0,9,2,2,2,2,2,2,2,2,2,2,2,2,2,2,2,2,2,2,2,2,2,2,2,2,2,2,2,2,2,2,2,2,2,2,2,2,2,2,2,2,2,2,2,2,2,2,2,2,2,2,2,2,2,2,2,2,2,2,2,2,0,0
0,0,2,2,2,2,2,2,2,2,2,2,2,2,2,2,2,2,2,2,2,2,2,2,2,2,2,2,2,2,2,2,2,2,2,2,2,2,2,2,2,2,2,2,2,2,2,2,2,2,2,2,2,2,2,2,2,2,2,2,2,2,0,0
0,0,2,2,2,2,2,2,10,0,0,0,0,0,0,0,0,0,0,0,0,0,10,10,10,0,0,0,0,2,2,2,0,0,0,0,10,10,10,0,0,0,0,0,0,0,0,0,0,0,0,0,0,0,0,0,10,2,2,2,2,2,7,0
0,9,2,2,2,13,13,13,0,10,10,10,10,10,10,10,10,10,10,10,10,10,8,8,10,0,0,0,0,13,13,13,0,0,0,0,10,8,8,10,10,10,10,10,10,10,10,10,10,10,10,10,10,10,10,10,0,13,2,2,2,2,0,0
0,0,2,2,2,0,0,0,0,10,10,10,10,10,10,10,10,10,10,10,10,10,8,8,10,0,0,0,0,0,0,0,0,0,0,0,10,8,8,10,10,10,10,10,10,10,10,10,10,10,10,10,10,10,10,10,0,0,2,2,2,2,0,0
0,0,2,2,2,0,0,0,0,10,8,8,8,8,8,8,8,8,8,8,8,10,8,8,10,0,0,0,0,0,0,0,0,0,0,0,10,8,8,10,8,8,8,8,8,8,8,8,8,8,8,8,8,8,8,10,0,0,2,2,2,2,7,0
0,9,2,2,2,0,0,0,0,10,8,8,8,8,8,8,8,8,8,8,8,8,8,8,22,0,0,0,0,0,0,0,0,0,0,0,18,8,8,8,8,8,8,8,8,8,8,8,8,8,8,8,8,8,8,10,0,0,2,2,2,2,0,0
0,0,2,2,2,0,0,0,0,10,8,8,8,8,8,8,8,8,8,8,8,8,8,8,22,0,0,0,0,0,0,0,0,0,0,0,18,8,8,8,8,8,8,8,8,8,8,8,8,8,8,8,8,8,8,10,0,0,2,2,2,2,0,0
0,0,2,2,2,0,0,0,0,10,8,8,8,8,8,8,8,8,8,8,8,8,8,8,10,0,0,0,0,0,0,0,0,0,0,0,10,8,8,8,8,8,8,8,8,8,8,8,8,8,8,8,8,8,8,10,0,0,2,2,2,2,7,0
0,9,2,2,2,0,0,0,0,10,10,10,10,10,10,10,10,10,10,10,10,10,8,8,10,0,0,0,0,0,0,0,0,0,0,0,10,8,8,10,10,10,10,10,10,10,10,10,10,10,10,8,10,10,10,10,0,0,2,2,2,2,0,0
0,0,2,2,2,0,0,0,0,10,10,10,10,10,10,10,10,10,10,10,10,10,8,8,10,0,0,0,0,0,0,0,0,0,0,0,10,8,8,10,10,10,10,10,10,10,10,10,10,10,10,10,10,10,10,10,0,0,2,2,2,2,0,0
0,0,2,2,2,0,0,0,10,0,0,0,0,0,0,0,0,0,0,0,0,0,10,10,10,0,0,0,0,0,0,0,0,0,0,0,10,10,10,0,0,0,0,0,0,0,0,0,0,0,0,0,0,0,0,0,10,0,2,2,2,2,7,0
0,9,2,2,2,0,0,0,0,0,0,0,0,0,0,0,0,0,0,0,0,0,0,0,0,0,0,0,0,0,0,0,0,0,0,0,0,0,0,0,0,0,0,0,0,0,0,0,0,0,0,0,0,0,0,0,0,0,2,2,2,2,0,0
0,0,2,2,2,0,0,0,0,10,2,2,10,2,2,10,2,2,10,2,2,10,71,71,71,0,0,0,0,0,0,0,0,0,0,0,71,71,71,10,2,2,10,2,2,10,2,2,10,2,2,10,0,0,0,0,0,0,2,2,2,2,0,0
0,9,2,2,2,0,0,0,0,2,88,86,10,84,82,10,80,78,10,76,74,2,0,0,71,0,0,0,0,0,0,0,0,0,0,0,71,0,0,2,67,65,10,63,61,10,58,56,10,52,49,2,0,0,0,0,0,0,2,2,2,2,7,0
0,0,2,2,2,0,0,0,0,2,0,0,0,0,0,0,0,0,0,0,0,72,0,0,0,0,0,0,0,0,0,0,0,0,0,0,0,0,0,69,0,0,0,0,0,0,0,0,0,0,0,2,0,0,0,0,0,0,2,2,2,2,0,0
0,0,2,2,2,0,0,0,0,2,0,0,0,0,0,0,0,0,0,0,0,73,0,0,0,0,0,0,0,0,0,0,0,0,0,0,0,0,0,70,0,0,0,0,0,0,0,0,0,0,0,2,0,0,0,0,0,0,2,2,2,2,0,0
0,9,2,2,2,0,0,0,0,2,89,87,10,85,83,10,81,79,10,77,75,2,0,0,71,0,0,0,0,0,0,0,0,0,0,0,71,0,0,2,68,66,10,64,62,10,59,57,10,53,50,2,0,0,0,0,0,0,2,2,2,2,7,0
0,0,2,2,2,0,0,0,0,10,2,2,10,2,2,10,2,2,10,2,2,10,71,71,71,0,0,0,0,0,0,0,0,0,0,0,71,71,71,10,2,2,10,2,2,10,2,2,10,2,2,10,0,0,0,0,0,0,2,2,2,2,0,0
0,0,2,2,2,30,30,0,0,0,0,0,0,0,0,0,0,0,0,0,0,0,0,0,0,0,0,0,0,0,0,0,0,0,0,0,0,0,0,0,0,0,0,0,0,0,0,0,0,0,0,0,0,0,0,0,0,0,2,2,2,2,0,0
0,9,2,2,2,2,2,0,0,0,0,0,0,0,0,0,0,0,0,0,0,0,0,0,0,0,0,0,0,0,0,0,0,0,0,0,0,0,0,0,0,0,0,0,0,0,0,0,0,0,0,0,0,0,0,0,0,0,2,2,2,2,7,0
0,0,2,2,2,2,2,2,2,2,2,2,2,2,2,2,2,45,2,2,2,2,2,2,2,2,2,14,0,0,0,0,0,14,2,2,2,2,2,2,2,2,2,2,2,2,2,2,2,2,2,2,2,2,2,0,0,0,2,2,2,2,0,0
0,0,2,2,2,2,2,2,2,0,0,0,0,0,0,0,0,8,0,0,0,0,0,0,0,0,18,2,0,0,0,0,0,2,2,8,0,0,0,0,32,0,0,0,0,8,0,0,0,0,0,2,2,2,2,0,0,0,2,2,2,2,0,0
0,9,2,2,2,2,2,2,2,0,0,0,0,0,0,0,33,8,0,0,0,0,0,0,0,0,0,2,0,0,0,0,0,2,2,8,0,0,0,0,0,0,0,0,0,8,0,0,0,0,0,2,2,2,2,30,30,30,2,2,2,2,7,0
0,0,2,2,2,2,2,2,2,8,60,0,0,0,0,0,0,8,0,0,0,0,0,0,0,0,0,2,0,0,0,0,0,2,2,8,0,0,0,0,0,0,0,0,0,8,0,0,0,0,0,2,2,2,2,2,2,2,2,2,2,2,0,0
0,0,2,2,2,2,2,2,2,8,18,18,18,22,22,22,22,8,0,0,0,0,0,0,0,0,0,2,0,0,0,0,0,2,2,8,8,8,8,8,8,8,8,8,8,8,0,0,0,0,0,2,2,2,2,2,2,2,2,2,2,2,0,0
0,9,2,2,2,2,2,2,2,24,0,0,0,0,0,0,0,8,0,0,0,0,0,0,0,0,0,2,0,0,0,0,0,2,2,8,24,0,0,0,0,0,0,0,0,8,0,0,0,0,0,2,2,2,2,2,2,2,2,2,2,2,7,0
0,0,2,2,2,2,2,2,2,0,0,0,0,0,0,0,0,8,0,0,0,0,0,0,0,0,0,2,0,0,0,0,0,2,2,8,0,0,0,0,0,0,0,0,0,8,0,0,0,0,0,2,2,2,2,2,2,2,2,2,2,2,0,0
0,0,2,2,2,2,2,2,2,0,0,0,0,0,0,0,0,8,0,0,0,0,0,0,8,8,8,2,0,0,0,0,0,2,2,8,0,0,0,0,0,0,0,0,0,8,0,0,0,0,0,2,2,2,2,2,2,2,2,2,2,2,0,0
0,9,2,2,2,2,2,2,2,0,0,0,0,0,0,0,0,8,8,8,8,8,8,8,22,0,0,2,0,0,0,0,0,2,2,8,0,0,0,0,0,0,0,0,0,8,0,0,0,0,0,2,2,2,2,2,2,2,2,2,2,2,7,0
0,0,2,2,2,2,2,2,2,0,0,0,0,0,0,37,0,8,8,8,8,8,8,8,8,0,0,2,0,0,0,0,0,2,2,8,8,0,0,0,0,0,0,0,0,8,0,0,0,0,0,2,2,2,2,2,2,2,2,2,2,2,0,0
0,0,2,2,2,2,2,2,2,2,2,2,2,8,8,8,2,8,8,8,8,8,0,0,0,0,0,2,0,0,0,0,0,2,2,8,8,0,0,0,0,0,0,0,0,8,0,0,0,0,0,2,2,2,2,2,2,2,2,2,2,2,0,0
0,9,2,2,2,2,2,2,2,2,0,0,2,8,24,8,2,8,8,8,8,8,8,8,8,8,8,2,0,0,0,0,0,2,2,8,8,8,0,0,0,0,0,0,0,8,60,0,0,0,33,2,2,2,2,2,2,2,2,2,2,2,7,0
0,0,2,2,2,2,2,2,2,0,0,0,0,8,0,8,8,8,8,8,8,8,8,32,0,0,18,2,0,0,0,0,0,2,2,8,24,8,0,0,0,0,0,0,0,8,2,2,2,2,2,2,2,2,2,2,2,2,2,2,2,2,0,0
0,0,2,2,2,2,2,2,2,0,0,0,0,0,0,0,0,8,8,8,8,8,8,8,8,8,8,2,0,0,0,0,0,2,2,8,0,8,8,8,8,0,0,0,0,8,2,2,2,2,2,2,2,2,2,2,2,2,2,2,2,2,0,0
0,9,2,2,2,2,2,2,2,0,0,0,0,0,0,0,0,8,8,8,8,8,8,0,0,0,8,2,0,0,0,0,0,2,2,8,0,0,32,8,8,0,0,0,0,8,2,2,13,13,2,2,2,2,2,2,2,2,2,2,2,2,7,0
0,0,2,2,2,2,2,2,2,2,60,0,0,0,0,0,0,8,8,8,8,8,8,0,0,0,8,2,0,0,0,0,0,2,2,8,10,11,11,11,11,11,11,11,11,10,2,2,55,54,2,2,2,2,2,2,2,2,2,2,2,2,0,0
0,0,2,2,2,2,2,2,2,2,2,2,2,2,2,2,2,10,11,11,11,11,11,11,11,10,2,2,0,0,0,0,0,2,2,10,0,13,0,0,13,0,0,13,0,0,13,0,0,0,0,13,0,0,13,0,0,13,0,0,13,0,0,0
0,9,2,2,2,2,2,2,2,8,2,2,2,2,2,2,2,0,0,0,13,0,0,13,0,0,0,0,0,0,0,0,0,0,0,0,0,0,0,0,0,0,0,0,0,0,0,51,0,0,51,0,0,0,0,0,0,0,0,0,0,0,0,0
0,0,2,2,2,2,2,2,10,2,2,2,2,2,2,2,10,0,0,0,0,0,0,0,0,0,0,0,0,0,0,0,0,0,0,0,0,0,0,0,0,0,0,0,0,0,0,0,0,0,0,0,0,0,0,0,0,0,0,0,0,0,0,0
0,0,0,13,0,0,13,0,0,0,13,0,0,0,13,0,0,0,0,0,0,0,0,0,0,0,0,0,0,0,0,0,0,0,0,0,0,0,0,0,0,0,0,0,0,0,0,0,0,0,0,0,0,0,0,0,0,0,0,0,0,0,0,0
0,0,0,0,0,0,0,0,0,0,0,0,0,0,0,0,0,0,0,0,0,0,0,0,0,0,0,0,0,0,0,0,0,0,0,0,0,0,0,0,0,0,0,0,0,0,0,0,0,0,0,0,0,0,0,0,0,0,0,0,0,0,0,0
0,0,0,0,0,0,0,0,0,0,0,0,0,0,0,0,0,0,0,0,0,0,0,0,0,0,0,0,0,0,0,0,0,0,0,0,0,0,0,0,0,0,0,0,0,0,0,0,0,0,0,0,0,0,0,0,0,0,0,0,0,0,0,0
0,0,0,0,0,0,0,0,0,0,0,0,0,0,0,0,0,0,0,0,0,0,0,0,0,0,0,0,0,0,0,0,0,0,0,0,0,0,0,0,0,0,0,0,0,0,0,0,0,0,0,0,0,0,0,0,0,0,0,0,0,0,0,0
:endlayer
layer: 8
0,0,0,0,0,0,0,0,0,0,0,0,0,0,0,0,0,0,0,0,0,0,0,0,0,0,0,0,0,0,0,0,0,0,0,0,0,0,0,0,0,0,0,0,0,0,0,0,0,0,0,0,0,0,0,0,0,0,0,0,0,0,0,0
0,0,0,0,0,0,0,0,0,0,0,0,0,0,0,0,0,0,0,0,0,0,0,0,0,0,0,0,0,0,0,0,0,0,0,0,0,0,0,0,0,0,0,0,0,0,0,0,0,0,0,0,0,0,0,0,0,0,0,0,0,0,0,0
0,0,2,2,2,2,2,2,2,2,2,2,2,2,2,2,2,2,2,2,2,2,2,2,2,2,2,2,2,2,2,2,2,2,2,2,2,2,2,2,2,2,2,2,2,2,2,2,2,2,2,2,2,2,2,2,2,2,2,2,2,2,0,0
0,0,2,2,2,2,2,2,2,2,2,2,2,2,2,2,2,2,2,2,2,2,2,2,2,2,2,2,2,2,2,2,2,2,2,2,2,2,2,2,2,2,2,2,2,2,2,2,2,2,2,2,2,2,2,2,2,2,2,2,2,2,0,0
0,0,2,2,2,2,2,2,2,2,2,2,2,2,2,2,2,2,2,2,2,2,2,2,2,2,2,2,2,2,2,2,2,2,2,2,2,2,2,2,2,2,2,2,2,2,2,2,2,2,2,2,2,2,2,2,2,2,2,2,2,2,0,0
0,0,2,2,2,13,13,13,10,0,0,0,0,0,0,0,0,0,0,0,0,0,10,24,71,0,0,0,32,13,13,13,32,0,0,0,71,24,10,0,0,0,0,0,0,0,0,0,0,0,0,0,0,0,0,0,10,13,2,2,2,2,0,0
0,0,2,2,2,0,0,0,0,2,2,2,2,2,2,2,2,2,2,2,2,2,0,0,71,0,0,0,0,0,0,0,0,0,0,0,71,0,0,2,2,2,2,2,2,2,2,2,2,2,2,2,2,2,2,2,0,0,2,2,2,2,0,0
0,0,2,2,2,0,0,0,0,2,8,8,8,8,8,8,8,8,8,8,8,2,0,0,71,0,0,0,0,0,0,0,0,0,0,0,71,0,0,2,8,8,8,8,8,8,8,8,8,8,8,95,2,92,90,2,0,0,2,2,2,2,0,0
0,0,2,2,2,0,0,0,0,2,0,0,153,150,0,145,142,0,137,134,0,2,0,0,71,0,0,0,0,0,0,0,0,0,0,0,71,0,0,2,0,121,119,0,113,111,0,105,102,0,0,0,2,0,0,2,0,0,2,2,2,2,0,0
0,0,2,2,2,0,0,0,0,2,0,0,0,0,0,0,0,0,0,0,0,72,0,0,0,0,0,0,0,0,0,0,0,0,0,0,0,0,0,69,0,0,0,0,0,0,0,0,0,0,9,2,2,93,0,2,0,0,2,2,2,2,0,0
0,0,2,2,2,0,0,0,0,2,0,0,0,0,0,0,0,0,0,0,0,73,0,0,0,0,0,0,0,0,0,0,0,0,0,0,0,0,0,70,0,0,0,0,0,0,0,0,0,0,0,0,2,0,0,2,0,0,2,2,2,2,0,0
0,0,2,2,2,0,0,0,0,2,0,155,154,0,147,146,0,139,138,0,131,2,0,0,71,0,0,0,0,0,0,0,0,0,0,0,71,0,0,2,124,0,120,116,0,112,108,0,103,98,0,0,69,0,0,2,0,0,2,2,2,2,0,0
0,0,2,2,2,0,0,0,0,2,8,8,8,8,8,8,8,8,8,8,8,2,0,0,71,0,0,0,0,0,0,0,0,0,0,0,71,0,0,2,8,8,8,8,8,8,8,8,8,8,8,0,2,94,91,2,0,0,2,2,2,2,0,0
0,0,2,2,2,0,0,0,0,2,2,2,2,2,2,2,2,2,2,2,2,2,0,0,71,0,0,0,0,0,0,0,0,0,0,0,71,0,0,2,2,2,2,2,2,2,2,2,2,2,2,2,2,2,2,2,0,0,2,2,2,2,0,0
0,0,2,2,2,0,0,0,10,0,0,0,0,0,0,0,0,0,0,0,0,0,10,71,71,0,0,0,0,0,0,0,0,0,0,0,71,71,10,0,0,0,0,0,0,0,0,0,0,0,0,0,0,0,0,0,10,0,2,2,2,2,0,0
0,0,2,2,2,0,0,0,0,0,0,0,0,0,0,0,0,0,0,0,0,0,0,0,0,0,0,0,0,0,0,0,0,0,0,0,0,0,0,0,0,0,0,0,0,0,0,0,0,0,0,0,0,0,0,0,0,0,2,2,2,2,0,0
0,0,2,2,2,0,0,0,0,10,2,2,10,2,2,10,2,2,10,2,2,10,0,0,0,0,0,0,0,0,0,0,0,0,0,0,0,0,0,10,2,2,10,2,2,10,2,2,10,2,2,10,0,0,0,0,0,0,2,2,2,2,0,0
0,0,2,2,2,0,0,0,0,2,158,156,10,151,148,10,143,140,10,135,132,2,0,0,48,0,0,0,0,0,0,0,0,0,0,0,48,0,0,2,125,122,10,117,114,10,109,106,10,99,96,2,0,0,0,0,0,0,2,2,2,2,0,0
0,0,2,2,2,0,0,0,0,2,0,0,0,0,0,0,0,0,0,0,0,129,0,0,0,0,0,0,0,0,0,0,0,0,0,0,0,0,0,127,0,0,0,0,0,0,0,0,0,0,0,2,0,0,0,0,0,0,2,2,2,2,0,0
0,0,2,2,2,0,0,0,0,2,0,0,0,0,0,0,0,0,0,0,0,130,0,0,0,0,0,0,0,0,0,0,0,0,0,0,0,0,0,128,0,0,0,0,0,0,0,0,0,0,0,2,0,0,0,0,0,0,2,2,2,2,0,0
0,0,2,2,2,0,0,0,0,2,159,157,10,152,149,10,144,141,10,136,133,2,0,0,48,0,0,0,0,0,0,0,0,0,0,0,48,0,0,2,126,123,10,118,115,10,110,107,10,100,97,2,0,0,0,0,0,0,2,2,2,2,0,0
0,0,2,2,2,0,0,0,0,10,2,2,10,2,2,10,2,2,10,2,2,10,0,0,0,0,0,0,0,0,0,0,0,0,0,0,0,0,0,10,2,2,10,2,2,10,2,2,10,2,2,10,0,0,0,0,0,0,2,2,2,2,0,0
0,0,2,2,2,0,0,0,0,0,0,0,0,0,0,0,0,0,0,0,0,0,0,0,0,0,0,0,0,0,0,0,0,0,0,0,0,0,0,0,0,0,0,0,0,0,0,0,0,0,0,0,0,0,0,0,0,0,2,2,2,2,0,0
0,0,2,2,2,30,30,0,0,0,0,0,0,0,0,0,0,0,0,0,0,0,0,0,0,0,0,0,0,0,0,0,0,0,0,0,0,0,0,0,0,0,0,0,0,0,0,0,0,0,0,0,0,0,0,0,0,0,2,2,2,2,0,0
0,0,2,2,2,2,2,2,2,2,2,2,2,2,2,2,2,2,2,2,2,2,2,2,2,2,2,2,14,0,0,0,14,2,2,2,45,2,2,2,2,2,2,2,45,2,2,2,2,2,2,2,2,2,2,0,0,0,2,2,2,2,0,0
0,0,2,2,2,2,2,2,2,8,8,8,8,8,8,8,8,8,0,32,0,0,0,0,0,0,0,18,2,0,0,0,2,8,0,8,8,8,8,8,8,8,8,8,8,8,60,0,0,0,33,2,2,2,2,0,0,0,2,2,2,2,0,0
0,0,2,2,2,2,2,2,2,8,8,8,8,8,8,8,8,8,0,0,0,0,0,0,0,0,0,8,2,0,0,0,2,8,0,8,8,8,8,8,8,8,8,8,8,8,0,0,0,0,0,2,2,2,2,0,0,0,2,2,2,2,0,0
0,0,2,2,2,2,2,2,2,8,8,8,8,8,8,8,8,8,0,0,0,0,0,0,0,0,0,8,2,60,0,33,2,8,0,8,8,8,8,8,8,8,8,8,8,8,0,0,0,0,0,2,2,2,2,30,30,30,2,2,2,2,0,0
0,0,2,2,2,2,2,2,2,24,8,8,8,8,8,8,8,8,0,0,0,0,0,0,0,0,0,8,2,0,0,0,2,8,0,8,24,8,8,8,8,8,8,8,8,8,0,0,0,0,0,2,2,2,2,2,2,2,2,2,2,2,0,0
0,0,2,2,2,2,2,2,2,0,8,8,8,8,8,8,8,8,0,0,0,0,0,0,0,0,0,8,2,0,0,0,2,8,2,8,60,0,0,0,0,0,0,0,0,8,0,0,0,0,0,2,2,2,2,2,2,2,2,2,2,2,0,0
0,0,2,2,2,2,2,2,2,0,8,8,8,8,8,8,8,8,0,0,0,0,0,0,0,0,0,8,2,0,0,0,2,2,2,8,0,0,0,0,0,0,0,0,0,8,0,0,0,0,0,2,2,2,2,2,2,2,2,2,2,2,0,0
0,0,2,2,2,2,2,2,2,0,8,8,8,8,8,8,8,8,0,0,0,0,0,8,8,8,8,8,2,2,2,2,2,2,2,8,0,0,0,0,0,0,0,0,0,8,0,0,0,0,0,2,2,2,2,2,2,2,2,2,2,2,0,0
0,0,2,2,2,2,2,2,2,0,8,8,8,8,8,8,8,8,8,8,8,8,8,22,0,0,0,8,2,2,2,2,2,2,2,8,0,0,0,0,0,0,0,0,0,8,0,0,0,0,0,2,2,2,2,2,2,2,2,2,2,2,0,0
0,0,2,2,2,2,2,2,2,0,8,8,32,8,8,8,8,8,0,0,0,0,8,8,71,0,0,8,2,2,2,2,2,2,2,8,8,0,0,0,0,0,0,0,0,8,0,0,0,0,0,2,2,2,2,2,2,2,2,2,2,2,0,0
0,0,2,2,2,2,2,2,2,2,8,8,8,22,0,8,8,8,0,0,0,0,8,0,0,0,0,8,2,2,2,2,2,2,2,8,8,0,0,0,0,0,0,0,0,8,2,2,2,2,2,2,2,2,2,2,2,2,2,2,2,2,0,0
0,0,2,2,2,2,2,2,2,2,0,0,2,8,0,8,8,8,0,0,0,0,8,8,8,8,8,8,2,2,2,2,2,2,2,8,24,8,0,0,0,0,0,0,0,8,2,2,2,2,2,2,2,2,2,2,2,2,2,2,2,2,0,0
0,0,2,2,2,2,2,2,2,0,0,0,0,8,0,8,8,8,0,0,0,0,0,8,0,0,0,18,2,2,2,2,2,2,2,8,0,8,0,0,0,0,0,0,0,8,2,2,13,13,2,2,2,2,2,2,2,2,2,2,2,2,0,0
0,0,2,2,2,2,2,2,2,0,0,0,0,0,0,0,0,8,0,0,0,0,0,8,8,8,8,8,2,2,2,2,2,2,2,8,0,8,8,8,8,0,0,0,0,8,2,2,0,0,2,2,2,2,2,2,2,2,2,2,2,2,0,0
0,0,2,2,2,2,2,2,2,0,0,0,0,0,0,0,0,8,0,0,0,0,0,18,8,8,8,8,2,0,0,0,2,2,2,8,0,0,0,0,8,0,0,0,0,8,2,2,0,0,2,2,2,2,2,2,2,2,2,2,2,2,0,0
0,0,2,2,2,2,2,2,2,2,0,0,0,0,0,0,33,8,0,0,0,0,0,18,8,8,8,8,2,0,0,0,2,2,2,8,10,11,11,11,11,11,11,11,11,10,45,2,104,101,2,2,2,2,2,2,2,2,2,2,2,2,0,0
0,0,2,2,2,2,2,2,2,2,2,2,2,2,2,2,2,10,2,2,2,2,2,45,2,10,2,2,0,0,0,0,0,2,2,10,0,32,0,0,32,0,0,32,0,0,0,0,0,0,0,0,0,0,0,0,0,0,0,0,0,0,0,0
0,0,2,2,2,2,2,2,2,8,2,2,2,2,2,2,2,0,0,0,32,0,0,32,0,0,0,0,0,0,0,0,0,0,0,0,0,0,0,0,0,0,0,0,0,0,0,48,0,0,48,0,0,0,0,0,0,0,0,0,0,0,0,0
0,0,2,2,2,2,2,2,10,2,2,2,2,2,2,2,10,0,0,0,0,0,0,0,0,0,0,0,0,0,0,0,0,0,0,0,0,0,0,0,0,0,0,0,0,0,0,0,0,0,0,0,0,0,0,0,0,0,0,0,0,0,0,0
0,0,0,0,0,0,0,0,0,0,0,0,0,0,0,0,0,0,0,0,0,0,0,0,0,0,0,0,0,0,0,0,0,0,0,0,0,0,0,0,0,0,0,0,0,0,0,0,0,0,0,0,0,0,0,0,0,0,0,0,0,0,0,0
0,0,0,0,0,0,0,0,0,0,0,0,0,0,0,0,0,0,0,0,0,0,0,0,0,0,0,0,0,0,0,0,0,0,0,0,0,0,0,0,0,0,0,0,0,0,0,0,0,0,0,0,0,0,0,0,0,0,0,0,0,0,0,0
0,0,0,0,0,0,0,0,0,0,0,0,0,0,0,0,0,0,0,0,0,0,0,0,0,0,0,0,0,0,0,0,0,0,0,0,0,0,0,0,0,0,0,0,0,0,0,0,0,0,0,0,0,0,0,0,0,0,0,0,0,0,0,0
0,0,0,0,0,0,0,0,0,0,0,0,0,0,0,0,0,0,0,0,0,0,0,0,0,0,0,0,0,0,0,0,0,0,0,0,0,0,0,0,0,0,0,0,0,0,0,0,0,0,0,0,0,0,0,0,0,0,0,0,0,0,0,0
:endlayer
layer: 9
0,0,0,0,0,0,0,0,0,0,0,0,0,0,0,0,0,0,0,0,0,0,0,0,0,0,0,0,0,0,0,0,0,0,0,0,0,0,0,0,0,0,0,0,0,0,0,0,0,0,0,0,0,0,0,0,0,0,0,0,0,0,0,0
0,0,0,0,0,0,0,0,0,0,0,0,0,0,0,0,0,0,0,0,0,0,0,0,0,0,0,0,0,0,0,0,0,0,0,0,0,0,0,0,0,0,0,0,0,0,0,0,0,0,0,0,0,0,0,0,0,0,0,0,0,0,0,0
0,0,2,2,2,2,2,2,2,2,2,2,2,2,2,2,2,2,2,2,2,2,2,2,2,2,2,2,2,2,2,2,2,2,2,2,2,2,2,2,2,2,2,2,2,2,2,2,2,2,2,2,2,2,2,2,2,2,2,2,2,2,0,0
0,0,2,0,0,0,0,0,0,0,0,0,0,0,0,0,0,0,0,0,0,0,0,0,0,0,0,0,0,0,0,0,0,0,0,0,0,0,0,0,0,0,0,0,0,0,0,0,0,0,0,0,0,0,0,0,0,0,0,0,0,2,0,0
0,0,2,0,0,0,0,0,0,0,0,0,0,0,0,0,0,0,0,0,0,0,0,0,0,0,0,0,0,0,0,0,0,0,0,0,0,0,0,0,0,0,0,0,0,0,0,0,0,0,0,0,0,0,0,0,0,0,0,0,0,2,0,0
0,0,2,0,0,0,0,0,10,0,0,0,0,0,0,0,0,0,0,0,0,0,10,0,0,0,0,0,0,0,0,0,0,0,0,0,48,0,10,0,0,0,0,0,0,0,0,0,0,0,0,0,0,0,0,0,10,0,0,0,0,2,0,0
0,0,2,0,0,0,0,0,0,2,2,2,2,2,2,2,2,2,2,2,2,2,0,0,0,0,0,0,0,0,0,0,0,0,0,0,0,0,0,2,2,2,2,2,2,2,2,2,2,2,2,2,2,2,2,2,0,0,0,0,0,2,0,0
0,0,2,0,0,0,0,0,0,2,240,236,0,231,225,0,215,211,0,207,203,2,0,0,0,0,0,0,0,0,0,0,0,0,0,0,0,0,0,2,192,188,0,184,179,0,175,171,0,166,162,0,2,0,0,2,0,0,0,0,0,2,0,0
0,0,2,0,0,0,0,0,0,2,0,0,0,0,0,0,0,0,0,0,0,2,60,0,48,0,0,0,0,0,0,0,0,0,0,0,48,0,33,2,0,0,0,0,0,0,0,0,0,0,0,0,2,0,0,2,0,0,0,0,0,2,0,0
0,0,2,0,0,0,0,0,0,2,0,0,0,0,0,0,0,0,0,0,0,200,0,0,0,0,0,0,0,0,0,0,0,0,0,0,0,0,0,196,0,0,0,0,0,0,0,0,0,0,0,9,2,0,0,2,0,0,0,0,0,2,0,0
0,0,2,0,0,0,0,0,0,2,0,0,0,0,0,0,0,0,0,0,0,201,0,0,0,0,0,0,0,0,0,0,0,0,0,0,0,0,0,197,0,0,0,0,0,0,0,0,0,0,0,0,2,0,0,2,0,0,0,0,0,2,0,0
0,0,2,0,0,0,0,0,0,2,0,0,0,0,0,0,0,0,0,0,0,2,60,0,48,0,0,0,0,0,0,0,0,0,0,0,48,0,33,2,0,0,0,0,0,0,0,0,0,0,0,0,160,0,0,2,0,0,0,0,0,2,0,0
0,0,2,0,0,0,0,0,0,2,241,237,0,232,226,0,216,212,0,208,204,2,0,0,0,0,0,0,0,0,0,0,0,0,0,0,0,0,0,2,193,189,0,185,180,0,176,172,0,167,163,161,2,0,0,2,0,0,0,0,0,2,0,0
0,0,2,0,0,0,0,0,0,2,2,2,2,2,2,2,2,2,2,2,2,2,0,0,0,0,0,0,0,0,0,0,0,0,0,0,0,0,0,2,2,2,2,2,2,2,2,2,2,2,2,2,2,2,2,2,0,0,0,0,0,2,0,0
0,0,2,0,0,0,0,0,10,0,0,0,0,0,0,0,0,0,0,0,0,0,10,0,48,0,0,0,0,0,0,0,0,0,0,0,48,0,10,0,0,0,0,0,0,0,0,0,0,0,0,0,0,0,0,0,10,0,0,0,0,2,0,0
0,0,2,0,0,0,0,0,0,0,0,0,0,0,0,0,0,0,0,0,0,0,0,0,0,0,0,0,0,0,0,0,0,0,0,0,0,0,0,0,0,0,0,0,0,0,0,0,0,0,0,0,0,0,0,0,0,0,0,0,0,2,0,0
0,0,2,0,0,0,0,0,33,10,2,2,10,2,2,10,2,2,10,2,2,10,60,0,0,0,0,0,0,0,0,0,0,0,0,0,0,0,33,10,2,2,10,2,2,10,2,2,10,2,2,10,60,0,0,0,0,0,0,0,0,2,0,0
0,0,2,0,0,0,0,0,0,2,242,238,10,233,227,10,217,213,10,209,205,2,0,0,0,0,0,0,0,0,0,0,0,0,0,0,0,0,0,2,194,190,10,186,181,10,177,173,10,168,164,2,0,0,0,0,0,0,0,0,0,2,0,0
0,0,2,0,0,0,0,0,0,2,0,0,0,0,0,0,0,0,0,0,0,198,0,0,0,0,0,0,0,0,0,0,0,0,0,0,0,0,0,198,0,0,0,0,0,0,0,0,0,0,0,2,0,0,0,0,0,0,0,0,0,2,0,0
0,0,2,0,0,0,0,0,0,2,0,0,0,0,0,0,0,0,0,0,0,198,0,0,0,0,0,0,0,0,0,0,0,0,0,0,0,0,0,198,0,0,0,0,0,0,0,0,0,0,0,2,0,0,0,0,0,0,0,0,0,2,0,0
0,0,2,0,0,0,0,0,0,2,243,239,10,234,228,10,218,214,10,210,206,2,0,0,0,0,0,0,0,0,0,0,0,0,0,0,0,0,0,2,195,191,10,187,182,10,178,174,10,169,165,2,0,0,0,0,0,0,0,0,0,2,0,0
0,0,2,0,0,0,0,0,33,10,2,2,10,2,2,10,2,2,10,2,2,10,60,0,0,0,0,0,0,0,0,0,0,0,0,0,0,0,33,10,2,2,10,2,2,10,2,2,10,2,2,10,60,0,0,0,0,0,0,0,0,2,0,0
0,0,2,0,0,0,0,0,0,32,0,0,32,0,0,32,0,0,32,0,0,32,0,0,0,0,0,0,0,0,0,0,0,0,0,0,0,0,0,32,0,0,32,0,0,32,0,0,32,0,0,32,0,0,0,0,0,0,0,0,0,2,0,0
0,0,2,0,0,0,0,0,0,0,0,0,0,0,0,0,0,0,0,0,0,0,0,0,0,0,0,0,0,0,0,0,0,0,0,0,0,0,0,0,0,0,0,0,0,0,0,0,0,0,0,0,0,0,0,0,0,0,0,0,0,2,0,0
0,0,2,0,0,0,0,0,2,2,45,2,2,2,2,2,2,2,2,2,2,2,2,2,2,2,2,2,2,14,14,14,2,2,2,2,2,2,2,2,2,2,2,2,2,2,2,2,2,2,2,2,2,2,2,0,0,0,0,0,0,2,0,0
0,0,2,0,0,0,0,0,2,0,0,0,0,0,224,219,219,8,0,0,0,0,0,0,0,0,0,0,18,2,2,2,8,8,8,8,0,199,0,0,0,0,32,0,0,8,0,0,0,0,0,2,0,0,2,0,0,0,0,0,0,2,0,0
0,0,2,0,0,2,30,30,2,0,0,0,0,0,0,220,220,8,0,0,0,0,0,0,0,0,0,8,8,2,2,2,8,8,8,8,0,8,0,0,0,0,0,0,0,8,0,0,0,0,0,2,0,0,2,0,0,0,0,0,0,2,0,0
0,0,2,0,0,2,2,2,2,244,8,0,0,0,0,0,0,8,0,0,0,0,0,0,0,0,0,8,8,2,2,2,8,8,8,8,0,8,0,0,0,0,0,0,0,8,0,0,0,0,0,2,0,0,2,0,0,0,0,0,0,2,0,0
0,0,2,0,0,2,2,2,2,0,8,0,0,0,0,223,221,8,0,0,0,0,0,0,0,0,0,8,8,2,2,2,8,8,8,8,0,8,8,8,8,8,8,8,8,8,0,0,0,0,0,2,0,0,2,0,0,0,0,0,0,2,0,0
0,0,2,0,0,2,0,0,2,0,8,0,71,229,229,71,0,8,0,0,0,0,0,0,0,0,0,8,8,2,2,2,8,8,8,8,0,0,0,0,0,0,0,0,0,8,0,0,0,0,0,2,2,2,2,0,0,0,0,0,0,2,0,0
0,0,2,0,0,2,0,0,2,0,8,222,0,0,0,0,222,8,0,0,0,0,0,0,0,0,0,8,8,2,2,2,2,2,2,8,0,0,0,0,0,0,0,0,0,8,0,0,0,0,0,2,13,13,2,0,0,0,0,0,0,2,0,0
0,0,2,0,0,2,0,0,2,0,8,1,235,0,0,224,1,8,0,0,0,0,8,8,8,8,8,8,8,2,2,2,2,2,2,8,0,0,0,0,0,0,0,0,0,8,0,0,0,0,0,2,0,0,2,0,0,0,0,0,0,2,0,0
0,0,2,0,0,2,0,0,2,0,8,220,71,230,230,71,220,8,8,8,8,8,22,0,0,0,0,8,8,2,2,2,2,2,2,8,0,0,0,0,0,0,0,0,0,8,0,0,0,0,0,2,0,0,0,0,0,0,0,0,0,2,0,0
0,0,2,0,0,2,0,0,10,0,8,8,8,8,8,8,8,8,0,0,0,0,8,8,60,0,0,8,8,2,2,2,2,2,2,8,8,0,0,0,0,0,0,0,0,8,0,0,0,0,0,2,0,0,0,0,0,0,0,0,0,2,0,0
0,0,2,0,0,245,0,0,2,8,8,8,22,0,0,8,8,8,0,0,0,0,8,0,0,0,0,8,8,2,2,2,2,2,2,8,24,8,0,0,0,0,0,0,0,8,2,2,2,2,2,2,0,0,0,0,0,0,0,0,0,2,0,0
0,0,2,0,0,2,0,0,2,2,2,2,2,8,0,8,8,8,0,0,0,0,8,8,8,8,8,8,8,2,2,2,2,2,2,8,0,8,0,0,0,0,0,0,0,8,2,2,13,13,2,2,0,0,0,0,0,0,0,0,0,2,0,0
0,0,2,0,0,2,0,0,2,0,0,0,0,8,0,8,8,8,0,0,0,0,0,8,8,0,0,0,18,2,2,2,2,2,2,8,0,8,0,0,0,0,0,0,0,8,2,2,0,0,2,2,0,0,0,0,0,0,0,0,0,2,0,0
0,0,2,0,0,2,0,0,2,0,0,0,0,0,0,0,0,8,0,0,0,0,0,8,8,8,8,8,8,2,2,2,2,2,2,8,0,8,8,8,8,0,0,0,0,8,2,2,0,0,2,2,0,0,0,0,0,0,0,0,0,2,0,0
0,0,2,0,0,2,2,2,2,2,0,0,0,0,0,0,0,8,0,0,0,0,0,0,18,8,2,2,2,2,2,2,2,2,2,8,0,0,0,0,8,0,0,0,37,8,2,2,0,0,2,2,0,0,0,0,0,0,0,0,0,2,0,0
0,0,2,0,0,2,2,2,2,2,2,0,0,0,0,0,0,8,0,0,0,0,0,0,0,8,2,2,2,2,2,2,2,2,2,8,10,183,183,183,183,183,183,183,183,10,2,2,170,170,2,2,2,2,2,2,2,2,2,2,2,2,0,0
0,0,2,0,0,2,2,2,2,2,2,2,2,2,2,2,2,10,2,2,202,202,2,2,2,10,2,2,0,0,0,0,0,2,2,10,0,0,0,0,0,0,0,0,0,0,0,0,0,0,0,0,0,0,0,0,0,0,0,0,0,0,0,0
0,0,2,0,0,0,0,0,2,8,2,2,2,2,2,2,2,0,0,0,0,0,0,0,0,0,0,0,0,0,0,0,0,0,0,0,0,0,0,0,0,0,0,0,0,0,0,0,0,0,0,0,0,0,0,0,0,0,0,0,0,0,0,0
0,0,2,2,2,2,2,2,10,2,2,2,2,2,2,2,10,0,0,0,0,0,0,0,0,0,0,0,0,0,0,0,0,0,0,0,0,0,0,0,0,0,0,0,0,0,0,0,0,0,0,0,0,0,0,0,0,0,0,0,0,0,0,0
0,0,0,0,0,0,0,0,0,0,0,0,0,0,0,0,0,0,0,0,0,0,0,0,0,0,0,0,0,0,0,0,0,0,0,0,0,0,0,0,0,0,0,0,0,0,0,0,0,0,0,0,0,0,0,0,0,0,0,0,0,0,0,0
0,0,0,0,0,0,0,0,0,0,0,0,0,0,0,0,0,0,0,0,0,0,0,0,0,0,0,0,0,0,0,0,0,0,0,0,0,0,0,0,0,0,0,0,0,0,0,0,0,0,0,0,0,0,0,0,0,0,0,0,0,0,0,0
0,0,0,0,0,0,0,0,0,0,0,0,0,0,0,0,0,0,0,0,0,0,0,0,0,0,0,0,0,0,0,0,0,0,0,0,0,0,0,0,0,0,0,0,0,0,0,0,0,0,0,0,0,0,0,0,0,0,0,0,0,0,0,0
0,0,0,0,0,0,0,0,0,0,0,0,0,0,0,0,0,0,0,0,0,0,0,0,0,0,0,0,0,0,0,0,0,0,0,0,0,0,0,0,0,0,0,0,0,0,0,0,0,0,0,0,0,0,0,0,0,0,0,0,0,0,0,0
:endlayer
layer: 10
0,0,0,0,0,0,0,0,0,0,0,0,0,0,0,0,0,0,0,0,0,0,0,0,0,0,0,0,0,0,0,0,0,0,0,0,0,0,0,0,0,0,0,0,0,0,0,0,0,0,0,0,0,0,0,0,0,0,0,0,0,0,0,0
0,0,0,0,0,0,0,0,0,0,0,0,0,0,0,0,0,0,0,0,0,0,0,0,0,0,0,0,0,0,0,0,0,0,0,0,0,0,0,0,0,0,0,0,0,0,0,0,0,0,0,0,0,0,0,0,0,0,0,0,0,0,0,0
0,0,246,0,247,246,247,0,247,246,247,0,247,246,247,0,247,246,247,0,0,247,246,247,0,247,246,247,0,247,246,247,0,247,246,247,0,247,246,247,0,247,246,247,0,247,246,247,0,247,246,247,0,247,246,247,0,247,246,247,0,246,0,0
0,0,0,0,0,0,0,0,0,0,0,0,0,0,0,0,0,0,0,0,0,0,0,0,0,0,0,0,0,0,0,0,0,0,0,0,0,0,0,0,0,0,0,0,0,0,0,0,0,0,0,0,0,0,0,0,0,0,0,0,0,247,0,0
0,0,247,0,0,0,0,0,0,0,0,0,0,0,0,0,0,0,0,0,0,0,0,0,0,0,0,0,0,0,0,0,0,0,0,0,0,0,0,0,0,0,0,0,0,0,0,0,0,0,0,0,0,0,0,0,0,0,0,0,0,0,0,0
0,0,246,0,0,0,0,0,10,0,0,0,0,0,0,0,0,0,0,0,0,0,10,0,0,0,0,0,0,0,0,0,0,0,0,0,0,0,10,0,0,0,0,0,0,0,0,0,0,0,0,0,0,0,0,0,10,0,0,0,0,247,0,0
0,0,247,0,0,0,0,0,32,2,2,249,2,249,2,249,2,249,2,249,2,2,32,0,0,0,0,0,0,0,0,0,0,0,0,0,0,0,32,2,2,249,2,249,2,249,2,249,2,249,2,249,2,248,2,2,32,0,0,0,0,246,0,0
0,0,0,0,0,0,0,0,0,2,0,0,32,0,0,0,0,0,0,0,0,2,0,0,0,0,0,0,0,0,0,0,0,0,0,0,0,0,0,2,0,0,0,0,0,0,0,0,32,0,0,0,2,0,33,2,0,0,0,0,0,247,0,0
0,0,247,0,0,0,0,0,0,2,0,0,0,0,0,0,0,0,0,0,0,2,0,0,0,0,0,0,0,0,0,0,0,0,0,0,0,0,0,2,0,0,0,0,0,0,0,0,0,0,0,33,2,0,0,248,0,0,0,0,0,0,0,0
0,0,246,0,0,0,0,0,0,2,0,0,0,0,0,0,0,0,0,0,0,198,0,0,0,0,0,0,0,0,0,0,0,0,0,0,0,0,0,198,0,0,0,0,0,0,0,0,0,0,0,0,9,0,0,2,0,0,0,0,0,247,0,0
0,0,247,0,0,0,0,0,0,2,0,0,0,0,0,0,0,0,0,0,0,250,0,0,0,0,0,0,0,0,0,0,0,0,0,0,0,0,0,250,0,0,0,0,0,0,0,0,0,0,0,0,2,0,0,2,0,0,0,0,0,246,0,0
0,0,0,0,0,0,0,0,0,2,0,0,0,0,0,0,0,0,0,0,0,2,0,0,0,0,0,0,0,0,0,0,0,0,0,0,0,0,0,2,0,0,0,0,0,0,0,0,0,0,0,33,2,0,0,248,0,0,0,0,0,247,0,0
0,0,247,0,0,0,0,0,0,2,0,0,37,0,0,0,0,0,0,0,0,2,0,0,0,0,0,0,0,0,0,0,0,0,0,0,0,0,0,2,0,0,0,0,0,0,0,0,37,0,0,0,2,0,33,2,0,0,0,0,0,0,0,0
0,0,246,0,0,0,0,0,37,2,2,249,2,249,2,249,2,249,2,249,2,2,37,0,0,0,0,0,0,0,0,0,0,0,0,0,0,0,37,2,2,249,2,249,2,249,2,249,2,249,2,249,2,248,2,2,37,0,0,0,0,247,0,0
0,0,247,0,0,0,0,0,10,0,0,0,0,0,0,0,0,0,0,0,0,0,10,0,0,0,0,0,0,0,0,0,0,0,0,0,0,0,10,0,0,0,0,0,0,0,0,0,0,0,0,0,0,0,0,0,10,0,0,0,0,246,0,0
0,0,0,0,0,0,0,0,0,0,0,0,0,0,0,0,0,0,0,0,0,0,0,0,0,0,0,0,0,0,0,0,0,0,0,0,0,0,0,0,0,0,0,0,0,0,0,0,0,0,0,0,0,0,0,0,0,0,0,0,0,247,0,0
0,0,247,0,0,0,0,0,0,10,10,10,10,10,10,10,10,10,10,10,10,10,0,0,0,0,0,0,0,0,0,0,0,0,0,0,0,0,0,10,10,10,10,10,10,10,10,10,10,10,10,10,0,0,0,0,0,0,0,0,0,0,0,0
0,0,246,0,0,0,0,0,0,10,71,71,10,71,71,10,71,71,10,71,71,2,0,0,0,0,0,0,0,0,0,0,0,0,0,0,0,0,0,2,71,71,10,71,71,10,71,71,10,71,71,10,0,0,0,0,0,0,0,0,0,247,0,0
0,0,247,0,0,0,0,0,0,10,0,0,32,0,0,32,0,0,32,0,0,2,0,0,0,0,0,0,0,0,0,0,0,0,0,0,0,0,0,2,0,0,32,0,0,32,0,0,32,0,0,10,0,0,0,0,0,0,0,0,0,246,0,0
0,0,0,0,0,0,0,0,0,10,0,0,37,0,0,37,0,0,37,0,0,2,0,0,0,0,0,0,0,0,0,0,0,0,0,0,0,0,0,2,0,0,37,0,0,37,0,0,37,0,0,10,0,0,0,0,0,0,0,0,0,247,0,0
0,0,247,0,0,0,0,0,0,10,71,71,10,71,71,10,71,71,10,71,71,2,0,0,0,0,0,0,0,0,0,0,0,0,0,0,0,0,0,2,71,71,10,71,71,10,71,71,10,71,71,10,0,0,0,0,0,0,0,0,0,0,0,0
0,0,246,0,0,0,0,0,0,10,10,10,10,10,10,10,10,10,10,10,10,10,0,0,0,0,0,0,0,0,0,0,0,0,0,0,0,0,0,10,10,10,10,10,10,10,10,10,10,10,10,10,0,0,0,0,0,0,0,0,0,247,0,0
0,0,247,0,0,0,0,0,24,24,24,24,24,24,24,24,24,24,24,24,24,24,24,0,0,0,0,0,0,0,0,0,0,0,0,0,0,0,24,24,24,24,24,24,24,24,24,24,24,24,24,24,24,0,0,0,0,0,0,0,0,246,0,0
0,0,0,0,0,0,0,0,0,0,0,0,0,0,0,0,0,0,0,0,0,0,0,0,0,0,0,0,0,0,0,0,0,0,0,0,0,0,0,0,0,0,0,0,0,0,0,0,0,0,0,0,0,0,0,0,0,0,0,0,0,247,0,0
0,0,247,0,0,0,0,0,2,2,2,2,2,2,2,2,2,2,2,2,2,2,2,2,2,2,2,2,2,2,2,2,2,2,2,2,2,2,2,2,2,2,2,2,2,2,2,2,2,45,2,2,2,2,2,0,0,0,0,0,0,0,0,0
0,0,246,0,0,0,0,0,2,0,0,0,0,0,32,0,0,8,0,0,0,0,0,0,0,0,0,0,0,0,0,8,0,0,0,8,0,251,0,0,0,0,0,0,0,8,0,0,0,0,0,2,0,0,2,0,0,0,0,0,0,247,0,0
0,0,247,0,0,2,0,0,2,0,0,0,0,0,0,0,0,8,0,0,0,0,0,0,0,0,0,8,0,0,0,8,0,0,0,8,0,8,0,0,0,0,0,0,0,8,0,0,0,0,0,2,0,0,2,0,0,0,0,0,0,246,0,0
0,0,0,0,0,2,30,30,2,253,8,0,0,0,0,0,0,8,0,0,0,0,0,0,0,0,0,8,0,0,0,252,0,0,0,8,0,8,0,0,0,0,0,0,0,8,0,0,0,0,0,2,0,0,2,0,0,0,0,0,0,247,0,0
0,0,247,0,0,2,2,2,2,0,0,0,0,0,0,0,0,8,0,0,0,0,0,0,0,0,0,8,0,0,0,8,0,0,0,8,0,8,8,71,71,71,71,71,8,8,0,0,0,0,0,2,2,2,2,0,0,0,0,0,0,0,0,0
0,0,246,0,0,2,0,0,2,0,0,0,71,0,0,71,0,8,0,0,0,0,0,0,0,0,0,8,0,0,0,8,0,0,0,8,0,0,0,0,0,0,0,0,0,8,0,0,0,0,0,2,13,13,2,0,0,0,0,0,0,247,0,0
0,0,247,0,0,2,0,0,2,33,8,0,0,0,0,0,0,8,0,0,0,0,0,0,0,0,0,8,8,16,8,8,8,0,8,8,0,0,0,0,0,0,0,0,0,8,0,0,0,0,0,2,0,0,2,0,0,0,0,0,0,246,0,0
0,0,0,0,0,2,0,0,2,0,0,29,0,0,0,0,29,8,0,0,8,8,8,8,8,8,8,8,0,0,0,0,0,0,0,8,0,0,0,0,0,0,0,0,0,8,0,0,0,0,0,2,0,0,0,0,0,0,0,0,0,247,0,0
0,0,247,0,0,2,0,0,2,0,0,0,71,0,0,71,0,8,8,8,8,22,0,0,0,0,0,8,0,0,0,0,0,0,0,8,8,8,0,0,0,0,0,0,0,8,0,0,0,0,0,2,0,0,0,0,0,0,0,0,0,0,0,0
0,0,246,0,0,2,0,0,10,0,8,8,8,8,8,8,8,8,8,0,0,8,8,71,0,0,0,8,0,0,0,0,0,0,0,8,24,8,0,0,0,0,0,0,0,8,2,2,2,2,2,2,0,0,0,0,0,0,0,0,0,247,0,0
0,0,247,0,0,254,0,0,2,8,8,22,0,0,33,8,8,8,0,0,0,0,8,0,0,0,0,8,0,0,0,0,0,0,0,8,0,8,0,0,0,0,0,0,0,8,2,2,13,13,2,2,0,0,0,0,0,0,0,0,0,246,0,0
0,0,0,0,0,2,0,0,2,8,8,8,8,8,8,8,8,8,0,0,0,0,8,8,8,8,8,8,8,0,0,0,0,0,0,8,0,8,0,0,0,0,0,0,0,8,2,2,0,0,2,2,0,0,0,0,0,0,0,0,0,247,0,0
0,0,247,0,0,2,0,0,2,8,8,8,8,8,8,8,8,8,0,0,0,0,0,8,8,32,0,0,0,0,0,0,0,0,0,8,0,8,0,0,0,0,0,0,0,8,2,2,0,0,2,2,0,0,0,0,0,0,0,0,0,0,0,0
0,0,246,0,0,2,0,0,2,8,8,8,8,8,8,8,8,8,0,0,0,0,0,8,8,8,8,8,8,0,0,0,0,0,0,8,0,8,8,8,8,0,0,0,0,8,2,2,0,0,2,2,0,0,0,0,0,0,0,0,0,247,0,0
0,0,247,0,0,2,2,2,2,8,8,8,8,8,8,8,8,8,0,0,0,0,0,0,0,0,0,0,0,0,0,0,0,0,0,8,37,0,0,0,8,0,0,0,0,8,2,2,0,0,2,2,0,0,0,0,0,0,0,0,0,246,0,0
0,0,0,0,0,2,2,2,2,8,8,8,8,8,8,8,8,8,0,0,0,0,0,0,0,8,0,0,0,0,0,0,0,0,0,8,10,2,2,2,2,2,2,2,14,10,2,2,2,2,2,2,0,247,246,247,0,247,246,247,0,247,0,0
0,0,247,0,0,2,2,2,2,2,2,2,2,2,2,2,8,10,2,202,202,202,202,2,2,10,2,2,2,2,2,2,2,2,2,10,0,0,0,0,0,0,0,0,0,0,0,0,0,0,0,0,0,0,0,0,0,0,0,0,0,0,0,0
0,0,246,0,0,0,0,0,2,8,8,8,2,2,8,8,2,0,0,0,0,0,0,0,0,24,229,24,24,229,229,229,24,24,229,24,0,0,0,0,0,0,0,0,0,0,0,0,0,0,0,0,0,0,0,0,0,0,0,0,0,0,0,0
0,0,247,0,247,246,247,0,10,2,2,2,2,2,2,2,10,0,0,0,0,0,0,0,0,0,0,0,0,0,0,0,0,0,0,0,0,0,0,0,0,0,0,0,0,0,0,0,0,0,0,0,0,0,0,0,0,0,0,0,0,0,0,0
0,0,0,0,0,0,0,0,0,0,0,0,0,0,0,0,0,0,0,0,0,0,0,0,0,0,0,0,0,0,0,0,0,0,0,0,0,0,0,0,0,0,0,0,0,0,0,0,0,0,0,0,0,0,0,0,0,0,0,0,0,0,0,0
0,0,0,0,0,0,0,0,0,0,0,0,0,0,0,0,0,0,0,0,0,0,0,0,0,0,0,0,0,0,0,0,0,0,0,0,0,0,0,0,0,0,0,0,0,0,0,0,0,0,0,0,0,0,0,0,0,0,0,0,0,0,0,0
0,0,0,0,0,0,0,0,0,0,0,0,0,0,0,0,0,0,0,0,0,0,0,0,0,0,0,0,0,0,0,0,0,0,0,0,0,0,0,0,0,0,0,0,0,0,0,0,0,0,0,0,0,0,0,0,0,0,0,0,0,0,0,0
0,0,0,0,0,0,0,0,0,0,0,0,0,0,0,0,0,0,0,0,0,0,0,0,0,0,0,0,0,0,0,0,0,0,0,0,0,0,0,0,0,0,0,0,0,0,0,0,0,0,0,0,0,0,0,0,0,0,0,0,0,0,0,0
:endlayer
layer: 11
0,0,0,0,0,0,0,0,0,0,0,0,0,0,0,0,0,0,0,0,0,0,0,0,0,0,0,0,0,0,0,0,0,0,0,0,0,0,0,0,0,0,0,0,0,0,0,0,0,0,0,0,0,0,0,0,0,0,0,0,0,0,0,0
0,0,0,0,0,0,0,0,0,0,0,0,0,0,0,0,0,0,0,0,0,0,0,0,0,0,0,0,0,0,0,0,0,0,0,0,0,0,0,0,0,0,0,0,0,0,0,0,0,0,0,0,0,0,0,0,0,0,0,0,0,0,0,0
0,0,48,0,0,48,0,0,0,48,0,0,0,48,0,0,0,48,0,0,0,0,48,0,0,0,48,0,0,0,48,0,0,0,48,0,0,0,48,0,0,0,48,0,0,0,48,0,0,0,48,0,0,0,48,0,0,0,48,0,0,48,0,0
0,0,0,0,0,0,0,0,0,0,0,0,0,0,0,0,0,0,0,0,0,0,0,0,0,0,0,0,0,0,0,0,0,0,0,0,0,0,0,0,0,0,0,0,0,0,0,0,0,0,0,0,0,0,0,0,0,0,0,0,0,0,0,0
0,0,0,0,0,0,0,0,0,0,0,0,0,0,0,0,0,0,0,0,0,0,0,0,0,0,0,0,0,0,0,0,0,0,0,0,0,0,0,0,0,0,0,0,0,0,0,0,0,0,0,0,0,0,0,0,0,0,0,0,0,0,0,0
0,0,48,0,0,0,0,0,10,0,0,0,0,37,0,0,0,0,0,0,0,33,10,0,0,0,0,0,0,0,0,0,0,0,0,0,0,0,10,60,0,0,0,0,0,0,0,37,0,0,0,0,0,0,0,33,10,0,0,0,0,0,0,0
0,0,0,0,0,0,0,0,44,8,8,8,8,8,8,8,8,8,8,8,8,8,43,0,0,0,0,0,0,0,0,0,0,0,0,0,0,0,44,8,8,8,8,8,8,8,8,8,8,8,8,8,8,8,8,8,43,0,0,0,0,48,0,0
0,0,0,0,0,0,0,0,44,8,8,8,8,8,8,8,8,8,8,8,8,8,43,0,0,0,0,0,0,0,0,0,0,0,0,0,0,0,44,8,8,8,8,8,8,8,8,8,8,8,8,8,8,8,8,8,43,0,0,0,0,0,0,0
0,0,0,0,0,0,0,0,44,255,255,255,255,255,255,255,255,255,255,255,8,8,43,0,0,0,0,0,0,0,0,0,0,0,0,0,0,0,44,8,8,255,255,255,255,255,255,255,255,255,255,255,255,255,8,8,43,0,0,0,0,0,0,0
0,0,48,0,0,0,0,0,44,0,0,0,0,0,0,0,0,0,0,255,8,2,43,0,0,0,0,0,0,0,0,0,0,0,0,0,0,0,44,2,8,255,0,0,0,0,0,0,0,0,0,0,0,255,8,8,43,0,0,0,0,0,0,0
0,0,0,0,0,0,0,0,44,0,0,0,0,0,0,0,0,0,0,255,8,2,43,0,0,0,0,0,0,0,0,0,0,0,0,0,0,0,44,2,8,255,0,0,0,0,0,0,0,0,0,0,255,255,8,8,43,0,0,0,0,48,0,0
0,0,0,0,0,0,0,0,44,255,255,255,255,255,255,255,255,255,255,255,8,8,43,0,0,0,0,0,0,0,0,0,0,0,0,0,0,0,44,8,8,255,255,255,255,255,255,255,255,255,255,255,255,255,8,8,43,0,0,0,0,0,0,0
0,0,0,0,0,0,0,0,44,8,8,8,8,8,8,8,8,8,8,8,8,8,43,0,0,0,0,0,0,0,0,0,0,0,0,0,0,0,44,8,8,8,8,8,8,8,8,8,8,8,8,8,8,8,8,8,43,0,0,0,0,0,0,0
0,0,48,0,0,0,0,0,44,8,8,8,8,8,8,8,8,8,8,8,8,8,43,0,0,0,0,0,0,0,0,0,0,0,0,0,0,0,44,8,8,8,8,8,8,8,8,8,8,8,8,8,8,8,8,8,43,0,0,0,0,0,0,0
0,0,0,0,0,0,0,0,10,0,0,0,0,32,0,0,0,0,0,0,0,33,10,0,0,0,0,0,0,0,0,0,0,0,0,0,0,0,10,60,0,0,0,0,0,0,0,32,0,0,0,0,0,0,0,33,10,0,0,0,0,48,0,0
0,0,0,0,0,0,0,0,0,0,0,0,0,0,0,0,0,0,0,0,0,0,0,0,0,0,0,0,0,0,0,0,0,0,0,0,0,0,0,0,0,0,0,0,0,0,0,0,0,0,0,0,0,0,0,0,0,0,0,0,0,0,0,0
0,0,0,0,0,0,0,0,256,256,256,256,256,256,256,256,256,256,256,256,256,256,256,0,0,0,0,0,0,0,0,0,0,0,0,0,0,0,256,256,256,256,256,256,256,256,256,256,256,256,256,256,256,0,0,0,0,0,0,0,0,0,0,0
0,0,48,0,0,0,0,0,0,10,10,10,10,10,10,10,10,10,10,10,10,10,0,0,0,0,0,0,0,0,0,0,0,0,0,0,0,0,0,10,10,10,10,10,10,10,10,10,10,10,10,10,0,0,0,0,0,0,0,0,0,0,0,0
0,0,0,0,0,0,0,0,0,249,0,0,0,0,0,0,0,0,0,0,0,249,0,0,0,0,0,0,0,0,0,0,0,0,0,0,0,0,0,249,0,0,0,0,0,0,0,0,0,0,0,249,0,0,0,0,0,0,0,0,0,48,0,0
0,0,0,0,0,0,0,0,0,249,0,0,0,0,0,0,0,0,0,0,0,249,0,0,0,0,0,0,0,0,0,0,0,0,0,0,0,0,0,249,0,0,0,0,0,0,0,0,0,0,0,249,0,0,0,0,0,0,0,0,0,0,0,0
0,0,0,0,0,0,0,0,0,10,10,10,10,10,10,10,10,10,10,10,10,10,0,0,0,0,0,0,0,0,0,0,0,0,0,0,0,0,0,10,10,10,10,10,10,10,10,10,10,10,10,10,0,0,0,0,0,0,0,0,0,0,0,0
0,0,48,0,0,0,0,0,24,24,24,24,24,24,24,24,24,24,24,24,24,24,24,0,0,0,0,0,0,0,0,0,0,0,0,0,0,0,24,24,24,24,24,24,24,24,24,24,24,24,24,24,24,0,0,0,0,0,0,0,0,0,0,0
0,0,0,0,0,0,0,0,0,0,0,0,0,0,0,0,0,0,0,0,0,0,0,0,0,0,0,0,0,0,0,0,0,0,0,0,0,0,0,0,0,0,0,0,0,0,0,0,0,0,0,0,0,0,0,0,0,0,0,0,0,48,0,0
0,0,0,0,0,0,0,0,0,0,0,0,0,0,0,0,0,0,0,0,0,0,0,0,0,0,0,0,0,0,0,0,0,0,0,0,0,0,0,0,0,0,0,0,0,0,0,0,0,0,0,0,0,0,0,0,0,0,0,0,0,0,0,0
0,0,0,0,0,0,0,0,2,2,2,2,2,2,2,45,2,2,2,2,2,2,2,2,2,45,2,249,2,2,2,2,2,249,2,2,2,2,2,2,2,45,2,2,2,2,2,2,2,2,2,2,2,2,2,0,0,0,0,0,0,0,0,0
0,0,48,0,0,0,0,0,2,32,0,0,0,0,0,0,0,8,0,0,0,0,0,0,0,0,0,0,0,0,0,8,0,0,32,8,32,18,0,0,0,0,0,0,0,8,2,2,2,2,2,2,0,0,2,0,0,0,0,0,0,0,0,0
0,0,0,0,0,0,0,0,2,263,0,0,0,0,0,0,0,8,0,0,0,0,0,0,0,0,0,8,0,0,0,8,0,0,0,8,0,8,0,0,0,0,0,0,0,8,2,2,2,2,2,2,0,0,2,0,0,0,0,0,0,48,0,0
0,0,0,0,0,2,0,0,2,8,8,0,0,0,0,0,0,8,0,0,0,0,0,0,0,0,0,8,0,0,0,257,0,0,0,8,0,8,0,0,0,0,0,0,0,8,2,2,2,2,2,2,2,2,2,0,0,0,0,0,0,0,0,0
0,0,0,0,0,2,30,30,2,0,8,0,0,0,0,0,0,8,0,0,0,0,0,0,0,0,0,8,0,0,0,8,0,0,0,8,0,8,8,8,8,8,8,8,8,8,2,2,2,2,2,2,13,13,2,0,0,0,0,0,0,0,0,0
0,0,48,0,0,2,264,264,2,0,8,0,259,0,0,259,0,8,0,0,0,0,0,0,0,0,0,8,37,0,0,8,0,0,37,8,0,0,0,0,0,0,0,0,0,8,2,2,2,2,2,2,0,0,2,0,0,0,0,0,0,0,0,0
0,0,0,0,0,2,60,0,2,0,8,0,0,0,0,0,0,8,0,0,0,0,0,0,0,0,0,8,8,258,8,8,8,0,8,8,0,0,0,0,0,0,0,0,0,8,2,2,2,2,2,2,0,0,0,0,0,0,0,0,0,48,0,0
0,0,0,0,0,2,0,0,2,0,8,0,0,0,0,0,0,8,0,0,8,8,8,8,8,8,8,8,0,0,0,0,0,0,0,8,8,8,0,0,0,0,0,0,0,8,2,2,2,2,2,2,0,0,0,0,0,0,0,0,0,0,0,0
0,0,0,0,0,2,0,0,2,0,8,0,259,261,261,259,0,8,8,22,0,0,0,0,0,0,0,8,0,0,0,0,0,0,0,8,0,18,0,0,0,0,0,0,0,8,2,2,2,2,2,2,0,0,0,0,0,0,0,0,0,0,0,0
0,0,48,0,0,2,0,0,10,0,8,8,8,8,8,8,8,8,8,8,8,8,71,48,0,0,0,8,0,0,0,0,0,0,0,8,0,8,0,0,0,0,0,0,0,8,2,2,13,13,2,2,0,0,0,0,0,0,0,0,0,0,0,0
0,0,0,0,0,2,0,0,2,8,0,0,0,0,0,71,0,8,32,0,0,32,8,0,0,0,0,8,0,0,0,0,0,0,0,8,0,8,0,0,0,0,0,0,0,8,2,2,0,0,2,2,0,0,0,0,0,0,0,0,0,48,0,0
0,0,0,0,0,2,0,0,2,8,0,71,71,71,71,71,0,8,0,0,0,0,8,8,8,8,8,8,8,0,0,0,0,0,0,8,0,8,0,0,0,0,0,0,0,8,2,2,0,0,2,2,0,0,0,0,0,0,0,0,0,0,0,0
0,0,0,0,0,2,60,0,2,8,0,0,0,0,0,0,0,8,0,0,0,0,0,8,8,0,0,0,0,0,0,0,0,0,0,8,0,8,0,0,0,0,0,0,0,8,2,2,0,0,2,2,0,0,0,0,0,0,0,0,0,0,0,0
0,0,48,0,0,2,265,265,2,8,0,0,0,0,0,0,0,8,0,0,0,0,0,8,8,8,8,8,8,0,0,0,0,0,0,8,0,8,8,8,8,0,0,0,0,8,2,2,0,0,2,2,0,0,0,0,0,0,0,0,0,0,0,0
0,0,0,0,0,2,2,2,2,8,0,0,71,71,71,0,0,8,0,0,0,0,0,0,0,0,0,0,0,0,0,0,0,0,0,8,0,0,0,0,8,0,0,0,0,8,2,2,0,0,45,2,0,0,0,0,0,0,0,0,0,48,0,0
0,0,0,0,0,2,2,2,2,8,22,0,0,0,0,0,0,8,0,0,0,0,0,0,0,8,37,0,0,0,0,0,0,0,37,8,10,2,14,2,2,2,2,2,2,10,2,2,2,2,2,2,0,0,48,0,0,0,48,0,0,0,0,0
0,0,0,0,0,2,2,2,2,8,262,0,0,0,0,260,8,10,2,2,202,202,2,2,2,10,2,202,202,2,2,2,202,202,2,10,0,0,0,0,0,0,0,0,0,0,0,0,0,0,0,0,0,0,0,0,0,0,0,0,0,0,0,0
0,0,48,0,0,0,0,0,2,8,219,21,0,0,21,219,2,0,0,0,0,0,0,0,0,0,0,0,0,0,0,0,0,0,0,0,0,0,0,0,0,0,0,0,0,0,0,0,0,0,0,0,0,0,0,0,0,0,0,0,0,0,0,0
0,0,0,0,0,48,0,0,10,2,2,2,14,14,2,14,10,0,0,0,0,0,0,0,0,0,0,0,0,0,0,0,0,0,0,0,0,0,0,0,0,0,0,0,0,0,0,0,0,0,0,0,0,0,0,0,0,0,0,0,0,0,0,0
0,0,0,0,0,0,0,0,0,0,0,0,0,0,0,0,0,0,0,0,0,0,0,0,0,0,0,0,0,0,0,0,0,0,0,0,0,0,0,0,0,0,0,0,0,0,0,0,0,0,0,0,0,0,0,0,0,0,0,0,0,0,0,0
0,0,0,0,0,0,0,0,0,0,0,0,0,0,0,0,0,0,0,0,0,0,0,0,0,0,0,0,0,0,0,0,0,0,0,0,0,0,0,0,0,0,0,0,0,0,0,0,0,0,0,0,0,0,0,0,0,0,0,0,0,0,0,0
0,0,0,0,0,0,0,0,0,0,0,0,0,0,0,0,0,0,0,0,0,0,0,0,0,0,0,0,0,0,0,0,0,0,0,0,0,0,0,0,0,0,0,0,0,0,0,0,0,0,0,0,0,0,0,0,0,0,0,0,0,0,0,0
0,0,0,0,0,0,0,0,0,0,0,0,0,0,0,0,0,0,0,0,0,0,0,0,0,0,0,0,0,0,0,0,0,0,0,0,0,0,0,0,0,0,0,0,0,0,0,0,0,0,0,0,0,0,0,0,0,0,0,0,0,0,0,0
:endlayer
layer: 12
0,0,0,0,0,0,0,0,0,0,0,0,0,0,0,0,0,0,0,0,0,0,0,0,0,0,0,0,0,0,0,0,0,0,0,0,0,0,0,0,0,0,0,0,0,0,0,0,0,0,0,0,0,0,0,0,0,0,0,0,0,0,0,0
0,0,0,0,0,0,0,0,0,0,0,0,0,0,0,0,0,0,0,0,0,0,0,0,0,0,0,0,0,0,0,0,0,0,0,0,0,0,0,0,0,0,0,0,0,0,0,0,0,0,0,0,0,0,0,0,0,0,0,0,0,0,0,0
0,0,0,0,0,0,0,0,0,0,0,0,0,0,0,0,0,0,0,0,0,0,0,0,0,0,0,0,0,0,0,0,0,0,0,0,0,0,0,0,0,0,0,0,0,0,0,0,0,0,0,0,0,0,0,0,0,0,0,0,0,0,0,0
0,0,0,0,0,0,0,0,0,0,0,0,0,0,0,0,0,0,0,0,0,0,0,0,0,0,0,0,0,0,0,0,0,0,0,0,0,0,0,0,0,0,0,0,0,0,0,0,0,0,0,0,0,0,0,0,0,0,0,0,0,0,0,0
0,0,0,0,0,0,0,0,0,0,0,0,0,0,0,0,0,0,0,0,0,0,0,0,0,0,0,0,0,0,0,0,0,0,0,0,0,0,0,0,0,0,0,0,0,0,0,0,0,0,0,0,0,0,0,0,0,0,0,0,0,0,0,0
0,0,0,0,0,0,0,256,256,256,256,256,256,256,256,256,256,256,256,256,256,256,256,0,0,0,0,0,0,0,0,0,0,0,0,0,0,0,256,256,256,256,256,256,256,256,256,256,256,256,256,256,256,256,256,256,256,0,0,0,0,0,0,0
0,0,0,0,0,0,0,0,8,8,8,8,8,8,8,8,8,8,8,8,8,8,0,0,0,0,0,0,0,0,0,0,0,0,0,0,0,0,0,8,8,8,8,8,8,8,8,8,8,8,8,8,8,8,8,8,0,0,0,0,0,0,0,0
0,0,0,0,0,0,0,0,8,0,309,307,0,305,303,0,301,299,0,297,293,8,0,0,0,0,0,0,0,0,0,0,0,0,0,0,0,0,0,8,287,285,0,283,281,0,279,277,0,275,273,0,270,268,0,8,0,0,0,0,0,0,0,0
0,0,0,0,0,0,0,0,8,0,0,0,0,0,0,0,0,0,0,0,0,8,0,0,0,0,0,0,0,0,0,0,0,0,0,0,0,0,0,8,0,0,0,0,0,0,0,0,0,0,0,0,0,0,0,8,0,0,0,0,0,0,0,0
0,0,0,0,0,0,0,0,8,0,0,0,0,0,0,0,0,0,0,0,294,8,0,0,0,0,0,0,0,0,0,0,0,0,0,0,0,0,0,8,288,0,0,0,0,0,0,0,0,0,0,0,0,0,266,8,0,0,0,0,0,0,0,0
0,0,0,0,0,0,0,0,8,0,0,0,0,0,0,0,0,0,0,0,295,8,0,0,0,0,0,0,0,0,0,0,0,0,0,0,0,0,0,8,289,0,0,0,0,0,0,0,0,0,0,0,0,0,267,8,0,0,0,0,0,0,0,0
0,0,0,0,0,0,0,0,8,0,0,0,0,0,0,0,0,0,0,0,0,8,0,0,0,0,0,0,0,0,0,0,0,0,0,0,0,0,0,8,0,0,0,0,0,0,0,0,0,0,0,0,0,0,0,8,0,0,0,0,0,0,0,0
0,0,0,0,0,0,0,0,8,0,310,308,0,306,304,0,302,300,0,298,296,8,0,0,0,0,0,0,0,0,0,0,0,0,0,0,0,0,0,8,290,286,0,284,282,0,280,278,0,276,274,0,271,269,0,8,0,0,0,0,0,0,0,0
0,0,0,0,0,0,0,0,8,8,8,8,8,8,8,8,8,8,8,8,8,8,0,0,0,0,0,0,0,0,0,0,0,0,0,0,0,0,0,8,8,8,8,8,8,8,8,8,8,8,8,8,8,8,8,8,0,0,0,0,0,0,0,0
0,0,0,0,0,0,0,24,24,24,24,24,24,24,24,24,24,24,24,24,24,24,24,0,0,0,0,0,0,0,0,0,0,0,0,0,0,0,24,24,24,24,24,24,24,24,24,24,24,24,24,24,24,24,24,24,24,0,0,0,0,0,0,0
0,0,0,0,0,0,0,0,0,0,0,0,0,0,0,0,0,0,0,0,0,0,0,0,0,0,0,0,0,0,0,0,0,0,0,0,0,0,0,0,0,0,0,0,0,0,0,0,0,0,0,0,0,0,0,0,0,0,0,0,0,0,0,0
0,0,0,0,0,0,0,0,0,0,0,0,0,0,0,0,0,0,0,0,0,0,0,0,0,0,0,0,0,0,0,0,0,0,0,0,0,0,0,0,0,0,0,0,0,0,0,0,0,0,0,0,0,0,0,0,0,0,0,0,0,0,0,0
0,0,0,0,0,0,0,0,256,256,256,256,256,256,256,256,256,256,256,256,256,256,256,0,0,0,0,0,0,0,0,0,0,0,0,0,0,0,256,256,256,256,256,256,256,256,256,256,256,256,256,256,256,0,0,0,0,0,0,0,0,0,0,0
0,0,0,0,0,0,0,0,272,10,0,0,10,0,0,10,0,0,10,0,0,10,272,0,0,0,0,0,0,0,0,0,0,0,0,0,0,0,272,10,0,0,10,0,0,10,0,0,10,0,0,10,272,0,0,0,0,0,0,0,0,0,0,0
0,0,0,0,0,0,0,0,272,10,0,0,10,0,0,10,0,0,10,0,0,10,272,0,0,0,0,0,0,0,0,0,0,0,0,0,0,0,272,10,0,0,10,0,0,10,0,0,10,0,0,10,272,0,0,0,0,0,0,0,0,0,0,0
0,0,0,0,0,0,0,0,24,24,24,24,24,24,24,24,24,24,24,24,24,24,24,0,0,0,0,0,0,0,0,0,0,0,0,0,0,0,24,24,24,24,24,24,24,24,24,24,24,24,24,24,24,0,0,0,0,0,0,0,0,0,0,0
0,0,0,0,0,0,0,0,0,0,0,0,0,0,0,0,0,0,0,0,0,0,0,0,0,0,0,0,0,0,0,0,0,0,0,0,0,0,0,0,0,0,0,0,0,0,0,0,0,0,0,0,0,0,0,0,0,0,0,0,0,0,0,0
0,0,0,0,0,0,0,0,0,0,0,0,0,0,0,0,0,0,0,0,0,0,0,0,0,0,0,0,0,0,0,0,0,0,0,0,0,0,0,0,0,0,0,0,0,0,0,0,0,0,0,0,0,0,0,0,0,0,0,0,0,0,0,0
0,0,0,0,0,0,0,0,0,0,0,0,0,0,0,0,0,0,0,0,0,0,0,0,0,0,0,0,0,0,0,0,0,0,0,0,0,0,0,0,0,0,0,0,0,0,0,0,0,0,0,0,0,0,0,0,0,0,0,0,0,0,0,0
0,0,0,0,0,0,0,0,2,2,2,2,2,2,2,2,2,2,2,2,2,2,2,2,2,2,2,2,2,2,2,2,2,2,2,2,2,2,2,2,2,2,2,2,2,2,2,2,2,2,2,2,2,2,2,0,0,0,0,0,0,0,0,0
0,0,0,0,0,0,0,0,2,2,2,2,2,2,2,2,2,2,2,2,2,2,2,2,2,2,2,2,2,2,2,2,2,2,2,2,2,2,2,2,2,2,2,2,2,2,2,2,2,2,2,2,2,2,2,0,0,0,0,0,0,0,0,0
0,0,0,0,0,0,0,0,2,2,3,3,3,3,3,3,3,3,3,3,3,3,3,3,3,3,3,3,3,3,3,3,3,3,3,3,3,3,3,3,3,3,3,3,3,3,3,3,3,3,2,2,2,2,2,0,0,0,0,0,0,0,0,0
0,0,0,0,0,0,0,0,2,2,3,3,3,3,3,3,3,3,3,3,3,3,3,3,3,3,3,3,3,3,3,3,3,3,3,3,3,3,3,3,3,3,3,3,3,3,3,3,3,3,2,2,13,13,2,0,0,0,0,0,0,0,0,0
0,0,0,0,0,2,0,0,2,2,3,3,3,3,3,3,3,3,3,3,3,3,3,3,3,3,3,3,3,3,3,3,3,3,3,3,3,3,3,3,3,3,3,3,3,3,3,3,3,3,2,2,0,0,2,0,0,0,0,0,0,0,0,0
0,0,0,0,0,2,30,30,2,2,2,2,2,2,2,3,2,2,2,2,2,2,3,2,2,2,2,2,2,2,2,2,3,2,2,2,2,2,2,2,2,2,2,2,2,2,2,2,3,3,2,2,0,0,0,0,0,0,0,0,0,0,0,0
0,0,0,0,0,2,2,2,2,2,2,2,2,2,2,3,2,2,2,2,2,2,2,2,2,2,2,2,2,2,2,2,3,2,2,2,2,2,2,2,2,2,2,2,2,10,2,2,3,3,2,2,0,0,0,0,0,0,0,0,0,0,0,0
0,0,0,0,0,2,2,2,2,2,2,2,2,2,2,2,2,2,2,2,2,2,2,2,2,2,2,2,2,2,2,2,2,2,2,2,8,8,8,8,8,8,8,8,8,2,2,2,3,3,2,2,0,0,0,0,0,0,0,0,0,0,0,0
0,0,0,0,0,2,2,2,2,2,2,2,2,2,2,2,2,2,0,0,0,0,0,2,2,2,2,2,2,2,2,2,2,2,2,2,0,0,18,8,8,8,8,8,8,2,2,2,13,13,2,2,0,0,0,0,0,0,0,0,0,0,0,0
0,0,0,0,0,2,2,2,10,2,2,2,2,2,2,2,2,2,256,292,292,292,2,2,2,2,2,2,2,2,2,2,2,2,2,2,0,8,8,8,8,8,8,8,8,2,2,2,0,0,2,2,0,0,0,0,0,0,0,0,0,0,0,0
0,0,0,0,0,2,2,2,2,32,0,0,0,0,0,0,0,2,292,292,292,292,292,2,2,2,2,2,2,2,2,2,2,2,2,2,0,8,8,8,8,8,8,8,8,2,2,2,0,0,2,2,0,0,0,0,0,0,0,0,0,0,0,0
0,0,0,0,0,2,2,2,2,0,0,0,0,0,0,0,0,2,292,292,292,292,292,2,2,2,2,2,2,2,2,2,2,2,2,2,0,8,8,8,8,8,8,8,8,2,2,2,0,0,2,2,0,0,0,0,0,0,0,0,0,0,0,0
0,0,0,0,0,2,2,2,2,8,0,0,0,0,0,0,0,2,292,292,292,292,292,2,2,2,2,2,2,2,2,2,2,2,2,2,8,8,8,8,8,8,8,8,8,2,2,2,0,0,2,2,0,0,0,0,0,0,0,0,0,0,0,0
0,0,0,0,0,2,2,2,2,8,0,0,0,0,0,0,0,2,2,292,292,292,292,2,2,2,2,2,2,2,2,2,2,2,2,2,8,8,8,8,8,8,8,8,8,2,2,2,0,0,2,2,0,0,0,0,0,0,0,0,0,0,0,0
0,0,0,0,0,2,2,2,2,24,0,0,42,42,42,0,0,2,2,292,292,292,292,2,2,2,2,2,2,2,2,2,2,2,2,2,8,8,8,8,8,8,8,8,8,2,2,2,0,0,2,2,0,0,0,0,0,0,0,0,0,0,0,0
0,0,0,0,0,2,2,2,2,0,0,0,0,0,0,0,0,2,2,2,292,292,292,2,2,2,2,2,2,2,2,2,2,2,2,2,10,2,2,2,2,2,14,2,2,10,2,2,2,2,2,2,0,0,0,0,0,0,0,0,0,0,0,0
0,0,0,0,0,2,2,2,2,0,0,0,0,0,0,0,8,10,45,2,2,2,2,2,2,10,291,2,2,2,2,2,2,2,291,10,0,0,0,0,0,0,0,0,0,0,0,0,0,0,0,0,0,0,0,0,0,0,0,0,0,0,0,0
0,0,0,0,0,0,0,0,2,8,21,219,0,0,219,21,2,71,0,71,0,71,0,71,0,71,0,71,0,71,0,71,0,71,0,71,0,0,0,0,0,0,0,0,0,0,0,0,0,0,0,0,0,0,0,0,0,0,0,0,0,0,0,0
0,0,0,0,0,0,0,0,10,2,2,2,249,249,2,2,10,0,0,0,0,0,0,0,0,0,0,0,0,0,0,0,0,0,0,0,0,0,0,0,0,0,0,0,0,0,0,0,0,0,0,0,0,0,0,0,0,0,0,0,0,0,0,0
0,0,0,0,0,0,0,0,0,0,0,0,0,0,0,0,0,0,0,0,0,0,0,0,0,0,0,0,0,0,0,0,0,0,0,0,0,0,0,0,0,0,0,0,0,0,0,0,0,0,0,0,0,0,0,0,0,0,0,0,0,0,0,0
0,0,0,0,0,0,0,0,0,0,0,0,0,0,0,0,0,0,0,0,0,0,0,0,0,0,0,0,0,0,0,0,0,0,0,0,0,0,0,0,0,0,0,0,0,0,0,0,0,0,0,0,0,0,0,0,0,0,0,0,0,0,0,0
0,0,0,0,0,0,0,0,0,0,0,0,0,0,0,0,0,0,0,0,0,0,0,0,0,0,0,0,0,0,0,0,0,0,0,0,0,0,0,0,0,0,0,0,0,0,0,0,0,0,0,0,0,0,0,0,0,0,0,0,0,0,0,0
0,0,0,0,0,0,0,0,0,0,0,0,0,0,0,0,0,0,0,0,0,0,0,0,0,0,0,0,0,0,0,0,0,0,0,0,0,0,0,0,0,0,0,0,0,0,0,0,0,0,0,0,0,0,0,0,0,0,0,0,0,0,0,0
:endlayer
layer: 13
0,0,0,0,0,0,0,0,0,0,0,0,0,0,0,0,0,0,0,0,0,0,0,0,0,0,0,0,0,0,0,0,0,0,0,0,0,0,0,0,0,0,0,0,0,0,0,0,0,0,0,0,0,0,0,0,0,0,0,0,0,0,0,0
0,0,0,0,0,0,0,0,0,0,0,0,0,0,0,0,0,0,0,0,0,0,0,0,0,0,0,0,0,0,0,0,0,0,0,0,0,0,0,0,0,0,0,0,0,0,0,0,0,0,0,0,0,0,0,0,0,0,0,0,0,0,0,0
0,0,0,0,0,0,0,0,0,0,0,0,0,0,0,0,0,0,0,0,0,0,0,0,0,0,0,0,0,0,0,0,0,0,0,0,0,0,0,0,0,0,0,0,0,0,0,0,0,0,0,0,0,0,0,0,0,0,0,0,0,0,0,0
0,0,0,0,0,0,0,0,0,0,0,0,0,0,0,0,0,0,0,0,0,0,0,0,0,0,0,0,0,0,0,0,0,0,0,0,0,0,0,0,0,0,0,0,0,0,0,0,0,0,0,0,0,0,0,0,0,0,0,0,0,0,0,0
0,0,0,0,0,0,0,0,0,0,0,0,0,0,0,0,0,0,0,0,0,0,0,0,0,0,0,0,0,0,0,0,0,0,0,0,0,0,0,0,0,0,0,0,0,0,0,0,0,0,0,0,0,0,0,0,0,0,0,0,0,0,0,0
0,0,0,0,0,0,0,0,0,0,0,0,0,0,0,0,0,0,0,0,0,0,0,0,0,0,0,0,0,0,0,0,0,0,0,0,0,0,0,0,0,0,0,0,0,0,0,0,0,0,0,0,0,0,0,0,0,0,0,0,0,0,0,0
0,0,0,0,0,0,0,256,256,256,256,256,256,256,256,256,256,256,256,256,256,256,256,0,0,0,0,0,0,0,0,0,0,0,0,0,0,0,256,256,256,256,256,256,256,256,256,256,256,256,256,256,256,256,256,256,256,0,0,0,0,0,0,0
0,0,0,0,0,0,0,0,8,0,0,0,32,0,0,0,0,0,0,0,0,8,0,0,0,0,0,0,0,0,0,0,0,0,0,0,0,0,0,8,0,0,0,0,0,0,0,0,32,0,0,0,0,0,0,8,0,0,0,0,0,0,0,0
0,0,0,0,0,0,0,0,8,0,0,0,0,0,0,0,0,0,0,0,0,249,0,0,0,0,0,0,0,0,0,0,0,0,0,0,0,0,0,249,0,0,0,0,0,0,0,0,0,0,0,0,0,0,0,249,0,0,0,0,0,0,0,0
0,0,0,0,0,0,0,0,8,0,0,0,0,0,0,0,0,0,0,0,0,8,0,0,0,0,0,0,0,0,0,0,0,0,0,0,0,0,0,8,0,0,0,0,0,0,0,0,0,0,0,0,0,0,0,8,0,0,0,0,0,0,0,0
0,0,0,0,0,0,0,0,8,0,0,0,0,0,0,0,0,0,0,0,0,8,0,0,0,0,0,0,0,0,0,0,0,0,0,0,0,0,0,8,0,0,0,0,0,0,0,0,0,0,0,0,0,0,0,8,0,0,0,0,0,0,0,0
0,0,0,0,0,0,0,0,8,0,0,0,0,0,0,0,0,0,0,0,0,249,0,0,0,0,0,0,0,0,0,0,0,0,0,0,0,0,0,249,0,0,0,0,0,0,0,0,0,0,0,0,0,0,0,249,0,0,0,0,0,0,0,0
0,0,0,0,0,0,0,0,8,0,0,0,37,0,0,0,0,0,0,0,0,8,0,0,0,0,0,0,0,0,0,0,0,0,0,0,0,0,0,8,0,0,0,0,0,0,0,0,37,0,0,0,0,0,0,8,0,0,0,0,0,0,0,0
0,0,0,0,0,0,0,24,24,24,24,24,24,24,24,24,24,24,24,24,24,24,24,0,0,0,0,0,0,0,0,0,0,0,0,0,0,0,24,24,24,24,24,24,24,24,24,24,24,24,24,24,24,24,24,24,24,0,0,0,0,0,0,0
0,0,0,0,0,0,0,0,0,0,0,0,0,0,0,0,0,0,0,0,0,0,0,0,0,0,0,0,0,0,0,0,0,0,0,0,0,0,0,0,0,0,0,0,0,0,0,0,0,0,0,0,0,0,0,0,0,0,0,0,0,0,0,0
0,0,0,0,0,0,0,0,0,0,0,0,0,0,0,0,0,0,0,0,0,0,0,0,0,0,0,0,0,0,0,0,0,0,0,0,0,0,0,0,0,0,0,0,0,0,0,0,0,0,0,0,0,0,0,0,0,0,0,0,0,0,0,0
0,0,0,0,0,0,0,0,0,0,0,0,0,0,0,0,0,0,0,0,0,0,0,0,0,0,0,0,0,0,0,0,0,0,0,0,0,0,0,0,0,0,0,0,0,0,0,0,0,0,0,0,0,0,0,0,0,0,0,0,0,0,0,0
0,0,0,0,0,0,0,0,0,0,0,0,0,0,0,0,0,0,0,0,0,0,0,0,0,0,0,0,0,0,0,0,0,0,0,0,0,0,0,0,0,0,0,0,0,0,0,0,0,0,0,0,0,0,0,0,0,0,0,0,0,0,0,0
0,0,0,0,0,0,0,0,0,229,256,256,256,256,256,256,256,256,256,256,256,229,0,0,0,0,0,0,0,0,0,0,0,0,0,0,0,0,0,229,256,256,256,256,256,256,256,256,256,256,256,229,0,0,0,0,0,0,0,0,0,0,0,0
0,0,0,0,0,0,0,0,0,229,24,24,24,24,24,24,24,24,24,24,24,229,0,0,0,0,0,0,0,0,0,0,0,0,0,0,0,0,0,229,24,24,24,24,24,24,24,24,24,24,24,229,0,0,0,0,0,0,0,0,0,0,0,0
0,0,0,0,0,0,0,0,0,0,0,0,0,0,0,0,0,0,0,0,0,0,0,0,0,0,0,0,0,0,0,0,0,0,0,0,0,0,0,0,0,0,0,0,0,0,0,0,0,0,0,0,0,0,0,0,0,0,0,0,0,0,0,0
0,0,0,0,0,0,0,0,0,0,0,0,0,0,0,0,0,0,0,0,0,0,0,0,0,0,0,0,0,0,0,0,0,0,0,0,0,0,0,0,0,0,0,0,0,0,0,0,0,0,0,0,0,0,0,0,0,0,0,0,0,0,0,0
0,0,0,0,0,0,0,0,0,0,0,0,0,0,0,0,0,0,0,0,0,0,0,0,0,0,0,0,0,0,0,0,0,0,0,0,0,0,0,0,0,0,0,0,0,0,0,0,0,0,0,0,0,0,0,0,0,0,0,0,0,0,0,0
0,0,0,0,0,0,0,0,0,0,0,0,0,0,0,0,0,0,0,0,0,0,0,0,0,0,0,0,0,0,0,0,0,0,0,0,0,0,0,0,0,0,0,0,0,0,0,0,0,0,0,0,0,0,0,0,0,0,0,0,0,0,0,0
0,0,0,0,0,0,0,0,2,2,2,2,2,2,2,2,2,2,2,2,2,2,2,2,2,2,2,2,2,2,2,2,2,2,2,2,2,2,2,2,2,2,2,2,2,2,2,2,2,2,2,2,2,2,2,0,0,0,0,0,0,0,0,0
0,0,0,0,0,0,0,0,2,0,0,0,0,0,0,0,0,0,0,0,0,0,0,0,0,0,0,0,0,0,0,0,0,0,0,0,0,0,0,0,0,0,0,0,0,0,0,0,0,0,0,0,0,0,2,0,0,0,0,0,0,0,0,0
0,0,0,0,0,0,0,0,2,0,0,0,0,0,0,0,0,0,0,0,0,0,0,0,0,0,0,0,0,0,0,0,0,0,0,0,0,0,0,0,0,0,0,0,0,0,0,0,0,0,0,0,0,0,2,0,0,0,0,0,0,0,0,0
0,0,0,0,0,0,0,0,2,0,0,0,0,0,0,0,0,0,0,0,0,0,0,0,0,0,0,0,0,0,0,0,0,0,0,0,0,0,0,0,0,0,0,0,0,0,0,0,0,0,0,2,0,0,2,0,0,0,0,0,0,0,0,0
0,0,0,0,0,0,0,0,2,0,0,0,0,0,0,0,0,0,0,0,0,0,0,0,0,0,0,0,0,0,0,0,0,0,0,0,0,0,0,0,0,0,0,0,0,0,0,0,0,0,0,2,0,0,0,0,0,0,0,0,0,0,0,0
0,0,0,0,0,2,0,0,2,0,0,0,0,0,0,0,0,0,256,256,0,0,0,0,0,256,256,256,0,0,0,0,0,0,0,0,0,0,0,0,8,0,8,0,0,35,0,0,0,0,0,2,0,0,0,0,0,0,0,0,0,0,0,0
0,0,0,0,0,2,0,0,0,0,0,0,0,0,30,0,30,18,4,4,22,2,30,2,18,4,4,4,22,0,18,8,0,8,22,0,10,14,2,2,2,20,2,2,2,10,311,0,0,0,0,2,0,0,0,0,0,0,0,0,0,0,0,0
0,0,0,0,0,2,0,0,0,0,0,0,0,0,2,30,2,10,8,8,8,2,8,2,10,8,8,8,10,8,8,8,34,8,8,10,0,0,0,0,0,0,0,0,0,312,311,0,0,0,0,2,0,0,0,0,0,0,0,0,0,0,0,0
0,0,0,0,0,2,0,0,0,0,0,0,0,0,2,0,0,8,0,0,0,0,8,8,0,0,0,0,0,0,0,0,0,0,0,8,0,0,0,0,0,0,0,0,0,312,311,0,0,0,0,2,0,0,0,0,0,0,0,0,0,0,0,0
0,0,0,0,0,2,0,0,10,183,183,183,183,183,8,8,8,8,0,71,71,8,24,8,0,0,0,0,0,0,0,0,0,0,0,8,0,71,0,0,0,0,0,0,8,10,311,0,0,0,0,2,0,0,0,0,0,0,0,0,0,0,0,0
0,0,0,0,0,2,0,0,2,0,0,0,0,0,0,0,0,8,0,0,0,0,0,8,256,0,0,0,0,0,0,0,0,0,0,8,0,71,0,0,0,0,0,0,8,312,2,2,0,0,2,2,0,0,0,0,0,0,0,0,0,0,0,0
0,0,0,0,0,2,0,0,2,0,0,0,0,0,0,0,0,8,0,0,0,0,0,8,8,0,0,0,0,0,0,0,0,0,0,8,0,71,0,0,0,0,0,0,8,10,4,2,0,0,2,2,0,0,0,0,0,0,0,0,0,0,0,0
0,0,0,0,0,2,0,0,2,8,0,0,0,0,0,0,0,8,0,0,0,0,0,8,8,0,0,0,0,0,0,0,0,0,0,8,71,71,0,0,0,0,0,0,8,8,4,2,0,0,2,2,0,0,0,0,0,0,0,0,0,0,0,0
0,0,0,0,0,2,0,0,2,24,0,0,0,0,0,0,0,8,256,0,0,0,0,8,8,0,0,0,0,0,0,0,0,0,0,8,0,0,0,0,0,0,0,0,24,8,4,2,0,0,2,2,0,0,0,0,0,0,0,0,0,0,0,0
0,0,0,0,0,2,0,0,2,0,0,0,0,0,0,0,0,8,8,0,0,0,0,8,0,0,0,0,0,0,0,0,0,0,0,8,0,0,0,0,0,0,0,0,0,8,4,2,0,0,2,2,0,0,0,0,0,0,0,0,0,0,0,0
0,0,0,0,0,2,0,0,2,0,0,0,0,0,0,0,0,8,8,8,0,0,0,8,0,0,0,0,0,0,0,0,0,0,0,8,10,8,8,8,8,8,8,8,8,10,2,2,2,2,2,2,0,0,0,0,0,0,0,0,0,0,0,0
0,0,0,0,33,2,2,2,2,0,0,0,0,0,0,0,8,10,8,8,8,8,8,8,8,8,8,8,8,8,8,8,8,8,8,10,0,0,256,256,0,0,256,256,0,0,0,0,0,0,0,0,0,0,0,0,0,0,0,0,0,0,0,0
0,0,0,0,0,32,0,0,2,8,0,37,0,0,37,0,2,24,24,24,24,24,24,24,24,24,24,24,24,24,24,24,24,24,24,24,0,0,0,0,0,0,0,0,0,0,0,0,0,0,0,0,0,0,0,0,0,0,0,0,0,0,0,0
0,0,0,0,0,0,0,0,10,2,14,2,2,2,2,2,10,0,0,0,0,0,0,0,0,0,0,0,0,0,0,0,0,0,0,0,0,0,0,0,0,0,0,0,0,0,0,0,0,0,0,0,0,0,0,0,0,0,0,0,0,0,0,0
0,0,0,0,0,0,0,0,0,0,0,0,0,0,0,0,0,0,0,0,0,0,0,0,0,0,0,0,0,0,0,0,0,0,0,0,0,0,0,0,0,0,0,0,0,0,0,0,0,0,0,0,0,0,0,0,0,0,0,0,0,0,0,0
0,0,0,0,0,0,0,0,0,0,0,0,0,0,0,0,0,0,0,0,0,0,0,0,0,0,0,0,0,0,0,0,0,0,0,0,0,0,0,0,0,0,0,0,0,0,0,0,0,0,0,0,0,0,0,0,0,0,0,0,0,0,0,0
0,0,0,0,0,0,0,0,0,0,0,0,0,0,0,0,0,0,0,0,0,0,0,0,0,0,0,0,0,0,0,0,0,0,0,0,0,0,0,0,0,0,0,0,0,0,0,0,0,0,0,0,0,0,0,0,0,0,0,0,0,0,0,0
0,0,0,0,0,0,0,0,0,0,0,0,0,0,0,0,0,0,0,0,0,0,0,0,0,0,0,0,0,0,0,0,0,0,0,0,0,0,0,0,0,0,0,0,0,0,0,0,0,0,0,0,0,0,0,0,0,0,0,0,0,0,0,0
:endlayer
layer: 14
0,0,0,0,0,0,0,0,0,0,0,0,0,0,0,0,0,0,0,0,0,0,0,0,0,0,0,0,0,0,0,0,0,0,0,0,0,0,0,0,0,0,0,0,0,0,0,0,0,0,0,0,0,0,0,0,0,0,0,0,0,0,0,0
0,0,0,0,0,0,0,0,0,0,0,0,0,0,0,0,0,0,0,0,0,0,0,0,0,0,0,0,0,0,0,0,0,0,0,0,0,0,0,0,0,0,0,0,0,0,0,0,0,0,0,0,0,0,0,0,0,0,0,0,0,0,0,0
0,0,0,0,0,0,0,0,0,0,0,0,0,0,0,0,0,0,0,0,0,0,0,0,0,0,0,0,0,0,0,0,0,0,0,0,0,0,0,0,0,0,0,0,0,0,0,0,0,0,0,0,0,0,0,0,0,0,0,0,0,0,0,0
0,0,0,0,0,0,0,0,0,0,0,0,0,0,0,0,0,0,0,0,0,0,0,0,0,0,0,0,0,0,0,0,0,0,0,0,0,0,0,0,0,0,0,0,0,0,0,0,0,0,0,0,0,0,0,0,0,0,0,0,0,0,0,0
0,0,0,0,0,0,0,0,0,0,0,0,0,0,0,0,0,0,0,0,0,0,0,0,0,0,0,0,0,0,0,0,0,0,0,0,0,0,0,0,0,0,0,0,0,0,0,0,0,0,0,0,0,0,0,0,0,0,0,0,0,0,0,0
0,0,0,0,0,0,0,0,0,0,0,0,0,0,0,0,0,0,0,0,0,0,0,0,0,0,0,0,0,0,0,0,0,0,0,0,0,0,0,0,0,0,0,0,0,0,0,0,0,0,0,0,0,0,0,0,0,0,0,0,0,0,0,0
0,0,0,0,0,0,0,0,0,0,0,0,0,0,0,0,0,0,0,0,0,0,0,0,0,0,0,0,0,0,0,0,0,0,0,0,0,0,0,0,0,0,0,0,0,0,0,0,0,0,0,0,0,0,0,0,0,0,0,0,0,0,0,0
0,0,0,0,0,0,0,256,256,256,256,256,256,256,256,256,256,256,256,256,256,256,256,0,0,0,0,0,0,0,0,0,0,0,0,0,0,0,256,256,256,256,256,256,256,256,256,256,256,256,256,256,256,256,256,256,256,0,0,0,0,0,0,0
0,0,0,0,0,0,0,0,8,0,0,0,0,0,0,0,0,0,0,0,33,8,60,0,0,0,0,0,0,0,0,0,0,0,0,0,0,0,33,8,60,0,0,0,0,0,0,0,0,0,0,0,0,0,33,8,60,0,0,0,0,0,0,0
0,0,0,0,0,0,0,0,8,0,0,0,0,0,0,0,0,0,0,0,0,8,0,0,0,0,0,0,0,0,0,0,0,0,0,0,0,0,0,8,0,0,0,0,0,0,0,0,0,0,0,0,0,0,0,8,0,0,0,0,0,0,0,0
0,0,0,0,0,0,0,0,8,0,0,0,0,0,0,0,0,0,0,0,0,8,0,0,0,0,0,0,0,0,0,0,0,0,0,0,0,0,0,8,0,0,0,0,0,0,0,0,0,0,0,0,0,0,0,8,0,0,0,0,0,0,0,0
0,0,0,0,0,0,0,0,8,0,0,0,0,0,0,0,0,0,0,0,33,8,60,0,0,0,0,0,0,0,0,0,0,0,0,0,0,0,33,8,60,0,0,0,0,0,0,0,0,0,0,0,0,0,33,8,60,0,0,0,0,0,0,0
0,0,0,0,0,0,0,24,24,24,24,24,24,24,24,24,24,24,24,24,24,24,24,0,0,0,0,0,0,0,0,0,0,0,0,0,0,0,24,24,24,24,24,24,24,24,24,24,24,24,24,24,24,24,24,24,24,0,0,0,0,0,0,0
0,0,0,0,0,0,0,0,0,0,0,0,0,0,0,0,0,0,0,0,0,0,0,0,0,0,0,0,0,0,0,0,0,0,0,0,0,0,0,0,0,0,0,0,0,0,0,0,0,0,0,0,0,0,0,0,0,0,0,0,0,0,0,0
0,0,0,0,0,0,0,0,0,0,0,0,0,0,0,0,0,0,0,0,0,0,0,0,0,0,0,0,0,0,0,0,0,0,0,0,0,0,0,0,0,0,0,0,0,0,0,0,0,0,0,0,0,0,0,0,0,0,0,0,0,0,0,0
0,0,0,0,0,0,0,0,0,0,0,0,0,0,0,0,0,0,0,0,0,0,0,0,0,0,0,0,0,0,0,0,0,0,0,0,0,0,0,0,0,0,0,0,0,0,0,0,0,0,0,0,0,0,0,0,0,0,0,0,0,0,0,0
0,0,0,0,0,0,0,0,0,0,0,0,0,0,0,0,0,0,0,0,0,0,0,0,0,0,0,0,0,0,0,0,0,0,0,0,0,0,0,0,0,0,0,0,0,0,0,0,0,0,0,0,0,0,0,0,0,0,0,0,0,0,0,0
0,0,0,0,0,0,0,0,0,0,0,0,0,0,0,0,0,0,0,0,0,0,0,0,0,0,0,0,0,0,0,0,0,0,0,0,0,0,0,0,0,0,0,0,0,0,0,0,0,0,0,0,0,0,0,0,0,0,0,0,0,0,0,0
0,0,0,0,0,0,0,0,0,0,0,0,0,0,0,0,0,0,0,0,0,0,0,0,0,0,0,0,0,0,0,0,0,0,0,0,0,0,0,0,0,0,0,0,0,0,0,0,0,0,0,0,0,0,0,0,0,0,0,0,0,0,0,0
0,0,0,0,0,0,0,0,0,0,0,0,0,0,0,0,0,0,0,0,0,0,0,0,0,0,0,0,0,0,0,0,0,0,0,0,0,0,0,0,0,0,0,0,0,0,0,0,0,0,0,0,0,0,0,0,0,0,0,0,0,0,0,0
0,0,0,0,0,0,0,0,0,0,0,0,0,0,0,0,0,0,0,0,0,0,0,0,0,0,0,0,0,0,0,0,0,0,0,0,0,0,0,0,0,0,0,0,0,0,0,0,0,0,0,0,0,0,0,0,0,0,0,0,0,0,0,0
0,0,0,0,0,0,0,0,0,0,0,0,0,0,0,0,0,0,0,0,0,0,0,0,0,0,0,0,0,0,0,0,0,0,0,0,0,0,0,0,0,0,0,0,0,0,0,0,0,0,0,0,0,0,0,0,0,0,0,0,0,0,0,0
0,0,0,0,0,0,0,0,0,0,0,0,0,0,0,0,0,0,0,0,0,0,0,0,0,0,0,0,0,0,0,0,0,0,0,0,0,0,0,0,0,0,0,0,0,0,0,0,0,0,0,0,0,0,0,0,0,0,0,0,0,0,0,0
0,0,0,0,0,0,0,0,0,0,0,0,0,0,0,0,0,0,0,0,0,0,0,0,0,0,0,0,0,0,0,0,0,0,0,0,0,0,0,0,0,0,0,0,0,0,0,0,0,0,0,0,0,0,0,0,0,0,0,0,0,0,0,0
0,0,0,0,0,0,0,0,246,247,0,247,246,247,0,247,246,247,0,247,246,247,0,247,246,247,0,247,246,247,0,247,246,247,0,247,246,247,0,247,246,247,0,247,246,247,0,247,246,247,0,247,246,247,0,0,0,0,0,0,0,0,0,0
0,0,0,0,0,0,0,0,247,0,0,0,0,0,0,0,0,0,0,0,0,0,0,0,0,0,0,0,0,0,0,0,0,0,0,0,0,0,0,0,0,0,0,0,0,0,0,0,0,0,0,0,0,0,0,0,0,0,0,0,0,0,0,0
0,0,0,0,0,0,0,0,0,0,0,0,0,0,0,0,0,0,0,0,0,0,0,0,0,0,0,0,0,0,0,0,0,0,0,0,0,0,0,0,0,0,0,0,0,0,0,0,0,0,0,0,0,0,247,0,0,0,0,0,0,0,0,0
0,0,0,0,0,0,0,0,247,0,0,0,0,0,0,0,0,0,0,0,0,0,0,0,0,0,0,0,0,0,0,0,0,0,0,0,0,0,0,0,0,0,0,0,0,0,0,0,0,0,0,246,0,0,246,0,0,0,0,0,0,0,0,0
0,0,0,0,0,0,0,0,246,0,0,0,0,0,0,0,0,0,0,0,0,0,0,0,0,0,0,0,0,0,0,0,0,0,0,0,0,0,0,0,0,0,0,0,0,0,0,0,0,0,0,247,0,0,0,0,0,0,0,0,0,0,0,0
0,0,0,0,0,247,0,0,247,0,0,0,0,0,0,0,0,0,0,0,0,0,0,0,0,0,0,0,0,0,0,0,0,0,0,0,0,0,0,0,18,0,22,0,0,0,0,0,0,0,0,0,0,0,0,0,0,0,0,0,0,0,0,0
0,0,0,0,0,0,0,0,0,0,0,0,0,0,0,0,0,35,29,315,0,71,0,71,0,315,29,315,0,0,0,8,0,8,0,0,10,14,14,2,2,313,2,2,2,10,311,0,0,0,0,247,0,0,0,0,0,0,0,0,0,0,0,0
0,0,0,0,0,247,0,0,0,0,0,0,0,0,7,0,9,10,2,14,14,2,316,2,10,2,14,2,10,2,2,2,314,2,2,10,0,0,0,0,0,0,0,0,0,2,311,0,0,0,0,246,0,0,0,0,0,0,0,0,0,0,0,0
0,0,0,0,0,246,0,0,0,0,0,0,0,0,2,30,2,8,0,0,0,8,0,8,0,0,0,0,0,0,0,0,0,0,0,8,0,0,0,0,0,0,0,0,0,14,311,0,0,0,0,247,0,0,0,0,0,0,0,0,0,0,0,0
0,0,0,0,0,247,0,0,10,2,14,2,2,2,2,2,8,8,0,0,0,71,0,8,0,0,0,0,0,0,0,0,0,0,0,8,0,48,0,0,0,0,0,0,8,10,311,0,0,0,0,0,0,0,0,0,0,0,0,0,0,0,0,0
0,0,0,0,0,0,0,0,2,8,8,8,8,8,8,8,8,8,0,0,0,0,0,8,0,0,0,0,0,0,0,0,0,0,0,8,0,0,0,0,0,0,0,0,8,2,311,0,0,0,0,247,0,0,0,0,0,0,0,0,0,0,0,0
0,0,0,0,0,247,0,0,2,8,8,8,8,8,8,8,8,8,0,0,0,0,0,8,256,0,0,0,0,0,0,0,0,0,0,8,0,0,0,0,0,0,0,0,8,2,311,71,0,0,71,246,0,0,0,0,0,0,0,0,0,0,0,0
0,0,0,0,0,246,0,0,2,24,8,292,292,292,292,8,8,8,0,0,0,0,0,8,8,0,0,0,0,0,0,0,0,0,0,8,0,0,0,0,0,0,0,0,24,10,311,71,0,0,71,247,0,0,0,0,0,0,0,0,0,0,0,0
0,0,0,0,0,247,0,0,2,0,8,292,292,292,292,8,8,8,0,0,0,0,0,8,8,0,0,0,0,0,0,0,0,0,0,8,0,0,0,0,0,0,0,0,0,2,6,71,0,0,71,0,0,0,0,0,0,0,0,0,0,0,0,0
0,0,0,0,0,0,0,0,2,0,8,292,292,292,292,8,8,8,256,0,0,0,0,8,0,0,0,0,0,0,0,0,0,0,0,8,0,0,0,0,0,0,0,0,0,2,0,71,0,0,71,247,0,0,0,0,0,0,0,0,0,0,0,0
0,0,0,0,0,247,0,0,2,0,8,292,292,292,292,8,8,8,8,8,0,0,0,8,0,0,0,0,0,0,0,0,0,0,0,8,10,2,202,202,2,2,202,202,2,10,71,9,0,0,7,246,0,0,0,0,0,0,0,0,0,0,0,0
0,0,0,0,0,246,247,0,2,0,8,8,8,8,8,8,8,10,183,183,183,183,183,183,183,183,183,183,183,183,183,183,183,183,183,10,0,8,229,229,8,8,229,229,8,0,0,0,0,0,0,0,0,0,0,0,0,0,0,0,0,0,0,0
0,0,0,0,0,0,0,0,2,8,8,8,8,8,8,8,2,0,0,0,0,0,0,0,0,0,0,0,0,0,0,0,0,0,0,0,0,0,0,0,0,0,0,0,0,0,0,0,0,0,0,0,0,0,0,0,0,0,0,0,0,0,0,0
0,0,0,0,0,0,0,0,10,2,2,2,2,2,2,2,10,0,0,0,0,0,0,0,0,0,0,0,0,0,0,0,0,0,0,0,0,0,0,0,0,0,0,0,0,0,0,0,0,0,0,0,0,0,0,0,0,0,0,0,0,0,0,0
0,0,0,0,0,0,0,0,0,0,0,0,0,0,0,0,0,0,0,0,0,0,0,0,0,0,0,0,0,0,0,0,0,0,0,0,0,0,0,0,0,0,0,0,0,0,0,0,0,0,0,0,0,0,0,0,0,0,0,0,0,0,0,0
0,0,0,0,0,0,0,0,0,0,0,0,0,0,0,0,0,0,0,0,0,0,0,0,0,0,0,0,0,0,0,0,0,0,0,0,0,0,0,0,0,0,0,0,0,0,0,0,0,0,0,0,0,0,0,0,0,0,0,0,0,0,0,0
0,0,0,0,0,0,0,0,0,0,0,0,0,0,0,0,0,0,0,0,0,0,0,0,0,0,0,0,0,0,0,0,0,0,0,0,0,0,0,0,0,0,0,0,0,0,0,0,0,0,0,0,0,0,0,0,0,0,0,0,0,0,0,0
0,0,0,0,0,0,0,0,0,0,0,0,0,0,0,0,0,0,0,0,0,0,0,0,0,0,0,0,0,0,0,0,0,0,0,0,0,0,0,0,0,0,0,0,0,0,0,0,0,0,0,0,0,0,0,0,0,0,0,0,0,0,0,0
:endlayer
layer: 15
0,0,0,0,0,0,0,0,0,0,0,0,0,0,0,0,0,0,0,0,0,0,0,0,0,0,0,0,0,0,0,0,0,0,0,0,0,0,0,0,0,0,0,0,0,0,0,0,0,0,0,0,0,0,0,0,0,0,0,0,0,0,0,0
0,0,0,0,0,0,0,0,0,0,0,0,0,0,0,0,0,0,0,0,0,0,0,0,0,0,0,0,0,0,0,0,0,0,0,0,0,0,0,0,0,0,0,0,0,0,0,0,0,0,0,0,0,0,0,0,0,0,0,0,0,0,0,0
0,0,0,0,0,0,0,0,0,0,0,0,0,0,0,0,0,0,0,0,0,0,0,0,0,0,0,0,0,0,0,0,0,0,0,0,0,0,0,0,0,0,0,0,0,0,0,0,0,0,0,0,0,0,0,0,0,0,0,0,0,0,0,0
0,0,0,0,0,0,0,0,0,0,0,0,0,0,0,0,0,0,0,0,0,0,0,0,0,0,0,0,0,0,0,0,0,0,0,0,0,0,0,0,0,0,0,0,0,0,0,0,0,0,0,0,0,0,0,0,0,0,0,0,0,0,0,0
0,0,0,0,0,0,0,0,0,0,0,0,0,0,0,0,0,0,0,0,0,0,0,0,0,0,0,0,0,0,0,0,0,0,0,0,0,0,0,0,0,0,0,0,0,0,0,0,0,0,0,0,0,0,0,0,0,0,0,0,0,0,0,0
0,0,0,0,0,0,0,0,0,0,0,0,0,0,0,0,0,0,0,0,0,0,0,0,0,0,0,0,0,0,0,0,0,0,0,0,0,0,0,0,0,0,0,0,0,0,0,0,0,0,0,0,0,0,0,0,0,0,0,0,0,0,0,0
0,0,0,0,0,0,0,0,0,0,0,0,0,0,0,0,0,0,0,0,0,0,0,0,0,0,0,0,0,0,0,0,0,0,0,0,0,0,0,0,0,0,0,0,0,0,0,0,0,0,0,0,0,0,0,0,0,0,0,0,0,0,0,0
0,0,0,0,0,0,0,0,0,0,0,0,0,0,0,0,0,0,0,0,0,0,0,0,0,0,0,0,0,0,0,0,0,0,0,0,0,0,0,0,0,0,0,0,0,0,0,0,0,0,0,0,0,0,0,0,0,0,0,0,0,0,0,0
0,0,0,0,0,0,0,256,256,256,256,256,256,256,256,256,256,256,256,256,256,256,256,0,0,0,0,0,0,0,0,0,0,0,0,0,0,0,256,256,256,256,256,256,256,256,256,256,256,256,256,256,256,256,256,256,256,0,0,0,0,0,0,0
0,0,0,0,0,0,0,0,8,0,0,0,0,0,0,0,0,0,0,0,0,8,0,0,0,0,0,0,0,0,0,0,0,0,0,0,0,0,0,8,0,0,0,0,0,0,0,0,0,0,0,0,0,0,0,8,0,0,0,0,0,0,0,0
0,0,0,0,0,0,0,0,8,0,0,0,0,0,0,0,0,0,0,0,0,8,0,0,0,0,0,0,0,0,0,0,0,0,0,0,0,0,0,8,0,0,0,0,0,0,0,0,0,0,0,0,0,0,0,8,0,0,0,0,0,0,0,0
0,0,0,0,0,0,0,24,24,24,24,24,24,24,24,24,24,24,24,24,24,24,24,0,0,0,0,0,0,0,0,0,0,0,0,0,0,0,24,24,24,24,24,24,24,24,24,24,24,24,24,24,24,24,24,24,24,0,0,0,0,0,0,0
0,0,0,0,0,0,0,0,0,0,0,0,0,0,0,0,0,0,0,0,0,0,0,0,0,0,0,0,0,0,0,0,0,0,0,0,0,0,0,0,0,0,0,0,0,0,0,0,0,0,0,0,0,0,0,0,0,0,0,0,0,0,0,0
0,0,0,0,0,0,0,0,0,0,0,0,0,0,0,0,0,0,0,0,0,0,0,0,0,0,0,0,0,0,0,0,0,0,0,0,0,0,0,0,0,0,0,0,0,0,0,0,0,0,0,0,0,0,0,0,0,0,0,0,0,0,0,0
0,0,0,0,0,0,0,0,0,0,0,0,0,0,0,0,0,0,0,0,0,0,0,0,0,0,0,0,0,0,0,0,0,0,0,0,0,0,0,0,0,0,0,0,0,0,0,0,0,0,0,0,0,0,0,0,0,0,0,0,0,0,0,0
0,0,0,0,0,0,0,0,0,0,0,0,0,0,0,0,0,0,0,0,0,0,0,0,0,0,0,0,0,0,0,0,0,0,0,0,0,0,0,0,0,0,0,0,0,0,0,0,0,0,0,0,0,0,0,0,0,0,0,0,0,0,0,0
0,0,0,0,0,0,0,0,0,0,0,0,0,0,0,0,0,0,0,0,0,0,0,0,0,0,0,0,0,0,0,0,0,0,0,0,0,0,0,0,0,0,0,0,0,0,0,0,0,0,0,0,0,0,0,0,0,0,0,0,0,0,0,0
0,0,0,0,0,0,0,0,0,0,0,0,0,0,0,0,0,0,0,0,0,0,0,0,0,0,0,0,0,0,0,0,0,0,0,0,0,0,0,0,0,0,0,0,0,0,0,0,0,0,0,0,0,0,0,0,0,0,0,0,0,0,0,0
0,0,0,0,0,0,0,0,0,0,0,0,0,0,0,0,0,0,0,0,0,0,0,0,0,0,0,0,0,0,0,0,0,0,0,0,0,0,0,0,0,0,0,0,0,0,0,0,0,0,0,0,0,0,0,0,0,0,0,0,0,0,0,0
0,0,0,0,0,0,0,0,0,0,0,0,0,0,0,0,0,0,0,0,0,0,0,0,0,0,0,0,0,0,0,0,0,0,0,0,0,0,0,0,0,0,0,0,0,0,0,0,0,0,0,0,0,0,0,0,0,0,0,0,0,0,0,0
0,0,0,0,0,0,0,0,0,0,0,0,0,0,0,0,0,0,0,0,0,0,0,0,0,0,0,0,0,0,0,0,0,0,0,0,0,0,0,0,0,0,0,0,0,0,0,0,0,0,0,0,0,0,0,0,0,0,0,0,0,0,0,0
0,0,0,0,0,0,0,0,0,0,0,0,0,0,0,0,0,0,0,0,0,0,0,0,0,0,0,0,0,0,0,0,0,0,0,0,0,0,0,0,0,0,0,0,0,0,0,0,0,0,0,0,0,0,0,0,0,0,0,0,0,0,0,0
0,0,0,0,0,0,0,0,0,0,0,0,0,0,0,0,0,0,0,0,0,0,0,0,0,0,0,0,0,0,0,0,0,0,0,0,0,0,0,0,0,0,0,0,0,0,0,0,0,0,0,0,0,0,0,0,0,0,0,0,0,0,0,0
0,0,0,0,0,0,0,0,0,0,0,0,0,0,0,0,0,0,0,0,0,0,0,0,0,0,0,0,0,0,0,0,0,0,0,0,0,0,0,0,0,0,0,0,0,0,0,0,0,0,0,0,0,0,0,0,0,0,0,0,0,0,0,0
0,0,0,0,0,0,0,0,48,0,0,0,0,0,0,0,48,0,0,0,0,0,0,0,48,0,0,0,0,0,0,0,48,0,0,0,0,0,0,0,48,0,0,0,0,0,0,0,48,0,0,0,48,0,0,0,0,0,0,0,0,0,0,0
0,0,0,0,0,0,0,0,0,0,0,0,0,0,0,0,0,0,0,0,0,0,0,0,0,0,0,0,0,0,0,0,0,0,0,0,0,0,0,0,0,0,0,0,0,0,0,0,0,0,0,0,0,0,0,0,0,0,0,0,0,0,0,0
0,0,0,0,0,0,0,0,0,0,0,0,0,0,0,0,0,0,0,0,0,0,0,0,0,0,0,0,0,0,0,0,0,0,0,0,0,0,0,0,0,0,0,0,0,0,0,0,0,0,0,0,0,0,0,0,0,0,0,0,0,0,0,0
0,0,0,0,0,0,0,0,0,0,0,0,0,0,0,0,0,0,0,0,0,0,0,0,0,0,0,0,0,0,0,0,0,0,0,0,0,0,0,0,0,0,0,0,0,0,0,0,0,0,0,48,0,0,48,0,0,0,0,0,0,0,0,0
0,0,0,0,0,0,0,0,48,0,0,0,0,0,0,0,0,0,0,0,0,0,0,0,0,0,0,0,0,0,0,0,0,0,0,0,0,0,0,0,0,0,0,0,0,0,0,0,0,0,0,0,0,0,0,0,0,0,0,0,0,0,0,0
0,0,0,0,0,0,0,0,0,0,0,0,0,0,0,0,0,0,0,0,0,0,0,0,0,0,0,0,0,0,0,0,0,0,0,0,0,0,0,0,0,256,0,0,0,0,0,0,0,0,0,0,0,0,0,0,0,0,0,0,0,0,0,0
0,0,0,0,0,0,0,0,0,0,0,0,0,0,0,0,0,35,35,0,0,71,0,71,0,0,0,0,0,0,0,18,8,22,0,0,10,2,2,2,2,2,2,2,2,10,311,0,0,0,0,0,0,0,0,0,0,0,0,0,0,0,0,0
0,0,0,0,0,0,0,0,0,0,0,0,0,0,0,0,15,10,2,202,2,2,317,2,10,2,202,2,10,2,2,14,2,2,2,10,0,0,0,0,0,0,0,0,0,2,311,0,0,0,0,48,0,0,0,0,0,0,0,0,0,0,0,0
0,0,0,0,0,48,0,0,0,0,0,0,0,0,0,0,0,2,0,0,0,8,0,8,0,0,0,0,0,0,0,32,0,0,0,8,0,0,0,0,0,0,0,0,0,2,311,0,0,0,0,0,0,0,0,0,0,0,0,0,0,0,0,0
0,0,0,0,0,0,0,0,10,2,2,2,2,2,10,20,10,8,0,0,0,0,0,8,0,0,0,0,0,0,0,0,0,0,0,8,0,0,0,0,0,0,0,0,8,10,311,0,0,0,0,0,0,0,0,0,0,0,0,0,0,0,0,0
0,0,0,0,0,0,0,0,2,0,0,0,0,0,0,0,0,8,0,0,0,0,0,8,0,0,0,0,0,0,0,0,0,0,0,8,0,0,0,0,0,0,0,0,8,2,311,0,0,0,0,0,0,0,0,0,0,0,0,0,0,0,0,0
0,0,0,0,0,0,0,0,2,0,0,0,0,0,0,0,0,8,60,0,0,0,0,8,0,0,0,0,0,0,0,0,0,0,0,8,0,0,0,0,0,0,0,0,24,14,311,0,0,0,0,48,0,0,0,0,0,0,0,0,0,0,0,0
0,0,0,0,0,48,0,0,2,0,71,0,0,0,0,0,0,8,0,0,0,0,33,8,256,0,0,0,0,0,0,0,0,0,0,8,0,0,0,0,0,0,0,0,0,10,311,0,0,0,0,0,0,0,0,0,0,0,0,0,0,0,0,0
0,0,0,0,0,0,0,0,2,0,71,0,0,0,0,0,0,8,0,0,0,0,0,8,8,0,0,0,0,0,0,0,0,0,0,8,0,0,0,0,0,0,0,0,0,2,311,0,0,0,0,0,0,0,0,0,0,0,0,0,0,0,0,0
