# Ancient Warfare Structure Template File
# auto-generated structure file. created on: 3/23/2014 at: 12:15:2
# Lines beginning with # denote comments

header:
version=2.0
name=CIVResourcesOpencastMineAbandonedMOH
size=51,84,51
offset=24,68,50
:endheader

#### VALIDATION ####
validation:
type=ground
survival=false
worldGenEnabled=true
unique=true
preserveBlocks=false
selectionWeight=50
clusterValue=501
minDuplicateDistance=400
dimensionWhiteList=false
dimensionList=
biomeWhiteList=true
biomeList=highlands_lowlands,highlands_woodlands,moor,heathland,dead forest,woodland,forest,birch forest
leveling=42
fill=8
border=8
validTargetBlocks=bedrock,clay,lapis_ore,lit_redstone_ore,stone,carpet,tile.bop.mud,gravel,coal_block,diamond_ore,tile.bop.generic.crag_rock,ice,snow,netherrack,tile.bop.generic.hard_dirt,tile.bop.redRocks,dirt,redstone_ore,mycelium,tile.bop.holyStone,bedrock,sand,grass,tile.bop.ash,tile.MoCDirt,iron_ore,tile.bop.originGrass,snow_layer,soul_sand,tile.bop.generic.dried_dirt,stained_hardened_clay,tile.bop.generic.ash_stone,tile.bop.generic.hard_ice,coal_ore,gold_ore,tile.bop.generic.hard_sand
data:
:enddata
:endvalidation

#### LAYERS ####
layer: 0
1,1,1,1,1,1,1,1,1,1,1,1,1,1,1,1,1,1,1,1,1,1,1,1,1,1,1,1,1,1,1,1,1,1,1,1,1,1,1,1,1,1,1,1,1,1,1,1,1,1,1
1,1,1,1,1,1,1,1,1,1,1,1,1,1,1,1,1,1,1,1,1,1,1,1,1,1,1,1,1,1,1,1,1,1,1,1,1,1,1,1,1,1,1,1,1,1,1,1,1,1,1
1,1,1,1,1,1,1,1,1,1,1,1,1,1,1,1,1,1,1,1,1,1,1,1,1,1,1,1,1,1,1,1,1,1,1,1,1,1,1,1,1,1,1,1,1,1,1,1,1,1,1
1,1,1,1,1,1,1,1,1,1,1,1,1,1,1,1,1,1,1,1,1,1,1,1,1,1,1,1,1,1,1,1,1,1,1,1,1,1,1,1,1,1,1,1,1,1,1,1,1,1,1
1,1,1,1,1,1,1,1,1,1,1,1,1,1,1,1,1,1,1,1,1,1,1,1,1,1,1,1,1,1,1,1,1,1,1,1,1,1,1,1,1,1,1,1,1,1,1,1,1,1,1
1,1,1,1,1,1,1,1,1,1,1,1,1,1,1,1,1,1,1,1,1,1,1,1,1,1,1,1,1,1,1,1,1,1,1,1,1,1,1,1,1,1,1,1,1,1,1,1,1,1,1
1,1,1,1,1,1,1,1,1,1,1,1,1,1,1,1,1,1,1,1,1,1,1,1,1,1,1,1,1,1,1,1,1,1,1,1,1,1,1,1,1,1,1,1,1,1,1,1,1,1,1
1,1,1,1,1,1,1,1,1,1,1,1,1,1,1,1,1,1,1,1,1,1,1,1,1,1,1,1,1,1,1,1,1,1,1,1,1,1,1,1,1,1,1,1,1,1,1,1,1,1,1
1,1,1,1,1,1,1,1,1,1,1,1,1,1,1,1,1,1,1,1,1,1,1,1,1,1,1,1,1,1,1,1,1,1,1,1,1,1,1,1,1,1,1,1,1,1,1,1,1,1,1
1,1,1,1,1,1,1,1,1,1,1,1,1,1,1,1,1,1,1,1,1,1,1,1,1,1,1,1,1,1,1,1,1,1,1,1,1,1,1,1,1,1,1,1,1,1,1,1,1,1,1
1,1,1,1,1,1,1,1,1,1,1,1,1,1,1,1,1,1,1,1,1,1,1,1,1,1,1,1,1,1,1,1,1,1,1,1,1,1,1,1,1,1,1,1,1,1,1,1,1,1,1
1,1,1,1,1,1,1,1,1,1,1,1,1,1,1,1,1,1,1,1,1,1,1,1,1,1,1,1,1,1,1,1,1,1,1,1,1,1,1,1,1,1,1,1,1,1,1,1,1,1,1
1,1,1,1,1,1,1,1,1,1,1,1,1,1,1,1,1,1,1,1,1,1,1,1,1,1,1,1,1,1,1,1,1,1,1,1,1,1,1,1,1,1,1,1,1,1,1,1,1,1,1
1,1,1,1,1,1,1,1,1,1,1,1,1,1,1,1,1,1,1,1,1,1,1,1,1,1,1,1,1,1,1,1,1,1,1,1,1,1,1,1,1,1,1,1,1,1,1,1,1,1,1
1,1,1,1,1,1,1,1,1,1,1,1,1,1,1,1,1,1,1,1,1,1,1,1,1,1,1,1,1,1,1,1,1,1,1,1,1,1,1,1,1,1,1,1,1,1,1,1,1,1,1
1,1,1,1,1,1,1,1,1,1,1,1,1,1,1,1,1,1,1,1,1,1,1,1,1,1,1,1,1,1,1,1,1,1,1,1,1,1,1,1,1,1,1,1,1,1,1,1,1,1,1
1,1,1,1,1,1,1,1,1,1,1,1,1,1,1,1,1,1,1,1,1,1,1,1,1,1,1,1,1,1,1,1,1,1,1,1,1,1,1,1,1,1,1,1,1,1,1,1,1,1,1
1,1,1,1,1,1,1,1,1,1,1,1,1,1,1,1,1,1,1,1,1,1,1,1,1,1,1,1,1,1,1,1,1,1,1,1,1,1,1,1,1,1,1,1,1,1,1,1,1,1,1
1,1,1,1,1,1,1,1,1,1,1,1,1,1,1,1,1,1,1,1,1,1,1,1,1,1,1,1,1,1,1,1,1,1,1,1,1,1,1,1,1,1,1,1,1,1,1,1,1,1,1
1,1,1,1,1,1,1,1,1,1,1,1,1,1,1,1,1,1,1,1,1,1,1,1,1,1,1,1,1,1,1,1,1,1,1,1,1,1,1,1,1,1,1,1,1,1,1,1,1,1,1
1,1,1,1,1,1,1,1,1,1,1,1,1,1,1,1,1,1,1,1,1,1,1,1,1,1,1,1,1,1,1,1,1,1,1,1,1,1,1,1,1,1,1,1,1,1,1,1,1,1,1
1,1,1,1,1,1,1,1,1,1,1,1,1,1,1,1,1,1,1,1,1,1,1,1,1,1,1,1,1,1,1,1,1,1,1,1,1,1,1,1,1,1,1,1,1,1,1,1,1,1,1
1,1,1,1,1,1,1,1,1,1,1,1,1,1,1,1,1,1,1,1,1,1,1,1,1,1,1,1,1,1,1,1,1,1,1,1,1,1,1,1,1,1,1,1,1,1,1,1,1,1,1
1,1,1,1,1,1,1,1,1,1,1,1,1,1,1,1,1,1,1,1,1,1,1,1,1,1,1,1,1,1,1,1,1,1,1,1,1,1,1,1,1,1,1,1,1,1,1,1,1,1,1
1,1,1,1,1,1,1,1,1,1,1,1,1,1,1,1,1,1,1,1,1,1,1,1,1,1,1,1,1,1,1,1,1,1,1,1,1,1,1,1,1,1,1,1,1,1,1,1,1,1,1
1,1,1,1,1,1,1,1,1,1,1,1,1,1,1,1,1,1,1,1,1,1,1,1,1,1,1,1,1,1,1,1,1,1,1,1,1,1,1,1,1,1,1,1,1,1,1,1,1,1,1
1,1,1,1,1,1,1,1,1,1,1,1,1,1,1,1,1,1,1,1,1,1,1,1,1,1,1,1,1,1,1,1,1,1,1,1,1,1,1,1,1,1,1,1,1,1,1,1,1,1,1
1,1,1,1,1,1,1,1,1,1,1,1,1,1,1,1,1,1,1,1,1,1,1,1,1,1,1,1,1,1,1,1,1,1,1,1,1,1,1,1,1,1,1,1,1,1,1,1,1,1,1
1,1,1,1,1,1,1,1,1,1,1,1,1,1,1,1,1,1,1,1,1,1,1,1,1,1,1,1,1,1,1,1,1,1,1,1,1,1,1,1,1,1,1,1,1,1,1,1,1,1,1
1,1,1,1,1,1,1,1,1,1,1,1,1,1,1,1,1,1,1,1,1,1,1,1,1,1,1,1,1,1,1,1,1,1,1,1,1,1,1,1,1,1,1,1,1,1,1,1,1,1,1
1,1,1,1,1,1,1,1,1,1,1,1,1,1,1,1,1,1,1,1,1,1,1,1,1,1,1,1,1,1,1,1,1,1,1,1,1,1,1,1,1,1,1,1,1,1,1,1,1,1,1
1,1,1,1,1,1,1,1,1,1,1,1,1,1,1,1,1,1,1,1,1,1,1,1,1,1,1,1,1,1,1,1,1,1,1,1,1,1,1,1,1,1,1,1,1,1,1,1,1,1,1
1,1,1,1,1,1,1,1,1,1,1,1,1,1,1,1,1,1,1,1,1,1,1,1,1,1,1,1,1,1,1,1,1,1,1,1,1,1,1,1,1,1,1,1,1,1,1,1,1,1,1
1,1,1,1,1,1,1,1,1,1,1,1,1,1,1,1,1,1,1,1,1,1,1,1,1,1,1,1,1,1,1,1,1,1,1,1,1,1,1,1,1,1,1,1,1,1,1,1,1,1,1
1,1,1,1,1,1,1,1,1,1,1,1,1,1,1,1,1,1,1,1,1,1,1,1,1,1,1,1,1,1,1,1,1,1,1,1,1,1,1,1,1,1,1,1,1,1,1,1,1,1,1
1,1,1,1,1,1,1,1,1,1,1,1,1,1,1,1,1,1,1,1,1,1,1,1,1,1,1,1,1,1,1,1,1,1,1,1,1,1,1,1,1,1,1,1,1,1,1,1,1,1,1
1,1,1,1,1,1,1,1,1,1,1,1,1,1,1,1,1,1,1,1,1,1,1,1,1,1,1,1,1,1,1,1,1,1,1,1,1,1,1,1,1,1,1,1,1,1,1,1,1,1,1
1,1,1,1,1,1,1,1,1,1,1,1,1,1,1,1,1,1,1,1,1,1,1,1,1,1,1,1,1,1,1,1,1,1,1,1,1,1,1,1,1,1,1,1,1,1,1,1,1,1,1
1,1,1,1,1,1,1,1,1,1,1,1,1,1,1,1,1,1,1,1,1,1,1,1,1,1,1,1,1,1,1,1,1,1,1,1,1,1,1,1,1,1,1,1,1,1,1,1,1,1,1
1,1,1,1,1,1,1,1,1,1,1,1,1,1,1,1,1,1,1,1,1,1,1,1,1,1,1,1,1,1,1,1,1,1,1,1,1,1,1,1,1,1,1,1,1,1,1,1,1,1,1
1,1,1,1,1,1,1,1,1,1,1,1,1,1,1,1,1,1,1,1,1,1,1,1,1,1,1,1,1,1,1,1,1,1,1,1,1,1,1,1,1,1,1,1,1,1,1,1,1,1,1
1,1,1,1,1,1,1,1,1,1,1,1,1,1,1,1,1,1,1,1,1,1,1,1,1,1,1,1,1,1,1,1,1,1,1,1,1,1,1,1,1,1,1,1,1,1,1,1,1,1,1
1,1,1,1,1,1,1,1,1,1,1,1,1,1,1,1,1,1,1,1,1,1,1,1,1,1,1,1,1,1,1,1,1,1,1,1,1,1,1,1,1,1,1,1,1,1,1,1,1,1,1
1,1,1,1,1,1,1,1,1,1,1,1,1,1,1,1,1,1,1,1,1,1,1,1,1,1,1,1,1,1,1,1,1,1,1,1,1,1,1,1,1,1,1,1,1,1,1,1,1,1,1
1,1,1,1,1,1,1,1,1,1,1,1,1,1,1,1,1,1,1,1,1,1,1,1,1,1,1,1,1,1,1,1,1,1,1,1,1,1,1,1,1,1,1,1,1,1,1,1,1,1,1
1,1,1,1,1,1,1,1,1,1,1,1,1,1,1,1,1,1,1,1,1,1,1,1,1,1,1,1,1,1,1,1,1,1,1,1,1,1,1,1,1,1,1,1,1,1,1,1,1,1,1
1,1,1,1,1,1,1,1,1,1,1,1,1,1,1,1,1,1,1,1,1,1,1,1,1,1,1,1,1,1,1,1,1,1,1,1,1,1,1,1,1,1,1,1,1,1,1,1,1,1,1
1,1,1,1,1,1,1,1,1,1,1,1,1,1,1,1,1,1,1,1,1,1,1,1,1,1,1,1,1,1,1,1,1,1,1,1,1,1,1,1,1,1,1,1,1,1,1,1,1,1,1
1,1,1,1,1,1,1,1,1,1,1,1,1,1,1,1,1,1,1,1,1,1,1,1,1,1,1,1,1,1,1,1,1,1,1,1,1,1,1,1,1,1,1,1,1,1,1,1,1,1,1
1,1,1,1,1,1,1,1,1,1,1,1,1,1,1,1,1,1,1,1,1,1,1,1,1,1,1,1,1,1,1,1,1,1,1,1,1,1,1,1,1,1,1,1,1,1,1,1,1,1,1
1,1,1,1,1,1,1,1,1,1,1,1,1,1,1,1,1,1,1,1,1,1,1,1,1,1,1,1,1,1,1,1,1,1,1,1,1,1,1,1,1,1,1,1,1,1,1,1,1,1,1
:endlayer
layer: 1
1,1,1,1,1,1,1,1,1,1,1,1,1,1,1,1,1,1,1,1,1,1,1,1,1,1,1,1,1,1,1,1,1,1,1,1,1,1,1,1,1,1,1,1,1,1,1,1,1,1,1
1,1,1,1,1,1,1,1,1,1,1,1,1,1,1,1,1,1,1,1,1,1,1,1,1,1,1,1,1,1,1,1,1,1,1,1,1,1,1,1,1,1,1,1,1,1,1,1,1,1,1
1,1,1,1,1,1,1,1,1,1,1,1,1,1,1,1,1,1,1,1,1,1,1,1,1,1,1,1,1,1,1,1,1,1,1,1,1,1,1,1,1,1,1,1,1,1,1,1,1,1,1
1,1,1,1,1,1,1,1,1,1,1,1,1,1,1,1,1,1,1,1,1,1,1,1,1,1,1,1,1,1,1,1,1,1,1,1,1,1,1,1,1,1,1,1,1,1,1,1,1,1,1
1,1,1,1,1,1,1,1,1,1,1,1,1,1,1,1,1,1,1,1,1,1,1,1,1,1,1,1,1,1,1,1,1,1,1,1,1,1,1,1,1,1,1,1,1,1,1,1,1,1,1
1,1,1,1,1,1,1,1,1,1,1,1,1,1,1,1,1,1,1,1,1,1,1,1,1,1,1,1,1,1,1,1,1,1,1,1,1,1,1,1,1,1,1,1,1,1,1,1,1,1,1
1,1,1,1,1,1,1,1,1,1,1,1,1,1,1,1,1,1,1,1,1,1,1,1,1,1,1,1,1,1,1,1,1,1,1,1,1,1,1,1,1,1,1,1,1,1,1,1,1,1,1
1,1,1,1,1,1,1,1,1,1,1,1,1,1,1,1,1,1,1,1,1,1,1,1,1,1,1,1,1,1,1,1,1,1,1,1,1,1,1,1,1,1,1,1,1,1,1,1,1,1,1
1,1,1,1,1,1,1,1,1,1,1,1,1,1,1,1,1,1,1,1,1,1,1,1,1,1,1,1,1,1,1,1,1,1,1,1,1,1,1,1,1,1,1,1,1,1,1,1,1,1,1
1,1,1,1,1,1,1,1,1,1,1,1,1,1,1,1,1,1,1,1,1,1,1,1,1,1,1,1,1,1,1,1,1,1,1,1,1,1,1,1,1,1,1,1,1,1,1,1,1,1,1
1,1,1,1,1,1,1,1,1,1,1,1,1,1,1,1,1,1,1,1,1,1,1,1,1,1,1,1,1,1,1,1,1,1,1,1,1,1,1,1,1,1,1,1,1,1,1,1,1,1,1
1,1,1,1,1,1,1,1,1,1,1,1,1,1,1,1,1,1,1,1,1,1,1,1,1,1,1,1,1,1,1,1,1,1,1,1,1,1,1,1,1,1,1,1,1,1,1,1,1,1,1
1,1,1,1,1,1,1,1,1,1,1,1,1,1,1,1,1,1,1,1,1,1,1,1,1,1,1,1,1,1,1,1,1,1,1,1,1,1,1,1,1,1,1,1,1,1,1,1,1,1,1
1,1,1,1,1,1,1,1,1,1,1,1,1,1,1,1,1,1,1,1,1,1,1,1,1,1,1,1,1,1,1,1,1,1,1,1,1,1,1,1,1,1,1,1,1,1,1,1,1,1,1
1,1,1,1,1,1,1,1,1,1,1,1,1,1,1,1,1,1,1,1,1,1,1,1,1,1,1,1,1,1,1,1,1,1,1,1,1,1,1,1,1,1,1,1,1,1,1,1,1,1,1
1,1,1,1,1,1,1,1,1,1,1,1,1,1,1,1,1,1,1,1,1,1,1,1,1,1,1,1,1,1,1,1,1,1,1,1,1,1,1,1,1,1,1,1,1,1,1,1,1,1,1
1,1,1,1,1,1,1,1,1,1,1,1,1,1,1,1,1,1,1,1,1,1,1,1,1,1,1,1,1,1,1,1,1,1,1,1,1,1,1,1,1,1,1,1,1,1,1,1,1,1,1
1,1,1,1,1,1,1,1,1,1,1,1,1,1,1,1,1,1,1,1,1,1,1,1,1,1,1,1,1,1,1,1,1,1,1,1,1,1,1,1,1,1,1,1,1,1,1,1,1,1,1
1,1,1,1,1,1,1,1,1,1,1,1,1,1,1,1,1,1,1,1,1,1,1,1,1,1,1,1,1,1,1,1,1,1,1,1,1,1,1,1,1,1,1,1,1,1,1,1,1,1,1
1,1,1,1,1,1,1,1,1,1,1,1,1,1,1,1,1,1,1,1,1,1,1,1,1,1,1,1,1,1,1,1,1,1,1,1,1,1,1,1,1,1,1,1,1,1,1,1,1,1,1
1,1,1,1,1,1,1,1,1,1,1,1,1,1,1,1,1,1,1,1,1,1,1,1,1,1,1,1,1,1,1,1,1,1,1,1,1,1,1,1,1,1,1,1,1,1,1,1,1,1,1
1,1,1,1,1,1,1,1,1,1,1,1,1,1,1,1,1,1,1,1,1,1,1,1,1,1,1,1,1,1,1,1,1,1,1,1,1,1,1,1,1,1,1,1,1,1,1,1,1,1,1
1,1,1,1,1,1,1,1,1,1,1,1,1,1,1,1,1,1,1,1,1,1,1,1,1,1,1,1,1,1,1,1,1,1,1,1,1,1,1,1,1,1,1,1,1,1,1,1,1,1,1
1,1,1,1,1,1,1,1,1,1,1,1,1,1,1,1,1,1,1,1,1,1,1,1,1,1,1,1,1,1,1,1,1,1,1,1,1,1,1,1,1,1,1,1,1,1,1,1,1,1,1
1,1,1,1,1,1,1,1,1,1,1,1,1,1,1,1,1,1,1,1,1,1,1,1,1,1,1,1,1,1,1,1,1,1,1,1,1,1,1,1,1,1,1,1,1,1,1,1,1,1,1
1,1,1,1,1,1,1,1,1,1,1,1,1,1,1,1,1,1,1,1,1,1,1,1,1,1,1,1,1,1,1,1,1,1,1,1,1,1,1,1,1,1,1,1,1,1,1,1,1,1,1
1,1,1,1,1,1,1,1,1,1,1,1,1,1,1,1,1,1,1,1,1,1,1,1,1,1,1,1,1,1,1,1,1,1,1,1,1,1,1,1,1,1,1,1,1,1,1,1,1,1,1
1,1,1,1,1,1,1,1,1,1,1,1,1,1,1,1,1,1,1,1,1,1,1,1,1,1,1,1,1,1,1,1,1,1,1,1,1,1,1,1,1,1,1,1,1,1,1,1,1,1,1
1,1,1,1,1,1,1,1,1,1,1,1,1,1,1,1,1,1,1,1,1,1,1,1,1,1,1,1,1,1,1,1,1,1,1,1,1,1,1,1,1,1,1,1,1,1,1,1,1,1,1
1,1,1,1,1,1,1,1,1,1,1,1,1,1,1,1,1,1,1,1,1,1,1,1,1,1,1,1,1,1,1,1,1,1,1,1,1,1,1,1,1,1,1,1,1,1,1,1,1,1,1
1,1,1,1,1,1,1,1,1,1,1,1,1,1,1,1,1,1,1,1,1,1,1,1,1,1,1,1,1,1,1,1,1,1,1,1,1,1,1,1,1,1,1,1,1,1,1,1,1,1,1
1,1,1,1,1,1,1,1,1,1,1,1,1,1,1,1,1,1,1,1,1,1,1,1,1,1,1,1,1,1,1,1,1,1,1,1,1,1,1,1,1,1,1,1,1,1,1,1,1,1,1
1,1,1,1,1,1,1,1,1,1,1,1,1,1,1,1,1,1,1,1,1,1,1,1,1,1,1,1,1,1,1,1,1,1,1,1,1,1,1,1,1,1,1,1,1,1,1,1,1,1,1
1,1,1,1,1,1,1,1,1,1,1,1,1,1,1,1,1,1,1,1,1,1,1,1,1,1,1,1,1,1,1,1,1,1,1,1,1,1,1,1,1,1,1,1,1,1,1,1,1,1,1
1,1,1,1,1,1,1,1,1,1,1,1,1,1,1,1,1,1,1,1,1,1,1,1,1,1,1,1,1,1,1,1,1,1,1,1,1,1,1,1,1,1,1,1,1,1,1,1,1,1,1
1,1,1,1,1,1,1,1,1,1,1,1,1,1,1,1,1,1,1,1,1,1,1,1,1,1,1,1,1,1,1,1,1,1,1,1,1,1,1,1,1,1,1,1,1,1,1,1,1,1,1
1,1,1,1,1,1,1,1,1,1,1,1,1,1,1,1,1,1,1,1,1,1,1,1,1,1,1,1,1,1,1,1,1,1,1,1,1,1,1,1,1,1,1,1,1,1,1,1,1,1,1
1,1,1,1,1,1,1,1,1,1,1,1,1,1,1,1,1,1,1,1,1,1,1,1,1,1,1,1,1,1,1,1,1,1,1,1,1,1,1,1,1,1,1,1,1,1,1,1,1,1,1
1,1,1,1,1,1,1,1,1,1,1,1,1,1,1,1,1,1,1,1,1,1,1,1,1,1,1,1,1,1,1,1,1,1,1,1,1,1,1,1,1,1,1,1,1,1,1,1,1,1,1
1,1,1,1,1,1,1,1,1,1,1,1,1,1,1,1,1,1,1,1,1,1,1,1,1,1,1,1,1,1,1,1,1,1,1,1,1,1,1,1,1,1,1,1,1,1,1,1,1,1,1
1,1,1,1,1,1,1,1,1,1,1,1,1,1,1,1,1,1,1,1,1,1,1,1,1,1,1,1,1,1,1,1,1,1,1,1,1,1,1,1,1,1,1,1,1,1,1,1,1,1,1
1,1,1,1,1,1,1,1,1,1,1,1,1,1,1,1,1,1,1,1,1,1,1,1,1,1,1,1,1,1,1,1,1,1,1,1,1,1,1,1,1,1,1,1,1,1,1,1,1,1,1
1,1,1,1,1,1,1,1,1,1,1,1,1,1,1,1,1,1,1,1,1,1,1,1,1,1,1,1,1,1,1,1,1,1,1,1,1,1,1,1,1,1,1,1,1,1,1,1,1,1,1
1,1,1,1,1,1,1,1,1,1,1,1,1,1,1,1,1,1,1,1,1,1,1,1,1,1,1,1,1,1,1,1,1,1,1,1,1,1,1,1,1,1,1,1,1,1,1,1,1,1,1
1,1,1,1,1,1,1,1,1,1,1,1,1,1,1,1,1,1,1,1,1,1,1,1,1,1,1,1,1,1,1,1,1,1,1,1,1,1,1,1,1,1,1,1,1,1,1,1,1,1,1
1,1,1,1,1,1,1,1,1,1,1,1,1,1,1,1,1,1,1,1,1,1,1,1,1,1,1,1,1,1,1,1,1,1,1,1,1,1,1,1,1,1,1,1,1,1,1,1,1,1,1
1,1,1,1,1,1,1,1,1,1,1,1,1,1,1,1,1,1,1,1,1,1,1,1,1,1,1,1,1,1,1,1,1,1,1,1,1,1,1,1,1,1,1,1,1,1,1,1,1,1,1
1,1,1,1,1,1,1,1,1,1,1,1,1,1,1,1,1,1,1,1,1,1,1,1,1,1,1,1,1,1,1,1,1,1,1,1,1,1,1,1,1,1,1,1,1,1,1,1,1,1,1
1,1,1,1,1,1,1,1,1,1,1,1,1,1,1,1,1,1,1,1,1,1,1,1,1,1,1,1,1,1,1,1,1,1,1,1,1,1,1,1,1,1,1,1,1,1,1,1,1,1,1
1,1,1,1,1,1,1,1,1,1,1,1,1,1,1,1,1,1,1,1,1,1,1,1,1,1,1,1,1,1,1,1,1,1,1,1,1,1,1,1,1,1,1,1,1,1,1,1,1,1,1
1,1,1,1,1,1,1,1,1,1,1,1,1,1,1,1,1,1,1,1,1,1,1,1,1,1,1,1,1,1,1,1,1,1,1,1,1,1,1,1,1,1,1,1,1,1,1,1,1,1,1
:endlayer
layer: 2
1,1,2,2,2,2,2,1,1,2,1,2,1,1,2,2,2,2,3,2,1,1,1,1,1,1,2,1,2,1,3,2,1,2,2,1,2,1,1,2,1,2,2,2,2,2,2,1,2,1,1
1,2,2,1,1,1,2,2,1,2,2,2,2,2,1,1,2,1,1,2,2,2,1,1,2,1,1,1,2,1,3,2,1,2,1,2,2,2,2,1,2,1,2,2,1,2,1,1,1,1,2
1,2,1,2,2,2,1,2,1,2,1,1,1,2,2,2,2,1,2,1,2,1,2,1,2,2,2,1,1,2,1,2,2,1,2,1,1,2,2,2,2,1,1,2,1,1,1,2,1,1,1
1,2,1,2,2,1,2,1,2,2,1,2,2,2,2,1,1,2,2,1,1,1,2,2,2,2,1,1,2,1,1,1,2,1,1,2,1,2,2,2,2,2,1,1,2,1,2,2,4,4,1
1,2,1,2,2,2,1,1,1,1,1,2,2,2,2,2,2,2,1,1,1,2,1,1,2,1,2,2,1,2,2,2,1,1,2,2,1,2,1,2,1,2,2,2,1,1,1,1,4,4,2
1,1,5,6,1,1,1,5,1,1,6,6,6,1,6,1,1,2,1,1,1,2,1,1,1,2,2,1,1,2,2,6,6,6,1,7,1,7,1,2,1,2,1,2,1,1,2,2,1,1,2
1,5,1,5,1,1,5,1,1,1,6,6,1,6,6,1,1,6,1,1,2,2,2,2,1,2,2,2,2,2,2,6,6,6,7,1,1,7,1,7,1,1,2,2,2,1,2,2,1,1,1
1,5,5,1,2,5,5,1,5,6,1,1,6,1,1,1,1,6,6,1,6,2,2,1,2,2,2,2,1,2,1,6,6,6,7,7,1,7,7,7,7,2,1,2,1,1,1,1,2,2,2
1,5,2,1,1,1,1,1,1,1,6,2,6,1,6,6,1,1,6,6,1,1,6,1,1,1,1,1,6,6,1,6,6,1,7,1,1,1,7,7,2,2,1,2,2,2,1,2,1,1,1
1,2,1,1,2,1,1,2,2,1,1,2,1,1,2,2,6,6,6,1,6,6,1,6,1,6,6,6,1,6,6,6,1,6,1,6,2,1,2,1,1,2,1,2,1,2,2,2,2,2,1
1,2,2,2,1,1,2,2,1,2,1,1,2,2,1,1,2,2,1,6,6,6,6,6,1,6,1,6,6,6,6,6,1,6,6,6,1,2,2,2,2,2,1,1,2,1,1,2,2,2,2
1,2,2,1,2,1,2,1,2,1,2,1,1,1,2,2,2,1,2,1,2,1,1,2,6,6,6,1,6,6,1,6,6,6,6,4,6,1,2,2,2,2,1,1,1,2,1,2,2,2,1
1,1,1,1,2,2,1,2,2,2,1,1,2,2,1,2,2,1,2,2,2,2,2,2,2,2,2,2,2,2,1,1,6,6,6,4,1,6,6,2,2,1,1,1,2,2,2,1,2,2,1
1,2,1,1,2,2,1,1,2,1,1,2,1,1,2,2,2,2,2,2,2,2,1,2,1,2,1,2,2,2,1,1,1,6,6,1,2,1,6,6,2,2,1,1,1,1,2,1,2,2,1
1,2,2,2,2,2,1,2,1,2,1,1,1,2,1,1,1,2,2,1,1,2,2,1,1,1,2,1,1,2,2,6,6,6,6,2,2,2,2,1,1,2,1,2,2,1,1,2,2,1,1
1,2,1,1,2,2,1,2,2,2,1,1,2,2,2,1,1,2,2,2,1,2,1,2,2,1,2,1,2,1,1,1,1,6,1,6,2,1,2,2,1,1,2,1,1,1,2,1,2,1,2
1,1,2,2,2,2,2,2,1,2,2,2,2,1,1,2,1,2,1,1,2,2,1,1,2,1,1,1,2,2,2,2,6,1,6,6,2,1,1,1,6,1,2,1,2,2,2,1,2,2,2
1,2,2,2,2,2,2,2,2,2,1,1,2,2,2,2,1,2,1,1,1,2,2,1,1,1,2,2,2,2,2,2,6,1,1,6,2,2,2,1,2,1,1,2,1,2,2,2,1,1,2
1,2,1,1,1,2,2,2,2,2,2,1,2,1,1,1,1,2,2,1,2,1,2,2,1,1,1,2,2,2,2,2,2,6,1,6,1,2,1,1,2,2,2,2,1,1,2,2,2,2,1
1,2,1,2,1,1,1,2,2,1,1,2,2,1,1,2,2,1,2,2,1,2,2,2,2,2,1,2,2,1,2,2,2,6,6,1,2,1,2,1,4,1,6,4,2,6,1,1,2,2,1
1,2,8,1,1,1,1,2,1,2,1,1,2,1,1,2,1,1,2,2,2,1,2,2,1,1,2,1,2,1,2,3,3,2,2,2,2,2,1,1,1,4,4,4,2,1,1,1,2,2,2
1,1,1,6,6,9,2,1,2,2,10,2,2,2,1,2,1,1,2,1,2,2,1,2,2,1,4,1,7,1,1,3,3,2,2,1,2,1,2,2,2,1,1,2,1,1,6,1,2,1,2
1,6,6,1,6,1,2,2,2,2,2,1,1,1,1,2,1,2,1,2,1,2,2,2,2,1,7,7,1,7,2,1,2,2,2,2,1,2,1,2,1,6,1,1,1,3,2,2,3,2,2
1,6,6,2,1,2,2,2,1,2,2,1,1,1,2,1,2,1,1,2,2,1,2,2,2,2,1,1,7,1,1,2,2,1,2,2,2,1,1,2,1,1,6,2,3,3,1,2,2,2,1
1,1,6,1,2,1,2,1,1,2,2,1,2,2,1,2,2,1,1,1,1,2,2,1,1,1,7,1,7,7,2,2,1,2,2,2,2,2,1,1,2,6,6,1,2,2,2,2,2,1,1
1,1,1,2,2,2,1,1,2,2,2,1,2,2,2,1,1,2,1,2,2,2,2,2,2,2,7,7,7,1,1,2,2,1,1,2,2,6,1,6,6,6,6,1,2,2,1,2,2,6,6
1,1,1,2,2,1,2,1,1,1,2,1,2,2,2,2,1,2,2,1,2,1,2,2,1,2,1,7,1,1,2,2,2,2,2,1,6,6,1,6,1,2,1,2,1,2,6,6,1,1,1
1,1,3,2,1,2,2,2,1,2,2,1,2,1,2,1,2,2,2,1,1,1,2,2,1,1,7,7,7,1,2,1,1,2,2,1,6,1,1,6,1,2,2,1,2,1,6,1,6,6,1
1,3,3,1,1,1,1,2,1,2,2,2,2,1,1,2,2,1,2,1,1,3,2,1,2,1,7,7,1,7,2,2,1,1,1,2,1,1,1,6,1,1,2,2,2,6,6,6,6,1,2
1,1,2,2,2,2,2,6,1,2,2,1,2,2,2,2,2,2,7,2,3,3,1,1,1,2,2,1,7,2,1,2,2,2,2,2,1,6,6,1,6,2,1,1,1,1,6,6,1,2,2
1,1,2,1,1,1,6,6,1,1,2,2,2,2,2,2,2,1,7,7,7,2,1,2,1,2,2,2,2,1,2,2,2,1,2,6,2,2,6,6,1,2,1,2,1,1,1,1,2,2,2
1,2,2,2,2,2,1,6,1,1,1,2,2,1,2,1,2,2,7,1,1,7,2,2,1,2,2,1,2,2,2,1,1,2,6,1,1,2,2,1,1,2,2,2,1,1,2,2,2,2,1
1,1,1,1,1,1,6,1,6,2,1,1,1,2,1,1,1,1,7,7,1,7,2,1,2,2,1,1,2,2,1,2,2,1,6,1,1,2,1,1,1,2,2,1,2,2,1,2,2,2,1
1,1,1,1,2,1,2,2,2,1,1,1,1,1,2,2,2,1,1,7,1,7,1,2,1,1,1,2,2,2,1,1,2,1,6,6,2,1,2,2,2,2,2,3,2,1,1,1,1,2,2
1,1,1,1,2,2,2,2,2,2,2,2,1,2,2,2,2,2,1,2,2,1,1,2,2,2,2,1,2,2,2,2,1,6,1,6,2,2,2,2,2,2,1,1,1,1,2,1,2,2,2
1,2,2,2,2,1,2,2,1,2,1,2,2,1,2,2,1,1,2,2,1,1,4,1,1,1,1,2,1,2,2,1,2,6,1,6,1,2,2,1,2,2,2,2,2,1,1,2,2,2,2
1,2,2,1,1,2,2,2,2,2,2,1,1,1,2,1,1,2,1,2,2,4,4,2,1,2,2,1,9,1,2,1,1,1,6,1,6,2,1,2,1,1,2,2,1,2,2,5,1,1,5
1,2,1,1,2,1,1,2,1,1,2,2,1,1,2,2,2,1,1,2,1,1,1,2,1,1,2,2,2,2,1,2,2,1,2,2,2,2,2,2,2,2,2,2,5,1,5,1,1,5,5
1,1,1,2,1,1,2,1,1,2,2,1,2,1,2,2,2,2,1,2,1,1,1,2,1,2,1,1,2,2,2,2,1,2,1,2,1,2,2,1,1,1,1,2,5,5,5,5,5,5,3
1,2,2,2,2,2,2,2,2,2,2,2,1,2,1,2,2,2,1,2,2,2,1,2,1,1,2,2,2,2,1,1,1,2,1,2,1,2,1,2,2,2,2,2,7,1,1,1,7,2,2
1,2,1,2,2,1,1,1,2,8,2,8,2,2,2,2,2,1,1,2,2,2,1,1,1,1,7,1,1,2,1,2,2,1,2,1,2,2,2,2,1,1,7,1,7,7,7,1,1,1,2
1,2,2,2,2,2,1,2,2,2,1,2,2,2,2,2,1,1,2,2,7,1,7,7,7,7,7,7,7,2,1,1,4,1,2,1,2,2,2,1,2,1,1,7,1,1,1,7,1,1,2
1,2,2,1,1,1,2,1,2,2,1,2,2,1,2,2,1,1,1,1,1,7,7,7,7,7,1,1,2,2,1,4,4,2,1,1,1,1,2,2,1,1,1,7,1,7,1,1,1,1,2
1,1,2,2,2,1,2,2,2,2,1,1,2,1,1,1,2,2,1,2,1,7,1,7,1,7,1,1,2,1,1,4,4,2,2,2,2,2,2,1,1,7,1,1,1,1,1,2,1,2,2
1,2,2,1,1,2,1,2,2,2,2,1,1,2,2,2,2,2,2,1,2,7,7,2,1,2,2,1,2,1,2,2,2,1,2,1,2,1,2,2,2,2,2,1,2,2,2,1,1,1,2
1,2,2,2,2,1,1,2,1,2,1,2,2,1,2,2,2,1,1,2,1,2,2,2,2,2,1,1,2,1,1,1,2,1,2,1,1,2,1,1,2,1,1,2,1,1,2,1,2,2,2
1,2,1,1,1,2,1,2,2,1,2,1,1,2,1,2,2,2,1,2,1,2,2,2,2,2,1,2,1,1,2,1,1,1,2,2,1,2,1,2,1,1,1,2,2,2,2,2,2,2,2
1,2,2,2,1,2,2,1,2,1,2,2,2,1,2,2,2,2,2,5,5,5,2,2,2,2,2,2,1,2,2,1,1,2,2,2,2,2,2,2,1,2,1,1,2,1,1,1,2,2,2
1,1,2,2,2,2,2,2,1,1,2,1,1,1,1,2,1,2,2,1,1,5,2,2,1,2,2,2,2,1,1,1,1,1,2,2,3,2,2,2,2,2,1,2,1,1,2,1,2,2,2
1,1,1,2,2,2,1,1,2,1,1,1,1,2,1,2,2,2,2,2,5,5,2,2,2,1,1,2,2,2,1,1,2,2,1,1,2,1,2,1,2,2,1,2,2,1,1,2,2,2,2
1,8,2,2,2,1,1,2,2,2,2,2,1,2,2,1,1,2,2,1,5,1,1,2,2,2,2,2,1,1,1,1,2,1,2,1,2,2,1,1,2,1,2,1,1,2,1,1,2,1,2
:endlayer
layer: 3
2,2,2,2,2,2,2,2,2,2,2,2,2,2,1,1,2,2,2,2,2,2,2,2,2,2,2,2,2,1,2,2,2,5,5,5,5,5,2,2,2,2,2,2,1,1,1,1,2,2,2
2,2,2,2,2,2,2,2,1,2,2,1,1,2,2,2,2,1,2,1,2,2,2,2,3,2,2,1,2,2,2,2,2,5,5,5,2,2,2,1,1,1,1,2,1,2,2,2,4,4,2
2,2,2,2,2,2,2,1,2,2,2,2,2,2,1,2,2,2,2,2,2,2,1,2,1,6,1,2,2,1,2,1,1,2,2,2,2,2,2,1,2,1,2,2,1,2,1,2,4,4,2
2,2,1,1,2,1,2,2,2,2,2,2,1,2,2,2,2,2,1,2,2,2,2,2,2,1,1,1,1,2,2,2,1,1,2,2,2,2,2,2,2,2,2,2,2,2,2,2,4,1,1
2,1,2,2,2,1,2,2,1,2,1,1,1,1,1,1,2,2,2,2,2,2,2,2,2,6,6,2,2,1,2,2,2,2,1,2,2,2,1,2,2,2,2,2,1,2,1,1,4,4,2
2,6,6,6,6,6,5,5,5,6,6,6,6,6,1,1,2,2,2,1,2,1,2,2,2,2,2,2,2,2,2,2,2,2,2,2,2,2,2,2,1,2,2,2,2,1,1,1,1,1,2
2,6,6,5,1,6,5,5,1,1,6,1,6,6,6,6,6,6,1,1,2,2,2,2,2,2,2,2,2,1,2,2,2,2,1,7,1,7,2,2,2,1,2,1,2,2,2,2,4,1,2
2,5,1,5,5,6,5,1,5,6,6,1,6,6,6,6,6,6,6,2,2,1,2,2,2,2,2,2,2,2,2,1,2,2,1,1,7,7,7,2,2,2,2,2,1,2,2,2,8,8,2
2,1,5,5,5,5,2,2,1,2,1,1,1,2,2,2,6,6,6,6,6,2,2,2,1,2,2,2,1,2,2,2,2,2,4,1,2,2,2,2,2,2,2,1,2,2,1,1,2,2,1
2,2,2,2,2,2,2,2,2,2,1,2,2,2,2,2,2,2,6,6,6,6,6,2,6,2,2,2,2,2,1,2,2,2,1,4,1,1,1,2,2,2,1,1,1,2,2,2,2,1,2
2,2,2,2,2,1,2,2,1,1,2,2,2,2,2,1,2,1,2,2,1,3,3,2,1,2,3,2,2,1,2,2,6,2,4,4,2,2,2,2,2,2,2,2,2,2,2,2,1,2,2
2,2,2,2,2,2,2,1,2,2,1,2,2,2,2,2,2,2,2,2,1,2,1,2,2,1,3,2,1,1,1,2,2,2,2,2,1,1,1,2,2,1,1,2,1,2,2,1,2,2,2
2,2,1,2,1,2,2,1,2,2,2,2,2,2,2,2,2,1,2,2,2,1,2,2,2,1,1,1,1,2,2,2,1,1,2,2,2,2,2,2,2,2,2,2,1,2,2,2,2,2,2
2,2,2,2,2,1,1,2,2,2,2,2,2,2,2,2,2,2,2,1,2,1,2,2,2,2,2,2,1,2,2,2,6,6,6,2,2,2,2,2,1,2,2,2,2,2,2,2,2,2,2
2,2,1,2,2,2,2,2,2,2,2,2,2,2,2,2,1,2,2,2,2,2,2,2,2,2,2,2,2,2,2,2,6,6,6,2,2,2,2,2,2,1,2,2,2,1,1,2,2,2,1
2,1,2,2,2,2,2,2,2,1,2,2,2,1,2,2,2,2,2,2,2,1,2,2,2,1,2,1,2,1,2,2,6,6,1,1,2,2,2,2,2,2,2,6,6,2,2,1,2,2,2
2,2,1,2,1,2,1,1,2,2,2,2,2,1,2,2,2,2,1,1,2,1,2,2,2,2,2,2,2,2,2,1,1,6,1,6,2,2,1,1,2,6,6,1,6,6,2,2,2,2,2
2,1,2,2,2,2,2,1,2,1,2,2,2,2,2,2,2,2,2,1,2,2,2,2,2,2,1,2,2,2,2,2,1,6,6,6,1,2,2,2,2,6,6,6,6,6,2,1,1,2,1
2,1,1,2,2,2,2,2,2,2,1,2,2,2,2,1,2,2,2,2,1,2,2,2,2,2,2,2,2,2,1,2,6,6,6,1,2,2,2,2,2,6,6,6,6,6,2,2,2,2,1
2,2,2,2,2,2,2,2,1,2,2,2,1,1,2,1,2,2,2,2,2,2,2,2,1,2,1,2,2,2,2,2,6,6,6,6,2,2,2,2,4,6,6,6,2,2,2,2,2,2,1
2,2,1,1,9,2,2,2,2,1,2,1,1,2,2,1,2,2,2,2,2,2,2,2,2,2,2,2,1,2,2,2,2,5,6,6,2,2,2,2,1,6,4,1,4,2,2,1,2,1,2
2,6,6,6,6,9,2,2,2,2,2,2,2,2,2,2,2,2,2,2,2,2,1,2,1,2,4,4,4,2,2,2,3,2,2,1,2,1,2,2,2,6,6,6,1,2,2,2,2,1,2
2,1,6,6,6,2,2,2,1,2,2,2,1,2,2,1,2,2,2,1,2,2,1,2,2,2,4,4,4,2,2,1,2,1,1,2,1,1,2,2,2,6,6,6,2,2,2,2,2,1,2
2,6,6,6,1,1,2,2,2,2,2,2,2,2,2,2,1,1,2,2,2,1,2,3,2,2,1,2,1,2,1,2,2,2,2,2,1,2,2,1,2,6,6,1,2,3,2,2,1,2,1
2,6,6,2,1,2,2,2,1,2,2,2,2,2,2,2,2,1,2,2,2,2,2,3,3,1,7,7,7,2,2,2,1,2,2,2,2,2,2,2,2,6,6,2,2,2,2,2,1,2,2
2,6,2,1,1,2,2,2,2,2,2,2,2,2,2,2,2,9,1,1,2,2,2,1,2,2,7,7,7,7,2,2,1,2,2,2,2,1,2,2,6,1,2,1,2,2,2,2,2,2,1
2,2,2,2,2,2,1,2,1,2,2,2,2,2,1,1,1,2,2,2,2,2,2,1,2,2,7,7,1,1,2,1,2,1,1,2,2,6,6,6,6,2,2,2,2,1,1,6,6,6,1
2,3,2,2,2,2,2,2,2,1,1,2,2,2,1,1,2,2,2,2,2,3,1,2,2,2,7,1,7,1,1,2,2,2,2,2,2,6,6,6,6,2,2,2,6,6,6,6,6,6,6
2,2,1,2,2,2,2,2,2,2,2,1,1,2,1,2,2,2,2,2,2,3,3,2,2,2,7,7,7,7,2,2,2,2,2,2,2,6,6,6,6,2,2,6,6,6,6,6,6,6,6
2,2,1,2,2,2,6,1,6,2,2,2,2,1,2,2,2,2,1,7,2,2,1,2,2,1,2,7,7,2,2,2,2,1,2,2,2,6,6,6,6,2,1,6,6,6,6,6,2,6,6
2,2,2,1,2,2,1,6,6,6,2,2,1,2,1,2,2,2,1,7,7,7,2,2,2,2,2,2,2,1,2,2,2,2,2,2,2,1,2,2,1,1,2,6,6,6,6,2,1,2,2
2,2,2,1,1,2,6,1,6,6,1,1,2,2,2,1,2,2,7,7,7,7,7,2,2,1,2,1,2,2,2,2,2,1,2,2,2,2,2,2,2,2,2,2,2,2,2,2,1,2,2
2,2,2,2,1,2,6,1,6,2,2,2,2,2,2,2,2,2,7,7,7,7,1,2,1,2,1,2,10,1,2,2,2,2,2,2,2,2,2,2,2,2,1,2,1,1,2,1,2,2,2
2,2,2,2,2,2,1,1,2,1,2,2,2,1,2,2,2,2,2,7,1,7,7,1,1,1,2,2,10,10,2,2,2,2,2,2,2,2,2,2,2,2,2,3,2,2,2,1,1,2,2
2,2,1,2,2,1,1,2,2,2,2,2,1,2,2,2,2,2,2,1,1,7,7,7,1,8,2,1,1,2,2,1,2,1,1,2,1,1,2,2,2,1,2,2,3,2,2,1,2,2,2
2,2,2,2,2,2,2,1,1,1,2,1,2,2,2,2,2,2,1,2,7,1,7,7,8,8,1,2,9,2,1,2,2,2,1,2,2,2,2,2,2,1,2,2,1,2,2,2,2,2,2
2,2,2,2,2,2,2,2,3,1,2,2,2,2,2,2,2,2,2,2,1,1,4,2,2,2,2,2,9,2,1,2,2,2,2,2,2,1,2,2,2,1,2,2,2,2,1,1,2,2,2
2,2,2,1,1,2,2,2,1,2,1,2,2,2,2,2,2,2,2,2,2,4,1,2,2,2,2,2,2,2,1,1,2,2,2,2,1,1,1,6,6,6,1,2,2,2,2,3,3,2,1
2,2,2,2,2,2,2,1,2,2,2,2,2,1,2,2,1,2,2,2,2,2,2,2,1,2,2,2,2,2,2,2,2,2,2,2,2,2,6,6,6,6,1,2,2,2,2,3,2,2,2
2,1,4,2,2,1,1,2,8,8,8,1,2,2,2,2,2,1,1,2,2,2,1,2,1,2,1,2,2,2,2,1,2,2,2,2,2,2,2,1,6,6,6,2,2,2,1,2,1,3,2
2,1,4,2,2,1,2,2,8,8,8,8,2,2,2,2,2,2,2,2,2,2,1,7,7,7,1,7,7,2,2,2,1,2,2,2,1,2,2,2,2,2,2,2,2,7,7,1,2,2,2
2,2,1,2,1,1,1,2,2,1,2,2,2,2,2,2,1,2,1,1,2,7,7,7,1,7,7,1,7,2,2,1,4,1,2,1,2,2,2,2,2,1,2,7,1,7,7,1,1,2,2
2,2,2,2,2,2,2,2,1,2,1,2,2,2,2,2,2,2,1,2,7,7,7,7,7,7,7,2,2,2,1,4,4,2,2,2,2,2,2,2,2,2,2,2,2,2,2,1,2,2,1
2,2,2,1,2,2,2,2,2,2,2,1,2,2,2,2,2,2,2,2,2,7,7,1,7,1,2,1,2,2,2,4,4,2,2,2,2,1,2,1,2,1,2,2,1,2,2,2,2,2,2
2,2,1,1,2,1,2,2,2,2,2,2,1,2,2,2,2,2,2,2,2,2,2,2,2,1,2,2,2,1,2,4,4,2,2,2,1,1,2,2,2,2,1,2,1,2,2,2,1,2,2
2,1,7,1,2,2,1,2,1,1,1,2,2,2,1,2,1,1,1,2,5,2,2,2,2,1,1,2,2,2,2,4,2,2,2,1,2,2,2,2,2,1,2,11,2,1,1,2,2,2,2
2,1,7,7,7,1,2,1,2,2,2,2,2,2,2,2,2,2,2,5,5,5,2,2,1,2,1,2,1,1,8,1,2,2,2,1,2,2,2,2,2,2,1,2,2,2,2,2,2,2,2
2,7,1,7,7,1,2,2,2,2,2,2,2,2,2,1,2,2,1,5,5,5,5,2,2,2,2,2,1,2,8,1,2,2,2,1,2,2,2,2,2,2,2,1,2,2,1,2,2,2,1
2,7,7,7,7,7,1,1,2,2,2,2,1,1,2,2,2,2,1,5,5,1,5,2,2,2,2,1,2,2,2,1,2,2,2,2,2,1,2,2,2,2,2,2,2,2,1,2,2,2,1
2,2,2,2,2,1,2,2,2,2,1,2,2,1,2,2,2,2,2,1,5,1,5,2,2,2,2,2,2,2,2,2,2,2,2,1,1,2,2,2,2,1,2,2,2,2,2,2,1,2,1
2,1,2,2,2,2,2,2,1,2,1,1,2,2,2,2,2,2,2,5,1,5,5,2,2,2,2,2,2,2,2,1,2,2,2,2,2,2,2,2,2,2,1,2,2,2,2,2,2,2,2
:endlayer
layer: 4
2,2,2,2,2,2,2,2,2,2,2,2,2,2,2,2,2,2,2,2,2,2,2,2,2,2,2,2,2,2,2,2,5,5,5,5,5,5,5,2,2,2,2,2,2,2,2,2,2,2,2
2,2,2,2,2,2,2,2,2,2,2,2,2,2,2,2,2,2,2,2,2,2,2,2,3,3,2,2,2,2,2,5,5,5,5,5,5,2,2,2,2,2,2,2,2,2,2,2,2,2,2
2,2,2,2,2,2,2,2,2,2,2,2,2,2,2,2,2,2,2,2,2,2,2,2,3,6,2,2,2,2,2,5,5,5,5,9,2,2,2,2,3,3,2,2,2,2,2,2,2,2,2
2,2,2,2,2,2,2,2,2,2,2,2,2,2,2,2,2,2,2,2,2,2,2,2,2,6,6,2,2,2,2,2,2,2,2,2,2,2,2,2,3,3,2,2,2,2,2,2,4,4,2
2,5,2,2,2,2,2,2,2,2,2,2,2,2,2,2,2,2,2,2,2,2,2,2,2,6,6,2,2,2,2,2,2,2,2,2,2,2,2,2,2,2,2,2,2,2,2,2,4,4,2
2,6,6,6,6,6,5,5,5,6,6,3,2,2,2,2,2,2,2,2,2,2,2,2,2,2,2,2,2,2,2,2,2,2,2,2,2,2,2,2,2,2,2,2,2,2,2,2,4,4,5
2,6,6,6,6,6,5,5,5,6,6,2,2,2,2,2,2,2,2,2,2,2,2,2,2,2,2,2,2,2,2,2,2,2,2,2,2,2,2,2,2,2,2,2,2,2,2,2,4,5,5
2,5,5,5,5,6,5,5,5,6,2,2,2,2,2,2,2,2,2,2,2,2,2,2,2,2,2,2,2,2,2,8,8,2,2,2,2,2,2,2,2,2,2,2,2,2,2,2,8,8,5
2,5,5,5,5,5,5,2,2,2,2,2,2,2,2,2,2,2,2,2,2,2,2,2,2,2,2,2,2,2,8,8,8,2,2,2,2,2,2,2,2,2,2,2,2,2,2,2,2,2,2
2,2,2,2,5,5,2,2,2,2,2,2,2,2,2,2,2,2,2,2,2,3,2,2,2,2,2,2,6,2,2,2,2,2,2,2,2,2,2,2,2,2,2,2,2,2,2,2,2,2,2
2,2,2,2,2,2,2,2,2,2,2,2,2,2,2,2,2,2,2,2,2,2,2,2,2,2,2,6,6,6,2,2,2,2,2,2,2,2,2,2,2,2,2,2,2,2,2,2,2,2,2
2,2,2,2,2,2,2,2,2,2,2,2,2,2,2,2,2,2,2,2,2,2,2,2,2,2,2,6,6,6,2,2,2,2,2,2,2,2,2,2,2,2,2,2,2,2,2,2,2,2,2
2,2,2,2,2,2,2,2,2,2,2,2,2,2,2,2,2,2,2,2,2,2,2,2,2,2,2,2,2,2,2,2,2,2,2,2,2,2,2,2,2,2,2,2,2,2,2,2,2,2,2
2,2,2,2,2,2,2,2,2,2,2,2,2,2,2,2,2,2,2,2,2,2,2,2,2,2,2,2,2,2,2,2,2,2,2,2,2,2,2,2,2,2,2,2,2,2,2,2,2,2,2
2,2,2,2,2,2,2,2,2,2,2,2,2,2,2,2,2,2,2,2,2,2,2,2,2,2,2,2,2,2,2,2,2,2,2,2,2,2,2,2,2,2,2,2,2,2,2,2,2,2,2
2,2,2,2,2,2,2,2,2,2,2,2,2,2,2,2,2,2,2,2,2,2,2,2,2,2,2,2,2,2,2,2,2,6,6,2,2,2,2,2,2,2,6,6,6,6,6,6,2,2,2
2,2,2,2,2,2,2,2,2,2,2,2,2,2,2,2,2,2,2,2,2,2,2,2,2,2,2,2,2,2,2,2,2,6,6,2,2,2,2,2,2,6,6,6,6,6,6,6,2,2,2
2,2,2,2,2,2,2,2,2,2,2,2,2,2,2,2,2,2,2,2,2,2,2,2,2,2,2,2,2,2,2,2,6,6,6,6,2,2,2,2,2,6,6,6,6,6,6,6,2,2,2
2,4,2,2,2,2,2,2,2,2,2,2,2,2,2,2,2,2,2,2,2,2,2,2,2,2,2,2,2,2,2,2,6,6,6,6,2,2,2,2,2,6,6,6,6,6,6,6,2,2,2
2,2,2,2,3,3,2,2,2,2,2,2,2,2,2,2,2,2,2,2,2,2,2,2,2,2,2,2,2,2,2,2,6,6,6,6,2,2,2,2,2,6,6,6,6,2,2,2,2,2,2
2,2,2,2,3,3,2,2,2,2,2,2,2,2,2,2,2,2,2,2,2,2,2,2,2,2,2,2,2,2,2,2,6,5,6,6,2,2,2,2,2,6,6,4,4,2,2,2,2,2,2
2,6,6,6,6,2,2,2,2,2,2,2,2,2,2,2,2,2,2,2,2,2,2,2,2,2,2,2,2,2,2,2,2,6,5,6,2,2,2,2,2,6,6,6,6,2,2,2,2,2,2
2,6,6,6,6,2,2,2,2,2,2,2,2,2,2,2,2,2,2,2,2,2,2,2,2,2,2,2,2,2,2,2,2,2,5,2,2,2,2,2,2,6,6,6,6,6,6,6,6,2,2
2,6,6,6,2,2,2,2,2,2,2,2,2,2,2,2,2,2,2,2,2,2,2,3,2,2,2,2,2,2,2,2,2,2,2,2,2,2,2,2,2,6,6,6,6,6,6,6,6,6,2
2,6,6,2,2,2,2,2,2,2,2,2,2,2,2,2,2,9,8,2,2,2,2,3,3,2,2,2,2,2,2,2,2,2,2,2,2,2,2,2,2,6,6,6,6,6,6,6,6,6,6
2,6,2,2,2,2,2,2,2,2,2,2,2,2,2,2,2,9,9,2,2,2,2,2,2,2,2,2,3,2,2,2,2,2,2,2,2,2,2,2,2,2,2,6,6,6,6,6,2,2,6
2,8,8,2,2,2,2,2,2,2,2,2,2,2,2,2,2,2,2,2,2,2,2,2,2,2,2,2,2,3,2,2,2,2,2,2,2,2,2,2,6,2,2,2,2,2,6,6,6,6,6
2,8,8,2,2,2,2,2,2,2,2,2,2,2,2,2,2,2,2,2,2,2,2,2,2,2,2,2,2,2,2,2,2,2,2,2,2,2,2,6,6,2,2,2,6,6,6,6,6,6,6
2,2,2,2,2,2,2,2,2,2,2,2,2,2,2,2,2,2,2,2,2,3,2,2,2,2,2,2,2,2,2,2,2,2,2,2,2,2,2,6,6,2,2,6,6,6,6,6,6,6,6
2,2,2,2,2,2,6,6,6,2,2,2,2,2,2,2,2,2,2,2,2,2,2,2,2,2,2,2,2,2,2,2,2,2,2,2,2,2,2,6,6,2,6,6,6,6,6,6,2,6,6
2,2,2,2,2,2,6,6,6,6,2,2,2,2,2,2,2,2,7,7,7,7,2,2,2,2,2,2,2,2,2,2,2,2,2,2,2,2,2,2,6,2,6,6,6,6,6,2,2,2,2
2,2,2,2,2,2,6,6,6,6,2,2,2,2,2,2,2,2,7,7,7,7,7,5,5,2,2,2,2,2,2,2,2,2,2,2,2,2,2,2,2,2,2,6,6,2,2,2,2,2,2
2,2,2,2,2,2,2,6,6,2,2,2,2,2,2,2,2,2,7,7,7,7,7,5,5,5,2,2,10,10,2,2,2,2,2,2,2,2,2,2,2,2,2,2,2,2,2,2,2,2,2
2,2,2,2,2,2,2,2,2,2,2,2,2,2,2,2,2,2,2,7,7,7,7,7,2,5,5,2,10,10,2,2,2,2,2,2,2,2,2,2,2,2,2,2,2,2,2,2,2,2,2
2,2,2,2,2,2,2,2,2,2,2,2,2,2,2,2,2,2,2,2,7,7,7,7,2,8,2,2,2,2,2,2,2,2,2,2,2,2,2,2,2,2,2,2,2,2,2,2,2,2,2
2,2,2,2,2,2,2,2,2,2,2,2,2,2,2,2,2,2,2,2,7,7,7,7,2,2,2,2,2,2,2,2,2,2,2,2,2,2,2,2,2,2,2,2,2,2,2,2,2,2,2
2,2,2,2,2,2,2,2,3,2,2,2,2,2,2,2,2,2,2,2,2,4,7,7,2,2,2,2,2,2,2,2,2,2,2,2,2,2,2,2,2,2,2,2,2,2,2,2,2,2,2
2,2,2,2,2,2,2,2,2,3,2,2,2,2,2,2,2,2,2,2,2,4,4,2,2,2,2,2,2,2,2,2,2,2,2,2,2,2,6,6,6,6,6,2,2,2,2,2,3,2,2
2,4,2,2,2,2,2,2,2,2,2,2,2,2,2,2,2,2,2,2,2,2,2,2,2,2,2,2,2,2,2,2,2,2,2,2,2,2,6,6,6,6,6,6,2,2,2,2,3,2,2
2,4,4,2,2,2,2,2,8,2,8,2,2,2,2,2,2,2,2,2,2,2,2,2,2,2,2,2,2,2,2,2,2,2,2,2,2,2,2,6,6,6,6,6,6,2,2,2,2,3,2
2,4,4,2,2,2,2,2,2,2,2,2,2,2,2,2,2,2,2,2,2,2,2,2,2,7,2,2,2,2,2,2,2,2,2,2,2,2,2,2,6,6,6,6,2,2,2,2,2,2,2
2,2,2,2,2,2,2,2,5,5,2,2,2,2,2,2,2,2,2,2,2,2,2,7,7,7,7,2,2,2,2,2,2,2,2,2,2,2,2,2,2,2,2,2,2,2,2,2,2,2,2
2,2,2,2,2,5,5,5,5,5,2,2,2,2,2,2,2,2,2,2,2,2,2,7,7,7,2,2,2,2,2,4,4,2,2,2,2,2,2,2,2,2,2,2,2,2,2,2,2,2,2
2,2,2,2,2,5,5,5,5,2,2,2,2,2,2,2,2,2,2,2,2,2,2,2,2,2,2,2,2,2,2,4,4,2,2,2,2,2,2,2,2,2,2,2,2,2,2,2,2,2,2
2,7,2,2,2,2,5,2,2,2,2,2,2,2,2,2,2,2,2,2,2,2,2,2,2,2,2,2,2,2,2,4,4,2,2,2,2,2,2,2,2,2,2,2,11,2,2,2,2,2,2
2,7,7,7,7,5,2,2,2,2,2,2,2,2,2,2,2,2,2,2,5,2,2,2,2,2,2,2,2,2,2,2,2,2,2,2,2,2,2,2,2,2,2,11,2,2,2,2,2,2,2
2,7,7,7,7,7,5,2,2,2,2,2,2,2,2,2,2,2,2,5,5,5,2,2,3,2,2,2,2,2,2,8,2,2,2,2,2,2,2,2,2,2,2,2,2,2,2,2,2,2,2
2,7,7,7,7,7,7,2,2,2,2,2,2,2,2,2,2,2,2,5,5,5,5,2,2,3,2,2,2,2,2,8,2,2,2,2,4,2,2,2,2,2,2,2,2,2,2,2,2,2,2
2,7,7,7,7,7,7,2,2,2,2,2,2,2,2,2,2,2,2,5,5,5,5,2,2,2,2,2,2,2,2,2,2,2,2,2,4,4,2,2,2,2,2,2,2,2,2,2,2,2,2
2,2,2,4,4,4,2,2,2,2,2,2,2,2,2,2,2,2,2,5,5,5,5,2,2,2,2,2,2,2,2,2,2,2,2,2,4,4,2,2,2,2,2,2,2,2,2,2,2,2,2
2,2,2,4,4,2,2,2,2,2,2,2,2,2,2,2,2,2,2,5,5,5,5,2,2,2,2,2,2,2,2,2,2,2,2,2,4,4,2,2,2,2,2,2,2,2,2,2,2,2,2
:endlayer
layer: 5
2,2,2,2,2,2,2,2,2,2,2,2,2,2,2,2,2,2,2,2,2,2,2,2,2,2,2,2,2,2,2,2,5,5,5,5,5,5,5,2,2,2,2,2,2,2,2,2,2,2,2
2,2,2,2,2,2,2,2,2,2,2,2,2,2,2,2,2,2,2,2,2,2,2,2,2,2,2,2,3,2,2,5,5,5,5,5,5,2,2,2,2,2,2,2,2,2,2,2,2,2,2
2,2,2,2,2,2,2,2,2,2,2,2,2,2,2,2,2,2,2,2,2,2,2,2,2,6,2,2,2,2,2,5,5,5,5,9,2,2,2,2,2,2,2,2,2,2,2,2,2,2,2
2,2,2,2,2,2,2,2,2,2,2,2,2,2,2,2,2,2,2,2,2,2,2,2,2,6,2,2,2,2,2,2,2,2,2,2,2,2,2,2,3,2,2,2,2,2,2,2,2,2,2
2,2,2,2,2,2,2,5,5,2,2,2,2,2,2,2,2,2,2,2,2,2,2,2,2,6,6,2,2,2,2,2,2,2,2,2,2,2,2,2,2,2,2,2,2,2,2,2,2,5,5
2,6,6,3,6,6,5,5,5,2,2,2,2,2,2,2,2,2,2,2,2,2,2,2,2,2,2,2,2,2,2,2,2,2,2,2,2,2,2,2,2,2,2,2,2,2,2,2,2,5,5
2,6,6,12,6,6,6,5,5,2,2,2,2,2,2,2,2,2,2,2,2,2,2,2,2,2,2,2,2,2,2,2,2,2,2,2,2,2,2,2,2,2,2,2,2,2,2,2,2,5,5
2,5,5,5,0,12,5,5,5,2,2,2,2,2,2,2,2,2,2,2,2,2,2,2,2,2,2,2,2,2,8,8,2,2,2,2,2,2,2,2,2,2,2,2,2,2,2,2,5,5,5
2,5,5,5,5,5,5,5,5,2,2,2,2,2,2,2,2,2,2,2,2,2,2,2,2,2,2,2,2,2,2,2,2,2,2,2,2,2,2,2,2,2,2,2,2,2,2,2,5,5,5
2,2,2,2,5,2,2,2,2,2,2,2,2,2,2,2,2,2,2,2,2,2,2,2,2,2,2,6,6,2,2,2,2,2,2,2,2,2,2,2,2,2,2,2,2,2,2,2,5,5,5
2,2,2,2,2,2,2,2,2,2,2,2,2,2,2,2,2,2,2,2,2,2,2,2,2,2,2,6,6,6,2,2,2,2,2,2,2,2,2,2,2,2,2,2,2,2,2,2,2,2,2
2,2,2,2,2,2,2,2,2,2,2,2,2,2,2,2,2,2,2,2,2,2,2,2,2,2,2,6,6,6,6,2,2,2,2,2,2,2,2,2,2,2,2,2,2,2,2,2,2,2,2
2,2,2,2,2,2,2,2,2,2,2,2,2,2,2,2,2,2,2,2,2,2,2,2,2,2,2,2,6,6,6,6,6,2,2,2,2,2,3,3,2,2,2,2,2,2,2,2,2,2,2
2,2,2,2,2,2,2,2,2,2,2,2,2,2,2,2,2,2,2,2,2,2,7,7,2,2,2,2,2,2,6,6,6,2,2,2,2,2,3,3,2,2,2,2,2,2,2,2,2,2,2
2,2,2,2,2,2,2,2,2,2,2,2,2,2,2,2,2,2,2,2,2,2,7,7,2,2,2,2,2,2,2,2,2,2,2,2,2,2,2,2,2,2,2,2,2,6,6,2,2,6,6
2,2,2,2,2,2,2,2,2,2,2,2,2,2,2,2,2,2,2,2,2,7,7,7,7,2,2,2,2,2,2,2,2,2,2,2,2,2,2,2,2,2,2,6,6,6,6,6,6,6,6
2,2,2,2,2,2,2,2,2,2,2,2,2,2,2,2,2,2,2,2,2,7,7,7,7,2,2,2,2,2,2,2,2,2,2,2,2,2,2,2,2,6,6,6,6,6,6,6,6,6,6
2,4,2,2,2,2,2,2,2,2,2,2,2,2,2,2,2,2,2,2,2,2,7,7,7,2,2,2,2,2,2,2,2,6,6,2,2,2,2,2,2,6,6,6,6,6,6,6,6,6,6
2,4,2,2,2,2,2,2,2,2,2,2,2,2,2,2,2,2,2,2,2,2,7,7,2,2,2,2,2,2,2,2,2,6,6,6,2,2,2,2,2,6,6,6,6,6,6,6,6,6,2
2,2,2,2,2,3,2,2,2,2,2,2,2,2,2,2,2,2,2,2,2,2,7,7,2,2,2,2,2,3,3,2,2,6,6,6,2,2,2,2,2,6,6,6,6,2,2,2,2,2,2
2,2,2,2,2,2,2,2,2,2,2,2,2,2,2,2,2,2,2,2,2,2,7,7,0,0,0,0,2,3,3,2,6,5,6,6,2,2,2,2,2,6,6,2,2,2,2,2,2,2,2
2,6,6,6,6,2,2,2,2,2,2,2,2,2,2,2,2,2,2,2,2,2,0,0,0,0,0,0,0,0,2,2,2,6,5,6,2,2,2,2,9,6,6,6,6,2,2,2,6,6,6
2,6,6,6,2,2,2,2,2,2,2,2,2,2,2,2,2,2,2,2,2,0,0,0,0,0,0,0,0,0,2,2,2,6,5,6,6,2,2,2,9,6,6,6,6,6,6,6,6,6,6
2,6,6,2,2,2,2,2,2,2,2,2,2,2,2,2,2,2,2,2,2,0,0,0,0,0,0,0,0,2,2,2,2,6,6,6,6,2,2,2,2,6,6,6,6,6,6,6,6,6,6
2,6,7,2,2,2,2,2,2,2,2,2,2,2,2,2,2,2,9,2,0,0,0,0,0,0,0,0,2,2,2,2,2,6,6,6,2,2,2,2,2,6,6,6,6,6,6,6,6,6,6
2,6,7,2,2,2,2,2,2,2,2,2,2,2,2,2,2,2,2,8,0,0,0,0,0,0,0,0,0,2,2,2,12,13,13,2,2,2,2,2,2,2,2,6,6,6,6,6,6,6,6
2,2,2,2,2,2,2,2,2,2,2,2,2,2,2,2,2,14,14,14,0,0,0,0,0,0,0,0,0,2,2,2,15,13,13,2,3,3,2,2,2,2,2,2,2,2,2,2,2,6,6
2,2,2,2,2,2,2,2,2,2,2,2,2,2,2,2,2,0,0,0,0,0,0,0,0,0,0,0,0,0,2,2,2,2,2,2,3,3,2,2,6,2,2,2,2,6,6,6,6,6,6
2,2,2,2,2,2,2,2,6,2,2,2,2,2,2,2,2,0,0,0,0,0,0,0,0,0,0,0,0,0,0,2,2,2,2,2,2,2,2,2,6,2,2,6,6,6,6,6,2,6,6
2,2,2,2,2,2,2,6,6,6,2,2,2,2,2,2,2,2,0,0,0,0,0,0,0,0,0,0,0,0,0,2,2,2,2,2,2,2,2,2,6,2,6,6,6,6,6,2,2,2,6
2,2,2,2,2,2,6,6,6,6,2,2,2,2,2,2,2,2,0,0,0,0,0,0,0,0,0,0,0,0,2,2,2,2,2,2,2,2,2,2,2,2,6,6,6,6,2,2,2,2,2
2,2,2,2,2,2,2,6,6,6,2,2,2,2,2,2,2,2,2,0,0,0,0,0,0,0,0,0,2,2,2,2,2,2,2,2,2,2,2,2,2,6,6,6,6,6,2,2,2,2,2
2,2,2,2,2,2,2,2,2,2,2,2,2,2,2,2,2,2,2,7,0,0,0,5,5,0,5,5,2,2,2,2,2,2,2,2,2,2,2,2,2,2,6,6,2,2,2,2,2,2,2
2,2,2,2,2,2,2,2,2,2,2,2,2,2,2,2,2,2,2,2,7,7,7,2,2,2,5,5,2,2,2,2,2,2,2,2,2,2,2,2,2,2,2,2,2,2,2,2,2,2,2
2,2,2,2,2,2,2,2,2,2,2,2,2,2,2,2,2,2,2,2,0,0,0,0,16,16,5,5,2,2,2,2,2,2,2,2,2,2,2,2,2,2,2,2,2,2,2,2,2,2,2
2,2,2,2,17,12,18,2,2,2,2,2,2,2,2,2,2,0,0,0,0,0,0,16,17,17,2,2,2,2,2,2,2,2,2,2,2,2,2,2,2,2,2,2,2,2,2,2,2,2,2
2,2,2,2,16,17,12,2,3,3,2,2,2,2,2,2,2,0,0,0,0,0,16,17,12,12,2,2,2,2,2,2,2,2,2,2,2,2,2,2,6,2,2,2,2,2,2,2,2,2,2
2,2,2,2,0,16,17,2,3,3,2,2,2,2,2,2,2,0,0,0,2,2,2,12,18,19,2,2,2,2,2,2,2,2,3,2,2,2,6,6,6,6,6,6,6,6,2,2,2,2,2
2,2,2,2,0,0,16,0,0,0,0,0,0,0,0,0,0,0,0,2,2,2,2,2,2,2,2,2,2,2,2,2,2,2,2,2,2,2,2,6,6,6,6,6,6,6,6,2,2,2,2
2,4,2,2,0,0,0,0,0,0,0,0,0,0,0,0,0,0,0,2,2,2,2,2,2,2,2,2,2,2,2,2,2,2,2,2,2,2,2,6,6,6,6,6,6,6,6,2,2,2,2
2,4,2,2,0,0,0,0,0,0,0,0,0,0,0,0,0,0,0,2,2,2,2,2,2,2,2,2,2,2,2,2,2,2,2,2,2,2,2,2,2,6,6,6,6,6,2,2,2,2,2
2,2,2,2,2,5,5,5,5,5,5,5,2,2,2,2,2,2,2,2,2,2,2,2,2,2,3,2,2,2,2,2,2,2,2,2,5,5,5,5,5,5,2,2,2,2,2,2,2,2,2
2,2,2,2,5,5,5,5,5,5,5,2,2,2,2,2,2,2,2,2,2,2,2,2,2,3,2,2,2,2,2,2,2,2,2,2,5,5,5,5,5,5,2,2,2,2,2,2,2,2,2
2,2,2,5,5,5,5,5,5,5,2,2,2,2,2,2,2,2,2,2,2,2,2,2,2,2,2,2,2,2,2,2,2,2,2,2,2,5,5,5,5,5,2,2,2,2,2,2,2,2,2
2,7,5,5,5,5,5,5,5,2,2,2,2,3,3,2,2,2,2,2,2,2,2,2,2,2,2,2,2,2,2,2,2,2,2,2,2,2,2,2,5,2,2,2,2,2,2,2,2,2,2
2,7,7,7,7,5,5,5,2,2,2,2,2,3,3,2,2,2,2,2,2,2,2,2,2,2,2,2,2,2,2,2,2,2,2,2,2,2,2,2,2,2,2,2,2,2,2,2,2,2,2
2,7,7,7,7,7,5,5,2,2,2,2,2,2,2,2,2,2,2,2,5,2,2,2,3,2,2,2,2,2,2,2,2,2,2,2,2,2,2,2,2,2,2,2,2,2,2,2,2,2,2
2,7,7,7,7,7,7,5,2,2,2,2,2,2,2,2,2,2,2,5,5,5,2,2,2,2,2,2,2,2,2,2,2,2,2,2,4,2,2,2,2,2,2,2,2,2,2,2,2,2,2
2,7,7,7,7,7,7,2,2,2,2,2,2,2,3,3,2,2,2,5,5,5,2,2,2,2,2,2,2,2,2,2,2,2,2,2,4,4,2,2,2,2,2,2,7,7,7,2,2,2,2
2,2,2,4,4,4,2,2,2,2,2,2,2,2,3,3,2,2,2,2,5,5,2,2,2,2,2,2,2,2,2,2,2,2,2,2,4,4,2,2,2,2,3,7,7,7,7,2,2,2,2
2,2,2,4,4,2,2,2,2,2,2,2,2,2,2,2,2,2,2,2,5,5,2,2,2,2,2,2,2,2,2,2,2,2,2,2,4,4,2,2,2,2,7,7,7,7,7,2,2,2,2
:endlayer
layer: 6
2,2,2,2,2,2,2,2,2,2,2,2,2,2,2,2,2,2,2,2,2,2,2,2,2,2,2,2,2,2,2,2,2,5,5,5,5,5,2,2,2,6,2,2,2,2,2,2,2,2,2
2,2,2,2,2,2,2,2,2,2,2,2,2,2,2,2,2,2,2,2,2,2,2,2,2,2,2,2,3,2,2,2,2,5,5,5,2,2,2,2,2,6,6,6,6,6,2,2,2,2,2
2,2,2,2,2,2,2,5,5,2,2,2,2,2,2,2,2,2,2,2,2,2,2,2,2,2,2,2,3,2,2,2,2,2,2,2,2,2,2,2,2,6,6,6,6,6,6,6,6,2,2
2,2,2,2,2,2,5,5,5,2,2,2,2,3,2,2,2,2,2,2,2,2,2,2,11,2,2,2,2,2,2,2,2,2,2,2,2,2,2,2,2,2,6,6,6,6,6,6,6,2,5
2,2,2,2,2,2,5,5,5,5,2,2,2,2,2,2,2,2,2,2,2,2,2,2,2,2,2,2,2,2,2,2,2,2,2,2,2,2,2,2,2,2,2,2,2,2,2,6,6,6,6
2,6,2,2,2,2,0,0,5,5,2,2,2,2,2,2,2,2,2,2,2,2,2,2,2,2,2,2,2,2,2,2,2,2,2,2,2,2,2,2,2,2,3,2,2,2,2,2,6,6,6
2,2,2,2,2,2,0,5,5,5,2,2,2,2,2,2,2,2,2,2,2,2,2,2,2,2,2,2,2,2,2,2,2,2,2,2,2,2,2,2,2,3,2,2,2,2,2,2,6,6,6
2,2,2,2,0,2,5,5,5,5,3,2,2,2,2,2,2,2,2,2,2,2,2,2,2,2,2,2,2,2,2,2,2,2,2,2,2,2,2,2,2,2,2,2,2,2,2,6,6,6,6
2,2,2,2,2,2,5,5,5,5,3,3,2,2,2,2,2,2,2,2,2,2,2,2,2,2,2,2,2,2,2,2,2,2,2,2,2,8,8,2,2,2,2,2,2,2,2,6,6,6,6
2,2,2,2,2,2,2,5,5,5,2,2,2,2,2,2,2,2,2,2,2,2,2,2,2,2,2,2,2,2,2,2,2,2,2,2,2,8,8,8,2,2,2,2,2,3,3,6,6,6,6
2,2,2,2,2,2,2,5,5,2,2,2,2,2,2,2,2,2,2,2,2,2,2,2,2,2,2,2,6,6,2,2,2,2,2,2,2,2,8,8,2,2,2,2,2,3,3,6,6,6,6
2,2,2,2,2,2,2,2,2,2,2,2,2,2,2,2,2,2,2,2,2,2,2,2,2,2,2,2,6,6,2,6,9,2,2,2,2,2,2,2,2,2,2,2,2,2,2,2,6,6,6
2,2,2,2,2,2,2,2,2,2,2,2,2,2,2,2,2,2,2,2,2,2,7,7,2,2,2,2,2,2,6,6,6,2,2,2,2,2,2,3,2,2,2,2,2,2,2,2,6,6,6
2,2,2,2,2,2,2,2,2,2,2,2,2,2,2,2,2,2,2,2,2,2,7,7,7,2,2,2,2,2,6,6,6,6,2,2,2,2,2,2,2,2,2,2,2,2,2,2,2,6,6
2,2,2,2,2,2,2,2,2,2,2,2,2,2,2,2,2,2,2,7,2,7,7,7,7,2,2,2,2,2,2,6,6,6,2,2,2,2,2,2,2,2,2,2,2,2,2,2,6,6,6
2,2,2,2,2,2,2,2,2,2,2,2,2,2,2,2,2,2,2,7,2,7,7,7,7,2,2,2,2,2,2,6,6,6,6,2,2,2,2,2,2,2,2,2,6,6,6,6,6,6,6
2,2,2,2,2,2,2,2,2,2,2,2,2,2,2,2,2,2,2,2,2,7,7,7,7,2,2,2,2,2,2,2,6,6,6,2,2,2,2,2,2,2,6,6,6,6,6,6,6,6,6
2,2,2,2,2,2,2,2,2,2,2,2,2,2,2,2,2,2,2,2,2,7,7,7,7,2,2,2,2,2,2,2,2,2,2,2,2,2,2,2,2,6,6,6,6,6,6,6,6,6,6
2,2,2,2,2,2,2,2,2,2,2,2,2,2,2,2,2,2,2,2,2,7,7,7,7,2,2,2,2,2,2,2,2,2,2,2,2,2,2,2,2,6,6,6,6,6,6,6,6,6,6
2,2,2,2,2,2,2,2,2,2,2,2,2,2,2,2,2,2,2,2,2,7,7,7,7,2,2,2,2,3,3,2,2,2,6,2,2,2,2,2,2,2,2,2,2,6,6,6,6,6,6
2,2,2,2,2,2,2,2,2,2,2,2,2,2,2,2,2,2,2,2,2,7,7,7,0,0,0,0,2,3,3,2,2,5,6,6,2,2,2,2,2,2,2,2,2,2,2,2,2,2,2
2,2,2,2,2,2,2,2,2,2,2,2,2,2,2,2,2,2,2,2,2,2,0,0,0,0,0,0,0,0,2,2,6,6,5,6,7,7,7,2,2,6,6,6,6,2,2,2,6,6,6
2,2,2,2,2,2,2,2,2,2,2,2,2,2,2,2,2,2,2,2,2,0,0,0,0,0,0,0,0,0,0,2,6,6,5,6,6,7,7,7,9,6,6,6,6,6,6,6,6,6,6
2,7,7,7,2,2,2,2,2,2,2,2,2,2,2,2,2,2,2,2,2,0,0,0,0,0,0,0,0,0,0,2,2,6,6,6,6,7,7,7,2,6,6,6,6,6,6,6,6,6,6
2,7,7,7,7,2,2,2,2,2,2,2,2,2,2,2,2,2,2,2,0,0,0,0,0,0,0,0,0,0,0,2,2,6,6,6,6,7,7,7,2,6,6,6,6,6,6,6,6,6,6
2,7,7,7,7,2,2,2,2,2,2,2,2,2,2,2,2,14,14,14,0,0,0,0,0,0,0,0,0,0,0,2,2,6,6,6,6,2,2,2,2,2,2,6,6,6,6,6,6,6,6
2,7,7,7,2,2,2,2,2,2,2,2,2,2,2,2,2,0,0,0,0,0,0,0,0,0,0,0,0,0,0,2,15,6,6,6,6,3,2,2,2,2,2,2,2,2,2,2,2,2,3
2,2,2,2,2,2,2,2,2,2,2,2,2,2,2,2,2,0,0,0,0,0,0,0,0,0,0,0,0,0,0,2,2,6,5,6,3,3,2,2,2,2,2,2,2,2,2,2,2,2,2
2,2,2,2,2,2,2,2,6,2,2,2,2,2,2,2,2,0,0,0,0,0,0,0,0,0,0,0,0,0,0,2,2,6,6,6,6,2,2,2,2,2,2,2,2,2,2,2,2,2,2
2,2,2,2,2,2,2,6,6,6,2,2,2,2,2,2,2,2,0,0,0,0,0,0,0,0,0,0,0,0,0,2,2,2,6,6,6,2,2,2,2,2,6,6,6,6,2,2,2,2,2
2,9,2,2,2,2,6,6,6,6,2,2,2,2,2,2,2,2,0,0,0,0,0,0,0,0,0,0,0,0,2,2,2,2,6,6,6,2,2,2,2,6,6,6,6,6,2,2,2,2,2
2,9,2,2,2,2,2,6,6,6,2,2,2,2,2,2,2,2,2,0,0,0,0,0,0,0,0,0,2,2,2,2,2,2,2,2,2,2,2,2,2,6,6,6,6,2,2,2,2,2,2
2,2,8,2,0,0,19,2,2,2,2,2,2,2,2,2,2,2,2,2,0,0,0,0,0,0,5,5,2,2,2,2,2,2,2,2,2,2,2,2,2,6,6,6,6,2,2,2,2,2,2
2,2,2,2,0,0,12,2,2,2,2,2,2,2,2,2,2,2,2,2,2,2,5,2,2,2,5,5,2,2,2,2,2,2,2,2,2,2,2,2,2,6,6,2,2,2,2,2,2,2,2
2,2,2,2,0,0,17,2,2,2,2,2,2,2,2,2,2,2,2,2,0,0,0,0,0,0,5,5,2,2,2,2,2,2,2,2,2,2,2,2,2,2,2,2,2,2,2,2,2,2,2
2,2,2,2,0,0,16,2,2,2,2,2,2,2,2,2,2,0,0,0,0,0,0,0,0,0,2,2,2,2,2,2,2,2,2,2,2,2,2,2,2,2,2,2,2,2,2,2,2,2,2
2,2,2,2,0,0,0,2,2,2,2,2,2,2,2,2,2,0,0,0,0,0,0,0,0,0,2,2,2,2,2,2,2,2,2,2,2,2,2,2,6,2,2,2,2,2,2,2,2,2,2
2,2,2,2,0,0,0,2,2,3,2,2,2,2,2,2,2,0,0,0,2,2,2,0,16,17,2,2,2,2,2,2,2,2,3,3,2,2,2,2,2,2,2,6,6,6,6,6,2,2,2
2,2,2,2,0,0,0,0,0,0,0,0,0,0,0,0,0,0,0,2,2,2,2,0,17,12,2,2,2,2,2,2,2,2,3,3,2,2,2,2,6,6,6,6,6,6,6,2,2,2,2
2,2,2,2,0,0,0,0,0,0,0,0,0,0,0,0,0,0,0,2,2,2,2,0,12,15,2,2,2,2,2,2,2,2,2,2,2,2,2,2,2,6,6,6,6,6,6,2,2,2,2
2,2,2,2,0,0,0,0,0,0,0,0,0,0,0,0,0,0,0,2,2,2,2,0,15,15,2,2,2,2,2,2,2,2,2,2,2,2,2,2,2,2,6,6,6,6,2,2,2,2,2
2,2,2,2,2,5,5,5,5,5,5,5,2,2,2,2,2,2,2,2,2,2,2,2,2,2,2,2,2,2,2,2,2,2,2,2,5,5,5,5,5,5,2,2,2,2,2,2,2,2,2
2,2,2,2,5,5,5,5,5,5,5,2,2,2,2,2,2,2,2,2,2,2,2,2,2,2,2,2,2,2,2,2,2,2,2,2,5,5,5,5,5,5,5,5,5,2,2,2,2,2,2
2,2,5,5,5,5,5,5,5,5,5,2,2,2,2,2,2,2,2,2,2,2,2,2,2,2,2,2,2,2,2,2,2,2,2,2,2,5,5,5,5,5,5,5,5,2,2,2,2,2,2
2,5,5,5,5,5,5,8,8,2,2,2,2,2,2,2,2,2,2,2,2,2,2,2,2,2,2,2,2,2,2,2,2,2,2,2,2,2,2,5,5,5,5,5,5,2,2,2,2,2,2
2,7,7,5,5,5,5,5,8,2,2,2,2,2,2,2,2,2,2,2,2,2,2,2,2,2,2,2,2,2,2,2,2,2,2,2,2,2,2,2,2,2,2,2,2,2,2,2,2,2,2
2,7,7,7,7,5,5,5,2,2,2,2,2,2,2,2,2,2,2,2,2,2,2,2,2,2,2,2,2,2,2,2,2,2,2,2,2,2,2,2,2,2,2,2,2,2,2,2,2,2,2
2,7,7,7,7,7,5,5,2,2,2,2,2,2,2,2,2,2,2,2,2,2,2,2,2,2,2,2,2,2,2,2,2,2,2,2,2,2,2,2,2,2,2,2,7,7,7,7,2,2,2
2,7,7,7,7,7,2,2,2,2,2,2,2,2,3,3,2,2,2,2,4,2,2,2,2,2,2,2,2,2,2,2,2,2,2,2,2,2,2,2,2,2,2,7,7,7,7,7,2,2,2
2,2,2,2,2,2,2,2,2,2,2,2,2,2,3,3,2,2,2,2,4,2,2,2,2,2,2,2,2,2,2,2,2,2,2,2,2,2,2,2,2,2,2,7,7,7,7,7,2,2,2
2,2,2,2,2,2,2,2,2,2,2,2,2,2,2,2,2,2,2,2,4,4,2,2,2,2,2,2,2,2,2,2,2,2,2,2,2,2,2,2,2,2,7,7,7,7,7,7,2,2,2
:endlayer
layer: 7
2,2,2,2,2,2,2,2,2,2,2,2,2,2,2,2,2,2,2,2,2,2,2,2,2,2,2,2,2,2,2,2,2,2,2,2,2,2,2,2,2,6,2,2,2,2,2,2,2,2,2
2,2,2,2,2,2,2,2,2,2,2,2,2,2,2,2,2,2,2,2,2,2,2,2,2,2,2,3,2,2,2,2,2,2,2,2,2,2,2,2,2,6,6,6,6,6,6,2,2,2,2
2,2,2,2,2,2,2,5,5,2,2,2,2,2,2,2,2,2,2,2,2,2,2,2,2,2,2,3,2,2,2,2,2,2,2,2,2,2,2,2,2,6,6,6,6,6,6,6,6,2,2
2,2,2,2,2,2,5,5,5,2,2,2,2,3,3,2,2,2,2,2,2,2,2,2,11,11,2,2,2,2,2,2,2,2,2,2,2,2,2,2,2,2,6,6,6,6,6,6,6,6,6
2,2,2,2,2,8,5,5,5,5,2,2,2,3,3,2,2,2,2,2,2,2,2,2,2,11,2,2,2,2,2,2,2,2,2,2,2,2,2,2,2,2,2,2,2,6,6,6,6,6,6
2,2,2,2,2,2,0,0,0,5,2,2,2,2,2,2,2,2,2,2,2,2,2,2,2,2,2,2,2,2,2,2,2,2,2,2,2,2,2,2,2,2,3,2,2,2,2,6,6,6,6
2,2,2,2,2,2,0,5,5,5,2,2,2,2,2,2,2,2,2,2,2,2,2,2,2,2,2,2,2,2,2,2,2,2,2,2,2,2,2,2,2,3,2,2,2,2,2,6,6,6,6
2,2,2,2,2,2,0,5,0,5,3,2,2,4,4,4,2,2,2,2,2,2,2,2,2,2,2,2,2,2,2,2,2,2,2,2,2,2,2,2,2,2,2,2,2,2,2,6,6,6,6
2,2,2,2,2,2,5,5,5,5,3,3,2,4,4,2,2,2,2,2,2,2,2,2,2,2,2,2,2,2,2,2,2,2,2,2,2,8,8,2,2,2,3,3,2,2,6,6,6,6,6
2,2,2,2,2,2,5,5,5,5,2,2,4,4,4,2,2,2,2,2,2,2,2,2,2,2,2,2,2,2,2,2,2,2,2,2,2,8,8,8,2,2,3,3,2,2,6,6,6,6,6
2,2,2,2,2,2,2,5,5,5,2,2,4,4,4,2,2,2,2,2,2,2,2,2,2,2,2,2,2,2,2,2,2,2,2,2,2,2,8,8,2,2,2,2,2,2,3,6,6,6,6
2,2,2,2,2,2,2,2,5,2,2,2,2,2,2,2,2,2,2,2,2,2,2,2,2,2,2,2,2,2,2,2,2,2,2,2,2,2,2,2,2,2,2,2,2,2,2,6,6,6,6
2,2,2,2,2,2,2,2,2,2,2,2,2,2,2,2,2,2,2,2,2,7,7,7,7,7,2,2,2,2,6,6,6,2,2,2,2,2,2,2,2,2,2,2,2,2,2,6,6,6,6
2,2,2,2,2,2,2,2,2,2,2,2,2,2,2,2,2,2,7,7,7,7,7,7,7,7,2,2,2,2,6,6,6,6,2,2,2,2,2,2,2,2,2,2,2,2,2,2,6,6,6
2,2,2,3,3,2,2,2,2,2,2,2,2,2,2,2,2,7,7,7,7,7,7,7,7,2,2,2,2,2,2,6,6,6,6,2,2,2,2,2,2,2,2,2,2,2,2,2,6,6,6
2,7,2,3,3,2,2,2,2,2,2,2,2,2,2,2,2,7,7,7,7,7,7,7,7,2,2,2,2,2,2,6,6,6,6,2,2,2,2,2,2,2,2,2,2,6,6,6,6,6,6
2,7,2,2,2,2,2,2,2,2,2,2,2,2,2,2,2,2,7,7,2,7,7,7,7,2,2,2,2,2,2,2,6,6,6,2,2,2,2,2,2,2,2,2,6,6,6,6,6,6,6
2,7,2,2,2,2,2,2,2,2,2,2,2,2,2,2,2,2,2,2,2,7,7,0,0,20,2,2,2,2,2,2,6,6,6,6,2,2,2,2,2,2,2,2,6,6,6,6,6,6,6
2,2,2,2,2,2,2,2,2,2,2,2,2,2,2,2,2,2,2,2,2,0,0,0,0,20,2,2,2,2,2,2,6,6,6,6,2,2,2,2,2,2,2,2,6,6,6,6,6,6,6
2,2,2,2,2,2,2,2,2,2,2,2,2,2,2,2,2,2,2,2,0,0,0,0,0,20,2,2,2,2,2,2,6,6,6,6,2,2,2,2,2,2,2,6,6,6,6,6,6,6,6
2,2,2,2,2,2,2,2,2,2,2,2,2,2,2,2,2,2,2,0,0,0,0,0,0,0,0,0,2,2,2,2,6,5,6,6,2,2,2,2,2,2,2,6,6,6,6,6,2,6,6
2,2,2,2,2,2,2,3,2,2,2,2,2,2,2,2,2,2,0,0,0,0,0,0,0,0,0,0,0,0,2,2,6,6,5,6,7,7,7,7,2,2,6,6,6,2,2,2,2,6,6
2,2,2,2,2,2,2,3,2,2,2,2,2,2,2,2,2,2,0,0,0,0,0,0,0,0,0,0,0,0,0,2,6,6,5,6,7,7,7,7,7,6,6,6,6,6,6,6,6,6,6
2,7,7,7,2,2,2,2,2,2,2,2,2,2,2,2,2,0,0,0,0,0,0,0,0,0,0,0,0,0,0,2,6,6,6,6,6,7,7,7,7,7,6,6,6,6,6,6,6,6,6
2,7,7,7,7,7,2,2,2,2,2,2,2,2,2,2,2,0,0,0,0,0,0,0,0,0,0,0,0,0,0,2,12,6,6,6,6,7,7,7,7,7,7,6,6,6,6,6,6,6,6
2,7,7,7,7,7,7,2,2,2,2,2,2,2,2,2,2,0,0,0,0,0,0,0,0,0,0,0,0,0,0,2,12,6,6,6,6,6,2,2,2,2,2,7,6,6,6,6,7,2,6
2,7,7,7,2,2,2,2,2,2,2,2,2,2,2,2,2,0,0,0,0,0,0,0,0,0,0,0,0,0,0,2,12,6,6,6,6,6,6,2,2,2,2,2,7,7,7,2,2,2,2
2,7,8,8,2,2,2,2,2,2,2,2,2,2,2,2,2,0,0,0,0,0,0,0,0,0,0,0,0,0,0,2,7,6,5,6,6,6,6,6,2,2,2,2,2,2,2,2,2,2,2
2,2,8,8,2,2,2,2,6,6,2,2,2,2,2,2,2,0,0,0,0,0,0,0,0,0,0,0,0,0,0,2,2,6,6,6,6,6,6,6,6,2,2,2,2,2,2,2,2,2,2
2,2,2,2,0,0,15,6,6,6,2,2,2,2,2,2,2,2,0,0,0,0,0,0,0,0,0,0,0,0,0,2,2,6,6,6,6,6,6,6,6,2,2,2,2,2,2,2,2,2,2
2,9,2,2,0,0,15,6,6,6,2,2,2,2,2,2,2,2,0,0,0,0,0,0,0,0,0,0,0,0,2,2,2,2,6,6,6,6,6,6,6,6,6,6,6,2,2,2,2,2,2
2,8,8,2,0,0,12,6,6,6,2,2,2,2,2,2,2,2,2,0,0,0,0,0,0,0,0,0,2,2,2,2,2,2,2,6,6,6,6,6,6,6,6,6,6,2,2,2,2,2,2
2,8,8,2,0,0,17,2,2,2,2,2,2,2,2,2,2,2,2,2,0,0,0,0,0,0,5,2,2,2,2,2,2,2,2,6,6,6,6,6,6,6,6,6,2,2,2,2,2,2,2
2,2,2,2,0,0,0,2,2,2,2,2,2,2,2,2,2,2,2,2,2,2,5,2,2,2,5,5,2,2,2,2,6,6,6,6,6,6,6,6,6,6,6,6,2,2,2,2,2,2,2
2,2,2,2,0,0,0,2,2,2,2,2,2,2,2,2,2,2,2,2,0,0,0,0,0,0,5,8,2,2,2,2,6,6,6,6,6,6,6,6,6,6,6,2,2,2,2,2,2,2,2
2,2,2,2,0,0,0,2,2,2,2,2,2,2,2,2,2,0,0,0,0,0,0,0,0,0,2,2,2,2,2,6,6,6,6,6,2,6,6,6,6,6,2,2,2,2,2,2,2,2,2
2,2,2,2,0,0,0,2,2,2,2,2,2,2,2,2,2,0,0,0,0,0,0,0,0,0,2,2,2,2,2,2,6,6,6,2,2,2,6,6,6,2,2,2,2,2,2,2,2,2,2
2,2,2,2,0,0,0,2,2,2,2,2,2,2,2,2,2,0,0,0,2,2,2,0,0,0,2,2,2,2,2,2,2,2,2,2,2,6,6,6,6,6,2,2,6,6,6,6,2,2,2
2,2,2,2,0,0,0,0,0,0,0,0,0,0,0,0,0,0,0,2,2,2,2,0,0,0,2,2,2,2,2,2,2,2,2,3,2,6,6,6,6,2,2,6,6,6,6,6,2,2,2
2,2,2,2,0,0,0,0,0,0,0,0,0,0,0,0,0,0,0,2,2,2,2,0,0,12,2,2,2,2,2,2,2,2,2,2,6,6,6,6,6,2,2,6,6,6,6,2,2,2,2
2,2,2,2,0,0,0,0,0,0,0,0,0,0,0,0,0,0,0,2,2,2,2,0,12,15,2,2,2,2,2,2,2,2,2,2,6,6,6,6,2,2,2,2,2,2,2,2,2,2,2
2,2,2,2,2,5,5,5,5,5,2,2,2,2,2,2,2,2,2,2,2,2,2,2,2,2,2,2,2,2,2,2,2,2,2,2,6,6,6,5,5,5,2,2,2,2,2,2,2,2,2
2,2,2,2,5,5,5,5,5,5,2,2,2,2,2,2,2,2,2,2,2,2,2,2,2,2,2,2,2,2,2,2,2,2,2,2,6,6,5,5,5,5,5,5,5,2,2,2,2,2,2
2,2,5,5,5,5,5,5,5,5,2,2,2,2,2,2,2,2,2,2,2,2,2,2,2,2,2,2,2,2,2,2,2,2,2,2,2,2,5,5,5,5,5,5,5,5,2,2,2,2,2
2,5,5,5,5,5,5,5,5,2,2,2,2,2,2,2,2,2,2,2,2,2,2,2,2,2,2,2,2,2,2,2,2,2,2,2,2,2,2,5,5,5,5,5,5,5,2,2,2,2,2
2,5,5,5,5,5,2,2,2,2,2,2,2,2,2,2,2,2,2,2,2,8,2,2,2,2,2,2,2,2,2,2,2,2,2,2,2,2,2,2,2,2,2,5,2,2,2,2,2,2,2
2,5,5,5,5,5,5,2,2,2,2,2,2,2,2,2,2,2,2,2,2,2,2,2,2,2,2,2,2,2,2,2,2,2,2,2,2,2,2,2,2,2,2,2,2,2,7,7,7,2,2
2,5,5,5,5,5,2,2,2,2,2,2,2,2,2,2,2,2,2,2,2,2,2,2,2,2,2,2,2,2,2,2,2,2,2,2,2,2,2,2,2,2,2,2,7,7,7,7,7,2,2
2,2,2,2,2,2,2,2,2,2,2,2,2,2,2,2,2,2,2,2,2,2,2,2,2,2,2,2,2,2,2,2,2,2,2,2,2,2,2,2,2,2,2,7,7,7,7,7,7,2,2
2,2,2,2,2,2,2,2,2,2,2,2,2,2,2,2,2,2,2,2,2,2,2,2,2,2,2,2,2,2,2,2,2,2,2,2,2,2,2,2,2,2,2,7,7,7,7,7,2,2,2
2,2,2,2,2,2,2,2,2,2,2,2,2,2,2,2,2,2,2,2,2,2,2,2,2,2,2,2,2,2,2,2,2,2,2,2,2,2,2,2,2,2,7,7,7,7,7,7,2,2,2
:endlayer
layer: 8
2,2,2,2,2,2,2,2,2,2,2,2,2,2,2,2,2,2,2,2,2,2,2,2,2,6,2,2,2,2,2,2,2,2,2,2,2,2,2,2,2,2,2,2,2,2,2,2,2,2,2
2,2,2,2,2,2,2,2,2,2,2,2,2,2,2,2,2,2,2,2,2,2,2,2,2,6,6,2,2,2,2,2,2,2,2,2,2,2,2,2,2,2,6,6,6,6,2,2,2,2,2
2,2,2,2,2,2,2,2,2,2,2,2,2,2,2,2,2,2,2,2,2,2,2,2,2,6,2,3,2,2,2,2,2,2,2,2,2,2,2,2,2,2,6,6,6,6,6,6,6,2,2
2,2,2,2,2,2,8,5,5,2,2,2,2,2,2,2,2,2,2,2,2,2,2,2,2,2,2,2,2,2,2,2,2,2,2,2,2,2,2,2,2,2,2,6,6,6,6,6,6,6,6
2,2,2,2,2,8,5,5,5,2,2,2,2,2,3,2,2,2,2,2,2,2,2,2,2,11,2,2,2,2,2,2,2,2,2,2,2,2,2,2,2,2,2,2,2,2,2,6,6,6,6
2,2,2,2,2,2,0,0,0,2,2,2,2,2,2,2,2,2,2,2,2,2,2,2,2,2,2,2,3,2,2,2,2,2,2,2,2,2,2,2,2,2,2,2,2,2,2,6,6,6,6
2,2,2,2,2,2,0,0,5,5,2,2,2,2,2,2,2,2,2,2,2,2,2,2,2,2,2,2,2,2,2,2,2,2,2,2,2,2,2,2,2,2,2,2,2,2,2,6,6,6,6
2,2,2,2,2,2,0,5,0,5,2,2,2,4,4,4,2,2,2,2,2,2,2,2,2,2,2,2,2,2,2,2,2,2,2,2,8,2,2,2,2,2,2,2,2,2,2,6,6,6,6
2,2,2,2,2,2,5,5,5,5,2,2,2,4,4,2,2,2,2,2,2,2,2,2,2,2,2,2,2,2,2,2,2,2,2,2,8,2,2,2,2,2,2,2,2,2,6,6,6,6,6
2,2,2,2,2,2,5,5,5,5,2,2,4,4,4,2,2,2,2,2,2,2,2,2,2,2,2,2,2,2,2,2,2,2,2,2,2,2,2,2,2,2,2,2,2,2,6,6,6,6,6
2,2,2,2,2,2,2,5,5,5,2,2,4,4,4,2,2,2,2,2,2,2,2,2,2,2,2,2,2,2,2,2,2,2,2,2,2,2,2,2,2,2,2,2,2,2,2,6,6,6,6
2,2,2,2,2,2,2,2,5,2,2,2,2,2,2,2,2,2,2,2,2,2,7,7,7,7,2,2,2,2,2,2,2,2,2,2,2,2,2,2,2,2,2,2,2,2,2,6,6,6,6
2,2,2,2,2,2,2,2,2,2,2,2,2,2,2,2,2,2,2,2,2,7,7,7,7,7,2,2,2,2,2,2,2,2,2,2,2,2,2,2,2,2,2,2,2,2,2,6,6,6,6
2,7,2,2,2,2,2,2,2,2,2,2,2,2,2,2,2,2,7,7,7,7,7,7,7,7,2,5,2,2,2,2,6,2,2,2,2,2,2,2,2,2,2,2,2,2,2,2,6,6,6
2,7,2,3,3,2,2,2,2,2,2,2,2,2,2,2,2,7,7,7,7,7,7,7,7,7,2,2,2,2,2,2,6,6,2,2,2,2,2,2,2,2,2,2,2,2,2,2,2,6,6
2,7,7,3,3,2,2,2,2,2,2,2,2,2,2,2,2,7,7,7,7,7,7,7,7,2,2,2,2,2,2,2,6,6,6,2,2,2,2,2,2,2,2,2,2,2,6,6,6,6,2
2,7,7,2,2,2,2,2,2,2,2,2,2,2,2,2,2,2,7,7,7,7,7,7,7,2,2,2,2,2,2,2,6,6,6,2,2,2,2,2,2,2,2,2,2,6,6,6,6,6,6
2,7,7,2,2,2,2,2,2,2,2,2,2,2,2,2,2,2,2,2,2,2,7,0,0,0,20,21,2,2,2,2,6,6,6,6,2,2,2,2,2,2,2,2,6,6,6,6,6,6,6
2,7,2,2,2,2,2,2,2,2,2,2,2,2,2,2,2,2,2,2,2,0,0,0,0,0,20,21,2,2,2,2,6,6,6,6,2,2,2,2,2,2,2,2,6,6,6,6,6,6,6
2,7,2,2,2,2,2,2,2,2,2,2,2,2,2,2,2,2,2,2,0,0,0,0,0,0,20,21,2,2,2,2,6,6,6,6,2,2,2,2,2,2,2,6,6,6,6,6,6,6,6
2,2,2,2,2,2,2,2,2,2,2,2,2,2,2,2,2,2,2,0,0,0,0,0,0,0,0,0,2,2,2,2,22,5,6,6,2,2,2,2,2,2,2,6,6,6,6,6,2,6,6
2,2,2,2,2,2,2,2,3,2,2,2,2,2,2,2,2,2,0,0,0,0,0,0,0,0,0,0,0,0,2,2,22,22,5,6,7,7,7,7,2,6,6,6,6,8,2,2,7,7,6
2,2,2,2,2,2,2,2,3,2,2,2,2,2,2,2,2,2,0,0,0,0,0,0,0,0,0,0,0,0,0,2,22,22,5,6,7,7,7,7,7,6,6,6,6,8,3,7,7,7,7
2,7,7,7,2,2,2,2,2,2,2,2,2,2,2,2,2,0,0,0,0,0,0,0,0,0,0,0,0,0,0,2,22,22,22,6,7,7,7,7,7,6,6,6,6,7,7,7,7,7,6
2,7,7,7,7,7,2,2,2,2,2,2,2,2,2,2,2,0,0,0,0,0,0,0,0,0,0,0,0,0,0,0,2,22,22,6,6,7,7,7,7,6,6,6,6,7,7,7,7,7,6
2,7,7,7,7,7,7,2,2,2,2,2,2,2,2,2,2,0,0,0,0,0,0,0,0,0,0,0,0,0,0,0,2,22,22,6,6,6,2,2,6,6,6,6,7,7,7,7,7,7,6
2,7,7,7,2,2,2,2,2,2,2,2,2,2,2,2,2,0,0,0,0,0,0,0,0,0,0,0,0,0,0,0,7,6,6,6,6,6,6,2,6,6,6,6,7,7,7,2,2,2,2
2,5,8,8,7,7,7,2,2,2,2,2,2,2,2,2,2,0,0,0,0,0,0,0,0,0,0,0,0,0,0,0,7,6,5,6,6,6,6,6,6,6,6,6,2,2,2,2,2,2,2
2,5,8,8,7,7,7,6,6,6,2,2,2,2,2,2,2,0,0,0,0,0,0,0,0,0,0,0,0,0,0,2,2,6,6,6,6,6,6,6,6,6,6,6,2,2,2,2,2,2,2
2,5,7,7,0,0,12,6,6,6,6,2,2,2,2,2,8,2,0,0,0,0,0,0,0,0,0,0,0,0,0,2,2,6,6,6,6,6,6,6,6,6,6,6,2,2,2,2,2,2,2
2,5,7,7,0,0,15,6,6,6,6,2,2,2,2,2,2,2,0,0,0,0,0,0,0,0,0,0,0,0,2,2,2,2,6,6,6,6,6,6,6,6,6,2,2,2,2,2,2,2,2
2,2,7,7,0,0,0,2,6,6,2,2,2,2,2,2,2,2,2,0,0,0,0,0,0,0,0,0,2,2,2,2,2,2,6,6,6,6,6,6,6,6,6,6,2,2,2,2,2,2,2
2,2,2,7,0,0,0,2,2,2,2,2,2,2,2,2,2,2,2,2,0,0,0,0,0,2,2,2,2,2,2,2,2,6,6,6,6,6,6,6,6,6,6,6,2,2,2,2,2,2,2
2,2,2,2,0,0,0,2,2,2,2,2,2,2,2,2,2,2,2,2,2,2,2,2,3,2,8,8,2,2,2,6,6,6,6,6,6,6,6,6,6,6,6,6,2,2,2,2,2,2,2
2,2,2,2,0,0,0,2,2,2,2,2,7,7,2,2,2,2,2,2,2,2,2,2,2,2,8,8,2,2,2,6,6,6,6,6,6,6,6,6,6,6,6,2,2,2,2,2,2,2,2
2,2,2,2,2,2,2,2,2,2,2,7,7,7,2,2,2,2,2,2,2,2,2,2,2,2,2,2,2,2,6,6,6,6,6,6,6,6,6,6,6,6,2,2,2,2,2,2,2,2,2
2,2,2,2,2,2,2,2,2,2,2,7,7,7,2,2,2,2,2,2,2,2,2,2,2,2,2,2,2,6,6,6,6,6,6,6,6,6,6,6,6,6,6,2,2,2,2,2,2,2,2
2,2,2,2,2,2,2,2,2,2,2,7,7,2,2,2,2,2,2,2,2,3,2,2,2,2,2,2,2,6,6,6,6,6,6,2,2,6,6,6,6,6,6,2,2,6,6,6,2,2,6
2,2,2,2,2,2,2,2,2,2,2,7,2,2,2,2,2,2,2,2,2,2,2,0,0,0,2,2,2,6,6,6,6,6,2,2,6,6,6,6,6,6,6,2,2,6,6,2,2,2,2
2,2,2,2,2,2,2,2,2,2,7,2,2,2,2,2,2,2,2,2,2,2,2,0,0,0,2,2,6,6,6,6,6,2,2,2,6,6,6,6,6,6,2,2,2,2,2,2,2,2,2
2,2,2,2,2,2,2,2,2,2,2,2,2,2,2,2,2,2,2,2,2,2,2,0,0,12,2,2,6,6,6,6,6,2,2,6,6,6,6,6,6,6,2,2,2,2,2,2,2,2,2
2,2,2,2,2,2,2,2,2,2,2,2,2,2,2,2,2,2,2,2,2,2,2,2,2,6,6,6,6,6,6,6,6,2,6,6,6,6,6,6,6,2,2,2,2,2,2,2,2,2,2
2,2,2,2,2,5,5,5,2,2,2,2,2,2,2,2,2,2,2,2,2,2,2,2,6,6,6,6,6,6,6,6,6,6,6,6,6,6,6,6,6,5,5,5,5,2,2,2,2,2,2
2,3,2,2,5,5,5,5,2,2,2,2,2,2,2,2,2,2,2,2,2,2,2,2,6,6,6,6,6,6,6,6,6,6,6,6,6,6,6,6,5,5,5,5,5,5,2,2,2,2,2
2,5,2,5,5,2,5,2,2,2,2,2,2,2,2,2,2,2,2,2,2,8,8,2,2,6,6,6,6,6,6,6,6,6,6,6,6,6,6,2,2,2,5,5,5,5,2,2,2,2,2
2,5,5,5,5,2,2,2,2,2,2,2,2,2,2,2,2,2,2,2,2,8,8,2,2,2,2,2,2,2,2,6,6,6,6,6,2,2,2,2,2,2,2,2,2,2,2,2,2,2,2
2,5,5,5,5,9,2,2,2,2,2,2,2,2,2,2,2,2,2,2,2,2,2,2,2,2,2,2,2,2,2,2,2,2,2,2,2,2,2,2,2,2,2,2,2,2,7,7,7,2,2
2,4,4,2,9,9,2,2,2,2,2,2,2,2,2,2,2,2,2,2,2,2,2,2,2,2,2,2,2,2,2,2,2,2,2,2,2,2,2,2,2,2,2,2,2,7,7,7,7,2,2
2,4,2,2,2,2,2,2,2,2,2,2,2,2,2,2,2,2,2,2,2,2,2,2,2,2,2,2,2,2,2,2,2,2,2,2,2,2,2,2,2,2,2,2,7,7,7,7,7,2,2
2,2,2,2,2,2,2,2,2,2,2,2,2,2,2,2,2,2,2,2,2,2,2,2,2,2,2,2,2,2,2,2,2,2,2,2,2,2,2,2,2,2,2,7,7,7,7,7,2,2,2
2,2,2,2,6,6,2,2,2,2,2,2,2,2,2,2,2,2,2,2,2,2,2,2,2,2,2,2,2,2,2,2,2,2,2,2,2,2,2,2,2,2,2,7,7,7,7,2,2,2,2
:endlayer
layer: 9
2,2,2,2,2,2,2,2,2,2,2,2,2,2,2,2,2,2,2,2,2,2,2,2,2,6,6,6,6,4,4,2,2,2,2,2,2,2,2,2,2,2,2,2,2,2,2,2,2,2,2
2,2,2,2,2,2,2,2,2,2,2,2,2,2,2,2,2,2,2,2,2,4,2,2,2,6,6,6,4,4,4,8,8,2,2,2,2,2,2,2,2,2,2,2,2,2,2,2,2,2,2
2,2,2,2,2,2,2,2,2,2,2,2,2,2,2,2,2,2,2,2,2,4,4,2,2,6,6,2,2,2,2,8,8,2,2,2,2,2,2,2,2,2,2,2,2,2,2,2,2,2,2
2,2,2,2,2,2,2,2,2,2,2,2,2,2,2,2,2,2,2,2,2,2,2,2,2,6,2,2,2,2,2,2,2,2,2,2,2,2,2,2,2,2,2,2,2,2,2,3,2,2,2
2,2,2,2,2,2,2,2,2,2,2,2,2,2,2,2,2,2,2,2,2,2,2,2,2,2,2,2,2,2,2,2,2,2,2,2,2,2,2,2,2,2,2,2,2,2,2,2,3,6,6
2,2,2,2,2,2,2,2,2,2,2,2,2,2,2,7,7,7,2,2,2,2,2,2,2,2,2,2,3,2,2,2,2,2,2,2,2,2,2,2,2,2,2,2,2,2,2,2,6,6,6
2,2,2,2,2,2,2,0,0,2,2,2,2,2,2,7,7,7,2,2,2,2,2,2,2,2,2,2,2,2,2,2,2,2,2,2,2,2,2,2,2,2,2,2,2,2,2,2,6,6,6
2,2,2,2,2,2,2,0,0,2,2,2,2,2,2,7,7,2,2,2,2,2,2,2,2,2,2,2,2,2,2,2,2,2,2,2,2,2,2,2,2,2,2,2,2,2,2,6,6,6,6
2,2,2,2,2,2,2,5,5,2,2,2,2,2,2,7,7,2,2,2,2,2,2,2,2,2,2,2,2,2,2,2,2,2,2,2,2,2,2,2,2,2,2,2,2,2,2,6,6,6,6
2,2,2,2,2,2,2,5,5,2,2,2,2,2,2,2,2,2,2,2,2,2,2,2,2,2,2,2,2,2,2,2,2,2,2,2,2,2,2,2,2,2,2,2,2,2,2,6,6,6,6
2,22,2,2,2,2,2,2,2,2,2,2,2,2,8,2,2,2,2,2,2,2,5,5,5,5,2,2,2,2,2,2,2,2,2,2,2,2,2,2,2,2,2,2,2,2,2,6,6,6,6
2,22,2,2,2,2,2,2,2,2,2,2,2,2,2,2,2,2,2,2,2,2,5,7,7,7,5,5,2,2,2,2,2,2,2,2,2,2,2,2,2,2,2,2,2,2,2,2,6,6,6
2,22,2,2,2,2,2,2,2,2,2,2,2,2,2,2,2,2,2,2,2,7,7,7,7,7,5,5,5,2,2,2,2,2,2,2,2,2,2,2,2,2,2,2,2,2,2,2,6,6,6
2,7,2,2,2,2,2,2,2,2,2,2,2,2,2,2,2,2,2,2,7,7,7,7,7,7,5,5,5,5,2,2,2,2,2,2,2,2,2,2,2,2,2,2,2,2,2,2,2,6,6
2,7,2,2,2,2,2,2,2,2,2,2,2,2,2,2,2,2,7,7,7,7,7,7,7,2,5,5,5,5,2,2,2,2,2,2,2,2,2,2,2,2,2,2,2,2,2,2,2,2,2
2,7,7,2,2,2,2,2,2,2,2,2,2,2,2,2,2,2,7,7,7,7,7,7,2,22,22,22,5,5,2,2,2,2,2,2,2,2,2,2,2,2,2,2,2,2,2,2,2,2,2
2,7,7,2,2,2,2,2,2,2,2,2,2,2,2,2,2,2,2,2,2,2,2,2,2,2,2,2,2,22,2,2,2,2,2,2,2,2,2,2,2,2,2,2,2,2,6,6,2,2,22
2,7,7,2,2,2,2,2,2,2,2,2,2,2,2,2,2,2,2,2,2,2,2,0,0,0,0,0,0,2,2,2,2,6,6,2,2,2,2,2,2,2,2,2,2,6,22,22,22,22,22
2,7,2,2,2,2,2,2,2,2,2,2,2,2,2,2,2,2,2,2,2,0,0,0,0,0,0,0,0,0,0,2,2,6,6,2,2,2,2,2,2,2,2,2,6,22,22,22,22,22,22
2,7,2,2,2,2,2,2,2,2,2,2,2,2,2,2,2,2,2,2,0,0,0,0,0,0,0,0,0,0,0,0,2,6,6,2,2,2,2,2,2,2,2,6,22,22,22,22,22,22,22
2,2,2,2,2,2,2,2,2,2,2,2,2,2,2,2,2,2,2,0,0,0,0,0,0,0,0,0,0,0,0,0,0,5,6,2,2,2,2,2,2,2,2,22,22,22,22,22,22,22,22
2,2,2,2,2,2,2,2,2,2,2,2,2,2,2,2,2,2,0,0,0,0,0,0,0,0,0,0,0,0,0,0,0,0,5,7,7,7,7,2,2,6,6,6,6,2,2,2,2,7,22
2,2,2,2,2,2,2,2,2,2,2,2,2,2,2,2,2,2,0,0,0,0,0,0,0,0,0,0,0,0,0,0,0,0,5,7,7,7,7,7,2,6,6,6,6,2,2,2,7,7,22
2,2,2,2,2,2,2,2,2,2,2,2,2,2,2,2,2,0,0,0,0,0,0,0,0,0,0,0,0,0,0,0,0,0,0,7,7,7,7,7,2,6,6,6,6,7,7,7,7,7,22
2,7,7,7,2,2,2,2,2,2,2,2,2,2,2,2,2,0,0,0,0,0,0,0,0,0,0,0,0,0,0,0,0,0,0,2,2,7,7,7,6,6,6,6,6,7,7,7,7,7,22
2,7,7,7,2,2,2,2,2,2,2,2,2,2,2,2,2,0,0,0,0,0,0,0,0,0,0,0,0,0,0,0,23,23,23,7,6,2,2,2,6,6,6,6,6,7,7,7,2,2,2
2,5,5,2,2,7,7,7,2,2,2,2,2,2,2,2,2,0,0,0,0,0,0,0,0,0,0,0,0,0,0,0,2,22,22,6,6,6,2,2,6,6,6,6,2,2,2,2,2,2,2
2,5,5,7,7,7,7,7,2,2,2,2,2,2,2,2,2,0,0,0,0,0,0,0,0,0,0,0,0,0,0,0,2,2,5,6,6,6,6,2,6,6,6,6,2,2,2,2,2,2,2
2,5,5,7,7,7,7,2,22,22,6,2,2,2,2,8,8,0,0,0,0,0,0,0,0,0,0,0,0,0,0,2,2,2,6,6,6,6,6,6,6,6,6,6,2,2,2,2,2,2,2
2,5,5,7,0,0,0,22,22,22,22,2,2,2,2,8,8,2,0,0,0,0,0,0,0,0,0,0,0,0,0,2,2,2,6,6,6,6,6,6,6,6,6,6,2,2,2,2,2,2,2
2,5,5,7,0,0,12,6,22,22,22,2,2,2,2,2,2,2,0,0,0,0,0,0,0,0,0,0,0,0,2,2,2,2,6,6,6,6,6,6,6,6,6,2,2,2,2,2,2,2,2
2,5,7,7,0,0,0,2,6,22,2,2,2,2,2,2,2,2,2,0,0,0,0,0,0,0,0,0,2,2,2,2,2,2,6,6,6,6,6,6,6,6,6,2,2,2,2,2,2,2,2
2,5,7,7,7,2,2,2,2,2,2,2,2,7,2,2,2,2,2,2,0,0,0,2,2,2,2,2,2,2,2,2,2,6,6,6,6,6,6,6,6,6,6,2,2,2,2,2,2,2,2
2,7,7,2,2,2,2,2,2,2,2,2,7,7,7,2,2,2,2,2,2,2,2,2,3,2,2,2,2,2,2,6,6,6,6,6,6,6,6,6,6,6,6,2,2,2,2,2,2,2,2
2,2,2,2,2,2,2,2,2,2,2,7,7,7,7,2,2,2,2,2,2,2,2,2,3,2,2,2,2,2,6,6,6,6,6,6,6,6,6,6,6,6,6,2,2,2,2,2,2,2,2
2,2,2,2,2,2,2,2,2,2,2,7,7,7,7,2,2,2,2,2,2,2,2,2,2,2,2,2,2,2,6,6,6,6,6,6,6,6,6,6,6,6,6,2,2,2,2,2,2,2,2
2,2,2,2,2,2,2,2,2,2,7,7,7,7,2,2,2,2,2,2,3,3,2,2,2,2,2,2,2,6,6,6,6,6,6,6,6,6,6,6,6,6,6,2,2,2,2,2,2,2,2
2,2,2,2,2,2,6,6,6,2,7,7,7,7,2,3,3,2,2,2,3,3,2,2,2,2,2,2,2,6,6,6,6,6,6,2,2,2,6,6,6,6,6,2,2,2,2,2,2,2,6
2,2,2,2,2,2,2,6,6,2,7,7,7,2,2,3,3,2,2,2,2,2,2,2,2,2,2,2,6,6,6,6,6,6,2,2,2,6,6,6,6,6,6,2,2,2,2,2,2,2,2
2,2,2,2,2,2,6,6,6,7,7,7,2,2,2,2,2,2,2,2,2,2,2,2,2,2,2,2,6,6,6,6,6,6,2,2,6,6,6,6,6,6,6,2,2,2,2,2,2,2,2
2,2,2,2,2,6,6,6,6,2,7,7,2,2,2,2,2,2,2,2,2,2,2,2,2,2,2,2,6,6,6,6,6,9,9,6,6,6,6,6,6,6,6,2,2,2,2,2,2,2,2
2,2,2,2,6,6,6,6,6,2,7,2,2,2,2,2,2,2,2,2,2,6,6,6,6,6,6,6,6,6,6,6,6,6,6,6,6,6,6,6,6,6,6,2,2,2,2,2,2,2,2
2,3,3,6,6,6,6,6,2,2,2,2,2,2,2,2,2,2,2,2,5,6,6,6,6,6,6,6,6,6,6,6,6,6,6,6,6,6,6,6,6,6,2,2,2,2,2,2,2,2,2
2,3,3,6,6,6,6,2,2,2,2,2,2,2,2,3,2,2,2,2,2,6,6,6,6,6,6,6,6,6,6,6,6,6,6,6,6,6,6,6,6,2,2,5,2,2,2,2,2,2,2
2,2,2,6,6,6,6,2,2,2,2,2,2,2,2,2,2,2,2,2,2,8,8,6,6,6,6,6,6,7,7,6,6,6,6,6,6,6,6,6,2,2,2,2,2,2,2,2,2,2,2
2,2,2,6,5,6,6,2,2,2,2,2,2,2,2,2,2,2,2,2,2,8,8,2,2,2,2,2,2,7,7,7,6,6,6,6,6,2,2,2,2,2,2,2,2,2,2,2,2,2,2
2,4,4,5,5,5,5,2,2,2,2,2,2,2,2,2,2,2,2,2,2,2,2,2,2,2,2,2,2,2,2,2,8,8,2,2,2,2,2,2,2,2,2,2,2,2,2,2,2,2,2
2,4,4,5,5,6,6,2,2,2,2,2,2,2,2,2,2,2,2,2,2,2,2,2,2,2,2,2,2,2,2,2,8,8,2,2,2,2,2,2,2,2,2,2,2,2,7,7,2,2,2
2,4,2,6,6,6,6,2,2,2,2,2,2,2,2,2,2,2,2,2,2,2,2,2,2,2,2,2,2,2,2,2,2,2,2,2,2,2,2,2,2,2,2,2,2,2,7,2,2,2,2
2,2,2,6,6,6,6,2,2,2,2,2,2,2,2,2,2,2,2,2,2,2,2,2,2,2,2,2,2,2,2,2,2,2,2,2,2,2,2,2,2,2,2,2,2,7,7,2,2,2,2
2,2,2,2,6,6,6,2,2,2,2,2,2,2,2,2,2,2,2,2,2,2,2,2,2,2,2,2,2,2,2,2,2,2,2,2,2,2,2,2,2,2,2,2,2,2,2,2,2,2,2
:endlayer
layer: 10
2,2,2,2,2,2,2,2,2,2,2,2,2,2,2,2,2,2,2,2,2,2,2,2,2,0,0,0,0,4,4,2,2,2,2,2,2,2,2,2,2,2,2,2,2,2,2,2,2,2,2
2,2,2,2,2,2,2,2,2,2,2,2,2,2,2,2,2,2,2,2,2,4,2,2,2,0,0,0,0,4,4,8,2,2,2,2,2,2,2,2,2,2,2,2,2,2,2,2,2,2,2
2,2,2,2,2,2,2,2,2,2,2,8,2,2,2,2,2,2,2,2,2,4,4,4,2,0,0,2,2,4,2,10,2,2,2,2,2,2,2,2,2,2,2,2,2,2,2,2,2,2,2
2,2,2,2,2,2,2,2,2,2,8,2,2,2,2,2,7,7,2,2,2,2,4,4,4,2,2,2,2,2,10,2,2,2,2,2,2,2,2,2,2,2,2,2,2,2,2,2,2,2,2
2,2,2,2,2,2,2,2,2,2,2,2,2,2,2,7,7,7,2,2,2,2,2,4,4,2,2,2,2,2,2,2,2,2,2,2,2,2,2,2,2,2,2,2,2,2,2,2,2,2,2
2,2,2,2,2,2,2,2,2,2,2,2,2,2,2,7,7,7,2,2,2,2,2,2,2,2,2,2,2,2,2,2,2,2,2,2,2,2,2,2,2,2,2,2,2,2,2,2,2,2,0
2,2,2,2,2,2,2,2,2,2,2,0,0,2,7,7,7,7,7,2,2,2,2,2,2,2,2,2,2,3,2,2,2,2,2,2,2,2,2,2,2,2,2,2,2,2,2,2,2,0,0
2,2,2,2,2,2,2,2,2,2,0,0,0,0,0,0,7,7,2,2,2,2,2,2,2,2,2,2,2,2,2,2,2,2,2,2,2,2,2,2,2,2,2,2,2,2,2,2,2,0,0
2,2,2,2,0,0,0,2,2,2,0,0,0,0,0,0,0,7,2,2,2,2,2,2,2,2,2,2,2,2,2,2,2,2,2,2,2,2,2,2,2,0,2,2,2,2,2,2,2,0,0
2,24,0,0,0,0,0,0,0,2,2,0,0,0,0,0,0,0,2,2,2,2,2,2,2,2,2,2,2,2,2,2,2,2,2,2,2,2,2,2,2,0,2,2,2,2,2,2,0,0,0
2,25,0,0,0,0,0,0,0,0,2,2,0,0,0,0,0,2,2,2,2,2,5,5,5,5,5,2,2,2,2,2,2,2,2,2,2,2,2,2,2,0,0,2,2,2,2,2,0,0,0
2,26,0,0,0,0,0,0,0,2,2,2,2,0,0,0,2,2,2,2,2,2,5,5,5,5,5,5,5,2,2,2,2,2,2,2,2,2,2,2,2,0,0,2,2,2,2,2,0,0,0
2,27,0,0,0,0,0,0,2,2,2,2,2,2,2,2,2,2,2,2,2,2,2,7,7,5,5,5,5,5,2,2,2,2,2,2,2,2,2,2,2,0,2,2,2,2,2,2,2,2,0
2,28,0,0,0,0,0,2,2,2,2,2,2,2,2,2,2,2,2,2,2,2,7,7,7,5,5,5,5,5,5,2,2,2,2,2,2,2,2,2,2,2,2,2,2,2,2,2,2,2,2
2,0,0,0,2,2,2,2,2,2,2,2,2,2,2,2,2,2,2,2,2,2,2,7,2,2,5,5,5,5,5,2,2,2,2,2,2,2,2,2,2,2,2,0,0,2,2,2,2,2,2
2,7,2,2,2,2,2,2,2,2,2,2,2,2,2,2,2,2,2,2,2,2,2,2,2,21,21,0,0,0,5,2,2,2,2,2,2,2,2,2,2,2,0,0,0,0,2,2,2,2,2
2,7,7,2,2,2,2,2,2,2,2,2,2,2,2,2,2,2,2,2,2,2,2,2,2,2,2,2,2,21,2,2,2,2,2,2,2,2,2,2,2,2,0,0,0,0,0,2,2,2,0
2,7,2,2,2,2,3,2,2,2,2,2,2,2,2,2,2,0,0,0,2,2,2,0,0,0,0,0,0,2,2,2,2,2,2,2,2,2,2,2,2,2,0,0,0,0,0,0,0,0,0
2,7,2,2,2,2,2,2,2,2,2,2,2,2,2,2,2,0,0,0,2,0,0,0,0,0,0,0,0,0,0,2,2,2,2,2,2,2,2,2,2,2,2,0,0,0,0,0,0,0,0
2,7,2,2,2,2,2,2,2,2,2,2,2,2,2,2,2,0,0,2,0,0,0,0,0,0,0,0,0,0,0,0,2,2,2,2,2,2,2,2,2,2,2,2,0,0,0,0,0,0,0
2,2,2,2,2,2,2,2,2,2,2,2,2,2,2,2,2,2,2,0,0,0,0,0,0,0,0,0,0,0,0,0,0,2,2,2,2,2,2,2,2,2,2,0,0,0,0,0,0,0,0
2,2,2,2,2,2,2,2,2,2,2,2,2,2,2,2,2,2,0,0,0,0,0,0,0,0,0,0,0,0,0,0,0,0,2,2,2,2,2,2,2,2,0,0,8,2,2,2,2,2,0
2,2,2,2,2,2,2,2,2,2,2,2,2,2,2,2,2,2,0,0,0,0,0,0,0,0,0,0,0,0,0,0,0,0,2,2,2,2,2,2,2,0,0,0,2,2,2,2,2,7,0
2,5,5,2,2,2,2,2,2,2,2,2,2,2,2,2,2,0,0,0,0,0,0,0,0,0,0,0,0,0,0,0,0,0,0,2,2,2,2,2,2,0,0,0,2,2,2,2,7,7,0
2,5,5,2,2,2,2,2,2,2,2,2,2,2,2,2,2,0,0,0,0,0,0,0,0,0,0,0,0,0,0,0,0,0,0,2,2,2,2,2,2,0,0,0,2,2,2,2,2,7,0
2,5,5,2,2,2,2,2,2,2,2,2,2,2,2,2,2,0,0,0,0,0,0,0,0,0,0,0,0,0,0,0,0,0,0,2,2,2,2,2,2,0,0,0,2,2,2,2,2,2,0
2,5,5,2,2,7,7,7,2,2,2,2,2,2,2,2,2,0,0,0,0,0,0,0,0,0,0,0,0,0,0,0,23,23,23,2,2,2,2,2,0,0,0,0,2,2,2,2,2,2,0
2,5,5,7,7,7,7,7,0,21,18,2,2,2,2,2,2,0,0,0,0,0,0,0,0,0,0,0,0,0,0,0,2,2,2,2,2,2,2,2,0,0,0,0,2,2,2,2,2,2,2
2,5,5,7,7,7,7,2,0,0,21,0,0,2,2,8,2,0,0,0,0,0,0,0,0,0,0,0,0,0,0,2,2,2,2,2,2,2,2,0,0,0,0,0,2,2,2,2,2,2,2
2,5,5,7,7,7,7,0,0,0,0,0,0,2,2,2,2,2,0,0,0,0,0,0,0,0,0,0,0,0,0,2,2,2,2,2,2,2,2,0,0,0,0,0,2,2,2,2,2,2,2
2,5,5,7,7,7,7,2,0,0,0,0,2,2,2,2,2,2,0,0,0,0,0,0,0,0,0,0,0,0,2,2,2,2,2,2,0,0,0,0,0,0,0,2,2,2,2,2,2,2,2
2,5,7,7,7,7,2,2,2,0,2,2,2,2,2,2,2,2,2,0,0,0,0,0,0,0,0,0,2,2,2,2,2,2,2,0,0,0,0,0,0,0,0,2,2,2,2,2,2,2,2
2,5,7,7,7,2,2,2,2,2,2,2,2,7,2,2,2,2,2,2,0,0,0,2,2,2,2,2,2,2,2,2,2,0,0,0,0,0,0,0,0,2,2,2,2,2,2,2,2,2,2
2,7,7,2,2,2,2,2,2,2,2,2,7,7,7,2,2,2,2,2,2,2,2,2,2,2,2,2,2,2,2,2,0,0,0,0,0,0,0,0,0,0,2,2,2,2,2,2,2,2,2
2,2,2,2,2,2,2,2,2,2,2,7,7,7,7,2,2,2,2,2,2,2,2,5,2,2,2,2,2,2,2,0,0,0,0,0,0,0,0,0,0,0,2,2,2,2,2,2,2,2,2
2,2,2,2,2,2,2,2,2,2,2,7,7,7,7,2,2,2,2,2,2,2,2,5,2,2,2,2,2,2,0,0,0,0,0,0,0,0,0,0,0,0,2,2,2,2,2,2,2,2,2
2,2,2,2,2,2,2,2,2,2,7,7,7,7,2,2,2,2,2,2,3,2,2,2,2,2,2,2,2,0,0,0,0,0,0,0,0,0,0,0,0,0,2,2,2,2,2,2,2,2,2
2,2,2,2,2,2,0,0,0,2,7,7,7,7,2,2,2,2,2,2,2,2,2,2,2,2,2,2,2,0,0,0,0,0,0,2,2,2,2,0,0,0,0,2,2,2,2,2,2,2,2
2,2,2,2,2,2,0,0,0,2,7,7,7,2,2,2,2,2,2,2,2,2,2,2,2,2,2,2,0,0,0,0,0,0,2,2,2,2,2,0,0,0,0,2,2,2,2,2,2,2,2
2,2,2,2,2,2,0,0,0,7,7,7,2,2,2,2,2,2,2,2,2,2,2,2,2,2,2,2,0,0,0,0,0,2,2,2,2,0,0,0,0,0,0,2,2,2,2,2,2,2,2
2,2,2,2,2,0,0,0,0,2,7,7,0,0,2,2,2,2,0,2,2,0,0,2,2,2,2,2,0,0,0,0,0,9,9,2,0,0,0,0,0,0,0,2,2,2,2,2,2,2,2
2,2,2,2,0,0,0,0,0,2,7,2,2,2,2,2,0,0,5,5,0,0,0,0,0,0,0,0,0,0,0,0,0,0,0,0,0,0,0,0,0,0,0,2,2,2,2,2,2,2,2
2,2,3,0,0,0,0,0,0,2,2,2,2,2,2,2,0,0,5,5,5,0,0,0,0,0,0,0,0,0,0,0,0,0,0,0,0,0,0,0,0,0,2,2,2,2,2,2,2,2,2
2,2,2,0,0,0,0,0,0,2,2,2,2,2,2,2,0,0,5,5,5,0,0,0,0,0,0,0,0,0,0,0,0,0,0,0,0,0,0,0,0,2,2,2,2,2,2,2,2,2,2
2,2,2,0,0,0,0,0,2,2,2,2,2,2,2,2,2,2,0,0,0,0,0,0,0,0,0,0,0,0,0,0,0,0,0,0,0,0,0,0,2,2,2,2,2,2,2,2,2,2,2
2,2,2,0,0,0,0,0,2,2,2,2,2,2,2,2,2,2,0,0,0,0,0,0,0,2,2,2,2,7,7,0,0,0,0,0,0,2,2,2,2,2,2,2,2,2,2,2,2,2,2
2,2,2,0,0,0,0,0,2,0,0,0,2,2,2,2,2,2,0,0,0,0,21,21,21,2,2,2,2,2,0,0,0,0,0,7,0,2,2,2,2,2,2,2,2,2,2,2,2,2,2
2,2,2,0,0,0,0,0,2,0,0,0,2,2,2,2,2,2,2,2,2,0,0,0,16,2,2,2,2,2,2,2,2,2,2,2,0,0,0,0,0,0,0,0,0,0,0,0,0,0,0
2,2,2,0,0,0,0,0,2,0,0,0,2,2,2,2,2,2,2,2,2,2,0,16,17,2,2,2,2,2,2,2,2,2,2,2,2,2,2,0,2,2,2,2,2,0,2,2,2,2,2
2,2,2,0,0,0,0,0,2,2,0,2,2,2,2,2,2,2,2,2,3,3,0,17,12,2,2,2,2,2,2,2,2,2,2,2,2,2,2,0,2,2,2,2,2,0,2,2,2,2,2
2,2,2,2,0,0,0,0,2,2,2,2,2,2,2,2,2,2,2,2,2,2,2,12,15,2,2,2,2,2,2,29,0,2,2,2,2,2,2,0,2,2,2,2,2,0,2,2,2,2,2
:endlayer
layer: 11
2,2,2,2,2,2,2,2,2,2,2,2,2,2,2,2,2,2,2,2,2,2,2,2,7,7,0,0,0,4,2,2,2,2,2,2,2,2,2,2,2,2,2,2,2,2,2,2,2,2,2
2,2,2,2,2,2,2,2,2,2,2,2,2,2,2,2,2,2,2,2,2,2,2,2,2,0,0,0,7,4,2,2,2,2,2,2,2,2,2,2,2,2,2,2,2,2,2,2,2,2,2
2,2,2,2,2,2,2,2,2,2,2,8,2,2,2,2,2,2,2,2,2,2,2,2,2,2,2,2,2,2,2,10,2,2,2,2,2,2,2,2,2,2,2,2,2,2,2,2,2,2,2
2,2,2,2,2,2,2,2,2,2,8,2,2,2,2,2,7,7,2,2,2,2,2,4,4,2,2,2,2,2,10,2,2,2,2,2,2,2,2,2,2,2,2,2,2,2,2,2,2,2,2
2,2,2,2,2,2,2,2,2,2,2,2,2,2,2,7,7,7,2,2,2,2,2,2,4,2,2,2,2,2,2,2,2,2,2,2,2,2,2,2,2,2,2,2,2,2,2,2,2,2,2
2,2,2,2,2,2,2,2,0,0,0,0,0,2,7,7,7,7,7,0,2,2,2,2,2,2,2,2,2,2,2,2,2,2,2,2,2,2,2,2,2,2,2,2,2,2,2,2,2,2,0
2,2,2,2,2,2,2,2,2,0,0,0,0,0,7,0,0,0,0,0,0,0,2,2,2,2,2,2,2,3,2,2,2,2,2,2,2,2,2,2,2,2,2,2,2,2,2,2,2,0,0
2,2,2,2,2,2,2,2,2,0,0,0,0,0,0,0,0,0,0,0,0,0,2,2,2,2,2,2,2,2,2,2,2,2,2,2,2,2,2,2,2,0,2,2,2,2,2,2,2,0,0
2,0,0,0,0,0,0,0,0,2,0,0,0,0,0,0,0,0,0,0,0,0,2,2,2,2,2,2,2,2,2,2,2,2,2,2,2,2,2,2,2,0,2,2,2,2,2,2,2,0,0
2,0,0,0,0,0,0,0,0,2,0,0,0,0,0,0,0,0,0,0,0,2,2,2,2,2,2,2,2,2,2,2,2,2,2,2,2,2,2,2,2,0,0,2,2,8,8,2,0,0,0
2,0,0,0,0,0,0,0,0,0,2,0,0,0,0,0,0,0,2,2,2,2,2,2,5,5,2,2,2,2,2,2,2,2,2,2,2,2,2,2,2,0,0,2,2,8,8,2,0,0,0
2,0,0,0,0,0,0,0,0,2,2,2,0,0,0,0,0,2,2,2,2,2,2,5,5,5,5,5,2,2,2,2,2,2,2,2,2,2,2,2,2,0,0,0,2,2,2,2,0,0,0
2,0,0,0,0,0,0,0,0,2,2,2,0,0,0,0,0,2,2,2,2,2,2,5,5,5,5,5,5,5,2,2,2,2,2,2,2,2,2,2,2,0,0,0,2,2,2,2,0,0,0
2,0,0,0,0,0,0,0,0,2,2,2,2,0,0,0,0,0,2,2,2,2,2,2,2,5,5,5,5,5,5,2,2,2,2,2,2,2,2,2,2,0,0,0,2,2,7,2,2,0,0
2,0,0,0,0,0,0,2,2,2,2,2,2,0,0,0,0,0,2,2,2,2,2,2,2,2,5,5,0,5,5,2,2,2,2,2,2,2,2,2,2,0,0,0,0,2,7,7,7,2,2
2,2,2,2,2,2,2,2,2,2,2,2,2,2,0,0,0,0,0,2,2,2,2,2,2,2,2,2,0,0,5,2,2,2,2,2,2,2,2,2,2,0,0,0,0,0,7,7,7,7,2
2,2,2,2,2,2,2,2,2,2,2,2,2,2,2,0,0,0,0,0,2,2,2,2,2,2,2,2,2,2,2,2,2,2,2,2,2,2,3,2,2,0,0,0,0,0,0,0,7,7,2
2,2,2,2,2,2,3,3,2,2,2,2,2,2,2,2,0,0,0,0,2,2,2,0,0,0,0,0,0,2,2,2,2,2,2,2,2,2,2,2,2,2,0,0,0,0,0,0,0,0,0
2,2,2,2,2,2,3,3,2,2,2,2,2,2,2,2,0,0,0,0,2,0,0,0,0,0,0,0,0,0,0,2,2,2,2,2,2,2,2,2,2,2,5,0,0,0,0,0,0,0,0
2,2,2,2,2,2,2,2,2,2,2,2,2,2,2,2,0,0,0,5,0,0,0,0,0,0,0,0,0,0,0,0,2,2,2,2,2,2,2,2,2,2,2,2,2,0,0,0,0,0,0
2,2,2,2,2,2,2,2,2,2,2,2,2,2,2,2,0,0,5,0,0,0,0,0,0,0,0,0,0,0,0,0,0,2,2,2,2,2,2,2,2,2,2,2,2,0,0,0,0,0,0
2,2,2,2,2,2,2,2,2,2,2,2,2,2,2,2,2,2,0,0,0,0,0,0,0,0,0,0,0,0,0,0,0,0,2,2,2,2,2,2,2,2,2,2,2,2,2,2,2,2,0
2,2,2,2,2,2,2,2,2,2,2,2,2,2,2,2,2,2,0,0,0,0,0,0,0,0,0,0,0,0,0,0,0,0,2,2,2,2,2,2,2,2,2,2,2,2,2,2,2,2,0
2,5,5,2,2,2,2,2,2,2,2,2,2,2,2,2,2,0,0,0,0,0,0,0,0,0,0,0,0,0,0,0,0,0,0,2,2,2,2,2,2,2,2,2,2,2,2,2,2,2,0
2,5,5,2,2,2,2,2,2,0,15,2,2,2,2,2,2,0,0,0,0,0,0,0,0,0,0,0,0,0,0,0,0,0,0,2,2,2,2,2,2,2,2,2,2,2,2,2,2,2,0
2,5,5,2,2,2,2,2,2,0,12,2,2,2,2,2,21,0,0,0,0,0,0,0,0,0,0,0,0,0,0,0,0,0,0,2,2,2,2,2,2,2,2,2,2,2,2,2,2,2,0
2,5,5,2,2,2,2,2,2,0,17,2,2,2,2,2,21,0,0,0,0,0,0,0,0,0,0,0,0,0,0,0,0,0,0,2,2,2,2,2,2,2,0,2,2,2,2,2,2,2,0
2,5,5,2,7,7,7,2,0,0,16,0,0,7,5,5,2,0,0,0,0,0,0,0,0,0,0,0,0,0,0,0,0,0,0,2,2,2,2,2,2,0,2,2,2,2,2,2,2,2,2
2,5,5,7,7,7,7,2,0,0,0,0,0,7,5,5,5,0,0,0,0,0,0,0,0,0,0,0,0,0,0,0,0,0,0,2,2,2,2,2,0,0,0,2,2,2,4,2,2,2,2
2,5,5,7,7,7,7,2,0,0,0,0,0,7,5,5,5,5,0,0,0,0,0,0,0,0,0,0,0,0,0,0,0,0,2,2,2,2,2,0,0,0,0,2,2,2,4,10,2,2,2
2,5,5,7,7,7,2,2,0,0,0,0,0,7,5,2,2,2,0,0,0,0,0,0,0,0,0,0,0,0,0,0,0,0,2,2,2,2,2,0,0,0,0,2,2,4,4,2,10,2,2
2,5,7,7,7,2,2,2,2,0,0,2,2,2,2,2,2,2,2,0,0,0,0,0,0,0,0,0,0,0,0,0,0,2,2,2,2,0,0,0,0,0,2,2,2,2,2,2,2,2,2
2,2,2,7,2,2,2,2,2,2,2,2,2,2,2,2,2,2,2,2,0,0,0,5,30,0,0,0,0,0,0,0,2,2,2,2,0,0,0,3,3,2,2,2,2,2,2,2,2,2,2
2,2,2,2,2,2,2,2,2,2,2,2,2,2,2,2,2,2,2,2,2,2,5,2,30,0,0,0,0,0,0,2,2,2,2,2,0,2,2,2,2,2,2,2,2,2,2,2,2,2,2
2,2,2,2,2,2,2,2,2,2,2,2,7,7,2,2,2,2,2,2,5,5,5,5,30,0,0,0,0,2,2,2,0,0,0,2,0,0,0,0,0,2,2,2,2,2,2,2,2,2,2
2,2,2,2,2,2,2,2,2,2,2,7,7,7,2,2,2,2,2,5,5,5,2,5,2,2,2,2,2,2,2,0,0,0,0,0,0,0,0,0,0,2,2,2,2,2,2,2,2,2,2
2,2,2,2,2,2,2,2,2,2,2,7,7,7,2,2,2,2,2,2,5,2,2,2,2,2,2,2,2,2,0,0,0,0,0,0,0,0,0,0,0,2,2,2,2,2,2,2,2,2,2
2,2,2,2,2,2,0,0,0,2,2,7,7,2,2,2,2,2,2,2,2,2,2,2,2,2,2,2,2,0,0,0,0,0,2,2,2,2,2,0,0,0,2,2,2,2,2,2,2,2,2
2,2,2,2,2,2,0,0,0,2,2,7,2,2,2,2,2,2,2,2,2,2,2,2,2,2,2,2,2,0,0,0,0,2,2,2,2,2,2,0,0,0,2,2,2,2,2,2,2,2,2
2,2,2,2,2,2,0,0,0,2,7,0,0,0,2,2,2,2,2,2,2,2,2,2,2,0,2,2,2,0,0,0,0,2,2,2,2,2,2,0,0,0,0,2,2,2,2,2,2,2,2
2,2,2,2,2,0,0,0,0,2,0,0,0,0,0,0,0,0,0,2,0,0,2,2,2,5,2,2,2,0,0,0,0,2,2,2,2,2,2,0,0,0,2,2,2,2,2,2,2,2,2
2,2,2,2,0,0,0,0,0,0,0,0,0,2,0,0,0,0,5,5,0,0,0,0,0,2,2,0,0,0,0,0,0,0,2,0,2,0,0,0,0,0,2,2,2,2,2,2,2,2,2
2,2,2,2,0,0,0,0,0,0,0,0,2,2,0,0,0,0,5,5,5,0,0,0,0,0,0,0,0,0,0,0,0,0,0,0,0,0,0,0,0,2,2,2,2,2,2,2,2,2,2
2,2,2,0,0,0,0,0,0,0,0,0,2,2,0,0,0,0,5,5,5,0,0,0,0,0,0,0,0,0,0,0,0,0,0,0,0,0,0,0,0,2,2,2,2,2,2,2,2,2,2
2,2,2,0,0,0,0,0,2,0,0,0,2,0,0,0,0,0,0,0,0,0,0,0,0,2,0,0,0,0,0,0,0,0,0,0,0,0,0,2,2,2,2,2,2,2,2,2,2,2,2
2,2,2,0,0,0,0,0,2,0,0,2,2,0,0,0,0,0,0,0,0,0,0,0,0,2,7,0,0,7,7,0,0,0,0,0,0,2,2,2,2,2,2,2,2,2,2,2,2,2,2
2,2,2,0,0,0,0,0,2,0,0,0,2,0,0,0,0,0,0,0,0,0,0,21,21,2,2,21,2,2,0,0,0,0,7,0,0,2,2,2,2,2,2,2,2,2,2,2,2,2,2
2,2,2,0,0,0,0,0,2,0,0,0,2,2,2,2,2,2,2,2,2,0,0,0,0,2,2,2,7,7,7,2,2,2,2,2,0,0,0,0,0,0,0,0,0,0,0,0,0,0,0
2,2,2,0,0,0,0,0,2,0,0,0,2,2,2,2,2,2,2,2,2,2,0,0,0,2,2,2,29,29,29,2,2,2,2,2,2,2,2,0,2,2,2,2,2,0,2,2,2,2,2
2,2,2,2,0,0,0,0,2,2,0,9,2,2,2,2,2,2,2,2,2,2,0,0,0,2,2,2,29,29,29,29,29,2,2,2,2,2,2,0,2,2,2,2,2,0,2,2,2,2,2
2,2,2,2,0,0,0,0,2,2,2,2,2,2,2,2,2,2,2,2,3,3,2,0,12,6,2,2,2,29,29,0,0,29,2,2,2,2,2,0,2,2,2,2,2,0,2,2,2,2,2
:endlayer
layer: 12
2,2,2,2,2,2,2,2,2,2,2,2,2,2,2,2,2,2,2,2,2,2,2,2,7,7,7,7,7,2,2,2,2,2,2,3,3,2,2,2,2,2,2,2,2,2,2,2,2,2,2
2,2,2,2,2,2,2,2,2,2,2,2,2,2,2,2,2,2,2,2,2,2,2,2,2,2,7,7,7,2,2,2,2,2,2,2,3,2,2,2,2,2,2,2,2,2,2,2,2,2,2
2,2,2,2,2,2,2,2,2,2,2,2,2,2,2,2,2,2,2,2,2,2,2,2,2,2,2,2,2,2,2,2,2,2,2,2,2,2,2,2,2,2,2,2,2,2,2,2,2,2,2
2,2,2,2,2,2,3,3,2,2,2,2,2,2,2,2,2,2,2,2,2,2,2,2,2,2,2,2,2,2,2,2,2,2,2,2,2,2,2,2,2,2,2,2,2,2,2,2,2,2,2
2,2,2,2,2,2,3,3,2,2,2,2,2,2,2,2,7,2,2,2,2,2,2,2,2,2,2,2,2,2,2,2,2,3,2,2,2,2,2,2,2,2,2,2,2,2,2,2,2,2,2
2,2,2,2,2,2,2,0,0,0,0,0,0,2,2,7,7,7,0,0,0,2,2,2,2,2,2,2,2,2,2,2,2,2,2,8,8,2,2,2,2,2,2,2,2,2,2,2,2,2,2
2,2,2,2,2,2,2,2,0,0,0,0,0,0,2,0,0,0,0,0,0,0,2,2,2,2,2,2,2,2,2,2,2,2,2,8,8,2,2,2,2,2,2,2,2,2,2,2,2,2,0
2,2,2,2,2,0,0,0,0,0,0,0,0,0,0,0,0,0,0,0,0,0,0,0,2,0,0,2,2,2,2,2,2,2,2,2,2,2,2,2,2,0,2,2,2,2,2,2,2,0,0
2,0,0,0,0,0,0,0,0,2,0,0,0,0,0,0,0,0,0,0,0,0,0,0,0,0,0,0,2,2,2,2,2,2,2,2,2,2,2,2,2,0,2,2,2,2,2,2,2,0,0
2,0,0,0,0,0,0,0,0,2,0,0,0,0,0,0,0,0,0,0,0,0,0,0,0,0,0,0,0,0,2,2,2,2,2,2,2,2,2,2,2,0,0,2,2,8,8,2,2,0,0
2,0,0,0,0,0,0,0,0,2,2,0,0,0,0,0,0,0,0,2,2,0,0,0,0,0,0,0,0,0,0,0,2,2,2,2,2,2,2,2,2,0,0,2,2,8,4,2,0,0,0
2,0,0,0,0,0,0,0,0,2,2,2,0,0,0,0,0,2,2,2,2,0,0,0,0,0,0,0,0,0,0,0,0,2,2,2,2,2,7,7,7,0,0,0,4,4,4,0,0,0,0
2,0,0,0,0,0,0,0,0,2,2,2,0,0,0,0,0,2,2,2,2,2,2,0,0,2,0,0,0,0,0,0,0,2,2,2,2,2,7,7,7,0,0,0,4,7,0,0,0,0,0
2,0,0,0,0,0,0,0,0,2,2,2,2,0,0,0,0,0,2,8,2,2,2,2,2,2,5,5,5,0,0,0,2,2,2,2,2,2,2,7,7,0,0,0,0,7,0,0,0,0,0
2,0,0,0,0,0,0,0,2,2,2,2,2,0,0,0,0,0,2,2,2,2,2,2,2,2,2,2,0,5,2,2,2,2,2,2,2,2,2,2,7,0,0,0,0,0,0,0,0,0,7
2,2,2,2,2,2,2,2,2,2,2,2,2,0,0,0,0,0,0,2,2,2,2,2,2,2,2,2,2,2,2,2,2,2,2,2,2,2,2,2,2,0,0,0,0,0,7,7,7,7,7
2,2,2,2,2,2,2,2,2,2,2,2,2,2,2,0,0,0,0,0,2,2,2,2,2,2,2,2,2,2,2,2,2,2,2,2,2,2,3,2,2,0,0,0,0,0,0,7,7,7,7
2,2,2,2,2,2,2,2,2,2,2,2,2,2,2,0,0,0,0,0,2,2,2,0,0,0,0,0,0,2,2,2,2,2,2,2,2,2,2,3,2,0,0,0,0,0,0,0,0,7,7
2,2,2,2,2,2,2,3,2,2,2,2,2,2,2,2,0,0,0,0,2,0,0,0,0,0,0,0,0,0,0,2,2,2,2,2,2,2,2,2,2,2,5,0,0,0,0,0,0,0,7
2,2,2,2,2,2,2,2,2,2,2,2,2,2,2,2,0,0,0,5,0,0,0,0,0,0,0,0,0,0,0,0,2,2,2,2,2,2,2,2,2,2,2,2,2,0,0,0,0,0,7
2,2,2,2,2,2,2,2,2,2,2,2,2,2,2,2,0,0,5,0,0,0,0,0,0,0,0,0,0,0,0,0,0,2,2,2,2,2,2,2,2,2,2,2,2,2,0,0,0,2,0
2,2,2,2,2,2,2,2,2,2,2,2,2,2,2,2,2,2,0,0,0,0,0,0,0,0,0,0,0,0,0,0,0,0,2,2,2,2,2,2,2,2,2,2,2,2,2,2,2,2,0
2,2,2,2,2,2,2,2,2,2,2,2,2,2,2,2,2,2,0,0,0,0,0,0,0,0,0,0,0,0,0,0,0,0,2,2,2,2,2,2,2,2,2,2,2,2,2,2,2,2,0
2,2,2,2,2,2,2,2,2,0,15,2,2,2,2,2,2,0,0,0,0,0,0,0,0,0,0,0,0,0,0,0,0,0,0,2,2,2,2,2,2,2,2,2,2,2,2,2,2,2,0
2,5,2,2,2,2,2,2,2,0,12,0,2,2,2,2,2,0,0,0,0,0,0,0,0,0,0,0,0,0,0,0,0,0,0,2,2,2,2,2,2,2,2,2,2,2,2,2,2,2,0
2,5,2,2,2,2,2,2,2,0,0,0,2,2,2,2,2,0,0,0,0,0,0,0,0,0,0,0,0,0,0,0,0,0,0,2,2,2,2,2,2,2,2,2,2,2,2,2,2,2,2
2,5,2,2,2,2,2,2,2,0,0,0,2,2,2,2,2,0,0,0,0,0,0,0,0,0,0,0,0,0,0,0,0,0,0,2,2,2,2,2,2,2,2,2,2,2,2,2,2,2,2
2,5,2,2,2,2,2,2,0,0,0,0,0,7,7,7,7,0,0,0,0,0,0,0,0,0,0,0,0,0,0,0,0,0,0,2,2,2,2,2,2,2,2,2,2,2,2,2,2,2,7
2,2,2,2,2,2,2,2,0,0,0,0,0,7,5,5,5,0,0,0,0,0,0,0,0,0,0,0,0,0,0,0,0,0,0,2,2,2,2,2,2,2,11,2,2,4,4,2,2,7,7
2,5,2,7,7,2,2,2,0,0,0,0,0,7,5,5,5,5,0,0,0,0,0,0,0,0,0,0,0,0,0,0,0,0,2,2,2,2,2,2,2,2,11,2,2,4,4,10,7,7,7
2,2,2,7,7,7,2,2,2,0,0,0,0,7,5,5,5,5,0,0,0,0,0,0,0,0,0,0,0,0,0,0,0,0,2,2,2,2,2,2,2,2,2,2,4,4,4,2,7,7,7
2,2,7,7,7,7,2,2,2,0,2,2,2,7,2,2,2,2,2,0,0,0,0,0,0,0,0,0,0,0,0,0,0,2,2,2,2,2,2,2,2,2,2,2,2,4,4,2,2,2,2
2,2,7,7,7,7,2,2,2,2,2,2,7,7,2,2,2,2,2,2,0,0,0,0,0,0,0,0,0,0,0,0,2,2,2,2,2,2,2,2,3,2,2,2,2,4,2,2,2,2,2
2,2,7,7,7,2,2,2,2,2,2,7,7,7,2,2,2,2,2,2,5,5,5,30,0,0,0,0,0,0,0,2,2,2,2,2,2,2,2,2,2,2,2,2,2,3,3,2,2,2,2
2,2,7,7,7,2,2,2,2,2,2,7,7,7,2,2,2,2,2,5,5,5,5,30,0,0,0,0,0,2,2,2,2,2,2,2,2,2,2,2,2,2,2,2,2,3,3,2,2,2,2
2,2,2,2,2,2,2,2,2,2,2,7,7,2,2,2,2,2,5,5,5,5,5,30,2,2,2,2,2,2,2,2,2,2,2,2,2,2,2,2,2,2,3,3,2,2,2,2,2,2,2
2,2,2,2,2,2,2,2,2,2,2,2,2,2,2,2,2,2,5,5,5,5,2,2,2,2,2,2,2,2,2,2,2,0,0,2,2,2,2,2,2,2,2,3,2,2,2,2,2,2,2
2,2,2,2,2,2,0,0,0,2,2,2,2,2,0,2,2,2,5,5,5,2,2,2,2,2,2,2,2,2,2,2,2,2,2,2,2,2,2,2,2,2,2,2,2,2,2,2,2,2,2
2,2,2,2,2,2,2,0,0,2,2,0,0,0,0,0,2,2,2,2,2,2,2,2,2,0,2,2,2,2,2,2,2,2,2,2,2,2,2,2,2,2,2,2,2,2,2,2,2,2,2
2,2,2,2,2,2,2,0,0,2,0,0,0,0,0,0,2,2,2,2,2,2,2,2,2,0,0,4,2,2,2,2,2,2,2,2,2,2,2,2,2,2,2,2,2,2,2,2,2,2,2
2,2,2,2,2,2,0,0,0,2,0,0,0,0,0,0,0,0,0,2,2,2,2,2,2,5,0,0,2,2,2,2,2,2,2,2,2,2,2,2,2,2,2,2,2,2,2,2,2,2,2
2,2,2,2,2,0,0,0,0,0,0,0,0,0,0,0,0,0,0,5,0,0,0,2,2,0,0,0,0,0,0,0,0,2,2,2,2,2,2,2,2,2,2,2,2,2,2,2,2,2,2
2,2,2,2,0,0,0,2,0,0,0,0,2,2,0,0,0,0,0,5,0,0,0,0,2,0,0,0,0,0,0,0,0,0,2,2,2,2,2,2,2,2,2,2,2,2,2,2,2,2,2
2,2,2,2,0,0,2,2,0,0,0,0,0,0,0,0,0,0,0,0,0,0,0,2,2,0,0,0,0,0,0,0,0,0,0,2,2,2,2,2,2,2,2,2,2,2,2,2,2,2,2
2,2,2,2,2,2,2,2,2,0,0,0,0,0,0,0,0,0,0,0,0,0,0,2,2,0,0,0,0,0,0,0,0,0,2,2,2,2,2,2,2,2,2,2,2,2,2,2,2,2,2
2,2,2,2,0,2,2,2,2,2,0,0,0,0,0,0,0,0,0,0,0,0,0,0,0,0,7,0,0,0,0,2,2,0,0,0,0,2,2,2,2,2,2,2,2,2,2,2,2,2,2
2,2,0,0,2,0,2,2,2,2,0,0,0,0,0,0,0,0,0,0,0,0,0,0,21,2,21,21,21,21,2,2,2,2,0,0,0,2,2,2,2,2,2,2,2,2,2,2,2,2,2
2,2,0,0,0,2,2,2,2,2,0,2,2,2,2,2,2,2,2,2,2,0,0,0,0,2,29,29,29,29,29,2,2,2,2,2,2,2,2,2,2,2,2,2,2,2,2,2,2,2,2
2,2,2,0,4,2,2,2,2,2,2,2,2,2,2,2,2,2,2,2,2,2,0,0,0,2,2,29,0,0,0,29,2,2,2,2,2,2,2,2,2,2,2,2,2,2,2,2,2,2,2
2,2,2,2,2,2,2,2,2,2,2,9,2,2,2,2,2,2,2,2,2,2,2,0,0,2,2,2,0,0,0,0,0,2,2,2,2,2,2,2,2,2,2,2,2,2,2,2,2,2,2
2,2,2,2,2,2,2,2,2,2,2,2,2,2,2,2,2,2,2,2,2,2,2,0,0,2,2,2,2,0,0,0,0,0,2,2,2,2,2,2,2,2,2,2,2,2,2,2,2,2,2
:endlayer
layer: 13
2,2,2,2,2,2,2,2,2,2,2,2,2,2,2,2,2,2,2,2,2,2,2,2,2,2,7,7,2,2,2,2,2,2,2,3,3,2,2,2,2,2,2,2,2,2,2,2,2,2,2
2,2,2,2,2,2,2,2,2,2,2,2,2,2,2,2,2,2,2,2,2,2,2,2,2,2,2,2,2,2,2,2,2,2,2,3,3,2,2,2,2,2,2,2,2,2,2,2,2,2,2
2,2,2,2,2,2,2,2,2,2,2,2,2,2,2,2,2,2,2,2,2,2,2,2,2,2,2,2,2,2,2,2,2,2,2,2,2,2,2,2,2,2,2,2,2,2,2,2,2,2,2
2,2,2,2,2,2,2,2,2,2,2,2,2,2,2,2,2,2,2,2,2,2,2,2,0,2,2,2,2,2,2,2,2,2,2,2,2,2,2,2,2,2,2,2,2,2,2,2,2,2,2
2,2,2,2,2,2,2,3,2,2,2,2,2,2,2,2,2,2,2,2,2,2,0,0,0,2,2,2,2,2,2,2,3,3,2,2,2,2,2,2,2,2,2,2,2,2,2,2,2,2,2
2,2,2,2,2,2,2,0,0,0,0,0,0,2,2,2,2,2,0,0,0,0,2,2,2,2,2,2,2,2,2,2,3,3,2,8,8,2,2,2,2,2,2,2,2,2,2,2,2,2,2
2,2,2,2,2,2,2,2,0,0,0,0,0,2,2,0,0,0,0,0,0,0,2,2,2,0,2,2,2,2,2,2,2,2,2,8,8,2,2,2,2,2,2,2,2,2,2,2,2,2,2
2,2,2,2,2,0,0,0,0,0,0,0,0,0,0,0,0,0,0,0,0,0,0,0,2,0,0,0,2,2,2,2,2,2,2,2,2,2,2,2,2,0,2,2,2,2,2,2,2,2,2
2,0,0,0,0,0,0,0,0,2,0,0,0,0,0,0,0,0,0,0,0,0,0,0,0,0,0,0,0,2,2,2,2,2,2,2,2,2,2,2,2,0,2,2,2,2,2,2,2,2,2
2,0,0,0,0,0,0,0,0,2,0,0,0,0,0,0,0,0,0,0,0,0,0,0,0,0,0,0,0,0,0,0,2,0,2,2,2,2,2,2,2,0,0,2,2,2,2,2,2,2,2
2,0,0,0,0,0,0,0,0,2,2,0,0,0,0,0,0,0,2,2,0,0,0,0,0,0,0,0,0,0,0,0,0,0,0,0,2,7,7,7,7,0,0,2,2,2,4,2,0,0,0
2,0,0,0,0,0,0,0,0,2,2,2,0,0,0,0,0,2,2,2,2,0,0,0,0,0,0,0,0,0,0,0,0,0,0,0,0,7,7,7,7,0,0,0,4,4,4,0,0,0,0
2,0,0,0,0,0,0,0,0,2,2,2,2,0,0,0,0,2,2,2,2,2,0,0,0,0,0,0,0,0,0,0,0,0,0,0,0,2,7,7,7,0,0,0,4,0,0,0,0,0,0
2,0,0,0,0,0,0,0,0,2,2,2,2,2,0,0,0,2,2,8,8,2,2,2,2,2,2,5,5,0,0,0,0,0,0,0,2,2,7,7,7,0,0,0,0,0,0,0,0,0,0
2,0,0,0,0,0,0,0,0,2,2,3,2,2,0,0,0,0,2,8,8,2,2,2,2,2,2,2,2,2,0,2,2,2,2,0,0,0,5,7,7,0,0,0,0,0,0,0,0,0,0
2,2,2,2,2,2,2,2,2,2,2,2,2,2,2,0,0,0,2,2,2,2,2,2,2,2,2,2,2,2,2,2,2,2,2,0,5,5,5,5,7,0,0,0,0,0,0,0,0,7,7
2,2,2,2,2,2,2,2,2,2,2,2,2,2,2,0,0,0,0,2,2,2,2,2,2,2,2,2,2,2,2,2,2,2,2,2,5,5,5,5,5,0,0,0,0,0,7,7,7,7,7
2,2,2,2,2,2,2,2,2,2,2,2,2,2,2,2,0,0,0,0,2,2,2,0,0,0,0,0,0,2,2,2,2,2,2,2,2,5,5,5,5,0,0,0,0,0,2,7,7,7,7
2,2,2,2,2,2,2,2,2,2,2,2,2,2,2,2,2,0,0,0,2,0,0,0,0,0,0,0,0,0,0,2,2,2,2,2,2,2,5,5,5,5,5,0,0,0,0,7,7,7,7
2,2,2,2,2,2,2,2,2,2,2,2,2,2,2,2,2,0,0,5,0,0,0,0,0,0,0,0,0,0,0,0,2,2,2,2,2,2,2,0,0,5,5,2,2,2,2,2,7,7,7
2,2,2,2,2,2,2,2,2,2,2,2,2,2,2,2,2,0,5,0,0,0,0,0,0,0,0,0,0,0,0,0,0,2,2,2,3,2,2,2,2,0,0,0,8,8,2,2,2,2,0
2,2,2,2,2,2,2,2,2,2,2,2,2,2,2,2,2,2,0,0,0,0,0,0,0,0,0,0,0,0,0,0,0,0,2,3,2,2,2,2,2,2,0,0,0,8,2,2,2,2,0
2,2,2,2,2,2,2,2,2,2,2,2,2,2,2,2,2,2,0,0,0,0,0,0,0,0,0,0,0,0,0,0,0,0,2,2,2,2,2,2,2,2,2,0,2,2,2,2,2,2,0
2,2,2,2,2,2,2,2,2,0,15,0,2,2,2,2,2,0,0,0,0,0,0,0,0,0,0,0,0,0,0,0,0,0,0,2,2,2,2,2,2,2,2,2,2,2,2,2,2,2,0
2,2,2,2,2,2,2,2,2,0,0,0,0,2,2,2,2,0,0,0,0,0,0,0,0,0,0,0,0,0,0,0,0,0,0,2,2,2,2,2,2,2,2,2,2,2,2,2,2,2,2
2,2,2,2,2,2,2,2,2,0,0,0,0,7,2,2,2,0,0,0,0,0,0,0,0,0,0,0,0,0,0,0,0,0,0,2,2,2,2,2,2,2,2,2,2,2,2,2,2,2,2
2,2,2,2,2,2,2,2,2,0,0,0,0,7,31,31,31,0,0,0,0,0,0,0,0,0,0,0,0,0,0,0,0,0,0,2,2,2,2,2,2,2,2,2,2,2,2,2,2,2,2
2,2,2,2,7,7,2,2,0,0,0,0,0,7,0,0,0,0,0,0,0,0,0,0,0,0,0,0,0,0,0,0,0,0,0,2,2,2,2,2,2,2,2,2,2,2,2,2,2,7,7
2,2,2,2,7,7,2,2,0,0,0,0,0,7,0,0,0,0,0,0,0,0,0,0,0,0,0,0,0,0,0,0,0,0,0,2,2,2,2,2,2,2,2,2,2,2,2,2,7,7,7
2,2,2,7,7,7,2,2,0,0,0,0,0,0,7,0,0,0,0,0,0,0,0,0,0,0,0,0,0,0,0,0,0,0,2,2,2,2,2,2,2,11,2,2,2,4,2,7,7,7,7
2,2,7,7,7,7,7,2,2,0,0,2,7,7,7,0,0,0,0,0,0,0,0,0,0,0,0,0,0,0,0,0,0,0,2,2,2,2,2,2,2,2,2,2,2,4,4,7,7,7,7
2,2,7,7,7,7,7,2,2,2,2,7,7,7,7,0,0,0,0,0,0,0,0,0,0,0,0,0,0,0,0,0,0,2,2,2,2,2,2,2,2,2,2,2,2,4,7,7,7,7,7
2,7,7,7,7,7,2,2,2,2,2,7,7,7,7,7,0,0,0,0,0,0,0,0,0,0,0,0,0,0,0,0,2,2,2,2,2,2,2,2,2,2,2,2,2,4,2,7,2,2,2
2,7,7,7,7,7,2,2,2,2,2,7,7,7,7,7,7,0,0,0,0,0,0,0,0,0,0,0,0,0,0,2,2,2,2,2,2,2,2,2,2,2,2,2,2,3,3,2,2,2,2
2,2,7,7,7,2,2,2,2,2,7,7,7,7,7,2,2,2,0,0,0,0,0,0,0,0,0,0,0,2,2,2,2,0,0,2,2,2,2,2,2,2,2,2,2,3,3,2,2,2,2
2,2,7,7,2,2,2,2,2,2,7,7,7,7,2,2,2,2,5,0,0,0,0,0,0,2,2,2,2,2,2,2,2,0,0,0,2,2,2,2,2,2,3,3,2,2,2,2,2,2,2
2,2,7,7,2,2,2,2,2,2,7,7,7,7,2,2,2,5,5,5,0,0,0,0,2,2,2,2,2,2,2,2,2,0,0,0,2,2,2,2,2,2,2,3,2,2,2,2,2,2,2
2,2,2,2,2,2,2,0,0,2,2,7,2,0,0,0,2,5,5,5,5,5,2,2,2,2,2,2,2,2,2,2,2,2,2,2,2,2,2,2,2,2,2,2,2,2,2,2,2,2,2
2,2,2,2,2,2,2,2,0,2,2,2,0,0,0,0,0,5,5,2,2,2,2,2,2,0,2,2,2,2,2,2,2,2,2,2,2,2,2,2,2,2,2,2,2,2,2,2,2,2,2
2,2,2,2,2,2,2,2,2,2,2,0,0,0,0,0,0,0,0,2,2,2,2,2,2,0,0,4,4,2,2,2,2,2,2,2,2,2,2,2,2,2,2,2,2,2,2,2,2,2,2
2,2,2,2,2,2,2,2,2,2,0,0,0,0,0,0,0,0,0,2,2,2,2,2,2,0,0,0,4,2,2,2,2,2,2,2,2,2,2,2,2,2,2,2,2,2,2,2,2,2,2
2,2,2,2,2,2,2,2,2,2,0,0,0,0,0,0,0,0,0,0,2,2,2,2,2,0,0,0,0,0,2,2,2,2,2,2,2,2,2,2,2,2,2,2,2,2,2,2,2,2,2
2,2,2,2,2,2,2,2,2,2,0,2,2,0,0,0,0,0,0,0,0,2,2,2,2,0,0,0,0,0,0,0,2,2,2,2,2,2,2,2,2,2,2,2,2,2,2,2,2,2,2
2,2,2,2,2,2,2,2,2,2,2,0,0,0,0,0,0,0,0,0,0,2,2,2,2,0,0,0,0,0,0,0,2,2,2,2,2,2,2,2,2,2,2,2,2,2,2,2,2,2,2
2,2,2,2,2,2,2,2,2,2,0,0,0,0,0,0,0,0,0,0,0,0,0,2,2,0,0,0,0,0,0,2,2,2,2,2,2,2,2,2,2,2,2,2,2,2,2,2,2,2,2
2,4,4,2,2,2,2,2,2,2,0,0,0,0,0,0,0,0,0,0,0,0,0,0,0,0,7,0,0,0,2,2,2,0,0,2,2,2,2,2,2,2,2,2,2,2,2,2,2,2,2
2,2,0,0,2,2,2,2,2,0,2,0,0,0,0,0,0,0,0,0,0,0,0,0,0,2,21,21,21,21,21,2,2,0,0,0,2,2,2,2,2,2,2,2,2,2,2,2,2,2,2
2,2,0,0,2,2,2,2,2,2,2,2,2,2,2,2,2,2,2,2,2,0,0,0,0,2,0,0,0,0,0,2,2,2,2,2,2,2,2,2,2,2,2,2,2,2,2,2,2,2,2
2,2,2,2,2,2,2,2,2,7,7,2,2,2,2,2,2,2,2,2,2,2,2,0,0,2,2,0,0,0,0,0,2,2,2,2,2,2,2,2,2,2,2,2,2,2,2,2,2,2,2
2,2,2,2,2,2,2,2,2,7,7,2,2,2,2,2,2,2,2,2,2,2,2,2,0,2,2,2,0,0,0,0,0,2,2,2,2,2,2,2,2,2,2,2,2,2,2,2,2,2,2
2,2,2,2,2,2,2,2,2,2,7,7,2,2,2,2,2,2,2,2,2,2,2,2,2,2,2,2,2,0,0,0,0,2,2,2,2,2,2,2,2,2,2,2,2,2,2,2,2,2,2
:endlayer
layer: 14
2,2,2,7,7,7,7,2,2,2,2,2,2,2,2,2,2,2,2,2,2,2,2,7,7,7,5,5,2,2,2,2,2,2,2,2,2,2,5,5,5,2,2,2,2,2,2,2,2,2,2
2,7,7,7,7,7,7,2,2,2,2,2,2,2,2,2,2,2,2,2,2,2,2,4,4,4,4,2,2,2,2,2,2,2,2,2,2,2,5,5,5,5,2,2,2,2,2,2,2,2,2
2,7,7,7,7,7,2,2,2,2,2,2,2,2,2,2,2,2,2,2,2,2,2,4,0,4,2,2,2,2,2,2,2,2,2,2,2,2,5,5,5,5,3,2,2,2,2,2,2,2,2
2,7,7,7,7,2,2,2,2,2,2,2,2,2,2,2,2,2,2,2,2,2,2,0,0,2,2,2,2,2,2,2,2,2,2,2,2,2,2,5,5,5,2,2,2,2,2,2,2,2,2
2,7,2,2,2,2,2,2,2,2,2,2,2,2,2,2,2,2,2,2,2,2,0,0,0,2,2,2,2,2,2,2,2,2,2,2,2,2,2,2,5,5,5,2,2,2,2,2,2,2,2
2,2,2,2,2,2,2,2,0,0,0,0,2,2,2,2,2,2,2,0,0,2,2,2,2,2,2,2,2,2,2,2,3,2,2,2,2,2,2,2,2,5,2,2,2,2,2,2,2,2,2
2,2,2,2,2,2,2,2,2,0,0,0,0,2,2,2,0,0,0,0,0,0,2,2,2,0,2,2,2,2,2,2,2,2,2,2,2,2,2,2,2,2,2,2,2,0,0,0,0,0,0
2,2,2,2,2,2,0,0,0,2,0,0,0,2,2,0,0,0,0,0,0,0,0,0,2,0,0,0,2,2,2,2,2,2,2,2,2,2,2,2,2,2,2,2,0,0,0,0,0,0,0
2,2,0,0,0,0,0,0,0,2,2,0,0,2,0,0,0,0,0,0,0,0,0,0,0,0,0,0,0,0,2,2,2,2,2,2,2,0,0,2,2,0,2,0,0,0,0,0,0,0,0
2,0,0,0,0,0,0,0,0,2,2,2,0,0,0,0,0,0,0,0,0,0,0,0,0,0,0,0,0,0,0,0,0,0,0,0,0,0,0,0,2,0,2,2,0,0,0,0,0,0,0
2,0,0,0,0,0,0,0,0,2,2,2,2,0,0,0,0,2,2,2,0,0,0,0,0,0,0,0,0,0,0,0,0,0,0,0,0,0,0,0,7,0,0,0,0,0,2,2,2,0,0
2,0,0,0,0,0,0,0,0,2,2,2,2,2,0,2,2,2,2,2,2,0,0,0,0,0,0,0,0,0,0,0,0,0,0,0,0,0,0,0,7,0,0,2,4,0,2,2,0,0,2
2,0,0,0,0,0,0,0,0,2,2,2,2,2,2,2,2,2,2,2,2,2,0,0,0,0,0,0,0,0,0,0,0,0,0,0,0,0,0,7,7,0,0,0,0,0,0,0,0,0,0
2,0,0,0,0,0,0,0,0,2,2,2,2,2,2,2,2,2,2,2,2,2,2,2,2,2,2,5,5,0,0,0,0,0,0,0,0,0,7,7,7,0,0,0,0,0,0,0,0,0,0
2,0,0,0,0,0,0,0,0,2,2,3,2,2,2,2,2,2,2,2,8,2,2,2,2,2,2,2,2,2,0,0,0,0,0,0,0,0,0,7,7,0,0,0,0,0,0,0,0,0,2
2,2,2,2,2,2,2,2,2,2,2,2,2,2,2,2,2,2,2,2,2,2,2,2,2,2,2,2,2,2,2,2,2,2,0,0,0,0,5,5,7,0,0,0,0,0,0,0,0,7,2
2,2,2,2,2,2,2,2,2,2,2,2,2,2,2,2,2,2,2,2,2,2,2,2,2,2,2,2,2,2,2,2,2,2,2,0,5,5,5,5,5,7,7,0,0,2,7,7,7,7,2
2,2,2,2,2,2,2,2,2,2,2,2,2,2,2,2,2,2,8,8,2,2,2,0,0,0,0,0,0,2,2,2,2,2,2,2,5,5,5,5,5,0,7,7,7,2,2,7,7,7,2
2,2,2,2,2,2,2,2,2,2,2,2,2,2,2,2,2,2,8,8,2,0,0,0,0,0,0,0,0,0,0,2,2,2,2,2,2,2,5,5,5,5,0,2,2,2,2,2,7,7,2
2,2,2,2,2,2,2,2,2,2,2,2,4,4,2,2,2,2,2,2,0,0,0,0,0,0,0,0,0,0,0,0,2,2,2,2,2,2,2,0,0,5,5,2,2,2,2,2,2,2,2
2,2,2,2,2,2,2,2,2,2,2,2,4,4,2,2,2,2,2,0,0,0,0,0,0,0,0,0,0,0,0,0,0,2,2,2,3,2,2,2,0,0,0,0,8,8,2,2,2,2,0
2,2,2,2,8,8,2,2,2,2,2,2,4,4,2,2,2,2,0,0,0,0,0,0,0,0,0,0,0,0,0,0,0,0,2,5,5,2,2,2,2,2,0,0,0,8,2,2,2,2,0
2,2,2,2,8,8,2,2,2,2,2,2,2,2,2,2,2,2,0,0,0,0,0,0,0,0,0,0,0,0,0,0,0,0,2,5,5,5,0,0,2,2,2,0,2,2,2,2,2,2,0
2,2,2,2,2,2,2,2,2,0,15,0,2,2,2,2,2,0,0,0,0,0,0,0,0,0,0,0,0,0,0,0,0,0,0,5,5,0,0,0,0,2,2,2,2,2,2,2,2,2,0
2,2,2,2,2,2,2,2,2,0,0,0,0,2,5,5,2,0,0,0,0,0,0,0,0,0,0,0,0,0,0,0,0,0,0,2,0,0,0,0,0,2,2,2,2,2,2,2,2,2,2
2,2,2,2,2,2,2,2,2,0,0,0,0,7,31,31,31,0,0,0,0,0,0,0,0,0,0,0,0,0,0,0,0,0,0,2,2,0,0,0,2,2,2,2,2,2,2,2,2,2,2
2,2,2,2,2,2,2,2,2,0,0,0,0,7,0,0,0,0,0,0,0,0,0,0,0,0,0,0,0,0,0,0,0,0,0,2,2,2,2,2,2,2,2,2,2,2,2,2,2,2,2
2,2,2,2,7,7,2,2,2,0,0,0,0,7,0,0,0,0,0,0,0,0,0,0,0,0,0,0,0,0,0,0,0,0,0,2,2,2,2,2,2,2,2,2,2,2,2,2,2,7,7
2,2,2,2,7,7,2,2,0,0,0,0,0,7,0,0,0,0,0,0,0,0,0,0,0,0,0,0,0,0,0,0,0,0,0,2,2,2,2,2,2,2,2,2,2,2,2,2,7,7,7
2,2,2,7,7,7,2,2,2,0,0,0,0,7,7,0,0,0,0,0,0,0,0,0,0,0,0,0,0,0,0,0,0,0,2,2,2,2,2,2,2,2,2,2,2,2,2,7,7,7,7
2,2,7,7,7,7,7,2,2,2,2,2,0,7,7,0,0,0,0,0,0,0,0,0,0,0,0,0,0,0,0,0,0,0,2,2,2,2,2,2,2,2,2,2,2,2,2,7,7,7,7
2,2,7,7,7,7,7,2,2,2,2,7,7,7,7,0,0,0,0,0,0,0,0,0,0,0,0,0,0,0,0,0,0,2,2,2,2,2,2,2,2,2,2,2,2,2,7,7,7,7,7
2,7,7,7,7,7,2,2,2,2,2,7,7,7,7,7,0,0,0,0,0,0,0,0,0,0,0,0,0,0,0,0,2,0,0,0,2,2,2,2,2,2,2,2,2,2,2,7,2,2,2
2,7,7,7,7,7,2,2,2,2,7,7,7,7,7,7,7,0,0,0,0,0,0,0,0,0,0,0,0,0,0,2,2,0,0,0,2,2,2,2,2,2,2,2,2,2,2,2,2,2,2
2,2,7,7,7,2,2,2,2,2,7,7,7,7,7,7,7,2,0,0,0,0,0,0,0,0,0,0,0,2,2,2,2,0,0,0,2,2,2,2,2,2,2,2,2,2,2,2,2,2,2
2,2,7,7,2,2,2,2,2,2,7,7,7,7,7,2,2,2,5,0,0,0,0,0,0,2,2,2,2,2,2,2,2,0,0,0,2,2,2,2,2,2,2,2,2,2,2,2,2,2,2
2,2,7,7,2,2,2,2,2,2,7,7,7,7,2,2,2,5,5,5,0,0,0,0,2,2,2,2,2,2,2,2,2,0,0,0,2,2,2,2,2,2,2,2,2,2,2,2,2,2,2
2,2,2,2,2,2,2,2,2,2,2,7,7,3,2,2,2,5,5,5,5,7,7,7,2,2,2,2,2,2,2,2,2,2,2,2,2,2,2,2,2,2,2,2,2,2,2,2,2,2,2
2,2,2,2,2,2,2,2,2,2,2,2,0,0,0,0,0,5,7,7,7,7,7,7,7,2,2,2,2,2,2,2,2,2,2,2,2,2,2,2,2,2,2,2,2,2,2,2,2,2,2
2,2,2,2,2,2,2,2,2,2,2,2,0,0,0,0,0,0,0,7,7,7,7,7,7,0,4,4,4,4,4,2,2,2,2,2,2,2,2,2,2,2,2,2,2,2,2,2,2,2,2
2,2,2,2,2,2,2,2,2,2,2,2,0,0,0,0,0,0,0,2,7,7,7,2,2,0,0,4,4,4,4,2,2,2,2,2,2,2,2,2,2,2,2,2,2,2,2,2,2,2,2
2,2,2,2,2,2,2,2,2,2,2,2,0,0,0,0,0,0,0,0,5,5,5,2,2,0,0,0,2,2,2,2,2,2,2,2,2,2,2,2,2,2,2,2,2,2,2,2,2,2,2
2,2,2,8,2,2,2,2,2,2,2,2,2,2,0,0,0,0,0,0,0,5,2,2,2,0,0,0,0,2,2,2,2,2,2,2,2,2,2,2,2,2,2,2,2,2,2,2,2,2,2
2,2,2,2,2,2,2,2,2,2,2,2,2,2,2,2,2,0,0,0,0,0,0,2,2,0,0,0,0,0,2,2,2,2,2,2,2,2,2,2,2,2,2,2,2,2,2,2,2,2,2
2,2,2,2,2,2,2,2,2,2,2,0,0,0,0,0,2,2,0,0,0,0,0,2,2,2,0,0,0,2,2,2,2,2,2,2,2,2,2,2,2,2,2,2,2,2,2,2,2,2,2
2,4,4,2,2,2,2,2,2,0,2,0,0,0,0,0,2,8,4,0,0,0,0,0,0,2,21,21,21,2,2,2,2,0,2,2,2,2,2,2,2,2,2,2,2,2,2,2,2,2,2
2,2,2,2,2,2,2,2,7,0,2,0,0,0,2,2,8,8,4,0,0,0,0,0,0,0,0,0,0,0,0,0,0,0,0,2,2,2,2,2,2,2,2,2,2,2,2,2,2,2,2
2,2,2,2,2,2,2,2,7,7,7,2,2,2,2,2,2,2,2,4,4,0,0,0,0,2,2,21,21,21,21,2,2,2,2,2,2,2,2,2,2,2,2,2,2,2,2,2,2,2,2
2,2,2,2,2,2,2,2,7,7,7,7,2,2,2,2,2,2,2,2,4,4,2,0,0,2,2,2,0,0,0,2,2,2,2,2,2,2,2,2,2,2,2,2,2,2,2,2,2,2,2
2,2,2,2,2,2,2,2,7,7,7,7,2,2,2,2,2,2,2,2,2,2,2,2,2,2,2,2,0,0,0,2,2,2,2,2,2,2,2,2,2,2,2,2,2,2,2,2,2,2,2
2,2,2,2,2,2,2,2,7,7,7,7,7,2,2,2,2,2,2,2,2,2,2,2,2,2,2,2,2,2,2,0,8,2,2,2,2,2,2,2,2,2,2,2,2,2,2,2,2,2,2
:endlayer
layer: 15
2,2,7,7,7,7,7,7,7,2,2,2,2,2,2,2,2,2,5,5,5,5,7,7,7,7,7,5,5,2,2,2,2,2,2,2,2,5,5,5,5,0,0,0,2,2,2,2,2,2,2
2,7,7,7,7,7,7,7,2,2,2,2,2,2,2,2,2,2,5,5,5,5,7,7,7,7,5,5,2,2,2,2,2,2,2,2,2,5,5,5,5,0,0,2,2,2,2,2,2,2,2
2,0,7,7,7,7,7,2,2,2,2,2,2,2,2,2,2,2,2,5,5,5,2,4,0,5,2,2,2,2,2,2,2,2,2,2,2,2,5,5,5,0,5,2,2,2,2,2,2,2,2
2,0,7,7,7,7,2,2,2,2,2,2,2,2,2,2,2,2,2,5,5,5,2,0,0,2,2,2,2,2,2,2,2,2,2,2,2,2,5,5,5,0,5,2,2,2,2,2,2,2,2
2,0,7,7,2,2,2,2,2,2,2,2,2,2,2,2,2,2,2,2,5,2,0,0,0,2,2,2,2,2,2,2,2,2,7,2,2,2,2,5,5,5,5,2,2,2,2,2,2,2,2
2,2,2,2,2,2,2,2,2,2,2,2,2,2,2,2,2,2,2,2,2,2,2,2,2,2,2,2,2,2,2,2,2,7,7,2,2,2,2,2,5,5,5,2,2,2,2,0,0,2,2
2,2,2,2,2,2,2,2,2,2,2,2,2,2,2,2,2,2,2,0,0,2,2,2,2,2,2,2,2,2,2,2,2,7,7,2,2,2,2,2,2,0,0,2,0,0,0,0,0,0,0
2,2,2,2,2,2,2,2,0,2,2,2,2,2,2,2,2,2,0,0,0,2,2,2,2,0,0,2,2,2,2,2,7,7,7,7,2,2,0,0,0,0,0,0,0,0,0,0,0,0,0
2,2,2,2,2,0,0,0,0,2,2,2,2,2,2,2,2,2,2,0,0,0,0,0,0,0,0,0,0,2,2,2,2,7,7,2,0,0,0,0,0,0,0,0,0,0,0,0,0,0,0
2,0,0,0,0,0,0,0,0,2,2,2,2,2,2,2,2,2,2,2,2,0,0,0,0,0,0,0,0,0,0,0,0,0,0,0,0,0,0,0,0,0,0,0,0,0,0,0,0,0,0
2,0,0,0,0,0,0,0,0,2,2,2,2,2,2,2,2,2,2,2,2,0,0,0,0,0,0,0,0,0,0,0,0,0,0,0,0,0,0,0,0,0,0,0,0,0,0,2,2,0,0
2,0,0,0,0,0,0,0,0,2,2,2,2,2,2,2,2,2,2,2,2,2,0,0,0,0,0,0,0,0,0,0,0,0,0,0,0,0,0,0,0,0,0,0,0,0,2,2,2,2,2
2,0,0,0,0,0,0,0,0,2,2,2,2,2,2,2,2,2,2,2,2,2,2,0,0,0,0,0,0,0,0,0,0,0,0,0,0,0,0,0,7,0,0,0,0,0,0,0,2,2,2
2,0,0,0,0,0,0,0,0,2,3,2,2,2,2,2,2,2,2,2,2,2,2,2,2,5,5,5,5,7,0,0,0,0,0,0,0,0,2,7,7,0,0,0,0,0,0,0,0,2,2
2,2,2,2,2,2,2,2,2,2,2,2,2,2,2,2,2,2,2,2,2,2,2,0,0,32,7,7,0,7,0,0,0,0,0,0,0,0,0,2,7,0,0,0,0,0,0,0,0,2,2
2,2,2,2,2,2,2,2,2,2,2,2,2,2,2,2,2,2,2,2,0,0,0,0,0,32,7,7,0,2,2,2,2,0,0,0,0,0,0,5,2,7,7,0,0,0,0,0,2,2,2
2,2,2,2,2,2,2,2,2,2,2,2,2,2,2,2,2,2,2,0,0,0,0,0,0,32,2,2,2,2,2,2,2,2,2,0,0,0,5,5,5,2,2,2,2,2,2,2,2,2,2
2,2,2,2,2,2,2,2,2,2,2,2,2,2,2,2,2,2,0,0,0,0,0,0,0,0,0,0,0,2,2,2,2,2,2,2,5,0,5,5,0,2,2,2,2,2,2,2,2,2,2
2,2,2,2,2,2,2,2,2,2,2,2,2,2,2,2,2,0,0,0,0,0,0,0,0,0,0,0,0,0,0,2,2,2,5,2,2,2,5,0,0,5,0,2,2,2,2,2,2,2,2
2,2,2,2,2,2,2,2,2,2,2,2,4,4,2,2,0,0,0,0,0,0,0,0,0,0,0,0,0,0,0,0,2,2,5,5,2,2,2,2,2,0,0,2,2,2,2,2,2,2,0
2,2,2,2,2,2,2,2,2,2,2,2,4,4,2,0,0,0,0,0,0,0,0,0,0,0,0,0,0,0,0,0,0,2,5,5,5,2,2,2,2,2,2,2,2,2,2,2,2,2,0
2,2,2,2,2,2,2,2,2,2,2,2,4,4,2,0,0,0,0,0,0,0,0,0,0,0,0,0,0,0,0,0,0,0,5,5,7,7,7,7,7,2,2,2,2,2,2,2,2,2,0
2,2,2,2,8,2,2,2,2,2,6,2,4,4,2,0,0,0,0,0,0,0,0,0,0,0,0,0,0,0,0,0,0,0,5,7,7,7,0,0,7,7,2,2,2,2,2,2,2,2,0
2,2,2,2,2,2,2,2,2,0,12,2,2,2,0,0,0,0,0,0,0,0,0,0,0,0,0,0,0,0,0,0,0,0,0,7,0,0,0,0,0,2,2,2,2,2,2,2,2,2,0
2,2,2,2,2,2,2,2,2,0,0,0,0,7,0,0,0,0,0,0,0,0,0,0,0,0,0,0,0,0,0,0,0,0,0,7,0,0,0,0,0,2,2,2,2,2,2,2,2,2,2
2,2,2,2,2,2,2,2,2,0,0,0,0,7,0,0,0,0,0,0,0,0,0,0,0,0,0,0,0,0,0,0,0,0,0,2,0,0,0,0,2,2,2,2,2,2,2,2,2,2,2
2,2,2,2,2,2,2,2,2,0,0,0,0,7,0,0,0,0,0,0,0,0,0,0,0,0,0,0,0,0,0,0,0,0,0,2,0,0,0,2,2,2,2,2,2,2,2,2,2,2,2
2,2,2,2,2,2,2,2,2,0,0,0,0,7,0,0,0,0,0,0,0,0,0,0,0,0,0,0,0,0,0,0,0,0,0,2,2,2,2,2,2,2,2,2,2,2,2,2,2,2,7
2,2,2,2,2,2,2,2,2,0,0,0,0,7,0,0,0,0,0,0,0,0,0,0,0,0,0,0,0,0,0,0,0,0,0,2,2,2,2,2,2,2,2,2,2,2,2,2,2,7,7
2,2,2,7,7,2,2,2,2,0,0,0,0,0,7,0,0,0,0,0,0,0,0,0,0,0,0,0,0,0,0,0,0,0,2,2,2,2,2,2,2,2,2,2,2,2,2,2,7,7,7
2,2,2,7,7,7,2,2,2,2,0,0,0,0,7,0,0,0,0,0,0,0,0,0,0,0,0,0,0,0,0,0,0,0,2,2,2,2,2,2,2,2,2,2,2,2,2,2,7,7,7
2,2,7,7,7,7,2,2,2,2,2,7,7,7,7,0,0,0,0,0,0,0,0,0,0,0,0,0,0,0,0,0,0,2,2,2,2,2,2,2,2,2,2,2,2,2,2,2,2,2,2
2,2,7,7,7,7,2,2,2,2,2,7,7,7,7,7,0,0,0,0,0,0,0,0,0,0,0,0,0,0,0,0,2,0,0,0,2,2,2,2,2,2,2,2,2,2,2,2,2,2,2
2,2,7,7,7,2,2,2,2,2,2,7,7,7,7,7,7,0,0,0,0,0,0,0,0,0,0,0,0,0,0,2,2,0,0,0,2,2,2,2,2,2,2,2,2,2,2,2,2,2,2
2,2,7,7,7,2,2,2,2,2,7,7,7,7,7,7,7,2,0,0,0,0,0,0,0,0,0,0,0,2,2,2,2,0,0,0,2,2,2,2,4,4,2,2,2,2,2,2,2,2,2
2,2,2,2,2,2,2,2,2,7,7,7,7,7,7,2,2,2,2,0,0,0,0,0,0,2,2,2,2,2,2,2,2,0,0,2,2,2,2,2,4,4,2,2,2,2,2,2,2,2,2
2,2,2,2,2,2,2,2,2,7,7,0,0,2,2,2,2,2,5,5,0,0,0,0,2,2,2,2,2,2,3,3,2,2,0,2,2,2,2,2,4,4,2,0,0,0,2,2,2,2,2
2,2,2,2,2,2,2,2,2,2,0,0,0,0,2,2,2,2,5,7,7,7,7,7,7,7,2,2,2,2,3,3,2,2,2,2,2,2,2,2,2,2,2,0,0,0,2,2,2,2,2
2,2,2,2,2,2,2,2,2,2,0,0,0,0,0,2,2,2,7,7,7,7,7,7,7,7,7,2,2,2,2,2,2,2,2,2,2,2,2,2,2,2,2,0,0,0,0,2,2,2,2
2,2,2,2,2,2,2,2,2,2,2,0,0,0,0,0,2,0,7,7,7,7,7,7,7,7,7,11,11,4,2,2,2,2,2,2,2,2,2,2,2,2,2,0,0,0,0,2,2,2,2
2,2,2,2,2,2,2,2,2,2,2,2,0,0,0,0,0,0,0,7,7,7,7,7,7,0,2,11,11,4,4,2,2,2,2,2,2,2,2,2,2,2,2,0,0,0,0,2,2,2,2
2,2,8,8,2,2,2,2,2,2,2,2,2,0,0,2,2,0,0,0,5,5,5,5,2,2,2,2,2,2,2,2,2,2,2,2,2,2,2,2,2,2,2,2,0,0,0,0,2,2,2
2,2,8,8,2,2,2,2,2,2,2,2,2,2,2,2,2,2,0,0,0,5,5,5,2,2,2,2,2,2,2,2,2,2,2,2,2,2,2,2,2,2,2,2,0,0,0,0,2,2,2
2,2,2,2,2,2,2,2,2,2,2,2,2,2,2,2,2,2,0,0,0,2,0,0,2,2,2,2,2,2,2,2,2,2,2,2,2,2,2,2,2,2,2,2,0,0,0,0,0,0,0
2,2,2,2,2,2,2,2,7,2,2,2,2,2,2,2,2,2,0,0,0,0,0,7,2,2,2,2,2,2,2,2,2,2,2,2,2,2,2,2,2,2,2,2,2,0,0,0,0,0,0
2,2,2,2,2,2,2,2,7,7,2,2,2,2,2,2,2,8,4,0,0,0,0,0,21,0,2,2,2,2,2,2,2,2,2,2,2,2,2,2,2,2,2,2,2,2,0,0,0,0,0
2,2,2,2,2,2,2,2,7,7,7,2,2,2,2,2,8,8,4,4,0,0,0,0,0,0,0,0,0,0,0,0,0,0,2,2,2,2,2,2,2,2,2,2,2,2,2,2,0,2,2
2,2,2,2,2,2,2,2,7,7,7,7,2,2,2,2,2,2,2,4,4,4,0,0,2,2,2,2,2,2,2,2,2,2,2,2,2,2,2,2,2,2,2,2,2,2,2,2,2,2,2
2,2,2,2,2,2,2,2,7,7,7,7,2,2,2,2,2,2,2,2,4,4,2,2,2,2,2,2,2,2,2,2,2,2,2,2,2,2,2,2,2,2,2,2,2,2,2,2,2,2,2
2,2,2,2,2,2,2,2,7,7,7,7,2,2,2,2,2,2,2,2,2,2,2,2,2,2,2,2,2,2,2,2,2,2,2,2,2,2,2,2,2,2,2,2,2,2,2,2,2,2,2
2,2,2,2,2,2,2,2,7,7,7,7,7,2,2,2,2,2,2,2,2,2,2,2,3,3,2,2,2,2,2,2,2,2,2,2,2,2,2,2,2,2,2,2,2,2,2,2,2,2,2
:endlayer
layer: 16
2,2,7,7,7,7,7,7,7,2,2,2,2,2,2,2,2,2,5,5,5,7,7,7,7,7,7,5,5,2,2,2,2,2,2,2,2,5,5,5,5,0,0,0,0,0,0,0,2,2,2
2,7,7,7,7,7,7,7,2,2,2,2,2,2,2,2,2,2,5,5,5,7,7,7,7,7,5,5,2,2,2,2,2,2,2,2,2,5,5,5,5,0,0,4,4,2,2,2,2,2,2
2,0,7,7,7,7,7,2,2,2,2,2,2,2,2,2,2,2,5,5,5,7,7,7,0,5,5,2,2,2,2,2,2,2,2,2,2,2,5,5,5,0,0,4,4,2,2,2,2,2,2
2,0,7,7,7,7,2,2,2,2,2,2,2,2,2,2,2,2,5,5,5,5,2,0,0,5,2,2,2,2,2,2,2,7,7,2,2,2,5,5,5,0,0,4,4,2,2,2,2,2,2
2,0,0,0,2,2,2,2,2,2,2,2,2,2,2,2,2,2,2,5,5,5,2,0,0,2,2,2,0,2,2,2,2,7,7,7,2,2,2,5,5,0,0,4,4,2,2,2,2,2,2
2,0,0,0,2,2,2,2,2,2,2,2,2,2,2,2,2,2,2,2,5,5,2,2,2,2,2,2,2,2,2,2,7,7,7,7,2,2,2,2,5,0,5,4,2,2,2,2,2,2,2
2,0,0,0,2,2,2,2,2,2,2,2,2,2,2,2,2,2,2,2,2,2,2,2,2,2,2,2,2,2,2,2,7,7,7,7,2,2,2,2,0,0,0,2,0,0,0,0,0,0,0
2,0,0,11,2,2,2,2,2,2,2,2,2,2,2,2,2,2,2,2,2,2,2,2,2,2,2,2,2,2,2,2,7,7,7,7,2,0,0,0,0,0,0,0,0,0,0,0,0,0,0
2,2,2,2,2,2,2,0,0,2,2,2,2,2,2,2,2,2,2,2,2,2,2,2,2,0,0,2,2,2,2,2,7,7,7,7,0,0,0,0,0,0,0,0,0,0,0,0,0,0,0
2,2,2,2,2,0,0,0,0,2,2,2,2,2,2,2,2,2,2,2,2,2,2,2,2,0,0,0,7,2,2,2,7,7,0,0,0,0,0,0,0,0,0,0,0,0,0,0,0,0,0
2,2,2,2,0,0,0,0,0,2,2,2,2,2,2,2,2,2,2,2,2,2,2,0,2,0,0,0,7,7,7,0,0,0,0,0,0,0,0,0,0,0,0,0,0,0,0,2,2,2,0
2,2,2,2,0,0,0,0,0,2,2,2,2,2,2,2,2,2,8,8,2,2,2,2,0,2,7,7,7,7,7,0,0,0,0,0,0,0,0,0,0,0,0,0,0,2,2,2,2,2,2
2,2,2,2,2,0,0,0,0,2,2,2,2,2,2,2,2,2,2,8,2,2,2,2,2,0,7,7,7,7,7,0,0,0,0,0,0,0,0,0,2,0,0,0,0,0,2,2,2,2,2
2,2,2,2,2,2,2,2,2,2,3,2,2,2,2,2,2,2,2,2,2,2,2,2,5,5,5,5,5,7,7,0,0,0,0,0,0,0,2,2,2,0,0,0,0,0,0,2,2,2,2
2,2,2,2,2,2,2,2,2,2,2,2,2,2,2,2,2,2,2,2,2,2,2,0,0,0,32,7,7,7,7,7,0,0,0,0,0,0,0,2,2,0,0,0,0,0,0,2,2,2,2
2,2,2,2,2,2,2,2,2,2,2,2,2,2,2,2,2,2,2,2,0,0,0,0,0,0,32,7,7,7,2,2,2,2,0,0,0,0,0,0,5,0,0,0,0,0,2,2,2,2,2
2,2,2,2,2,2,2,2,2,2,2,2,2,2,2,2,2,2,2,0,0,0,0,0,0,0,32,7,2,2,2,2,2,2,2,2,0,0,0,0,0,2,2,2,2,2,2,2,2,2,2
2,2,2,2,2,2,2,2,2,2,2,2,2,2,2,2,2,2,0,0,0,0,0,0,0,0,0,0,0,2,2,2,2,2,5,2,0,0,0,0,0,5,5,2,2,2,2,2,2,2,2
2,2,2,2,2,2,2,2,2,2,2,2,2,2,2,2,2,0,0,0,0,0,0,0,0,0,0,0,0,0,0,2,2,5,5,5,2,5,0,0,0,0,0,2,2,2,2,2,2,2,2
2,2,2,2,2,2,2,2,2,2,2,2,2,2,2,2,0,0,0,0,0,0,0,0,0,0,0,0,0,0,0,0,2,5,5,5,5,2,2,2,5,0,0,2,2,2,2,2,2,2,2
2,2,2,2,2,2,2,2,2,2,2,2,4,4,2,0,0,0,0,0,0,0,0,0,0,0,0,0,0,0,0,0,0,5,5,5,5,2,2,2,2,2,2,2,2,2,2,2,2,2,0
2,2,2,2,2,2,2,2,0,2,2,2,4,4,2,0,0,0,0,0,0,0,0,0,0,0,0,0,0,0,0,0,0,0,5,7,7,7,7,7,7,7,2,2,2,2,2,2,2,2,0
2,2,2,2,2,2,2,2,2,2,2,2,4,4,2,0,0,0,0,0,0,0,0,0,0,0,0,0,0,0,0,0,0,0,7,7,7,7,7,7,7,7,7,2,2,2,2,2,2,2,0
2,2,2,2,2,2,2,2,2,2,2,2,2,2,0,0,0,0,0,0,0,0,0,0,0,0,0,0,0,0,0,0,0,0,0,7,7,7,0,0,7,7,2,2,2,2,2,2,2,2,2
2,2,2,2,2,2,2,2,2,0,0,0,0,7,0,0,0,0,0,0,0,0,0,0,0,0,0,0,0,0,0,0,0,0,0,7,7,7,0,0,2,2,2,2,2,2,2,2,2,2,2
2,2,2,2,2,2,2,2,2,0,0,0,0,7,0,0,0,0,0,0,0,0,0,0,0,0,0,0,0,0,0,0,0,0,0,7,0,0,0,0,2,2,2,2,2,2,2,2,2,2,2
2,2,2,2,2,2,2,2,2,0,0,0,0,7,0,0,0,0,0,0,0,0,0,0,0,0,0,0,0,0,0,0,0,0,0,7,0,0,0,2,2,2,2,2,2,2,2,2,2,2,2
2,2,2,2,2,2,2,2,2,0,0,0,0,7,0,0,0,0,0,0,0,0,0,0,0,0,0,0,0,0,0,0,0,0,0,7,0,0,2,2,2,2,2,2,2,2,2,2,2,2,2
2,2,3,3,2,2,2,2,2,0,0,0,0,7,0,0,0,0,0,0,0,0,0,0,0,0,0,0,0,0,0,0,0,0,0,7,2,2,2,2,2,2,2,2,2,2,2,2,2,2,2
2,2,3,3,2,2,2,2,2,0,0,0,0,0,7,0,0,0,0,0,0,0,0,0,0,0,0,0,0,0,0,0,0,0,2,2,2,2,2,2,2,2,2,2,2,2,2,2,2,2,2
2,2,2,2,2,2,2,2,2,2,0,0,0,0,7,0,0,0,0,0,0,0,0,0,0,0,0,0,0,0,0,0,0,0,2,2,2,2,2,2,2,2,2,2,2,2,2,2,2,2,2
2,2,2,2,2,2,2,2,2,2,2,2,7,7,2,0,0,0,0,0,0,0,0,0,0,0,0,0,0,0,0,0,0,2,2,2,2,2,2,2,2,2,2,2,2,2,2,2,2,2,2
2,2,2,2,2,2,2,2,2,2,2,2,7,7,7,7,0,0,0,0,0,0,0,0,0,0,0,0,0,0,0,0,2,2,2,2,2,2,2,2,2,2,2,0,2,2,2,2,7,7,7
2,2,2,2,2,2,2,2,2,2,2,7,7,7,7,7,7,0,0,0,0,0,0,0,0,0,0,0,0,0,0,2,2,2,2,2,2,2,2,2,4,4,0,0,0,2,2,7,7,7,28
2,2,2,2,2,2,2,2,2,2,7,7,7,7,7,7,7,2,0,0,0,0,0,0,0,0,0,0,0,2,2,2,2,2,2,2,2,2,2,2,4,4,0,0,0,2,2,2,7,0,33
2,2,2,2,2,2,2,2,2,7,7,7,7,7,7,2,2,2,2,0,0,0,0,0,0,2,5,5,5,2,2,2,2,2,2,2,2,2,2,2,4,4,0,0,0,0,2,2,2,0,0
2,2,2,2,2,2,2,2,2,7,7,0,0,2,2,2,2,2,2,2,0,0,0,0,2,2,2,0,0,2,2,2,2,2,2,3,2,2,2,2,4,4,0,0,0,0,2,2,2,0,0
2,2,2,2,2,2,2,2,2,2,0,0,0,0,2,2,2,2,2,7,7,7,7,7,7,7,2,2,2,2,2,2,2,2,3,2,2,2,2,2,4,4,0,0,0,0,2,2,2,0,0
2,2,2,2,2,2,2,2,2,2,0,0,0,0,2,2,2,2,7,7,7,7,7,7,7,7,7,2,2,2,2,2,2,2,2,2,2,2,2,2,2,2,2,0,0,0,0,2,2,0,0
2,2,2,2,2,2,2,2,2,2,0,0,0,0,2,2,2,2,7,7,7,7,7,7,7,7,7,11,2,2,2,2,2,2,2,2,2,2,2,2,2,2,2,0,0,0,0,2,2,0,0
2,2,2,2,2,2,2,2,2,2,2,2,2,2,2,2,2,2,7,7,7,7,7,7,7,0,2,2,2,2,2,2,2,2,2,2,2,2,2,2,2,2,2,0,0,0,0,2,2,0,0
2,2,8,2,2,2,2,2,2,2,2,2,2,2,2,2,2,2,0,0,5,5,5,5,2,2,2,2,2,2,2,2,2,2,2,2,2,2,2,2,2,2,2,2,0,0,0,0,2,0,0
2,2,2,2,2,2,2,2,2,2,2,2,2,2,2,2,2,5,0,0,0,5,5,5,2,2,2,2,2,2,2,2,2,2,2,2,2,2,2,2,2,2,2,2,0,0,0,0,0,0,0
2,2,2,2,2,2,2,2,2,2,2,2,2,2,2,2,2,5,0,0,0,5,0,0,2,2,2,2,2,2,2,2,2,2,2,2,2,2,2,2,2,2,2,2,0,0,0,0,0,0,0
2,2,2,2,2,2,2,2,7,2,2,2,2,2,2,2,2,2,2,2,2,2,0,7,0,0,2,2,11,2,2,2,2,2,2,2,2,2,2,2,2,2,2,2,2,0,0,0,0,0,0
2,2,2,2,2,2,2,2,7,7,2,2,2,2,2,2,2,2,2,2,2,2,2,7,0,0,2,2,2,11,2,2,2,2,2,2,2,2,2,2,2,2,2,2,2,0,0,0,0,0,0
2,2,2,2,2,2,2,2,7,7,7,2,2,2,2,2,2,2,2,2,2,2,2,2,2,0,0,2,2,2,2,2,2,2,2,2,2,2,2,2,2,2,2,2,2,2,2,0,0,0,0
2,2,2,2,2,2,2,2,7,7,7,7,2,2,2,2,2,2,2,2,2,2,2,2,2,2,2,2,2,2,2,2,2,2,2,2,2,2,2,2,2,2,2,2,2,2,2,2,2,2,2
2,2,2,2,2,2,2,2,7,7,7,7,2,2,2,2,2,2,2,2,2,2,2,2,2,2,2,2,2,2,2,2,2,2,2,2,2,2,2,2,2,2,2,2,2,2,2,2,2,2,2
2,2,2,2,2,2,2,2,7,7,7,7,8,2,2,2,2,2,2,2,2,2,2,2,2,2,2,2,2,2,2,2,2,2,2,2,2,2,2,2,2,2,2,2,2,2,2,2,2,2,2
2,2,2,2,2,2,2,2,7,7,7,7,8,2,2,2,2,2,2,2,2,2,2,2,3,3,2,2,2,2,2,2,2,2,2,2,2,2,2,2,2,2,2,2,2,2,2,2,2,2,2
:endlayer
layer: 17
2,2,2,7,7,7,7,2,2,2,2,2,2,2,2,2,2,2,5,5,5,5,7,7,7,7,5,5,5,5,2,2,2,2,2,2,2,2,5,5,5,0,0,0,0,0,0,0,0,0,2
2,7,7,7,7,7,7,2,2,2,2,2,2,2,2,2,2,2,5,5,5,7,7,7,7,5,5,5,2,2,2,2,2,2,2,2,2,2,5,5,5,0,0,4,4,0,0,0,0,0,2
2,0,7,7,7,7,2,2,2,2,2,2,2,2,2,2,2,2,5,5,5,7,7,2,0,5,5,2,2,2,2,2,2,2,2,2,2,2,5,5,5,0,0,4,4,2,2,2,2,2,2
2,0,7,7,7,2,2,2,2,2,2,2,2,2,2,2,2,2,5,5,5,5,2,2,0,5,2,2,2,0,0,2,2,7,7,2,2,2,2,5,5,0,0,4,4,2,2,2,2,2,2
2,0,0,0,2,2,2,2,2,2,2,2,2,2,2,2,2,2,2,5,5,5,2,2,0,2,2,2,0,0,0,2,2,7,7,7,2,2,2,2,5,0,0,0,4,2,2,2,2,2,2
2,0,0,0,0,2,2,2,2,2,2,2,2,2,2,2,2,2,2,2,5,5,2,2,2,2,2,2,2,2,2,2,7,7,7,7,2,2,2,2,2,0,0,0,2,2,2,2,2,2,2
2,0,0,0,0,2,2,2,2,2,2,2,2,2,2,2,2,2,2,2,2,2,2,2,2,2,2,2,2,2,2,2,7,7,7,7,2,2,2,2,0,0,0,0,2,0,0,0,0,2,2
2,0,0,0,0,0,2,2,2,2,2,2,2,2,2,2,2,2,2,2,2,2,2,2,2,2,2,2,2,2,2,2,7,7,7,7,2,2,0,0,0,0,0,0,0,0,0,0,0,0,0
2,0,0,0,0,0,2,2,2,2,2,2,2,2,2,2,2,2,2,2,2,2,2,2,2,2,2,2,34,0,2,2,7,7,7,7,0,0,0,0,0,0,0,0,0,0,0,0,0,0,0
2,2,0,0,0,0,2,2,2,2,2,2,2,2,2,2,2,2,2,2,2,2,2,2,2,2,2,2,2,0,0,0,35,7,7,0,0,0,0,0,0,0,0,0,0,0,0,0,0,0,2
2,2,2,0,0,2,2,2,0,2,2,2,2,2,2,2,2,2,2,2,2,2,2,2,2,2,2,2,7,0,7,2,2,7,0,0,0,0,0,0,0,0,0,0,7,2,2,2,2,2,2
2,2,2,2,2,2,2,2,0,2,2,2,2,2,2,2,2,2,8,8,2,2,2,2,2,2,7,7,7,0,7,0,0,0,0,0,0,0,0,0,0,0,0,2,2,2,2,2,2,2,2
2,2,2,2,2,2,2,2,2,2,2,2,2,2,2,2,2,2,2,8,2,2,2,2,2,0,7,0,0,0,7,0,0,0,0,0,0,0,0,2,2,0,0,0,0,2,2,2,2,2,2
2,2,2,2,2,2,2,2,2,2,2,2,2,2,2,2,2,2,2,2,2,2,2,2,5,5,7,0,7,7,7,0,0,0,0,0,0,2,2,2,2,0,0,0,0,0,2,2,2,2,2
2,2,2,2,2,2,2,2,2,2,2,2,2,2,2,2,2,2,2,2,2,2,2,0,0,0,0,0,0,7,7,7,0,0,0,0,2,2,2,2,2,0,0,0,0,2,2,2,2,2,2
2,2,2,2,2,2,2,2,2,2,2,2,2,2,2,2,2,2,2,2,0,0,0,0,0,0,0,0,0,0,0,0,2,2,2,2,0,0,0,0,2,0,11,2,2,2,2,2,2,2,2
2,2,2,2,2,2,2,2,2,2,2,2,2,2,2,2,2,2,2,0,0,0,0,0,0,0,0,0,0,0,0,0,0,2,2,2,0,0,0,0,0,2,2,2,2,2,2,2,2,2,0
2,2,2,2,2,2,2,2,2,2,2,2,2,2,2,2,2,2,0,0,0,0,0,0,0,0,0,0,0,0,0,0,0,0,5,2,2,0,0,0,0,5,5,2,2,2,2,2,2,2,2
2,2,2,2,2,2,2,2,2,2,2,2,2,2,2,2,2,0,0,0,0,0,0,0,0,0,0,0,0,0,0,0,0,0,0,5,2,2,0,0,0,0,0,2,2,2,2,2,2,2,2
2,2,2,2,2,2,2,2,2,2,2,2,2,2,2,2,0,0,0,0,0,0,0,0,0,0,0,0,0,0,0,0,0,0,0,0,5,2,2,2,5,0,0,2,2,2,2,2,2,2,0
2,2,2,2,2,2,2,2,2,2,2,2,2,2,2,0,0,0,0,0,0,0,0,0,0,0,0,0,0,0,0,0,0,0,0,0,0,2,2,2,2,2,2,2,2,2,2,2,2,2,0
2,2,2,2,2,2,2,2,2,2,2,2,2,2,2,0,0,0,0,0,0,0,0,0,0,0,0,0,0,0,0,0,0,0,0,0,0,7,7,7,7,7,2,2,2,2,2,2,2,2,0
2,2,2,2,2,2,2,2,2,2,2,2,2,2,2,0,0,0,0,0,0,0,0,0,0,0,0,0,0,0,0,0,0,0,0,0,0,7,7,7,7,7,7,2,2,2,2,2,2,2,0
2,2,2,2,2,2,2,2,2,2,2,2,2,2,0,0,0,0,0,0,0,0,0,0,0,0,0,0,0,0,0,0,0,0,0,0,0,0,7,7,7,7,2,2,2,2,2,2,2,2,2
2,2,2,2,2,2,2,2,2,2,0,0,0,2,0,0,0,0,0,0,0,0,0,0,0,0,0,0,0,0,0,0,0,0,0,0,0,0,7,7,2,2,2,2,2,2,2,2,2,2,2
2,2,2,2,2,2,2,2,2,0,0,0,0,7,0,0,0,0,0,0,0,0,0,0,0,0,0,0,0,0,0,0,0,0,0,36,36,36,7,2,2,2,2,0,0,2,2,2,2,2,2
2,2,2,2,2,2,2,2,2,0,0,0,0,7,0,0,0,0,0,0,0,0,0,0,0,0,0,0,0,0,0,0,0,0,0,7,0,0,2,2,2,2,0,0,0,2,2,2,2,2,2
2,2,2,2,2,2,2,2,2,0,0,0,0,7,0,0,0,0,0,0,0,0,0,0,0,0,0,0,0,0,0,0,0,0,0,7,0,0,2,2,2,2,0,0,0,2,2,2,5,5,5
2,2,2,2,2,2,2,2,2,0,0,0,0,7,0,0,0,0,0,0,0,0,0,0,0,0,0,0,0,0,0,0,0,0,0,7,0,2,2,2,2,2,0,0,0,2,2,2,5,5,5
2,2,2,2,2,2,2,2,2,2,0,0,0,0,7,0,0,0,0,0,0,0,0,0,0,0,0,0,0,0,0,0,0,0,7,2,2,2,2,2,2,2,0,0,0,2,2,2,2,2,2
2,2,2,2,2,2,2,2,2,2,2,0,0,0,7,0,0,0,0,0,0,0,0,0,0,0,0,0,0,0,0,0,0,0,2,2,2,2,2,2,2,2,0,0,0,2,2,2,2,2,2
2,2,2,2,2,2,2,2,2,2,2,2,2,2,2,0,0,0,0,0,0,0,0,0,0,0,0,0,0,0,0,0,0,2,2,2,2,2,2,2,2,2,0,0,0,2,2,2,7,7,2
2,2,2,2,2,2,2,2,2,2,2,2,2,2,2,2,0,0,0,0,0,0,0,0,0,0,0,0,0,0,0,0,2,2,2,2,2,2,2,2,2,2,0,0,0,2,7,7,7,7,7
2,2,2,2,2,2,2,2,2,2,2,2,2,2,2,2,2,0,0,0,0,0,0,0,0,0,0,0,0,0,0,2,2,2,2,2,2,2,2,2,2,2,0,0,0,2,7,7,7,7,0
2,2,2,2,2,2,2,2,2,2,2,2,2,7,11,2,2,2,0,0,0,0,0,0,0,0,0,0,0,2,2,2,2,2,2,2,2,2,2,2,2,2,0,0,0,2,2,7,7,0,0
2,2,2,2,2,2,2,2,2,2,2,2,2,2,11,2,2,2,2,0,0,0,0,0,0,2,5,5,5,2,2,2,2,2,2,2,2,2,2,2,4,4,0,0,0,0,2,2,7,0,0
2,2,2,2,2,2,2,2,2,2,2,2,2,2,2,2,2,2,2,2,0,0,0,0,2,2,0,0,0,0,2,2,2,2,2,3,2,2,2,2,4,4,0,0,0,0,2,2,0,0,0
2,2,2,2,2,2,2,2,2,2,2,0,0,0,2,2,2,2,2,2,2,7,7,7,2,2,2,2,2,2,2,2,2,2,3,2,2,2,2,2,4,4,2,0,0,0,2,2,0,0,0
2,2,2,2,2,2,2,2,2,2,0,0,0,0,2,2,2,2,7,7,7,7,7,7,7,2,2,2,2,2,2,2,2,2,2,2,2,2,2,2,2,2,2,0,0,0,2,2,2,0,0
2,2,2,2,2,2,2,2,2,2,2,0,0,2,2,2,2,2,7,7,7,7,7,7,7,5,2,2,2,2,2,2,2,2,2,2,2,2,2,2,2,2,2,0,0,0,2,2,2,0,0
2,2,2,2,2,2,2,2,2,2,2,2,2,2,2,2,2,2,2,5,7,7,7,5,2,2,2,2,2,2,2,2,2,2,2,2,2,2,2,2,2,2,2,2,0,0,0,2,2,0,0
2,2,2,2,2,2,2,2,2,2,2,2,2,2,2,2,2,2,0,0,5,5,5,5,2,2,2,2,2,2,2,2,2,2,2,2,2,2,2,2,2,2,2,2,0,0,0,0,2,0,0
2,2,2,2,2,2,2,8,2,2,2,2,2,2,2,2,2,5,0,0,0,5,5,5,2,2,2,2,2,2,2,2,2,2,2,2,2,2,2,2,2,2,2,2,0,0,0,0,0,0,0
2,2,2,2,2,2,8,2,2,2,2,2,2,2,2,2,2,5,0,0,0,2,2,2,0,0,0,2,2,2,2,2,2,2,2,2,2,2,2,2,2,2,2,2,0,0,0,0,0,0,0
2,2,2,2,2,2,2,2,2,2,2,2,2,2,2,2,2,2,2,2,2,2,2,7,0,0,2,2,11,2,2,2,2,2,2,2,2,2,2,2,2,2,2,2,2,0,0,0,0,0,0
2,2,2,2,2,2,2,2,2,2,2,2,2,2,2,2,2,2,2,2,2,2,2,2,0,0,2,2,2,11,2,2,2,2,2,2,2,2,2,2,2,2,2,7,7,7,0,0,0,0,0
2,2,2,2,2,2,2,2,2,2,2,2,2,2,2,2,2,2,2,2,2,2,2,2,2,2,2,2,2,2,2,2,2,2,2,2,2,2,2,2,2,2,2,7,7,7,7,0,0,0,0
2,2,2,2,2,2,2,2,2,7,2,2,2,2,2,2,2,2,2,2,2,2,2,2,2,2,2,2,2,2,2,2,2,2,2,2,2,2,2,2,2,2,2,2,2,7,7,2,2,2,2
2,2,2,2,2,2,2,2,2,7,7,2,2,2,2,2,2,2,2,4,4,2,2,2,2,2,2,2,2,2,2,2,2,2,2,2,2,2,2,2,2,2,2,2,2,2,2,2,2,2,2
2,2,2,2,2,2,2,2,7,7,7,8,2,2,2,2,2,2,4,4,4,2,2,2,2,2,2,2,2,2,2,2,2,2,2,2,2,2,2,2,2,2,2,2,2,2,2,2,2,2,2
2,2,2,7,7,7,7,7,7,7,2,2,2,2,2,2,2,4,4,4,2,2,2,2,2,2,2,2,2,2,2,2,2,2,2,2,2,2,2,2,2,2,2,2,2,2,2,2,2,2,2
:endlayer
layer: 18
2,2,2,2,2,2,2,2,2,2,2,2,2,2,2,2,2,2,5,5,5,5,2,7,7,2,5,2,2,2,2,2,2,2,2,2,2,2,2,2,2,0,0,2,0,0,0,0,0,0,0
2,2,2,2,2,2,2,2,2,2,2,2,2,2,2,2,2,2,5,5,5,5,2,2,2,2,2,2,5,5,5,2,2,2,2,2,2,2,2,2,2,0,0,2,2,2,0,0,0,0,0
2,2,2,2,2,2,2,2,2,2,2,2,2,2,2,2,2,2,2,5,5,5,2,2,0,2,2,2,2,2,2,0,0,2,2,2,2,2,2,2,2,0,0,2,2,2,2,2,2,2,2
2,2,2,2,2,2,2,2,2,2,2,2,2,2,2,2,2,2,2,5,5,5,2,2,0,2,2,2,2,0,0,0,0,0,2,2,2,2,2,2,2,0,0,2,2,2,2,2,2,2,2
2,0,0,0,2,2,2,2,2,2,2,2,2,2,2,2,2,2,2,2,5,2,2,2,0,2,2,2,2,0,0,0,0,2,7,2,2,2,2,2,2,0,0,0,2,2,2,2,2,2,2
2,0,0,0,0,2,2,2,2,2,2,2,2,2,2,2,2,2,2,2,2,2,2,2,2,2,2,2,2,2,2,2,2,7,7,2,2,2,2,2,2,0,0,0,2,2,2,2,2,2,2
2,0,0,0,0,0,2,2,2,2,2,2,2,2,2,2,2,2,2,2,2,2,2,2,2,2,2,2,2,2,2,2,2,7,7,2,2,2,2,2,2,0,0,0,0,2,2,2,2,2,2
2,0,0,0,0,0,2,2,2,2,2,2,2,2,2,2,2,2,2,2,2,2,2,2,2,2,2,2,2,2,2,2,7,7,7,7,2,2,2,0,0,0,0,0,0,2,2,2,2,2,2
2,0,0,0,0,0,2,2,2,2,2,2,2,2,2,2,2,2,2,2,2,2,2,2,2,2,2,7,34,0,2,2,2,7,7,2,2,0,0,0,0,0,0,0,0,0,2,2,2,2,2
2,2,0,0,0,0,0,0,0,2,2,2,2,2,2,2,2,2,2,2,2,2,2,8,8,2,2,2,2,0,0,0,0,7,7,7,0,0,0,0,0,0,0,0,0,2,2,2,2,2,2
2,2,0,0,0,0,0,0,0,0,0,2,2,2,2,2,2,2,2,2,2,2,2,8,8,2,2,2,2,0,2,2,2,7,7,7,0,0,0,0,0,0,0,0,0,2,2,2,2,2,2
2,2,2,0,0,0,0,0,0,0,0,2,2,2,8,2,2,2,2,2,2,2,2,2,2,2,2,7,7,0,7,0,0,2,2,7,0,0,0,0,7,0,0,0,2,2,2,2,2,2,2
2,2,2,2,0,0,0,0,0,0,0,2,2,2,2,2,2,2,2,2,2,2,2,2,2,0,7,0,0,0,7,0,0,0,2,2,2,2,2,2,2,0,0,2,2,2,2,2,2,2,8
2,2,2,2,2,2,0,0,0,0,2,2,2,2,2,2,2,2,2,2,2,2,2,2,5,7,7,0,7,7,7,0,0,2,2,2,2,2,2,2,2,0,0,2,2,2,2,2,2,2,8
2,2,2,2,2,2,2,2,2,2,2,2,2,2,2,2,2,2,2,2,2,2,2,0,0,0,0,0,0,7,7,2,2,2,2,2,2,2,2,2,2,0,0,2,2,2,2,2,2,2,2
2,2,2,2,2,2,2,2,2,2,2,2,2,2,2,2,2,2,2,2,0,0,0,0,0,0,0,0,0,0,0,0,2,2,2,2,2,2,2,2,2,2,11,2,2,2,2,2,2,2,37
2,2,2,2,2,2,2,2,2,2,2,2,2,2,2,2,2,2,2,0,0,0,0,0,0,0,0,0,0,0,0,0,0,2,2,2,2,2,0,0,2,11,2,2,2,2,2,2,2,2,0
2,2,2,2,2,2,2,2,2,2,2,2,2,2,2,2,2,2,0,0,0,0,0,0,0,0,0,0,0,0,0,0,0,0,2,2,2,2,0,0,2,2,2,2,2,2,2,2,2,2,0
2,2,2,2,2,2,2,2,2,2,2,2,2,2,2,2,2,0,0,0,0,0,0,0,0,0,0,0,0,0,0,0,0,0,0,2,2,2,2,2,2,0,2,2,2,2,2,2,2,2,2
2,2,2,2,2,2,2,2,2,2,2,2,2,2,2,2,0,0,0,0,0,0,0,0,0,0,0,0,0,0,0,0,0,0,0,0,2,2,2,2,2,2,2,2,2,2,2,2,2,2,0
2,2,2,2,2,2,2,2,2,2,2,2,2,2,2,0,0,0,0,0,0,0,0,0,0,0,0,0,0,0,0,0,0,0,0,0,0,2,2,2,2,2,2,2,2,2,2,2,2,2,0
2,2,2,2,2,2,2,2,2,2,2,2,2,2,2,0,0,0,0,0,0,0,0,0,0,0,0,0,0,0,0,0,0,0,0,0,0,7,7,7,7,2,2,2,2,2,2,2,2,2,0
2,2,2,2,2,2,2,2,2,2,2,2,2,2,2,0,0,0,0,0,0,0,0,0,0,0,0,0,0,0,0,0,0,0,0,0,0,7,7,7,7,7,2,2,2,2,2,2,2,2,2
2,2,2,2,2,2,2,2,2,2,2,2,2,2,0,0,0,0,0,0,0,0,0,0,0,0,0,0,0,0,0,0,0,0,0,0,0,0,7,7,7,2,2,2,2,2,4,2,2,2,2
2,2,2,2,2,2,2,2,2,2,2,0,0,2,0,0,0,0,0,0,0,0,0,0,0,0,0,0,0,0,0,0,0,0,0,0,0,0,7,2,2,2,2,2,2,4,4,2,2,2,2
2,2,2,2,2,2,2,2,2,2,0,0,0,7,0,0,0,0,0,0,0,0,0,0,0,0,0,0,0,0,0,0,0,0,0,0,0,0,2,2,2,2,2,0,0,2,2,2,2,2,2
2,2,2,2,2,2,2,2,2,2,0,0,0,7,0,0,0,0,0,0,0,0,0,0,0,0,0,0,0,0,0,0,0,0,0,36,36,36,2,2,2,2,0,0,0,2,2,5,5,5,5
2,2,2,2,2,2,2,2,2,2,0,0,0,7,0,0,0,0,0,0,0,0,0,0,0,0,0,0,0,0,0,0,0,0,0,7,7,2,2,2,2,2,0,0,0,5,5,5,5,5,5
2,2,2,2,2,2,2,2,2,2,0,0,0,7,0,0,0,0,0,0,0,0,0,0,0,0,0,0,0,0,0,0,0,0,0,7,7,2,2,2,2,2,0,0,0,5,5,5,5,5,5
2,2,8,2,2,2,2,2,2,2,0,0,0,0,7,0,0,0,0,0,0,0,0,0,0,0,0,0,0,0,0,0,0,0,7,2,2,2,2,2,2,2,0,0,0,2,2,5,5,5,5
2,2,8,8,2,2,2,2,2,2,2,2,0,0,7,0,0,0,0,0,0,0,0,0,0,0,0,0,0,0,0,0,0,0,7,2,2,2,2,2,2,2,0,0,0,2,2,2,2,2,2
2,2,2,2,2,2,2,2,2,2,2,2,2,2,2,0,0,0,0,0,0,0,0,0,0,0,0,0,0,0,0,0,0,2,2,2,2,2,2,2,2,2,0,0,0,2,7,7,7,7,2
2,2,2,2,2,2,2,2,2,2,2,2,2,2,2,2,0,0,0,0,0,0,0,0,0,0,0,0,0,0,0,0,2,2,2,2,2,2,2,2,2,2,0,0,0,2,7,7,7,7,7
2,2,2,2,2,2,2,2,2,2,2,2,2,2,2,2,2,0,0,0,0,0,0,0,0,0,0,0,0,0,0,2,2,2,2,2,2,2,2,2,2,2,0,0,0,2,7,7,7,7,0
2,2,2,2,2,2,2,2,2,2,2,2,2,2,2,2,2,2,0,0,0,0,0,0,0,0,0,0,0,2,2,2,2,2,2,2,2,2,2,2,2,2,0,0,0,2,7,7,7,0,0
2,2,2,2,2,2,2,0,0,2,2,2,2,2,2,2,2,2,2,0,0,0,0,0,0,2,21,21,21,2,2,2,2,2,2,2,2,2,2,2,2,2,0,0,0,2,2,2,7,0,0
2,2,2,2,2,2,0,0,0,0,2,2,2,2,2,2,2,2,2,2,0,0,0,0,2,2,2,21,21,2,2,2,2,2,2,2,2,2,2,2,2,2,2,0,0,2,2,2,2,0,0
2,2,2,2,2,2,2,2,2,0,2,2,2,2,2,2,2,2,2,2,2,2,2,2,2,2,2,2,2,2,2,2,2,2,2,2,2,2,2,2,2,2,2,2,2,2,2,2,0,0,0
2,2,2,2,2,2,2,2,2,0,2,2,2,2,2,2,2,2,2,2,2,2,2,2,2,2,2,2,2,2,2,2,2,2,2,2,2,2,2,2,2,2,2,2,2,2,2,2,2,0,0
2,2,2,2,2,2,2,2,2,2,2,2,2,2,2,2,2,2,2,2,2,2,2,2,2,2,2,2,2,2,2,2,2,2,2,2,2,2,2,2,2,2,2,2,2,2,2,2,2,0,0
2,2,2,2,2,2,2,2,2,2,2,2,2,2,2,2,2,2,2,2,5,5,5,2,2,2,2,2,2,2,2,2,2,2,2,2,2,2,2,2,2,2,2,2,2,2,2,2,2,0,0
2,2,2,2,2,2,2,2,2,2,2,2,2,2,2,2,2,2,2,0,5,5,5,2,2,2,2,2,2,2,2,2,2,2,2,2,2,2,2,2,2,2,2,2,2,2,2,2,2,0,0
2,2,2,2,2,2,2,8,2,2,2,2,2,2,2,2,2,2,2,0,0,5,2,2,0,0,2,2,2,2,2,2,2,2,2,2,2,2,2,2,2,2,2,2,2,2,0,2,2,0,0
2,2,2,2,2,2,8,2,2,2,2,2,2,2,2,2,2,2,2,2,2,2,2,7,0,0,0,2,2,2,2,2,2,2,2,2,2,2,2,2,2,2,2,2,2,0,0,0,0,0,0
