# Ancient Warfare Structure Template File
# auto-generated structure file. created on: 4/14/2014 at: 16:53:41
# Lines beginning with # denote comments

header:
version=2.0
name=CivReligiousCloisteredMonasteryMOH
size=31,49,45
offset=13,2,42
:endheader

#### VALIDATION ####
validation:
type=ground
survival=false
worldGenEnabled=true
unique=true
preserveBlocks=false
selectionWeight=10
clusterValue=10
minDuplicateDistance=1
dimensionWhiteList=false
dimensionList=
biomeWhiteList=true
biomeList=highlands.meadow,bop.meadow,ebxl.meadow,field,orchard
leveling=12
fill=5
border=5
validTargetBlocks=clay,lapis_ore,sand,grass,lit_redstone_ore,stone,gravel,iron_ore,diamond_ore,stained_hardened_clay,dirt,coal_ore,redstone_ore,gold_ore
data:
:enddata
:endvalidation

#### LAYERS ####
layer: 0
1,1,1,1,1,1,1,1,1,1,1,1,1,1,1,1,1,1,1,1,1,1,1,1,1,1,1,1,1,1,1
1,1,1,1,1,1,1,1,1,1,1,1,1,1,1,1,1,1,1,1,1,1,1,1,1,1,1,1,1,1,1
1,1,1,1,1,1,1,1,1,1,1,1,1,1,1,1,1,1,1,1,1,1,1,1,1,1,1,1,1,1,1
1,1,1,1,1,1,1,1,1,1,1,1,1,1,1,1,1,1,1,1,1,1,1,1,1,1,1,1,1,1,1
1,1,1,1,1,1,1,1,1,1,1,1,1,1,1,1,1,1,1,1,1,1,1,1,1,1,1,1,1,1,1
1,1,1,1,1,1,1,1,1,1,1,1,1,1,1,1,1,1,1,1,1,1,1,1,1,1,1,1,1,1,1
1,1,1,1,1,1,1,1,1,1,1,1,1,1,1,1,1,1,1,1,1,1,1,1,1,1,1,1,1,1,1
1,1,1,1,1,1,1,1,1,1,1,1,1,1,1,1,1,1,1,1,1,1,1,1,1,1,1,1,1,1,1
1,1,1,1,1,1,1,1,1,1,1,1,1,1,1,1,1,1,1,1,1,1,1,1,1,1,1,1,1,1,1
1,1,1,1,1,1,1,1,1,1,1,1,1,1,1,1,1,1,1,1,1,1,1,1,1,1,1,1,1,1,1
1,1,1,1,1,1,1,1,1,1,1,1,1,1,1,1,1,1,1,1,1,1,1,1,1,1,1,1,1,1,1
1,1,1,1,1,1,1,1,1,1,1,1,1,1,1,1,1,1,1,1,1,1,1,1,1,1,1,1,1,1,1
1,1,1,1,1,1,1,1,1,1,1,1,1,1,1,1,1,1,1,1,1,1,1,1,1,1,1,1,1,1,1
1,1,1,1,1,1,1,1,1,1,1,1,1,1,1,1,1,1,1,1,1,1,1,1,1,1,1,1,1,1,1
1,1,1,1,1,1,1,1,1,1,1,1,1,1,1,1,1,1,1,1,1,1,1,1,1,1,1,1,1,1,1
1,1,1,1,1,1,1,1,1,1,1,1,1,1,1,1,1,1,1,1,1,1,1,1,1,1,1,1,1,1,1
1,1,1,1,1,1,1,1,1,1,1,1,1,1,1,1,1,1,1,1,1,1,1,1,1,1,1,1,1,1,1
1,1,1,1,1,1,1,1,1,1,1,1,1,1,1,1,1,1,1,1,1,1,1,1,1,1,1,1,1,1,1
1,1,1,1,1,1,1,1,1,1,1,1,1,1,1,1,1,1,1,1,1,1,1,1,1,1,1,1,1,1,1
1,1,1,1,1,1,1,1,1,1,1,1,1,1,1,1,1,1,1,1,1,1,1,1,1,1,1,1,1,1,1
1,1,1,1,1,1,1,1,1,1,1,1,1,1,1,1,1,1,1,1,1,1,1,1,1,1,1,1,1,1,1
1,1,1,1,1,1,1,1,1,1,1,1,1,1,1,1,1,1,1,1,1,1,1,1,1,1,1,1,1,1,1
1,1,1,1,1,1,1,1,1,1,1,1,1,1,1,1,1,1,1,1,1,1,1,1,1,1,1,1,1,1,1
1,1,1,1,1,1,1,1,1,1,1,1,1,1,1,1,1,1,1,1,1,1,1,1,1,1,1,1,1,1,1
1,1,1,1,1,1,1,1,1,1,1,1,1,1,1,1,1,1,1,1,1,1,1,1,1,1,1,1,1,1,1
1,1,1,1,1,1,1,1,1,1,1,1,1,1,1,1,1,1,1,1,1,1,1,1,1,1,1,1,1,1,1
1,1,1,1,1,1,1,1,1,1,1,1,1,1,1,1,1,1,1,1,1,1,1,1,1,1,1,1,1,1,1
1,1,1,1,1,1,1,1,1,1,1,1,1,1,1,1,1,1,1,1,1,1,1,1,1,1,1,1,1,1,1
1,1,1,1,1,1,1,1,1,1,1,1,1,1,1,1,1,1,1,1,1,1,1,1,1,1,1,1,1,1,1
1,1,1,1,1,1,1,1,1,1,1,1,1,1,1,1,1,1,1,1,1,1,1,1,1,1,1,1,1,1,1
1,1,1,1,1,1,1,1,1,1,1,1,1,1,1,1,1,1,1,1,1,1,1,1,1,1,1,1,1,1,1
1,1,1,1,1,1,1,1,1,1,1,1,1,1,1,1,1,1,1,1,1,1,1,1,1,1,1,1,1,1,1
1,1,1,1,1,1,1,1,1,1,1,1,1,1,1,1,1,1,1,1,1,1,1,1,1,1,1,1,1,1,1
1,1,1,1,1,1,1,1,1,1,1,1,1,1,1,1,1,1,1,1,1,1,1,1,1,1,1,1,1,1,1
1,1,1,1,1,1,1,1,1,1,1,1,1,1,1,1,1,1,1,1,1,1,1,1,1,1,1,1,1,1,1
1,1,1,1,1,1,1,1,1,1,1,1,1,1,1,1,1,1,1,1,1,1,1,1,1,1,1,1,1,1,1
1,1,1,1,1,1,1,1,1,1,1,1,1,1,1,1,1,1,1,1,1,1,1,1,1,1,1,1,1,1,1
1,1,1,1,1,1,1,1,1,1,1,1,1,1,1,1,1,1,1,1,1,1,1,1,1,1,1,1,1,1,1
1,1,1,1,1,1,1,1,1,1,1,1,1,1,1,1,1,1,1,1,1,1,1,1,1,1,1,1,1,1,1
1,1,1,1,1,1,1,1,1,1,1,1,1,1,1,1,1,1,1,1,1,1,1,1,1,1,1,1,1,1,1
1,1,1,1,1,1,1,1,1,1,1,1,1,1,1,1,1,1,1,1,1,1,1,1,1,1,1,1,1,1,1
1,1,1,1,1,1,1,1,1,1,1,1,1,1,1,1,1,1,1,1,1,1,1,1,1,1,1,1,1,1,1
1,1,1,1,1,1,1,1,1,1,1,1,1,1,1,1,1,1,1,1,1,1,1,1,1,1,1,1,1,1,1
1,1,1,1,1,1,1,1,1,1,1,1,1,1,1,1,1,1,1,1,1,1,1,1,1,1,1,1,1,1,1
1,1,1,1,1,1,1,1,1,1,1,1,1,1,1,1,1,1,1,1,1,1,1,1,1,1,1,1,1,1,1
:endlayer
layer: 1
2,2,2,2,2,2,2,2,2,2,2,2,2,2,2,2,2,2,2,2,2,2,2,2,2,2,2,2,2,2,2
2,3,3,3,3,3,3,3,3,3,3,3,3,3,3,3,3,3,3,3,3,3,3,3,3,3,3,3,3,3,2
2,3,4,4,4,4,4,4,4,4,4,4,4,4,4,4,4,4,4,4,4,4,4,4,4,4,4,4,4,3,2
2,3,4,4,4,4,4,4,4,4,4,4,4,4,4,4,4,4,4,4,4,4,4,4,4,4,4,4,4,3,2
2,3,4,4,4,4,4,4,4,4,4,4,4,4,4,4,4,4,4,4,4,4,4,4,4,4,4,4,4,3,2
2,3,4,4,4,4,4,4,4,4,4,4,4,4,4,4,4,4,4,4,4,4,4,4,4,4,4,4,4,3,2
2,3,4,4,4,4,4,4,4,4,4,4,4,4,4,4,4,4,4,4,4,4,4,4,4,4,4,4,4,3,2
2,3,4,4,4,4,4,4,4,4,4,4,4,4,4,4,4,4,4,4,4,4,4,4,4,4,4,4,4,3,2
2,3,4,4,4,4,4,4,4,4,4,4,4,4,4,4,4,4,4,4,4,4,4,4,4,4,4,4,4,3,2
2,3,4,4,4,4,4,4,4,4,4,4,4,4,4,4,4,4,4,4,4,4,4,4,4,4,4,4,4,3,2
2,3,4,4,4,4,4,4,4,4,4,4,4,4,4,4,4,4,4,4,4,4,4,4,4,4,4,4,4,3,2
2,3,4,4,4,4,4,4,4,4,4,4,4,4,4,4,4,4,4,4,4,4,4,4,4,4,4,4,4,3,2
2,3,4,4,4,4,4,4,4,4,4,4,4,4,4,4,4,4,4,4,4,4,4,4,4,4,4,4,4,3,2
2,3,4,4,4,4,4,4,4,4,4,4,4,4,4,4,4,4,4,4,4,4,4,4,4,4,4,4,4,3,2
2,3,4,4,4,4,4,4,4,4,4,4,4,4,4,4,4,4,4,4,4,4,4,4,4,4,4,4,4,3,2
2,3,4,4,4,4,4,4,4,4,4,4,4,4,4,4,4,4,4,4,4,4,4,4,4,4,4,4,4,3,2
2,3,4,4,4,4,4,4,4,4,4,4,4,4,4,4,4,4,4,4,4,4,4,4,4,4,4,4,4,3,2
2,3,4,4,4,4,4,4,4,4,4,4,4,4,4,4,4,4,4,4,4,4,4,4,4,4,4,4,4,3,2
2,3,4,4,4,4,4,4,4,4,4,4,4,4,4,4,4,4,4,4,4,4,4,4,4,4,4,4,4,3,2
2,3,4,4,4,4,4,4,4,4,4,4,4,4,4,4,4,4,4,4,4,4,4,4,4,4,4,4,4,3,2
2,3,4,4,4,4,4,4,4,4,4,4,4,4,4,4,4,4,4,4,4,4,4,4,4,4,4,4,4,3,2
2,3,4,4,4,4,4,4,4,4,4,4,4,4,4,4,4,4,4,4,4,4,4,4,4,4,4,4,4,3,2
2,3,4,4,4,4,4,4,4,4,4,4,4,4,4,4,4,4,4,4,4,4,4,4,4,4,4,4,4,3,2
2,3,4,4,4,4,4,4,4,4,4,4,4,4,4,4,4,4,4,4,4,4,4,4,4,4,4,4,4,3,2
2,3,4,4,4,4,4,4,4,4,4,4,4,4,4,4,4,4,4,4,4,4,4,4,4,4,4,4,4,3,2
2,3,4,4,4,4,4,4,4,4,4,4,4,4,4,4,4,4,4,4,4,4,4,4,4,4,4,4,4,3,2
2,3,4,4,4,4,4,4,4,4,4,4,4,4,4,4,4,4,4,4,4,4,4,4,4,4,4,4,4,3,2
2,3,4,4,4,4,4,4,4,4,4,4,4,4,4,4,4,4,4,4,4,4,4,4,4,4,4,4,4,3,2
2,3,4,4,4,4,4,4,4,4,4,4,4,4,4,4,4,4,4,4,4,4,4,4,4,4,4,4,4,3,2
2,3,4,4,4,4,4,4,4,4,4,4,4,4,4,4,4,4,4,4,4,4,4,4,4,4,4,4,4,3,2
2,3,4,4,4,4,4,4,4,4,4,4,4,4,4,4,4,4,4,4,4,4,4,4,4,4,4,4,4,3,2
2,3,4,4,4,4,4,4,4,4,4,4,4,4,4,4,4,4,4,4,4,4,4,4,4,4,4,4,4,3,2
2,3,4,4,4,4,4,4,4,4,4,4,4,4,4,4,4,4,4,4,4,4,4,4,4,4,4,4,4,3,2
2,3,4,4,4,4,4,4,4,4,4,4,4,4,4,4,4,4,4,4,4,4,4,4,4,4,4,4,4,3,2
2,3,4,4,4,4,4,4,4,4,4,4,4,4,4,4,4,4,4,4,4,4,4,4,4,4,4,4,4,3,2
2,3,4,4,4,4,4,4,4,4,4,4,4,4,4,4,4,4,4,4,4,4,4,4,4,4,4,4,4,3,2
2,3,4,4,4,4,4,4,4,4,4,4,4,4,4,4,4,4,4,4,4,4,4,4,4,4,4,4,4,3,2
2,3,4,4,4,4,4,4,4,4,4,4,4,4,4,4,4,4,4,4,4,4,4,4,4,4,4,4,4,3,2
2,3,4,4,4,4,4,4,4,4,4,4,4,4,4,4,4,4,4,4,4,4,4,4,4,4,4,4,4,3,2
2,3,4,4,4,4,4,4,4,4,4,4,4,4,4,4,4,4,4,4,4,4,4,4,4,4,4,4,4,3,2
2,3,4,4,4,4,4,4,4,4,4,4,4,4,4,4,4,4,4,4,4,4,4,4,4,4,4,4,4,3,2
2,3,4,4,4,4,4,4,4,4,4,4,4,4,4,4,4,4,4,4,4,4,4,4,4,4,4,4,4,3,2
2,3,4,4,4,4,4,4,4,4,4,4,4,4,4,4,4,4,4,4,4,4,4,4,4,4,4,4,4,3,2
2,3,3,3,3,3,3,3,3,3,3,3,3,3,3,3,3,3,3,3,3,3,3,3,3,3,3,3,3,3,2
2,2,2,2,2,2,2,2,2,2,2,2,2,2,3,3,3,2,2,2,2,2,2,2,2,2,2,2,2,2,2
:endlayer
layer: 2
0,0,0,0,0,0,0,0,0,0,0,0,0,0,0,0,0,0,0,0,0,0,0,0,0,0,0,0,0,0,0
0,0,0,0,0,0,0,0,0,0,0,0,0,0,0,0,0,0,0,0,0,0,0,0,0,0,0,0,0,0,0
0,0,5,5,5,5,5,5,5,5,5,5,5,5,5,5,5,5,5,5,5,5,5,5,5,5,5,5,5,0,0
0,0,5,4,4,4,5,4,4,4,5,4,4,4,4,4,4,4,4,4,5,4,4,4,5,4,4,4,5,0,0
0,0,5,4,4,4,5,4,4,4,5,4,7,7,5,5,5,7,7,4,5,4,4,4,5,4,4,4,5,0,0
0,0,5,4,4,4,5,4,4,4,5,4,7,4,4,4,4,4,7,4,5,4,4,4,5,4,4,4,5,0,0
0,0,5,5,5,5,4,5,5,5,4,5,7,4,4,4,4,4,7,5,4,5,5,5,4,5,5,5,5,0,0
0,0,5,4,4,4,5,4,4,4,5,4,7,4,4,4,4,4,7,4,5,4,4,4,5,4,4,4,5,0,0
0,0,5,4,4,4,5,4,4,4,5,4,7,4,7,7,7,4,7,4,5,4,4,4,5,4,4,4,5,0,0
0,0,5,4,4,4,5,4,4,4,5,4,7,4,4,7,4,4,7,4,5,4,4,4,5,4,4,4,5,0,0
0,0,5,5,5,5,7,7,7,7,7,7,7,7,7,7,7,7,7,7,7,7,7,7,7,5,5,5,5,0,0
0,0,5,4,4,4,5,7,4,4,4,4,4,4,4,7,4,4,4,4,4,4,4,7,5,4,4,4,5,0,0
0,0,5,4,4,4,5,7,4,4,4,4,27,27,27,6,27,27,27,4,4,4,4,7,5,4,4,4,5,0,0
0,0,5,4,4,4,5,7,4,4,4,26,25,24,23,0,22,21,20,19,4,4,4,7,5,4,4,4,5,0,0
0,0,5,5,5,5,1,7,7,4,4,11,0,0,0,0,0,0,0,11,4,4,7,7,1,5,5,5,5,0,0
0,0,5,4,4,4,5,16,0,7,0,0,0,0,0,0,0,0,0,0,0,7,0,16,5,4,4,4,5,0,0
0,0,5,4,4,4,5,16,0,18,0,0,0,0,0,0,0,0,0,0,0,17,0,16,5,4,4,4,5,0,0
0,0,5,4,4,4,5,16,0,7,0,0,0,0,0,0,0,0,0,0,0,7,0,16,5,4,4,4,5,0,0
0,0,5,5,5,5,5,7,8,8,4,11,0,0,0,0,0,0,0,11,4,8,8,7,5,5,5,5,5,0,0
0,0,5,4,4,4,5,7,4,4,4,15,0,0,0,0,0,0,0,15,4,4,4,7,5,4,4,4,5,0,0
0,0,5,4,4,4,5,7,4,4,4,15,0,0,0,0,0,0,0,15,4,4,4,7,5,4,4,4,5,0,0
0,0,5,4,4,4,5,7,4,4,4,11,0,0,0,11,0,0,0,11,4,4,4,7,5,4,4,4,5,0,0
0,0,5,5,5,5,5,7,4,4,4,15,0,0,0,4,0,0,0,15,4,4,4,7,5,5,5,5,5,0,0
0,0,5,4,4,4,5,7,4,4,4,15,0,0,0,4,0,0,0,15,4,4,4,7,5,4,4,4,5,0,0
0,0,5,4,4,4,5,7,4,4,4,15,0,0,0,4,0,0,0,15,4,4,4,7,5,4,4,4,5,0,0
0,0,5,4,4,4,5,7,4,4,4,11,4,14,4,11,4,14,4,11,4,4,4,7,5,4,4,4,5,0,0
0,0,5,5,5,5,5,7,4,4,4,4,0,0,0,4,0,0,0,4,4,4,4,7,5,5,5,5,5,0,0
0,0,5,4,4,4,5,7,4,4,4,4,13,0,0,4,0,0,13,4,4,4,4,7,5,4,4,4,5,0,0
0,0,5,4,4,4,5,7,4,4,4,4,12,0,0,4,0,0,12,4,4,4,4,7,5,4,4,4,5,0,0
0,0,5,4,4,4,5,7,4,4,4,11,0,0,0,11,0,0,0,11,4,4,4,7,5,4,4,4,5,0,0
0,0,5,5,5,5,5,7,9,10,0,0,0,0,0,0,0,0,0,0,0,9,10,7,5,5,5,5,5,0,0
0,0,5,4,4,4,5,7,0,0,0,0,0,0,0,0,0,0,0,0,0,0,0,7,5,4,4,4,5,0,0
0,0,5,4,4,4,5,7,0,0,0,0,0,0,0,0,0,0,0,0,0,0,0,7,5,4,4,4,5,0,0
0,0,5,4,4,4,5,7,0,0,0,0,0,0,0,11,0,0,0,0,0,0,0,7,5,4,4,4,5,0,0
0,0,5,5,5,5,1,7,0,0,0,11,0,0,0,0,0,0,0,11,0,0,0,7,1,5,5,5,5,0,0
0,0,5,4,4,4,5,7,0,10,0,0,0,0,0,0,0,0,0,0,0,9,0,7,5,4,4,4,5,0,0
0,0,5,4,4,4,5,7,0,10,0,0,0,0,0,0,0,0,0,0,0,9,0,7,5,4,4,4,5,0,0
0,0,5,4,4,4,5,7,7,7,7,7,7,7,7,7,7,8,7,7,7,7,7,7,5,4,4,4,5,0,0
0,0,5,5,5,5,7,7,7,7,7,7,7,7,7,7,7,8,7,7,7,7,7,7,7,5,5,5,5,0,0
0,0,5,4,4,4,5,4,4,4,5,4,4,4,4,4,4,4,4,4,5,4,4,4,5,4,4,4,5,0,0
0,0,5,4,4,4,5,4,4,4,5,4,4,4,4,4,4,4,4,4,5,4,4,4,5,4,4,4,5,0,0
0,0,5,4,4,4,5,4,4,4,5,4,4,4,4,4,4,4,4,4,5,4,4,4,5,4,4,4,5,0,0
0,0,5,5,5,5,5,5,5,5,5,5,5,5,6,6,6,5,5,5,5,5,5,5,5,5,5,5,5,0,0
0,0,0,0,0,0,0,0,0,0,0,0,0,0,0,0,0,0,0,0,0,0,0,0,0,0,0,0,0,0,0
0,0,0,0,0,0,0,0,0,0,0,0,0,0,0,0,0,0,0,0,0,0,0,0,0,0,0,0,0,0,0
:endlayer
layer: 3
0,0,0,0,0,0,0,0,0,0,0,0,0,0,0,0,0,0,0,0,0,0,0,0,0,0,0,0,0,0,0
0,0,0,0,0,0,0,0,0,0,0,0,0,0,0,0,0,0,0,0,0,0,0,0,0,0,0,0,0,0,0
0,0,28,16,16,16,28,16,16,16,28,16,16,16,16,28,16,16,16,16,28,16,16,16,28,16,16,16,28,0,0
0,0,16,0,0,0,0,0,0,0,0,0,0,0,0,0,0,0,0,0,0,0,0,0,0,0,0,0,16,0,0
0,0,16,0,0,0,0,0,0,0,0,0,8,7,7,7,7,7,8,0,0,0,0,0,0,0,0,0,16,0,0
0,0,16,0,0,0,0,0,0,0,0,0,8,40,0,0,40,0,8,0,0,0,0,0,0,0,0,0,16,0,0
0,0,28,0,0,0,7,0,0,0,7,0,8,49,7,7,7,49,8,0,7,0,0,0,7,0,0,0,28,0,0
0,0,16,0,0,0,0,0,0,0,0,0,8,7,40,48,40,7,8,0,0,0,0,0,0,0,0,0,16,0,0
0,0,16,0,0,0,0,0,0,0,0,0,8,6,7,7,7,6,8,0,0,0,0,0,0,0,0,0,16,0,0
0,0,16,0,0,0,0,0,0,0,0,0,7,0,0,0,0,40,7,0,0,0,0,0,0,0,0,0,16,0,0
0,0,28,0,0,0,8,7,7,7,7,7,7,7,7,47,7,7,7,7,7,7,7,7,8,0,0,0,28,0,0
0,0,16,0,0,0,0,7,4,4,4,4,4,4,4,0,4,4,4,4,4,4,4,7,0,0,0,0,16,0,0
0,0,16,0,0,0,0,7,4,4,4,40,46,45,44,0,43,42,41,40,4,4,4,7,0,0,0,0,16,0,0
0,0,16,0,0,0,0,7,4,4,4,39,0,0,0,0,0,0,0,38,4,4,4,7,0,0,0,0,16,0,0
0,0,28,0,0,0,8,7,8,4,4,11,0,0,0,0,0,0,0,11,4,4,8,7,8,0,0,0,28,0,0
0,0,16,0,0,0,0,0,0,7,0,29,0,0,0,0,0,0,0,29,0,7,0,0,0,0,0,0,16,0,0
0,0,16,0,0,0,0,0,0,37,0,0,0,0,0,0,0,0,0,0,0,36,0,0,0,0,0,0,16,0,0
0,0,16,0,0,0,0,0,0,7,0,35,0,0,0,0,0,0,0,35,0,7,0,0,0,0,0,0,16,0,0
0,0,28,0,0,0,8,7,8,7,4,11,0,0,0,0,0,0,0,11,4,7,8,7,8,0,0,0,28,0,0
0,0,16,0,0,0,0,7,4,4,4,32,0,0,0,0,0,0,0,32,4,4,4,7,0,0,0,0,16,0,0
0,0,16,0,0,0,0,7,4,4,4,32,0,0,0,0,0,0,0,32,4,4,4,7,0,0,0,0,16,0,0
0,0,16,0,0,0,0,7,4,4,4,11,34,0,0,11,0,0,33,11,4,4,4,7,0,0,0,0,16,0,0
0,0,28,0,0,0,8,7,4,4,4,32,0,0,0,4,0,0,0,32,4,4,4,7,8,0,0,0,28,0,0
0,0,16,0,0,0,0,7,4,4,4,32,0,0,0,4,0,0,0,32,4,4,4,7,0,0,0,0,16,0,0
0,0,16,0,0,0,0,7,4,4,4,32,0,0,0,4,0,0,0,32,4,4,4,7,0,0,0,0,16,0,0
0,0,16,0,0,0,0,7,4,4,4,11,4,31,4,11,4,30,4,11,4,4,4,7,0,0,0,0,16,0,0
0,0,28,0,0,0,8,7,4,4,4,4,0,0,0,4,0,0,0,4,4,4,4,7,8,0,0,0,28,0,0
0,0,16,0,0,0,0,7,4,4,4,4,13,0,0,4,0,0,13,4,4,4,4,7,0,0,0,0,16,0,0
0,0,16,0,0,0,0,7,4,4,4,4,12,0,0,4,0,0,12,4,4,4,4,7,0,0,0,0,16,0,0
0,0,16,0,0,0,0,7,4,4,4,11,0,0,0,11,0,0,0,11,4,4,4,7,0,0,0,0,16,0,0
0,0,28,0,0,0,8,7,9,10,0,29,0,0,0,0,0,0,0,29,0,9,10,7,8,0,0,0,28,0,0
0,0,16,0,0,0,0,7,0,0,0,0,0,0,0,0,0,0,0,0,0,0,0,7,0,0,0,0,16,0,0
0,0,16,0,0,0,0,7,0,0,0,0,0,0,0,0,0,0,0,0,0,0,0,7,0,0,0,0,16,0,0
0,0,16,0,0,0,0,7,0,0,0,0,0,0,0,11,0,0,0,0,0,0,0,7,0,0,0,0,16,0,0
0,0,28,0,0,0,8,7,0,0,0,11,0,0,0,0,0,0,0,11,0,0,0,7,8,0,0,0,28,0,0
0,0,16,0,0,0,0,7,0,0,10,0,0,0,0,0,0,0,0,0,9,0,0,7,0,0,0,0,16,0,0
0,0,16,0,0,0,0,7,0,0,10,0,0,0,0,0,0,0,0,0,9,0,0,7,0,0,0,0,16,0,0
0,0,16,0,0,0,0,7,7,7,7,7,7,7,7,7,7,8,7,7,7,7,7,7,0,0,0,0,16,0,0
0,0,28,0,0,0,8,7,7,7,7,7,7,28,7,7,7,4,7,7,7,7,7,7,8,0,0,0,28,0,0
0,0,16,0,0,0,0,0,0,0,0,0,0,5,7,7,7,5,0,0,0,0,0,0,0,0,0,0,16,0,0
0,0,16,0,0,0,0,0,0,0,0,0,0,5,7,7,7,5,0,0,0,0,0,0,0,0,0,0,16,0,0
0,0,16,0,0,0,0,0,0,0,0,0,0,16,6,6,6,16,0,0,0,0,0,0,0,0,0,0,16,0,0
0,0,28,16,16,16,28,16,16,16,28,16,16,28,0,0,0,28,16,16,28,16,16,16,28,16,16,16,28,0,0
0,0,0,0,0,0,0,0,0,0,0,0,0,0,0,0,0,0,0,0,0,0,0,0,0,0,0,0,0,0,0
0,0,0,0,0,0,0,0,0,0,0,0,0,0,0,0,0,0,0,0,0,0,0,0,0,0,0,0,0,0,0
:endlayer
layer: 4
0,0,0,0,0,0,0,0,0,0,0,0,0,0,0,0,0,0,0,0,0,0,0,0,0,0,0,0,0,0,0
0,0,0,0,0,0,0,0,0,0,0,0,0,0,0,0,0,0,0,0,0,0,0,0,0,0,0,0,0,0,0
0,0,7,0,0,0,7,0,0,0,7,0,0,0,0,7,0,0,0,0,7,0,0,0,7,0,0,0,7,0,0
0,0,0,0,0,0,0,0,0,0,0,0,0,0,0,0,0,0,0,0,0,0,0,0,0,0,0,0,0,0,0
0,0,0,0,0,0,0,0,0,0,0,0,7,62,0,7,0,61,7,0,0,0,0,0,0,0,0,0,0,0,0
0,0,0,0,0,0,0,0,0,0,0,0,7,0,0,0,0,0,7,0,0,0,0,0,0,0,0,0,0,0,0
0,0,7,0,0,0,7,0,0,0,7,0,49,0,0,0,0,0,49,0,7,0,0,0,7,0,0,0,7,0,0
0,0,0,0,0,0,0,0,0,0,0,0,7,40,16,16,16,40,7,0,0,0,0,0,0,0,0,0,0,0,0
0,0,0,0,0,0,0,0,0,0,0,0,49,0,60,59,58,0,49,0,0,0,0,0,0,0,0,0,0,0,0
0,0,0,0,0,0,0,0,0,0,0,0,8,0,0,0,0,0,8,0,0,0,0,0,0,0,0,0,0,0,0
0,0,7,0,0,0,8,7,7,7,7,7,7,7,7,47,7,7,7,7,7,7,7,7,8,0,0,0,7,0,0
0,0,0,0,0,0,0,7,4,4,4,4,4,4,4,0,4,4,4,4,4,4,4,7,0,0,0,0,0,0,0
0,0,0,0,0,0,0,7,4,4,4,40,0,0,29,0,29,0,0,0,4,4,4,7,0,0,0,0,0,0,0
0,0,0,0,0,0,0,7,4,4,4,0,0,0,0,0,0,0,0,0,4,4,4,7,0,0,0,0,0,0,0
0,0,8,0,0,0,8,7,7,4,4,11,53,0,0,0,0,0,50,11,4,4,7,7,8,0,0,0,8,0,0
0,0,0,0,0,0,0,56,27,7,27,0,0,0,0,0,0,0,0,0,27,7,27,56,0,0,0,0,0,0,0
0,0,0,0,0,0,0,0,33,7,0,0,0,0,0,0,0,0,0,0,0,7,34,0,0,0,0,0,0,0,0
0,0,0,0,0,0,0,56,57,7,57,0,0,0,0,0,0,0,0,0,57,7,57,56,0,0,0,0,0,0,0
0,0,8,0,0,0,8,7,7,7,4,11,53,0,0,0,0,0,50,11,4,7,7,7,8,0,0,0,8,0,0
0,0,0,0,0,0,0,7,4,4,4,0,0,0,0,0,0,0,0,0,4,4,4,7,0,0,0,0,0,0,0
0,0,0,0,0,0,0,7,4,4,4,0,0,0,0,52,0,0,0,0,4,4,4,7,0,0,0,0,0,0,0
0,0,0,0,0,0,0,7,4,4,4,11,53,51,50,11,53,51,50,11,4,4,4,7,0,0,0,0,0,0,0
0,0,8,0,0,0,8,7,4,4,4,0,0,0,0,4,0,0,0,0,4,4,4,7,8,0,0,0,8,0,0
0,0,0,0,0,0,0,7,4,4,4,0,0,0,0,4,0,0,0,0,4,4,4,7,0,0,0,0,0,0,0
0,0,0,0,0,0,0,7,4,4,4,0,0,0,0,4,0,0,0,0,4,4,4,7,0,0,0,0,0,0,0
0,0,0,0,0,0,0,7,4,4,4,11,4,4,4,11,4,4,4,11,4,4,4,7,0,0,0,0,0,0,0
0,0,8,0,0,0,8,7,4,4,4,4,0,0,0,4,0,0,0,4,4,4,4,7,8,0,0,0,8,0,0
0,0,0,0,0,0,0,7,4,4,4,4,54,0,0,4,0,0,54,4,4,4,4,7,0,0,0,0,0,0,0
0,0,0,0,0,0,0,7,4,4,4,4,54,0,0,4,0,0,54,4,4,4,4,7,0,0,0,0,0,0,0
0,0,0,0,0,0,0,7,4,4,4,11,53,51,50,11,53,51,50,11,4,4,4,7,0,0,0,0,0,0,0
0,0,8,0,0,0,8,7,54,54,0,55,0,0,0,0,0,0,0,55,0,54,54,7,8,0,0,0,8,0,0
0,0,0,0,0,0,0,7,0,0,0,51,0,0,0,0,0,0,0,51,0,0,0,7,0,0,0,0,0,0,0
0,0,0,0,0,0,0,7,0,0,0,51,0,0,0,0,0,0,0,51,0,0,0,7,0,0,0,0,0,0,0
0,0,0,0,0,0,0,7,53,51,51,52,51,51,50,11,53,51,51,52,51,51,50,7,0,0,0,0,0,0,0
0,0,8,0,0,0,8,7,0,0,0,11,0,0,0,0,0,0,0,11,0,0,0,7,8,0,0,0,8,0,0
0,0,0,0,0,0,0,7,0,0,0,10,0,0,0,0,0,0,0,9,0,0,0,7,0,0,0,0,0,0,0
0,0,0,0,0,0,0,7,0,0,0,10,0,0,0,0,0,0,0,9,0,0,0,7,0,0,0,0,0,0,0
0,0,0,0,0,0,0,7,7,7,7,7,7,7,7,7,7,7,7,7,7,7,7,7,0,0,0,0,0,0,0
0,0,7,0,0,0,8,7,7,7,7,7,7,28,7,7,7,28,7,7,7,7,7,7,8,0,0,0,7,0,0
0,0,0,0,0,0,0,0,0,0,0,0,0,16,7,7,7,16,0,0,0,0,0,0,0,0,0,0,0,0,0
0,0,0,0,0,0,0,0,0,0,0,0,0,0,6,6,6,0,0,0,0,0,0,0,0,0,0,0,0,0,0
0,0,0,0,0,0,0,0,0,0,0,0,0,0,0,0,0,0,0,0,0,0,0,0,0,0,0,0,0,0,0
0,0,7,0,0,0,7,0,0,0,7,0,0,28,0,0,0,28,0,0,7,0,0,0,7,0,0,0,7,0,0
0,0,0,0,0,0,0,0,0,0,0,0,0,0,0,0,0,0,0,0,0,0,0,0,0,0,0,0,0,0,0
0,0,0,0,0,0,0,0,0,0,0,0,0,0,0,0,0,0,0,0,0,0,0,0,0,0,0,0,0,0,0
:endlayer
layer: 5
0,0,0,0,0,0,0,0,0,0,0,0,0,0,0,0,0,0,0,0,0,0,0,0,0,0,0,0,0,0,0
0,0,0,0,0,0,0,0,0,0,0,0,0,0,0,0,0,0,0,0,0,0,0,0,0,0,0,0,0,0,0
0,0,7,26,0,19,7,26,0,19,7,26,0,0,19,7,26,0,0,19,7,26,0,19,7,26,0,19,7,0,0
0,0,27,0,0,0,27,0,0,0,27,0,0,0,0,0,0,0,0,0,27,0,0,0,27,0,0,0,27,0,0
0,0,0,0,0,0,0,0,0,0,0,33,7,7,26,7,19,7,7,34,0,0,0,0,0,0,0,0,0,0,0
0,0,57,0,0,0,57,0,0,0,57,0,7,0,0,29,0,0,7,0,57,0,0,0,57,0,0,0,57,0,0
0,0,7,26,0,19,7,26,0,19,7,33,7,0,0,0,0,0,7,34,7,26,0,19,7,26,0,19,7,0,0
0,0,27,0,0,0,27,0,0,0,27,0,7,34,0,0,0,33,7,0,27,0,0,0,27,0,0,0,27,0,0
0,0,0,0,0,0,0,0,0,0,0,0,7,0,0,0,0,0,7,0,0,0,0,0,0,0,0,0,0,0,0
0,0,57,0,0,0,57,0,0,0,57,0,7,40,0,0,0,40,7,0,57,0,0,0,57,0,0,0,57,0,0
0,0,7,26,0,19,7,7,7,7,7,7,7,7,7,0,7,7,7,7,7,7,7,7,7,26,0,19,7,0,0
0,0,27,0,0,0,27,7,63,63,63,63,63,63,63,0,63,63,63,63,63,63,63,7,27,0,0,0,27,0,0
0,0,0,0,0,0,33,7,63,63,63,63,63,63,63,63,63,63,63,63,63,63,63,7,34,0,0,0,0,0,0
0,0,57,0,0,0,57,7,63,63,63,63,63,63,63,63,63,63,63,63,63,63,63,7,57,0,0,0,57,0,0
0,0,7,26,0,19,7,7,63,63,63,63,63,63,63,63,63,63,63,63,63,63,63,7,7,26,0,19,7,0,0
0,0,27,0,0,0,27,7,7,8,7,8,63,63,63,63,63,63,63,8,7,8,7,7,27,0,0,0,27,0,0
0,0,0,0,0,0,0,19,7,7,8,8,63,63,63,63,63,63,63,8,8,7,7,26,0,0,0,0,0,0,0
0,0,57,0,0,0,57,7,8,8,8,8,63,63,63,63,63,63,63,8,8,8,8,7,57,0,0,0,57,0,0
0,0,8,26,0,19,8,7,63,63,63,63,63,63,63,63,63,63,63,63,63,63,63,7,8,26,0,19,8,0,0
0,0,27,0,0,0,27,7,63,63,63,63,63,63,63,63,63,63,63,63,63,63,63,7,27,0,0,0,27,0,0
0,0,0,0,0,0,33,7,64,63,63,63,63,63,63,63,63,63,63,63,63,63,64,7,34,0,0,0,0,0,0
0,0,57,0,0,0,57,7,63,63,63,63,63,63,63,63,63,63,63,63,63,63,63,7,57,0,0,0,57,0,0
0,0,8,26,0,19,8,7,63,63,63,63,63,63,63,63,63,63,63,63,63,63,63,7,8,26,0,19,8,0,0
0,0,27,0,0,0,27,7,63,63,63,63,63,63,63,63,63,63,63,63,63,63,63,7,27,0,0,0,27,0,0
0,0,0,0,0,0,33,7,63,63,63,63,63,63,63,63,63,63,63,63,63,63,63,7,34,0,0,0,0,0,0
0,0,57,0,0,0,57,7,63,63,63,63,63,63,63,63,63,63,63,63,63,63,63,7,57,0,0,0,57,0,0
0,0,8,26,0,19,8,7,63,63,63,63,63,63,63,63,63,63,63,63,63,63,63,7,8,26,0,19,8,0,0
0,0,27,0,0,0,27,7,63,63,63,63,63,63,63,63,63,63,63,63,63,63,63,7,27,0,0,0,27,0,0
0,0,0,0,0,0,33,7,63,63,63,63,63,63,63,63,63,63,63,63,63,63,63,7,34,0,0,0,0,0,0
0,0,57,0,0,0,57,7,63,63,63,63,63,63,63,63,63,63,63,63,63,63,63,7,57,0,0,0,57,0,0
0,0,8,26,0,19,8,7,63,63,63,63,63,63,63,63,63,63,63,63,63,63,63,7,8,26,0,19,8,0,0
0,0,27,0,0,0,27,7,63,63,63,63,63,63,63,63,63,63,63,63,63,63,63,7,27,0,0,0,27,0,0
0,0,0,0,0,0,33,7,63,63,63,63,63,63,63,63,63,63,63,63,63,63,63,7,34,0,0,0,0,0,0
0,0,57,0,0,0,57,7,63,63,63,63,63,63,63,63,63,63,63,63,63,63,63,7,57,0,0,0,57,0,0
0,0,7,26,0,19,7,7,63,64,64,11,63,63,63,63,63,63,63,11,64,64,63,7,7,26,0,19,7,0,0
0,0,27,0,0,0,27,7,0,0,0,0,10,63,63,63,63,63,9,0,0,0,0,7,27,0,0,0,27,0,0
0,0,0,0,0,0,33,7,0,0,0,0,10,63,63,63,63,63,9,0,0,0,0,7,34,0,0,0,0,0,0
0,0,57,0,0,0,57,7,7,7,7,7,7,7,7,7,7,7,7,7,7,7,7,7,57,0,0,0,57,0,0
0,0,7,26,0,19,7,7,7,7,7,7,7,28,7,7,7,28,7,7,7,7,7,7,7,26,0,19,7,0,0
0,0,27,0,0,0,27,0,29,0,27,0,29,0,6,6,6,0,29,0,27,0,29,0,27,0,0,0,27,0,0
0,0,0,0,0,0,0,0,0,0,0,0,0,0,0,0,0,0,0,0,0,0,0,0,0,0,0,0,0,0,0
0,0,57,0,0,0,57,0,0,0,57,0,0,35,0,0,0,35,0,0,57,0,0,0,57,0,0,0,57,0,0
0,0,7,26,0,19,7,26,0,19,7,0,0,28,0,0,0,28,0,0,7,26,0,19,7,26,0,19,7,0,0
0,0,0,0,0,0,0,0,0,0,0,0,0,29,0,0,0,29,0,0,0,0,0,0,0,0,0,0,0,0,0
0,0,0,0,0,0,0,0,0,0,0,0,0,0,0,0,0,0,0,0,0,0,0,0,0,0,0,0,0,0,0
:endlayer
layer: 6
0,0,0,0,0,0,0,0,0,0,0,0,0,0,0,0,0,0,0,0,0,0,0,0,0,0,0,0,0,0,0
0,0,35,0,0,0,0,0,0,0,0,0,0,0,0,35,0,0,0,0,0,0,0,0,0,0,0,0,35,0,0
0,33,7,7,7,7,7,7,7,7,7,7,7,7,7,7,7,7,7,7,7,7,7,7,7,7,7,7,7,34,0
0,0,7,0,0,0,7,0,0,0,7,0,0,0,0,0,0,0,0,0,7,0,0,0,7,0,0,0,7,0,0
0,0,7,0,0,0,7,0,0,0,7,0,7,7,7,7,7,7,7,0,7,0,0,0,7,0,0,0,7,0,0
0,0,7,0,0,0,7,0,0,0,7,0,7,26,40,0,40,19,7,0,7,0,0,0,7,0,0,0,7,0,0
0,0,7,7,7,7,7,7,7,7,7,7,7,26,0,0,0,19,7,7,7,7,7,7,7,7,7,7,7,0,0
0,0,7,0,0,0,7,0,0,0,7,0,7,26,0,0,0,19,7,0,7,0,0,0,7,0,0,0,7,0,0
0,0,7,0,0,0,7,0,0,0,7,0,7,26,40,0,40,19,7,0,7,0,0,0,7,0,0,0,7,0,0
0,0,7,0,0,0,7,0,35,0,7,0,7,26,40,0,40,19,7,0,7,0,35,0,7,0,0,0,7,0,0
0,0,7,7,7,8,7,7,7,7,7,7,7,7,7,7,7,7,7,7,7,7,7,7,7,8,7,7,7,0,0
0,0,7,7,8,8,7,7,7,7,7,7,7,7,7,7,7,7,7,7,7,7,7,7,7,8,8,7,7,0,0
0,0,8,8,8,7,7,7,63,63,63,63,63,63,63,63,63,63,63,63,63,63,63,7,7,7,8,8,8,0,0
0,0,7,8,7,7,7,7,63,63,63,63,63,63,63,63,63,63,63,63,63,63,63,7,7,7,7,8,7,0,0
0,0,7,7,7,7,7,7,63,63,63,63,63,63,63,68,63,63,63,63,63,63,63,7,7,7,7,7,7,0,0
0,0,7,7,7,7,7,7,63,63,63,63,63,63,68,68,68,63,63,63,63,63,63,7,7,7,7,7,7,0,0
0,0,7,7,7,7,7,7,63,63,63,67,67,67,68,68,68,67,67,67,63,63,63,7,7,7,7,7,7,0,0
0,0,7,7,7,7,7,7,63,63,63,67,67,67,68,68,68,67,67,67,63,63,63,7,7,7,7,7,7,0,0
0,0,7,7,7,7,7,7,63,63,63,67,67,67,68,68,68,67,67,67,63,63,63,7,7,7,7,7,7,0,0
0,0,7,7,7,7,7,7,63,63,63,63,63,63,68,68,68,63,63,63,63,63,63,7,7,7,7,7,7,0,0
0,0,7,7,7,7,7,7,63,63,63,63,63,63,68,68,68,63,63,63,63,63,63,7,7,7,7,7,7,0,0
0,0,7,7,7,7,7,7,63,63,63,63,63,63,68,68,68,63,63,63,63,63,63,7,7,7,7,7,7,0,0
0,33,7,7,7,7,7,7,63,63,63,63,63,63,68,68,68,63,63,63,63,63,63,7,7,7,7,7,7,0,0
0,0,7,7,7,7,7,7,63,63,63,63,63,63,68,68,68,63,63,63,63,63,63,7,7,7,7,7,7,34,0
0,0,7,7,7,7,7,7,63,63,69,69,69,63,68,68,68,63,69,69,69,63,63,7,7,7,7,7,7,0,0
0,0,7,7,7,7,7,7,63,63,63,63,63,63,68,68,68,63,63,63,63,63,63,7,7,7,7,7,7,0,0
0,33,7,7,7,7,7,7,63,63,63,63,63,63,68,68,68,63,63,63,63,63,63,7,7,7,7,7,7,34,0
0,0,7,7,7,7,7,7,63,63,63,63,63,63,68,68,68,63,63,63,63,63,63,7,7,7,7,7,7,0,0
0,0,7,7,7,7,7,7,63,63,63,63,63,63,68,68,68,63,63,63,63,63,63,7,7,7,7,7,7,0,0
0,0,7,7,7,7,7,7,63,63,63,63,63,63,68,68,68,63,63,63,63,63,63,7,7,7,7,7,7,0,0
0,0,7,7,7,7,7,7,63,63,63,67,67,67,68,68,68,67,67,67,63,63,63,7,7,7,7,7,7,0,0
0,0,7,7,7,7,7,7,63,63,63,67,67,67,68,68,68,67,67,67,63,63,63,7,7,7,7,7,7,0,0
0,0,7,7,7,7,7,7,63,63,63,67,67,67,68,68,68,67,67,67,63,63,63,7,7,7,7,7,7,0,0
0,0,7,7,7,7,7,7,63,63,63,63,63,63,63,63,63,63,63,63,63,63,63,7,7,7,7,7,7,0,0
0,0,7,7,7,7,7,7,66,66,66,11,63,63,63,63,63,63,63,11,66,66,66,7,7,7,7,7,7,0,0
0,0,7,8,7,7,7,7,0,0,0,0,0,10,63,63,63,9,0,0,0,0,0,7,7,7,7,8,7,0,0
0,0,8,8,8,7,7,7,0,0,0,0,0,10,63,63,63,9,0,0,0,0,0,7,7,7,8,8,8,0,0
0,0,7,7,8,8,7,7,7,7,7,7,7,7,7,7,7,7,7,7,7,7,7,7,7,8,8,7,7,0,0
0,0,7,7,7,8,7,7,7,7,7,7,7,28,6,6,6,28,7,7,7,7,7,7,7,8,7,7,7,0,0
0,0,7,0,0,0,7,0,0,0,7,0,0,0,0,0,0,0,0,0,7,0,0,0,7,0,0,0,7,0,0
0,0,7,0,0,0,7,0,0,0,7,0,0,0,0,0,0,0,0,0,7,0,0,0,7,0,0,0,7,0,0
0,0,7,0,0,0,7,0,0,0,7,0,0,0,0,0,0,0,0,0,7,0,0,0,7,0,0,0,7,0,0
0,33,7,7,7,7,7,7,7,7,7,34,0,65,0,0,0,65,0,33,7,7,7,7,7,7,7,7,7,34,0
0,0,29,0,0,0,0,0,0,0,29,0,0,0,0,0,0,0,0,0,29,0,0,0,0,0,0,0,29,0,0
0,0,0,0,0,0,0,0,0,0,0,0,0,0,0,0,0,0,0,0,0,0,0,0,0,0,0,0,0,0,0
:endlayer
layer: 7
0,0,0,0,0,0,0,0,0,0,0,0,0,0,0,0,0,0,0,0,0,0,0,0,0,0,0,0,0,0,0
0,0,0,0,0,0,0,0,0,0,0,0,0,0,0,0,0,0,0,0,0,0,0,0,0,0,0,0,0,0,0
0,0,5,16,16,16,5,16,16,16,5,16,16,16,16,5,16,16,16,16,5,16,16,16,5,16,16,16,5,0,0
0,0,16,70,70,70,16,70,70,70,16,70,70,70,70,70,70,70,70,70,16,70,70,70,16,70,70,70,16,0,0
0,0,16,70,70,70,16,70,70,70,16,70,10,63,63,63,63,63,9,70,16,70,70,70,16,70,70,70,16,0,0
0,0,16,70,70,70,16,70,70,70,16,70,10,63,26,40,19,63,9,70,16,70,70,70,16,70,70,70,16,0,0
0,0,5,16,16,16,5,16,16,16,5,16,10,63,26,40,19,63,9,16,5,16,16,16,5,16,16,16,5,0,0
0,0,16,70,70,70,16,70,70,70,16,70,10,63,26,0,19,63,9,70,16,70,70,70,16,70,70,70,16,0,0
0,0,16,70,70,70,16,70,70,70,16,70,10,63,26,40,19,63,9,70,16,70,70,70,16,70,70,70,16,0,0
0,0,16,70,70,70,16,70,70,70,16,70,10,63,26,40,19,63,9,70,16,70,70,70,16,70,70,70,16,0,0
0,0,5,16,16,16,5,16,16,16,5,16,10,63,7,7,7,63,9,16,5,16,16,16,5,16,16,16,5,0,0
0,0,16,62,49,49,49,11,7,7,7,7,7,7,7,7,7,7,7,7,7,7,7,11,49,49,49,61,16,0,0
0,0,16,62,0,0,0,7,54,64,0,0,83,82,66,0,66,81,80,0,0,64,54,7,0,0,0,61,16,0,0
0,0,16,62,0,0,0,7,54,79,78,0,0,0,77,0,76,0,0,0,75,74,54,7,0,0,0,61,16,0,0
0,0,5,62,0,0,0,7,66,66,66,11,66,66,11,0,11,66,66,11,66,66,66,7,0,0,0,61,5,0,0
0,0,16,62,0,0,0,7,7,0,0,0,0,0,0,0,0,0,0,0,0,0,7,7,0,0,0,61,16,0,0
0,0,16,62,0,0,0,7,7,13,0,0,0,73,66,66,66,72,0,0,0,13,7,7,0,0,0,61,16,0,0
0,0,16,62,0,0,0,7,7,54,0,0,0,73,66,66,66,72,0,0,0,54,7,7,0,0,0,61,16,0,0
0,0,5,62,0,0,0,7,7,12,0,0,0,73,66,66,66,72,0,0,0,12,7,7,0,0,0,61,5,0,0
0,0,16,62,0,0,0,7,7,0,0,0,0,0,0,0,0,0,0,0,0,0,7,7,0,0,0,61,16,0,0
0,0,16,62,0,0,0,7,7,0,0,9,0,9,0,0,0,10,0,10,0,0,7,7,0,0,0,61,16,0,0
0,0,16,62,0,0,11,7,11,0,11,9,0,9,0,0,0,10,0,10,11,0,11,7,11,0,0,61,16,0,0
0,0,5,62,0,0,0,7,7,0,0,9,0,9,0,0,0,10,0,10,0,0,7,7,0,0,0,61,5,0,0
0,0,16,62,0,0,71,0,7,0,0,9,0,9,0,0,0,10,0,10,0,0,7,0,71,0,0,61,16,0,0
0,0,16,62,0,0,0,0,17,0,0,0,0,0,0,0,0,0,0,0,0,0,18,0,0,0,0,61,16,0,0
0,0,16,62,0,0,71,0,7,0,0,9,0,9,0,0,0,10,0,10,0,0,7,0,71,0,0,61,16,0,0
0,0,5,62,0,0,0,7,7,0,0,9,0,9,0,0,0,10,0,10,0,0,7,7,0,0,0,61,5,0,0
0,0,16,62,0,0,11,7,11,0,11,9,0,9,0,0,0,10,0,10,11,0,11,7,11,0,0,61,16,0,0
0,0,16,62,0,0,0,7,7,0,0,9,0,9,0,0,0,10,0,10,0,0,7,7,0,0,0,61,16,0,0
0,0,16,62,0,0,0,7,7,0,0,9,0,9,0,0,0,10,0,10,0,0,7,7,0,0,0,61,16,0,0
0,0,5,62,0,0,0,7,7,13,0,0,0,0,0,0,0,0,0,0,0,13,7,7,0,0,0,61,5,0,0
0,0,16,62,0,0,0,7,7,54,0,0,0,0,0,0,0,0,0,0,0,54,7,7,0,0,0,61,16,0,0
0,0,16,62,0,0,0,7,7,12,0,0,0,0,0,0,0,0,0,0,0,12,7,7,0,0,0,61,16,0,0
0,0,16,62,0,0,0,7,7,0,0,0,0,0,0,0,0,0,0,0,0,0,7,7,0,0,0,61,16,0,0
0,0,5,62,0,0,0,7,66,66,66,11,71,11,0,0,0,11,71,11,66,66,66,7,0,0,0,61,5,0,0
0,0,16,62,0,0,0,7,0,0,0,0,0,0,0,0,0,0,0,0,0,0,0,7,0,0,0,61,16,0,0
0,0,16,62,0,0,0,7,0,0,0,0,0,0,0,0,0,0,0,0,0,0,0,7,0,0,0,61,16,0,0
0,0,16,6,6,6,6,11,7,7,7,7,7,28,0,0,0,28,7,7,7,7,7,11,6,6,6,6,16,0,0
0,0,5,16,16,16,5,16,16,16,5,16,16,28,0,0,0,28,16,16,5,16,16,16,5,16,16,16,5,0,0
0,0,16,70,70,70,16,70,70,70,16,0,0,0,0,0,0,0,0,0,16,70,70,70,16,70,70,70,16,0,0
0,0,16,70,70,70,16,70,70,70,16,0,0,0,0,0,0,0,0,0,16,70,70,70,16,70,70,70,16,0,0
0,0,16,70,70,70,16,70,70,70,16,0,0,0,0,0,0,0,0,0,16,70,70,70,16,70,70,70,16,0,0
0,0,5,16,16,16,5,16,16,16,5,0,0,0,0,0,0,0,0,0,5,16,16,16,5,16,16,16,5,0,0
0,0,0,0,0,0,0,0,0,0,0,0,0,0,0,0,0,0,0,0,0,0,0,0,0,0,0,0,0,0,0
0,0,0,0,0,0,0,0,0,0,0,0,0,0,0,0,0,0,0,0,0,0,0,0,0,0,0,0,0,0,0
:endlayer
layer: 8
0,0,0,0,0,0,0,0,0,0,0,0,0,0,0,0,0,0,0,0,0,0,0,0,0,0,0,0,0,0,0
0,0,0,0,0,0,0,0,0,0,0,0,0,0,0,0,0,0,0,0,0,0,0,0,0,0,0,0,0,0,0
0,0,0,0,0,0,0,0,0,0,0,0,0,0,0,0,0,0,0,0,0,0,0,0,0,0,0,0,0,0,0
0,0,0,0,0,0,0,0,0,0,0,0,0,0,0,0,0,0,0,0,0,0,0,0,0,0,0,0,0,0,0
0,0,0,0,0,0,0,0,0,0,0,0,0,10,63,63,63,9,0,0,0,0,0,0,0,0,0,0,0,0,0
0,0,0,0,0,0,0,0,0,0,0,0,0,10,63,8,63,9,0,0,0,0,0,0,0,0,0,0,0,0,0
0,0,0,0,0,0,0,0,0,0,0,0,0,10,63,8,63,9,0,0,0,0,0,0,0,0,0,0,0,0,0
0,0,0,0,0,0,0,0,0,0,0,0,0,10,63,7,63,9,0,0,0,0,0,0,0,0,0,0,0,0,0
0,0,0,0,0,0,0,0,0,0,0,0,0,10,63,7,63,9,0,0,0,0,0,0,0,0,0,0,0,0,0
0,0,0,0,0,0,0,0,0,0,0,0,0,10,63,7,63,9,0,0,0,0,0,0,0,0,0,0,0,0,0
0,0,0,0,0,0,0,35,0,0,0,0,0,10,63,7,63,9,0,0,0,0,0,35,0,0,0,0,0,0,0
0,0,0,0,0,0,33,11,7,7,7,7,7,7,7,7,7,7,7,7,7,7,7,11,34,0,0,0,0,0,0
0,0,0,0,0,0,0,7,87,65,0,0,0,0,66,0,66,0,0,0,0,65,87,7,0,0,0,0,0,0,0
0,0,0,0,0,0,0,7,87,0,0,0,0,0,88,0,88,0,0,0,0,0,87,7,0,0,0,0,0,0,0
0,0,0,0,0,0,0,7,66,66,66,11,66,66,11,0,11,66,66,11,66,66,66,7,0,0,0,0,0,0,0
0,0,0,0,0,0,0,7,7,0,0,0,0,0,0,0,0,0,0,0,0,0,7,7,0,0,0,0,0,0,0
0,0,0,0,0,0,0,7,7,54,0,0,0,0,71,0,71,0,0,0,0,54,7,7,0,0,0,0,0,0,0
0,0,0,0,0,0,0,7,7,54,0,0,0,0,0,86,0,0,0,0,0,54,7,7,0,0,0,0,0,0,0
0,0,0,0,0,0,0,7,7,54,0,0,0,0,71,0,71,0,0,0,0,54,7,7,0,0,0,0,0,0,0
0,0,0,0,0,0,0,7,7,0,0,0,0,0,0,0,0,0,0,0,0,0,7,7,0,0,0,0,0,0,0
0,0,0,0,0,0,0,7,7,0,0,0,0,0,0,0,0,0,0,0,0,0,7,7,0,0,0,0,0,0,0
0,0,0,0,0,33,11,7,11,0,11,0,0,0,0,0,0,0,0,0,11,0,11,7,11,34,0,0,0,0,0
0,0,0,0,0,0,0,7,7,0,0,0,0,0,0,0,0,0,0,0,0,0,7,7,0,0,0,0,0,0,0
0,0,0,0,0,0,71,0,7,0,0,0,0,0,0,0,0,0,0,0,0,0,7,0,71,0,0,0,0,0,0
0,0,0,0,0,0,0,0,85,0,0,0,0,0,0,0,0,0,0,0,0,0,84,0,0,0,0,0,0,0,0
0,0,0,0,0,0,71,0,7,0,0,0,0,0,0,0,0,0,0,0,0,0,7,0,71,0,0,0,0,0,0
0,0,0,0,0,0,0,7,7,0,0,0,0,0,0,0,0,0,0,0,0,0,7,7,0,0,0,0,0,0,0
0,0,0,0,0,33,11,7,11,0,11,0,0,0,0,0,0,0,0,0,11,0,11,7,11,34,0,0,0,0,0
0,0,0,0,0,0,0,7,7,0,0,0,0,0,0,0,0,0,0,0,0,0,7,7,0,0,0,0,0,0,0
0,0,0,0,0,0,0,7,7,0,0,0,0,0,0,0,0,0,0,0,0,0,7,7,0,0,0,0,0,0,0
0,0,0,0,0,0,0,7,7,54,0,0,0,0,0,0,0,0,0,0,0,54,7,7,0,0,0,0,0,0,0
0,0,0,0,0,0,0,7,7,54,0,0,0,0,0,0,0,0,0,0,0,54,7,7,0,0,0,0,0,0,0
0,0,0,0,0,0,0,7,7,54,0,0,0,0,0,0,0,0,0,0,0,54,7,7,0,0,0,0,0,0,0
0,0,0,0,0,0,0,7,7,0,0,0,0,0,0,0,0,0,0,0,0,0,7,7,0,0,0,0,0,0,0
0,0,0,0,0,0,0,7,66,66,66,11,0,11,0,0,0,11,0,11,66,66,66,7,0,0,0,0,0,0,0
0,0,0,0,0,0,0,7,0,0,0,0,0,0,0,0,0,0,0,0,0,0,0,7,0,0,0,0,0,0,0
0,0,0,0,0,0,0,7,0,0,0,0,0,0,0,0,0,0,0,0,0,0,0,7,0,0,0,0,0,0,0
0,0,0,0,0,0,33,11,7,7,7,7,7,28,0,0,0,28,7,7,7,7,7,11,34,0,0,0,0,0,0
0,0,0,0,0,0,0,29,0,0,0,0,0,28,0,0,0,28,0,0,0,0,0,29,0,0,0,0,0,0,0
0,0,0,0,0,0,0,0,0,0,0,0,0,29,0,0,0,29,0,0,0,0,0,0,0,0,0,0,0,0,0
0,0,0,0,0,0,0,0,0,0,0,0,0,0,0,0,0,0,0,0,0,0,0,0,0,0,0,0,0,0,0
0,0,0,0,0,0,0,0,0,0,0,0,0,0,0,0,0,0,0,0,0,0,0,0,0,0,0,0,0,0,0
0,0,0,0,0,0,0,0,0,0,0,0,0,0,0,0,0,0,0,0,0,0,0,0,0,0,0,0,0,0,0
0,0,0,0,0,0,0,0,0,0,0,0,0,0,0,0,0,0,0,0,0,0,0,0,0,0,0,0,0,0,0
0,0,0,0,0,0,0,0,0,0,0,0,0,0,0,0,0,0,0,0,0,0,0,0,0,0,0,0,0,0,0
:endlayer
layer: 9
0,0,0,0,0,0,0,0,0,0,0,0,0,0,0,0,0,0,0,0,0,0,0,0,0,0,0,0,0,0,0
0,0,0,0,0,0,0,0,0,0,0,0,0,0,0,0,0,0,0,0,0,0,0,0,0,0,0,0,0,0,0
0,0,0,0,0,0,0,0,0,0,0,0,0,0,0,0,0,0,0,0,0,0,0,0,0,0,0,0,0,0,0
0,0,0,0,0,0,0,0,0,0,0,0,0,0,0,0,0,0,0,0,0,0,0,0,0,0,0,0,0,0,0
0,0,0,0,0,0,0,0,0,0,0,0,0,0,10,64,9,0,0,0,0,0,0,0,0,0,0,0,0,0,0
0,0,0,0,0,0,0,0,0,0,0,0,0,0,10,64,9,0,0,0,0,0,0,0,0,0,0,0,0,0,0
0,0,0,0,0,0,0,0,0,0,0,0,0,0,10,64,9,0,0,0,0,0,0,0,0,0,0,0,0,0,0
0,0,0,0,0,0,0,0,0,0,0,0,0,0,10,64,9,0,0,0,0,0,0,0,0,0,0,0,0,0,0
0,0,0,0,0,0,0,0,0,0,0,0,0,0,10,64,9,0,0,0,0,0,0,0,0,0,0,0,0,0,0
0,0,0,0,0,0,0,0,0,0,0,0,0,0,10,64,9,0,0,0,0,0,0,0,0,0,0,0,0,0,0
0,0,0,0,0,0,51,51,51,51,51,51,51,51,63,51,63,51,51,51,51,51,51,51,51,0,0,0,0,0,0
0,0,0,0,0,0,51,11,7,7,7,7,7,7,7,7,7,7,7,7,7,7,7,11,51,0,0,0,0,0,0
0,0,0,0,0,0,51,7,54,0,0,0,0,0,66,0,66,0,0,0,0,0,54,7,51,0,0,0,0,0,0
0,0,0,0,0,0,51,7,54,0,0,0,0,0,66,0,66,0,0,0,0,0,54,7,51,0,0,0,0,0,0
0,0,0,0,0,0,51,7,66,66,66,11,66,66,11,0,11,66,66,11,66,66,66,7,51,0,0,0,0,0,0
0,0,0,0,0,0,51,7,7,0,0,0,0,0,0,0,0,0,0,0,0,0,7,7,51,0,0,0,0,0,0
0,0,0,0,0,0,51,7,7,0,0,0,0,0,65,0,65,0,0,0,0,0,7,7,51,0,0,0,0,0,0
0,0,0,0,0,0,51,7,7,0,0,0,0,0,0,0,0,0,0,0,0,0,7,7,51,0,0,0,0,0,0
0,0,0,0,0,0,51,7,7,0,0,0,0,0,65,0,65,0,0,0,0,0,7,7,51,0,0,0,0,0,0
0,0,0,0,0,0,51,7,7,0,0,0,0,0,0,0,0,0,0,0,0,0,7,7,51,0,0,0,0,0,0
0,0,0,0,0,51,51,7,7,0,0,0,0,0,0,0,0,0,0,0,0,0,7,7,51,51,0,0,0,0,0
0,0,0,0,0,0,11,7,11,0,11,34,0,0,0,0,0,0,0,33,11,0,11,7,11,0,0,0,0,0,0
0,0,0,0,0,0,52,7,7,0,0,0,0,0,0,0,0,0,0,0,0,0,7,7,52,0,0,0,0,0,0
0,0,0,0,0,0,63,0,7,0,0,0,0,0,0,0,0,0,0,0,0,0,7,0,63,0,0,0,0,0,0
0,0,0,0,0,0,51,0,7,0,0,0,0,0,0,0,0,0,0,0,0,0,7,0,51,0,0,0,0,0,0
0,0,0,0,0,0,63,0,7,0,0,0,0,0,0,0,0,0,0,0,0,0,7,0,63,0,0,0,0,0,0
0,0,0,0,0,0,55,7,7,0,0,0,0,0,0,0,0,0,0,0,0,0,7,7,55,0,0,0,0,0,0
0,0,0,0,0,0,11,7,11,0,11,34,0,0,0,0,0,0,0,33,11,0,11,7,11,0,0,0,0,0,0
0,0,0,0,0,51,51,7,7,0,0,0,0,0,0,0,0,0,0,0,0,0,7,7,51,51,0,0,0,0,0
0,0,0,0,0,0,51,7,7,0,0,0,0,0,0,0,0,0,0,0,0,0,7,7,51,0,0,0,0,0,0
0,0,0,0,0,0,51,7,7,0,0,0,0,0,0,0,0,0,0,0,0,0,7,7,51,0,0,0,0,0,0
0,0,0,0,0,0,51,7,7,0,0,0,0,0,0,0,0,0,0,0,0,0,7,7,51,0,0,0,0,0,0
0,0,0,0,0,0,51,7,7,0,0,0,0,0,0,0,0,0,0,0,0,0,7,7,51,0,0,0,0,0,0
0,0,0,0,0,0,51,7,7,0,0,0,0,35,0,0,0,35,0,0,0,0,7,7,51,0,0,0,0,0,0
0,0,0,0,0,0,51,7,66,66,66,11,0,11,0,0,0,11,0,11,66,66,66,7,51,0,0,0,0,0,0
0,0,0,0,0,0,51,7,0,0,0,0,0,0,0,0,0,0,0,0,0,0,0,7,51,0,0,0,0,0,0
0,0,0,0,0,0,51,7,0,0,0,0,0,35,0,0,0,35,0,0,0,0,0,7,51,0,0,0,0,0,0
0,0,0,0,0,0,51,11,7,7,7,7,7,28,0,0,0,28,7,7,7,7,7,11,51,0,0,0,0,0,0
0,0,0,0,0,0,51,51,51,51,51,51,51,28,0,0,0,28,51,51,51,51,51,51,51,0,0,0,0,0,0
0,0,0,0,0,0,0,0,0,0,0,0,0,0,0,0,0,0,0,0,0,0,0,0,0,0,0,0,0,0,0
0,0,0,0,0,0,0,0,0,0,0,0,0,0,0,0,0,0,0,0,0,0,0,0,0,0,0,0,0,0,0
0,0,0,0,0,0,0,0,0,0,0,0,0,0,0,0,0,0,0,0,0,0,0,0,0,0,0,0,0,0,0
0,0,0,0,0,0,0,0,0,0,0,0,0,0,0,0,0,0,0,0,0,0,0,0,0,0,0,0,0,0,0
0,0,0,0,0,0,0,0,0,0,0,0,0,0,0,0,0,0,0,0,0,0,0,0,0,0,0,0,0,0,0
0,0,0,0,0,0,0,0,0,0,0,0,0,0,0,0,0,0,0,0,0,0,0,0,0,0,0,0,0,0,0
:endlayer
layer: 10
0,0,0,0,0,0,0,0,0,0,0,0,0,0,0,0,0,0,0,0,0,0,0,0,0,0,0,0,0,0,0
0,0,0,0,0,0,0,0,0,0,0,0,0,0,0,0,0,0,0,0,0,0,0,0,0,0,0,0,0,0,0
0,0,0,0,0,0,0,0,0,0,0,0,0,0,0,0,0,0,0,0,0,0,0,0,0,0,0,0,0,0,0
0,0,0,0,0,0,0,0,0,0,0,0,0,0,0,0,0,0,0,0,0,0,0,0,0,0,0,0,0,0,0
0,0,0,0,0,0,0,0,0,0,0,0,0,0,0,54,0,0,0,0,0,0,0,0,0,0,0,0,0,0,0
0,0,0,0,0,0,0,0,0,0,0,0,0,0,0,54,0,0,0,0,0,0,0,0,0,0,0,0,0,0,0
0,0,0,0,0,0,0,0,0,0,0,0,0,0,0,54,0,0,0,0,0,0,0,0,0,0,0,0,0,0,0
0,0,0,0,0,0,0,0,0,0,0,0,0,0,0,54,0,0,0,0,0,0,0,0,0,0,0,0,0,0,0
0,0,0,0,0,0,0,0,0,0,0,0,0,0,0,54,0,0,0,0,0,0,0,0,0,0,0,0,0,0,0
0,0,0,0,0,0,0,0,0,0,0,0,0,0,0,54,0,0,0,0,0,0,0,0,0,0,0,0,0,0,0
0,0,0,0,0,0,11,11,11,11,11,11,11,11,11,11,11,11,11,11,11,11,11,11,11,0,0,0,0,0,0
0,0,0,0,0,0,11,7,7,7,7,7,7,7,7,7,7,7,7,7,7,7,7,7,11,0,0,0,0,0,0
0,0,0,0,0,0,11,7,0,0,0,0,0,0,66,0,66,0,0,0,0,0,0,7,11,0,0,0,0,0,0
0,0,0,0,0,0,11,7,0,0,0,0,0,0,66,0,66,0,0,0,0,0,0,7,11,0,0,0,0,0,0
0,0,0,0,0,0,11,7,66,66,66,11,66,66,11,0,11,66,66,11,66,66,66,7,11,0,0,0,0,0,0
0,0,0,0,0,0,11,7,7,0,0,0,0,0,29,0,29,0,0,0,0,0,7,7,11,0,0,0,0,0,0
0,0,0,0,0,0,11,7,7,0,0,0,0,0,0,0,0,0,0,0,0,0,7,7,11,0,0,0,0,0,0
0,0,0,0,0,0,11,7,7,0,0,0,0,0,0,0,0,0,0,0,0,0,7,7,11,0,0,0,0,0,0
0,0,0,0,0,0,11,7,7,0,0,0,0,0,0,0,0,0,0,0,0,0,7,7,11,0,0,0,0,0,0
0,0,0,0,0,0,11,7,7,0,0,0,0,0,0,0,0,0,0,0,0,0,7,7,11,0,0,0,0,0,0
0,0,0,0,0,11,64,7,7,0,0,0,0,0,0,0,0,0,0,0,0,0,7,7,64,11,0,0,0,0,0
0,0,0,0,0,51,11,7,11,0,11,0,0,0,0,0,0,0,0,0,11,0,11,7,11,51,0,0,0,0,0
0,0,0,0,0,0,63,7,7,0,0,0,0,0,0,0,0,0,0,0,0,0,7,7,63,0,0,0,0,0,0
0,0,0,0,0,0,13,0,7,0,0,0,0,0,0,0,0,0,0,0,0,0,7,0,13,0,0,0,0,0,0
0,0,0,0,0,0,0,0,7,0,0,0,0,0,0,0,0,0,0,0,0,0,7,0,0,0,0,0,0,0,0
0,0,0,0,0,0,12,0,7,0,0,0,0,0,0,0,0,0,0,0,0,0,7,0,12,0,0,0,0,0,0
0,0,0,0,0,0,63,7,7,0,0,0,0,0,0,0,0,0,0,0,0,0,7,7,63,0,0,0,0,0,0
0,0,0,0,0,51,11,7,11,0,11,0,0,0,0,0,0,0,0,0,11,0,11,7,11,51,0,0,0,0,0
0,0,0,0,0,11,64,7,7,0,0,0,0,0,0,0,0,0,0,0,0,0,7,7,64,11,0,0,0,0,0
0,0,0,0,0,0,11,7,7,0,0,0,0,0,0,0,0,0,0,0,0,0,7,7,11,0,0,0,0,0,0
0,0,0,0,0,0,11,7,7,0,0,0,0,0,0,0,0,0,0,0,0,0,7,7,11,0,0,0,0,0,0
0,0,0,0,0,0,11,7,7,0,0,0,0,0,0,0,0,0,0,0,0,0,7,7,11,0,0,0,0,0,0
0,0,0,0,0,0,11,7,7,0,0,0,0,0,0,0,0,0,0,0,0,0,7,7,11,0,0,0,0,0,0
0,0,0,0,0,0,11,7,7,0,0,0,0,0,0,0,0,0,0,0,0,0,7,7,11,0,0,0,0,0,0
0,0,0,0,0,0,11,7,66,66,66,11,0,11,0,0,0,11,0,11,66,66,66,7,11,0,0,0,0,0,0
0,0,0,0,0,0,11,7,0,0,0,0,0,0,0,0,0,0,0,0,0,0,0,7,11,0,0,0,0,0,0
0,0,0,0,0,0,11,7,0,0,0,0,0,0,0,35,0,0,0,0,0,0,0,7,11,0,0,0,0,0,0
0,0,0,0,0,0,11,7,7,7,7,7,7,28,28,28,28,28,7,7,7,7,7,7,11,0,0,0,0,0,0
0,0,0,0,0,0,11,11,11,11,11,11,11,11,55,55,55,11,11,11,11,11,11,11,11,0,0,0,0,0,0
0,0,0,0,0,0,0,0,0,0,0,0,0,0,0,0,0,0,0,0,0,0,0,0,0,0,0,0,0,0,0
0,0,0,0,0,0,0,0,0,0,0,0,0,0,0,0,0,0,0,0,0,0,0,0,0,0,0,0,0,0,0
0,0,0,0,0,0,0,0,0,0,0,0,0,0,0,0,0,0,0,0,0,0,0,0,0,0,0,0,0,0,0
0,0,0,0,0,0,0,0,0,0,0,0,0,0,0,0,0,0,0,0,0,0,0,0,0,0,0,0,0,0,0
0,0,0,0,0,0,0,0,0,0,0,0,0,0,0,0,0,0,0,0,0,0,0,0,0,0,0,0,0,0,0
0,0,0,0,0,0,0,0,0,0,0,0,0,0,0,0,0,0,0,0,0,0,0,0,0,0,0,0,0,0,0
:endlayer
layer: 11
0,0,0,0,0,0,0,0,0,0,0,0,0,0,0,0,0,0,0,0,0,0,0,0,0,0,0,0,0,0,0
0,0,0,0,0,0,0,0,0,0,0,0,0,0,0,0,0,0,0,0,0,0,0,0,0,0,0,0,0,0,0
0,0,0,0,0,0,0,0,0,0,0,0,0,0,0,0,0,0,0,0,0,0,0,0,0,0,0,0,0,0,0
0,0,0,0,0,0,0,0,0,0,0,0,0,0,0,0,0,0,0,0,0,0,0,0,0,0,0,0,0,0,0
0,0,0,0,0,0,0,0,0,0,0,0,0,0,0,0,0,0,0,0,0,0,0,0,0,0,0,0,0,0,0
0,0,0,0,0,0,0,0,0,0,0,0,0,0,0,0,0,0,0,0,0,0,0,0,0,0,0,0,0,0,0
0,0,0,0,0,0,0,0,0,0,0,0,0,0,0,0,0,0,0,0,0,0,0,0,0,0,0,0,0,0,0
0,0,0,0,0,0,0,0,0,0,0,0,0,0,0,0,0,0,0,0,0,0,0,0,0,0,0,0,0,0,0
0,0,0,0,0,0,0,0,0,0,0,0,0,0,0,0,0,0,0,0,0,0,0,0,0,0,0,0,0,0,0
0,0,0,0,0,0,0,0,0,0,0,0,0,0,0,0,0,0,0,0,0,0,0,0,0,0,0,0,0,0,0
0,0,0,0,0,0,54,12,12,12,12,12,12,12,12,12,12,12,12,12,12,12,12,12,54,0,0,0,0,0,0
0,0,0,0,0,0,10,11,63,63,63,63,63,63,63,63,63,63,63,63,63,63,63,11,9,0,0,0,0,0,0
0,0,0,0,0,0,10,63,63,55,55,55,55,55,55,55,55,55,55,55,55,55,63,63,9,0,0,0,0,0,0
0,0,0,0,0,0,10,63,53,0,0,0,0,0,66,0,66,0,0,0,0,0,50,63,9,0,0,0,0,0,0
0,0,0,0,0,0,10,63,63,66,66,11,66,66,11,0,11,66,66,11,66,66,63,63,9,0,0,0,0,0,0
0,0,0,0,0,0,10,63,7,0,0,0,0,0,0,0,0,0,0,0,0,0,7,63,9,0,0,0,0,0,0
0,0,0,0,0,0,10,63,7,0,0,0,0,0,0,0,0,0,0,0,0,0,7,63,9,0,0,0,0,0,0
0,0,0,0,0,0,10,63,7,0,0,0,0,0,0,0,0,0,0,0,0,0,7,63,9,0,0,0,0,0,0
0,0,0,0,0,0,10,63,7,0,0,0,0,0,0,0,0,0,0,0,0,0,7,63,9,0,0,0,0,0,0
0,0,0,0,0,0,10,63,7,0,0,0,0,0,0,0,0,0,0,0,0,0,7,63,9,0,0,0,0,0,0
0,0,0,0,0,12,63,63,7,0,0,0,0,0,0,0,0,0,0,0,0,0,7,63,63,12,0,0,0,0,0
0,0,0,0,0,11,11,11,11,0,11,0,0,0,0,0,0,0,0,0,11,0,11,11,11,11,0,0,0,0,0
0,0,0,0,0,51,63,7,7,0,0,0,0,0,0,0,0,0,0,0,0,0,7,7,63,51,0,0,0,0,0
0,0,0,0,0,0,55,0,7,0,0,0,0,0,0,0,0,0,0,0,0,0,7,0,55,0,0,0,0,0,0
0,0,0,0,0,0,0,0,7,0,0,0,0,0,0,0,0,0,0,0,0,0,7,0,0,0,0,0,0,0,0
0,0,0,0,0,0,52,0,7,0,0,0,0,0,0,0,0,0,0,0,0,0,7,0,52,0,0,0,0,0,0
0,0,0,0,0,51,13,7,7,0,0,0,0,0,0,0,0,0,0,0,0,0,7,7,13,51,0,0,0,0,0
0,0,0,0,0,11,11,11,11,0,11,0,0,0,0,0,0,0,0,0,11,0,11,11,11,11,0,0,0,0,0
0,0,0,0,0,13,63,63,7,0,0,0,0,0,0,0,0,0,0,0,0,0,7,63,63,13,0,0,0,0,0
0,0,0,0,0,0,10,63,7,0,0,0,0,0,0,0,0,0,0,0,0,0,7,63,9,0,0,0,0,0,0
0,0,0,0,0,0,10,63,7,0,0,0,0,0,0,0,0,0,0,0,0,0,7,63,9,0,0,0,0,0,0
0,0,0,0,0,0,10,63,7,0,0,0,0,0,0,0,0,0,0,0,0,0,7,63,9,0,0,0,0,0,0
0,0,0,0,0,0,10,63,7,0,0,0,0,0,0,0,0,0,0,0,0,0,7,63,9,0,0,0,0,0,0
0,0,0,0,0,0,10,63,7,0,0,0,0,0,0,0,0,0,0,0,0,0,7,63,9,0,0,0,0,0,0
0,0,0,0,0,0,10,63,63,66,66,11,0,11,0,0,0,11,0,11,66,66,63,63,9,0,0,0,0,0,0
0,0,0,0,0,0,10,63,53,0,0,0,0,0,0,0,0,0,0,0,0,0,50,63,9,0,0,0,0,0,0
0,0,0,0,0,0,10,63,63,52,52,52,52,52,52,52,52,52,52,52,52,52,63,63,9,0,0,0,0,0,0
0,0,0,0,0,0,10,63,63,63,63,63,63,63,63,63,63,63,63,63,63,63,63,63,9,0,0,0,0,0,0
0,0,0,0,0,0,54,13,13,13,13,13,13,13,13,13,13,13,13,13,13,13,13,13,54,0,0,0,0,0,0
0,0,0,0,0,0,0,0,0,0,0,0,0,0,0,0,0,0,0,0,0,0,0,0,0,0,0,0,0,0,0
0,0,0,0,0,0,0,0,0,0,0,0,0,0,0,0,0,0,0,0,0,0,0,0,0,0,0,0,0,0,0
0,0,0,0,0,0,0,0,0,0,0,0,0,0,0,0,0,0,0,0,0,0,0,0,0,0,0,0,0,0,0
0,0,0,0,0,0,0,0,0,0,0,0,0,0,0,0,0,0,0,0,0,0,0,0,0,0,0,0,0,0,0
0,0,0,0,0,0,0,0,0,0,0,0,0,0,0,0,0,0,0,0,0,0,0,0,0,0,0,0,0,0,0
0,0,0,0,0,0,0,0,0,0,0,0,0,0,0,0,0,0,0,0,0,0,0,0,0,0,0,0,0,0,0
:endlayer
layer: 12
0,0,0,0,0,0,0,0,0,0,0,0,0,0,0,0,0,0,0,0,0,0,0,0,0,0,0,0,0,0,0
0,0,0,0,0,0,0,0,0,0,0,0,0,0,0,0,0,0,0,0,0,0,0,0,0,0,0,0,0,0,0
0,0,0,0,0,0,0,0,0,0,0,0,0,0,0,0,0,0,0,0,0,0,0,0,0,0,0,0,0,0,0
0,0,0,0,0,0,0,0,0,0,0,0,0,0,0,0,0,0,0,0,0,0,0,0,0,0,0,0,0,0,0
0,0,0,0,0,0,0,0,0,0,0,0,0,0,0,0,0,0,0,0,0,0,0,0,0,0,0,0,0,0,0
0,0,0,0,0,0,0,0,0,0,0,0,0,0,0,0,0,0,0,0,0,0,0,0,0,0,0,0,0,0,0
0,0,0,0,0,0,0,0,0,0,0,0,0,0,0,0,0,0,0,0,0,0,0,0,0,0,0,0,0,0,0
0,0,0,0,0,0,0,0,0,0,0,0,0,0,0,0,0,0,0,0,0,0,0,0,0,0,0,0,0,0,0
0,0,0,0,0,0,0,0,0,0,0,0,0,0,0,0,0,0,0,0,0,0,0,0,0,0,0,0,0,0,0
0,0,0,0,0,0,0,0,0,0,0,0,0,0,0,0,0,0,0,0,0,0,0,0,0,0,0,0,0,0,0
0,0,0,0,0,0,0,0,0,0,0,0,0,0,0,0,0,0,0,0,0,0,0,0,0,0,0,0,0,0,0
0,0,0,0,0,0,0,54,12,12,12,12,12,12,12,12,12,12,12,12,12,12,12,54,0,0,0,0,0,0,0
0,0,0,0,0,0,0,10,11,63,63,63,63,63,63,63,63,63,63,63,63,63,11,9,0,0,0,0,0,0,0
0,0,0,0,0,0,0,10,63,63,55,55,55,55,55,64,55,55,55,55,55,63,63,9,0,0,0,0,0,0,0
0,0,0,0,0,0,0,10,63,53,66,11,66,66,11,54,11,66,66,11,66,50,63,9,0,0,0,0,0,0,0
0,0,0,0,0,0,0,10,63,53,0,54,54,54,54,54,54,54,54,54,0,50,63,9,0,0,0,0,0,0,0
0,0,0,0,0,0,0,10,63,64,54,54,0,0,0,0,0,0,0,54,54,64,63,9,0,0,0,0,0,0,0
0,0,0,0,0,0,0,10,63,53,0,54,0,0,0,0,0,0,0,54,0,50,63,9,0,0,0,0,0,0,0
0,0,0,0,0,0,0,10,63,53,0,54,0,0,0,0,0,0,0,54,0,50,63,9,0,0,0,0,0,0,0
0,0,0,0,0,0,0,10,63,64,54,54,0,0,0,0,0,0,0,54,54,64,63,9,0,0,0,0,0,0,0
0,0,0,0,0,0,0,10,63,53,0,54,0,0,0,0,0,0,0,54,0,50,63,9,0,0,0,0,0,0,0
0,0,0,0,0,12,12,63,63,53,11,54,0,0,0,0,0,0,0,54,11,50,63,63,12,12,0,0,0,0,0
0,0,0,0,0,11,63,11,63,53,0,54,0,0,0,0,0,0,0,54,0,50,63,11,63,11,0,0,0,0,0
0,0,0,0,0,51,63,0,7,53,0,54,0,0,0,0,0,0,0,54,0,50,7,0,63,51,0,0,0,0,0
0,0,0,0,0,33,63,0,7,64,54,54,0,0,0,0,0,0,0,54,54,64,7,0,63,34,0,0,0,0,0
0,0,0,0,0,51,63,0,7,53,0,54,0,0,0,0,0,0,0,54,0,50,7,0,63,51,0,0,0,0,0
0,0,0,0,0,11,55,11,63,53,0,54,0,0,0,0,0,0,0,54,0,50,63,11,55,11,0,0,0,0,0
0,0,0,0,0,13,13,63,63,53,11,54,0,0,0,0,0,0,0,54,11,50,63,63,13,13,0,0,0,0,0
0,0,0,0,0,0,0,10,63,53,0,54,0,0,0,0,0,0,0,54,0,50,63,9,0,0,0,0,0,0,0
0,0,0,0,0,0,0,10,63,64,54,54,0,0,0,0,0,0,0,54,54,64,63,9,0,0,0,0,0,0,0
0,0,0,0,0,0,0,10,63,53,0,54,0,0,0,0,0,0,0,54,0,50,63,9,0,0,0,0,0,0,0
0,0,0,0,0,0,0,10,63,53,0,54,0,0,0,0,0,0,0,54,0,50,63,9,0,0,0,0,0,0,0
0,0,0,0,0,0,0,10,63,64,54,54,0,0,0,0,0,0,0,54,54,64,63,9,0,0,0,0,0,0,0
0,0,0,0,0,0,0,10,63,53,0,54,54,54,54,54,54,54,54,54,0,50,63,9,0,0,0,0,0,0,0
0,0,0,0,0,0,0,10,63,53,66,11,66,11,0,54,0,11,66,11,66,50,63,9,0,0,0,0,0,0,0
0,0,0,0,0,0,0,10,63,63,52,52,52,52,52,64,52,52,52,52,52,63,63,9,0,0,0,0,0,0,0
0,0,0,0,0,0,0,10,63,63,63,63,63,63,63,63,63,63,63,63,63,63,63,9,0,0,0,0,0,0,0
0,0,0,0,0,0,0,54,13,13,13,13,13,13,13,13,13,13,13,13,13,13,13,54,0,0,0,0,0,0,0
0,0,0,0,0,0,0,0,0,0,0,0,0,0,0,0,0,0,0,0,0,0,0,0,0,0,0,0,0,0,0
0,0,0,0,0,0,0,0,0,0,0,0,0,0,0,0,0,0,0,0,0,0,0,0,0,0,0,0,0,0,0
0,0,0,0,0,0,0,0,0,0,0,0,0,0,0,0,0,0,0,0,0,0,0,0,0,0,0,0,0,0,0
0,0,0,0,0,0,0,0,0,0,0,0,0,0,0,0,0,0,0,0,0,0,0,0,0,0,0,0,0,0,0
0,0,0,0,0,0,0,0,0,0,0,0,0,0,0,0,0,0,0,0,0,0,0,0,0,0,0,0,0,0,0
0,0,0,0,0,0,0,0,0,0,0,0,0,0,0,0,0,0,0,0,0,0,0,0,0,0,0,0,0,0,0
0,0,0,0,0,0,0,0,0,0,0,0,0,0,0,0,0,0,0,0,0,0,0,0,0,0,0,0,0,0,0
:endlayer
layer: 13
0,0,0,0,0,0,0,0,0,0,0,0,0,0,0,0,0,0,0,0,0,0,0,0,0,0,0,0,0,0,0
0,0,0,0,0,0,0,0,0,0,0,0,0,0,0,0,0,0,0,0,0,0,0,0,0,0,0,0,0,0,0
0,0,0,0,0,0,0,0,0,0,0,0,0,0,0,0,0,0,0,0,0,0,0,0,0,0,0,0,0,0,0
0,0,0,0,0,0,0,0,0,0,0,0,0,0,0,0,0,0,0,0,0,0,0,0,0,0,0,0,0,0,0
0,0,0,0,0,0,0,0,0,0,0,0,0,0,0,0,0,0,0,0,0,0,0,0,0,0,0,0,0,0,0
0,0,0,0,0,0,0,0,0,0,0,0,0,0,0,0,0,0,0,0,0,0,0,0,0,0,0,0,0,0,0
0,0,0,0,0,0,0,0,0,0,0,0,0,0,0,0,0,0,0,0,0,0,0,0,0,0,0,0,0,0,0
0,0,0,0,0,0,0,0,0,0,0,0,0,0,0,0,0,0,0,0,0,0,0,0,0,0,0,0,0,0,0
0,0,0,0,0,0,0,0,0,0,0,0,0,0,0,0,0,0,0,0,0,0,0,0,0,0,0,0,0,0,0
0,0,0,0,0,0,0,0,0,0,0,0,0,0,0,0,0,0,0,0,0,0,0,0,0,0,0,0,0,0,0
0,0,0,0,0,0,0,0,0,0,0,0,0,0,0,0,0,0,0,0,0,0,0,0,0,0,0,0,0,0,0
0,0,0,0,0,0,0,0,0,0,0,0,0,0,0,0,0,0,0,0,0,0,0,0,0,0,0,0,0,0,0
0,0,0,0,0,0,0,0,54,12,12,12,12,12,12,12,12,12,12,12,12,12,54,0,0,0,0,0,0,0,0
0,0,0,0,0,0,0,0,10,11,63,63,63,63,63,63,63,63,63,63,63,11,9,0,0,0,0,0,0,0,0
0,0,0,0,0,0,0,0,10,63,63,11,11,11,11,11,11,11,11,11,63,63,9,0,0,0,0,0,0,0,0
0,0,0,0,0,0,0,0,10,63,11,0,0,0,0,0,0,0,0,0,11,63,9,0,0,0,0,0,0,0,0
0,0,0,0,0,0,0,0,10,63,11,0,0,0,0,0,0,0,0,0,11,63,9,0,0,0,0,0,0,0,0
0,0,0,0,0,0,0,0,10,63,11,0,0,0,0,0,0,0,0,0,11,63,9,0,0,0,0,0,0,0,0
0,0,0,0,0,0,0,0,10,63,11,0,0,0,0,0,0,0,0,0,11,63,9,0,0,0,0,0,0,0,0
0,0,0,0,0,0,0,0,10,63,11,0,0,0,0,0,0,0,0,0,11,63,9,0,0,0,0,0,0,0,0
0,0,0,0,0,0,0,0,10,63,11,0,0,0,0,0,0,0,0,0,11,63,9,0,0,0,0,0,0,0,0
0,0,0,0,0,0,0,0,10,63,11,0,0,0,0,0,0,0,0,0,11,63,9,0,0,0,0,0,0,0,0
0,0,0,0,0,12,12,12,63,63,11,0,0,0,0,0,0,0,0,0,11,63,63,12,12,12,0,0,0,0,0
0,0,0,0,0,11,63,11,63,63,11,0,0,0,0,71,0,0,0,0,11,63,63,11,63,11,0,0,0,0,0
0,0,0,0,0,51,63,0,7,63,11,0,0,0,71,71,71,0,0,0,11,63,7,0,63,51,0,0,0,0,0
0,0,0,0,0,11,63,11,63,63,11,0,0,0,0,71,0,0,0,0,11,63,63,11,63,11,0,0,0,0,0
0,0,0,0,0,13,13,13,63,63,11,0,0,0,0,0,0,0,0,0,11,63,63,13,13,13,0,0,0,0,0
0,0,0,0,0,0,0,0,10,63,11,0,0,0,0,0,0,0,0,0,11,63,9,0,0,0,0,0,0,0,0
0,0,0,0,0,0,0,0,10,63,11,0,0,0,0,0,0,0,0,0,11,63,9,0,0,0,0,0,0,0,0
0,0,0,0,0,0,0,0,10,63,11,0,0,0,0,0,0,0,0,0,11,63,9,0,0,0,0,0,0,0,0
0,0,0,0,0,0,0,0,10,63,11,0,0,0,0,0,0,0,0,0,11,63,9,0,0,0,0,0,0,0,0
0,0,0,0,0,0,0,0,10,63,11,0,0,0,0,0,0,0,0,0,11,63,9,0,0,0,0,0,0,0,0
0,0,0,0,0,0,0,0,10,63,11,0,0,0,0,0,0,0,0,0,11,63,9,0,0,0,0,0,0,0,0
0,0,0,0,0,0,0,0,10,63,11,0,0,0,0,0,0,0,0,0,11,63,9,0,0,0,0,0,0,0,0
0,0,0,0,0,0,0,0,10,63,63,11,11,11,11,11,11,11,11,11,63,63,9,0,0,0,0,0,0,0,0
0,0,0,0,0,0,0,0,10,63,63,63,63,63,63,63,63,63,63,63,63,63,9,0,0,0,0,0,0,0,0
0,0,0,0,0,0,0,0,54,13,13,13,13,13,13,13,13,13,13,13,13,13,54,0,0,0,0,0,0,0,0
0,0,0,0,0,0,0,0,0,0,0,0,0,0,0,0,0,0,0,0,0,0,0,0,0,0,0,0,0,0,0
0,0,0,0,0,0,0,0,0,0,0,0,0,0,0,0,0,0,0,0,0,0,0,0,0,0,0,0,0,0,0
0,0,0,0,0,0,0,0,0,0,0,0,0,0,0,0,0,0,0,0,0,0,0,0,0,0,0,0,0,0,0
0,0,0,0,0,0,0,0,0,0,0,0,0,0,0,0,0,0,0,0,0,0,0,0,0,0,0,0,0,0,0
0,0,0,0,0,0,0,0,0,0,0,0,0,0,0,0,0,0,0,0,0,0,0,0,0,0,0,0,0,0,0
0,0,0,0,0,0,0,0,0,0,0,0,0,0,0,0,0,0,0,0,0,0,0,0,0,0,0,0,0,0,0
0,0,0,0,0,0,0,0,0,0,0,0,0,0,0,0,0,0,0,0,0,0,0,0,0,0,0,0,0,0,0
0,0,0,0,0,0,0,0,0,0,0,0,0,0,0,0,0,0,0,0,0,0,0,0,0,0,0,0,0,0,0
:endlayer
layer: 14
0,0,0,0,0,0,0,0,0,0,0,0,0,0,0,0,0,0,0,0,0,0,0,0,0,0,0,0,0,0,0
0,0,0,0,0,0,0,0,0,0,0,0,0,0,0,0,0,0,0,0,0,0,0,0,0,0,0,0,0,0,0
0,0,0,0,0,0,0,0,0,0,0,0,0,0,0,0,0,0,0,0,0,0,0,0,0,0,0,0,0,0,0
0,0,0,0,0,0,0,0,0,0,0,0,0,0,0,0,0,0,0,0,0,0,0,0,0,0,0,0,0,0,0
0,0,0,0,0,0,0,0,0,0,0,0,0,0,0,0,0,0,0,0,0,0,0,0,0,0,0,0,0,0,0
0,0,0,0,0,0,0,0,0,0,0,0,0,0,0,0,0,0,0,0,0,0,0,0,0,0,0,0,0,0,0
0,0,0,0,0,0,0,0,0,0,0,0,0,0,0,0,0,0,0,0,0,0,0,0,0,0,0,0,0,0,0
0,0,0,0,0,0,0,0,0,0,0,0,0,0,0,0,0,0,0,0,0,0,0,0,0,0,0,0,0,0,0
0,0,0,0,0,0,0,0,0,0,0,0,0,0,0,0,0,0,0,0,0,0,0,0,0,0,0,0,0,0,0
0,0,0,0,0,0,0,0,0,0,0,0,0,0,0,0,0,0,0,0,0,0,0,0,0,0,0,0,0,0,0
0,0,0,0,0,0,0,0,0,0,0,0,0,0,0,0,0,0,0,0,0,0,0,0,0,0,0,0,0,0,0
0,0,0,0,0,0,0,0,0,0,0,0,0,0,0,0,0,0,0,0,0,0,0,0,0,0,0,0,0,0,0
0,0,0,0,0,0,0,0,0,0,0,0,0,0,0,0,0,0,0,0,0,0,0,0,0,0,0,0,0,0,0
0,0,0,0,0,0,0,0,0,54,12,12,12,12,12,12,12,12,12,12,12,54,0,0,0,0,0,0,0,0,0
0,0,0,0,0,0,0,0,0,10,7,7,7,7,66,66,66,66,66,66,7,9,0,0,0,0,0,0,0,0,0
0,0,0,0,0,0,0,0,0,10,7,0,0,0,0,0,0,0,0,0,7,9,0,0,0,0,0,0,0,0,0
0,0,0,0,0,0,0,0,0,10,7,0,0,0,0,0,0,0,0,0,7,9,0,0,0,0,0,0,0,0,0
0,0,0,0,0,0,0,0,0,10,7,0,0,0,0,0,0,0,0,0,7,9,0,0,0,0,0,0,0,0,0
0,0,0,0,0,0,0,0,0,10,7,0,0,0,0,0,0,0,0,0,7,9,0,0,0,0,0,0,0,0,0
0,0,0,0,0,0,0,0,0,10,7,0,0,0,0,0,0,0,0,0,7,9,0,0,0,0,0,0,0,0,0
0,0,0,0,0,0,0,0,0,10,7,0,0,0,0,0,0,0,0,0,7,9,0,0,0,0,0,0,0,0,0
0,0,0,0,0,0,0,0,0,10,11,0,0,0,0,0,0,0,0,0,11,9,0,0,0,0,0,0,0,0,0
0,0,0,0,0,0,0,0,0,10,7,0,0,0,0,0,0,0,0,0,7,9,0,0,0,0,0,0,0,0,0
0,0,0,0,0,12,12,12,12,63,7,0,0,0,0,65,0,0,0,0,7,63,12,12,12,12,0,0,0,0,0
0,0,0,0,0,11,11,11,63,63,7,0,0,0,65,71,65,0,0,0,7,63,63,11,11,11,0,0,0,0,0
0,0,0,0,0,13,13,13,13,63,7,0,0,0,0,65,0,0,0,0,7,63,13,13,13,13,0,0,0,0,0
0,0,0,0,0,0,0,0,0,10,7,0,0,0,0,0,0,0,0,0,7,9,0,0,0,0,0,0,0,0,0
0,0,0,0,0,0,0,0,0,10,11,0,0,0,0,0,0,0,0,0,11,9,0,0,0,0,0,0,0,0,0
0,0,0,0,0,0,0,0,0,10,7,0,0,0,0,0,0,0,0,0,7,9,0,0,0,0,0,0,0,0,0
0,0,0,0,0,0,0,0,0,10,7,0,0,0,0,0,0,0,0,0,7,9,0,0,0,0,0,0,0,0,0
0,0,0,0,0,0,0,0,0,10,7,0,0,0,0,0,0,0,0,0,7,9,0,0,0,0,0,0,0,0,0
0,0,0,0,0,0,0,0,0,10,7,0,0,0,0,0,0,0,0,0,7,9,0,0,0,0,0,0,0,0,0
0,0,0,0,0,0,0,0,0,10,7,0,0,0,0,0,0,0,0,0,7,9,0,0,0,0,0,0,0,0,0
0,0,0,0,0,0,0,0,0,10,7,0,0,0,0,0,0,0,0,0,7,9,0,0,0,0,0,0,0,0,0
0,0,0,0,0,0,0,0,0,10,7,7,7,7,7,7,7,7,7,7,7,9,0,0,0,0,0,0,0,0,0
0,0,0,0,0,0,0,0,0,0,13,13,13,13,13,13,13,13,13,13,13,0,0,0,0,0,0,0,0,0,0
0,0,0,0,0,0,0,0,0,0,0,0,0,0,0,0,0,0,0,0,0,0,0,0,0,0,0,0,0,0,0
0,0,0,0,0,0,0,0,0,0,0,0,0,0,0,0,0,0,0,0,0,0,0,0,0,0,0,0,0,0,0
0,0,0,0,0,0,0,0,0,0,0,0,0,0,0,0,0,0,0,0,0,0,0,0,0,0,0,0,0,0,0
0,0,0,0,0,0,0,0,0,0,0,0,0,0,0,0,0,0,0,0,0,0,0,0,0,0,0,0,0,0,0
0,0,0,0,0,0,0,0,0,0,0,0,0,0,0,0,0,0,0,0,0,0,0,0,0,0,0,0,0,0,0
0,0,0,0,0,0,0,0,0,0,0,0,0,0,0,0,0,0,0,0,0,0,0,0,0,0,0,0,0,0,0
0,0,0,0,0,0,0,0,0,0,0,0,0,0,0,0,0,0,0,0,0,0,0,0,0,0,0,0,0,0,0
0,0,0,0,0,0,0,0,0,0,0,0,0,0,0,0,0,0,0,0,0,0,0,0,0,0,0,0,0,0,0
0,0,0,0,0,0,0,0,0,0,0,0,0,0,0,0,0,0,0,0,0,0,0,0,0,0,0,0,0,0,0
:endlayer
layer: 15
0,0,0,0,0,0,0,0,0,0,0,0,0,0,0,0,0,0,0,0,0,0,0,0,0,0,0,0,0,0,0
0,0,0,0,0,0,0,0,0,0,0,0,0,0,0,0,0,0,0,0,0,0,0,0,0,0,0,0,0,0,0
0,0,0,0,0,0,0,0,0,0,0,0,0,0,0,0,0,0,0,0,0,0,0,0,0,0,0,0,0,0,0
0,0,0,0,0,0,0,0,0,0,0,0,0,0,0,0,0,0,0,0,0,0,0,0,0,0,0,0,0,0,0
0,0,0,0,0,0,0,0,0,0,0,0,0,0,0,0,0,0,0,0,0,0,0,0,0,0,0,0,0,0,0
0,0,0,0,0,0,0,0,0,0,0,0,0,0,0,0,0,0,0,0,0,0,0,0,0,0,0,0,0,0,0
0,0,0,0,0,0,0,0,0,0,0,0,0,0,0,0,0,0,0,0,0,0,0,0,0,0,0,0,0,0,0
0,0,0,0,0,0,0,0,0,0,0,0,0,0,0,0,0,0,0,0,0,0,0,0,0,0,0,0,0,0,0
0,0,0,0,0,0,0,0,0,0,0,0,0,0,0,0,0,0,0,0,0,0,0,0,0,0,0,0,0,0,0
0,0,0,0,0,0,0,0,0,0,0,0,0,0,0,0,0,0,0,0,0,0,0,0,0,0,0,0,0,0,0
0,0,0,0,0,0,0,0,0,0,0,0,0,0,0,0,0,0,0,0,0,0,0,0,0,0,0,0,0,0,0
0,0,0,0,0,0,0,0,0,0,0,0,0,0,0,0,0,0,0,0,0,0,0,0,0,0,0,0,0,0,0
0,0,0,0,0,0,0,0,0,0,0,0,0,0,0,0,0,0,0,0,0,0,0,0,0,0,0,0,0,0,0
0,0,0,0,0,0,0,0,0,0,0,0,0,0,0,0,0,0,0,0,0,0,0,0,0,0,0,0,0,0,0
0,0,0,0,0,0,0,0,0,0,11,7,7,7,7,7,7,7,7,7,11,0,0,0,0,0,0,0,0,0,0
0,0,0,0,0,0,0,0,0,0,7,0,0,55,55,55,55,55,0,0,7,0,0,0,0,0,0,0,0,0,0
0,0,0,0,0,0,0,0,0,0,7,0,0,0,0,89,0,0,0,0,7,0,0,0,0,0,0,0,0,0,0
0,0,0,0,0,0,0,0,0,0,7,0,0,0,0,89,0,0,0,0,7,0,0,0,0,0,0,0,0,0,0
0,0,0,0,0,0,0,0,0,0,7,0,0,0,0,0,0,0,0,0,7,0,0,0,0,0,0,0,0,0,0
0,0,0,0,0,0,0,0,0,0,7,0,0,0,0,0,0,0,0,0,7,0,0,0,0,0,0,0,0,0,0
0,0,0,0,0,0,0,0,0,0,7,0,0,0,0,0,0,0,0,0,7,0,0,0,0,0,0,0,0,0,0
0,0,0,0,0,0,0,0,0,0,11,0,0,0,0,0,0,0,0,0,11,0,0,0,0,0,0,0,0,0,0
0,0,0,0,0,0,0,0,0,0,7,0,0,0,0,0,0,0,0,0,7,0,0,0,0,0,0,0,0,0,0
0,0,0,0,0,0,0,0,0,0,7,0,0,0,0,0,0,0,0,0,7,0,0,0,0,0,0,0,0,0,0
0,0,0,0,0,54,54,54,54,54,7,0,0,0,0,71,0,0,0,0,7,54,54,54,54,54,0,0,0,0,0
0,0,0,0,0,0,0,0,0,0,7,0,0,0,0,0,0,0,0,0,7,0,0,0,0,0,0,0,0,0,0
0,0,0,0,0,0,0,0,0,0,7,0,0,0,0,0,0,0,0,0,7,0,0,0,0,0,0,0,0,0,0
0,0,0,0,0,0,0,0,0,0,11,0,0,0,0,0,0,0,0,0,11,0,0,0,0,0,0,0,0,0,0
0,0,0,0,0,0,0,0,0,0,7,0,0,0,0,0,0,0,0,0,7,0,0,0,0,0,0,0,0,0,0
0,0,0,0,0,0,0,0,0,0,7,0,0,0,0,0,0,0,0,0,7,0,0,0,0,0,0,0,0,0,0
0,0,0,0,0,0,0,0,0,0,7,0,0,0,0,0,0,0,0,0,7,0,0,0,0,0,0,0,0,0,0
0,0,0,0,0,0,0,0,0,0,7,0,0,0,0,0,0,0,0,0,7,0,0,0,0,0,0,0,0,0,0
0,0,0,0,0,0,0,0,0,0,7,0,0,0,0,0,0,0,0,0,7,0,0,0,0,0,0,0,0,0,0
0,0,0,0,0,0,0,0,0,0,7,0,0,0,0,0,0,0,0,0,7,0,0,0,0,0,0,0,0,0,0
0,0,0,0,0,0,0,0,0,0,11,7,7,7,7,7,7,7,7,7,11,0,0,0,0,0,0,0,0,0,0
0,0,0,0,0,0,0,0,0,0,0,0,0,0,0,0,0,0,0,0,0,0,0,0,0,0,0,0,0,0,0
0,0,0,0,0,0,0,0,0,0,0,0,0,0,0,0,0,0,0,0,0,0,0,0,0,0,0,0,0,0,0
0,0,0,0,0,0,0,0,0,0,0,0,0,0,0,0,0,0,0,0,0,0,0,0,0,0,0,0,0,0,0
0,0,0,0,0,0,0,0,0,0,0,0,0,0,0,0,0,0,0,0,0,0,0,0,0,0,0,0,0,0,0
0,0,0,0,0,0,0,0,0,0,0,0,0,0,0,0,0,0,0,0,0,0,0,0,0,0,0,0,0,0,0
0,0,0,0,0,0,0,0,0,0,0,0,0,0,0,0,0,0,0,0,0,0,0,0,0,0,0,0,0,0,0
0,0,0,0,0,0,0,0,0,0,0,0,0,0,0,0,0,0,0,0,0,0,0,0,0,0,0,0,0,0,0
0,0,0,0,0,0,0,0,0,0,0,0,0,0,0,0,0,0,0,0,0,0,0,0,0,0,0,0,0,0,0
0,0,0,0,0,0,0,0,0,0,0,0,0,0,0,0,0,0,0,0,0,0,0,0,0,0,0,0,0,0,0
0,0,0,0,0,0,0,0,0,0,0,0,0,0,0,0,0,0,0,0,0,0,0,0,0,0,0,0,0,0,0
:endlayer
layer: 16
0,0,0,0,0,0,0,0,0,0,0,0,0,0,0,0,0,0,0,0,0,0,0,0,0,0,0,0,0,0,0
0,0,0,0,0,0,0,0,0,0,0,0,0,0,0,0,0,0,0,0,0,0,0,0,0,0,0,0,0,0,0
0,0,0,0,0,0,0,0,0,0,0,0,0,0,0,0,0,0,0,0,0,0,0,0,0,0,0,0,0,0,0
0,0,0,0,0,0,0,0,0,0,0,0,0,0,0,0,0,0,0,0,0,0,0,0,0,0,0,0,0,0,0
0,0,0,0,0,0,0,0,0,0,0,0,0,0,0,0,0,0,0,0,0,0,0,0,0,0,0,0,0,0,0
0,0,0,0,0,0,0,0,0,0,0,0,0,0,0,0,0,0,0,0,0,0,0,0,0,0,0,0,0,0,0
0,0,0,0,0,0,0,0,0,0,0,0,0,0,0,0,0,0,0,0,0,0,0,0,0,0,0,0,0,0,0
0,0,0,0,0,0,0,0,0,0,0,0,0,0,0,0,0,0,0,0,0,0,0,0,0,0,0,0,0,0,0
0,0,0,0,0,0,0,0,0,0,0,0,0,0,0,0,0,0,0,0,0,0,0,0,0,0,0,0,0,0,0
0,0,0,0,0,0,0,0,0,0,0,0,0,0,0,0,0,0,0,0,0,0,0,0,0,0,0,0,0,0,0
0,0,0,0,0,0,0,0,0,0,0,0,0,0,0,0,0,0,0,0,0,0,0,0,0,0,0,0,0,0,0
0,0,0,0,0,0,0,0,0,0,0,0,0,0,0,0,0,0,0,0,0,0,0,0,0,0,0,0,0,0,0
0,0,0,0,0,0,0,0,0,0,0,0,0,0,0,0,0,0,0,0,0,0,0,0,0,0,0,0,0,0,0
0,0,0,0,0,0,0,0,0,0,0,0,0,0,0,0,0,0,0,0,0,0,0,0,0,0,0,0,0,0,0
0,0,0,0,0,0,0,0,0,0,11,7,7,7,70,70,70,7,7,7,11,0,0,0,0,0,0,0,0,0,0
0,0,0,0,0,0,0,0,0,0,7,89,89,9,0,0,0,10,89,89,7,0,0,0,0,0,0,0,0,0,0
0,0,0,0,0,0,0,0,0,0,7,0,0,0,0,0,0,0,0,0,7,0,0,0,0,0,0,0,0,0,0
0,0,0,0,0,0,0,0,0,0,7,0,0,0,0,0,0,0,0,0,7,0,0,0,0,0,0,0,0,0,0
0,0,0,0,0,0,0,0,0,0,7,0,0,0,0,90,0,0,0,0,7,0,0,0,0,0,0,0,0,0,0
0,0,0,0,0,0,0,0,0,0,7,0,0,0,0,89,0,0,0,0,7,0,0,0,0,0,0,0,0,0,0
0,0,0,0,0,0,0,0,0,0,7,0,0,0,0,0,0,0,0,0,7,0,0,0,0,0,0,0,0,0,0
0,0,0,0,0,0,0,0,0,0,11,53,0,0,0,0,0,0,0,50,11,0,0,0,0,0,0,0,0,0,0
0,0,0,0,0,0,0,0,0,0,70,0,0,0,0,0,0,0,0,0,70,0,0,0,0,0,0,0,0,0,0
0,0,0,0,0,0,0,0,0,0,7,0,0,0,0,0,0,0,0,0,7,0,0,0,0,0,0,0,0,0,0
0,0,0,0,0,0,0,0,0,0,70,0,0,0,0,71,0,0,0,0,70,0,0,0,0,0,0,0,0,0,0
0,0,0,0,0,0,0,0,0,0,7,0,0,0,0,0,0,0,0,0,7,0,0,0,0,0,0,0,0,0,0
0,0,0,0,0,0,0,0,0,0,70,0,0,0,0,0,0,0,0,0,70,0,0,0,0,0,0,0,0,0,0
0,0,0,0,0,0,0,0,0,0,11,53,0,0,0,0,0,0,0,50,11,0,0,0,0,0,0,0,0,0,0
0,0,0,0,0,0,0,0,0,0,7,0,0,0,0,0,0,0,0,0,7,0,0,0,0,0,0,0,0,0,0
0,0,0,0,0,0,0,0,0,0,7,0,0,0,0,0,0,0,0,0,7,0,0,0,0,0,0,0,0,0,0
0,0,0,0,0,0,0,0,0,0,7,0,0,0,0,0,0,0,0,0,7,0,0,0,0,0,0,0,0,0,0
0,0,0,0,0,0,0,0,0,0,7,0,0,0,0,0,0,0,0,0,7,0,0,0,0,0,0,0,0,0,0
0,0,0,0,0,0,0,0,0,0,7,0,0,0,0,0,0,0,0,0,7,0,0,0,0,0,0,0,0,0,0
0,0,0,0,0,0,0,0,0,0,7,0,0,0,0,52,0,0,0,0,7,0,0,0,0,0,0,0,0,0,0
0,0,0,0,0,0,0,0,0,0,11,7,7,7,7,7,7,7,7,7,11,0,0,0,0,0,0,0,0,0,0
0,0,0,0,0,0,0,0,0,0,0,0,0,0,0,0,0,0,0,0,0,0,0,0,0,0,0,0,0,0,0
0,0,0,0,0,0,0,0,0,0,0,0,0,0,0,0,0,0,0,0,0,0,0,0,0,0,0,0,0,0,0
0,0,0,0,0,0,0,0,0,0,0,0,0,0,0,0,0,0,0,0,0,0,0,0,0,0,0,0,0,0,0
0,0,0,0,0,0,0,0,0,0,0,0,0,0,0,0,0,0,0,0,0,0,0,0,0,0,0,0,0,0,0
0,0,0,0,0,0,0,0,0,0,0,0,0,0,0,0,0,0,0,0,0,0,0,0,0,0,0,0,0,0,0
0,0,0,0,0,0,0,0,0,0,0,0,0,0,0,0,0,0,0,0,0,0,0,0,0,0,0,0,0,0,0
0,0,0,0,0,0,0,0,0,0,0,0,0,0,0,0,0,0,0,0,0,0,0,0,0,0,0,0,0,0,0
0,0,0,0,0,0,0,0,0,0,0,0,0,0,0,0,0,0,0,0,0,0,0,0,0,0,0,0,0,0,0
0,0,0,0,0,0,0,0,0,0,0,0,0,0,0,0,0,0,0,0,0,0,0,0,0,0,0,0,0,0,0
0,0,0,0,0,0,0,0,0,0,0,0,0,0,0,0,0,0,0,0,0,0,0,0,0,0,0,0,0,0,0
:endlayer
layer: 17
0,0,0,0,0,0,0,0,0,0,0,0,0,0,0,0,0,0,0,0,0,0,0,0,0,0,0,0,0,0,0
0,0,0,0,0,0,0,0,0,0,0,0,0,0,0,0,0,0,0,0,0,0,0,0,0,0,0,0,0,0,0
0,0,0,0,0,0,0,0,0,0,0,0,0,0,0,0,0,0,0,0,0,0,0,0,0,0,0,0,0,0,0
0,0,0,0,0,0,0,0,0,0,0,0,0,0,0,0,0,0,0,0,0,0,0,0,0,0,0,0,0,0,0
0,0,0,0,0,0,0,0,0,0,0,0,0,0,0,0,0,0,0,0,0,0,0,0,0,0,0,0,0,0,0
0,0,0,0,0,0,0,0,0,0,0,0,0,0,0,0,0,0,0,0,0,0,0,0,0,0,0,0,0,0,0
0,0,0,0,0,0,0,0,0,0,0,0,0,0,0,0,0,0,0,0,0,0,0,0,0,0,0,0,0,0,0
0,0,0,0,0,0,0,0,0,0,0,0,0,0,0,0,0,0,0,0,0,0,0,0,0,0,0,0,0,0,0
0,0,0,0,0,0,0,0,0,0,0,0,0,0,0,0,0,0,0,0,0,0,0,0,0,0,0,0,0,0,0
0,0,0,0,0,0,0,0,0,0,0,0,0,0,0,0,0,0,0,0,0,0,0,0,0,0,0,0,0,0,0
0,0,0,0,0,0,0,0,0,0,0,0,0,0,0,0,0,0,0,0,0,0,0,0,0,0,0,0,0,0,0
0,0,0,0,0,0,0,0,0,0,0,0,0,0,0,0,0,0,0,0,0,0,0,0,0,0,0,0,0,0,0
0,0,0,0,0,0,0,0,0,0,0,0,0,0,0,0,0,0,0,0,0,0,0,0,0,0,0,0,0,0,0
0,0,0,0,0,0,0,0,0,51,0,0,0,0,0,0,0,0,0,0,0,51,0,0,0,0,0,0,0,0,0
0,0,0,0,0,0,0,0,0,51,11,7,7,7,70,70,70,7,7,7,11,51,0,0,0,0,0,0,0,0,0
0,0,0,0,0,0,0,0,0,51,7,54,90,0,0,0,0,0,90,54,7,51,0,0,0,0,0,0,0,0,0
0,0,0,0,0,0,0,0,0,51,7,54,0,0,0,0,0,0,0,54,7,51,0,0,0,0,0,0,0,0,0
0,0,0,0,0,0,0,0,0,51,7,54,0,0,0,0,0,0,0,54,7,51,0,0,0,0,0,0,0,0,0
0,0,0,0,0,0,0,0,0,51,7,54,0,0,0,0,0,0,0,54,7,51,0,0,0,0,0,0,0,0,0
0,0,0,0,0,0,0,0,0,51,7,54,0,0,0,0,0,0,0,54,7,51,0,0,0,0,0,0,0,0,0
0,0,0,0,0,0,0,0,0,51,7,54,0,0,0,90,0,0,0,54,7,51,0,0,0,0,0,0,0,0,0
0,0,0,0,0,0,0,0,0,0,11,9,54,54,54,63,54,54,54,10,11,0,0,0,0,0,0,0,0,0,0
0,0,0,0,0,0,0,0,0,0,7,54,0,0,0,54,0,0,0,54,7,0,0,0,0,0,0,0,0,0,0
0,0,0,0,0,0,0,0,0,0,7,54,0,0,0,54,0,0,0,54,7,0,0,0,0,0,0,0,0,0,0
0,0,0,0,0,0,0,0,0,0,7,54,0,0,0,54,0,0,0,54,7,0,0,0,0,0,0,0,0,0,0
0,0,0,0,0,0,0,0,0,0,7,54,0,0,0,54,0,0,0,54,7,0,0,0,0,0,0,0,0,0,0
0,0,0,0,0,0,0,0,0,0,7,54,0,0,0,54,0,0,0,54,7,0,0,0,0,0,0,0,0,0,0
0,0,0,0,0,0,0,0,0,0,11,9,54,54,54,63,54,54,54,10,11,0,0,0,0,0,0,0,0,0,0
0,0,0,0,0,0,0,0,0,51,7,54,0,0,0,54,0,0,0,54,7,51,0,0,0,0,0,0,0,0,0
0,0,0,0,0,0,0,0,0,51,7,54,0,0,0,54,0,0,0,54,7,51,0,0,0,0,0,0,0,0,0
0,0,0,0,0,0,0,0,0,51,7,54,0,0,0,54,0,0,0,54,7,51,0,0,0,0,0,0,0,0,0
0,0,0,0,0,0,0,0,0,51,7,54,0,0,0,54,0,0,0,54,7,51,0,0,0,0,0,0,0,0,0
0,0,0,0,0,0,0,0,0,51,7,54,0,0,0,54,0,0,0,54,7,51,0,0,0,0,0,0,0,0,0
0,0,0,0,0,0,0,0,0,51,7,54,54,54,54,63,54,54,54,54,7,51,0,0,0,0,0,0,0,0,0
0,0,0,0,0,0,0,0,0,51,11,7,7,7,7,7,7,7,7,7,11,51,0,0,0,0,0,0,0,0,0
0,0,0,0,0,0,0,0,0,51,0,0,0,0,0,0,0,0,0,0,0,51,0,0,0,0,0,0,0,0,0
0,0,0,0,0,0,0,0,0,0,0,0,0,0,0,0,0,0,0,0,0,0,0,0,0,0,0,0,0,0,0
0,0,0,0,0,0,0,0,0,0,0,0,0,0,0,0,0,0,0,0,0,0,0,0,0,0,0,0,0,0,0
0,0,0,0,0,0,0,0,0,0,0,0,0,0,0,0,0,0,0,0,0,0,0,0,0,0,0,0,0,0,0
0,0,0,0,0,0,0,0,0,0,0,0,0,0,0,0,0,0,0,0,0,0,0,0,0,0,0,0,0,0,0
0,0,0,0,0,0,0,0,0,0,0,0,0,0,0,0,0,0,0,0,0,0,0,0,0,0,0,0,0,0,0
0,0,0,0,0,0,0,0,0,0,0,0,0,0,0,0,0,0,0,0,0,0,0,0,0,0,0,0,0,0,0
0,0,0,0,0,0,0,0,0,0,0,0,0,0,0,0,0,0,0,0,0,0,0,0,0,0,0,0,0,0,0
0,0,0,0,0,0,0,0,0,0,0,0,0,0,0,0,0,0,0,0,0,0,0,0,0,0,0,0,0,0,0
0,0,0,0,0,0,0,0,0,0,0,0,0,0,0,0,0,0,0,0,0,0,0,0,0,0,0,0,0,0,0
:endlayer
layer: 18
0,0,0,0,0,0,0,0,0,0,0,0,0,0,0,0,0,0,0,0,0,0,0,0,0,0,0,0,0,0,0
0,0,0,0,0,0,0,0,0,0,0,0,0,0,0,0,0,0,0,0,0,0,0,0,0,0,0,0,0,0,0
0,0,0,0,0,0,0,0,0,0,0,0,0,0,0,0,0,0,0,0,0,0,0,0,0,0,0,0,0,0,0
0,0,0,0,0,0,0,0,0,0,0,0,0,0,0,0,0,0,0,0,0,0,0,0,0,0,0,0,0,0,0
0,0,0,0,0,0,0,0,0,0,0,0,0,0,0,0,0,0,0,0,0,0,0,0,0,0,0,0,0,0,0
0,0,0,0,0,0,0,0,0,0,0,0,0,0,0,0,0,0,0,0,0,0,0,0,0,0,0,0,0,0,0
0,0,0,0,0,0,0,0,0,0,0,0,0,0,0,0,0,0,0,0,0,0,0,0,0,0,0,0,0,0,0
0,0,0,0,0,0,0,0,0,0,0,0,0,0,0,0,0,0,0,0,0,0,0,0,0,0,0,0,0,0,0
0,0,0,0,0,0,0,0,0,0,0,0,0,0,0,0,0,0,0,0,0,0,0,0,0,0,0,0,0,0,0
0,0,0,0,0,0,0,0,0,0,0,0,0,0,0,0,0,0,0,0,0,0,0,0,0,0,0,0,0,0,0
0,0,0,0,0,0,0,0,0,0,0,0,0,0,0,0,0,0,0,0,0,0,0,0,0,0,0,0,0,0,0
0,0,0,0,0,0,0,0,0,0,0,0,0,0,0,0,0,0,0,0,0,0,0,0,0,0,0,0,0,0,0
0,0,0,0,0,0,0,0,0,0,0,0,0,0,0,0,0,0,0,0,0,0,0,0,0,0,0,0,0,0,0
0,0,0,0,0,0,0,0,0,11,51,0,0,0,0,0,0,0,0,0,51,11,0,0,0,0,0,0,0,0,0
0,0,0,0,0,0,0,0,0,11,11,11,11,11,70,70,70,11,11,11,11,11,0,0,0,0,0,0,0,0,0
0,0,0,0,0,0,0,0,0,11,11,0,0,29,0,0,0,29,0,0,11,11,0,0,0,0,0,0,0,0,0
0,0,0,0,0,0,0,0,0,11,11,0,0,0,0,0,0,0,0,0,11,11,0,0,0,0,0,0,0,0,0
0,0,0,0,0,0,0,0,0,11,11,0,0,0,0,0,0,0,0,0,11,11,0,0,0,0,0,0,0,0,0
0,0,0,0,0,0,0,0,0,11,11,0,0,0,0,0,0,0,0,0,11,11,0,0,0,0,0,0,0,0,0
0,0,0,0,0,0,0,0,0,11,11,0,0,0,0,0,0,0,0,0,11,11,0,0,0,0,0,0,0,0,0
0,0,0,0,0,0,0,0,0,11,11,0,0,0,0,0,0,0,0,0,11,11,0,0,0,0,0,0,0,0,0
0,0,0,0,0,0,0,0,0,51,11,0,0,0,0,65,0,0,0,0,11,51,0,0,0,0,0,0,0,0,0
0,0,0,0,0,0,0,0,0,0,11,0,0,0,0,0,0,0,0,0,11,0,0,0,0,0,0,0,0,0,0
0,0,0,0,0,0,0,0,0,0,11,0,0,0,0,0,0,0,0,0,11,0,0,0,0,0,0,0,0,0,0
0,0,0,0,0,0,0,0,0,0,11,0,0,0,0,0,0,0,0,0,11,0,0,0,0,0,0,0,0,0,0
0,0,0,0,0,0,0,0,0,0,11,0,0,0,0,0,0,0,0,0,11,0,0,0,0,0,0,0,0,0,0
0,0,0,0,0,0,0,0,0,0,11,0,0,0,0,0,0,0,0,0,11,0,0,0,0,0,0,0,0,0,0
0,0,0,0,0,0,0,0,0,51,11,0,0,0,0,65,0,0,0,0,11,51,0,0,0,0,0,0,0,0,0
0,0,0,0,0,0,0,0,0,11,11,0,0,0,0,0,0,0,0,0,11,11,0,0,0,0,0,0,0,0,0
0,0,0,0,0,0,0,0,0,11,11,0,0,0,0,0,0,0,0,0,11,11,0,0,0,0,0,0,0,0,0
0,0,0,0,0,0,0,0,0,11,11,0,0,0,0,0,0,0,0,0,11,11,0,0,0,0,0,0,0,0,0
0,0,0,0,0,0,0,0,0,11,11,0,0,0,0,0,0,0,0,0,11,11,0,0,0,0,0,0,0,0,0
0,0,0,0,0,0,0,0,0,11,11,0,0,0,0,0,0,0,0,0,11,11,0,0,0,0,0,0,0,0,0
0,0,0,0,0,0,0,0,0,11,11,0,0,0,0,65,0,0,0,0,11,11,0,0,0,0,0,0,0,0,0
0,0,0,0,0,0,0,0,0,11,11,11,11,11,11,11,11,11,11,11,11,11,0,0,0,0,0,0,0,0,0
0,0,0,0,0,0,0,0,0,11,51,0,0,0,0,0,0,0,0,0,51,11,0,0,0,0,0,0,0,0,0
0,0,0,0,0,0,0,0,0,0,0,0,0,0,0,0,0,0,0,0,0,0,0,0,0,0,0,0,0,0,0
0,0,0,0,0,0,0,0,0,0,0,0,0,0,0,0,0,0,0,0,0,0,0,0,0,0,0,0,0,0,0
0,0,0,0,0,0,0,0,0,0,0,0,0,0,0,0,0,0,0,0,0,0,0,0,0,0,0,0,0,0,0
0,0,0,0,0,0,0,0,0,0,0,0,0,0,0,0,0,0,0,0,0,0,0,0,0,0,0,0,0,0,0
0,0,0,0,0,0,0,0,0,0,0,0,0,0,0,0,0,0,0,0,0,0,0,0,0,0,0,0,0,0,0
0,0,0,0,0,0,0,0,0,0,0,0,0,0,0,0,0,0,0,0,0,0,0,0,0,0,0,0,0,0,0
0,0,0,0,0,0,0,0,0,0,0,0,0,0,0,0,0,0,0,0,0,0,0,0,0,0,0,0,0,0,0
0,0,0,0,0,0,0,0,0,0,0,0,0,0,0,0,0,0,0,0,0,0,0,0,0,0,0,0,0,0,0
0,0,0,0,0,0,0,0,0,0,0,0,0,0,0,0,0,0,0,0,0,0,0,0,0,0,0,0,0,0,0
:endlayer
layer: 19
0,0,0,0,0,0,0,0,0,0,0,0,0,0,0,0,0,0,0,0,0,0,0,0,0,0,0,0,0,0,0
0,0,0,0,0,0,0,0,0,0,0,0,0,0,0,0,0,0,0,0,0,0,0,0,0,0,0,0,0,0,0
0,0,0,0,0,0,0,0,0,0,0,0,0,0,0,0,0,0,0,0,0,0,0,0,0,0,0,0,0,0,0
0,0,0,0,0,0,0,0,0,0,0,0,0,0,0,0,0,0,0,0,0,0,0,0,0,0,0,0,0,0,0
0,0,0,0,0,0,0,0,0,0,0,0,0,0,0,0,0,0,0,0,0,0,0,0,0,0,0,0,0,0,0
0,0,0,0,0,0,0,0,0,0,0,0,0,0,0,0,0,0,0,0,0,0,0,0,0,0,0,0,0,0,0
0,0,0,0,0,0,0,0,0,0,0,0,0,0,0,0,0,0,0,0,0,0,0,0,0,0,0,0,0,0,0
0,0,0,0,0,0,0,0,0,0,0,0,0,0,0,0,0,0,0,0,0,0,0,0,0,0,0,0,0,0,0
0,0,0,0,0,0,0,0,0,0,0,0,0,0,0,0,0,0,0,0,0,0,0,0,0,0,0,0,0,0,0
0,0,0,0,0,0,0,0,0,0,0,0,0,0,0,0,0,0,0,0,0,0,0,0,0,0,0,0,0,0,0
0,0,0,0,0,0,0,0,0,0,0,0,0,0,0,0,0,0,0,0,0,0,0,0,0,0,0,0,0,0,0
0,0,0,0,0,0,0,0,0,0,0,0,0,0,0,0,0,0,0,0,0,0,0,0,0,0,0,0,0,0,0
0,0,0,0,0,0,0,0,0,0,0,0,0,0,0,0,0,0,0,0,0,0,0,0,0,0,0,0,0,0,0
0,0,0,0,0,0,0,0,0,54,11,51,0,35,0,0,0,35,0,51,11,54,0,0,0,0,0,0,0,0,0
0,0,0,0,0,0,0,0,0,10,63,7,7,7,70,70,70,7,7,7,63,9,0,0,0,0,0,0,0,0,0
0,0,0,0,0,0,0,0,0,10,63,0,0,0,0,0,0,0,0,0,63,9,0,0,0,0,0,0,0,0,0
0,0,0,0,0,0,0,0,0,10,63,0,0,0,0,0,0,0,0,0,63,9,0,0,0,0,0,0,0,0,0
0,0,0,0,0,0,0,0,0,10,63,0,0,0,0,0,0,0,0,0,63,9,0,0,0,0,0,0,0,0,0
0,0,0,0,0,0,0,0,0,10,63,0,0,0,0,0,0,0,0,0,63,9,0,0,0,0,0,0,0,0,0
0,0,0,0,0,0,0,0,0,10,63,0,0,0,0,0,0,0,0,0,63,9,0,0,0,0,0,0,0,0,0
0,0,0,0,0,0,0,0,0,10,63,0,0,0,0,0,0,0,0,0,63,9,0,0,0,0,0,0,0,0,0
0,0,0,0,0,0,0,0,0,11,11,0,0,0,0,0,0,0,0,0,11,11,0,0,0,0,0,0,0,0,0
0,0,0,0,0,0,0,0,0,51,7,0,0,0,0,0,0,0,0,0,7,51,0,0,0,0,0,0,0,0,0
0,0,0,0,0,0,0,0,0,0,7,0,0,0,0,0,0,0,0,0,7,0,0,0,0,0,0,0,0,0,0
0,0,0,0,0,0,0,0,0,0,7,0,0,0,0,0,0,0,0,0,7,0,0,0,0,0,0,0,0,0,0
0,0,0,0,0,0,0,0,0,0,7,0,0,0,0,0,0,0,0,0,7,0,0,0,0,0,0,0,0,0,0
0,0,0,0,0,0,0,0,0,51,7,0,0,0,0,0,0,0,0,0,7,51,0,0,0,0,0,0,0,0,0
0,0,0,0,0,0,0,0,0,11,11,0,0,0,0,0,0,0,0,0,11,11,0,0,0,0,0,0,0,0,0
0,0,0,0,0,0,0,0,0,10,63,0,0,0,0,0,0,0,0,0,63,9,0,0,0,0,0,0,0,0,0
0,0,0,0,0,0,0,0,0,10,63,0,0,0,0,0,0,0,0,0,63,9,0,0,0,0,0,0,0,0,0
0,0,0,0,0,0,0,0,0,10,63,0,0,0,0,0,0,0,0,0,63,9,0,0,0,0,0,0,0,0,0
0,0,0,0,0,0,0,0,0,10,63,0,0,0,0,0,0,0,0,0,63,9,0,0,0,0,0,0,0,0,0
0,0,0,0,0,0,0,0,0,10,63,0,0,0,0,0,0,0,0,0,63,9,0,0,0,0,0,0,0,0,0
0,0,0,0,0,0,0,0,0,10,63,0,0,0,0,0,0,0,0,0,63,9,0,0,0,0,0,0,0,0,0
0,0,0,0,0,0,0,0,0,10,63,7,7,7,70,70,70,7,7,7,63,9,0,0,0,0,0,0,0,0,0
0,0,0,0,0,0,0,0,0,54,11,51,0,29,0,0,0,29,0,51,11,54,0,0,0,0,0,0,0,0,0
0,0,0,0,0,0,0,0,0,0,0,0,0,0,0,0,0,0,0,0,0,0,0,0,0,0,0,0,0,0,0
0,0,0,0,0,0,0,0,0,0,0,0,0,0,0,0,0,0,0,0,0,0,0,0,0,0,0,0,0,0,0
0,0,0,0,0,0,0,0,0,0,0,0,0,0,0,0,0,0,0,0,0,0,0,0,0,0,0,0,0,0,0
0,0,0,0,0,0,0,0,0,0,0,0,0,0,0,0,0,0,0,0,0,0,0,0,0,0,0,0,0,0,0
0,0,0,0,0,0,0,0,0,0,0,0,0,0,0,0,0,0,0,0,0,0,0,0,0,0,0,0,0,0,0
0,0,0,0,0,0,0,0,0,0,0,0,0,0,0,0,0,0,0,0,0,0,0,0,0,0,0,0,0,0,0
0,0,0,0,0,0,0,0,0,0,0,0,0,0,0,0,0,0,0,0,0,0,0,0,0,0,0,0,0,0,0
0,0,0,0,0,0,0,0,0,0,0,0,0,0,0,0,0,0,0,0,0,0,0,0,0,0,0,0,0,0,0
0,0,0,0,0,0,0,0,0,0,0,0,0,0,0,0,0,0,0,0,0,0,0,0,0,0,0,0,0,0,0
:endlayer
layer: 20
0,0,0,0,0,0,0,0,0,0,0,0,0,0,0,0,0,0,0,0,0,0,0,0,0,0,0,0,0,0,0
0,0,0,0,0,0,0,0,0,0,0,0,0,0,0,0,0,0,0,0,0,0,0,0,0,0,0,0,0,0,0
0,0,0,0,0,0,0,0,0,0,0,0,0,0,0,0,0,0,0,0,0,0,0,0,0,0,0,0,0,0,0
0,0,0,0,0,0,0,0,0,0,0,0,0,0,0,0,0,0,0,0,0,0,0,0,0,0,0,0,0,0,0
0,0,0,0,0,0,0,0,0,0,0,0,0,0,0,0,0,0,0,0,0,0,0,0,0,0,0,0,0,0,0
0,0,0,0,0,0,0,0,0,0,0,0,0,0,0,0,0,0,0,0,0,0,0,0,0,0,0,0,0,0,0
0,0,0,0,0,0,0,0,0,0,0,0,0,0,0,0,0,0,0,0,0,0,0,0,0,0,0,0,0,0,0
0,0,0,0,0,0,0,0,0,0,0,0,0,0,0,0,0,0,0,0,0,0,0,0,0,0,0,0,0,0,0
0,0,0,0,0,0,0,0,0,0,0,0,0,0,0,0,0,0,0,0,0,0,0,0,0,0,0,0,0,0,0
0,0,0,0,0,0,0,0,0,0,0,0,0,0,0,0,0,0,0,0,0,0,0,0,0,0,0,0,0,0,0
0,0,0,0,0,0,0,0,0,0,0,0,0,0,0,0,0,0,0,0,0,0,0,0,0,0,0,0,0,0,0
0,0,0,0,0,0,0,0,0,0,0,0,0,0,0,0,0,0,0,0,0,0,0,0,0,0,0,0,0,0,0
0,0,0,0,0,0,0,0,0,0,0,0,0,0,0,0,0,0,0,0,0,0,0,0,0,0,0,0,0,0,0
0,0,0,0,0,0,0,0,0,0,54,11,0,0,0,0,0,0,0,11,54,0,0,0,0,0,0,0,0,0,0
0,0,0,0,0,0,0,0,0,0,10,63,7,7,70,70,70,7,7,63,9,0,0,0,0,0,0,0,0,0,0
0,0,0,0,0,0,0,0,0,0,10,63,0,0,0,0,0,0,0,63,9,0,0,0,0,0,0,0,0,0,0
0,0,0,0,0,0,0,0,0,0,10,63,0,0,0,0,0,0,0,63,9,0,0,0,0,0,0,0,0,0,0
0,0,0,0,0,0,0,0,0,0,10,63,0,0,0,0,0,0,0,63,9,0,0,0,0,0,0,0,0,0,0
0,0,0,0,0,0,0,0,0,0,10,63,0,0,0,0,0,0,0,63,9,0,0,0,0,0,0,0,0,0,0
0,0,0,0,0,0,0,0,0,0,10,63,0,0,0,0,0,0,0,63,9,0,0,0,0,0,0,0,0,0,0
0,0,0,0,0,0,0,0,0,0,10,63,0,0,0,0,0,0,0,63,9,0,0,0,0,0,0,0,0,0,0
0,0,0,0,0,0,0,0,0,12,63,63,0,0,0,0,0,0,0,63,63,12,0,0,0,0,0,0,0,0,0
0,0,0,0,0,0,0,0,0,11,7,0,0,0,0,0,0,0,0,0,7,11,0,0,0,0,0,0,0,0,0
0,0,0,0,0,0,0,0,0,51,7,0,0,0,0,0,0,0,0,0,7,51,0,0,0,0,0,0,0,0,0
0,0,0,0,0,0,0,0,0,33,7,0,0,0,0,0,0,0,0,0,7,34,0,0,0,0,0,0,0,0,0
0,0,0,0,0,0,0,0,0,51,7,0,0,0,0,0,0,0,0,0,7,51,0,0,0,0,0,0,0,0,0
0,0,0,0,0,0,0,0,0,11,7,0,0,0,0,0,0,0,0,0,7,11,0,0,0,0,0,0,0,0,0
0,0,0,0,0,0,0,0,0,13,63,63,0,0,0,0,0,0,0,63,63,13,0,0,0,0,0,0,0,0,0
0,0,0,0,0,0,0,0,0,0,10,63,0,0,0,0,0,0,0,63,9,0,0,0,0,0,0,0,0,0,0
0,0,0,0,0,0,0,0,0,0,10,63,0,0,0,0,0,0,0,63,9,0,0,0,0,0,0,0,0,0,0
0,0,0,0,0,0,0,0,0,0,10,63,0,0,0,0,0,0,0,63,9,0,0,0,0,0,0,0,0,0,0
0,0,0,0,0,0,0,0,0,0,10,63,0,0,0,0,0,0,0,63,9,0,0,0,0,0,0,0,0,0,0
0,0,0,0,0,0,0,0,0,0,10,63,0,0,0,0,0,0,0,63,9,0,0,0,0,0,0,0,0,0,0
0,0,0,0,0,0,0,0,0,0,10,63,0,0,0,0,0,0,0,63,9,0,0,0,0,0,0,0,0,0,0
0,0,0,0,0,0,0,0,0,0,10,63,7,7,70,70,70,7,7,63,9,0,0,0,0,0,0,0,0,0,0
0,0,0,0,0,0,0,0,0,0,54,11,0,0,0,0,0,0,0,11,54,0,0,0,0,0,0,0,0,0,0
0,0,0,0,0,0,0,0,0,0,0,0,0,0,0,0,0,0,0,0,0,0,0,0,0,0,0,0,0,0,0
0,0,0,0,0,0,0,0,0,0,0,0,0,0,0,0,0,0,0,0,0,0,0,0,0,0,0,0,0,0,0
0,0,0,0,0,0,0,0,0,0,0,0,0,0,0,0,0,0,0,0,0,0,0,0,0,0,0,0,0,0,0
0,0,0,0,0,0,0,0,0,0,0,0,0,0,0,0,0,0,0,0,0,0,0,0,0,0,0,0,0,0,0
0,0,0,0,0,0,0,0,0,0,0,0,0,0,0,0,0,0,0,0,0,0,0,0,0,0,0,0,0,0,0
0,0,0,0,0,0,0,0,0,0,0,0,0,0,0,0,0,0,0,0,0,0,0,0,0,0,0,0,0,0,0
0,0,0,0,0,0,0,0,0,0,0,0,0,0,0,0,0,0,0,0,0,0,0,0,0,0,0,0,0,0,0
0,0,0,0,0,0,0,0,0,0,0,0,0,0,0,0,0,0,0,0,0,0,0,0,0,0,0,0,0,0,0
0,0,0,0,0,0,0,0,0,0,0,0,0,0,0,0,0,0,0,0,0,0,0,0,0,0,0,0,0,0,0
:endlayer
layer: 21
0,0,0,0,0,0,0,0,0,0,0,0,0,0,0,0,0,0,0,0,0,0,0,0,0,0,0,0,0,0,0
0,0,0,0,0,0,0,0,0,0,0,0,0,0,0,0,0,0,0,0,0,0,0,0,0,0,0,0,0,0,0
0,0,0,0,0,0,0,0,0,0,0,0,0,0,0,0,0,0,0,0,0,0,0,0,0,0,0,0,0,0,0
0,0,0,0,0,0,0,0,0,0,0,0,0,0,0,0,0,0,0,0,0,0,0,0,0,0,0,0,0,0,0
0,0,0,0,0,0,0,0,0,0,0,0,0,0,0,0,0,0,0,0,0,0,0,0,0,0,0,0,0,0,0
0,0,0,0,0,0,0,0,0,0,0,0,0,0,0,0,0,0,0,0,0,0,0,0,0,0,0,0,0,0,0
0,0,0,0,0,0,0,0,0,0,0,0,0,0,0,0,0,0,0,0,0,0,0,0,0,0,0,0,0,0,0
0,0,0,0,0,0,0,0,0,0,0,0,0,0,0,0,0,0,0,0,0,0,0,0,0,0,0,0,0,0,0
0,0,0,0,0,0,0,0,0,0,0,0,0,0,0,0,0,0,0,0,0,0,0,0,0,0,0,0,0,0,0
0,0,0,0,0,0,0,0,0,0,0,0,0,0,0,0,0,0,0,0,0,0,0,0,0,0,0,0,0,0,0
0,0,0,0,0,0,0,0,0,0,0,0,0,0,0,0,0,0,0,0,0,0,0,0,0,0,0,0,0,0,0
0,0,0,0,0,0,0,0,0,0,0,0,0,0,0,0,0,0,0,0,0,0,0,0,0,0,0,0,0,0,0
0,0,0,0,0,0,0,0,0,0,0,0,0,0,0,0,0,0,0,0,0,0,0,0,0,0,0,0,0,0,0
0,0,0,0,0,0,0,0,0,0,0,11,51,0,0,0,0,0,51,11,0,0,0,0,0,0,0,0,0,0,0
0,0,0,0,0,0,0,0,0,0,0,63,7,7,70,70,70,7,7,63,0,0,0,0,0,0,0,0,0,0,0
0,0,0,0,0,0,0,0,0,0,0,63,63,0,0,0,0,0,63,63,0,0,0,0,0,0,0,0,0,0,0
0,0,0,0,0,0,0,0,0,0,0,63,63,0,0,0,0,0,63,63,0,0,0,0,0,0,0,0,0,0,0
0,0,0,0,0,0,0,0,0,0,0,63,63,0,0,0,0,0,63,63,0,0,0,0,0,0,0,0,0,0,0
0,0,0,0,0,0,0,0,0,0,0,63,63,0,0,0,0,0,63,63,0,0,0,0,0,0,0,0,0,0,0
0,0,0,0,0,0,0,0,0,0,0,63,63,0,0,0,0,0,63,63,0,0,0,0,0,0,0,0,0,0,0
0,0,0,0,0,0,0,0,0,0,0,63,63,0,0,0,0,0,63,63,0,0,0,0,0,0,0,0,0,0,0
0,0,0,0,0,0,0,0,0,0,0,63,63,0,0,0,0,0,63,63,0,0,0,0,0,0,0,0,0,0,0
0,0,0,0,0,0,0,0,0,12,12,63,63,0,0,0,0,0,63,63,12,12,0,0,0,0,0,0,0,0,0
0,0,0,0,0,0,0,0,0,11,7,0,0,0,0,0,0,0,0,0,7,11,0,0,0,0,0,0,0,0,0
0,0,0,0,0,0,0,0,0,51,7,0,0,0,0,0,0,0,0,0,7,51,0,0,0,0,0,0,0,0,0
0,0,0,0,0,0,0,0,0,11,7,0,0,0,0,0,0,0,0,0,7,11,0,0,0,0,0,0,0,0,0
0,0,0,0,0,0,0,0,0,13,13,63,63,0,0,0,0,0,63,63,13,13,0,0,0,0,0,0,0,0,0
0,0,0,0,0,0,0,0,0,0,0,63,63,0,0,0,0,0,63,63,0,0,0,0,0,0,0,0,0,0,0
0,0,0,0,0,0,0,0,0,0,0,63,63,0,0,0,0,0,63,63,0,0,0,0,0,0,0,0,0,0,0
0,0,0,0,0,0,0,0,0,0,0,63,63,0,0,0,0,0,63,63,0,0,0,0,0,0,0,0,0,0,0
0,0,0,0,0,0,0,0,0,0,0,63,63,0,0,0,0,0,63,63,0,0,0,0,0,0,0,0,0,0,0
0,0,0,0,0,0,0,0,0,0,0,63,63,0,0,0,0,0,63,63,0,0,0,0,0,0,0,0,0,0,0
0,0,0,0,0,0,0,0,0,0,0,63,63,0,0,0,0,0,63,63,0,0,0,0,0,0,0,0,0,0,0
0,0,0,0,0,0,0,0,0,0,0,63,63,0,0,0,0,0,63,63,0,0,0,0,0,0,0,0,0,0,0
0,0,0,0,0,0,0,0,0,0,0,63,7,7,70,70,70,7,7,63,0,0,0,0,0,0,0,0,0,0,0
0,0,0,0,0,0,0,0,0,0,0,11,51,0,0,0,0,0,51,11,0,0,0,0,0,0,0,0,0,0,0
0,0,0,0,0,0,0,0,0,0,0,0,0,0,0,0,0,0,0,0,0,0,0,0,0,0,0,0,0,0,0
0,0,0,0,0,0,0,0,0,0,0,0,0,0,0,0,0,0,0,0,0,0,0,0,0,0,0,0,0,0,0
0,0,0,0,0,0,0,0,0,0,0,0,0,0,0,0,0,0,0,0,0,0,0,0,0,0,0,0,0,0,0
0,0,0,0,0,0,0,0,0,0,0,0,0,0,0,0,0,0,0,0,0,0,0,0,0,0,0,0,0,0,0
0,0,0,0,0,0,0,0,0,0,0,0,0,0,0,0,0,0,0,0,0,0,0,0,0,0,0,0,0,0,0
0,0,0,0,0,0,0,0,0,0,0,0,0,0,0,0,0,0,0,0,0,0,0,0,0,0,0,0,0,0,0
0,0,0,0,0,0,0,0,0,0,0,0,0,0,0,0,0,0,0,0,0,0,0,0,0,0,0,0,0,0,0
0,0,0,0,0,0,0,0,0,0,0,0,0,0,0,0,0,0,0,0,0,0,0,0,0,0,0,0,0,0,0
0,0,0,0,0,0,0,0,0,0,0,0,0,0,0,0,0,0,0,0,0,0,0,0,0,0,0,0,0,0,0
:endlayer
layer: 22
0,0,0,0,0,0,0,0,0,0,0,0,0,0,0,0,0,0,0,0,0,0,0,0,0,0,0,0,0,0,0
0,0,0,0,0,0,0,0,0,0,0,0,0,0,0,0,0,0,0,0,0,0,0,0,0,0,0,0,0,0,0
0,0,0,0,0,0,0,0,0,0,0,0,0,0,0,0,0,0,0,0,0,0,0,0,0,0,0,0,0,0,0
0,0,0,0,0,0,0,0,0,0,0,0,0,0,0,0,0,0,0,0,0,0,0,0,0,0,0,0,0,0,0
0,0,0,0,0,0,0,0,0,0,0,0,0,0,0,0,0,0,0,0,0,0,0,0,0,0,0,0,0,0,0
0,0,0,0,0,0,0,0,0,0,0,0,0,0,0,0,0,0,0,0,0,0,0,0,0,0,0,0,0,0,0
0,0,0,0,0,0,0,0,0,0,0,0,0,0,0,0,0,0,0,0,0,0,0,0,0,0,0,0,0,0,0
0,0,0,0,0,0,0,0,0,0,0,0,0,0,0,0,0,0,0,0,0,0,0,0,0,0,0,0,0,0,0
0,0,0,0,0,0,0,0,0,0,0,0,0,0,0,0,0,0,0,0,0,0,0,0,0,0,0,0,0,0,0
0,0,0,0,0,0,0,0,0,0,0,0,0,0,0,0,0,0,0,0,0,0,0,0,0,0,0,0,0,0,0
0,0,0,0,0,0,0,0,0,0,0,0,0,0,0,0,0,0,0,0,0,0,0,0,0,0,0,0,0,0,0
0,0,0,0,0,0,0,0,0,0,0,0,0,0,0,0,0,0,0,0,0,0,0,0,0,0,0,0,0,0,0
0,0,0,0,0,0,0,0,0,0,0,0,0,0,0,0,0,0,0,0,0,0,0,0,0,0,0,0,0,0,0
0,0,0,0,0,0,0,0,0,0,0,54,11,51,0,0,0,51,11,54,0,0,0,0,0,0,0,0,0,0,0
0,0,0,0,0,0,0,0,0,0,0,10,63,7,7,70,7,7,63,9,0,0,0,0,0,0,0,0,0,0,0
0,0,0,0,0,0,0,0,0,0,0,10,63,63,0,0,0,63,63,9,0,0,0,0,0,0,0,0,0,0,0
0,0,0,0,0,0,0,0,0,0,0,10,63,63,0,0,0,63,63,9,0,0,0,0,0,0,0,0,0,0,0
0,0,0,0,0,0,0,0,0,0,0,10,63,63,0,0,0,63,63,9,0,0,0,0,0,0,0,0,0,0,0
0,0,0,0,0,0,0,0,0,0,0,10,63,63,0,0,0,63,63,9,0,0,0,0,0,0,0,0,0,0,0
0,0,0,0,0,0,0,0,0,0,0,10,63,63,0,0,0,63,63,9,0,0,0,0,0,0,0,0,0,0,0
0,0,0,0,0,0,0,0,0,0,0,10,63,63,0,0,0,63,63,9,0,0,0,0,0,0,0,0,0,0,0
0,0,0,0,0,0,0,0,0,0,0,10,63,63,0,0,0,63,63,9,0,0,0,0,0,0,0,0,0,0,0
0,0,0,0,0,0,0,0,0,0,0,10,63,63,0,0,0,63,63,9,0,0,0,0,0,0,0,0,0,0,0
0,0,0,0,0,0,0,0,0,12,12,63,63,63,0,0,0,63,63,63,12,12,0,0,0,0,0,0,0,0,0
0,0,0,0,0,0,0,0,0,11,7,0,63,63,0,0,0,63,63,0,7,11,0,0,0,0,0,0,0,0,0
0,0,0,0,0,0,0,0,0,13,13,63,63,63,0,0,0,63,63,63,13,13,0,0,0,0,0,0,0,0,0
0,0,0,0,0,0,0,0,0,0,0,10,63,63,0,0,0,63,63,9,0,0,0,0,0,0,0,0,0,0,0
0,0,0,0,0,0,0,0,0,0,0,10,63,63,0,0,0,63,63,9,0,0,0,0,0,0,0,0,0,0,0
0,0,0,0,0,0,0,0,0,0,0,10,63,63,0,0,0,63,63,9,0,0,0,0,0,0,0,0,0,0,0
0,0,0,0,0,0,0,0,0,0,0,10,63,63,0,0,0,63,63,9,0,0,0,0,0,0,0,0,0,0,0
0,0,0,0,0,0,0,0,0,0,0,10,63,63,0,0,0,63,63,9,0,0,0,0,0,0,0,0,0,0,0
0,0,0,0,0,0,0,0,0,0,0,10,63,63,0,0,0,63,63,9,0,0,0,0,0,0,0,0,0,0,0
0,0,0,0,0,0,0,0,0,0,0,10,63,63,0,0,0,63,63,9,0,0,0,0,0,0,0,0,0,0,0
0,0,0,0,0,0,0,0,0,0,0,10,63,63,0,0,0,63,63,9,0,0,0,0,0,0,0,0,0,0,0
0,0,0,0,0,0,0,0,0,0,0,10,63,7,7,70,7,7,63,9,0,0,0,0,0,0,0,0,0,0,0
0,0,0,0,0,0,0,0,0,0,0,54,11,51,0,0,0,51,11,54,0,0,0,0,0,0,0,0,0,0,0
0,0,0,0,0,0,0,0,0,0,0,0,0,0,0,0,0,0,0,0,0,0,0,0,0,0,0,0,0,0,0
0,0,0,0,0,0,0,0,0,0,0,0,0,0,0,0,0,0,0,0,0,0,0,0,0,0,0,0,0,0,0
0,0,0,0,0,0,0,0,0,0,0,0,0,0,0,0,0,0,0,0,0,0,0,0,0,0,0,0,0,0,0
0,0,0,0,0,0,0,0,0,0,0,0,0,0,0,0,0,0,0,0,0,0,0,0,0,0,0,0,0,0,0
0,0,0,0,0,0,0,0,0,0,0,0,0,0,0,0,0,0,0,0,0,0,0,0,0,0,0,0,0,0,0
0,0,0,0,0,0,0,0,0,0,0,0,0,0,0,0,0,0,0,0,0,0,0,0,0,0,0,0,0,0,0
0,0,0,0,0,0,0,0,0,0,0,0,0,0,0,0,0,0,0,0,0,0,0,0,0,0,0,0,0,0,0
0,0,0,0,0,0,0,0,0,0,0,0,0,0,0,0,0,0,0,0,0,0,0,0,0,0,0,0,0,0,0
0,0,0,0,0,0,0,0,0,0,0,0,0,0,0,0,0,0,0,0,0,0,0,0,0,0,0,0,0,0,0
:endlayer
layer: 23
0,0,0,0,0,0,0,0,0,0,0,0,0,0,0,0,0,0,0,0,0,0,0,0,0,0,0,0,0,0,0
0,0,0,0,0,0,0,0,0,0,0,0,0,0,0,0,0,0,0,0,0,0,0,0,0,0,0,0,0,0,0
0,0,0,0,0,0,0,0,0,0,0,0,0,0,0,0,0,0,0,0,0,0,0,0,0,0,0,0,0,0,0
0,0,0,0,0,0,0,0,0,0,0,0,0,0,0,0,0,0,0,0,0,0,0,0,0,0,0,0,0,0,0
0,0,0,0,0,0,0,0,0,0,0,0,0,0,0,0,0,0,0,0,0,0,0,0,0,0,0,0,0,0,0
0,0,0,0,0,0,0,0,0,0,0,0,0,0,0,0,0,0,0,0,0,0,0,0,0,0,0,0,0,0,0
0,0,0,0,0,0,0,0,0,0,0,0,0,0,0,0,0,0,0,0,0,0,0,0,0,0,0,0,0,0,0
0,0,0,0,0,0,0,0,0,0,0,0,0,0,0,0,0,0,0,0,0,0,0,0,0,0,0,0,0,0,0
0,0,0,0,0,0,0,0,0,0,0,0,0,0,0,0,0,0,0,0,0,0,0,0,0,0,0,0,0,0,0
0,0,0,0,0,0,0,0,0,0,0,0,0,0,0,0,0,0,0,0,0,0,0,0,0,0,0,0,0,0,0
0,0,0,0,0,0,0,0,0,0,0,0,0,0,0,0,0,0,0,0,0,0,0,0,0,0,0,0,0,0,0
0,0,0,0,0,0,0,0,0,0,0,0,0,0,0,0,0,0,0,0,0,0,0,0,0,0,0,0,0,0,0
0,0,0,0,0,0,0,0,0,0,0,0,0,0,0,0,0,0,0,0,0,0,0,0,0,0,0,0,0,0,0
0,0,0,0,0,0,0,0,0,0,0,0,54,11,0,0,0,11,54,0,0,0,0,0,0,0,0,0,0,0,0
0,0,0,0,0,0,0,0,0,0,0,0,10,63,7,70,7,63,9,0,0,0,0,0,0,0,0,0,0,0,0
0,0,0,0,0,0,0,0,0,0,0,0,10,63,0,0,0,63,9,0,0,0,0,0,0,0,0,0,0,0,0
0,0,0,0,0,0,0,0,0,0,0,0,10,63,0,0,0,63,9,0,0,0,0,0,0,0,0,0,0,0,0
0,0,0,0,0,0,0,0,0,0,0,0,10,63,0,0,0,63,9,0,0,0,0,0,0,0,0,0,0,0,0
0,0,0,0,0,0,0,0,0,0,0,0,10,63,0,0,0,63,9,0,0,0,0,0,0,0,0,0,0,0,0
0,0,0,0,0,0,0,0,0,0,0,0,10,63,0,0,0,63,9,0,0,0,0,0,0,0,0,0,0,0,0
0,0,0,0,0,0,0,0,0,0,0,0,10,63,0,0,0,63,9,0,0,0,0,0,0,0,0,0,0,0,0
0,0,0,0,0,0,0,0,0,0,0,0,10,63,0,0,0,63,9,0,0,0,0,0,0,0,0,0,0,0,0
0,0,0,0,0,0,0,0,0,0,0,0,63,63,0,0,0,63,63,0,0,0,0,0,0,0,0,0,0,0,0
0,0,0,0,0,0,0,0,0,0,0,0,10,63,0,0,0,63,9,0,0,0,0,0,0,0,0,0,0,0,0
0,0,0,0,0,0,0,0,0,54,54,54,10,63,0,0,0,63,9,54,54,54,0,0,0,0,0,0,0,0,0
0,0,0,0,0,0,0,0,0,0,0,0,10,63,0,0,0,63,9,0,0,0,0,0,0,0,0,0,0,0,0
0,0,0,0,0,0,0,0,0,0,0,0,63,63,0,0,0,63,63,0,0,0,0,0,0,0,0,0,0,0,0
0,0,0,0,0,0,0,0,0,0,0,0,10,63,0,0,0,63,9,0,0,0,0,0,0,0,0,0,0,0,0
0,0,0,0,0,0,0,0,0,0,0,0,10,63,0,0,0,63,9,0,0,0,0,0,0,0,0,0,0,0,0
0,0,0,0,0,0,0,0,0,0,0,0,10,63,0,0,0,63,9,0,0,0,0,0,0,0,0,0,0,0,0
0,0,0,0,0,0,0,0,0,0,0,0,10,63,0,0,0,63,9,0,0,0,0,0,0,0,0,0,0,0,0
0,0,0,0,0,0,0,0,0,0,0,0,10,63,0,0,0,63,9,0,0,0,0,0,0,0,0,0,0,0,0
0,0,0,0,0,0,0,0,0,0,0,0,10,63,0,0,0,63,9,0,0,0,0,0,0,0,0,0,0,0,0
0,0,0,0,0,0,0,0,0,0,0,0,10,63,0,0,0,63,9,0,0,0,0,0,0,0,0,0,0,0,0
0,0,0,0,0,0,0,0,0,0,0,0,10,63,7,70,7,63,9,0,0,0,0,0,0,0,0,0,0,0,0
0,0,0,0,0,0,0,0,0,0,0,0,54,11,0,0,0,11,54,0,0,0,0,0,0,0,0,0,0,0,0
0,0,0,0,0,0,0,0,0,0,0,0,0,0,0,0,0,0,0,0,0,0,0,0,0,0,0,0,0,0,0
0,0,0,0,0,0,0,0,0,0,0,0,0,0,0,0,0,0,0,0,0,0,0,0,0,0,0,0,0,0,0
0,0,0,0,0,0,0,0,0,0,0,0,0,0,0,0,0,0,0,0,0,0,0,0,0,0,0,0,0,0,0
0,0,0,0,0,0,0,0,0,0,0,0,0,0,0,0,0,0,0,0,0,0,0,0,0,0,0,0,0,0,0
0,0,0,0,0,0,0,0,0,0,0,0,0,0,0,0,0,0,0,0,0,0,0,0,0,0,0,0,0,0,0
0,0,0,0,0,0,0,0,0,0,0,0,0,0,0,0,0,0,0,0,0,0,0,0,0,0,0,0,0,0,0
0,0,0,0,0,0,0,0,0,0,0,0,0,0,0,0,0,0,0,0,0,0,0,0,0,0,0,0,0,0,0
0,0,0,0,0,0,0,0,0,0,0,0,0,0,0,0,0,0,0,0,0,0,0,0,0,0,0,0,0,0,0
0,0,0,0,0,0,0,0,0,0,0,0,0,0,0,0,0,0,0,0,0,0,0,0,0,0,0,0,0,0,0
:endlayer
layer: 24
0,0,0,0,0,0,0,0,0,0,0,0,0,0,0,0,0,0,0,0,0,0,0,0,0,0,0,0,0,0,0
0,0,0,0,0,0,0,0,0,0,0,0,0,0,0,0,0,0,0,0,0,0,0,0,0,0,0,0,0,0,0
0,0,0,0,0,0,0,0,0,0,0,0,0,0,0,0,0,0,0,0,0,0,0,0,0,0,0,0,0,0,0
0,0,0,0,0,0,0,0,0,0,0,0,0,0,0,0,0,0,0,0,0,0,0,0,0,0,0,0,0,0,0
0,0,0,0,0,0,0,0,0,0,0,0,0,0,0,0,0,0,0,0,0,0,0,0,0,0,0,0,0,0,0
0,0,0,0,0,0,0,0,0,0,0,0,0,0,0,0,0,0,0,0,0,0,0,0,0,0,0,0,0,0,0
0,0,0,0,0,0,0,0,0,0,0,0,0,0,0,0,0,0,0,0,0,0,0,0,0,0,0,0,0,0,0
0,0,0,0,0,0,0,0,0,0,0,0,0,0,0,0,0,0,0,0,0,0,0,0,0,0,0,0,0,0,0
0,0,0,0,0,0,0,0,0,0,0,0,0,0,0,0,0,0,0,0,0,0,0,0,0,0,0,0,0,0,0
0,0,0,0,0,0,0,0,0,0,0,0,0,0,0,0,0,0,0,0,0,0,0,0,0,0,0,0,0,0,0
0,0,0,0,0,0,0,0,0,0,0,0,0,0,0,0,0,0,0,0,0,0,0,0,0,0,0,0,0,0,0
0,0,0,0,0,0,0,0,0,0,0,0,0,0,0,0,0,0,0,0,0,0,0,0,0,0,0,0,0,0,0
0,0,0,0,0,0,0,0,0,0,0,0,0,0,0,0,0,0,0,0,0,0,0,0,0,0,0,0,0,0,0
0,0,0,0,0,0,0,0,0,0,0,0,0,11,51,35,51,11,0,0,0,0,0,0,0,0,0,0,0,0,0
0,0,0,0,0,0,0,0,0,0,0,0,0,63,7,7,7,63,0,0,0,0,0,0,0,0,0,0,0,0,0
0,0,0,0,0,0,0,0,0,0,0,0,0,63,0,0,0,63,0,0,0,0,0,0,0,0,0,0,0,0,0
0,0,0,0,0,0,0,0,0,0,0,0,0,63,0,0,0,63,0,0,0,0,0,0,0,0,0,0,0,0,0
0,0,0,0,0,0,0,0,0,0,0,0,0,63,0,0,0,63,0,0,0,0,0,0,0,0,0,0,0,0,0
0,0,0,0,0,0,0,0,0,0,0,0,0,63,0,0,0,63,0,0,0,0,0,0,0,0,0,0,0,0,0
0,0,0,0,0,0,0,0,0,0,0,0,0,63,0,0,0,63,0,0,0,0,0,0,0,0,0,0,0,0,0
0,0,0,0,0,0,0,0,0,0,0,0,0,63,0,0,0,63,0,0,0,0,0,0,0,0,0,0,0,0,0
0,0,0,0,0,0,0,0,0,0,0,0,0,63,0,0,0,63,0,0,0,0,0,0,0,0,0,0,0,0,0
0,0,0,0,0,0,0,0,0,0,0,0,11,63,0,0,0,63,11,0,0,0,0,0,0,0,0,0,0,0,0
0,0,0,0,0,0,0,0,0,0,0,0,51,63,0,0,0,63,51,0,0,0,0,0,0,0,0,0,0,0,0
0,0,0,0,0,0,0,0,0,0,0,0,51,63,0,0,0,63,51,0,0,0,0,0,0,0,0,0,0,0,0
0,0,0,0,0,0,0,0,0,0,0,0,51,63,0,0,0,63,51,0,0,0,0,0,0,0,0,0,0,0,0
0,0,0,0,0,0,0,0,0,0,0,0,11,63,0,0,0,63,11,0,0,0,0,0,0,0,0,0,0,0,0
0,0,0,0,0,0,0,0,0,0,0,0,0,63,0,0,0,63,0,0,0,0,0,0,0,0,0,0,0,0,0
0,0,0,0,0,0,0,0,0,0,0,0,0,63,0,0,0,63,0,0,0,0,0,0,0,0,0,0,0,0,0
0,0,0,0,0,0,0,0,0,0,0,0,0,63,0,0,0,63,0,0,0,0,0,0,0,0,0,0,0,0,0
0,0,0,0,0,0,0,0,0,0,0,0,0,63,0,0,0,63,0,0,0,0,0,0,0,0,0,0,0,0,0
0,0,0,0,0,0,0,0,0,0,0,0,0,63,0,0,0,63,0,0,0,0,0,0,0,0,0,0,0,0,0
0,0,0,0,0,0,0,0,0,0,0,0,0,63,0,0,0,63,0,0,0,0,0,0,0,0,0,0,0,0,0
0,0,0,0,0,0,0,0,0,0,0,0,0,63,0,0,0,63,0,0,0,0,0,0,0,0,0,0,0,0,0
0,0,0,0,0,0,0,0,0,0,0,0,0,63,7,7,7,63,0,0,0,0,0,0,0,0,0,0,0,0,0
0,0,0,0,0,0,0,0,0,0,0,0,0,11,51,29,51,11,0,0,0,0,0,0,0,0,0,0,0,0,0
0,0,0,0,0,0,0,0,0,0,0,0,0,0,0,0,0,0,0,0,0,0,0,0,0,0,0,0,0,0,0
0,0,0,0,0,0,0,0,0,0,0,0,0,0,0,0,0,0,0,0,0,0,0,0,0,0,0,0,0,0,0
0,0,0,0,0,0,0,0,0,0,0,0,0,0,0,0,0,0,0,0,0,0,0,0,0,0,0,0,0,0,0
0,0,0,0,0,0,0,0,0,0,0,0,0,0,0,0,0,0,0,0,0,0,0,0,0,0,0,0,0,0,0
0,0,0,0,0,0,0,0,0,0,0,0,0,0,0,0,0,0,0,0,0,0,0,0,0,0,0,0,0,0,0
0,0,0,0,0,0,0,0,0,0,0,0,0,0,0,0,0,0,0,0,0,0,0,0,0,0,0,0,0,0,0
0,0,0,0,0,0,0,0,0,0,0,0,0,0,0,0,0,0,0,0,0,0,0,0,0,0,0,0,0,0,0
0,0,0,0,0,0,0,0,0,0,0,0,0,0,0,0,0,0,0,0,0,0,0,0,0,0,0,0,0,0,0
0,0,0,0,0,0,0,0,0,0,0,0,0,0,0,0,0,0,0,0,0,0,0,0,0,0,0,0,0,0,0
:endlayer
layer: 25
0,0,0,0,0,0,0,0,0,0,0,0,0,0,0,0,0,0,0,0,0,0,0,0,0,0,0,0,0,0,0
0,0,0,0,0,0,0,0,0,0,0,0,0,0,0,0,0,0,0,0,0,0,0,0,0,0,0,0,0,0,0
0,0,0,0,0,0,0,0,0,0,0,0,0,0,0,0,0,0,0,0,0,0,0,0,0,0,0,0,0,0,0
0,0,0,0,0,0,0,0,0,0,0,0,0,0,0,0,0,0,0,0,0,0,0,0,0,0,0,0,0,0,0
0,0,0,0,0,0,0,0,0,0,0,0,0,0,0,0,0,0,0,0,0,0,0,0,0,0,0,0,0,0,0
0,0,0,0,0,0,0,0,0,0,0,0,0,0,0,0,0,0,0,0,0,0,0,0,0,0,0,0,0,0,0
0,0,0,0,0,0,0,0,0,0,0,0,0,0,0,0,0,0,0,0,0,0,0,0,0,0,0,0,0,0,0
0,0,0,0,0,0,0,0,0,0,0,0,0,0,0,0,0,0,0,0,0,0,0,0,0,0,0,0,0,0,0
0,0,0,0,0,0,0,0,0,0,0,0,0,0,0,0,0,0,0,0,0,0,0,0,0,0,0,0,0,0,0
0,0,0,0,0,0,0,0,0,0,0,0,0,0,0,0,0,0,0,0,0,0,0,0,0,0,0,0,0,0,0
0,0,0,0,0,0,0,0,0,0,0,0,0,0,0,0,0,0,0,0,0,0,0,0,0,0,0,0,0,0,0
0,0,0,0,0,0,0,0,0,0,0,0,0,0,0,0,0,0,0,0,0,0,0,0,0,0,0,0,0,0,0
0,0,0,0,0,0,0,0,0,0,0,0,0,0,0,0,0,0,0,0,0,0,0,0,0,0,0,0,0,0,0
0,0,0,0,0,0,0,0,0,0,0,0,0,54,11,51,11,54,0,0,0,0,0,0,0,0,0,0,0,0,0
0,0,0,0,0,0,0,0,0,0,0,0,0,10,63,7,63,9,0,0,0,0,0,0,0,0,0,0,0,0,0
0,0,0,0,0,0,0,0,0,0,0,0,0,10,63,0,63,9,0,0,0,0,0,0,0,0,0,0,0,0,0
0,0,0,0,0,0,0,0,0,0,0,0,0,10,63,0,63,9,0,0,0,0,0,0,0,0,0,0,0,0,0
0,0,0,0,0,0,0,0,0,0,0,0,0,10,63,0,63,9,0,0,0,0,0,0,0,0,0,0,0,0,0
0,0,0,0,0,0,0,0,0,0,0,0,0,10,63,0,63,9,0,0,0,0,0,0,0,0,0,0,0,0,0
0,0,0,0,0,0,0,0,0,0,0,0,0,10,63,0,63,9,0,0,0,0,0,0,0,0,0,0,0,0,0
0,0,0,0,0,0,0,0,0,0,0,0,0,10,63,0,63,9,0,0,0,0,0,0,0,0,0,0,0,0,0
0,0,0,0,0,0,0,0,0,0,0,0,0,10,63,0,63,9,0,0,0,0,0,0,0,0,0,0,0,0,0
0,0,0,0,0,0,0,0,0,0,0,0,11,10,63,0,63,9,11,0,0,0,0,0,0,0,0,0,0,0,0
0,0,0,0,0,0,0,0,0,0,0,0,11,10,0,0,0,9,11,0,0,0,0,0,0,0,0,0,0,0,0
0,0,0,0,0,0,0,0,0,0,0,0,11,10,0,0,0,9,11,0,0,0,0,0,0,0,0,0,0,0,0
0,0,0,0,0,0,0,0,0,0,0,0,11,10,0,0,0,9,11,0,0,0,0,0,0,0,0,0,0,0,0
0,0,0,0,0,0,0,0,0,0,0,0,11,10,63,0,63,9,11,0,0,0,0,0,0,0,0,0,0,0,0
0,0,0,0,0,0,0,0,0,0,0,0,0,10,63,0,63,9,0,0,0,0,0,0,0,0,0,0,0,0,0
0,0,0,0,0,0,0,0,0,0,0,0,0,10,63,0,63,9,0,0,0,0,0,0,0,0,0,0,0,0,0
0,0,0,0,0,0,0,0,0,0,0,0,0,10,63,0,63,9,0,0,0,0,0,0,0,0,0,0,0,0,0
0,0,0,0,0,0,0,0,0,0,0,0,0,10,63,0,63,9,0,0,0,0,0,0,0,0,0,0,0,0,0
0,0,0,0,0,0,0,0,0,0,0,0,0,10,63,0,63,9,0,0,0,0,0,0,0,0,0,0,0,0,0
0,0,0,0,0,0,0,0,0,0,0,0,0,10,63,0,63,9,0,0,0,0,0,0,0,0,0,0,0,0,0
0,0,0,0,0,0,0,0,0,0,0,0,0,10,63,0,63,9,0,0,0,0,0,0,0,0,0,0,0,0,0
0,0,0,0,0,0,0,0,0,0,0,0,0,10,63,7,63,9,0,0,0,0,0,0,0,0,0,0,0,0,0
0,0,0,0,0,0,0,0,0,0,0,0,0,54,11,51,11,54,0,0,0,0,0,0,0,0,0,0,0,0,0
0,0,0,0,0,0,0,0,0,0,0,0,0,0,0,0,0,0,0,0,0,0,0,0,0,0,0,0,0,0,0
0,0,0,0,0,0,0,0,0,0,0,0,0,0,0,0,0,0,0,0,0,0,0,0,0,0,0,0,0,0,0
0,0,0,0,0,0,0,0,0,0,0,0,0,0,0,0,0,0,0,0,0,0,0,0,0,0,0,0,0,0,0
0,0,0,0,0,0,0,0,0,0,0,0,0,0,0,0,0,0,0,0,0,0,0,0,0,0,0,0,0,0,0
0,0,0,0,0,0,0,0,0,0,0,0,0,0,0,0,0,0,0,0,0,0,0,0,0,0,0,0,0,0,0
0,0,0,0,0,0,0,0,0,0,0,0,0,0,0,0,0,0,0,0,0,0,0,0,0,0,0,0,0,0,0
0,0,0,0,0,0,0,0,0,0,0,0,0,0,0,0,0,0,0,0,0,0,0,0,0,0,0,0,0,0,0
0,0,0,0,0,0,0,0,0,0,0,0,0,0,0,0,0,0,0,0,0,0,0,0,0,0,0,0,0,0,0
0,0,0,0,0,0,0,0,0,0,0,0,0,0,0,0,0,0,0,0,0,0,0,0,0,0,0,0,0,0,0
:endlayer
layer: 26
0,0,0,0,0,0,0,0,0,0,0,0,0,0,0,0,0,0,0,0,0,0,0,0,0,0,0,0,0,0,0
0,0,0,0,0,0,0,0,0,0,0,0,0,0,0,0,0,0,0,0,0,0,0,0,0,0,0,0,0,0,0
0,0,0,0,0,0,0,0,0,0,0,0,0,0,0,0,0,0,0,0,0,0,0,0,0,0,0,0,0,0,0
0,0,0,0,0,0,0,0,0,0,0,0,0,0,0,0,0,0,0,0,0,0,0,0,0,0,0,0,0,0,0
0,0,0,0,0,0,0,0,0,0,0,0,0,0,0,0,0,0,0,0,0,0,0,0,0,0,0,0,0,0,0
0,0,0,0,0,0,0,0,0,0,0,0,0,0,0,0,0,0,0,0,0,0,0,0,0,0,0,0,0,0,0
0,0,0,0,0,0,0,0,0,0,0,0,0,0,0,0,0,0,0,0,0,0,0,0,0,0,0,0,0,0,0
0,0,0,0,0,0,0,0,0,0,0,0,0,0,0,0,0,0,0,0,0,0,0,0,0,0,0,0,0,0,0
0,0,0,0,0,0,0,0,0,0,0,0,0,0,0,0,0,0,0,0,0,0,0,0,0,0,0,0,0,0,0
0,0,0,0,0,0,0,0,0,0,0,0,0,0,0,0,0,0,0,0,0,0,0,0,0,0,0,0,0,0,0
0,0,0,0,0,0,0,0,0,0,0,0,0,0,0,0,0,0,0,0,0,0,0,0,0,0,0,0,0,0,0
0,0,0,0,0,0,0,0,0,0,0,0,0,0,0,0,0,0,0,0,0,0,0,0,0,0,0,0,0,0,0
0,0,0,0,0,0,0,0,0,0,0,0,0,0,0,0,0,0,0,0,0,0,0,0,0,0,0,0,0,0,0
0,0,0,0,0,0,0,0,0,0,0,0,0,0,54,11,54,0,0,0,0,0,0,0,0,0,0,0,0,0,0
0,0,0,0,0,0,0,0,0,0,0,0,0,0,10,63,9,0,0,0,0,0,0,0,0,0,0,0,0,0,0
0,0,0,0,0,0,0,0,0,0,0,0,0,0,10,63,9,0,0,0,0,0,0,0,0,0,0,0,0,0,0
0,0,0,0,0,0,0,0,0,0,0,0,0,0,10,63,9,0,0,0,0,0,0,0,0,0,0,0,0,0,0
0,0,0,0,0,0,0,0,0,0,0,0,0,0,10,63,9,0,0,0,0,0,0,0,0,0,0,0,0,0,0
0,0,0,0,0,0,0,0,0,0,0,0,0,0,10,63,9,0,0,0,0,0,0,0,0,0,0,0,0,0,0
0,0,0,0,0,0,0,0,0,0,0,0,0,0,10,63,9,0,0,0,0,0,0,0,0,0,0,0,0,0,0
0,0,0,0,0,0,0,0,0,0,0,0,0,0,10,63,9,0,0,0,0,0,0,0,0,0,0,0,0,0,0
0,0,0,0,0,0,0,0,0,0,0,0,0,0,10,63,9,0,0,0,0,0,0,0,0,0,0,0,0,0,0
0,0,0,0,0,0,0,0,0,0,0,0,11,0,10,63,9,0,11,0,0,0,0,0,0,0,0,0,0,0,0
0,0,0,0,0,0,0,0,0,0,0,0,63,34,0,54,0,33,63,0,0,0,0,0,0,0,0,0,0,0,0
0,0,0,0,0,0,0,0,0,0,0,0,63,0,0,54,0,0,63,0,0,0,0,0,0,0,0,0,0,0,0
0,0,0,0,0,0,0,0,0,0,0,0,63,34,0,54,0,33,63,0,0,0,0,0,0,0,0,0,0,0,0
0,0,0,0,0,0,0,0,0,0,0,0,11,0,10,63,9,0,11,0,0,0,0,0,0,0,0,0,0,0,0
0,0,0,0,0,0,0,0,0,0,0,0,0,0,10,63,9,0,0,0,0,0,0,0,0,0,0,0,0,0,0
0,0,0,0,0,0,0,0,0,0,0,0,0,0,10,63,9,0,0,0,0,0,0,0,0,0,0,0,0,0,0
0,0,0,0,0,0,0,0,0,0,0,0,0,0,10,63,9,0,0,0,0,0,0,0,0,0,0,0,0,0,0
0,0,0,0,0,0,0,0,0,0,0,0,0,0,10,63,9,0,0,0,0,0,0,0,0,0,0,0,0,0,0
0,0,0,0,0,0,0,0,0,0,0,0,0,0,10,63,9,0,0,0,0,0,0,0,0,0,0,0,0,0,0
0,0,0,0,0,0,0,0,0,0,0,0,0,0,10,63,9,0,0,0,0,0,0,0,0,0,0,0,0,0,0
0,0,0,0,0,0,0,0,0,0,0,0,0,0,10,63,9,0,0,0,0,0,0,0,0,0,0,0,0,0,0
0,0,0,0,0,0,0,0,0,0,0,0,0,0,10,63,9,0,0,0,0,0,0,0,0,0,0,0,0,0,0
0,0,0,0,0,0,0,0,0,0,0,0,0,0,54,11,54,0,0,0,0,0,0,0,0,0,0,0,0,0,0
0,0,0,0,0,0,0,0,0,0,0,0,0,0,0,0,0,0,0,0,0,0,0,0,0,0,0,0,0,0,0
0,0,0,0,0,0,0,0,0,0,0,0,0,0,0,0,0,0,0,0,0,0,0,0,0,0,0,0,0,0,0
0,0,0,0,0,0,0,0,0,0,0,0,0,0,0,0,0,0,0,0,0,0,0,0,0,0,0,0,0,0,0
0,0,0,0,0,0,0,0,0,0,0,0,0,0,0,0,0,0,0,0,0,0,0,0,0,0,0,0,0,0,0
0,0,0,0,0,0,0,0,0,0,0,0,0,0,0,0,0,0,0,0,0,0,0,0,0,0,0,0,0,0,0
0,0,0,0,0,0,0,0,0,0,0,0,0,0,0,0,0,0,0,0,0,0,0,0,0,0,0,0,0,0,0
0,0,0,0,0,0,0,0,0,0,0,0,0,0,0,0,0,0,0,0,0,0,0,0,0,0,0,0,0,0,0
0,0,0,0,0,0,0,0,0,0,0,0,0,0,0,0,0,0,0,0,0,0,0,0,0,0,0,0,0,0,0
0,0,0,0,0,0,0,0,0,0,0,0,0,0,0,0,0,0,0,0,0,0,0,0,0,0,0,0,0,0,0
:endlayer
layer: 27
0,0,0,0,0,0,0,0,0,0,0,0,0,0,0,0,0,0,0,0,0,0,0,0,0,0,0,0,0,0,0
0,0,0,0,0,0,0,0,0,0,0,0,0,0,0,0,0,0,0,0,0,0,0,0,0,0,0,0,0,0,0
0,0,0,0,0,0,0,0,0,0,0,0,0,0,0,0,0,0,0,0,0,0,0,0,0,0,0,0,0,0,0
0,0,0,0,0,0,0,0,0,0,0,0,0,0,0,0,0,0,0,0,0,0,0,0,0,0,0,0,0,0,0
0,0,0,0,0,0,0,0,0,0,0,0,0,0,0,0,0,0,0,0,0,0,0,0,0,0,0,0,0,0,0
0,0,0,0,0,0,0,0,0,0,0,0,0,0,0,0,0,0,0,0,0,0,0,0,0,0,0,0,0,0,0
0,0,0,0,0,0,0,0,0,0,0,0,0,0,0,0,0,0,0,0,0,0,0,0,0,0,0,0,0,0,0
0,0,0,0,0,0,0,0,0,0,0,0,0,0,0,0,0,0,0,0,0,0,0,0,0,0,0,0,0,0,0
0,0,0,0,0,0,0,0,0,0,0,0,0,0,0,0,0,0,0,0,0,0,0,0,0,0,0,0,0,0,0
0,0,0,0,0,0,0,0,0,0,0,0,0,0,0,0,0,0,0,0,0,0,0,0,0,0,0,0,0,0,0
0,0,0,0,0,0,0,0,0,0,0,0,0,0,0,0,0,0,0,0,0,0,0,0,0,0,0,0,0,0,0
0,0,0,0,0,0,0,0,0,0,0,0,0,0,0,0,0,0,0,0,0,0,0,0,0,0,0,0,0,0,0
0,0,0,0,0,0,0,0,0,0,0,0,0,0,0,52,0,0,0,0,0,0,0,0,0,0,0,0,0,0,0
0,0,0,0,0,0,0,0,0,0,0,0,0,0,0,11,0,0,0,0,0,0,0,0,0,0,0,0,0,0,0
0,0,0,0,0,0,0,0,0,0,0,0,0,0,0,11,0,0,0,0,0,0,0,0,0,0,0,0,0,0,0
0,0,0,0,0,0,0,0,0,0,0,0,0,0,0,11,0,0,0,0,0,0,0,0,0,0,0,0,0,0,0
0,0,0,0,0,0,0,0,0,0,0,0,0,0,0,11,0,0,0,0,0,0,0,0,0,0,0,0,0,0,0
0,0,0,0,0,0,0,0,0,0,0,0,0,0,0,11,0,0,0,0,0,0,0,0,0,0,0,0,0,0,0
0,0,0,0,0,0,0,0,0,0,0,0,0,0,0,11,0,0,0,0,0,0,0,0,0,0,0,0,0,0,0
0,0,0,0,0,0,0,0,0,0,0,0,0,0,0,11,0,0,0,0,0,0,0,0,0,0,0,0,0,0,0
0,0,0,0,0,0,0,0,0,0,0,0,0,0,0,11,0,0,0,0,0,0,0,0,0,0,0,0,0,0,0
0,0,0,0,0,0,0,0,0,0,0,0,0,0,0,11,0,0,0,0,0,0,0,0,0,0,0,0,0,0,0
0,0,0,0,0,0,0,0,0,0,0,0,11,51,51,11,51,51,11,0,0,0,0,0,0,0,0,0,0,0,0
0,0,0,0,0,0,0,0,0,0,0,0,71,0,0,0,0,0,71,0,0,0,0,0,0,0,0,0,0,0,0
0,0,0,0,0,0,0,0,0,0,0,0,71,0,0,0,0,0,71,0,0,0,0,0,0,0,0,0,0,0,0
0,0,0,0,0,0,0,0,0,0,0,0,71,0,0,0,0,0,71,0,0,0,0,0,0,0,0,0,0,0,0
0,0,0,0,0,0,0,0,0,0,0,0,11,51,51,11,51,51,11,0,0,0,0,0,0,0,0,0,0,0,0
0,0,0,0,0,0,0,0,0,0,0,0,0,0,0,11,0,0,0,0,0,0,0,0,0,0,0,0,0,0,0
0,0,0,0,0,0,0,0,0,0,0,0,0,0,0,11,0,0,0,0,0,0,0,0,0,0,0,0,0,0,0
0,0,0,0,0,0,0,0,0,0,0,0,0,0,0,11,0,0,0,0,0,0,0,0,0,0,0,0,0,0,0
0,0,0,0,0,0,0,0,0,0,0,0,0,0,0,11,0,0,0,0,0,0,0,0,0,0,0,0,0,0,0
0,0,0,0,0,0,0,0,0,0,0,0,0,0,0,11,0,0,0,0,0,0,0,0,0,0,0,0,0,0,0
0,0,0,0,0,0,0,0,0,0,0,0,0,0,0,11,0,0,0,0,0,0,0,0,0,0,0,0,0,0,0
0,0,0,0,0,0,0,0,0,0,0,0,0,0,0,11,0,0,0,0,0,0,0,0,0,0,0,0,0,0,0
0,0,0,0,0,0,0,0,0,0,0,0,0,0,0,11,0,0,0,0,0,0,0,0,0,0,0,0,0,0,0
0,0,0,0,0,0,0,0,0,0,0,0,0,0,0,11,0,0,0,0,0,0,0,0,0,0,0,0,0,0,0
0,0,0,0,0,0,0,0,0,0,0,0,0,0,0,55,0,0,0,0,0,0,0,0,0,0,0,0,0,0,0
0,0,0,0,0,0,0,0,0,0,0,0,0,0,0,0,0,0,0,0,0,0,0,0,0,0,0,0,0,0,0
0,0,0,0,0,0,0,0,0,0,0,0,0,0,0,0,0,0,0,0,0,0,0,0,0,0,0,0,0,0,0
0,0,0,0,0,0,0,0,0,0,0,0,0,0,0,0,0,0,0,0,0,0,0,0,0,0,0,0,0,0,0
0,0,0,0,0,0,0,0,0,0,0,0,0,0,0,0,0,0,0,0,0,0,0,0,0,0,0,0,0,0,0
0,0,0,0,0,0,0,0,0,0,0,0,0,0,0,0,0,0,0,0,0,0,0,0,0,0,0,0,0,0,0
0,0,0,0,0,0,0,0,0,0,0,0,0,0,0,0,0,0,0,0,0,0,0,0,0,0,0,0,0,0,0
0,0,0,0,0,0,0,0,0,0,0,0,0,0,0,0,0,0,0,0,0,0,0,0,0,0,0,0,0,0,0
0,0,0,0,0,0,0,0,0,0,0,0,0,0,0,0,0,0,0,0,0,0,0,0,0,0,0,0,0,0,0
:endlayer
layer: 28
0,0,0,0,0,0,0,0,0,0,0,0,0,0,0,0,0,0,0,0,0,0,0,0,0,0,0,0,0,0,0
0,0,0,0,0,0,0,0,0,0,0,0,0,0,0,0,0,0,0,0,0,0,0,0,0,0,0,0,0,0,0
0,0,0,0,0,0,0,0,0,0,0,0,0,0,0,0,0,0,0,0,0,0,0,0,0,0,0,0,0,0,0
0,0,0,0,0,0,0,0,0,0,0,0,0,0,0,0,0,0,0,0,0,0,0,0,0,0,0,0,0,0,0
0,0,0,0,0,0,0,0,0,0,0,0,0,0,0,0,0,0,0,0,0,0,0,0,0,0,0,0,0,0,0
0,0,0,0,0,0,0,0,0,0,0,0,0,0,0,0,0,0,0,0,0,0,0,0,0,0,0,0,0,0,0
0,0,0,0,0,0,0,0,0,0,0,0,0,0,0,0,0,0,0,0,0,0,0,0,0,0,0,0,0,0,0
0,0,0,0,0,0,0,0,0,0,0,0,0,0,0,0,0,0,0,0,0,0,0,0,0,0,0,0,0,0,0
0,0,0,0,0,0,0,0,0,0,0,0,0,0,0,0,0,0,0,0,0,0,0,0,0,0,0,0,0,0,0
0,0,0,0,0,0,0,0,0,0,0,0,0,0,0,0,0,0,0,0,0,0,0,0,0,0,0,0,0,0,0
0,0,0,0,0,0,0,0,0,0,0,0,0,0,0,0,0,0,0,0,0,0,0,0,0,0,0,0,0,0,0
0,0,0,0,0,0,0,0,0,0,0,0,0,0,0,0,0,0,0,0,0,0,0,0,0,0,0,0,0,0,0
0,0,0,0,0,0,0,0,0,0,0,0,0,0,0,11,0,0,0,0,0,0,0,0,0,0,0,0,0,0,0
0,0,0,0,0,0,0,0,0,0,0,0,0,0,0,11,0,0,0,0,0,0,0,0,0,0,0,0,0,0,0
0,0,0,0,0,0,0,0,0,0,0,0,0,0,0,13,0,0,0,0,0,0,0,0,0,0,0,0,0,0,0
0,0,0,0,0,0,0,0,0,0,0,0,0,0,0,54,0,0,0,0,0,0,0,0,0,0,0,0,0,0,0
0,0,0,0,0,0,0,0,0,0,0,0,0,0,0,54,0,0,0,0,0,0,0,0,0,0,0,0,0,0,0
0,0,0,0,0,0,0,0,0,0,0,0,0,0,0,54,0,0,0,0,0,0,0,0,0,0,0,0,0,0,0
0,0,0,0,0,0,0,0,0,0,0,0,0,0,0,54,0,0,0,0,0,0,0,0,0,0,0,0,0,0,0
0,0,0,0,0,0,0,0,0,0,0,0,0,0,0,54,0,0,0,0,0,0,0,0,0,0,0,0,0,0,0
0,0,0,0,0,0,0,0,0,0,0,0,0,0,0,54,0,0,0,0,0,0,0,0,0,0,0,0,0,0,0
0,0,0,0,0,0,0,0,0,0,0,10,53,0,0,54,0,0,50,9,0,0,0,0,0,0,0,0,0,0,0
0,0,0,0,0,0,0,0,0,0,0,10,11,11,11,11,11,11,11,9,0,0,0,0,0,0,0,0,0,0,0
0,0,0,0,0,0,0,0,0,0,0,10,11,0,0,0,0,0,11,9,0,0,0,0,0,0,0,0,0,0,0
0,0,0,0,0,0,0,0,0,0,0,10,11,0,0,0,0,0,11,9,0,0,0,0,0,0,0,0,0,0,0
0,0,0,0,0,0,0,0,0,0,0,10,11,0,0,0,0,0,11,9,0,0,0,0,0,0,0,0,0,0,0
0,0,0,0,0,0,0,0,0,0,0,10,11,11,11,11,11,11,11,9,0,0,0,0,0,0,0,0,0,0,0
0,0,0,0,0,0,0,0,0,0,0,10,53,0,0,54,0,0,50,9,0,0,0,0,0,0,0,0,0,0,0
0,0,0,0,0,0,0,0,0,0,0,0,0,0,0,54,0,0,0,0,0,0,0,0,0,0,0,0,0,0,0
0,0,0,0,0,0,0,0,0,0,0,0,0,0,0,54,0,0,0,0,0,0,0,0,0,0,0,0,0,0,0
0,0,0,0,0,0,0,0,0,0,0,0,0,0,0,54,0,0,0,0,0,0,0,0,0,0,0,0,0,0,0
0,0,0,0,0,0,0,0,0,0,0,0,0,0,0,54,0,0,0,0,0,0,0,0,0,0,0,0,0,0,0
0,0,0,0,0,0,0,0,0,0,0,0,0,0,0,54,0,0,0,0,0,0,0,0,0,0,0,0,0,0,0
0,0,0,0,0,0,0,0,0,0,0,0,0,0,0,54,0,0,0,0,0,0,0,0,0,0,0,0,0,0,0
0,0,0,0,0,0,0,0,0,0,0,0,0,0,0,12,0,0,0,0,0,0,0,0,0,0,0,0,0,0,0
0,0,0,0,0,0,0,0,0,0,0,0,0,0,0,11,0,0,0,0,0,0,0,0,0,0,0,0,0,0,0
0,0,0,0,0,0,0,0,0,0,0,0,0,0,0,11,0,0,0,0,0,0,0,0,0,0,0,0,0,0,0
0,0,0,0,0,0,0,0,0,0,0,0,0,0,0,0,0,0,0,0,0,0,0,0,0,0,0,0,0,0,0
0,0,0,0,0,0,0,0,0,0,0,0,0,0,0,0,0,0,0,0,0,0,0,0,0,0,0,0,0,0,0
0,0,0,0,0,0,0,0,0,0,0,0,0,0,0,0,0,0,0,0,0,0,0,0,0,0,0,0,0,0,0
0,0,0,0,0,0,0,0,0,0,0,0,0,0,0,0,0,0,0,0,0,0,0,0,0,0,0,0,0,0,0
0,0,0,0,0,0,0,0,0,0,0,0,0,0,0,0,0,0,0,0,0,0,0,0,0,0,0,0,0,0,0
0,0,0,0,0,0,0,0,0,0,0,0,0,0,0,0,0,0,0,0,0,0,0,0,0,0,0,0,0,0,0
0,0,0,0,0,0,0,0,0,0,0,0,0,0,0,0,0,0,0,0,0,0,0,0,0,0,0,0,0,0,0
0,0,0,0,0,0,0,0,0,0,0,0,0,0,0,0,0,0,0,0,0,0,0,0,0,0,0,0,0,0,0
:endlayer
layer: 29
0,0,0,0,0,0,0,0,0,0,0,0,0,0,0,0,0,0,0,0,0,0,0,0,0,0,0,0,0,0,0
0,0,0,0,0,0,0,0,0,0,0,0,0,0,0,0,0,0,0,0,0,0,0,0,0,0,0,0,0,0,0
0,0,0,0,0,0,0,0,0,0,0,0,0,0,0,0,0,0,0,0,0,0,0,0,0,0,0,0,0,0,0
0,0,0,0,0,0,0,0,0,0,0,0,0,0,0,0,0,0,0,0,0,0,0,0,0,0,0,0,0,0,0
0,0,0,0,0,0,0,0,0,0,0,0,0,0,0,0,0,0,0,0,0,0,0,0,0,0,0,0,0,0,0
0,0,0,0,0,0,0,0,0,0,0,0,0,0,0,0,0,0,0,0,0,0,0,0,0,0,0,0,0,0,0
0,0,0,0,0,0,0,0,0,0,0,0,0,0,0,0,0,0,0,0,0,0,0,0,0,0,0,0,0,0,0
0,0,0,0,0,0,0,0,0,0,0,0,0,0,0,0,0,0,0,0,0,0,0,0,0,0,0,0,0,0,0
0,0,0,0,0,0,0,0,0,0,0,0,0,0,0,0,0,0,0,0,0,0,0,0,0,0,0,0,0,0,0
0,0,0,0,0,0,0,0,0,0,0,0,0,0,0,0,0,0,0,0,0,0,0,0,0,0,0,0,0,0,0
0,0,0,0,0,0,0,0,0,0,0,0,0,0,0,0,0,0,0,0,0,0,0,0,0,0,0,0,0,0,0
0,0,0,0,0,0,0,0,0,0,0,0,0,0,0,52,0,0,0,0,0,0,0,0,0,0,0,0,0,0,0
0,0,0,0,0,0,0,0,0,0,0,0,0,0,0,13,0,0,0,0,0,0,0,0,0,0,0,0,0,0,0
0,0,0,0,0,0,0,0,0,0,0,0,0,0,0,54,0,0,0,0,0,0,0,0,0,0,0,0,0,0,0
0,0,0,0,0,0,0,0,0,0,0,0,0,0,0,0,0,0,0,0,0,0,0,0,0,0,0,0,0,0,0
0,0,0,0,0,0,0,0,0,0,0,0,0,0,0,0,0,0,0,0,0,0,0,0,0,0,0,0,0,0,0
0,0,0,0,0,0,0,0,0,0,0,0,0,0,0,0,0,0,0,0,0,0,0,0,0,0,0,0,0,0,0
0,0,0,0,0,0,0,0,0,0,0,0,0,0,0,0,0,0,0,0,0,0,0,0,0,0,0,0,0,0,0
0,0,0,0,0,0,0,0,0,0,0,0,0,0,0,0,0,0,0,0,0,0,0,0,0,0,0,0,0,0,0
0,0,0,0,0,0,0,0,0,0,0,0,0,0,0,0,0,0,0,0,0,0,0,0,0,0,0,0,0,0,0
0,0,0,0,0,0,0,0,0,0,0,0,0,0,0,0,0,0,0,0,0,0,0,0,0,0,0,0,0,0,0
0,0,0,0,0,0,0,0,0,0,0,0,10,53,0,0,0,50,9,0,0,0,0,0,0,0,0,0,0,0,0
0,0,0,0,0,0,0,0,0,0,0,0,10,11,51,51,51,11,9,0,0,0,0,0,0,0,0,0,0,0,0
0,0,0,0,0,0,0,0,0,0,0,0,10,0,0,0,0,0,9,0,0,0,0,0,0,0,0,0,0,0,0
0,0,0,0,0,0,0,0,0,0,0,0,10,0,0,0,0,0,9,0,0,0,0,0,0,0,0,0,0,0,0
0,0,0,0,0,0,0,0,0,0,0,0,10,0,0,0,0,0,9,0,0,0,0,0,0,0,0,0,0,0,0
0,0,0,0,0,0,0,0,0,0,0,0,10,11,51,51,51,11,9,0,0,0,0,0,0,0,0,0,0,0,0
0,0,0,0,0,0,0,0,0,0,0,0,10,53,0,0,0,50,9,0,0,0,0,0,0,0,0,0,0,0,0
0,0,0,0,0,0,0,0,0,0,0,0,0,0,0,0,0,0,0,0,0,0,0,0,0,0,0,0,0,0,0
0,0,0,0,0,0,0,0,0,0,0,0,0,0,0,0,0,0,0,0,0,0,0,0,0,0,0,0,0,0,0
0,0,0,0,0,0,0,0,0,0,0,0,0,0,0,0,0,0,0,0,0,0,0,0,0,0,0,0,0,0,0
0,0,0,0,0,0,0,0,0,0,0,0,0,0,0,0,0,0,0,0,0,0,0,0,0,0,0,0,0,0,0
0,0,0,0,0,0,0,0,0,0,0,0,0,0,0,0,0,0,0,0,0,0,0,0,0,0,0,0,0,0,0
0,0,0,0,0,0,0,0,0,0,0,0,0,0,0,0,0,0,0,0,0,0,0,0,0,0,0,0,0,0,0
0,0,0,0,0,0,0,0,0,0,0,0,0,0,0,0,0,0,0,0,0,0,0,0,0,0,0,0,0,0,0
0,0,0,0,0,0,0,0,0,0,0,0,0,0,0,54,0,0,0,0,0,0,0,0,0,0,0,0,0,0,0
0,0,0,0,0,0,0,0,0,0,0,0,0,0,0,12,0,0,0,0,0,0,0,0,0,0,0,0,0,0,0
0,0,0,0,0,0,0,0,0,0,0,0,0,0,0,55,0,0,0,0,0,0,0,0,0,0,0,0,0,0,0
0,0,0,0,0,0,0,0,0,0,0,0,0,0,0,0,0,0,0,0,0,0,0,0,0,0,0,0,0,0,0
0,0,0,0,0,0,0,0,0,0,0,0,0,0,0,0,0,0,0,0,0,0,0,0,0,0,0,0,0,0,0
0,0,0,0,0,0,0,0,0,0,0,0,0,0,0,0,0,0,0,0,0,0,0,0,0,0,0,0,0,0,0
0,0,0,0,0,0,0,0,0,0,0,0,0,0,0,0,0,0,0,0,0,0,0,0,0,0,0,0,0,0,0
0,0,0,0,0,0,0,0,0,0,0,0,0,0,0,0,0,0,0,0,0,0,0,0,0,0,0,0,0,0,0
0,0,0,0,0,0,0,0,0,0,0,0,0,0,0,0,0,0,0,0,0,0,0,0,0,0,0,0,0,0,0
0,0,0,0,0,0,0,0,0,0,0,0,0,0,0,0,0,0,0,0,0,0,0,0,0,0,0,0,0,0,0
:endlayer
layer: 30
0,0,0,0,0,0,0,0,0,0,0,0,0,0,0,0,0,0,0,0,0,0,0,0,0,0,0,0,0,0,0
0,0,0,0,0,0,0,0,0,0,0,0,0,0,0,0,0,0,0,0,0,0,0,0,0,0,0,0,0,0,0
0,0,0,0,0,0,0,0,0,0,0,0,0,0,0,0,0,0,0,0,0,0,0,0,0,0,0,0,0,0,0
0,0,0,0,0,0,0,0,0,0,0,0,0,0,0,0,0,0,0,0,0,0,0,0,0,0,0,0,0,0,0
0,0,0,0,0,0,0,0,0,0,0,0,0,0,0,0,0,0,0,0,0,0,0,0,0,0,0,0,0,0,0
0,0,0,0,0,0,0,0,0,0,0,0,0,0,0,0,0,0,0,0,0,0,0,0,0,0,0,0,0,0,0
0,0,0,0,0,0,0,0,0,0,0,0,0,0,0,0,0,0,0,0,0,0,0,0,0,0,0,0,0,0,0
0,0,0,0,0,0,0,0,0,0,0,0,0,0,0,0,0,0,0,0,0,0,0,0,0,0,0,0,0,0,0
0,0,0,0,0,0,0,0,0,0,0,0,0,0,0,0,0,0,0,0,0,0,0,0,0,0,0,0,0,0,0
0,0,0,0,0,0,0,0,0,0,0,0,0,0,0,0,0,0,0,0,0,0,0,0,0,0,0,0,0,0,0
0,0,0,0,0,0,0,0,0,0,0,0,0,0,0,0,0,0,0,0,0,0,0,0,0,0,0,0,0,0,0
0,0,0,0,0,0,0,0,0,0,0,0,0,0,0,0,0,0,0,0,0,0,0,0,0,0,0,0,0,0,0
0,0,0,0,0,0,0,0,0,0,0,0,0,0,0,0,0,0,0,0,0,0,0,0,0,0,0,0,0,0,0
0,0,0,0,0,0,0,0,0,0,0,0,0,0,0,0,0,0,0,0,0,0,0,0,0,0,0,0,0,0,0
0,0,0,0,0,0,0,0,0,0,0,0,0,0,0,0,0,0,0,0,0,0,0,0,0,0,0,0,0,0,0
0,0,0,0,0,0,0,0,0,0,0,0,0,0,0,0,0,0,0,0,0,0,0,0,0,0,0,0,0,0,0
0,0,0,0,0,0,0,0,0,0,0,0,0,0,0,0,0,0,0,0,0,0,0,0,0,0,0,0,0,0,0
0,0,0,0,0,0,0,0,0,0,0,0,0,0,0,0,0,0,0,0,0,0,0,0,0,0,0,0,0,0,0
0,0,0,0,0,0,0,0,0,0,0,0,0,0,0,0,0,0,0,0,0,0,0,0,0,0,0,0,0,0,0
0,0,0,0,0,0,0,0,0,0,0,0,0,0,0,0,0,0,0,0,0,0,0,0,0,0,0,0,0,0,0
0,0,0,0,0,0,0,0,0,0,0,0,0,0,0,0,0,0,0,0,0,0,0,0,0,0,0,0,0,0,0
0,0,0,0,0,0,0,0,0,0,0,0,0,10,53,0,50,9,0,0,0,0,0,0,0,0,0,0,0,0,0
0,0,0,0,0,0,0,0,0,0,0,0,0,10,11,11,11,9,0,0,0,0,0,0,0,0,0,0,0,0,0
0,0,0,0,0,0,0,0,0,0,0,0,0,10,0,0,0,9,0,0,0,0,0,0,0,0,0,0,0,0,0
0,0,0,0,0,0,0,0,0,0,0,0,0,10,0,0,0,9,0,0,0,0,0,0,0,0,0,0,0,0,0
0,0,0,0,0,0,0,0,0,0,0,0,0,10,0,0,0,9,0,0,0,0,0,0,0,0,0,0,0,0,0
0,0,0,0,0,0,0,0,0,0,0,0,0,10,11,11,11,9,0,0,0,0,0,0,0,0,0,0,0,0,0
0,0,0,0,0,0,0,0,0,0,0,0,0,10,53,0,50,9,0,0,0,0,0,0,0,0,0,0,0,0,0
0,0,0,0,0,0,0,0,0,0,0,0,0,0,0,0,0,0,0,0,0,0,0,0,0,0,0,0,0,0,0
0,0,0,0,0,0,0,0,0,0,0,0,0,0,0,0,0,0,0,0,0,0,0,0,0,0,0,0,0,0,0
0,0,0,0,0,0,0,0,0,0,0,0,0,0,0,0,0,0,0,0,0,0,0,0,0,0,0,0,0,0,0
0,0,0,0,0,0,0,0,0,0,0,0,0,0,0,0,0,0,0,0,0,0,0,0,0,0,0,0,0,0,0
0,0,0,0,0,0,0,0,0,0,0,0,0,0,0,0,0,0,0,0,0,0,0,0,0,0,0,0,0,0,0
0,0,0,0,0,0,0,0,0,0,0,0,0,0,0,0,0,0,0,0,0,0,0,0,0,0,0,0,0,0,0
0,0,0,0,0,0,0,0,0,0,0,0,0,0,0,0,0,0,0,0,0,0,0,0,0,0,0,0,0,0,0
0,0,0,0,0,0,0,0,0,0,0,0,0,0,0,0,0,0,0,0,0,0,0,0,0,0,0,0,0,0,0
0,0,0,0,0,0,0,0,0,0,0,0,0,0,0,0,0,0,0,0,0,0,0,0,0,0,0,0,0,0,0
0,0,0,0,0,0,0,0,0,0,0,0,0,0,0,0,0,0,0,0,0,0,0,0,0,0,0,0,0,0,0
0,0,0,0,0,0,0,0,0,0,0,0,0,0,0,0,0,0,0,0,0,0,0,0,0,0,0,0,0,0,0
0,0,0,0,0,0,0,0,0,0,0,0,0,0,0,0,0,0,0,0,0,0,0,0,0,0,0,0,0,0,0
0,0,0,0,0,0,0,0,0,0,0,0,0,0,0,0,0,0,0,0,0,0,0,0,0,0,0,0,0,0,0
0,0,0,0,0,0,0,0,0,0,0,0,0,0,0,0,0,0,0,0,0,0,0,0,0,0,0,0,0,0,0
0,0,0,0,0,0,0,0,0,0,0,0,0,0,0,0,0,0,0,0,0,0,0,0,0,0,0,0,0,0,0
0,0,0,0,0,0,0,0,0,0,0,0,0,0,0,0,0,0,0,0,0,0,0,0,0,0,0,0,0,0,0
0,0,0,0,0,0,0,0,0,0,0,0,0,0,0,0,0,0,0,0,0,0,0,0,0,0,0,0,0,0,0
:endlayer
layer: 31
0,0,0,0,0,0,0,0,0,0,0,0,0,0,0,0,0,0,0,0,0,0,0,0,0,0,0,0,0,0,0
0,0,0,0,0,0,0,0,0,0,0,0,0,0,0,0,0,0,0,0,0,0,0,0,0,0,0,0,0,0,0
0,0,0,0,0,0,0,0,0,0,0,0,0,0,0,0,0,0,0,0,0,0,0,0,0,0,0,0,0,0,0
0,0,0,0,0,0,0,0,0,0,0,0,0,0,0,0,0,0,0,0,0,0,0,0,0,0,0,0,0,0,0
0,0,0,0,0,0,0,0,0,0,0,0,0,0,0,0,0,0,0,0,0,0,0,0,0,0,0,0,0,0,0
0,0,0,0,0,0,0,0,0,0,0,0,0,0,0,0,0,0,0,0,0,0,0,0,0,0,0,0,0,0,0
0,0,0,0,0,0,0,0,0,0,0,0,0,0,0,0,0,0,0,0,0,0,0,0,0,0,0,0,0,0,0
0,0,0,0,0,0,0,0,0,0,0,0,0,0,0,0,0,0,0,0,0,0,0,0,0,0,0,0,0,0,0
0,0,0,0,0,0,0,0,0,0,0,0,0,0,0,0,0,0,0,0,0,0,0,0,0,0,0,0,0,0,0
0,0,0,0,0,0,0,0,0,0,0,0,0,0,0,0,0,0,0,0,0,0,0,0,0,0,0,0,0,0,0
0,0,0,0,0,0,0,0,0,0,0,0,0,0,0,0,0,0,0,0,0,0,0,0,0,0,0,0,0,0,0
0,0,0,0,0,0,0,0,0,0,0,0,0,0,0,0,0,0,0,0,0,0,0,0,0,0,0,0,0,0,0
0,0,0,0,0,0,0,0,0,0,0,0,0,0,0,0,0,0,0,0,0,0,0,0,0,0,0,0,0,0,0
0,0,0,0,0,0,0,0,0,0,0,0,0,0,0,0,0,0,0,0,0,0,0,0,0,0,0,0,0,0,0
0,0,0,0,0,0,0,0,0,0,0,0,0,0,0,0,0,0,0,0,0,0,0,0,0,0,0,0,0,0,0
0,0,0,0,0,0,0,0,0,0,0,0,0,0,0,0,0,0,0,0,0,0,0,0,0,0,0,0,0,0,0
0,0,0,0,0,0,0,0,0,0,0,0,0,0,0,0,0,0,0,0,0,0,0,0,0,0,0,0,0,0,0
0,0,0,0,0,0,0,0,0,0,0,0,0,0,0,0,0,0,0,0,0,0,0,0,0,0,0,0,0,0,0
0,0,0,0,0,0,0,0,0,0,0,0,0,0,0,0,0,0,0,0,0,0,0,0,0,0,0,0,0,0,0
0,0,0,0,0,0,0,0,0,0,0,0,0,0,0,0,0,0,0,0,0,0,0,0,0,0,0,0,0,0,0
0,0,0,0,0,0,0,0,0,0,0,0,0,0,0,0,0,0,0,0,0,0,0,0,0,0,0,0,0,0,0
0,0,0,0,0,0,0,0,0,0,0,0,0,0,10,64,9,0,0,0,0,0,0,0,0,0,0,0,0,0,0
0,0,0,0,0,0,0,0,0,0,0,0,0,0,10,11,9,0,0,0,0,0,0,0,0,0,0,0,0,0,0
0,0,0,0,0,0,0,0,0,0,0,0,0,0,7,7,7,0,0,0,0,0,0,0,0,0,0,0,0,0,0
0,0,0,0,0,0,0,0,0,0,0,0,0,0,7,0,7,0,0,0,0,0,0,0,0,0,0,0,0,0,0
0,0,0,0,0,0,0,0,0,0,0,0,0,0,7,7,7,0,0,0,0,0,0,0,0,0,0,0,0,0,0
0,0,0,0,0,0,0,0,0,0,0,0,0,0,10,11,9,0,0,0,0,0,0,0,0,0,0,0,0,0,0
0,0,0,0,0,0,0,0,0,0,0,0,0,0,10,64,9,0,0,0,0,0,0,0,0,0,0,0,0,0,0
0,0,0,0,0,0,0,0,0,0,0,0,0,0,0,0,0,0,0,0,0,0,0,0,0,0,0,0,0,0,0
0,0,0,0,0,0,0,0,0,0,0,0,0,0,0,0,0,0,0,0,0,0,0,0,0,0,0,0,0,0,0
0,0,0,0,0,0,0,0,0,0,0,0,0,0,0,0,0,0,0,0,0,0,0,0,0,0,0,0,0,0,0
0,0,0,0,0,0,0,0,0,0,0,0,0,0,0,0,0,0,0,0,0,0,0,0,0,0,0,0,0,0,0
0,0,0,0,0,0,0,0,0,0,0,0,0,0,0,0,0,0,0,0,0,0,0,0,0,0,0,0,0,0,0
0,0,0,0,0,0,0,0,0,0,0,0,0,0,0,0,0,0,0,0,0,0,0,0,0,0,0,0,0,0,0
0,0,0,0,0,0,0,0,0,0,0,0,0,0,0,0,0,0,0,0,0,0,0,0,0,0,0,0,0,0,0
0,0,0,0,0,0,0,0,0,0,0,0,0,0,0,0,0,0,0,0,0,0,0,0,0,0,0,0,0,0,0
0,0,0,0,0,0,0,0,0,0,0,0,0,0,0,0,0,0,0,0,0,0,0,0,0,0,0,0,0,0,0
0,0,0,0,0,0,0,0,0,0,0,0,0,0,0,0,0,0,0,0,0,0,0,0,0,0,0,0,0,0,0
0,0,0,0,0,0,0,0,0,0,0,0,0,0,0,0,0,0,0,0,0,0,0,0,0,0,0,0,0,0,0
0,0,0,0,0,0,0,0,0,0,0,0,0,0,0,0,0,0,0,0,0,0,0,0,0,0,0,0,0,0,0
0,0,0,0,0,0,0,0,0,0,0,0,0,0,0,0,0,0,0,0,0,0,0,0,0,0,0,0,0,0,0
0,0,0,0,0,0,0,0,0,0,0,0,0,0,0,0,0,0,0,0,0,0,0,0,0,0,0,0,0,0,0
0,0,0,0,0,0,0,0,0,0,0,0,0,0,0,0,0,0,0,0,0,0,0,0,0,0,0,0,0,0,0
0,0,0,0,0,0,0,0,0,0,0,0,0,0,0,0,0,0,0,0,0,0,0,0,0,0,0,0,0,0,0
0,0,0,0,0,0,0,0,0,0,0,0,0,0,0,0,0,0,0,0,0,0,0,0,0,0,0,0,0,0,0
:endlayer
layer: 32
0,0,0,0,0,0,0,0,0,0,0,0,0,0,0,0,0,0,0,0,0,0,0,0,0,0,0,0,0,0,0
0,0,0,0,0,0,0,0,0,0,0,0,0,0,0,0,0,0,0,0,0,0,0,0,0,0,0,0,0,0,0
0,0,0,0,0,0,0,0,0,0,0,0,0,0,0,0,0,0,0,0,0,0,0,0,0,0,0,0,0,0,0
0,0,0,0,0,0,0,0,0,0,0,0,0,0,0,0,0,0,0,0,0,0,0,0,0,0,0,0,0,0,0
0,0,0,0,0,0,0,0,0,0,0,0,0,0,0,0,0,0,0,0,0,0,0,0,0,0,0,0,0,0,0
0,0,0,0,0,0,0,0,0,0,0,0,0,0,0,0,0,0,0,0,0,0,0,0,0,0,0,0,0,0,0
0,0,0,0,0,0,0,0,0,0,0,0,0,0,0,0,0,0,0,0,0,0,0,0,0,0,0,0,0,0,0
0,0,0,0,0,0,0,0,0,0,0,0,0,0,0,0,0,0,0,0,0,0,0,0,0,0,0,0,0,0,0
0,0,0,0,0,0,0,0,0,0,0,0,0,0,0,0,0,0,0,0,0,0,0,0,0,0,0,0,0,0,0
0,0,0,0,0,0,0,0,0,0,0,0,0,0,0,0,0,0,0,0,0,0,0,0,0,0,0,0,0,0,0
0,0,0,0,0,0,0,0,0,0,0,0,0,0,0,0,0,0,0,0,0,0,0,0,0,0,0,0,0,0,0
0,0,0,0,0,0,0,0,0,0,0,0,0,0,0,0,0,0,0,0,0,0,0,0,0,0,0,0,0,0,0
0,0,0,0,0,0,0,0,0,0,0,0,0,0,0,0,0,0,0,0,0,0,0,0,0,0,0,0,0,0,0
0,0,0,0,0,0,0,0,0,0,0,0,0,0,0,0,0,0,0,0,0,0,0,0,0,0,0,0,0,0,0
0,0,0,0,0,0,0,0,0,0,0,0,0,0,0,0,0,0,0,0,0,0,0,0,0,0,0,0,0,0,0
0,0,0,0,0,0,0,0,0,0,0,0,0,0,0,0,0,0,0,0,0,0,0,0,0,0,0,0,0,0,0
0,0,0,0,0,0,0,0,0,0,0,0,0,0,0,0,0,0,0,0,0,0,0,0,0,0,0,0,0,0,0
0,0,0,0,0,0,0,0,0,0,0,0,0,0,0,0,0,0,0,0,0,0,0,0,0,0,0,0,0,0,0
0,0,0,0,0,0,0,0,0,0,0,0,0,0,0,0,0,0,0,0,0,0,0,0,0,0,0,0,0,0,0
0,0,0,0,0,0,0,0,0,0,0,0,0,0,0,0,0,0,0,0,0,0,0,0,0,0,0,0,0,0,0
0,0,0,0,0,0,0,0,0,0,0,0,0,0,0,0,0,0,0,0,0,0,0,0,0,0,0,0,0,0,0
0,0,0,0,0,0,0,0,0,0,0,0,0,0,0,54,0,0,0,0,0,0,0,0,0,0,0,0,0,0,0
0,0,0,0,0,0,0,0,0,0,0,0,0,0,0,54,0,0,0,0,0,0,0,0,0,0,0,0,0,0,0
0,0,0,0,0,0,0,0,0,0,0,0,0,0,7,7,7,0,0,0,0,0,0,0,0,0,0,0,0,0,0
0,0,0,0,0,0,0,0,0,0,0,0,0,0,7,0,7,0,0,0,0,0,0,0,0,0,0,0,0,0,0
0,0,0,0,0,0,0,0,0,0,0,0,0,0,7,7,7,0,0,0,0,0,0,0,0,0,0,0,0,0,0
0,0,0,0,0,0,0,0,0,0,0,0,0,0,0,54,0,0,0,0,0,0,0,0,0,0,0,0,0,0,0
0,0,0,0,0,0,0,0,0,0,0,0,0,0,0,54,0,0,0,0,0,0,0,0,0,0,0,0,0,0,0
0,0,0,0,0,0,0,0,0,0,0,0,0,0,0,0,0,0,0,0,0,0,0,0,0,0,0,0,0,0,0
0,0,0,0,0,0,0,0,0,0,0,0,0,0,0,0,0,0,0,0,0,0,0,0,0,0,0,0,0,0,0
0,0,0,0,0,0,0,0,0,0,0,0,0,0,0,0,0,0,0,0,0,0,0,0,0,0,0,0,0,0,0
0,0,0,0,0,0,0,0,0,0,0,0,0,0,0,0,0,0,0,0,0,0,0,0,0,0,0,0,0,0,0
0,0,0,0,0,0,0,0,0,0,0,0,0,0,0,0,0,0,0,0,0,0,0,0,0,0,0,0,0,0,0
0,0,0,0,0,0,0,0,0,0,0,0,0,0,0,0,0,0,0,0,0,0,0,0,0,0,0,0,0,0,0
0,0,0,0,0,0,0,0,0,0,0,0,0,0,0,0,0,0,0,0,0,0,0,0,0,0,0,0,0,0,0
0,0,0,0,0,0,0,0,0,0,0,0,0,0,0,0,0,0,0,0,0,0,0,0,0,0,0,0,0,0,0
0,0,0,0,0,0,0,0,0,0,0,0,0,0,0,0,0,0,0,0,0,0,0,0,0,0,0,0,0,0,0
0,0,0,0,0,0,0,0,0,0,0,0,0,0,0,0,0,0,0,0,0,0,0,0,0,0,0,0,0,0,0
0,0,0,0,0,0,0,0,0,0,0,0,0,0,0,0,0,0,0,0,0,0,0,0,0,0,0,0,0,0,0
0,0,0,0,0,0,0,0,0,0,0,0,0,0,0,0,0,0,0,0,0,0,0,0,0,0,0,0,0,0,0
0,0,0,0,0,0,0,0,0,0,0,0,0,0,0,0,0,0,0,0,0,0,0,0,0,0,0,0,0,0,0
0,0,0,0,0,0,0,0,0,0,0,0,0,0,0,0,0,0,0,0,0,0,0,0,0,0,0,0,0,0,0
0,0,0,0,0,0,0,0,0,0,0,0,0,0,0,0,0,0,0,0,0,0,0,0,0,0,0,0,0,0,0
0,0,0,0,0,0,0,0,0,0,0,0,0,0,0,0,0,0,0,0,0,0,0,0,0,0,0,0,0,0,0
0,0,0,0,0,0,0,0,0,0,0,0,0,0,0,0,0,0,0,0,0,0,0,0,0,0,0,0,0,0,0
:endlayer
layer: 33
0,0,0,0,0,0,0,0,0,0,0,0,0,0,0,0,0,0,0,0,0,0,0,0,0,0,0,0,0,0,0
0,0,0,0,0,0,0,0,0,0,0,0,0,0,0,0,0,0,0,0,0,0,0,0,0,0,0,0,0,0,0
0,0,0,0,0,0,0,0,0,0,0,0,0,0,0,0,0,0,0,0,0,0,0,0,0,0,0,0,0,0,0
0,0,0,0,0,0,0,0,0,0,0,0,0,0,0,0,0,0,0,0,0,0,0,0,0,0,0,0,0,0,0
0,0,0,0,0,0,0,0,0,0,0,0,0,0,0,0,0,0,0,0,0,0,0,0,0,0,0,0,0,0,0
0,0,0,0,0,0,0,0,0,0,0,0,0,0,0,0,0,0,0,0,0,0,0,0,0,0,0,0,0,0,0
0,0,0,0,0,0,0,0,0,0,0,0,0,0,0,0,0,0,0,0,0,0,0,0,0,0,0,0,0,0,0
0,0,0,0,0,0,0,0,0,0,0,0,0,0,0,0,0,0,0,0,0,0,0,0,0,0,0,0,0,0,0
0,0,0,0,0,0,0,0,0,0,0,0,0,0,0,0,0,0,0,0,0,0,0,0,0,0,0,0,0,0,0
0,0,0,0,0,0,0,0,0,0,0,0,0,0,0,0,0,0,0,0,0,0,0,0,0,0,0,0,0,0,0
0,0,0,0,0,0,0,0,0,0,0,0,0,0,0,0,0,0,0,0,0,0,0,0,0,0,0,0,0,0,0
0,0,0,0,0,0,0,0,0,0,0,0,0,0,0,0,0,0,0,0,0,0,0,0,0,0,0,0,0,0,0
0,0,0,0,0,0,0,0,0,0,0,0,0,0,0,0,0,0,0,0,0,0,0,0,0,0,0,0,0,0,0
0,0,0,0,0,0,0,0,0,0,0,0,0,0,0,0,0,0,0,0,0,0,0,0,0,0,0,0,0,0,0
0,0,0,0,0,0,0,0,0,0,0,0,0,0,0,0,0,0,0,0,0,0,0,0,0,0,0,0,0,0,0
0,0,0,0,0,0,0,0,0,0,0,0,0,0,0,0,0,0,0,0,0,0,0,0,0,0,0,0,0,0,0
0,0,0,0,0,0,0,0,0,0,0,0,0,0,0,0,0,0,0,0,0,0,0,0,0,0,0,0,0,0,0
0,0,0,0,0,0,0,0,0,0,0,0,0,0,0,0,0,0,0,0,0,0,0,0,0,0,0,0,0,0,0
0,0,0,0,0,0,0,0,0,0,0,0,0,0,0,0,0,0,0,0,0,0,0,0,0,0,0,0,0,0,0
0,0,0,0,0,0,0,0,0,0,0,0,0,0,0,0,0,0,0,0,0,0,0,0,0,0,0,0,0,0,0
0,0,0,0,0,0,0,0,0,0,0,0,0,0,0,0,0,0,0,0,0,0,0,0,0,0,0,0,0,0,0
0,0,0,0,0,0,0,0,0,0,0,0,0,0,0,0,0,0,0,0,0,0,0,0,0,0,0,0,0,0,0
0,0,0,0,0,0,0,0,0,0,0,0,0,0,0,0,0,0,0,0,0,0,0,0,0,0,0,0,0,0,0
0,0,0,0,0,0,0,0,0,0,0,0,0,0,12,63,12,0,0,0,0,0,0,0,0,0,0,0,0,0,0
0,0,0,0,0,0,0,0,0,0,0,0,0,0,63,0,63,0,0,0,0,0,0,0,0,0,0,0,0,0,0
0,0,0,0,0,0,0,0,0,0,0,0,0,0,13,63,13,0,0,0,0,0,0,0,0,0,0,0,0,0,0
0,0,0,0,0,0,0,0,0,0,0,0,0,0,0,0,0,0,0,0,0,0,0,0,0,0,0,0,0,0,0
0,0,0,0,0,0,0,0,0,0,0,0,0,0,0,0,0,0,0,0,0,0,0,0,0,0,0,0,0,0,0
0,0,0,0,0,0,0,0,0,0,0,0,0,0,0,0,0,0,0,0,0,0,0,0,0,0,0,0,0,0,0
0,0,0,0,0,0,0,0,0,0,0,0,0,0,0,0,0,0,0,0,0,0,0,0,0,0,0,0,0,0,0
0,0,0,0,0,0,0,0,0,0,0,0,0,0,0,0,0,0,0,0,0,0,0,0,0,0,0,0,0,0,0
0,0,0,0,0,0,0,0,0,0,0,0,0,0,0,0,0,0,0,0,0,0,0,0,0,0,0,0,0,0,0
0,0,0,0,0,0,0,0,0,0,0,0,0,0,0,0,0,0,0,0,0,0,0,0,0,0,0,0,0,0,0
0,0,0,0,0,0,0,0,0,0,0,0,0,0,0,0,0,0,0,0,0,0,0,0,0,0,0,0,0,0,0
0,0,0,0,0,0,0,0,0,0,0,0,0,0,0,0,0,0,0,0,0,0,0,0,0,0,0,0,0,0,0
0,0,0,0,0,0,0,0,0,0,0,0,0,0,0,0,0,0,0,0,0,0,0,0,0,0,0,0,0,0,0
0,0,0,0,0,0,0,0,0,0,0,0,0,0,0,0,0,0,0,0,0,0,0,0,0,0,0,0,0,0,0
