# Ancient Warfare Structure Template File
# auto-generated structure file. created on: 4/14/2014 at: 18:0:11
# Lines beginning with # denote comments

header:
version=2.0
name=CivResourcesBlacksmithSmallMOH
size=18,22,14
offset=7,6,12
:endheader

#### VALIDATION ####
validation:
type=ground
survival=false
worldGenEnabled=true
unique=false
preserveBlocks=false
selectionWeight=10
clusterValue=10
minDuplicateDistance=40
dimensionWhiteList=false
dimensionList=
biomeWhiteList=true
biomeList=highlands.meadow,bop.meadow,ebxl.meadow,field,orchard
leveling=9
fill=5
border=5
validTargetBlocks=clay,sand,lapis_ore,grass,lit_redstone_ore,stone,iron_ore,gravel,diamond_ore,stained_hardened_clay,dirt,coal_ore,redstone_ore,gold_ore
data:
:enddata
:endvalidation

#### LAYERS ####
layer: 0
1,1,1,1,1,1,1,1,1,1,1,1,1,1,4,4,1,1
1,1,1,1,1,1,1,1,1,1,1,1,1,4,4,4,1,1
1,1,1,1,1,1,1,1,1,1,1,1,1,4,4,4,1,1
1,1,1,1,1,1,1,1,1,1,1,1,1,1,4,1,1,1
1,1,1,1,1,1,1,1,1,1,1,1,1,1,1,1,1,1
1,1,1,1,1,1,1,1,1,1,1,1,1,1,1,1,1,1
1,1,1,1,1,1,1,1,1,1,1,1,1,1,1,1,1,1
1,1,3,1,1,1,1,1,1,1,1,1,1,1,1,1,0,1
2,1,3,3,1,1,1,1,1,1,1,1,1,1,1,1,1,1
2,2,3,3,1,1,1,1,1,1,1,1,1,1,1,1,1,1
2,2,2,1,1,1,0,1,1,1,1,1,1,1,1,1,1,1
2,2,1,1,1,1,1,0,1,1,1,1,1,1,1,1,1,1
1,1,1,1,1,1,1,1,1,1,1,1,1,1,1,1,1,1
1,1,1,1,1,1,1,1,1,1,1,1,1,1,1,5,5,5
:endlayer
layer: 1
2,2,2,2,2,2,2,2,2,2,2,2,2,2,2,2,2,2
2,1,1,1,1,1,1,1,1,1,1,1,1,1,1,1,1,2
2,1,1,1,1,1,1,1,1,1,1,1,1,1,1,1,1,2
2,2,2,2,1,6,6,6,6,1,1,1,1,1,1,1,1,2
2,2,2,2,1,1,1,1,1,1,1,1,1,1,1,1,1,2
2,2,2,2,1,1,1,1,1,1,1,1,1,1,1,7,1,2
2,2,2,2,1,1,1,1,1,1,1,1,1,1,7,7,1,2
2,2,2,2,1,1,6,6,6,6,1,6,6,6,1,1,1,2
2,2,2,2,1,1,6,6,6,6,6,6,6,6,1,1,1,2
2,2,2,2,1,1,6,6,6,6,0,6,6,6,1,1,1,2
2,2,2,2,1,0,0,0,0,0,0,0,7,5,7,7,1,2
2,1,1,1,1,1,1,1,1,1,1,1,1,1,1,1,1,2
2,1,1,1,1,1,1,1,1,1,1,1,1,1,1,1,1,2
2,2,2,2,2,2,2,2,2,2,2,2,2,2,2,2,2,2
:endlayer
layer: 2
2,2,2,2,2,2,2,2,2,2,2,2,2,2,2,2,2,2
2,1,1,1,1,1,1,1,1,1,1,1,1,1,1,1,1,2
2,1,1,1,1,1,1,1,1,1,1,1,1,1,1,1,1,2
2,2,2,2,1,2,6,6,6,1,6,1,6,1,1,1,1,2
2,2,2,2,1,1,12,0,0,0,6,0,0,0,6,1,1,2
2,2,2,2,1,1,11,0,0,0,0,0,0,0,6,7,1,2
2,2,2,2,1,1,8,0,0,8,1,0,0,0,6,7,1,2
2,2,2,2,1,1,10,0,0,16,6,0,6,17,6,7,1,2
2,2,2,2,1,1,9,0,0,15,6,0,0,6,6,7,1,2
2,2,2,2,7,1,8,13,14,8,6,0,0,6,6,1,1,2
2,2,2,2,7,0,6,6,6,6,7,6,6,6,7,7,1,2
2,1,1,1,1,1,1,1,1,1,1,1,1,1,1,1,1,2
2,1,1,1,1,1,1,1,1,1,1,1,1,1,1,1,1,2
2,2,2,2,2,2,2,2,2,2,2,2,2,2,2,2,2,2
:endlayer
layer: 3
2,2,2,2,2,2,2,2,2,2,2,2,2,2,2,2,2,2
2,1,1,1,1,1,1,1,1,1,1,1,1,1,1,1,1,2
2,1,1,1,1,1,1,1,1,1,1,1,1,1,1,1,1,2
2,2,2,2,1,1,1,1,1,1,6,6,6,1,7,7,1,2
2,2,2,2,1,1,0,0,0,0,6,0,20,0,6,7,1,2
2,2,2,2,1,1,18,0,0,0,0,0,0,0,6,7,1,2
2,2,2,2,1,6,0,0,0,0,1,0,0,0,6,7,1,2
2,2,2,2,7,1,0,0,0,0,6,0,6,0,6,7,1,2
2,2,2,2,1,1,18,0,0,0,6,0,0,17,6,7,1,2
2,2,2,2,7,6,0,0,0,0,6,0,19,6,6,7,1,2
2,2,2,2,7,1,6,6,6,6,7,6,6,6,7,7,1,2
2,1,1,1,1,1,1,1,1,1,1,1,1,1,1,1,1,2
2,1,1,1,1,1,1,1,1,1,1,1,1,1,1,1,1,2
2,2,2,2,2,2,2,2,2,2,2,2,2,2,2,2,2,2
:endlayer
layer: 4
2,2,2,2,2,2,2,2,2,2,2,2,2,2,2,2,2,2
2,1,1,1,1,1,1,1,1,1,1,1,1,1,1,1,1,2
2,1,1,1,1,1,1,1,1,1,1,1,1,1,1,1,1,2
2,2,2,2,1,7,6,1,1,1,6,6,6,6,7,7,1,2
2,2,2,2,1,6,0,0,0,0,6,0,0,0,6,21,1,2
2,2,2,2,2,6,0,0,0,0,6,0,0,0,6,21,1,2
2,2,2,2,7,6,0,0,0,0,1,0,0,0,6,21,1,2
2,2,2,2,7,6,0,0,0,0,6,6,6,0,6,21,1,2
2,2,2,2,1,6,0,0,0,0,6,6,6,0,6,21,1,2
2,2,2,2,7,6,0,0,0,0,6,6,22,0,6,6,1,2
2,2,2,2,7,1,6,6,6,6,21,6,6,6,21,21,1,2
2,1,1,1,1,1,1,1,1,1,1,1,1,1,1,1,1,2
2,1,1,1,1,1,1,1,1,1,1,1,1,1,1,1,1,2
2,2,2,2,2,2,2,2,2,2,2,2,2,2,2,2,2,2
:endlayer
layer: 5
23,23,23,23,23,23,23,23,5,23,23,23,23,23,23,23,23,23
23,23,23,23,23,23,23,23,5,23,23,23,23,23,23,23,23,23
23,23,6,6,6,6,6,6,6,6,6,6,6,6,6,6,23,23
23,2,6,6,6,2,6,6,6,6,2,2,6,2,2,6,23,23
23,23,6,6,6,6,6,6,6,6,2,6,6,6,2,6,23,23
23,23,6,6,6,6,6,6,6,6,2,6,6,6,2,6,23,23
23,23,6,6,6,6,6,6,6,6,6,6,6,6,24,6,23,23
23,23,6,6,6,6,6,6,6,6,6,6,6,0,6,6,23,23
23,23,6,6,6,6,6,6,6,6,6,25,6,0,6,6,23,23
23,23,6,6,6,6,6,6,6,6,6,0,0,0,6,6,23,23
23,2,6,6,6,2,6,6,6,6,24,6,6,6,24,6,23,23
23,23,6,6,6,6,6,6,6,6,6,6,6,6,6,6,23,23
23,23,23,23,23,23,23,23,5,23,23,23,23,23,23,23,23,23
23,23,23,23,23,23,23,23,5,23,23,23,23,23,23,23,23,23
:endlayer
layer: 6
0,0,0,0,0,0,0,0,0,0,0,0,0,0,0,0,0,0
0,26,26,26,26,26,26,26,39,26,26,26,26,26,26,26,26,0
0,26,0,0,0,0,0,0,0,0,0,0,0,0,0,0,26,0
0,27,0,0,0,27,33,33,0,0,24,27,27,27,24,0,26,0
0,26,0,0,0,28,32,36,0,0,27,0,42,0,27,0,26,0
0,26,0,0,0,27,6,37,0,0,27,0,0,0,27,0,26,0
0,26,0,0,0,30,31,36,0,0,41,0,0,0,27,0,26,0
0,26,0,0,0,29,31,36,0,0,40,0,0,17,27,0,26,0
0,26,0,0,0,27,6,35,0,0,27,0,6,0,27,0,26,0
0,26,0,0,0,28,0,0,0,0,27,0,0,0,27,0,26,0
0,27,0,0,0,27,0,34,0,0,24,27,27,27,24,0,26,0
0,26,0,0,0,0,0,0,0,0,0,0,0,0,0,0,26,0
0,26,26,26,26,26,26,26,38,26,26,26,26,26,26,26,26,0
0,0,0,0,0,0,0,0,0,0,0,0,0,0,0,0,0,0
:endlayer
layer: 7
0,0,0,0,0,0,0,0,0,0,0,0,0,0,0,0,0,0
0,0,0,0,0,0,0,0,0,0,0,0,0,0,0,0,0,0
0,0,0,0,0,0,0,0,0,0,47,0,0,0,47,0,0,0
0,27,0,0,0,27,0,0,0,0,24,27,48,27,24,0,0,0
0,0,0,0,0,0,0,0,0,0,27,0,0,0,27,18,0,0
0,0,0,0,19,27,27,44,0,0,27,0,0,0,27,0,0,0
0,0,0,0,0,0,0,0,0,0,46,0,0,0,48,0,0,0
0,0,0,0,0,0,0,0,0,0,45,0,0,0,48,0,0,0
0,0,0,0,19,27,27,43,0,0,27,0,6,17,27,0,0,0
0,0,0,0,0,0,0,0,0,0,27,0,0,6,27,18,0,0
0,27,0,0,0,27,0,0,0,0,24,27,48,27,24,0,0,0
0,0,0,0,0,0,0,0,0,0,20,0,0,0,20,0,0,0
0,0,0,0,0,0,0,0,0,0,0,0,0,0,0,0,0,0
0,0,0,0,0,0,0,0,0,0,0,0,0,0,0,0,0,0
:endlayer
layer: 8
0,0,0,0,0,0,0,0,0,0,0,0,0,0,0,0,0,0
0,0,0,0,0,0,0,0,0,0,0,0,0,0,0,0,0,0
0,0,0,0,0,0,0,0,0,0,0,0,0,0,0,0,0,0
0,27,0,0,0,27,0,0,0,0,24,27,27,27,24,0,0,0
0,0,0,0,0,0,0,0,0,0,27,0,0,19,27,0,0,0
0,0,0,0,0,28,33,33,0,0,27,18,0,0,27,0,0,0
0,0,0,0,0,28,0,36,0,19,27,0,0,0,27,0,0,0
0,0,0,0,0,28,0,36,0,19,27,0,0,0,27,0,0,0
0,0,0,0,0,28,49,49,0,0,27,0,6,0,27,0,0,0
0,0,0,0,0,0,0,0,0,0,27,18,22,0,27,0,0,0
0,27,0,0,0,27,0,0,0,0,24,27,27,27,24,0,0,0
0,0,0,0,0,0,0,0,0,0,0,0,0,0,0,0,0,0
0,0,0,0,0,0,0,0,0,0,0,0,0,0,0,0,0,0
0,0,0,0,0,0,0,0,0,0,0,0,0,0,0,0,0,0
:endlayer
layer: 9
0,0,0,0,0,0,0,0,0,0,0,0,0,0,0,0,0,0
0,0,0,0,0,0,0,0,0,0,0,0,0,0,0,0,0,0
0,47,0,0,0,47,0,0,0,0,0,0,0,0,0,50,0,0
0,27,18,0,19,27,27,27,27,27,24,24,24,24,24,50,0,0
0,20,0,0,0,0,27,6,6,6,6,6,6,6,24,50,0,0
0,0,0,0,0,0,27,6,6,6,6,6,6,6,24,50,0,0
0,0,0,0,0,0,27,6,6,6,6,6,6,6,24,50,0,0
0,0,0,0,0,0,27,6,6,6,6,6,6,0,24,50,0,0
0,0,0,0,0,0,27,6,6,6,6,6,6,0,24,50,0,0
0,47,0,0,0,0,27,6,6,6,6,22,0,0,24,50,0,0
0,27,0,0,19,27,27,27,27,27,24,24,24,24,24,50,0,0
0,20,0,0,0,20,0,0,0,0,0,0,0,0,0,50,0,0
0,0,0,0,0,0,0,0,0,0,0,0,0,0,0,0,0,0
0,0,0,0,0,0,0,0,0,0,0,0,0,0,0,0,0,0
:endlayer
layer: 10
0,0,0,0,0,0,0,0,0,0,0,0,0,0,0,0,0,0
0,0,0,0,0,0,0,0,0,0,0,0,0,0,0,0,0,0
0,51,51,51,51,28,0,0,0,0,0,0,0,0,50,0,0,0
0,27,51,51,51,28,27,27,27,27,27,27,27,27,50,0,0,0
0,51,51,51,51,28,27,54,0,56,0,0,58,0,50,0,0,0
0,51,51,51,51,28,27,0,0,0,0,0,57,0,50,0,0,0
0,51,51,51,51,28,27,53,55,0,0,0,26,26,50,0,0,0
0,51,51,51,51,28,27,53,55,0,0,0,26,0,50,0,0,0
0,51,51,51,51,28,27,0,0,0,0,26,26,0,50,0,0,0
0,51,51,51,51,28,27,52,0,0,0,0,0,0,50,0,0,0
0,27,51,51,51,28,27,27,27,27,27,27,27,27,50,0,0,0
0,51,51,51,51,28,0,0,0,0,0,0,0,0,50,0,0,0
0,0,0,0,0,0,0,0,0,0,0,0,0,0,0,0,0,0
0,0,0,0,0,0,0,0,0,0,0,0,0,0,0,0,0,0
:endlayer
layer: 11
0,0,0,0,0,0,0,0,0,0,0,0,0,0,0,0,0,0
0,0,0,0,0,0,0,0,0,0,0,0,0,0,0,0,0,0
0,0,0,0,0,0,60,0,0,0,0,0,0,50,0,0,0,0
0,59,0,0,0,0,60,27,27,48,48,27,27,50,0,0,0,0
0,0,0,0,0,0,60,20,0,0,0,0,0,50,0,0,0,0
0,0,0,0,0,0,60,0,0,0,0,0,0,50,0,0,0,0
0,0,0,0,0,0,27,0,0,0,0,0,0,50,0,0,0,0
0,0,0,0,0,0,27,0,0,0,0,0,0,50,0,0,0,0
0,0,0,0,0,0,60,0,0,0,0,0,0,50,0,0,0,0
0,0,0,0,0,0,60,47,0,0,0,0,47,50,0,0,0,0
0,59,0,0,0,0,60,27,27,48,48,27,27,50,0,0,0,0
0,0,0,0,0,0,60,0,0,0,0,0,0,50,0,0,0,0
0,0,0,0,0,0,0,0,0,0,0,0,0,0,0,0,0,0
0,0,0,0,0,0,0,0,0,0,0,0,0,0,0,0,0,0
:endlayer
layer: 12
0,0,0,0,0,0,0,0,0,0,0,0,0,0,0,0,0,0
0,0,0,0,0,0,0,0,0,0,0,0,0,0,0,0,0,0
0,0,0,0,0,0,0,60,0,47,47,0,50,0,0,0,0,0
0,0,0,0,0,0,0,60,27,27,27,27,50,0,0,0,0,0
0,0,0,0,0,0,0,60,0,0,0,20,50,0,0,0,0,0
0,0,0,0,0,0,0,60,0,0,0,0,50,0,0,0,0,0
0,0,0,0,0,0,27,8,0,0,0,0,50,0,0,0,0,0
0,0,0,0,0,0,27,8,0,0,0,0,50,0,0,0,0,0
0,0,0,0,0,0,0,60,0,0,0,0,50,0,0,0,0,0
0,0,0,0,0,0,0,60,0,0,0,0,50,0,0,0,0,0
0,0,0,0,0,0,0,60,27,27,27,27,50,0,0,0,0,0
0,0,0,0,0,0,0,60,0,20,20,0,50,0,0,0,0,0
0,0,0,0,0,0,0,0,0,0,0,0,0,0,0,0,0,0
0,0,0,0,0,0,0,0,0,0,0,0,0,0,0,0,0,0
:endlayer
layer: 13
0,0,0,0,0,0,0,0,0,0,0,0,0,0,0,0,0,0
0,0,0,0,0,0,0,0,0,0,0,0,0,0,0,0,0,0
0,0,0,0,0,0,0,0,61,60,50,61,0,0,0,0,0,0
0,0,0,0,0,0,0,0,61,60,50,61,0,0,0,0,0,0
0,0,0,0,0,0,0,0,61,60,50,61,0,0,0,0,0,0
0,0,0,0,0,0,0,0,61,60,50,61,0,0,0,0,0,0
0,0,0,0,0,19,27,59,61,60,50,61,0,0,0,0,0,0
0,0,0,0,0,19,27,59,61,60,50,61,0,0,0,0,0,0
0,0,0,0,0,0,0,0,61,60,50,61,0,0,0,0,0,0
0,0,0,0,0,0,0,0,61,60,50,61,0,0,0,0,0,0
0,0,0,0,0,0,0,0,61,60,50,61,0,0,0,0,0,0
0,0,0,0,0,0,0,0,61,60,50,61,0,0,0,0,0,0
0,0,0,0,0,0,0,0,0,0,0,0,0,0,0,0,0,0
0,0,0,0,0,0,0,0,0,0,0,0,0,0,0,0,0,0
:endlayer
layer: 14
0,0,0,0,0,0,0,0,0,0,0,0,0,0,0,0,0,0
0,0,0,0,0,0,0,0,0,0,0,0,0,0,0,0,0,0
0,0,0,0,0,0,0,0,0,0,0,0,0,0,0,0,0,0
0,0,0,0,0,0,0,0,0,0,0,0,0,0,0,0,0,0
0,0,0,0,0,0,0,0,0,0,0,0,0,0,0,0,0,0
0,0,0,0,0,0,0,0,0,0,0,0,0,0,0,0,0,0
0,0,0,0,0,0,27,0,0,0,0,0,0,0,0,0,0,0
0,0,0,0,0,0,27,0,0,0,0,0,0,0,0,0,0,0
0,0,0,0,0,0,0,0,0,0,0,0,0,0,0,0,0,0
0,0,0,0,0,0,0,0,0,0,0,0,0,0,0,0,0,0
0,0,0,0,0,0,0,0,0,0,0,0,0,0,0,0,0,0
0,0,0,0,0,0,0,0,0,0,0,0,0,0,0,0,0,0
0,0,0,0,0,0,0,0,0,0,0,0,0,0,0,0,0,0
0,0,0,0,0,0,0,0,0,0,0,0,0,0,0,0,0,0
:endlayer
layer: 15
0,0,0,0,0,0,0,0,0,0,0,0,0,0,0,0,0,0
0,0,0,0,0,0,0,0,0,0,0,0,0,0,0,0,0,0
0,0,0,0,0,0,0,0,0,0,0,0,0,0,0,0,0,0
0,0,0,0,0,0,0,0,0,0,0,0,0,0,0,0,0,0
0,0,0,0,0,0,0,0,0,0,0,0,0,0,0,0,0,0
0,0,0,0,0,0,0,0,0,0,0,0,0,0,0,0,0,0
0,0,0,0,0,0,0,0,0,0,0,0,0,0,0,0,0,0
0,0,0,0,0,0,62,0,0,0,0,0,0,0,0,0,0,0
0,0,0,0,0,0,0,0,0,0,0,0,0,0,0,0,0,0
0,0,0,0,0,0,0,0,0,0,0,0,0,0,0,0,0,0
0,0,0,0,0,0,0,0,0,0,0,0,0,0,0,0,0,0
0,0,0,0,0,0,0,0,0,0,0,0,0,0,0,0,0,0
0,0,0,0,0,0,0,0,0,0,0,0,0,0,0,0,0,0
0,0,0,0,0,0,0,0,0,0,0,0,0,0,0,0,0,0
:endlayer
layer: 16
0,0,0,0,0,0,0,0,0,0,0,0,0,0,0,0,0,0
0,0,0,0,0,0,0,0,0,0,0,0,0,0,0,0,0,0
0,0,0,0,0,0,0,0,0,0,0,0,0,0,0,0,0,0
0,0,0,0,0,0,0,0,0,0,0,0,0,0,0,0,0,0
0,0,0,0,0,0,0,0,0,0,0,0,0,0,0,0,0,0
0,0,0,0,0,0,0,0,0,0,0,0,0,0,0,0,0,0
0,0,0,0,0,0,0,0,0,0,0,0,0,0,0,0,0,0
0,0,0,0,0,0,0,0,0,0,0,0,0,0,0,0,0,0
0,0,0,0,0,0,0,0,0,0,0,0,0,0,0,0,0,0
0,0,0,0,0,0,0,0,0,0,0,0,0,0,0,0,0,0
0,0,0,0,0,0,0,0,0,0,0,0,0,0,0,0,0,0
0,0,0,0,0,0,0,0,0,0,0,0,0,0,0,0,0,0
0,0,0,0,0,0,0,0,0,0,0,0,0,0,0,0,0,0
0,0,0,0,0,0,0,0,0,0,0,0,0,0,0,0,0,0
:endlayer
layer: 17
0,0,0,0,0,0,0,0,0,0,0,0,0,0,0,0,0,0
0,0,0,0,0,0,0,0,0,0,0,0,0,0,0,0,0,0
0,0,0,0,0,0,0,0,0,0,0,0,0,0,0,0,0,0
0,0,0,0,0,0,0,0,0,0,0,0,0,0,0,0,0,0
0,0,0,0,0,0,0,0,0,0,0,0,0,0,0,0,0,0
0,0,0,0,0,0,0,0,0,0,0,0,0,0,0,0,0,0
0,0,0,0,0,0,0,0,0,0,0,0,0,0,0,0,0,0
0,0,0,0,0,0,0,0,0,0,0,0,0,0,0,0,0,0
0,0,0,0,0,0,0,0,0,0,0,0,0,0,0,0,0,0
0,0,0,0,0,0,0,0,0,0,0,0,0,0,0,0,0,0
0,0,0,0,0,0,0,0,0,0,0,0,0,0,0,0,0,0
0,0,0,0,0,0,0,0,0,0,0,0,0,0,0,0,0,0
0,0,0,0,0,0,0,0,0,0,0,0,0,0,0,0,0,0
0,0,0,0,0,0,0,0,0,0,0,0,0,0,0,0,0,0
:endlayer
layer: 18
0,0,0,0,0,0,0,0,0,0,0,0,0,0,0,0,0,0
0,0,0,0,0,0,0,0,0,0,0,0,0,0,0,0,0,0
0,0,0,0,0,0,0,0,0,0,0,0,0,0,0,0,0,0
0,0,0,0,0,0,0,0,0,0,0,0,0,0,0,0,0,0
0,0,0,0,0,0,0,0,0,0,0,0,0,0,0,0,0,0
0,0,0,0,0,0,0,0,0,0,0,0,0,0,0,0,0,0
0,0,0,0,0,0,0,0,0,0,0,0,0,0,0,0,0,0
0,0,0,0,0,0,0,0,0,0,0,0,0,0,0,0,0,0
0,0,0,0,0,0,0,0,0,0,0,0,0,0,0,0,0,0
0,0,0,0,0,0,0,0,0,0,0,0,0,0,0,0,0,0
0,0,0,0,0,0,0,0,0,0,0,0,0,0,0,0,0,0
0,0,0,0,0,0,0,0,0,0,0,0,0,0,0,0,0,0
0,0,0,0,0,0,0,0,0,0,0,0,0,0,0,0,0,0
0,0,0,0,0,0,0,0,0,0,0,0,0,0,0,0,0,0
:endlayer
layer: 19
0,0,0,0,0,0,0,0,0,0,0,0,0,0,0,0,0,0
0,0,0,0,0,0,0,0,0,0,0,0,0,0,0,0,0,0
0,0,0,0,0,0,0,0,0,0,0,0,0,0,0,0,0,0
0,0,0,0,0,0,0,0,0,0,0,0,0,0,0,0,0,0
0,0,0,0,0,0,0,0,0,0,0,0,0,0,0,0,0,0
0,0,0,0,0,0,0,0,0,0,0,0,0,0,0,0,0,0
0,0,0,0,0,0,0,0,0,0,0,0,0,0,0,0,0,0
0,0,0,0,0,0,0,0,0,0,0,0,0,0,0,0,0,0
0,0,0,0,0,0,0,0,0,0,0,0,0,0,0,0,0,0
0,0,0,0,0,0,0,0,0,0,0,0,0,0,0,0,0,0
0,0,0,0,0,0,0,0,0,0,0,0,0,0,0,0,0,0
0,0,0,0,0,0,0,0,0,0,0,0,0,0,0,0,0,0
0,0,0,0,0,0,0,0,0,0,0,0,0,0,0,0,0,0
0,0,0,0,0,0,0,0,0,0,0,0,0,0,0,0,0,0
:endlayer
layer: 20
0,0,0,0,0,0,0,0,0,0,0,0,0,0,0,0,0,0
0,0,0,0,0,0,0,0,0,0,0,0,0,0,0,0,0,0
0,0,0,0,0,0,0,0,0,0,0,0,0,0,0,0,0,0
0,0,0,0,0,0,0,0,0,0,0,0,0,0,0,0,0,0
0,0,0,0,0,0,0,0,0,0,0,0,0,0,0,0,0,0
0,0,0,0,0,0,0,0,0,0,0,0,0,0,0,0,0,0
0,0,0,0,0,0,0,0,0,0,0,0,0,0,0,0,0,0
0,0,0,0,0,0,0,0,0,0,0,0,0,0,0,0,0,0
0,0,0,0,0,0,0,0,0,0,0,0,0,0,0,0,0,0
0,0,0,0,0,0,0,0,0,0,0,0,0,0,0,0,0,0
0,0,0,0,0,0,0,0,0,0,0,0,0,0,0,0,0,0
0,0,0,0,0,0,0,0,0,0,0,0,0,0,0,0,0,0
0,0,0,0,0,0,0,0,0,0,0,0,0,0,0,0,0,0
0,0,0,0,0,0,0,0,0,0,0,0,0,0,0,0,0,0
:endlayer
layer: 21
0,0,0,0,0,0,0,0,0,0,0,0,0,0,0,0,0,0
0,0,0,0,0,0,0,0,0,0,0,0,0,0,0,0,0,0
0,0,0,0,0,0,0,0,0,0,0,0,0,0,0,0,0,0
0,0,0,0,0,0,0,0,0,0,0,0,0,0,0,0,0,0
0,0,0,0,0,0,0,0,0,0,0,0,0,0,0,0,0,0
0,0,0,0,0,0,0,0,0,0,0,0,0,0,0,0,0,0
0,0,0,0,0,0,0,0,0,0,0,0,0,0,0,0,0,0
0,0,0,0,0,0,0,0,0,0,0,0,0,0,0,0,0,0
0,0,0,0,0,0,0,0,0,0,0,0,0,0,0,0,0,0
0,0,0,0,0,0,0,0,0,0,0,0,0,0,0,0,0,0
0,0,0,0,0,0,0,0,0,0,0,0,0,0,0,0,0,0
0,0,0,0,0,0,0,0,0,0,0,0,0,0,0,0,0,0
0,0,0,0,0,0,0,0,0,0,0,0,0,0,0,0,0,0
0,0,0,0,0,0,0,0,0,0,0,0,0,0,0,0,0,0
:endlayer

#### RULES ####
rule:
plugin=vanillaBlocks
number=1
data:
tag:
TAG=10={
TAG=8=blockName{stone}
TAG=3=meta{0}
TAG=3=buildPass{0}
}
:endtag
:enddata
:endrule

rule:
plugin=vanillaBlocks
number=2
data:
tag:
TAG=10={
TAG=8=blockName{dirt}
TAG=3=meta{0}
TAG=3=buildPass{0}
}
:endtag
:enddata
:endrule

rule:
plugin=vanillaBlocks
number=3
data:
tag:
TAG=10={
TAG=8=blockName{iron_ore}
TAG=3=meta{0}
TAG=3=buildPass{0}
}
:endtag
:enddata
:endrule

rule:
plugin=vanillaBlocks
number=4
data:
tag:
TAG=10={
TAG=8=blockName{coal_ore}
TAG=3=meta{0}
TAG=3=buildPass{0}
}
:endtag
:enddata
:endrule

rule:
plugin=vanillaBlocks
number=5
data:
tag:
TAG=10={
TAG=8=blockName{gravel}
TAG=3=meta{0}
TAG=3=buildPass{1}
}
:endtag
:enddata
:endrule

rule:
plugin=vanillaBlocks
number=6
data:
tag:
TAG=10={
TAG=8=blockName{cobblestone}
TAG=3=meta{0}
TAG=3=buildPass{0}
}
:endtag
:enddata
:endrule

rule:
plugin=vanillaBlocks
number=7
data:
tag:
TAG=10={
TAG=8=blockName{sandstone}
TAG=3=meta{0}
TAG=3=buildPass{0}
}
:endtag
:enddata
:endrule

rule:
plugin=vanillaBlocks
number=8
data:
tag:
TAG=10={
TAG=8=blockName{planks}
TAG=3=meta{0}
TAG=3=buildPass{0}
}
:endtag
:enddata
:endrule

rule:
plugin=vanillaInventory
number=9
data:
tag:
TAG=10={
TAG=3=lootLevel{0}
TAG=10=teData{
TAG=9=Items{
TAG=10={
TAG=2=id{297}
TAG=2=Damage{0}
TAG=1=Count{1}
TAG=1=Slot{4}
}
}
TAG=8=id{Chest}
}
TAG=8=blockName{chest}
TAG=3=meta{5}
TAG=3=buildPass{0}
}
:endtag
:enddata
:endrule

rule:
plugin=vanillaInventory
number=10
data:
tag:
TAG=10={
TAG=3=lootLevel{0}
TAG=10=teData{
TAG=9=Items{
TAG=10={
TAG=2=id{287}
TAG=2=Damage{0}
TAG=1=Count{1}
TAG=1=Slot{8}
}
TAG=10={
TAG=2=id{265}
TAG=2=Damage{0}
TAG=1=Count{2}
TAG=1=Slot{17}
}
}
TAG=8=id{Chest}
}
TAG=8=blockName{chest}
TAG=3=meta{5}
TAG=3=buildPass{0}
}
:endtag
:enddata
:endrule

rule:
plugin=vanillaInventory
number=11
data:
tag:
TAG=10={
TAG=3=lootLevel{0}
TAG=10=teData{
TAG=9=Items{
TAG=10={
TAG=2=id{296}
TAG=2=Damage{0}
TAG=1=Count{1}
TAG=1=Slot{0}
}
TAG=10={
TAG=2=id{297}
TAG=2=Damage{0}
TAG=1=Count{1}
TAG=1=Slot{12}
}
TAG=10={
TAG=2=id{265}
TAG=2=Damage{0}
TAG=1=Count{1}
TAG=1=Slot{17}
}
TAG=10={
TAG=2=id{287}
TAG=2=Damage{0}
TAG=1=Count{1}
TAG=1=Slot{24}
}
}
TAG=8=id{Chest}
}
TAG=8=blockName{chest}
TAG=3=meta{5}
TAG=3=buildPass{0}
}
:endtag
:enddata
:endrule

rule:
plugin=vanillaInventory
number=12
data:
tag:
TAG=10={
TAG=3=lootLevel{0}
TAG=10=teData{
TAG=9=Items{
TAG=10={
TAG=2=id{325}
TAG=2=Damage{0}
TAG=1=Count{1}
TAG=1=Slot{8}
}
}
TAG=8=id{Chest}
}
TAG=8=blockName{chest}
TAG=3=meta{5}
TAG=3=buildPass{0}
}
:endtag
:enddata
:endrule

rule:
plugin=vanillaInventory
number=13
data:
tag:
TAG=10={
TAG=3=lootLevel{0}
TAG=10=teData{
TAG=9=Items{
TAG=10={
TAG=2=id{265}
TAG=2=Damage{0}
TAG=1=Count{1}
TAG=1=Slot{11}
}
TAG=10={
TAG=2=id{265}
TAG=2=Damage{0}
TAG=1=Count{2}
TAG=1=Slot{22}
}
}
TAG=8=id{Chest}
}
TAG=8=blockName{chest}
TAG=3=meta{2}
TAG=3=buildPass{0}
}
:endtag
:enddata
:endrule

rule:
plugin=vanillaInventory
number=14
data:
tag:
TAG=10={
TAG=3=lootLevel{0}
TAG=10=teData{
TAG=9=Items{
TAG=10={
TAG=2=id{403}
TAG=2=Damage{0}
TAG=1=Count{1}
TAG=10=tag{
TAG=9=StoredEnchantments{
TAG=10={
TAG=2=id{35}
TAG=2=lvl{2}
}
}
}
TAG=1=Slot{6}
}
TAG=10={
TAG=2=id{418}
TAG=2=Damage{0}
TAG=1=Count{1}
TAG=1=Slot{21}
}
}
TAG=8=id{Chest}
}
TAG=8=blockName{chest}
TAG=3=meta{2}
TAG=3=buildPass{0}
}
:endtag
:enddata
:endrule

rule:
plugin=vanillaInventory
number=15
data:
tag:
TAG=10={
TAG=3=lootLevel{0}
TAG=10=teData{
TAG=9=Items{
TAG=10={
TAG=2=id{421}
TAG=2=Damage{0}
TAG=1=Count{1}
TAG=1=Slot{0}
}
TAG=10={
TAG=2=id{289}
TAG=2=Damage{0}
TAG=1=Count{3}
TAG=1=Slot{14}
}
TAG=10={
TAG=2=id{289}
TAG=2=Damage{0}
TAG=1=Count{2}
TAG=1=Slot{23}
}
}
TAG=8=id{Chest}
}
TAG=8=blockName{chest}
TAG=3=meta{5}
TAG=3=buildPass{0}
}
:endtag
:enddata
:endrule

rule:
plugin=vanillaInventory
number=16
data:
tag:
TAG=10={
TAG=3=lootLevel{0}
TAG=10=teData{
TAG=9=Items{
}
TAG=8=id{Chest}
}
TAG=8=blockName{chest}
TAG=3=meta{5}
TAG=3=buildPass{0}
}
:endtag
:enddata
:endrule

rule:
plugin=vanillaBlocks
number=17
data:
tag:
TAG=10={
TAG=8=blockName{stone_stairs}
TAG=3=meta{2}
TAG=3=buildPass{0}
}
:endtag
:enddata
:endrule

rule:
plugin=vanillaBlocks
number=18
data:
tag:
TAG=10={
TAG=8=blockName{torch}
TAG=3=meta{1}
TAG=3=buildPass{1}
}
:endtag
:enddata
:endrule

rule:
plugin=vanillaBlocks
number=19
data:
tag:
TAG=10={
TAG=8=blockName{torch}
TAG=3=meta{2}
TAG=3=buildPass{1}
}
:endtag
:enddata
:endrule

rule:
plugin=vanillaBlocks
number=20
data:
tag:
TAG=10={
TAG=8=blockName{torch}
TAG=3=meta{3}
TAG=3=buildPass{1}
}
:endtag
:enddata
:endrule

rule:
plugin=vanillaBlocks
number=21
data:
tag:
TAG=10={
TAG=8=blockName{sand}
TAG=3=meta{0}
TAG=3=buildPass{1}
}
:endtag
:enddata
:endrule

rule:
plugin=vanillaBlocks
number=22
data:
tag:
TAG=10={
TAG=8=blockName{stone_stairs}
TAG=3=meta{1}
TAG=3=buildPass{0}
}
:endtag
:enddata
:endrule

rule:
plugin=vanillaBlocks
number=23
data:
tag:
TAG=10={
TAG=8=blockName{grass}
TAG=3=meta{0}
TAG=3=buildPass{0}
}
:endtag
:enddata
:endrule

rule:
plugin=vanillaBlocks
number=24
data:
tag:
TAG=10={
TAG=8=blockName{log}
TAG=3=meta{0}
TAG=3=buildPass{0}
}
:endtag
:enddata
:endrule

rule:
plugin=vanillaBlocks
number=25
data:
tag:
TAG=10={
TAG=8=blockName{stone_stairs}
TAG=3=meta{3}
TAG=3=buildPass{0}
}
:endtag
:enddata
:endrule

rule:
plugin=vanillaBlocks
number=26
data:
tag:
TAG=10={
TAG=8=blockName{fence}
TAG=3=meta{0}
TAG=3=buildPass{0}
}
:endtag
:enddata
:endrule

rule:
plugin=vanillaBlocks
number=27
data:
tag:
TAG=10={
TAG=8=blockName{stonebrick}
TAG=3=meta{0}
TAG=3=buildPass{0}
}
:endtag
:enddata
:endrule

rule:
plugin=vanillaBlocks
number=28
data:
tag:
TAG=10={
TAG=8=blockName{stone_brick_stairs}
TAG=3=meta{0}
TAG=3=buildPass{0}
}
:endtag
:enddata
:endrule

rule:
plugin=awAdvancedSpawner
number=29
data:
tag:
TAG=10={
TAG=10=teData{
TAG=9=Items{
}
TAG=8=id{Furnace}
TAG=2=BurnTime{0}
TAG=3=z{-99}
TAG=2=CookTime{0}
TAG=3=y{65}
TAG=3=x{272}
}
TAG=8=blockName{furnace}
TAG=3=meta{2}
TAG=3=buildPass{0}
}
:endtag
:enddata
:endrule

rule:
plugin=awAdvancedSpawner
number=30
data:
tag:
TAG=10={
TAG=10=teData{
TAG=9=Items{
}
TAG=8=id{Furnace}
TAG=2=BurnTime{0}
TAG=3=z{-99}
TAG=2=CookTime{0}
TAG=3=y{65}
TAG=3=x{273}
}
TAG=8=blockName{furnace}
TAG=3=meta{2}
TAG=3=buildPass{0}
}
:endtag
:enddata
:endrule

rule:
plugin=vanillaBlocks
number=31
data:
tag:
TAG=10={
TAG=8=blockName{lava}
TAG=3=meta{0}
TAG=3=buildPass{1}
}
:endtag
:enddata
:endrule

rule:
plugin=vanillaBlocks
number=32
data:
tag:
TAG=10={
TAG=8=blockName{water}
TAG=3=meta{0}
TAG=3=buildPass{1}
}
:endtag
:enddata
:endrule

rule:
plugin=vanillaBlocks
number=33
data:
tag:
TAG=10={
TAG=8=blockName{stone_brick_stairs}
TAG=3=meta{2}
TAG=3=buildPass{0}
}
:endtag
:enddata
:endrule

rule:
plugin=vanillaBlocks
number=34
data:
tag:
TAG=10={
TAG=8=blockName{anvil}
TAG=3=meta{0}
TAG=3=buildPass{1}
}
:endtag
:enddata
:endrule

rule:
plugin=awAdvancedSpawner
number=35
data:
tag:
TAG=10={
TAG=10=teData{
TAG=9=Items{
TAG=10={
TAG=2=id{265}
TAG=2=Damage{0}
TAG=1=Count{1}
TAG=1=Slot{0}
}
TAG=10={
TAG=2=id{263}
TAG=2=Damage{0}
TAG=1=Count{4}
TAG=1=Slot{1}
}
}
TAG=8=id{Furnace}
TAG=2=BurnTime{0}
TAG=3=z{-97}
TAG=2=CookTime{0}
TAG=3=y{65}
TAG=3=x{271}
}
TAG=8=blockName{furnace}
TAG=3=meta{5}
TAG=3=buildPass{0}
}
:endtag
:enddata
:endrule

rule:
plugin=vanillaBlocks
number=36
data:
tag:
TAG=10={
TAG=8=blockName{stone_brick_stairs}
TAG=3=meta{1}
TAG=3=buildPass{0}
}
:endtag
:enddata
:endrule

rule:
plugin=awAdvancedSpawner
number=37
data:
tag:
TAG=10={
TAG=10=teData{
TAG=9=Items{
TAG=10={
TAG=2=id{265}
TAG=2=Damage{0}
TAG=1=Count{1}
TAG=1=Slot{0}
}
TAG=10={
TAG=2=id{263}
TAG=2=Damage{0}
TAG=1=Count{4}
TAG=1=Slot{1}
}
}
TAG=8=id{Furnace}
TAG=2=BurnTime{0}
TAG=3=z{-97}
TAG=2=CookTime{0}
TAG=3=y{65}
TAG=3=x{274}
}
TAG=8=blockName{furnace}
TAG=3=meta{5}
TAG=3=buildPass{0}
}
:endtag
:enddata
:endrule

rule:
plugin=vanillaBlocks
number=38
data:
tag:
TAG=10={
TAG=8=blockName{fence_gate}
TAG=3=meta{2}
TAG=3=buildPass{0}
}
:endtag
:enddata
:endrule

rule:
plugin=vanillaBlocks
number=39
data:
tag:
TAG=10={
TAG=8=blockName{fence_gate}
TAG=3=meta{0}
TAG=3=buildPass{0}
}
:endtag
:enddata
:endrule

rule:
plugin=vanillaDoors
number=40
data:
tag:
TAG=10={
TAG=1=sideFlag{9}
TAG=8=blockName{wooden_door}
TAG=3=meta{0}
TAG=3=buildPass{1}
}
:endtag
:enddata
:endrule

rule:
plugin=vanillaDoors
number=41
data:
tag:
TAG=10={
TAG=1=sideFlag{8}
TAG=8=blockName{wooden_door}
TAG=3=meta{0}
TAG=3=buildPass{1}
}
:endtag
:enddata
:endrule

rule:
plugin=vanillaBlocks
number=42
data:
tag:
TAG=10={
TAG=8=blockName{crafting_table}
TAG=3=meta{0}
TAG=3=buildPass{0}
}
:endtag
:enddata
:endrule

rule:
plugin=awAdvancedSpawner
number=43
data:
tag:
TAG=10={
TAG=10=teData{
TAG=9=Items{
TAG=10={
TAG=2=id{265}
TAG=2=Damage{0}
TAG=1=Count{1}
TAG=1=Slot{0}
}
TAG=10={
TAG=2=id{263}
TAG=2=Damage{0}
TAG=1=Count{4}
TAG=1=Slot{1}
}
}
TAG=8=id{Furnace}
TAG=2=BurnTime{0}
TAG=3=z{-97}
TAG=2=CookTime{0}
TAG=3=y{66}
TAG=3=x{271}
}
TAG=8=blockName{furnace}
TAG=3=meta{5}
TAG=3=buildPass{0}
}
:endtag
:enddata
:endrule

rule:
plugin=awAdvancedSpawner
number=44
data:
tag:
TAG=10={
TAG=10=teData{
TAG=9=Items{
TAG=10={
TAG=2=id{265}
TAG=2=Damage{0}
TAG=1=Count{1}
TAG=1=Slot{0}
}
TAG=10={
TAG=2=id{263}
TAG=2=Damage{0}
TAG=1=Count{4}
TAG=1=Slot{1}
}
}
TAG=8=id{Furnace}
TAG=2=BurnTime{0}
TAG=3=z{-97}
TAG=2=CookTime{0}
TAG=3=y{66}
TAG=3=x{274}
}
TAG=8=blockName{furnace}
TAG=3=meta{5}
TAG=3=buildPass{0}
}
:endtag
:enddata
:endrule

rule:
plugin=vanillaDoors
number=45
data:
tag:
TAG=10={
TAG=1=sideFlag{0}
TAG=8=blockName{wooden_door}
TAG=3=meta{2}
TAG=3=buildPass{1}
}
:endtag
:enddata
:endrule

rule:
plugin=vanillaDoors
number=46
data:
tag:
TAG=10={
TAG=1=sideFlag{0}
TAG=8=blockName{wooden_door}
TAG=3=meta{8}
TAG=3=buildPass{1}
}
:endtag
:enddata
:endrule

rule:
plugin=vanillaBlocks
number=47
data:
tag:
TAG=10={
TAG=8=blockName{torch}
TAG=3=meta{4}
TAG=3=buildPass{1}
}
:endtag
:enddata
:endrule

rule:
plugin=vanillaBlocks
number=48
data:
tag:
TAG=10={
TAG=8=blockName{glass}
TAG=3=meta{0}
TAG=3=buildPass{0}
}
:endtag
:enddata
:endrule

rule:
plugin=vanillaBlocks
number=49
data:
tag:
TAG=10={
TAG=8=blockName{stone_brick_stairs}
TAG=3=meta{3}
TAG=3=buildPass{0}
}
:endtag
:enddata
:endrule

rule:
plugin=vanillaBlocks
number=50
data:
tag:
TAG=10={
TAG=8=blockName{oak_stairs}
TAG=3=meta{1}
TAG=3=buildPass{0}
}
:endtag
:enddata
:endrule

rule:
plugin=vanillaBlocks
number=51
data:
tag:
TAG=10={
TAG=8=blockName{stone_slab}
TAG=3=meta{5}
TAG=3=buildPass{0}
}
:endtag
:enddata
:endrule

rule:
plugin=vanillaInventory
number=52
data:
tag:
TAG=10={
TAG=3=lootLevel{0}
TAG=10=teData{
TAG=9=Items{
TAG=10={
TAG=2=id{344}
TAG=2=Damage{0}
TAG=1=Count{1}
TAG=1=Slot{12}
}
TAG=10={
TAG=2=id{349}
TAG=2=Damage{0}
TAG=1=Count{3}
TAG=1=Slot{17}
}
}
TAG=8=id{Chest}
}
TAG=8=blockName{chest}
TAG=3=meta{2}
TAG=3=buildPass{0}
}
:endtag
:enddata
:endrule

rule:
plugin=vanillaBlocks
number=53
data:
tag:
TAG=10={
TAG=8=blockName{bed}
TAG=3=meta{9}
TAG=3=buildPass{0}
}
:endtag
:enddata
:endrule

rule:
plugin=vanillaInventory
number=54
data:
tag:
TAG=10={
TAG=3=lootLevel{0}
TAG=10=teData{
TAG=9=Items{
}
TAG=8=id{Chest}
}
TAG=8=blockName{chest}
TAG=3=meta{5}
TAG=3=buildPass{0}
}
:endtag
:enddata
:endrule

rule:
plugin=vanillaBlocks
number=55
data:
tag:
TAG=10={
TAG=8=blockName{bed}
TAG=3=meta{1}
TAG=3=buildPass{0}
}
:endtag
:enddata
:endrule

rule:
plugin=vanillaBlocks
number=56
data:
tag:
TAG=10={
TAG=8=blockName{oak_stairs}
TAG=3=meta{3}
TAG=3=buildPass{0}
}
:endtag
:enddata
:endrule

rule:
plugin=vanillaBlocks
number=57
data:
tag:
TAG=10={
TAG=8=blockName{bed}
TAG=3=meta{2}
TAG=3=buildPass{0}
}
:endtag
:enddata
:endrule

rule:
plugin=vanillaBlocks
number=58
data:
tag:
TAG=10={
TAG=8=blockName{bed}
TAG=3=meta{10}
TAG=3=buildPass{0}
}
:endtag
:enddata
:endrule

rule:
plugin=vanillaBlocks
number=59
data:
tag:
TAG=10={
TAG=8=blockName{torch}
TAG=3=meta{5}
TAG=3=buildPass{1}
}
:endtag
:enddata
:endrule

rule:
plugin=vanillaBlocks
number=60
data:
tag:
TAG=10={
TAG=8=blockName{oak_stairs}
TAG=3=meta{0}
TAG=3=buildPass{0}
}
:endtag
:enddata
:endrule

rule:
plugin=vanillaBlocks
number=61
data:
tag:
TAG=10={
TAG=8=blockName{stone_slab}
TAG=3=meta{2}
TAG=3=buildPass{0}
}
:endtag
:enddata
:endrule

rule:
plugin=vanillaBlocks
number=62
data:
tag:
TAG=10={
TAG=8=blockName{cobblestone_wall}
TAG=3=meta{0}
TAG=3=buildPass{0}
}
:endtag
:enddata
:endrule

#### ENTITIES ####
entity:
plugin=vanillaLogicEntity
number=0
data:
position=1,6,12
tag:
TAG=10={
TAG=10=entityData{
TAG=9=DropChances{
TAG=5=0{0.085}
TAG=5=1{0.085}
TAG=5=2{0.085}
TAG=5=3{0.085}
TAG=5=4{0.085}
}
TAG=3=Age{0}
TAG=9=Attributes{
TAG=10={
TAG=8=Name{generic.maxHealth}
TAG=6=Base{20.0}
}
TAG=10={
TAG=8=Name{generic.knockbackResistance}
TAG=6=Base{0.0}
}
TAG=10={
TAG=8=Name{generic.movementSpeed}
TAG=6=Base{0.5}
}
TAG=10={
TAG=8=Name{generic.followRange}
TAG=6=Base{16.0}
TAG=9=Modifiers{
TAG=10={
TAG=8=Name{Random spawn bonus}
TAG=4=UUIDLeast{-8669617427760337556}
TAG=3=Operation{1}
TAG=6=Amount{-0.003909808829537233}
TAG=4=UUIDMost{-3844371734636377787}
}
}
}
}
TAG=9=Motion{
TAG=6={0.0}
TAG=6={-0.0784000015258789}
TAG=6={0.0}
}
TAG=8=CustomName{}
TAG=2=Health{20}
TAG=5=HealF{20.0}
TAG=1=CustomNameVisible{0}
TAG=3=Riches{0}
TAG=2=AttackTime{0}
TAG=2=Fire{-1}
TAG=1=Invulnerable{0}
TAG=2=DeathTime{0}
TAG=10=ForgeData{
TAG=1=MP|Init{1}
}
TAG=5=AbsorptionAmount{0.0}
TAG=9=Equipment{
TAG=10={
}
TAG=10={
}
TAG=10={
}
TAG=10={
}
TAG=10={
}
}
TAG=1=OnGround{1}
TAG=2=HurtTime{0}
TAG=3=Profession{4}
TAG=3=Dimension{0}
TAG=2=Air{300}
TAG=9=Pos{
TAG=6={267.92500001192093}
TAG=6={65.0}
TAG=6={-102.07499998807907}
}
TAG=1=CanPickUpLoot{0}
TAG=3=PortalCooldown{0}
TAG=1=PersistenceRequired{0}
TAG=1=Leashed{0}
TAG=5=FallDistance{0.0}
TAG=9=Rotation{
TAG=5={135.0}
TAG=5={0.0}
}
}
TAG=5=yOffset{0.0}
TAG=5=xOffset{0.925}
TAG=5=zOffset{0.07499999}
TAG=8=mobID{Villager}
TAG=5=rotation{45.0}
}
:endtag
:enddata
:endentity

entity:
plugin=vanillaLogicEntity
number=1
data:
position=10,6,2
tag:
TAG=10={
TAG=10=entityData{
TAG=9=DropChances{
TAG=5=0{0.085}
TAG=5=1{0.085}
TAG=5=2{0.085}
TAG=5=3{0.085}
TAG=5=4{0.085}
}
TAG=3=Age{0}
TAG=9=Attributes{
TAG=10={
TAG=8=Name{generic.maxHealth}
TAG=6=Base{20.0}
}
TAG=10={
TAG=8=Name{generic.knockbackResistance}
TAG=6=Base{0.0}
}
TAG=10={
TAG=8=Name{generic.movementSpeed}
TAG=6=Base{0.5}
}
TAG=10={
TAG=8=Name{generic.followRange}
TAG=6=Base{16.0}
TAG=9=Modifiers{
TAG=10={
TAG=8=Name{Random spawn bonus}
TAG=4=UUIDLeast{-7980261300699912686}
TAG=3=Operation{1}
TAG=6=Amount{-0.022876849484476658}
TAG=4=UUIDMost{-8102879677628986212}
}
}
}
}
TAG=9=Motion{
TAG=6={-1.0157424102013885E-4}
TAG=6={-0.0784000015258789}
TAG=6={-0.10603872067828744}
}
TAG=8=CustomName{}
TAG=2=Health{20}
TAG=5=HealF{20.0}
TAG=1=CustomNameVisible{0}
TAG=3=Riches{0}
TAG=2=AttackTime{0}
TAG=2=Fire{-1}
TAG=1=Invulnerable{0}
TAG=2=DeathTime{0}
TAG=10=ForgeData{
TAG=1=MP|Init{1}
}
TAG=5=AbsorptionAmount{0.0}
TAG=9=Equipment{
TAG=10={
}
TAG=10={
}
TAG=10={
}
TAG=10={
}
TAG=10={
}
}
TAG=1=OnGround{1}
TAG=2=HurtTime{0}
TAG=3=Profession{3}
TAG=3=Dimension{0}
TAG=2=Air{300}
TAG=9=Pos{
TAG=6={277.50253185594977}
TAG=6={65.0}
TAG=6={-93.37059523537029}
}
TAG=1=CanPickUpLoot{0}
TAG=3=PortalCooldown{0}
TAG=1=PersistenceRequired{0}
TAG=1=Leashed{0}
TAG=5=FallDistance{0.0}
TAG=9=Rotation{
TAG=5={539.8823}
TAG=5={0.0}
}
}
TAG=5=yOffset{0.0}
TAG=5=xOffset{0.6294048}
TAG=5=zOffset{0.49746817}
TAG=8=mobID{Villager}
TAG=5=rotation{89.882324}
}
:endtag
:enddata
:endentity

