# Ancient Warfare Structure Template File
# auto-generated structure file. created on: 4/14/2014 at: 16:41:45
# Lines beginning with # denote comments

header:
version=2.0
name=CivReligiousPeasantChapel
size=19,24,14
offset=1,2,5
:endheader

#### VALIDATION ####
validation:
type=ground
survival=false
worldGenEnabled=true
unique=false
preserveBlocks=false
selectionWeight=10
clusterValue=10
minDuplicateDistance=60
dimensionWhiteList=false
dimensionList=
biomeWhiteList=true
biomeList=highlands.meadow,bop.meadow,ebxl.meadow,field,orchard
leveling=9
fill=5
border=5
validTargetBlocks=clay,lapis_ore,sand,grass,lit_redstone_ore,stone,gravel,iron_ore,diamond_ore,stained_hardened_clay,dirt,coal_ore,redstone_ore,gold_ore
data:
:enddata
:endvalidation

#### LAYERS ####
layer: 0
1,1,1,1,1,1,1,1,1,1,1,1,1,1,1,1,1,1,1
1,1,1,1,1,1,1,1,1,1,1,1,1,1,1,1,1,1,1
1,1,1,1,1,1,1,1,1,1,1,1,1,1,1,1,1,1,1
1,1,1,1,1,1,1,1,1,1,1,1,1,1,1,1,1,1,1
1,1,1,1,1,1,1,1,1,1,1,1,1,1,1,1,1,1,1
1,1,1,1,1,1,1,1,1,1,1,1,1,1,1,1,1,1,1
1,1,1,1,1,1,1,1,1,1,1,1,1,1,1,1,1,1,1
1,1,1,1,1,1,1,1,1,1,1,1,1,1,1,1,1,1,1
1,1,1,1,1,1,1,1,1,1,1,1,1,1,1,1,1,1,1
1,1,1,1,1,1,1,1,1,1,1,1,1,1,1,1,1,1,1
1,1,1,1,1,1,1,1,1,1,1,1,1,1,1,1,1,1,1
1,1,1,1,1,1,1,1,1,1,1,1,1,1,1,1,1,1,1
1,1,1,1,1,1,1,1,1,1,1,1,1,1,1,1,1,1,1
1,1,1,1,1,1,1,1,1,1,1,1,1,1,1,1,1,1,1
:endlayer
layer: 1
2,2,2,2,2,2,2,2,2,2,2,2,2,2,2,2,2,2,2
2,2,2,2,2,2,2,1,2,2,2,2,2,2,2,2,1,2,2
2,2,2,2,2,2,1,1,1,1,1,1,1,1,1,1,1,1,2
2,2,1,1,1,1,1,1,4,4,4,4,4,4,4,4,1,2,2
2,2,1,1,1,1,1,1,4,4,4,4,4,4,4,4,1,2,2
2,1,1,4,4,4,4,4,4,4,4,4,4,4,4,4,1,1,2
3,3,3,3,3,3,3,3,3,3,3,3,3,3,5,5,1,2,2
3,3,3,3,3,3,3,3,3,3,3,3,3,3,5,5,1,2,2
2,1,1,4,4,4,4,4,4,4,4,4,4,4,4,4,1,1,2
2,2,1,1,1,1,1,1,4,4,4,4,4,4,4,4,1,2,2
2,2,1,1,1,1,1,1,4,4,4,4,4,4,4,4,1,2,2
2,2,2,2,2,2,1,1,1,1,1,1,1,1,1,1,1,1,2
2,2,2,2,2,2,2,1,2,2,2,2,2,2,2,2,1,2,2
2,2,2,2,2,2,2,2,2,2,2,2,2,2,2,2,2,2,2
:endlayer
layer: 2
0,0,0,0,0,0,0,0,0,0,0,0,0,0,0,0,0,0,0
0,0,0,0,0,0,0,6,0,0,0,0,0,0,0,0,6,0,0
0,0,0,0,0,0,6,6,6,6,6,6,6,6,6,6,6,6,0
0,0,6,6,6,6,6,6,0,0,0,0,0,0,0,0,6,0,0
0,0,6,6,6,6,6,6,0,9,0,9,0,0,0,0,6,0,0
0,6,6,0,0,0,0,0,0,9,0,9,0,10,11,11,6,6,0
0,0,8,0,0,0,0,0,0,0,0,0,0,11,12,12,6,0,0
0,0,7,0,0,0,0,0,0,0,0,0,0,11,12,12,6,0,0
0,6,6,0,0,0,0,0,0,9,0,9,0,10,11,11,6,6,0
0,0,6,6,6,6,6,6,0,9,0,9,0,0,0,0,6,0,0
0,0,6,6,6,6,6,6,0,0,0,0,0,0,0,0,6,0,0
0,0,0,0,0,0,6,6,6,6,6,6,6,6,6,6,6,6,0
0,0,0,0,0,0,0,6,0,0,0,0,0,0,0,0,6,0,0
0,0,0,0,0,0,0,0,0,0,0,0,0,0,0,0,0,0,0
:endlayer
layer: 3
0,0,0,0,0,0,0,0,0,0,0,0,0,0,0,0,0,0,0
0,0,0,0,0,0,0,6,0,0,0,0,0,0,0,0,6,0,0
0,0,0,0,0,0,6,6,6,6,21,6,6,21,6,6,6,6,0
0,0,18,20,20,20,20,6,13,0,0,13,13,0,13,13,6,0,0
0,14,6,6,6,6,6,6,0,0,0,0,0,0,0,0,6,0,0
0,6,6,13,13,13,13,13,0,0,0,0,0,0,0,0,6,6,0
0,0,17,0,0,0,0,0,0,0,0,0,0,0,22,0,23,0,0
0,0,16,0,0,0,0,0,0,0,0,0,0,0,22,0,23,0,0
0,6,6,14,14,14,14,14,0,0,0,0,0,0,0,0,6,6,0
0,13,6,6,6,6,6,6,0,0,0,0,0,0,0,0,6,0,0
0,0,15,19,19,19,19,6,14,14,0,14,14,0,14,14,6,0,0
0,0,0,0,0,0,6,6,6,6,21,6,6,21,6,6,6,6,0
0,0,0,0,0,0,0,6,0,0,0,0,0,0,0,0,6,0,0
0,0,0,0,0,0,0,0,0,0,0,0,0,0,0,0,0,0,0
:endlayer
layer: 4
0,0,0,0,0,0,0,0,0,0,0,0,0,0,0,0,0,0,0
0,0,0,0,0,0,0,6,0,0,0,0,0,0,0,0,6,0,0
0,0,0,0,0,0,6,6,6,6,21,6,6,21,6,6,6,6,0
0,0,0,0,0,0,0,6,0,0,0,0,0,0,0,0,6,0,0
0,0,18,20,20,20,20,6,0,0,0,0,0,0,0,0,6,0,0
0,24,6,0,0,0,0,0,0,0,0,0,0,0,0,0,6,6,0
0,24,22,0,0,0,0,0,0,0,0,0,0,0,0,0,23,0,0
0,24,22,0,0,0,0,0,0,0,0,0,0,0,0,0,23,0,0
0,24,6,0,0,0,0,0,0,0,0,0,0,0,0,0,6,6,0
0,0,15,19,19,19,19,6,0,0,0,0,0,0,0,0,6,0,0
0,0,0,0,0,0,0,6,0,0,0,0,0,0,0,0,6,0,0
0,0,0,0,0,0,6,6,6,6,21,6,6,21,6,6,6,6,0
0,0,0,0,0,0,0,6,0,0,0,0,0,0,0,0,6,0,0
0,0,0,0,0,0,0,0,0,0,0,0,0,0,0,0,0,0,0
:endlayer
layer: 5
0,0,0,0,0,0,0,0,0,0,0,0,0,0,0,0,0,0,0
0,0,0,0,0,0,25,6,26,0,0,0,0,0,0,25,6,14,0
0,0,0,0,0,0,6,6,6,6,21,6,6,21,6,6,6,6,0
0,0,0,0,0,0,0,6,0,0,0,0,0,0,0,0,6,13,0
0,0,0,0,0,0,0,6,0,0,0,0,0,0,0,0,6,0,0
0,0,18,20,20,20,20,6,0,0,0,0,0,0,0,0,6,27,0
0,0,6,0,0,0,0,0,0,0,0,0,0,0,0,0,23,0,0
0,25,6,0,0,0,0,0,0,0,0,0,0,0,0,0,23,0,0
0,0,15,19,19,19,19,6,0,0,0,0,0,0,0,0,6,27,0
0,0,0,0,0,0,0,6,0,0,0,0,0,0,0,0,6,0,0
0,0,0,0,0,0,0,6,0,0,0,0,0,0,0,0,6,14,0
0,0,0,0,0,0,6,6,6,6,21,6,6,21,6,6,6,6,0
0,0,0,0,0,0,25,6,26,0,0,0,0,0,0,25,6,26,0
0,0,0,0,0,0,0,0,0,0,0,0,0,0,0,0,0,0,0
:endlayer
layer: 6
0,0,0,0,0,0,0,0,0,0,0,0,0,0,0,0,0,0,0
0,0,0,0,0,0,0,18,20,20,20,20,20,20,20,20,18,0,0
0,0,0,0,0,0,24,6,6,6,6,6,6,6,6,6,6,6,0
0,0,0,0,0,0,0,6,0,0,0,0,0,0,0,0,6,0,0
0,0,0,0,0,0,0,6,0,0,0,0,0,0,0,0,23,0,0
0,0,0,0,0,0,0,6,0,0,0,0,0,0,0,0,23,0,0
0,0,18,20,20,20,20,6,0,0,0,0,0,0,0,0,23,0,0
0,0,15,19,19,19,19,6,0,0,0,0,0,0,0,0,23,0,0
0,0,0,0,0,0,0,6,0,0,0,0,0,0,0,0,23,0,0
0,0,0,0,0,0,0,6,0,0,0,0,0,0,0,0,23,0,0
0,0,0,0,0,0,0,6,0,0,0,0,0,0,0,0,6,0,0
0,0,0,0,0,0,24,6,6,6,6,6,6,6,6,6,6,6,0
0,0,0,0,0,0,0,15,19,19,19,19,19,19,19,19,15,0,0
0,0,0,0,0,0,0,0,0,0,0,0,0,0,0,0,0,0,0
:endlayer
layer: 7
0,0,0,0,0,0,0,0,0,0,0,0,0,0,0,0,0,0,0
0,0,0,0,0,0,0,0,0,0,0,0,0,0,0,0,0,0,0
0,0,0,0,0,0,0,18,20,20,20,20,20,20,20,20,18,27,0
0,0,0,0,0,0,0,6,0,0,0,0,0,0,0,0,6,0,0
0,0,0,0,0,0,0,6,0,0,0,0,0,0,0,0,23,0,0
0,0,0,0,0,0,0,6,0,0,0,0,0,0,0,0,23,0,0
0,0,0,0,0,0,0,23,0,0,0,0,0,0,0,0,23,0,0
0,0,0,0,0,0,0,23,0,0,0,0,0,0,0,0,23,0,0
0,0,0,0,0,0,0,6,0,0,0,0,0,0,0,0,23,0,0
0,0,0,0,0,0,0,6,0,0,0,0,0,0,0,0,23,0,0
0,0,0,0,0,0,0,6,0,0,0,0,0,0,0,0,6,0,0
0,0,0,0,0,0,0,15,19,19,19,19,19,19,19,19,15,27,0
0,0,0,0,0,0,0,0,0,0,0,0,0,0,0,0,0,0,0
0,0,0,0,0,0,0,0,0,0,0,0,0,0,0,0,0,0,0
:endlayer
layer: 8
0,0,0,0,0,0,0,0,0,0,0,0,0,0,0,0,0,0,0
0,0,0,0,0,0,0,0,0,0,0,0,0,0,0,0,0,0,0
0,0,0,0,0,0,0,0,0,0,0,0,0,0,0,0,0,0,0
0,0,0,0,0,0,0,6,20,20,20,20,20,20,20,20,18,0,0
0,0,0,0,0,0,0,6,0,0,0,0,0,0,0,0,6,0,0
0,0,0,0,0,0,0,6,0,0,0,0,0,0,0,0,6,0,0
0,0,0,0,0,0,0,23,0,0,0,0,0,0,0,0,23,0,0
0,0,0,0,0,0,0,23,0,0,0,0,0,0,0,0,23,0,0
0,0,0,0,0,0,0,6,0,0,0,0,0,0,0,0,6,0,0
0,0,0,0,0,0,0,6,0,0,0,0,0,0,0,0,6,0,0
0,0,0,0,0,0,0,15,19,19,19,19,19,19,19,19,15,0,0
0,0,0,0,0,0,0,0,0,0,0,0,0,0,0,0,0,0,0
0,0,0,0,0,0,0,0,0,0,0,0,0,0,0,0,0,0,0
0,0,0,0,0,0,0,0,0,0,0,0,0,0,0,0,0,0,0
:endlayer
layer: 9
0,0,0,0,0,0,0,0,0,0,0,0,0,0,0,0,0,0,0
0,0,0,0,0,0,0,0,0,0,0,0,0,0,0,0,0,0,0
0,0,0,0,0,0,0,0,0,0,0,0,0,0,0,0,0,0,0
0,0,0,0,0,0,0,0,0,0,0,0,0,0,0,0,0,0,0
0,0,0,0,0,0,0,18,20,20,20,20,20,20,20,20,18,0,0
0,0,0,0,0,0,0,6,0,0,0,0,0,0,0,0,6,0,0
0,0,0,0,0,0,0,6,0,0,0,0,0,0,0,0,6,0,0
0,0,0,0,0,0,0,6,0,0,0,0,0,0,0,0,6,0,0
0,0,0,0,0,0,0,6,0,0,0,0,0,0,0,0,6,0,0
0,0,0,0,0,0,0,15,19,19,19,19,19,19,19,19,15,0,0
0,0,0,0,0,0,0,0,0,0,0,0,0,0,0,0,0,0,0
0,0,0,0,0,0,0,0,0,0,0,0,0,0,0,0,0,0,0
0,0,0,0,0,0,0,0,0,0,0,0,0,0,0,0,0,0,0
0,0,0,0,0,0,0,0,0,0,0,0,0,0,0,0,0,0,0
:endlayer
layer: 10
0,0,0,0,0,0,0,0,0,0,0,0,0,0,0,0,0,0,0
0,0,0,0,0,0,0,0,0,0,0,0,0,0,0,0,0,0,0
0,0,0,0,0,0,0,0,0,0,0,0,0,0,0,0,0,0,0
0,0,0,0,0,0,0,0,0,0,0,0,0,0,0,0,0,0,0
0,0,0,0,0,0,0,0,0,0,0,0,0,0,0,0,0,0,0
0,0,0,0,0,0,0,18,20,20,20,20,20,20,20,20,18,0,0
0,0,0,0,0,0,0,6,0,0,0,0,0,0,0,0,6,0,0
0,0,0,0,0,0,0,6,0,0,0,0,0,0,0,0,6,0,0
0,0,0,0,0,0,0,6,19,19,19,19,19,19,19,19,15,0,0
0,0,0,0,0,0,0,0,0,0,0,0,0,0,0,0,0,0,0
0,0,0,0,0,0,0,0,0,0,0,0,0,0,0,0,0,0,0
0,0,0,0,0,0,0,0,0,0,0,0,0,0,0,0,0,0,0
0,0,0,0,0,0,0,0,0,0,0,0,0,0,0,0,0,0,0
0,0,0,0,0,0,0,0,0,0,0,0,0,0,0,0,0,0,0
:endlayer
layer: 11
0,0,0,0,0,0,0,0,0,0,0,0,0,0,0,0,0,0,0
0,0,0,0,0,0,0,0,0,0,0,0,0,0,0,0,0,0,0
0,0,0,0,0,0,0,0,0,0,0,0,0,0,0,0,0,0,0
0,0,0,0,0,0,0,0,0,0,0,0,0,0,0,0,0,0,0
0,0,0,0,0,0,0,0,0,0,0,0,0,0,0,0,0,0,0
0,0,0,0,0,0,0,0,0,0,0,0,0,0,0,0,0,0,0
0,0,0,0,0,0,0,18,20,20,20,20,20,20,20,20,18,0,0
0,0,0,0,0,0,0,15,19,19,19,19,19,19,19,19,15,0,0
0,0,0,0,0,0,0,0,0,0,0,0,0,0,0,0,0,0,0
0,0,0,0,0,0,0,0,0,0,0,0,0,0,0,0,0,0,0
0,0,0,0,0,0,0,0,0,0,0,0,0,0,0,0,0,0,0
0,0,0,0,0,0,0,0,0,0,0,0,0,0,0,0,0,0,0
0,0,0,0,0,0,0,0,0,0,0,0,0,0,0,0,0,0,0
0,0,0,0,0,0,0,0,0,0,0,0,0,0,0,0,0,0,0
:endlayer
layer: 12
0,0,0,0,0,0,0,0,0,0,0,0,0,0,0,0,0,0,0
0,0,0,0,0,0,0,0,0,0,0,0,0,0,0,0,0,0,0
0,0,0,0,0,0,0,0,0,0,0,0,0,0,0,0,0,0,0
0,0,0,0,0,0,0,0,0,0,0,0,0,0,0,0,0,0,0
0,0,0,0,0,0,0,0,0,0,0,0,0,0,0,0,0,0,0
0,0,0,0,0,0,0,0,0,0,0,0,0,0,0,0,0,0,0
0,0,0,0,0,0,0,0,0,0,0,0,0,0,0,0,0,0,0
0,0,0,0,0,0,0,0,0,0,0,0,0,0,0,0,0,0,0
0,0,0,0,0,0,0,0,0,0,0,0,0,0,0,0,0,0,0
0,0,0,0,0,0,0,0,0,0,0,0,0,0,0,0,0,0,0
0,0,0,0,0,0,0,0,0,0,0,0,0,0,0,0,0,0,0
0,0,0,0,0,0,0,0,0,0,0,0,0,0,0,0,0,0,0
0,0,0,0,0,0,0,0,0,0,0,0,0,0,0,0,0,0,0
0,0,0,0,0,0,0,0,0,0,0,0,0,0,0,0,0,0,0
:endlayer
layer: 13
0,0,0,0,0,0,0,0,0,0,0,0,0,0,0,0,0,0,0
0,0,0,0,0,0,0,0,0,0,0,0,0,0,0,0,0,0,0
0,0,0,0,0,0,0,0,0,0,0,0,0,0,0,0,0,0,0
0,0,0,0,0,0,0,0,0,0,0,0,0,0,0,0,0,0,0
0,0,0,0,0,0,0,0,0,0,0,0,0,0,0,0,0,0,0
0,0,0,0,0,0,0,0,0,0,0,0,0,0,0,0,0,0,0
0,0,0,0,0,0,0,0,0,0,0,0,0,0,0,0,0,0,0
0,0,0,0,0,0,0,0,0,0,0,0,0,0,0,0,0,0,0
0,0,0,0,0,0,0,0,0,0,0,0,0,0,0,0,0,0,0
0,0,0,0,0,0,0,0,0,0,0,0,0,0,0,0,0,0,0
0,0,0,0,0,0,0,0,0,0,0,0,0,0,0,0,0,0,0
0,0,0,0,0,0,0,0,0,0,0,0,0,0,0,0,0,0,0
0,0,0,0,0,0,0,0,0,0,0,0,0,0,0,0,0,0,0
0,0,0,0,0,0,0,0,0,0,0,0,0,0,0,0,0,0,0
:endlayer
layer: 14
0,0,0,0,0,0,0,0,0,0,0,0,0,0,0,0,0,0,0
0,0,0,0,0,0,0,0,0,0,0,0,0,0,0,0,0,0,0
0,0,0,0,0,0,0,0,0,0,0,0,0,0,0,0,0,0,0
0,0,0,0,0,0,0,0,0,0,0,0,0,0,0,0,0,0,0
0,0,0,0,0,0,0,0,0,0,0,0,0,0,0,0,0,0,0
0,0,0,0,0,0,0,0,0,0,0,0,0,0,0,0,0,0,0
0,0,0,0,0,0,0,0,0,0,0,0,0,0,0,0,0,0,0
0,0,0,0,0,0,0,0,0,0,0,0,0,0,0,0,0,0,0
0,0,0,0,0,0,0,0,0,0,0,0,0,0,0,0,0,0,0
0,0,0,0,0,0,0,0,0,0,0,0,0,0,0,0,0,0,0
0,0,0,0,0,0,0,0,0,0,0,0,0,0,0,0,0,0,0
0,0,0,0,0,0,0,0,0,0,0,0,0,0,0,0,0,0,0
0,0,0,0,0,0,0,0,0,0,0,0,0,0,0,0,0,0,0
0,0,0,0,0,0,0,0,0,0,0,0,0,0,0,0,0,0,0
:endlayer
layer: 15
0,0,0,0,0,0,0,0,0,0,0,0,0,0,0,0,0,0,0
0,0,0,0,0,0,0,0,0,0,0,0,0,0,0,0,0,0,0
0,0,0,0,0,0,0,0,0,0,0,0,0,0,0,0,0,0,0
0,0,0,0,0,0,0,0,0,0,0,0,0,0,0,0,0,0,0
0,0,0,0,0,0,0,0,0,0,0,0,0,0,0,0,0,0,0
0,0,0,0,0,0,0,0,0,0,0,0,0,0,0,0,0,0,0
0,0,0,0,0,0,0,0,0,0,0,0,0,0,0,0,0,0,0
0,0,0,0,0,0,0,0,0,0,0,0,0,0,0,0,0,0,0
0,0,0,0,0,0,0,0,0,0,0,0,0,0,0,0,0,0,0
0,0,0,0,0,0,0,0,0,0,0,0,0,0,0,0,0,0,0
0,0,0,0,0,0,0,0,0,0,0,0,0,0,0,0,0,0,0
0,0,0,0,0,0,0,0,0,0,0,0,0,0,0,0,0,0,0
0,0,0,0,0,0,0,0,0,0,0,0,0,0,0,0,0,0,0
0,0,0,0,0,0,0,0,0,0,0,0,0,0,0,0,0,0,0
:endlayer
layer: 16
0,0,0,0,0,0,0,0,0,0,0,0,0,0,0,0,0,0,0
0,0,0,0,0,0,0,0,0,0,0,0,0,0,0,0,0,0,0
0,0,0,0,0,0,0,0,0,0,0,0,0,0,0,0,0,0,0
0,0,0,0,0,0,0,0,0,0,0,0,0,0,0,0,0,0,0
0,0,0,0,0,0,0,0,0,0,0,0,0,0,0,0,0,0,0
0,0,0,0,0,0,0,0,0,0,0,0,0,0,0,0,0,0,0
0,0,0,0,0,0,0,0,0,0,0,0,0,0,0,0,0,0,0
0,0,0,0,0,0,0,0,0,0,0,0,0,0,0,0,0,0,0
0,0,0,0,0,0,0,0,0,0,0,0,0,0,0,0,0,0,0
0,0,0,0,0,0,0,0,0,0,0,0,0,0,0,0,0,0,0
0,0,0,0,0,0,0,0,0,0,0,0,0,0,0,0,0,0,0
0,0,0,0,0,0,0,0,0,0,0,0,0,0,0,0,0,0,0
0,0,0,0,0,0,0,0,0,0,0,0,0,0,0,0,0,0,0
0,0,0,0,0,0,0,0,0,0,0,0,0,0,0,0,0,0,0
:endlayer
layer: 17
0,0,0,0,0,0,0,0,0,0,0,0,0,0,0,0,0,0,0
0,0,0,0,0,0,0,0,0,0,0,0,0,0,0,0,0,0,0
0,0,0,0,0,0,0,0,0,0,0,0,0,0,0,0,0,0,0
0,0,0,0,0,0,0,0,0,0,0,0,0,0,0,0,0,0,0
0,0,0,0,0,0,0,0,0,0,0,0,0,0,0,0,0,0,0
0,0,0,0,0,0,0,0,0,0,0,0,0,0,0,0,0,0,0
0,0,0,0,0,0,0,0,0,0,0,0,0,0,0,0,0,0,0
0,0,0,0,0,0,0,0,0,0,0,0,0,0,0,0,0,0,0
0,0,0,0,0,0,0,0,0,0,0,0,0,0,0,0,0,0,0
0,0,0,0,0,0,0,0,0,0,0,0,0,0,0,0,0,0,0
0,0,0,0,0,0,0,0,0,0,0,0,0,0,0,0,0,0,0
0,0,0,0,0,0,0,0,0,0,0,0,0,0,0,0,0,0,0
0,0,0,0,0,0,0,0,0,0,0,0,0,0,0,0,0,0,0
0,0,0,0,0,0,0,0,0,0,0,0,0,0,0,0,0,0,0
:endlayer
layer: 18
0,0,0,0,0,0,0,0,0,0,0,0,0,0,0,0,0,0,0
0,0,0,0,0,0,0,0,0,0,0,0,0,0,0,0,0,0,0
0,0,0,0,0,0,0,0,0,0,0,0,0,0,0,0,0,0,0
0,0,0,0,0,0,0,0,0,0,0,0,0,0,0,0,0,0,0
0,0,0,0,0,0,0,0,0,0,0,0,0,0,0,0,0,0,0
0,0,0,0,0,0,0,0,0,0,0,0,0,0,0,0,0,0,0
0,0,0,0,0,0,0,0,0,0,0,0,0,0,0,0,0,0,0
0,0,0,0,0,0,0,0,0,0,0,0,0,0,0,0,0,0,0
0,0,0,0,0,0,0,0,0,0,0,0,0,0,0,0,0,0,0
0,0,0,0,0,0,0,0,0,0,0,0,0,0,0,0,0,0,0
0,0,0,0,0,0,0,0,0,0,0,0,0,0,0,0,0,0,0
0,0,0,0,0,0,0,0,0,0,0,0,0,0,0,0,0,0,0
0,0,0,0,0,0,0,0,0,0,0,0,0,0,0,0,0,0,0
0,0,0,0,0,0,0,0,0,0,0,0,0,0,0,0,0,0,0
:endlayer
layer: 19
0,0,0,0,0,0,0,0,0,0,0,0,0,0,0,0,0,0,0
0,0,0,0,0,0,0,0,0,0,0,0,0,0,0,0,0,0,0
0,0,0,0,0,0,0,0,0,0,0,0,0,0,0,0,0,0,0
0,0,0,0,0,0,0,0,0,0,0,0,0,0,0,0,0,0,0
0,0,0,0,0,0,0,0,0,0,0,0,0,0,0,0,0,0,0
0,0,0,0,0,0,0,0,0,0,0,0,0,0,0,0,0,0,0
0,0,0,0,0,0,0,0,0,0,0,0,0,0,0,0,0,0,0
0,0,0,0,0,0,0,0,0,0,0,0,0,0,0,0,0,0,0
0,0,0,0,0,0,0,0,0,0,0,0,0,0,0,0,0,0,0
0,0,0,0,0,0,0,0,0,0,0,0,0,0,0,0,0,0,0
0,0,0,0,0,0,0,0,0,0,0,0,0,0,0,0,0,0,0
0,0,0,0,0,0,0,0,0,0,0,0,0,0,0,0,0,0,0
0,0,0,0,0,0,0,0,0,0,0,0,0,0,0,0,0,0,0
0,0,0,0,0,0,0,0,0,0,0,0,0,0,0,0,0,0,0
:endlayer
layer: 20
0,0,0,0,0,0,0,0,0,0,0,0,0,0,0,0,0,0,0
0,0,0,0,0,0,0,0,0,0,0,0,0,0,0,0,0,0,0
0,0,0,0,0,0,0,0,0,0,0,0,0,0,0,0,0,0,0
0,0,0,0,0,0,0,0,0,0,0,0,0,0,0,0,0,0,0
0,0,0,0,0,0,0,0,0,0,0,0,0,0,0,0,0,0,0
0,0,0,0,0,0,0,0,0,0,0,0,0,0,0,0,0,0,0
0,0,0,0,0,0,0,0,0,0,0,0,0,0,0,0,0,0,0
0,0,0,0,0,0,0,0,0,0,0,0,0,0,0,0,0,0,0
0,0,0,0,0,0,0,0,0,0,0,0,0,0,0,0,0,0,0
0,0,0,0,0,0,0,0,0,0,0,0,0,0,0,0,0,0,0
0,0,0,0,0,0,0,0,0,0,0,0,0,0,0,0,0,0,0
0,0,0,0,0,0,0,0,0,0,0,0,0,0,0,0,0,0,0
0,0,0,0,0,0,0,0,0,0,0,0,0,0,0,0,0,0,0
0,0,0,0,0,0,0,0,0,0,0,0,0,0,0,0,0,0,0
:endlayer
layer: 21
0,0,0,0,0,0,0,0,0,0,0,0,0,0,0,0,0,0,0
0,0,0,0,0,0,0,0,0,0,0,0,0,0,0,0,0,0,0
0,0,0,0,0,0,0,0,0,0,0,0,0,0,0,0,0,0,0
0,0,0,0,0,0,0,0,0,0,0,0,0,0,0,0,0,0,0
0,0,0,0,0,0,0,0,0,0,0,0,0,0,0,0,0,0,0
0,0,0,0,0,0,0,0,0,0,0,0,0,0,0,0,0,0,0
0,0,0,0,0,0,0,0,0,0,0,0,0,0,0,0,0,0,0
0,0,0,0,0,0,0,0,0,0,0,0,0,0,0,0,0,0,0
0,0,0,0,0,0,0,0,0,0,0,0,0,0,0,0,0,0,0
0,0,0,0,0,0,0,0,0,0,0,0,0,0,0,0,0,0,0
0,0,0,0,0,0,0,0,0,0,0,0,0,0,0,0,0,0,0
0,0,0,0,0,0,0,0,0,0,0,0,0,0,0,0,0,0,0
0,0,0,0,0,0,0,0,0,0,0,0,0,0,0,0,0,0,0
0,0,0,0,0,0,0,0,0,0,0,0,0,0,0,0,0,0,0
:endlayer
layer: 22
0,0,0,0,0,0,0,0,0,0,0,0,0,0,0,0,0,0,0
0,0,0,0,0,0,0,0,0,0,0,0,0,0,0,0,0,0,0
0,0,0,0,0,0,0,0,0,0,0,0,0,0,0,0,0,0,0
0,0,0,0,0,0,0,0,0,0,0,0,0,0,0,0,0,0,0
0,0,0,0,0,0,0,0,0,0,0,0,0,0,0,0,0,0,0
0,0,0,0,0,0,0,0,0,0,0,0,0,0,0,0,0,0,0
0,0,0,0,0,0,0,0,0,0,0,0,0,0,0,0,0,0,0
0,0,0,0,0,0,0,0,0,0,0,0,0,0,0,0,0,0,0
0,0,0,0,0,0,0,0,0,0,0,0,0,0,0,0,0,0,0
0,0,0,0,0,0,0,0,0,0,0,0,0,0,0,0,0,0,0
0,0,0,0,0,0,0,0,0,0,0,0,0,0,0,0,0,0,0
0,0,0,0,0,0,0,0,0,0,0,0,0,0,0,0,0,0,0
0,0,0,0,0,0,0,0,0,0,0,0,0,0,0,0,0,0,0
0,0,0,0,0,0,0,0,0,0,0,0,0,0,0,0,0,0,0
:endlayer
layer: 23
0,0,0,0,0,0,0,0,0,0,0,0,0,0,0,0,0,0,0
0,0,0,0,0,0,0,0,0,0,0,0,0,0,0,0,0,0,0
0,0,0,0,0,0,0,0,0,0,0,0,0,0,0,0,0,0,0
0,0,0,0,0,0,0,0,0,0,0,0,0,0,0,0,0,0,0
0,0,0,0,0,0,0,0,0,0,0,0,0,0,0,0,0,0,0
0,0,0,0,0,0,0,0,0,0,0,0,0,0,0,0,0,0,0
0,0,0,0,0,0,0,0,0,0,0,0,0,0,0,0,0,0,0
0,0,0,0,0,0,0,0,0,0,0,0,0,0,0,0,0,0,0
0,0,0,0,0,0,0,0,0,0,0,0,0,0,0,0,0,0,0
0,0,0,0,0,0,0,0,0,0,0,0,0,0,0,0,0,0,0
0,0,0,0,0,0,0,0,0,0,0,0,0,0,0,0,0,0,0
0,0,0,0,0,0,0,0,0,0,0,0,0,0,0,0,0,0,0
0,0,0,0,0,0,0,0,0,0,0,0,0,0,0,0,0,0,0
0,0,0,0,0,0,0,0,0,0,0,0,0,0,0,0,0,0,0
:endlayer

#### RULES ####
rule:
plugin=vanillaBlocks
number=1
data:
tag:
TAG=10={
TAG=8=blockName{dirt}
TAG=3=meta{0}
TAG=3=buildPass{0}
}
:endtag
:enddata
:endrule

rule:
plugin=vanillaBlocks
number=2
data:
tag:
TAG=10={
TAG=8=blockName{grass}
TAG=3=meta{0}
TAG=3=buildPass{0}
}
:endtag
:enddata
:endrule

rule:
plugin=vanillaBlocks
number=3
data:
tag:
TAG=10={
TAG=8=blockName{cobblestone}
TAG=3=meta{0}
TAG=3=buildPass{0}
}
:endtag
:enddata
:endrule

rule:
plugin=vanillaBlocks
number=4
data:
tag:
TAG=10={
TAG=8=blockName{stone}
TAG=3=meta{0}
TAG=3=buildPass{0}
}
:endtag
:enddata
:endrule

rule:
plugin=vanillaBlocks
number=5
data:
tag:
TAG=10={
TAG=8=blockName{wool}
TAG=3=meta{14}
TAG=3=buildPass{0}
}
:endtag
:enddata
:endrule

rule:
plugin=vanillaBlocks
number=6
data:
tag:
TAG=10={
TAG=8=blockName{stonebrick}
TAG=3=meta{0}
TAG=3=buildPass{0}
}
:endtag
:enddata
:endrule

rule:
plugin=vanillaDoors
number=7
data:
tag:
TAG=10={
TAG=1=sideFlag{9}
TAG=8=blockName{wooden_door}
TAG=3=meta{0}
TAG=3=buildPass{1}
}
:endtag
:enddata
:endrule

rule:
plugin=vanillaDoors
number=8
data:
tag:
TAG=10={
TAG=1=sideFlag{8}
TAG=8=blockName{wooden_door}
TAG=3=meta{0}
TAG=3=buildPass{1}
}
:endtag
:enddata
:endrule

rule:
plugin=vanillaBlocks
number=9
data:
tag:
TAG=10={
TAG=8=blockName{oak_stairs}
TAG=3=meta{1}
TAG=3=buildPass{0}
}
:endtag
:enddata
:endrule

rule:
plugin=vanillaBlocks
number=10
data:
tag:
TAG=10={
TAG=8=blockName{torch}
TAG=3=meta{5}
TAG=3=buildPass{1}
}
:endtag
:enddata
:endrule

rule:
plugin=vanillaBlocks
number=11
data:
tag:
TAG=10={
TAG=8=blockName{stone_slab}
TAG=3=meta{0}
TAG=3=buildPass{0}
}
:endtag
:enddata
:endrule

rule:
plugin=vanillaBlocks
number=12
data:
tag:
TAG=10={
TAG=8=blockName{double_stone_slab}
TAG=3=meta{0}
TAG=3=buildPass{0}
}
:endtag
:enddata
:endrule

rule:
plugin=vanillaBlocks
number=13
data:
tag:
TAG=10={
TAG=8=blockName{torch}
TAG=3=meta{3}
TAG=3=buildPass{1}
}
:endtag
:enddata
:endrule

rule:
plugin=vanillaBlocks
number=14
data:
tag:
TAG=10={
TAG=8=blockName{torch}
TAG=3=meta{4}
TAG=3=buildPass{1}
}
:endtag
:enddata
:endrule

rule:
plugin=vanillaBlocks
number=15
data:
tag:
TAG=10={
TAG=8=blockName{stone_brick_stairs}
TAG=3=meta{3}
TAG=3=buildPass{0}
}
:endtag
:enddata
:endrule

rule:
plugin=vanillaDoors
number=16
data:
tag:
TAG=10={
TAG=1=sideFlag{0}
TAG=8=blockName{wooden_door}
TAG=3=meta{2}
TAG=3=buildPass{1}
}
:endtag
:enddata
:endrule

rule:
plugin=vanillaDoors
number=17
data:
tag:
TAG=10={
TAG=1=sideFlag{0}
TAG=8=blockName{wooden_door}
TAG=3=meta{8}
TAG=3=buildPass{1}
}
:endtag
:enddata
:endrule

rule:
plugin=vanillaBlocks
number=18
data:
tag:
TAG=10={
TAG=8=blockName{stone_brick_stairs}
TAG=3=meta{2}
TAG=3=buildPass{0}
}
:endtag
:enddata
:endrule

rule:
plugin=vanillaBlocks
number=19
data:
tag:
TAG=10={
TAG=8=blockName{oak_stairs}
TAG=3=meta{3}
TAG=3=buildPass{0}
}
:endtag
:enddata
:endrule

rule:
plugin=vanillaBlocks
number=20
data:
tag:
TAG=10={
TAG=8=blockName{oak_stairs}
TAG=3=meta{2}
TAG=3=buildPass{0}
}
:endtag
:enddata
:endrule

rule:
plugin=vanillaBlocks
number=21
data:
tag:
TAG=10={
TAG=8=blockName{glass_pane}
TAG=3=meta{0}
TAG=3=buildPass{0}
}
:endtag
:enddata
:endrule

rule:
plugin=vanillaBlocks
number=22
data:
tag:
TAG=10={
TAG=8=blockName{planks}
TAG=3=meta{0}
TAG=3=buildPass{0}
}
:endtag
:enddata
:endrule

rule:
plugin=vanillaBlocks
number=23
data:
tag:
TAG=10={
TAG=8=blockName{glass}
TAG=3=meta{0}
TAG=3=buildPass{0}
}
:endtag
:enddata
:endrule

rule:
plugin=vanillaBlocks
number=24
data:
tag:
TAG=10={
TAG=8=blockName{stone_brick_stairs}
TAG=3=meta{0}
TAG=3=buildPass{0}
}
:endtag
:enddata
:endrule

rule:
plugin=vanillaBlocks
number=25
data:
tag:
TAG=10={
TAG=8=blockName{torch}
TAG=3=meta{2}
TAG=3=buildPass{1}
}
:endtag
:enddata
:endrule

rule:
plugin=vanillaBlocks
number=26
data:
tag:
TAG=10={
TAG=8=blockName{torch}
TAG=3=meta{1}
TAG=3=buildPass{1}
}
:endtag
:enddata
:endrule

rule:
plugin=vanillaBlocks
number=27
data:
tag:
TAG=10={
TAG=8=blockName{stone_brick_stairs}
TAG=3=meta{1}
TAG=3=buildPass{0}
}
:endtag
:enddata
:endrule

#### ENTITIES ####
