# Ancient Warfare Structure Template File
# auto-generated structure file. created on: 4/14/2014 at: 18:20:7
# Lines beginning with # denote comments

header:
version=2.0
name=CivResourcesWellMOH
size=10,22,10
offset=1,12,8
:endheader

#### VALIDATION ####
validation:
type=ground
survival=false
worldGenEnabled=true
unique=false
preserveBlocks=false
selectionWeight=10
clusterValue=10
minDuplicateDistance=40
dimensionWhiteList=false
dimensionList=
biomeWhiteList=true
biomeList=highlands.meadow,bop.meadow,ebxl.meadow,field,orchard
leveling=9
fill=5
border=5
validTargetBlocks=clay,sand,lapis_ore,grass,lit_redstone_ore,stone,gravel,iron_ore,diamond_ore,stained_hardened_clay,dirt,coal_ore,gold_ore,redstone_ore
data:
:enddata
:endvalidation

#### LAYERS ####
layer: 0
1,1,1,1,1,1,1,1,1,1
1,1,1,1,1,1,1,1,1,1
1,1,1,1,1,1,1,1,1,1
1,1,1,2,2,2,2,1,1,1
1,1,1,2,2,2,2,1,1,1
1,1,1,2,2,2,2,1,1,1
1,1,1,2,2,2,2,1,1,1
1,1,1,1,1,1,1,1,1,1
1,1,1,1,1,1,1,1,1,1
1,1,1,1,1,1,1,1,1,1
:endlayer
layer: 1
1,1,1,1,1,1,1,1,1,1
1,1,1,1,1,1,1,1,1,1
1,1,1,1,1,1,1,1,1,1
1,1,1,2,2,2,2,1,1,1
1,1,1,2,3,3,2,1,1,1
1,1,1,2,3,3,2,1,1,1
1,1,1,2,2,2,2,1,1,1
1,1,1,1,1,1,1,1,1,1
1,1,1,1,1,1,1,1,1,1
1,1,1,1,1,1,1,1,1,1
:endlayer
layer: 2
1,1,1,1,1,1,1,1,1,1
1,1,1,1,1,1,1,1,1,1
1,1,1,1,1,1,1,1,1,1
1,1,1,2,2,2,2,1,1,1
1,1,1,2,3,3,2,1,1,1
1,1,1,2,3,3,2,1,1,1
1,1,1,2,2,2,2,1,1,1
1,1,1,1,1,1,1,1,1,1
1,1,1,1,1,1,1,1,1,1
1,1,1,1,1,1,1,1,1,1
:endlayer
layer: 3
1,1,1,1,1,1,1,1,1,1
1,1,1,1,1,1,1,1,1,1
1,1,1,1,1,1,1,1,1,1
1,1,1,2,2,2,2,1,1,1
1,1,1,2,3,3,2,1,1,1
1,1,1,2,3,3,2,1,1,1
1,1,1,2,2,2,2,1,1,1
1,1,1,1,1,1,1,1,1,1
1,1,1,1,1,1,1,1,1,1
1,1,1,1,1,1,1,1,1,1
:endlayer
layer: 4
1,1,1,1,1,1,1,1,1,1
1,1,1,1,1,1,1,1,1,1
1,1,1,1,1,1,1,1,1,1
1,1,1,2,2,2,2,1,1,1
1,1,1,2,3,3,2,1,1,1
1,1,1,2,3,3,2,1,1,1
1,1,1,2,2,2,2,1,1,1
1,1,1,1,1,1,1,1,1,1
1,1,1,1,1,1,1,1,1,1
1,1,1,1,1,1,1,1,1,1
:endlayer
layer: 5
1,1,1,1,1,1,1,1,1,1
1,1,1,1,1,1,1,1,1,1
1,1,1,1,1,1,1,1,1,1
1,1,1,2,2,2,2,1,1,1
1,1,1,2,3,3,2,1,1,1
1,1,1,2,3,3,2,1,1,1
1,1,1,2,2,2,2,1,1,1
1,1,1,1,1,1,1,1,1,1
1,1,1,1,1,1,1,1,1,1
1,1,1,1,1,1,1,1,1,1
:endlayer
layer: 6
1,1,1,1,1,1,1,1,1,1
1,1,1,1,1,1,1,1,1,1
1,1,1,1,1,1,1,1,1,1
1,1,1,2,2,2,2,1,1,1
1,1,1,2,3,3,2,1,1,1
1,1,1,2,3,3,2,1,1,1
1,1,1,2,2,2,2,1,1,1
1,1,1,1,1,1,1,1,1,1
1,1,1,1,1,1,1,1,1,1
1,1,1,1,1,1,1,1,1,1
:endlayer
layer: 7
1,1,1,1,1,1,1,1,1,1
1,1,1,1,1,1,1,1,1,1
1,1,1,1,1,1,1,1,1,1
1,1,1,2,2,2,2,1,1,1
1,1,1,2,3,3,2,1,1,1
1,1,1,2,3,3,2,1,1,1
1,1,1,2,2,2,2,1,1,1
1,1,1,1,1,1,1,1,1,1
1,1,1,1,1,1,1,1,1,1
1,1,1,1,1,1,1,1,1,1
:endlayer
layer: 8
4,4,4,4,4,4,4,4,4,4
4,4,4,4,4,4,4,4,4,4
4,1,1,1,1,1,1,1,1,4
4,1,1,2,2,2,2,1,1,4
4,1,1,2,3,3,2,1,1,4
4,1,1,2,3,3,2,1,1,4
4,1,1,2,2,2,2,1,1,4
4,1,1,1,1,1,1,1,1,4
4,1,1,1,1,1,1,1,1,4
4,4,4,4,4,4,4,4,4,4
:endlayer
layer: 9
4,4,4,4,4,4,4,4,4,4
4,4,4,4,4,4,4,4,4,4
4,4,1,1,1,1,1,1,4,4
4,4,1,2,2,2,2,1,4,4
4,4,1,2,3,3,2,1,4,4
4,4,1,2,3,3,2,1,4,4
4,4,1,2,2,2,2,1,4,4
4,4,1,1,1,1,1,1,4,4
4,4,4,4,4,4,4,4,4,4
4,4,4,4,4,4,4,4,4,4
:endlayer
layer: 10
4,4,4,4,4,4,4,4,4,4
4,4,4,4,4,4,4,4,4,4
4,4,4,4,4,4,4,4,4,4
4,4,4,2,2,2,2,4,4,4
4,4,4,2,3,3,2,4,4,4
4,4,4,2,3,3,2,4,4,4
4,4,4,2,2,2,2,4,4,4
4,4,4,4,4,4,4,4,4,4
4,4,4,4,4,4,4,4,4,4
4,4,4,4,4,4,4,4,4,4
:endlayer
layer: 11
5,5,5,5,5,5,5,5,5,5
5,6,5,5,5,5,5,5,6,5
5,5,5,5,5,5,5,5,5,5
5,5,5,2,2,2,2,5,5,5
5,5,5,2,3,3,2,5,5,5
5,5,5,2,3,3,2,5,5,5
5,5,5,2,2,2,2,5,5,5
5,5,5,5,5,5,5,5,5,5
5,6,5,5,5,5,5,5,6,5
5,5,5,5,5,5,5,5,5,5
:endlayer
layer: 12
0,0,0,0,0,0,0,0,0,0
0,6,0,0,0,0,0,0,6,0
0,0,0,0,0,0,0,0,0,0
0,0,0,2,2,2,2,0,0,0
0,0,0,2,0,0,2,0,0,0
0,0,0,2,0,0,2,0,0,0
0,0,0,2,2,2,2,0,0,0
0,0,0,0,0,0,0,0,0,0
0,6,0,0,0,0,0,0,6,0
0,0,0,0,0,0,0,0,0,0
:endlayer
layer: 13
0,0,0,0,0,0,0,0,0,0
0,7,0,0,0,0,0,0,7,0
0,0,0,0,0,0,0,0,0,0
0,0,0,8,0,0,8,0,0,0
0,0,0,0,0,0,0,0,0,0
0,0,0,0,0,0,0,0,0,0
0,0,0,8,0,0,8,0,0,0
0,0,0,0,0,0,0,0,0,0
0,7,0,0,0,0,0,0,7,0
0,0,0,0,0,0,0,0,0,0
:endlayer
layer: 14
0,0,0,0,0,0,0,0,0,0
0,0,0,0,0,0,0,0,0,0
0,0,0,0,0,0,0,0,0,0
0,0,0,8,0,0,8,0,0,0
0,0,0,0,0,0,0,0,0,0
0,0,0,0,0,0,0,0,0,0
0,0,0,8,0,0,8,0,0,0
0,0,0,0,0,0,0,0,0,0
0,0,0,0,0,0,0,0,0,0
0,0,0,0,0,0,0,0,0,0
:endlayer
layer: 15
0,0,0,0,0,0,0,0,0,0
0,0,0,0,0,0,0,0,0,0
0,0,9,9,9,9,9,9,0,0
0,0,13,12,0,0,12,10,0,0
0,0,13,0,0,0,0,10,0,0
0,0,13,0,0,0,0,10,0,0
0,0,13,12,0,0,12,10,0,0
0,0,11,11,11,11,11,11,0,0
0,0,0,0,0,0,0,0,0,0
0,0,0,0,0,0,0,0,0,0
:endlayer
layer: 16
0,0,0,0,0,0,0,0,0,0
0,0,0,0,0,0,0,0,0,0
0,0,0,0,0,0,0,0,0,0
0,0,0,9,9,9,10,0,0,0
0,0,0,13,0,0,10,0,0,0
0,0,0,13,0,0,10,0,0,0
0,0,0,13,11,11,11,0,0,0
0,0,0,0,0,0,0,0,0,0
0,0,0,0,0,0,0,0,0,0
0,0,0,0,0,0,0,0,0,0
:endlayer
layer: 17
0,0,0,0,0,0,0,0,0,0
0,0,0,0,0,0,0,0,0,0
0,0,0,0,0,0,0,0,0,0
0,0,0,0,0,0,0,0,0,0
0,0,0,0,9,9,0,0,0,0
0,0,0,0,11,11,0,0,0,0
0,0,0,0,0,0,0,0,0,0
0,0,0,0,0,0,0,0,0,0
0,0,0,0,0,0,0,0,0,0
0,0,0,0,0,0,0,0,0,0
:endlayer
layer: 18
0,0,0,0,0,0,0,0,0,0
0,0,0,0,0,0,0,0,0,0
0,0,0,0,0,0,0,0,0,0
0,0,0,0,0,0,0,0,0,0
0,0,0,0,0,0,0,0,0,0
0,0,0,0,0,0,0,0,0,0
0,0,0,0,0,0,0,0,0,0
0,0,0,0,0,0,0,0,0,0
0,0,0,0,0,0,0,0,0,0
0,0,0,0,0,0,0,0,0,0
:endlayer
layer: 19
0,0,0,0,0,0,0,0,0,0
0,0,0,0,0,0,0,0,0,0
0,0,0,0,0,0,0,0,0,0
0,0,0,0,0,0,0,0,0,0
0,0,0,0,0,0,0,0,0,0
0,0,0,0,0,0,0,0,0,0
0,0,0,0,0,0,0,0,0,0
0,0,0,0,0,0,0,0,0,0
0,0,0,0,0,0,0,0,0,0
0,0,0,0,0,0,0,0,0,0
:endlayer
layer: 20
0,0,0,0,0,0,0,0,0,0
0,0,0,0,0,0,0,0,0,0
0,0,0,0,0,0,0,0,0,0
0,0,0,0,0,0,0,0,0,0
0,0,0,0,0,0,0,0,0,0
0,0,0,0,0,0,0,0,0,0
0,0,0,0,0,0,0,0,0,0
0,0,0,0,0,0,0,0,0,0
0,0,0,0,0,0,0,0,0,0
0,0,0,0,0,0,0,0,0,0
:endlayer
layer: 21
0,0,0,0,0,0,0,0,0,0
0,0,0,0,0,0,0,0,0,0
0,0,0,0,0,0,0,0,0,0
0,0,0,0,0,0,0,0,0,0
0,0,0,0,0,0,0,0,0,0
0,0,0,0,0,0,0,0,0,0
0,0,0,0,0,0,0,0,0,0
0,0,0,0,0,0,0,0,0,0
0,0,0,0,0,0,0,0,0,0
0,0,0,0,0,0,0,0,0,0
:endlayer

#### RULES ####
rule:
plugin=vanillaBlocks
number=1
data:
tag:
TAG=10={
TAG=8=blockName{stone}
TAG=3=meta{0}
TAG=3=buildPass{0}
}
:endtag
:enddata
:endrule

rule:
plugin=vanillaBlocks
number=2
data:
tag:
TAG=10={
TAG=8=blockName{cobblestone}
TAG=3=meta{0}
TAG=3=buildPass{0}
}
:endtag
:enddata
:endrule

rule:
plugin=vanillaBlocks
number=3
data:
tag:
TAG=10={
TAG=8=blockName{water}
TAG=3=meta{0}
TAG=3=buildPass{1}
}
:endtag
:enddata
:endrule

rule:
plugin=vanillaBlocks
number=4
data:
tag:
TAG=10={
TAG=8=blockName{dirt}
TAG=3=meta{0}
TAG=3=buildPass{0}
}
:endtag
:enddata
:endrule

rule:
plugin=vanillaBlocks
number=5
data:
tag:
TAG=10={
TAG=8=blockName{gravel}
TAG=3=meta{0}
TAG=3=buildPass{1}
}
:endtag
:enddata
:endrule

rule:
plugin=vanillaBlocks
number=6
data:
tag:
TAG=10={
TAG=8=blockName{stonebrick}
TAG=3=meta{0}
TAG=3=buildPass{0}
}
:endtag
:enddata
:endrule

rule:
plugin=vanillaBlocks
number=7
data:
tag:
TAG=10={
TAG=8=blockName{torch}
TAG=3=meta{5}
TAG=3=buildPass{1}
}
:endtag
:enddata
:endrule

rule:
plugin=vanillaBlocks
number=8
data:
tag:
TAG=10={
TAG=8=blockName{fence}
TAG=3=meta{0}
TAG=3=buildPass{0}
}
:endtag
:enddata
:endrule

rule:
plugin=vanillaBlocks
number=9
data:
tag:
TAG=10={
TAG=8=blockName{oak_stairs}
TAG=3=meta{2}
TAG=3=buildPass{0}
}
:endtag
:enddata
:endrule

rule:
plugin=vanillaBlocks
number=10
data:
tag:
TAG=10={
TAG=8=blockName{oak_stairs}
TAG=3=meta{1}
TAG=3=buildPass{0}
}
:endtag
:enddata
:endrule

rule:
plugin=vanillaBlocks
number=11
data:
tag:
TAG=10={
TAG=8=blockName{oak_stairs}
TAG=3=meta{3}
TAG=3=buildPass{0}
}
:endtag
:enddata
:endrule

rule:
plugin=vanillaBlocks
number=12
data:
tag:
TAG=10={
TAG=8=blockName{planks}
TAG=3=meta{0}
TAG=3=buildPass{0}
}
:endtag
:enddata
:endrule

rule:
plugin=vanillaBlocks
number=13
data:
tag:
TAG=10={
TAG=8=blockName{oak_stairs}
TAG=3=meta{0}
TAG=3=buildPass{0}
}
:endtag
:enddata
:endrule

#### ENTITIES ####
