# Ancient Warfare Structure Template File
# auto-generated structure file. created on: 4/15/2014 at: 23:25:35
# Lines beginning with # denote comments

header:
version=2.0
name=CivResourcesOpenCastMineWorkingMOH
size=54,122,54
offset=37,69,53
:endheader

#### VALIDATION ####
validation:
type=ground
survival=false
worldGenEnabled=true
unique=true
preserveBlocks=false
selectionWeight=50
clusterValue=501
minDuplicateDistance=1
dimensionWhiteList=false
dimensionList=
biomeWhiteList=true
biomeList=highlands_lowlands,highlands_woodlands,moor,heathland,dead forest,woodland,forest,birch forest
leveling=42
fill=9
border=9
validTargetBlocks=bedrock,clay,lapis_ore,lit_redstone_ore,stone,carpet,tile.bop.mud,gravel,coal_block,diamond_ore,tile.bop.generic.crag_rock,ice,snow,netherrack,tile.bop.generic.hard_dirt,tile.bop.redRocks,dirt,redstone_ore,mycelium,tile.bop.holyStone,bedrock,sand,grass,tile.bop.ash,tile.MoCDirt,iron_ore,tile.bop.originGrass,snow_layer,soul_sand,tile.bop.generic.dried_dirt,stained_hardened_clay,tile.bop.generic.ash_stone,tile.bop.generic.hard_ice,coal_ore,gold_ore,tile.bop.generic.hard_sand
data:
:enddata
:endvalidation

#### LAYERS ####
layer: 0
1,1,1,1,1,1,1,1,1,1,1,1,1,1,1,1,1,1,1,1,1,1,1,1,1,1,1,1,1,1,1,1,1,1,1,1,1,1,1,1,1,1,1,1,1,1,1,1,1,1,1,1,1,1
1,1,1,1,1,1,1,1,1,1,1,1,1,1,1,1,1,1,1,1,1,1,1,1,1,1,1,1,1,1,1,1,1,1,1,1,1,1,1,1,1,1,1,1,1,1,1,1,1,1,1,1,1,1
1,1,1,1,1,1,1,1,1,1,1,1,1,1,1,1,1,1,1,1,1,1,1,1,1,1,1,1,1,1,1,1,1,1,1,1,1,1,1,1,1,1,1,1,1,1,1,1,1,1,1,1,1,1
1,1,1,1,1,1,1,1,1,1,1,1,1,1,1,1,1,1,1,1,1,1,1,1,1,1,1,1,1,1,1,1,1,1,1,1,1,1,1,1,1,1,1,1,1,1,1,1,1,1,1,1,1,1
1,1,1,1,1,1,1,1,1,1,1,1,1,1,1,1,1,1,1,1,1,1,1,1,1,1,1,1,1,1,1,1,1,1,1,1,1,1,1,1,1,1,1,1,1,1,1,1,1,1,1,1,1,1
1,1,1,1,1,1,1,1,1,1,1,1,1,1,1,1,1,1,1,1,1,1,1,1,1,1,1,1,1,1,1,1,1,1,1,1,1,1,1,1,1,1,1,1,1,1,1,1,1,1,1,1,1,1
1,1,1,1,1,1,1,1,1,1,1,1,1,1,1,1,1,1,1,1,1,1,1,1,1,1,1,1,1,1,1,1,1,1,1,1,1,1,1,1,1,1,1,1,1,1,1,1,1,1,1,1,1,1
1,1,1,1,1,1,1,1,1,1,1,1,1,1,1,1,1,1,1,1,1,1,1,1,1,1,1,1,1,1,1,1,1,1,1,1,1,1,1,1,1,1,1,1,1,1,1,1,1,1,1,1,1,1
1,1,1,1,1,1,1,1,1,1,1,1,1,1,1,1,1,1,1,1,1,1,1,1,1,1,1,1,1,1,1,1,1,1,1,1,1,1,1,1,1,1,1,1,1,1,1,1,1,1,1,1,1,1
1,1,1,1,1,1,1,1,1,1,1,1,1,1,1,1,1,1,1,1,1,1,1,1,1,1,1,1,1,1,1,1,1,1,1,1,1,1,1,1,1,1,1,1,1,1,1,1,1,1,1,1,1,1
1,1,1,1,1,1,1,1,1,1,1,1,1,1,1,1,1,1,1,1,1,1,1,1,1,1,1,1,1,1,1,1,1,1,1,1,1,1,1,1,1,1,1,1,1,1,1,1,1,1,1,1,1,1
1,1,1,1,1,1,1,1,1,1,1,1,1,1,1,1,1,1,1,1,1,1,1,1,1,1,1,1,1,1,1,1,1,1,1,1,1,1,1,1,1,1,1,1,1,1,1,1,1,1,1,1,1,1
1,1,1,1,1,1,1,1,1,1,1,1,1,1,1,1,1,1,1,1,1,1,1,1,1,1,1,1,1,1,1,1,1,1,1,1,1,1,1,1,1,1,1,1,1,1,1,1,1,1,1,1,1,1
1,1,1,1,1,1,1,1,1,1,1,1,1,1,1,1,1,1,1,1,1,1,1,1,1,1,1,1,1,1,1,1,1,1,1,1,1,1,1,1,1,1,1,1,1,1,1,1,1,1,1,1,1,1
1,1,1,1,1,1,1,1,1,1,1,1,1,1,1,1,1,1,1,1,1,1,1,1,1,1,1,1,1,1,1,1,1,1,1,1,1,1,1,1,1,1,1,1,1,1,1,1,1,1,1,1,1,1
1,1,1,1,1,1,1,1,1,1,1,1,1,1,1,1,1,1,1,1,1,1,1,1,1,1,1,1,1,1,1,1,1,1,1,1,1,1,1,1,1,1,1,1,1,1,1,1,1,1,1,1,1,1
1,1,1,1,1,1,1,1,1,1,1,1,1,1,1,1,1,1,1,1,1,1,1,1,1,1,1,1,1,1,1,1,1,1,1,1,1,1,1,1,1,1,1,1,1,1,1,1,1,1,1,1,1,1
1,1,1,1,1,1,1,1,1,1,1,1,1,1,1,1,1,1,1,1,1,1,1,1,1,1,1,1,1,1,1,1,1,1,1,1,1,1,1,1,1,1,1,1,1,1,1,1,1,1,1,1,1,1
1,1,1,1,1,1,1,1,1,1,1,1,1,1,1,1,1,1,1,1,1,1,1,1,1,1,1,1,1,1,1,1,1,1,1,1,1,1,1,1,1,1,1,1,1,1,1,1,1,1,1,1,1,1
1,1,1,1,1,1,1,1,1,1,1,1,1,1,1,1,1,1,1,1,1,1,1,1,1,1,1,1,1,1,1,1,1,1,1,1,1,1,1,1,1,1,1,1,1,1,1,1,1,1,1,1,1,1
1,1,1,1,1,1,1,1,1,1,1,1,1,1,1,1,1,1,1,1,1,1,1,1,1,1,1,1,1,1,1,1,1,1,1,1,1,1,1,1,1,1,1,1,1,1,1,1,1,1,1,1,1,1
1,1,1,1,1,1,1,1,1,1,1,1,1,1,1,1,1,1,1,1,1,1,1,1,1,1,1,1,1,1,1,1,1,1,1,1,1,1,1,1,1,1,1,1,1,1,1,1,1,1,1,1,1,1
1,1,1,1,1,1,1,1,1,1,1,1,1,1,1,1,1,1,1,1,1,1,1,1,1,1,1,1,1,1,1,1,1,1,1,1,1,1,1,1,1,1,1,1,1,1,1,1,1,1,1,1,1,1
1,1,1,1,1,1,1,1,1,1,1,1,1,1,1,1,1,1,1,1,1,1,1,1,1,1,1,1,1,1,1,1,1,1,1,1,1,1,1,1,1,1,1,1,1,1,1,1,1,1,1,1,1,1
1,1,1,1,1,1,1,1,1,1,1,1,1,1,1,1,1,1,1,1,1,1,1,1,1,1,1,1,1,1,1,1,1,1,1,1,1,1,1,1,1,1,1,1,1,1,1,1,1,1,1,1,1,1
1,1,1,1,1,1,1,1,1,1,1,1,1,1,1,1,1,1,1,1,1,1,1,1,1,1,1,1,1,1,1,1,1,1,1,1,1,1,1,1,1,1,1,1,1,1,1,1,1,1,1,1,1,1
1,1,1,1,1,1,1,1,1,1,1,1,1,1,1,1,1,1,1,1,1,1,1,1,1,1,1,1,1,1,1,1,1,1,1,1,1,1,1,1,1,1,1,1,1,1,1,1,1,1,1,1,1,1
1,1,1,1,1,1,1,1,1,1,1,1,1,1,1,1,1,1,1,1,1,1,1,1,1,1,1,1,1,1,1,1,1,1,1,1,1,1,1,1,1,1,1,1,1,1,1,1,1,1,1,1,1,1
1,1,1,1,1,1,1,1,1,1,1,1,1,1,1,1,1,1,1,1,1,1,1,1,1,1,1,1,1,1,1,1,1,1,1,1,1,1,1,1,1,1,1,1,1,1,1,1,1,1,1,1,1,1
1,1,1,1,1,1,1,1,1,1,1,1,1,1,1,1,1,1,1,1,1,1,1,1,1,1,1,1,1,1,1,1,1,1,1,1,1,1,1,1,1,1,1,1,1,1,1,1,1,1,1,1,1,1
1,1,1,1,1,1,1,1,1,1,1,1,1,1,1,1,1,1,1,1,1,1,1,1,1,1,1,1,1,1,1,1,1,1,1,1,1,1,1,1,1,1,1,1,1,1,1,1,1,1,1,1,1,1
1,1,1,1,1,1,1,1,1,1,1,1,1,1,1,1,1,1,1,1,1,1,1,1,1,1,1,1,1,1,1,1,1,1,1,1,1,1,1,1,1,1,1,1,1,1,1,1,1,1,1,1,1,1
1,1,1,1,1,1,1,1,1,1,1,1,1,1,1,1,1,1,1,1,1,1,1,1,1,1,1,1,1,1,1,1,1,1,1,1,1,1,1,1,1,1,1,1,1,1,1,1,1,1,1,1,1,1
1,1,1,1,1,1,1,1,1,1,1,1,1,1,1,1,1,1,1,1,1,1,1,1,1,1,1,1,1,1,1,1,1,1,1,1,1,1,1,1,1,1,1,1,1,1,1,1,1,1,1,1,1,1
1,1,1,1,1,1,1,1,1,1,1,1,1,1,1,1,1,1,1,1,1,1,1,1,1,1,1,1,1,1,1,1,1,1,1,1,1,1,1,1,1,1,1,1,1,1,1,1,1,1,1,1,1,1
1,1,1,1,1,1,1,1,1,1,1,1,1,1,1,1,1,1,1,1,1,1,1,1,1,1,1,1,1,1,1,1,1,1,1,1,1,1,1,1,1,1,1,1,1,1,1,1,1,1,1,1,1,1
1,1,1,1,1,1,1,1,1,1,1,1,1,1,1,1,1,1,1,1,1,1,1,1,1,1,1,1,1,1,1,1,1,1,1,1,1,1,1,1,1,1,1,1,1,1,1,1,1,1,1,1,1,1
1,1,1,1,1,1,1,1,1,1,1,1,1,1,1,1,1,1,1,1,1,1,1,1,1,1,1,1,1,1,1,1,1,1,1,1,1,1,1,1,1,1,1,1,1,1,1,1,1,1,1,1,1,1
1,1,1,1,1,1,1,1,1,1,1,1,1,1,1,1,1,1,1,1,1,1,1,1,1,1,1,1,1,1,1,1,1,1,1,1,1,1,1,1,1,1,1,1,1,1,1,1,1,1,1,1,1,1
1,1,1,1,1,1,1,1,1,1,1,1,1,1,1,1,1,1,1,1,1,1,1,1,1,1,1,1,1,1,1,1,1,1,1,1,1,1,1,1,1,1,1,1,1,1,1,1,1,1,1,1,1,1
1,1,1,1,1,1,1,1,1,1,1,1,1,1,1,1,1,1,1,1,1,1,1,1,1,1,1,1,1,1,1,1,1,1,1,1,1,1,1,1,1,1,1,1,1,1,1,1,1,1,1,1,1,1
1,1,1,1,1,1,1,1,1,1,1,1,1,1,1,1,1,1,1,1,1,1,1,1,1,1,1,1,1,1,1,1,1,1,1,1,1,1,1,1,1,1,1,1,1,1,1,1,1,1,1,1,1,1
1,1,1,1,1,1,1,1,1,1,1,1,1,1,1,1,1,1,1,1,1,1,1,1,1,1,1,1,1,1,1,1,1,1,1,1,1,1,1,1,1,1,1,1,1,1,1,1,1,1,1,1,1,1
1,1,1,1,1,1,1,1,1,1,1,1,1,1,1,1,1,1,1,1,1,1,1,1,1,1,1,1,1,1,1,1,1,1,1,1,1,1,1,1,1,1,1,1,1,1,1,1,1,1,1,1,1,1
1,1,1,1,1,1,1,1,1,1,1,1,1,1,1,1,1,1,1,1,1,1,1,1,1,1,1,1,1,1,1,1,1,1,1,1,1,1,1,1,1,1,1,1,1,1,1,1,1,1,1,1,1,1
1,1,1,1,1,1,1,1,1,1,1,1,1,1,1,1,1,1,1,1,1,1,1,1,1,1,1,1,1,1,1,1,1,1,1,1,1,1,1,1,1,1,1,1,1,1,1,1,1,1,1,1,1,1
1,1,1,1,1,1,1,1,1,1,1,1,1,1,1,1,1,1,1,1,1,1,1,1,1,1,1,1,1,1,1,1,1,1,1,1,1,1,1,1,1,1,1,1,1,1,1,1,1,1,1,1,1,1
1,1,1,1,1,1,1,1,1,1,1,1,1,1,1,1,1,1,1,1,1,1,1,1,1,1,1,1,1,1,1,1,1,1,1,1,1,1,1,1,1,1,1,1,1,1,1,1,1,1,1,1,1,1
1,1,1,1,1,1,1,1,1,1,1,1,1,1,1,1,1,1,1,1,1,1,1,1,1,1,1,1,1,1,1,1,1,1,1,1,1,1,1,1,1,1,1,1,1,1,1,1,1,1,1,1,1,1
1,1,1,1,1,1,1,1,1,1,1,1,1,1,1,1,1,1,1,1,1,1,1,1,1,1,1,1,1,1,1,1,1,1,1,1,1,1,1,1,1,1,1,1,1,1,1,1,1,1,1,1,1,1
1,1,1,1,1,1,1,1,1,1,1,1,1,1,1,1,1,1,1,1,1,1,1,1,1,1,1,1,1,1,1,1,1,1,1,1,1,1,1,1,1,1,1,1,1,1,1,1,1,1,1,1,1,1
1,1,1,1,1,1,1,1,1,1,1,1,1,1,1,1,1,1,1,1,1,1,1,1,1,1,1,1,1,1,1,1,1,1,1,1,1,1,1,1,1,1,1,1,1,1,1,1,1,1,1,1,1,1
1,1,1,1,1,1,1,1,1,1,1,1,1,1,1,1,1,1,1,1,1,1,1,1,1,1,1,1,1,1,1,1,1,1,1,1,1,1,1,1,1,1,1,1,1,1,1,1,1,1,1,1,1,1
1,1,1,1,1,1,1,1,1,1,1,1,1,1,1,1,1,1,1,1,1,1,1,1,1,1,1,1,1,1,1,1,1,1,1,1,1,1,1,1,1,1,1,1,1,1,1,1,1,1,1,1,1,1
:endlayer
layer: 1
1,1,1,1,1,1,1,1,1,1,1,1,1,1,1,1,1,1,1,1,1,1,1,1,1,1,1,1,1,1,1,1,1,1,1,1,1,1,1,1,1,1,1,1,1,1,1,1,1,1,1,1,1,1
1,1,1,1,1,1,1,1,1,1,1,1,1,1,1,1,1,1,1,1,1,1,1,1,1,1,1,1,1,1,1,1,1,1,1,1,1,1,1,1,1,1,1,1,1,1,1,1,1,1,1,1,1,1
1,1,1,1,1,1,1,1,1,1,1,1,1,1,1,1,1,1,1,1,1,1,1,1,1,1,1,1,1,1,1,1,1,1,1,1,1,1,1,1,1,1,1,1,1,1,1,1,1,1,1,1,1,1
1,1,1,1,1,1,1,1,1,1,1,1,1,1,1,1,1,1,1,1,1,1,1,1,1,1,1,1,1,1,1,1,1,1,1,1,1,1,1,1,1,1,1,1,1,1,1,1,1,1,1,1,1,1
1,1,1,1,1,1,1,1,1,1,1,1,1,1,1,1,1,1,1,1,1,1,1,1,1,1,1,1,1,1,1,1,1,1,1,1,1,1,1,1,1,1,1,1,1,1,1,1,1,1,1,1,1,1
1,1,1,1,1,1,1,1,1,1,1,1,1,1,1,1,1,1,1,1,1,1,1,1,1,1,1,1,1,1,1,1,1,1,1,1,1,1,1,1,1,1,1,1,1,1,1,1,1,1,1,1,1,1
1,1,1,1,1,1,1,1,1,1,1,1,1,1,1,1,1,1,1,1,1,1,1,1,1,1,1,1,1,1,1,1,1,1,1,1,1,1,1,1,1,1,1,1,1,1,1,1,1,1,1,1,1,1
1,1,1,1,1,1,1,1,1,1,1,1,1,1,1,1,1,1,1,1,1,1,1,1,1,1,1,1,1,1,1,1,1,1,1,1,1,1,1,1,1,1,1,1,1,1,1,1,1,1,1,1,1,1
1,1,1,1,1,1,1,1,1,1,1,1,1,1,1,1,1,1,1,1,1,1,1,1,1,1,1,1,1,1,1,1,1,1,1,1,1,1,1,1,1,1,1,1,1,1,1,1,1,1,1,1,1,1
1,1,1,1,1,1,1,1,1,1,1,1,1,1,1,1,1,1,1,1,1,1,1,1,1,1,1,1,1,1,1,1,1,1,1,1,1,1,1,1,1,1,1,1,1,1,1,1,1,1,1,1,1,1
1,1,1,1,1,1,1,1,1,1,1,1,1,1,1,1,1,1,1,1,1,1,1,1,1,1,1,1,1,1,1,1,1,1,1,1,1,1,1,1,1,1,1,1,1,1,1,1,1,1,1,1,1,1
1,1,1,1,1,1,1,1,1,1,1,1,1,1,1,1,1,1,1,1,1,1,1,1,1,1,1,1,1,1,1,1,1,1,1,1,1,1,1,1,1,1,1,1,1,1,1,1,1,1,1,1,1,1
1,1,1,1,1,1,1,1,1,1,1,1,1,1,1,1,1,1,1,1,1,1,1,1,1,1,1,1,1,1,1,1,1,1,1,1,1,1,1,1,1,1,1,1,1,1,1,1,1,1,1,1,1,1
1,1,1,1,1,1,1,1,1,1,1,1,1,1,1,1,1,1,1,1,1,1,1,1,1,1,1,1,1,1,1,1,1,1,1,1,1,1,1,1,1,1,1,1,1,1,1,1,1,1,1,1,1,1
1,1,1,1,1,1,1,1,1,1,1,1,1,1,1,1,1,1,1,1,1,1,1,1,1,1,1,1,1,1,1,1,1,1,1,1,1,1,1,1,1,1,1,1,1,1,1,1,1,1,1,1,1,1
1,1,1,1,1,1,1,1,1,1,1,1,1,1,1,1,1,1,1,1,1,1,1,1,1,1,1,1,1,1,1,1,1,1,1,1,1,1,1,1,1,1,1,1,1,1,1,1,1,1,1,1,1,1
1,1,1,1,1,1,1,1,1,1,1,1,1,1,1,1,1,1,1,1,1,1,1,1,1,1,1,1,1,1,1,1,1,1,1,1,1,1,1,1,1,1,1,1,1,1,1,1,1,1,1,1,1,1
1,1,1,1,1,1,1,1,1,1,1,1,1,1,1,1,1,1,1,1,1,1,1,1,1,1,1,1,1,1,1,1,1,1,1,1,1,1,1,1,1,1,1,1,1,1,1,1,1,1,1,1,1,1
1,1,1,1,1,1,1,1,1,1,1,1,1,1,1,1,1,1,1,1,1,1,1,1,1,1,1,1,1,1,1,1,1,1,1,1,1,1,1,1,1,1,1,1,1,1,1,1,1,1,1,1,1,1
1,1,1,1,1,1,1,1,1,1,1,1,1,1,1,1,1,1,1,1,1,1,1,1,1,1,1,1,1,1,1,1,1,1,1,1,1,1,1,1,1,1,1,1,1,1,1,1,1,1,1,1,1,1
1,1,1,1,1,1,1,1,1,1,1,1,1,1,1,1,1,1,1,1,1,1,1,1,1,1,1,1,1,1,1,1,1,1,1,1,1,1,1,1,1,1,1,1,1,1,1,1,1,1,1,1,1,1
1,1,1,1,1,1,1,1,1,1,1,1,1,1,1,1,1,1,1,1,1,1,1,1,1,1,1,1,1,1,1,1,1,1,1,1,1,1,1,1,1,1,1,1,1,1,1,1,1,1,1,1,1,1
1,1,1,1,1,1,1,1,1,1,1,1,1,1,1,1,1,1,1,1,1,1,1,1,1,1,1,1,1,1,1,1,1,1,1,1,1,1,1,1,1,1,1,1,1,1,1,1,1,1,1,1,1,1
1,1,1,1,1,1,1,1,1,1,1,1,1,1,1,1,1,1,1,1,1,1,1,1,1,1,1,1,1,1,1,1,1,1,1,1,1,1,1,1,1,1,1,1,1,1,1,1,1,1,1,1,1,1
1,1,1,1,1,1,1,1,1,1,1,1,1,1,1,1,1,1,1,1,1,1,1,1,1,1,1,1,1,1,1,1,1,1,1,1,1,1,1,1,1,1,1,1,1,1,1,1,1,1,1,1,1,1
1,1,1,1,1,1,1,1,1,1,1,1,1,1,1,1,1,1,1,1,1,1,1,1,1,1,1,1,1,1,1,1,1,1,1,1,1,1,1,1,1,1,1,1,1,1,1,1,1,1,1,1,1,1
1,1,1,1,1,1,1,1,1,1,1,1,1,1,1,1,1,1,1,1,1,1,1,1,1,1,1,1,1,1,1,1,1,1,1,1,1,1,1,1,1,1,1,1,1,1,1,1,1,1,1,1,1,1
1,1,1,1,1,1,1,1,1,1,1,1,1,1,1,1,1,1,1,1,1,1,1,1,1,1,1,1,1,1,1,1,1,1,1,1,1,1,1,1,1,1,1,1,1,1,1,1,1,1,1,1,1,1
1,1,1,1,1,1,1,1,1,1,1,1,1,1,1,1,1,1,1,1,1,1,1,1,1,1,1,1,1,1,1,1,1,1,1,1,1,1,1,1,1,1,1,1,1,1,1,1,1,1,1,1,1,1
1,1,1,1,1,1,1,1,1,1,1,1,1,1,1,1,1,1,1,1,1,1,1,1,1,1,1,1,1,1,1,1,1,1,1,1,1,1,1,1,1,1,1,1,1,1,1,1,1,1,1,1,1,1
1,1,1,1,1,1,1,1,1,1,1,1,1,1,1,1,1,1,1,1,1,1,1,1,1,1,1,1,1,1,1,1,1,1,1,1,1,1,1,1,1,1,1,1,1,1,1,1,1,1,1,1,1,1
1,1,1,1,1,1,1,1,1,1,1,1,1,1,1,1,1,1,1,1,1,1,1,1,1,1,1,1,1,1,1,1,1,1,1,1,1,1,1,1,1,1,1,1,1,1,1,1,1,1,1,1,1,1
1,1,1,1,1,1,1,1,1,1,1,1,1,1,1,1,1,1,1,1,1,1,1,1,1,1,1,1,1,1,1,1,1,1,1,1,1,1,1,1,1,1,1,1,1,1,1,1,1,1,1,1,1,1
1,1,1,1,1,1,1,1,1,1,1,1,1,1,1,1,1,1,1,1,1,1,1,1,1,1,1,1,1,1,1,1,1,1,1,1,1,1,1,1,1,1,1,1,1,1,1,1,1,1,1,1,1,1
1,1,1,1,1,1,1,1,1,1,1,1,1,1,1,1,1,1,1,1,1,1,1,1,1,1,1,1,1,1,1,1,1,1,1,1,1,1,1,1,1,1,1,1,1,1,1,1,1,1,1,1,1,1
1,1,1,1,1,1,1,1,1,1,1,1,1,1,1,1,1,1,1,1,1,1,1,1,1,1,1,1,1,1,1,1,1,1,1,1,1,1,1,1,1,1,1,1,1,1,1,1,1,1,1,1,1,1
1,1,1,1,1,1,1,1,1,1,1,1,1,1,1,1,1,1,1,1,1,1,1,1,1,1,1,1,1,1,1,1,1,1,1,1,1,1,1,1,1,1,1,1,1,1,1,1,1,1,1,1,1,1
1,1,1,1,1,1,1,1,1,1,1,1,1,1,1,1,1,1,1,1,1,1,1,1,1,1,1,1,1,1,1,1,1,1,1,1,1,1,1,1,1,1,1,1,1,1,1,1,1,1,1,1,1,1
1,1,1,1,1,1,1,1,1,1,1,1,1,1,1,1,1,1,1,1,1,1,1,1,1,1,1,1,1,1,1,1,1,1,1,1,1,1,1,1,1,1,1,1,1,1,1,1,1,1,1,1,1,1
1,1,1,1,1,1,1,1,1,1,1,1,1,1,1,1,1,1,1,1,1,1,1,1,1,1,1,1,1,1,1,1,1,1,1,1,1,1,1,1,1,1,1,1,1,1,1,1,1,1,1,1,1,1
1,1,1,1,1,1,1,1,1,1,1,1,1,1,1,1,1,1,1,1,1,1,1,1,1,1,1,1,1,1,1,1,1,1,1,1,1,1,1,1,1,1,1,1,1,1,1,1,1,1,1,1,1,1
1,1,1,1,1,1,1,1,1,1,1,1,1,1,1,1,1,1,1,1,1,1,1,1,1,1,1,1,1,1,1,1,1,1,1,1,1,1,1,1,1,1,1,1,1,1,1,1,1,1,1,1,1,1
1,1,1,1,1,1,1,1,1,1,1,1,1,1,1,1,1,1,1,1,1,1,1,1,1,1,1,1,1,1,1,1,1,1,1,1,1,1,1,1,1,1,1,1,1,1,1,1,1,1,1,1,1,1
1,1,1,1,1,1,1,1,1,1,1,1,1,1,1,1,1,1,1,1,1,1,1,1,1,1,1,1,1,1,1,1,1,1,1,1,1,1,1,1,1,1,1,1,1,1,1,1,1,1,1,1,1,1
1,1,1,1,1,1,1,1,1,1,1,1,1,1,1,1,1,1,1,1,1,1,1,1,1,1,1,1,1,1,1,1,1,1,1,1,1,1,1,1,1,1,1,1,1,1,1,1,1,1,1,1,1,1
1,1,1,1,1,1,1,1,1,1,1,1,1,1,1,1,1,1,1,1,1,1,1,1,1,1,1,1,1,1,1,1,1,1,1,1,1,1,1,1,1,1,1,1,1,1,1,1,1,1,1,1,1,1
1,1,1,1,1,1,1,1,1,1,1,1,1,1,1,1,1,1,1,1,1,1,1,1,1,1,1,1,1,1,1,1,1,1,1,1,1,1,1,1,1,1,1,1,1,1,1,1,1,1,1,1,1,1
1,1,1,1,1,1,1,1,1,1,1,1,1,1,1,1,1,1,1,1,1,1,1,1,1,1,1,1,1,1,1,1,1,1,1,1,1,1,1,1,1,1,1,1,1,1,1,1,1,1,1,1,1,1
1,1,1,1,1,1,1,1,1,1,1,1,1,1,1,1,1,1,1,1,1,1,1,1,1,1,1,1,1,1,1,1,1,1,1,1,1,1,1,1,1,1,1,1,1,1,1,1,1,1,1,1,1,1
1,1,1,1,1,1,1,1,1,1,1,1,1,1,1,1,1,1,1,1,1,1,1,1,1,1,1,1,1,1,1,1,1,1,1,1,1,1,1,1,1,1,1,1,1,1,1,1,1,1,1,1,1,1
1,1,1,1,1,1,1,1,1,1,1,1,1,1,1,1,1,1,1,1,1,1,1,1,1,1,1,1,1,1,1,1,1,1,1,1,1,1,1,1,1,1,1,1,1,1,1,1,1,1,1,1,1,1
1,1,1,1,1,1,1,1,1,1,1,1,1,1,1,1,1,1,1,1,1,1,1,1,1,1,1,1,1,1,1,1,1,1,1,1,1,1,1,1,1,1,1,1,1,1,1,1,1,1,1,1,1,1
1,1,1,1,1,1,1,1,1,1,1,1,1,1,1,1,1,1,1,1,1,1,1,1,1,1,1,1,1,1,1,1,1,1,1,1,1,1,1,1,1,1,1,1,1,1,1,1,1,1,1,1,1,1
1,1,1,1,1,1,1,1,1,1,1,1,1,1,1,1,1,1,1,1,1,1,1,1,1,1,1,1,1,1,1,1,1,1,1,1,1,1,1,1,1,1,1,1,1,1,1,1,1,1,1,1,1,1
:endlayer
layer: 2
1,1,1,1,1,2,2,2,2,2,1,1,2,1,2,1,1,2,2,2,2,3,2,1,1,1,1,1,1,2,1,2,1,3,2,1,2,2,1,2,1,1,2,1,2,2,2,2,2,2,1,2,1,1
1,1,1,1,1,2,1,1,1,2,2,1,2,2,2,2,2,1,1,2,1,1,2,2,2,1,1,2,1,1,1,2,1,3,2,1,2,1,2,2,2,2,1,2,1,2,2,1,2,1,1,1,1,2
1,1,1,1,1,1,2,2,2,1,2,1,2,1,1,1,2,2,2,2,1,2,1,2,1,2,1,2,2,2,1,1,2,1,2,2,1,2,1,1,2,2,2,2,1,1,2,1,1,1,2,1,1,1
1,1,1,1,1,1,2,2,1,2,1,2,2,1,2,2,2,2,1,1,2,2,1,1,1,2,2,2,2,1,1,2,1,1,1,2,1,1,2,1,2,2,2,2,2,1,1,2,1,2,2,4,4,1
1,1,1,1,1,1,2,2,2,1,1,1,1,1,2,2,2,2,2,2,2,1,1,1,2,1,1,2,1,2,2,1,2,2,2,1,1,2,2,1,2,1,2,1,2,2,2,1,1,1,1,4,4,2
1,1,1,1,1,5,6,1,1,1,5,1,1,6,6,6,1,6,1,1,2,1,1,1,2,1,1,1,2,2,1,1,2,2,6,6,6,1,7,1,7,1,2,1,2,1,2,1,1,2,2,1,1,2
1,1,1,1,1,1,5,1,1,5,1,1,1,6,6,1,6,6,1,1,6,1,1,2,2,2,2,1,2,2,2,2,2,2,6,6,6,7,1,1,7,1,7,1,1,2,2,2,1,2,2,1,1,1
1,1,1,1,1,5,1,2,5,5,1,5,6,1,1,6,1,1,1,1,6,6,1,6,2,2,1,2,2,2,2,1,2,1,6,6,6,7,7,1,7,7,7,7,2,1,2,1,1,1,1,2,2,2
1,1,1,1,1,2,1,1,1,1,1,1,1,6,2,6,1,6,6,1,1,6,6,1,1,6,1,1,1,1,1,6,6,1,6,6,1,7,1,1,1,7,7,2,2,1,2,2,2,1,2,1,1,1
1,1,1,1,1,1,1,2,1,1,2,2,1,1,2,1,1,2,2,6,6,6,1,6,6,1,6,1,6,6,6,1,6,6,6,1,6,1,6,2,1,2,1,1,2,1,2,1,2,2,2,2,2,1
1,1,1,1,1,2,2,1,1,2,2,1,2,1,1,2,2,1,1,2,2,1,6,6,6,6,6,1,6,1,6,6,6,6,6,1,6,6,6,1,2,2,2,2,2,1,1,2,1,1,2,2,2,2
1,1,1,1,1,2,1,2,1,2,1,2,1,2,1,1,1,2,2,2,1,2,1,2,1,1,2,6,6,6,1,6,6,1,6,6,6,6,4,6,1,2,2,2,2,1,1,1,2,1,2,2,2,1
1,1,1,1,1,1,1,2,2,1,2,2,2,1,1,2,2,1,2,2,1,2,2,2,2,2,2,2,2,2,2,2,2,1,1,6,6,6,4,1,6,6,2,2,1,1,1,2,2,2,1,2,2,1
1,1,1,1,1,1,1,2,2,1,1,2,1,1,2,1,1,2,2,2,2,2,2,2,2,1,2,1,2,1,2,2,2,1,1,1,6,6,1,2,1,6,6,2,2,1,1,1,1,2,1,2,2,1
1,1,1,1,1,2,2,2,2,1,2,1,2,1,1,1,2,1,1,1,2,2,1,1,2,2,1,1,1,2,1,1,2,2,6,6,6,6,2,2,2,2,1,1,2,1,2,2,1,1,2,2,1,1
1,1,1,1,1,1,1,2,2,1,2,2,2,1,1,2,2,2,1,1,2,2,2,1,2,1,2,2,1,2,1,2,1,1,1,1,6,1,6,2,1,2,2,1,1,2,1,1,1,2,1,2,1,2
1,1,1,1,1,2,2,2,2,2,2,1,2,2,2,2,1,1,2,1,2,1,1,2,2,1,1,2,1,1,1,2,2,2,2,6,1,6,6,2,1,1,1,6,1,2,1,2,2,2,1,2,2,2
1,1,1,1,1,2,2,2,2,2,2,2,2,1,1,2,2,2,2,1,2,1,1,1,2,2,1,1,1,2,2,2,2,2,2,6,1,1,6,2,2,2,1,2,1,1,2,1,2,2,2,1,1,2
1,1,1,1,1,1,1,1,2,2,2,2,2,2,1,2,1,1,1,1,2,2,1,2,1,2,2,1,1,1,2,2,2,2,2,2,6,1,6,1,2,1,1,2,2,2,2,1,1,2,2,2,2,1
1,1,1,1,1,1,2,1,1,1,2,2,1,1,2,2,1,1,2,2,1,2,2,1,2,2,2,2,2,1,2,2,1,2,2,2,6,6,1,2,1,2,1,4,1,6,4,2,6,1,1,2,2,1
1,1,1,1,1,8,1,1,1,1,2,1,2,1,1,2,1,1,2,1,1,2,2,2,1,2,2,1,1,2,1,2,1,2,3,3,2,2,2,2,2,1,1,1,4,4,4,2,1,1,1,2,2,2
1,1,1,1,1,1,6,6,9,2,1,2,2,10,2,2,2,1,2,1,1,2,1,2,2,1,2,2,1,4,1,7,1,1,3,3,2,2,1,2,1,2,2,2,1,1,2,1,1,6,1,2,1,2
1,1,1,1,1,6,1,6,1,2,2,2,2,2,1,1,1,1,2,1,2,1,2,1,2,2,2,2,1,7,7,1,7,2,1,2,2,2,2,1,2,1,2,1,6,1,1,1,3,2,2,3,2,2
1,1,1,1,1,6,2,1,2,2,2,1,2,2,1,1,1,2,1,2,1,1,2,2,1,2,2,2,2,1,1,7,1,1,2,2,1,2,2,2,1,1,2,1,1,6,2,3,3,1,2,2,2,1
1,1,1,1,1,6,1,2,1,2,1,1,2,2,1,2,2,1,2,2,1,1,1,1,2,2,1,1,1,7,1,7,7,2,2,1,2,2,2,2,2,1,1,2,6,6,1,2,2,2,2,2,1,1
1,1,1,1,1,1,2,2,2,1,1,2,2,2,1,2,2,2,1,1,2,1,2,2,2,2,2,2,2,7,7,7,1,1,2,2,1,1,2,2,6,1,6,6,6,6,1,2,2,1,2,2,6,6
1,1,1,1,1,1,2,2,1,2,1,1,1,2,1,2,2,2,2,1,2,2,1,2,1,2,2,1,2,1,7,1,1,2,2,2,2,2,1,6,6,1,6,1,2,1,2,1,2,6,6,1,1,1
1,1,1,1,1,3,2,1,2,2,2,1,2,2,1,2,1,2,1,2,2,2,1,1,1,2,2,1,1,7,7,7,1,2,1,1,2,2,1,6,1,1,6,1,2,2,1,2,1,6,1,6,6,1
1,1,1,1,1,3,1,1,1,1,2,1,2,2,2,2,1,1,2,2,1,2,1,1,3,2,1,2,1,7,7,1,7,2,2,1,1,1,2,1,1,1,6,1,1,2,2,2,6,6,6,6,1,2
1,1,1,1,1,2,2,2,2,2,6,1,2,2,1,2,2,2,2,2,2,7,2,3,3,1,1,1,2,2,1,7,2,1,2,2,2,2,2,1,6,6,1,6,2,1,1,1,1,6,6,1,2,2
1,1,1,1,1,2,1,1,1,6,6,1,1,2,2,2,2,2,2,2,1,7,7,7,2,1,2,1,2,2,2,2,1,2,2,2,1,2,6,2,2,6,6,1,2,1,2,1,1,1,1,2,2,2
1,1,1,1,1,2,2,2,2,1,6,1,1,1,2,2,1,2,1,2,2,7,1,1,7,2,2,1,2,2,1,2,2,2,1,1,2,6,1,1,2,2,1,1,2,2,2,1,1,2,2,2,2,1
1,1,1,1,1,1,1,1,1,6,1,6,2,1,1,1,2,1,1,1,1,7,7,1,7,2,1,2,2,1,1,2,2,1,2,2,1,6,1,1,2,1,1,1,2,2,1,2,2,1,2,2,2,1
1,1,1,1,1,1,1,2,1,2,2,2,1,1,1,1,1,2,2,2,1,1,7,1,7,1,2,1,1,1,2,2,2,1,1,2,1,6,6,2,1,2,2,2,2,2,3,2,1,1,1,1,2,2
1,1,1,1,1,1,1,2,2,2,2,2,2,2,2,1,2,2,2,2,2,1,2,2,1,1,2,2,2,2,1,2,2,2,2,1,6,1,6,2,2,2,2,2,2,1,1,1,1,2,1,2,2,2
1,1,1,1,1,2,2,2,1,2,2,1,2,1,2,2,1,2,2,1,1,2,2,1,1,4,1,1,1,1,2,1,2,2,1,2,6,1,6,1,2,2,1,2,2,2,2,2,1,1,2,2,2,2
1,1,1,1,1,2,1,1,2,2,2,2,2,2,1,1,1,2,1,1,2,1,2,2,4,4,2,1,2,2,1,9,1,2,1,1,1,6,1,6,2,1,2,1,1,2,2,1,2,2,5,1,1,5
1,1,1,1,1,1,1,2,1,1,2,1,1,2,2,1,1,2,2,2,1,1,2,1,1,1,2,1,1,2,2,2,2,1,2,2,1,2,2,2,2,2,2,2,2,2,2,5,1,5,1,1,5,5
1,1,1,1,1,1,2,1,1,2,1,1,2,2,1,2,1,2,2,2,2,1,2,1,1,1,2,1,2,1,1,2,2,2,2,1,2,1,2,1,2,2,1,1,1,1,2,5,5,5,5,5,5,3
1,1,1,1,1,2,2,2,2,2,2,2,2,2,2,1,2,1,2,2,2,1,2,2,2,1,2,1,1,2,2,2,2,1,1,1,2,1,2,1,2,1,2,2,2,2,2,7,1,1,1,7,2,2
1,1,1,1,1,1,2,2,1,1,1,2,8,2,8,2,2,2,2,2,1,1,2,2,2,1,1,1,1,7,1,1,2,1,2,2,1,2,1,2,2,2,2,1,1,7,1,7,7,7,1,1,1,2
1,1,1,1,1,2,2,2,2,1,2,2,2,1,2,2,2,2,2,1,1,2,2,7,1,7,7,7,7,7,7,7,2,1,1,4,1,2,1,2,2,2,1,2,1,1,7,1,1,1,7,1,1,2
1,1,1,1,1,2,1,1,1,2,1,2,2,1,2,2,1,2,2,1,1,1,1,1,7,7,7,7,7,1,1,2,2,1,4,4,2,1,1,1,1,2,2,1,1,1,7,1,7,1,1,1,1,2
1,1,1,1,1,2,2,2,1,2,2,2,2,1,1,2,1,1,1,2,2,1,2,1,7,1,7,1,7,1,1,2,1,1,4,4,2,2,2,2,2,2,1,1,7,1,1,1,1,1,2,1,2,2
1,1,1,1,1,2,1,1,2,1,2,2,2,2,1,1,2,2,2,2,2,2,1,2,7,7,2,1,2,2,1,2,1,2,2,2,1,2,1,2,1,2,2,2,2,2,1,2,2,2,1,1,1,2
1,1,1,1,1,2,2,2,1,1,2,1,2,1,2,2,1,2,2,2,1,1,2,1,2,2,2,2,2,1,1,2,1,1,1,2,1,2,1,1,2,1,1,2,1,1,2,1,1,2,1,2,2,2
1,1,1,1,1,1,1,1,2,1,2,2,1,2,1,1,2,1,2,2,2,1,2,1,2,2,2,2,2,1,2,1,1,2,1,1,1,2,2,1,2,1,2,1,1,1,2,2,2,2,2,2,2,2
1,1,1,1,1,2,2,1,2,2,1,2,1,2,2,2,1,2,2,2,2,2,5,5,5,2,2,2,2,2,2,1,2,2,1,1,2,2,2,2,2,2,2,1,2,1,1,2,1,1,1,2,2,2
1,1,1,1,1,2,2,2,2,2,2,1,1,2,1,1,1,1,2,1,2,2,1,1,5,2,2,1,2,2,2,2,1,1,1,1,1,2,2,3,2,2,2,2,2,1,2,1,1,2,1,2,2,2
1,1,1,1,1,1,2,2,2,1,1,2,1,1,1,1,2,1,2,2,2,2,2,5,5,2,2,2,1,1,2,2,2,1,1,2,2,1,1,2,1,2,1,2,2,1,2,2,1,1,2,2,2,2
1,1,1,1,1,2,2,2,1,1,2,2,2,2,2,1,2,2,1,1,2,2,1,5,1,1,2,2,2,2,2,1,1,1,1,2,1,2,1,2,2,1,1,2,1,2,1,1,2,1,1,2,1,2
1,1,1,1,1,1,1,1,1,1,1,1,1,1,1,1,1,1,1,1,1,1,1,1,1,1,1,1,1,1,1,1,1,1,1,1,1,1,1,1,1,1,1,1,1,1,1,1,1,1,1,1,1,1
1,1,1,1,1,1,1,1,1,1,1,1,1,1,1,1,1,1,1,1,1,1,1,1,1,1,1,1,1,1,1,1,1,1,1,1,1,1,1,1,1,1,1,1,1,1,1,1,1,1,1,1,1,1
1,1,1,1,1,1,1,1,1,1,1,1,1,1,1,1,1,1,1,1,1,1,1,1,1,1,1,1,1,1,1,1,1,1,1,1,1,1,1,1,1,1,1,1,1,1,1,1,1,1,1,1,1,1
:endlayer
layer: 3
2,2,2,2,2,2,2,2,2,2,2,2,2,2,2,2,2,1,1,2,2,2,2,2,2,2,2,2,2,2,2,2,1,2,2,2,5,5,5,5,5,2,2,2,2,2,2,1,1,1,1,2,2,2
2,2,2,2,2,2,2,2,2,2,2,1,2,2,1,1,2,2,2,2,1,2,1,2,2,2,2,3,2,2,1,2,2,2,2,2,5,5,5,2,2,2,1,1,1,1,2,1,2,2,2,4,4,2
2,2,2,2,2,2,2,2,2,2,1,2,2,2,2,2,2,1,2,2,2,2,2,2,2,1,2,1,6,1,2,2,1,2,1,1,2,2,2,2,2,2,1,2,1,2,2,1,2,1,2,4,4,2
2,2,2,2,2,1,1,2,1,2,2,2,2,2,2,1,2,2,2,2,2,1,2,2,2,2,2,2,1,1,1,1,2,2,2,1,1,2,2,2,2,2,2,2,2,2,2,2,2,2,2,4,1,1
2,2,2,2,1,2,2,2,1,2,2,1,2,1,1,1,1,1,1,2,2,2,2,2,2,2,2,2,6,6,2,2,1,2,2,2,2,1,2,2,2,1,2,2,2,2,2,1,2,1,1,4,4,2
2,2,2,2,6,6,6,6,6,5,5,5,6,6,6,6,6,1,1,2,2,2,1,2,1,2,2,2,2,2,2,2,2,2,2,2,2,2,2,2,2,2,2,1,2,2,2,2,1,1,1,1,1,2
2,2,2,2,6,6,5,1,6,5,5,1,1,6,1,6,6,6,6,6,6,1,1,2,2,2,2,2,2,2,2,2,1,2,2,2,2,1,7,1,7,2,2,2,1,2,1,2,2,2,2,4,1,2
2,2,2,2,5,1,5,5,6,5,1,5,6,6,1,6,6,6,6,6,6,6,2,2,1,2,2,2,2,2,2,2,2,2,1,2,2,1,1,7,7,7,2,2,2,2,2,1,2,2,2,8,8,2
2,2,2,2,1,5,5,5,5,2,2,1,2,1,1,1,2,2,2,6,6,6,6,6,2,2,2,1,2,2,2,1,2,2,2,2,2,4,1,2,2,2,2,2,2,2,1,2,2,1,1,2,2,1
2,2,2,2,2,2,2,2,2,2,2,2,2,1,2,2,2,2,2,2,2,6,6,6,6,6,2,6,2,2,2,2,2,1,2,2,2,1,4,1,1,1,2,2,2,1,1,1,2,2,2,2,1,2
2,2,2,2,2,2,2,2,1,2,2,1,1,2,2,2,2,2,1,2,1,2,2,1,3,3,2,1,2,3,2,2,1,2,2,6,2,4,4,2,2,2,2,2,2,2,2,2,2,2,2,1,2,2
2,2,2,2,2,2,2,2,2,2,1,2,2,1,2,2,2,2,2,2,2,2,2,1,2,1,2,2,1,3,2,1,1,1,2,2,2,2,2,1,1,1,2,2,1,1,2,1,2,2,1,2,2,2
2,2,2,2,2,1,2,1,2,2,1,2,2,2,2,2,2,2,2,2,1,2,2,2,1,2,2,2,1,1,1,1,2,2,2,1,1,2,2,2,2,2,2,2,2,2,2,1,2,2,2,2,2,2
2,2,2,2,2,2,2,2,1,1,2,2,2,2,2,2,2,2,2,2,2,2,1,2,1,2,2,2,2,2,2,1,2,2,2,6,6,6,2,2,2,2,2,1,2,2,2,2,2,2,2,2,2,2
2,2,2,2,2,1,2,2,2,2,2,2,2,2,2,2,2,2,2,1,2,2,2,2,2,2,2,2,2,2,2,2,2,2,2,6,6,6,2,2,2,2,2,2,1,2,2,2,1,1,2,2,2,1
2,2,2,2,1,2,2,2,2,2,2,2,1,2,2,2,1,2,2,2,2,2,2,2,1,2,2,2,1,2,1,2,1,2,2,6,6,1,1,2,2,2,2,2,2,2,6,6,2,2,1,2,2,2
2,2,2,2,2,1,2,1,2,1,1,2,2,2,2,2,1,2,2,2,2,1,1,2,1,2,2,2,2,2,2,2,2,2,1,1,6,1,6,2,2,1,1,2,6,6,1,6,6,2,2,2,2,2
2,2,2,2,1,2,2,2,2,2,1,2,1,2,2,2,2,2,2,2,2,2,1,2,2,2,2,2,2,1,2,2,2,2,2,1,6,6,6,1,2,2,2,2,6,6,6,6,6,2,1,1,2,1
2,2,2,2,1,1,2,2,2,2,2,2,2,1,2,2,2,2,1,2,2,2,2,1,2,2,2,2,2,2,2,2,2,1,2,6,6,6,1,2,2,2,2,2,6,6,6,6,6,2,2,2,2,1
2,2,2,2,2,2,2,2,2,2,2,1,2,2,2,1,1,2,1,2,2,2,2,2,2,2,2,1,2,1,2,2,2,2,2,6,6,6,6,2,2,2,2,4,6,6,6,2,2,2,2,2,2,1
2,2,0,0,2,1,1,9,2,2,2,2,1,2,1,1,2,2,1,2,2,2,2,2,2,2,2,2,2,2,2,1,2,2,2,2,5,6,6,2,2,2,2,1,6,4,1,4,2,2,1,2,1,2
2,2,0,0,6,6,6,6,9,2,2,2,2,2,2,2,2,2,2,2,2,2,2,2,2,1,2,1,2,4,4,4,2,2,2,3,2,2,1,2,1,2,2,2,6,6,6,1,2,2,2,2,1,2
2,2,0,0,1,6,6,6,2,2,2,1,2,2,2,1,2,2,1,2,2,2,1,2,2,1,2,2,2,4,4,4,2,2,1,2,1,1,2,1,1,2,2,2,6,6,6,2,2,2,2,2,1,2
2,2,0,11,6,6,6,1,1,2,2,2,2,2,2,2,2,2,2,1,1,2,2,2,1,2,3,2,2,1,2,1,2,1,2,2,2,2,2,1,2,2,1,2,6,6,1,2,3,2,2,1,2,1
2,2,0,11,6,6,2,1,2,2,2,1,2,2,2,2,2,2,2,2,1,2,2,2,2,2,3,3,1,7,7,7,2,2,2,1,2,2,2,2,2,2,2,2,6,6,2,2,2,2,2,1,2,2
2,2,0,12,5,2,1,1,2,2,2,2,2,2,2,2,2,2,2,2,9,1,1,2,2,2,1,2,2,7,7,7,7,2,2,1,2,2,2,2,1,2,2,6,1,2,1,2,2,2,2,2,2,1
2,2,0,0,2,2,2,2,2,1,2,1,2,2,2,2,2,1,1,1,2,2,2,2,2,2,1,2,2,7,7,1,1,2,1,2,1,1,2,2,6,6,6,6,2,2,2,2,1,1,6,6,6,1
2,2,0,0,3,2,2,2,2,2,2,2,1,1,2,2,2,1,1,2,2,2,2,2,3,1,2,2,2,7,1,7,1,1,2,2,2,2,2,2,6,6,6,6,2,2,2,6,6,6,6,6,6,6
2,2,0,0,2,1,2,2,2,2,2,2,2,2,1,1,2,1,2,2,2,2,2,2,3,3,2,2,2,7,7,7,7,2,2,2,2,2,2,2,6,6,6,6,2,2,6,6,6,6,6,6,6,6
2,2,0,0,2,1,2,2,2,6,1,6,2,2,2,2,1,2,2,2,2,1,7,2,2,1,2,2,1,2,7,7,2,2,2,2,1,2,2,2,6,6,6,6,2,1,6,6,6,6,6,2,6,6
2,2,0,0,2,2,1,2,2,1,6,6,6,2,2,1,2,1,2,2,2,1,7,7,7,2,2,2,2,2,2,2,1,2,2,2,2,2,2,2,1,2,2,1,1,2,6,6,6,6,2,1,2,2
2,2,2,2,2,2,1,1,2,6,1,6,6,1,1,2,2,2,1,2,2,7,7,7,7,7,2,2,1,2,1,2,2,2,2,2,1,2,2,2,2,2,2,2,2,2,2,2,2,2,2,1,2,2
2,2,2,2,2,2,2,1,2,6,1,6,2,2,2,2,2,2,2,2,2,7,7,7,7,1,2,1,2,1,2,10,1,2,2,2,2,2,2,2,2,2,2,2,2,1,2,1,1,2,1,2,2,2
2,2,2,2,2,2,2,2,2,1,1,2,1,2,2,2,1,2,2,2,2,2,7,1,7,7,1,1,1,2,2,10,10,2,2,2,2,2,2,2,2,2,2,2,2,2,3,2,2,2,1,1,2,2
2,2,2,2,2,1,2,2,1,1,2,2,2,2,2,1,2,2,2,2,2,2,1,1,7,7,7,1,8,2,1,1,2,2,1,2,1,1,2,1,1,2,2,2,1,2,2,3,2,2,1,2,2,2
2,2,2,2,2,2,2,2,2,2,1,1,1,2,1,2,2,2,2,2,2,1,2,7,1,7,7,8,8,1,2,9,2,1,2,2,2,1,2,2,2,2,2,2,1,2,2,1,2,2,2,2,2,2
2,2,2,2,2,2,2,2,2,2,2,3,1,2,2,2,2,2,2,2,2,2,2,1,1,4,2,2,2,2,2,9,2,1,2,2,2,2,2,2,1,2,2,2,1,2,2,2,2,1,1,2,2,2
2,2,2,2,2,2,1,1,2,2,2,1,2,1,2,2,2,2,2,2,2,2,2,2,4,1,2,2,2,2,2,2,2,1,1,2,2,2,2,1,1,1,6,6,6,1,2,2,2,2,3,3,2,1
2,2,2,2,2,2,2,2,2,2,1,2,2,2,2,2,1,2,2,1,2,2,2,2,2,2,2,1,2,2,2,2,2,2,2,2,2,2,2,2,2,6,6,6,6,1,2,2,2,2,3,2,2,2
2,2,2,2,1,4,2,2,1,1,2,8,8,8,1,2,2,2,2,2,1,1,2,2,2,1,2,1,2,1,2,2,2,2,1,2,2,2,2,2,2,2,1,6,6,6,2,2,2,1,2,1,3,2
2,2,2,2,1,4,2,2,1,2,2,8,8,8,8,2,2,2,2,2,2,2,2,2,2,1,7,7,7,1,7,7,2,2,2,1,2,2,2,1,2,2,2,2,2,2,2,2,7,7,1,2,2,2
2,2,2,2,2,1,2,1,1,1,2,2,1,2,2,2,2,2,2,1,2,1,1,2,7,7,7,1,7,7,1,7,2,2,1,4,1,2,1,2,2,2,2,2,1,2,7,1,7,7,1,1,2,2
2,2,2,2,2,2,2,2,2,2,2,1,2,1,2,2,2,2,2,2,2,1,2,7,7,7,7,7,7,7,2,2,2,1,4,4,2,2,2,2,2,2,2,2,2,2,2,2,2,2,1,2,2,1
2,2,2,2,2,2,1,2,2,2,2,2,2,2,1,2,2,2,2,2,2,2,2,2,7,7,1,7,1,2,1,2,2,2,4,4,2,2,2,2,1,2,1,2,1,2,2,1,2,2,2,2,2,2
2,2,2,2,2,1,1,2,1,2,2,2,2,2,2,1,2,2,2,2,2,2,2,2,2,2,2,2,1,2,2,2,1,2,4,4,2,2,2,1,1,2,2,2,2,1,2,1,2,2,2,1,2,2
2,2,2,2,1,7,1,2,2,1,2,1,1,1,2,2,2,1,2,1,1,1,2,5,2,2,2,2,1,1,2,2,2,2,4,2,2,2,1,2,2,2,2,2,1,2,13,2,1,1,2,2,2,2
2,2,2,2,1,7,7,7,1,2,1,2,2,2,2,2,2,2,2,2,2,2,5,5,5,2,2,1,2,1,2,1,1,8,1,2,2,2,1,2,2,2,2,2,2,1,2,2,2,2,2,2,2,2
2,2,2,2,7,1,7,7,1,2,2,2,2,2,2,2,2,2,1,2,2,1,5,5,5,5,2,2,2,2,2,1,2,8,1,2,2,2,1,2,2,2,2,2,2,2,1,2,2,1,2,2,2,1
2,2,2,2,7,7,7,7,7,1,1,2,2,2,2,1,1,2,2,2,2,1,5,5,1,5,2,2,2,2,1,2,2,2,1,2,2,2,2,2,1,2,2,2,2,2,2,2,2,1,2,2,2,1
2,2,2,2,2,2,2,2,1,2,2,2,2,1,2,2,1,2,2,2,2,2,1,5,1,5,2,2,2,2,2,2,2,2,2,2,2,2,1,1,2,2,2,2,1,2,2,2,2,2,2,1,2,1
2,2,2,2,1,2,2,2,2,2,2,1,2,1,1,2,2,2,2,2,2,2,5,1,5,5,2,2,2,2,2,2,2,2,1,2,2,2,2,2,2,2,2,2,2,1,2,2,2,2,2,2,2,2
2,2,2,2,2,2,2,2,2,2,2,2,2,2,2,2,2,2,2,2,2,2,2,2,2,2,2,2,2,2,2,2,2,2,2,2,2,2,2,2,2,2,2,2,2,2,2,2,2,2,2,2,2,2
2,2,2,2,2,2,2,2,2,2,2,2,2,2,2,2,2,2,2,2,2,2,2,2,2,2,2,2,2,2,2,2,2,2,2,2,2,2,2,2,2,2,2,2,2,2,2,2,2,2,2,2,2,2
2,2,2,2,2,2,2,2,2,2,2,2,2,2,2,2,2,2,2,2,2,2,2,2,2,2,2,2,2,2,2,2,2,2,2,2,2,2,2,2,2,2,2,2,2,2,2,2,2,2,2,2,2,2
:endlayer
layer: 4
2,2,2,2,2,2,2,2,2,2,2,2,2,2,2,2,2,2,2,2,2,2,2,2,2,2,2,2,2,2,2,2,2,2,2,5,5,5,5,5,5,5,2,2,2,2,2,2,2,2,2,2,2,2
2,2,2,2,2,2,2,2,2,2,2,2,2,2,2,2,2,2,2,2,2,2,2,2,2,2,2,3,3,2,2,2,2,2,5,5,5,5,5,5,2,2,2,2,2,2,2,2,2,2,2,2,2,2
2,2,2,2,2,2,2,2,2,2,2,2,2,2,2,2,2,2,2,2,2,2,2,2,2,2,2,3,6,2,2,2,2,2,5,5,5,5,9,2,2,2,2,3,3,2,2,2,2,2,2,2,2,2
2,2,2,2,2,2,2,2,2,2,2,2,2,2,2,2,2,2,2,2,2,2,2,2,2,2,2,2,6,6,2,2,2,2,2,2,2,2,2,2,2,2,2,3,3,2,2,2,2,2,2,4,4,2
2,2,2,2,5,2,2,2,2,2,2,2,2,2,2,2,2,2,2,2,2,2,2,2,2,2,2,2,6,6,2,2,2,2,2,2,2,2,2,2,2,2,2,2,2,2,2,2,2,2,2,4,4,2
2,2,2,2,6,6,6,6,6,5,5,5,6,6,3,2,2,2,2,2,2,2,2,2,2,2,2,2,2,2,2,2,2,2,2,2,2,2,2,2,2,2,2,2,2,2,2,2,2,2,2,4,4,5
2,2,2,2,6,6,6,6,6,5,5,5,6,6,2,2,2,2,2,2,2,2,2,2,2,2,2,2,2,2,2,2,2,2,2,2,2,2,2,2,2,2,2,2,2,2,2,2,2,2,2,4,5,5
2,2,2,2,5,5,5,5,6,5,5,5,6,2,2,2,2,2,2,2,2,2,2,2,2,2,2,2,2,2,2,2,2,2,8,8,2,2,2,2,2,2,2,2,2,2,2,2,2,2,2,8,8,5
2,2,2,2,5,5,5,5,5,5,2,2,2,2,2,2,2,2,2,2,2,2,2,2,2,2,2,2,2,2,2,2,2,8,8,8,2,2,2,2,2,2,2,2,2,2,2,2,2,2,2,2,2,2
2,2,2,2,2,2,2,5,5,2,2,2,2,2,2,2,2,2,2,2,2,2,2,2,3,2,2,2,2,2,2,6,2,2,2,2,2,2,2,2,2,2,2,2,2,2,2,2,2,2,2,2,2,2
2,2,2,2,2,2,2,2,2,2,2,2,2,2,2,2,2,2,2,2,2,2,2,2,2,2,2,2,2,2,6,6,6,2,2,2,2,2,2,2,2,2,2,2,2,2,2,2,2,2,2,2,2,2
2,2,2,2,2,2,2,2,2,2,2,2,2,2,2,2,2,2,2,2,2,2,2,2,2,2,2,2,2,2,6,6,6,2,2,2,2,2,2,2,2,2,2,2,2,2,2,2,2,2,2,2,2,2
2,2,2,2,2,2,2,2,2,2,2,2,2,2,2,2,2,2,2,2,2,2,2,2,2,2,2,2,2,2,2,2,2,2,2,2,2,2,2,2,2,2,2,2,2,2,2,2,2,2,2,2,2,2
2,2,2,2,2,2,2,2,2,2,2,2,2,2,2,2,2,2,2,2,2,2,2,2,2,2,2,2,2,2,2,2,2,2,2,2,2,2,2,2,2,2,2,2,2,2,2,2,2,2,2,2,2,2
2,2,2,2,2,2,2,2,2,2,2,2,2,2,2,2,2,2,2,2,2,2,2,2,2,2,2,2,2,2,2,2,2,2,2,2,2,2,2,2,2,2,2,2,2,2,2,2,2,2,2,2,2,2
2,2,2,2,2,2,2,2,2,2,2,2,2,2,2,2,2,2,2,2,2,2,2,2,2,2,2,2,2,2,2,2,2,2,2,2,6,6,2,2,2,2,2,2,2,6,6,6,6,6,6,2,2,2
2,2,2,2,2,2,2,2,2,2,2,2,2,2,2,2,2,2,2,2,2,2,2,2,2,2,2,2,2,2,2,2,2,2,2,2,6,6,2,2,2,2,2,2,6,6,6,6,6,6,6,2,2,2
2,2,2,2,2,2,2,2,2,2,2,2,2,2,2,2,2,2,2,2,2,2,2,2,2,2,2,2,2,2,2,2,2,2,2,6,6,6,6,2,2,2,2,2,6,6,6,6,6,6,6,2,2,2
2,2,2,2,4,2,2,2,2,2,2,2,2,2,2,2,2,2,2,2,2,2,2,2,2,2,2,2,2,2,2,2,2,2,2,6,6,6,6,2,2,2,2,2,6,6,6,6,6,6,6,2,2,2
2,2,2,2,2,2,2,3,3,2,2,2,2,2,2,2,2,2,2,2,2,2,2,2,2,2,2,2,2,2,2,2,2,2,2,6,6,6,6,2,2,2,2,2,6,6,6,6,2,2,2,2,2,2
2,2,2,2,2,2,2,3,3,2,2,2,2,2,2,2,2,2,2,2,2,2,2,2,2,2,2,2,2,2,2,2,2,2,2,6,5,6,6,2,2,2,2,2,6,6,4,4,2,2,2,2,2,2
2,2,2,2,6,6,6,6,2,2,2,2,2,2,2,2,2,2,2,2,2,2,2,2,14,2,2,2,2,2,2,2,2,2,2,2,6,5,6,2,2,2,2,2,6,6,6,6,2,2,2,2,2,2
2,2,2,2,6,6,6,6,2,2,2,2,2,2,2,2,2,2,2,2,2,2,2,2,15,2,2,2,2,2,2,2,2,2,2,2,2,5,2,2,2,2,2,2,6,6,6,6,6,6,6,6,2,2
2,2,2,2,6,6,6,2,2,2,2,2,2,2,2,2,2,2,2,2,2,2,2,2,2,2,3,2,2,2,2,2,2,2,2,2,2,2,2,2,2,2,2,2,6,6,6,6,6,6,6,6,6,2
2,2,2,2,6,6,2,2,2,2,2,2,2,2,2,2,2,2,2,2,9,8,2,2,2,2,3,3,2,2,2,2,2,2,2,2,2,2,2,2,2,2,2,2,6,6,6,6,6,6,6,6,6,6
2,2,2,2,5,2,2,2,2,2,2,2,2,2,2,2,2,2,2,2,9,9,2,2,2,2,2,2,2,2,2,3,2,2,2,2,2,2,2,2,2,2,2,2,2,2,6,6,6,6,6,2,2,6
2,2,2,2,8,8,2,2,2,2,2,2,2,2,2,2,2,2,2,2,2,2,2,2,2,2,2,2,2,2,2,2,3,2,2,2,2,2,2,2,2,2,2,6,2,2,2,2,2,6,6,6,6,6
2,2,2,2,8,8,2,2,2,2,2,2,2,2,2,2,2,2,2,2,2,2,2,2,2,2,2,2,2,2,2,2,2,2,2,2,2,2,2,2,2,2,6,6,2,2,2,6,6,6,6,6,6,6
2,2,2,2,2,2,2,2,2,2,2,2,2,2,2,2,2,2,2,2,2,2,2,2,3,2,2,2,2,2,2,2,2,2,2,2,2,2,2,2,2,2,6,6,2,2,6,6,6,6,6,6,6,6
2,2,2,2,2,2,2,2,2,6,6,6,2,2,2,2,2,2,2,2,2,2,2,2,2,2,2,2,2,2,2,2,2,2,2,2,2,2,2,2,2,2,6,6,2,6,6,6,6,6,6,2,6,6
2,2,2,2,2,2,2,2,2,6,6,6,6,2,2,16,17,2,2,2,2,7,7,7,7,2,2,2,2,2,2,2,2,2,2,2,2,2,2,2,2,2,2,6,2,6,6,6,6,6,2,2,2,2
2,2,2,2,2,2,2,2,2,6,6,6,6,2,12,18,16,2,2,2,2,7,7,7,7,7,5,5,2,2,2,2,2,2,2,2,2,2,2,2,2,2,2,2,2,2,6,6,2,2,2,2,2,2
2,2,2,2,2,2,2,2,2,2,6,6,2,2,2,2,2,2,2,2,2,7,7,7,7,7,5,5,5,2,2,10,10,2,2,2,2,2,2,2,2,2,2,2,2,2,2,2,2,2,2,2,2,2
2,2,2,2,2,2,2,2,2,2,2,2,2,2,2,2,2,2,2,2,2,2,7,7,7,7,7,2,5,5,2,10,10,2,2,2,2,2,2,2,2,2,2,2,2,2,2,2,2,2,2,2,2,2
2,2,2,2,2,2,2,2,2,2,2,2,2,2,2,2,2,2,2,2,2,2,2,7,7,7,7,2,8,2,2,2,2,2,2,2,2,2,2,2,2,2,2,2,2,2,2,2,2,2,2,2,2,2
2,2,2,2,2,2,2,2,2,2,2,2,2,2,2,2,2,2,2,2,2,2,2,7,7,7,7,2,2,2,2,2,2,2,2,2,2,2,2,2,2,2,2,2,2,2,2,2,2,2,2,2,2,2
2,2,2,2,2,2,2,2,2,2,2,3,2,2,2,2,2,2,2,2,2,2,2,2,4,7,7,2,2,2,2,2,2,2,2,2,2,2,2,2,2,2,2,2,2,2,2,2,2,2,2,2,2,2
2,2,2,2,2,2,2,2,2,2,2,2,3,2,2,2,2,2,2,2,2,2,2,2,4,4,2,2,2,2,2,2,2,2,2,2,2,2,2,2,2,6,6,6,6,6,2,2,2,2,2,3,2,2
2,2,2,2,4,2,2,2,2,2,2,2,2,2,2,2,2,2,2,2,2,2,2,2,2,2,2,2,2,2,2,2,2,2,2,2,2,2,2,2,2,6,6,6,6,6,6,2,2,2,2,3,2,2
2,2,2,2,4,4,2,2,2,2,2,8,2,8,2,2,2,2,2,2,2,2,2,2,2,2,2,2,2,2,2,2,2,2,2,2,2,2,2,2,2,2,6,6,6,6,6,6,2,2,2,2,3,2
2,2,2,2,4,4,2,2,2,2,2,2,2,2,2,2,2,2,2,2,2,2,2,2,2,2,2,2,7,2,2,2,2,2,2,2,2,2,2,2,2,2,2,6,6,6,6,2,2,2,2,2,2,2
2,2,2,2,2,2,2,2,2,2,2,5,5,2,2,2,2,2,2,2,2,2,2,2,2,2,7,7,7,7,2,2,2,2,2,2,2,2,2,2,2,2,2,2,2,2,2,2,2,2,2,2,2,2
2,2,2,2,2,2,2,2,5,5,5,5,5,2,2,2,2,2,2,2,2,2,2,2,2,2,7,7,7,2,2,2,2,2,4,4,2,2,2,2,2,2,2,2,2,2,2,2,2,2,2,2,2,2
2,2,2,2,2,2,2,2,5,5,5,5,2,2,2,2,2,2,2,2,2,2,2,2,2,2,2,2,2,2,2,2,2,2,4,4,2,2,2,2,2,2,2,2,2,2,2,2,2,2,2,2,2,2
2,2,2,2,7,2,2,2,2,5,2,2,2,2,2,2,2,2,2,2,2,2,2,2,2,2,2,2,2,2,2,2,2,2,4,4,2,2,2,2,2,2,2,2,2,2,2,13,2,2,2,2,2,2
2,2,2,2,7,7,7,7,5,2,2,2,2,2,2,2,2,2,2,2,2,2,2,5,2,2,2,2,2,2,2,2,2,2,2,2,2,2,2,2,2,2,2,2,2,2,13,2,2,2,2,2,2,2
2,2,2,2,7,7,7,7,7,5,2,2,2,2,2,2,2,2,2,2,2,2,5,5,5,2,2,3,2,2,2,2,2,2,8,2,2,2,2,2,2,2,2,2,2,2,2,2,2,2,2,2,2,2
2,2,2,2,7,7,7,7,7,7,2,2,2,2,2,2,2,2,2,2,2,2,5,5,5,5,2,2,3,2,2,2,2,2,8,2,2,2,2,4,2,2,2,2,2,2,2,2,2,2,2,2,2,2
2,2,2,2,7,7,7,7,7,7,2,2,2,2,2,2,2,2,2,2,2,2,5,5,5,5,2,2,2,2,2,2,2,2,2,2,2,2,2,4,4,2,2,2,2,2,2,2,2,2,2,2,2,2
2,2,2,2,2,2,4,4,4,2,2,2,2,2,2,2,2,2,2,2,2,2,5,5,5,5,2,2,2,2,2,2,2,2,2,2,2,2,2,4,4,2,2,2,2,2,2,2,2,2,2,2,2,2
2,2,2,2,2,2,4,4,2,2,2,2,2,2,2,2,2,2,2,2,2,2,5,5,5,5,2,2,2,2,2,2,2,2,2,2,2,2,2,4,4,2,2,2,2,2,2,2,2,2,2,2,2,2
2,2,2,2,2,2,2,2,2,2,2,2,2,2,2,2,2,2,2,2,2,2,2,2,2,2,2,2,2,2,2,2,2,2,2,2,2,2,2,2,2,2,2,2,2,2,2,2,2,2,2,2,2,2
2,2,2,2,2,2,2,2,2,2,2,2,2,2,2,2,2,2,2,2,2,2,2,2,2,2,2,2,2,2,2,2,2,2,2,2,2,2,2,2,2,2,2,2,2,2,2,2,2,2,2,2,2,2
2,2,2,2,2,2,2,2,2,2,2,2,2,2,2,2,2,2,2,2,2,2,2,2,2,2,2,2,2,2,2,2,2,2,2,2,2,2,2,2,2,2,2,2,2,2,2,2,2,2,2,2,2,2
:endlayer
layer: 5
2,2,2,2,2,2,2,2,2,2,2,2,2,2,2,2,2,2,2,2,2,2,2,2,2,2,2,2,2,2,2,2,2,2,2,5,5,5,5,5,5,5,2,2,2,2,2,2,2,2,2,2,2,2
2,2,2,2,2,2,2,2,2,2,2,2,2,2,2,2,2,2,2,2,2,2,2,2,2,2,2,2,2,2,2,3,2,2,5,5,5,5,5,5,2,2,2,2,2,2,2,2,2,2,2,2,2,2
2,2,2,2,2,2,2,2,2,2,2,2,2,2,2,2,2,2,2,2,2,2,2,2,2,2,2,2,6,2,2,2,2,2,5,5,5,5,9,2,2,2,2,2,2,2,2,2,2,2,2,2,2,2
2,2,2,2,2,2,2,2,2,2,2,2,2,2,2,2,2,2,2,2,2,2,2,2,2,2,2,2,6,2,2,2,2,2,2,2,2,2,2,2,2,2,2,3,2,2,2,2,2,2,2,2,2,2
2,2,2,2,2,2,2,2,2,2,5,5,2,2,2,2,2,2,2,2,2,2,2,2,2,2,2,2,6,6,2,2,2,2,2,2,2,2,2,2,2,2,2,2,2,2,2,2,2,2,2,2,5,5
2,2,2,2,6,6,3,6,6,5,5,5,2,2,2,2,2,2,2,2,2,2,2,2,2,2,2,2,2,2,2,2,2,2,2,2,2,2,2,2,2,2,2,2,2,2,2,2,2,2,2,2,5,5
2,2,2,2,6,6,18,6,6,6,5,5,2,2,2,2,2,2,2,2,2,2,2,2,2,2,2,2,2,2,2,2,2,2,2,2,2,2,2,2,2,2,2,2,2,2,2,2,2,2,2,2,5,5
2,2,2,2,5,5,5,0,18,5,5,5,2,2,2,2,2,2,2,2,2,2,2,2,2,2,2,2,2,2,2,2,2,8,8,2,2,2,2,2,2,2,2,2,2,2,2,2,2,2,2,5,5,5
2,2,2,2,5,5,5,5,5,5,5,5,2,2,2,2,2,2,2,2,2,2,2,2,2,2,2,2,2,2,2,2,2,2,2,2,2,2,2,2,2,2,2,2,2,2,2,2,2,2,2,5,5,5
2,2,2,2,2,2,2,5,2,2,2,2,2,2,2,2,2,2,2,2,2,2,2,2,2,2,2,2,2,2,6,6,2,2,2,2,2,2,2,2,2,2,2,2,2,2,2,2,2,2,2,5,5,5
2,2,2,2,2,2,2,2,2,2,2,2,2,2,2,2,2,2,2,2,2,2,2,2,2,2,2,2,2,2,6,6,6,2,2,2,2,2,2,2,2,2,2,2,2,2,2,2,2,2,2,2,2,2
2,2,2,2,2,2,2,2,2,2,2,2,2,2,2,2,2,2,2,2,2,2,2,2,2,2,2,2,2,2,6,6,6,6,2,2,2,2,2,2,2,2,2,2,2,2,2,2,2,2,2,2,2,2
2,2,2,2,2,2,2,2,2,2,2,2,2,2,2,2,2,2,2,2,2,2,2,2,2,2,2,2,2,2,2,6,6,6,6,6,2,2,2,2,2,3,3,2,2,2,2,2,2,2,2,2,2,2
2,2,2,2,2,2,2,2,2,2,2,2,2,2,2,2,2,2,2,2,2,2,2,2,2,7,7,2,2,2,2,2,2,6,6,6,2,2,2,2,2,3,3,2,2,2,2,2,2,2,2,2,2,2
2,2,2,2,2,2,2,2,2,2,2,2,2,2,2,2,2,2,2,2,2,2,2,2,2,7,7,2,2,2,2,2,2,2,2,2,2,2,2,2,2,2,2,2,2,2,2,2,6,6,2,2,6,6
2,2,2,2,2,2,2,2,2,2,2,2,2,2,2,2,2,2,2,2,2,2,2,2,7,7,7,7,2,2,2,2,2,2,2,2,2,2,2,2,2,2,2,2,2,2,6,6,6,6,6,6,6,6
2,2,2,2,2,2,2,2,2,2,2,2,2,2,2,2,2,2,2,2,2,2,2,2,7,7,7,7,2,2,2,2,2,2,2,2,2,2,2,2,2,2,2,2,6,6,6,6,6,6,6,6,6,6
2,2,2,2,4,2,2,2,2,2,2,2,2,2,2,2,2,2,2,2,2,2,2,2,2,7,7,7,2,2,2,2,2,2,2,2,6,6,2,2,2,2,2,2,6,6,6,6,6,6,6,6,6,6
2,2,2,2,4,2,2,2,2,2,2,2,2,2,2,2,2,2,2,2,2,2,2,2,2,7,7,2,2,2,2,2,2,2,2,2,6,6,6,2,2,2,2,2,6,6,6,6,6,6,6,6,6,2
2,2,2,2,2,2,2,2,3,2,2,2,2,2,2,2,2,2,2,2,2,2,2,2,2,2,2,2,2,2,2,2,3,3,2,2,6,6,6,2,2,2,2,2,6,6,6,6,2,2,2,2,2,2
2,2,2,2,2,2,2,2,2,2,2,2,2,2,2,2,2,2,2,2,2,2,2,2,2,19,20,20,21,21,21,2,3,3,2,6,5,6,6,2,2,2,2,2,6,6,2,2,2,2,2,2,2,2
2,2,2,2,6,6,6,6,2,2,2,2,2,2,2,2,2,2,2,2,2,2,2,2,2,19,20,20,21,2,19,19,19,2,2,2,6,5,6,2,2,2,2,9,6,6,6,6,2,2,2,6,6,6
2,2,2,2,6,6,6,2,2,2,2,2,2,2,2,2,2,2,2,2,2,2,2,2,15,19,20,20,21,2,19,19,19,19,2,2,6,5,6,6,2,2,2,9,6,6,6,6,6,6,6,6,6,6
2,2,2,2,6,6,2,2,2,2,2,2,2,2,2,2,2,2,2,2,2,2,2,2,19,19,20,20,21,2,19,19,19,19,2,2,6,6,6,6,2,2,2,2,6,6,6,6,6,6,6,6,6,6
2,2,2,2,6,18,2,2,2,2,2,2,2,2,2,2,2,2,2,2,2,9,2,19,19,19,20,20,21,2,19,19,19,19,19,2,6,6,6,2,2,2,2,2,6,6,6,6,6,6,6,6,6,6
2,2,2,2,5,5,2,2,2,2,2,2,2,2,2,2,2,2,2,2,2,2,8,20,20,20,20,20,21,2,19,19,19,19,19,2,2,2,2,2,2,2,2,2,2,2,6,6,6,6,6,6,6,6
2,2,2,2,2,2,2,2,2,2,2,2,2,2,2,2,2,2,2,2,2,2,2,20,20,20,20,20,21,2,19,19,19,19,19,2,2,2,2,3,3,2,2,2,2,2,2,2,2,2,2,2,6,6
2,2,2,2,2,0,2,2,2,2,2,2,2,2,2,2,2,2,2,2,2,2,2,2,20,20,20,20,21,2,2,19,19,19,19,2,2,2,2,3,3,2,2,6,2,2,2,2,6,6,6,6,6,6
2,2,2,2,2,2,2,2,2,2,2,6,2,2,2,2,2,2,2,2,2,2,2,2,0,0,0,0,22,0,2,19,19,19,2,2,2,2,2,2,2,2,2,6,2,2,6,6,6,6,6,2,6,6
2,2,2,2,2,2,2,2,2,2,6,6,6,2,2,2,2,2,2,2,2,2,0,0,0,0,0,0,23,0,2,2,19,19,2,2,2,2,2,2,2,2,2,6,2,6,6,6,6,6,2,2,2,6
2,2,2,2,2,2,2,2,2,6,6,6,6,2,0,0,0,0,24,24,24,24,24,24,24,24,21,0,23,0,2,2,2,2,2,2,2,2,2,2,2,2,2,2,2,6,6,6,6,2,2,2,2,2
2,2,2,2,2,2,2,2,2,2,6,6,6,18,16,0,0,0,0,0,0,0,0,0,0,0,0,0,23,0,2,2,2,2,2,2,2,2,2,2,2,2,2,2,6,6,6,6,6,2,2,2,2,2
2,2,2,2,2,2,2,2,2,2,2,2,2,2,2,2,2,2,2,2,2,2,7,0,0,0,5,0,23,0,5,2,2,2,2,2,2,2,2,2,2,2,2,2,2,6,6,2,2,2,2,2,2,2
2,2,2,2,2,2,2,2,2,2,2,2,2,2,2,2,2,2,2,2,2,2,2,7,7,7,7,0,23,0,5,2,2,2,2,2,2,2,2,2,2,2,2,2,2,2,2,2,2,2,2,2,2,2
2,2,2,2,2,2,2,2,2,2,2,2,2,2,2,2,2,2,2,2,2,2,2,7,7,7,7,0,23,0,5,2,2,2,2,2,2,2,2,2,2,2,2,2,2,2,2,2,2,2,2,2,2,2
2,2,2,2,2,2,2,2,2,2,2,2,2,2,2,2,2,2,2,2,2,2,2,2,7,7,7,0,23,0,2,2,2,2,2,2,2,2,2,2,2,2,2,2,2,2,2,2,2,2,2,2,2,2
2,2,2,2,2,2,2,2,2,2,2,3,3,2,2,2,2,2,2,2,2,2,2,2,2,7,7,0,23,0,2,2,2,2,2,2,2,2,2,2,2,2,2,6,2,2,2,2,2,2,2,2,2,2
2,2,2,2,2,2,2,2,2,2,2,3,3,2,2,2,2,2,2,2,2,2,2,2,2,2,2,0,23,0,2,2,2,2,2,2,2,3,2,2,2,6,6,6,6,6,6,6,6,2,2,2,2,2
2,2,2,2,2,2,2,2,2,2,2,2,2,2,2,2,2,2,2,2,2,2,2,2,2,2,2,0,0,0,2,2,2,2,2,2,2,2,2,2,2,2,6,6,6,6,6,6,6,6,2,2,2,2
2,2,2,2,4,2,2,2,2,2,2,2,2,2,2,2,2,2,2,2,2,2,2,2,2,2,2,0,0,0,2,2,2,2,2,2,2,2,2,2,2,2,6,6,6,6,6,6,6,6,2,2,2,2
2,2,2,2,4,2,2,2,2,2,2,5,2,2,2,2,2,2,2,2,2,2,2,2,2,2,2,2,2,2,2,2,2,2,2,2,2,2,2,2,2,2,2,2,6,6,6,6,6,2,2,2,2,2
2,2,2,2,2,2,2,2,5,5,5,5,5,5,5,2,2,2,2,2,2,2,2,2,2,2,2,2,2,3,2,2,2,2,2,2,2,2,2,5,5,5,5,5,5,2,2,2,2,2,2,2,2,2
2,2,2,2,2,2,2,5,5,5,5,5,5,5,2,2,2,2,2,2,2,2,2,2,2,2,2,2,3,2,2,2,2,2,2,2,2,2,2,5,5,5,5,5,5,2,2,2,2,2,2,2,2,2
2,2,2,2,2,2,5,5,5,5,5,5,5,2,2,2,2,2,2,2,2,2,2,2,2,2,2,2,2,2,2,2,2,2,2,2,2,2,2,2,5,5,5,5,5,2,2,2,2,2,2,2,2,2
2,2,2,2,7,5,5,5,5,5,5,5,2,2,2,2,3,3,2,2,2,2,2,2,2,2,2,2,2,2,2,2,2,2,2,2,2,2,2,2,2,2,2,5,2,2,2,2,2,2,2,2,2,2
2,2,2,2,7,7,7,7,5,5,5,2,2,2,2,2,3,3,2,2,2,2,2,2,2,2,2,2,2,2,2,2,2,2,2,2,2,2,2,2,2,2,2,2,2,2,2,2,2,2,2,2,2,2
2,2,2,2,7,7,7,7,7,5,5,2,2,2,2,2,2,2,2,2,2,2,2,5,2,2,2,3,2,2,2,2,2,2,2,2,2,2,2,2,2,2,2,2,2,2,2,2,2,2,2,2,2,2
2,2,2,2,7,7,7,7,7,7,5,2,2,2,2,2,2,2,2,2,2,2,5,5,5,2,2,2,2,2,2,2,2,2,2,2,2,2,2,4,2,2,2,2,2,2,2,2,2,2,2,2,2,2
2,2,2,2,7,7,7,7,7,7,2,2,2,2,2,2,2,3,3,2,2,2,5,5,5,2,2,2,2,2,2,2,2,2,2,2,2,2,2,4,4,2,2,2,2,2,2,7,7,7,2,2,2,2
2,2,2,2,2,2,4,4,4,2,2,2,2,2,2,2,2,3,3,2,2,2,2,5,5,2,2,2,2,2,2,2,2,2,2,2,2,2,2,4,4,2,2,2,2,3,7,7,7,7,2,2,2,2
2,2,2,2,2,2,4,4,2,2,2,2,2,2,2,2,2,2,2,2,2,2,2,5,5,2,2,2,2,2,2,2,2,2,2,2,2,2,2,4,4,2,2,2,2,7,7,7,7,7,2,2,2,2
2,2,2,2,2,2,2,2,2,2,2,2,2,2,2,2,2,2,2,2,2,2,2,2,2,2,2,2,2,2,2,2,2,2,2,2,2,2,2,2,2,2,2,2,2,2,2,2,2,2,2,2,2,2
2,2,2,2,2,2,2,2,2,2,2,2,2,2,2,2,2,2,2,2,2,2,2,2,2,2,2,2,2,2,2,2,2,2,2,2,2,2,2,2,2,2,2,2,2,2,2,2,2,2,2,2,2,2
2,2,2,2,2,2,2,2,2,2,2,2,2,2,2,2,2,2,2,2,2,2,2,2,2,2,2,2,2,2,2,2,2,2,2,2,2,2,2,2,2,2,2,2,2,2,2,2,2,2,2,2,2,2
:endlayer
layer: 6
2,2,2,2,2,2,2,2,2,2,2,2,2,2,2,2,2,2,2,2,2,2,2,2,2,2,2,2,2,2,2,2,2,2,2,2,5,5,5,5,5,2,2,2,6,2,2,2,2,2,2,2,2,2
2,2,2,2,2,2,2,2,2,2,2,2,2,2,2,2,2,2,2,2,2,2,2,2,2,2,2,2,2,2,2,3,2,2,2,2,5,5,5,2,2,2,2,2,6,6,6,6,6,2,2,2,2,2
2,2,2,2,2,2,2,2,2,2,5,5,2,2,2,2,2,2,2,2,2,2,2,2,2,2,2,2,2,2,2,3,2,2,2,2,2,2,2,2,2,2,2,2,6,6,6,6,6,6,6,6,2,2
2,2,2,2,2,2,2,2,2,5,5,5,2,2,2,2,3,2,2,2,2,2,2,2,2,2,2,13,2,2,2,2,2,2,2,2,2,2,2,2,2,2,2,2,2,6,6,6,6,6,6,6,2,5
2,2,2,2,2,2,2,2,2,5,5,5,5,2,2,2,2,2,2,2,2,2,2,2,2,2,2,2,2,2,2,2,2,2,2,2,2,2,2,2,2,2,2,2,2,2,2,2,2,2,6,6,6,6
2,2,2,2,6,2,2,2,2,0,0,5,5,2,2,2,2,2,2,2,2,2,2,2,2,2,2,2,2,2,2,2,2,2,2,2,2,2,2,2,2,2,2,2,2,3,2,2,2,2,2,6,6,6
2,2,2,2,2,2,2,2,2,0,5,5,5,2,2,2,2,2,2,2,2,2,2,2,2,2,2,2,2,2,2,2,2,2,2,2,2,2,2,2,2,2,2,2,3,2,2,2,2,2,2,6,6,6
2,2,2,2,2,2,2,0,2,5,5,5,5,3,2,2,2,2,2,2,2,2,2,2,2,2,2,2,2,2,2,2,2,2,2,2,2,2,2,2,2,2,2,2,2,2,2,2,2,2,6,6,6,6
2,2,2,2,2,2,2,2,2,5,5,5,5,3,3,2,2,2,2,2,2,2,2,2,2,2,2,2,2,2,2,2,2,2,2,2,2,2,2,2,8,8,2,2,2,2,2,2,2,2,6,6,6,6
2,2,2,2,2,2,2,2,2,2,5,5,5,2,2,2,2,2,2,2,2,2,2,2,2,2,2,2,2,2,2,2,2,2,2,2,2,2,2,2,8,8,8,2,2,2,2,2,3,3,6,6,6,6
2,2,2,2,2,2,2,2,2,2,5,5,2,2,2,2,2,2,2,2,2,2,2,2,2,2,2,2,2,2,2,6,6,2,2,2,2,2,2,2,2,8,8,2,2,2,2,2,3,3,6,6,6,6
2,2,2,2,2,2,2,2,2,2,2,2,2,2,2,2,2,2,2,2,2,2,2,2,2,2,2,2,2,2,2,6,6,2,6,9,2,2,2,2,2,2,2,2,2,2,2,2,2,2,2,6,6,6
2,2,2,2,2,2,2,2,2,2,2,2,2,2,2,2,2,2,2,2,2,2,2,2,2,7,7,2,2,2,2,2,2,6,6,6,2,2,2,2,2,2,3,2,2,2,2,2,2,2,2,6,6,6
2,2,2,2,2,2,2,2,2,2,2,2,2,2,2,2,2,2,2,2,2,2,2,2,2,7,7,7,2,2,2,2,2,6,6,6,6,2,2,2,2,2,2,2,2,2,2,2,2,2,2,2,6,6
2,2,2,2,2,2,2,2,2,2,2,2,2,2,2,2,2,2,2,2,2,2,7,2,7,7,7,7,2,2,2,2,2,2,6,6,6,2,2,2,2,2,2,2,2,2,2,2,2,2,2,6,6,6
2,2,2,2,2,2,2,2,2,2,2,2,2,2,2,2,2,2,2,2,2,2,7,2,7,7,7,7,2,2,2,2,2,2,6,6,6,6,2,2,2,2,2,2,2,2,2,6,6,6,6,6,6,6
2,2,2,2,2,2,2,2,2,2,2,2,2,2,2,2,2,2,2,2,2,2,2,2,7,7,7,7,2,2,2,2,2,2,2,6,6,6,2,2,2,2,2,2,2,6,6,6,6,6,6,6,6,6
2,2,2,2,2,2,2,2,2,2,2,2,2,2,2,2,2,2,2,2,2,2,2,2,7,7,20,20,2,2,2,2,2,2,2,2,2,2,2,2,2,2,2,2,6,6,6,6,6,6,6,6,6,6
2,2,2,2,2,2,2,2,2,2,2,2,2,2,2,2,2,2,2,2,2,2,2,2,2,2,20,20,2,2,2,2,2,2,2,2,2,2,2,2,2,2,2,2,6,6,6,6,6,6,6,6,6,6
2,2,2,2,2,2,2,2,2,2,2,2,2,2,2,2,2,2,2,2,2,2,2,2,2,2,20,20,2,2,2,2,3,3,2,2,2,6,2,2,2,2,2,2,2,2,2,2,6,6,6,6,6,6
2,2,2,2,2,2,2,2,2,2,2,2,2,2,2,2,2,2,2,2,2,14,2,2,2,0,25,25,21,21,21,2,3,3,2,2,5,6,6,2,2,2,2,2,2,2,2,2,2,2,2,2,2,2
2,2,2,2,2,2,2,2,2,2,2,2,2,2,2,2,2,2,2,2,2,19,2,2,2,0,0,0,21,0,0,0,26,2,2,6,6,5,6,7,7,7,2,2,6,6,6,6,2,2,2,6,6,6
2,2,2,2,2,2,2,2,2,2,2,2,2,2,2,2,2,2,2,2,2,19,14,27,28,0,0,0,21,0,0,0,0,0,2,6,6,5,6,6,7,7,7,9,6,6,6,6,6,6,6,6,6,6
2,2,2,2,0,0,0,2,2,2,2,2,2,2,2,2,2,2,2,2,29,14,2,2,0,0,0,0,21,0,0,0,0,0,2,6,6,6,6,6,7,7,7,2,6,6,6,6,6,6,6,6,6,6
2,2,2,2,0,0,0,0,2,2,2,2,2,2,2,2,2,2,2,2,2,2,2,0,0,0,0,0,21,0,0,0,0,0,0,2,6,6,6,6,7,7,7,2,6,6,6,6,6,6,6,6,6,6
2,2,2,2,0,0,0,0,2,2,2,2,2,2,2,2,2,2,2,2,2,2,0,0,0,0,0,0,22,0,0,0,0,0,0,20,20,6,6,6,2,2,2,2,2,2,6,6,6,6,6,6,6,6
2,2,2,2,0,0,0,2,2,2,2,2,2,2,2,2,2,2,2,2,2,2,0,0,0,0,0,0,23,0,0,0,0,0,0,2,6,6,6,6,3,2,2,2,2,2,2,2,2,2,2,2,2,3
2,2,2,2,2,0,2,2,2,2,2,2,2,2,2,2,2,2,2,2,2,2,2,2,0,0,0,0,23,0,0,0,0,0,0,2,6,5,6,3,3,2,2,2,2,2,2,2,2,2,2,2,2,2
2,2,2,2,2,2,2,2,2,2,2,6,2,2,2,2,2,2,2,2,2,2,2,2,0,0,0,0,0,0,0,0,0,0,2,2,6,6,6,6,2,2,2,2,2,2,2,2,2,2,2,2,2,2
2,2,2,2,2,2,2,2,2,2,6,6,6,2,2,2,2,2,2,2,2,2,0,0,0,0,0,0,0,0,0,0,0,26,2,2,2,6,6,6,2,2,2,2,2,6,6,6,6,2,2,2,2,2
2,2,2,2,9,2,2,2,2,6,6,6,6,2,0,0,0,0,0,0,0,0,0,0,0,0,0,0,0,0,0,0,0,2,2,2,2,6,6,6,2,2,2,2,6,6,6,6,6,2,2,2,2,2
2,2,2,2,9,2,2,2,2,2,6,6,6,2,0,0,0,0,0,0,0,0,0,0,0,0,0,0,0,0,0,2,2,2,2,2,2,2,2,2,2,2,2,2,6,6,6,6,2,2,2,2,2,2
2,2,2,2,2,8,2,2,2,2,2,2,2,2,2,2,2,2,2,2,2,2,2,0,0,0,5,0,0,0,5,2,2,2,2,2,2,2,2,2,2,2,2,2,6,6,6,6,2,2,2,2,2,2
2,2,2,2,2,2,2,2,2,2,2,2,2,2,2,2,2,2,2,2,2,2,2,2,2,5,5,0,0,0,5,2,2,2,2,2,2,2,2,2,2,2,2,2,6,6,2,2,2,2,2,2,2,2
2,2,2,2,2,2,2,2,2,2,2,2,2,2,2,2,2,2,2,2,2,2,2,2,2,2,2,0,0,0,5,2,2,2,2,2,2,2,2,2,2,2,2,2,2,2,2,2,2,2,2,2,2,2
2,2,2,2,2,2,2,2,2,2,2,2,2,2,2,2,2,2,2,2,2,2,2,2,2,2,2,0,0,0,2,2,2,2,2,2,2,2,2,2,2,2,2,2,2,2,2,2,2,2,2,2,2,2
2,2,2,2,2,2,2,2,2,2,2,2,2,2,2,2,2,2,2,2,2,2,2,2,2,2,2,0,0,0,2,2,2,2,2,2,2,2,2,2,2,2,2,6,2,2,2,2,2,2,2,2,2,2
2,2,2,2,2,2,2,2,2,2,2,2,3,2,2,2,2,2,2,2,2,2,2,2,2,2,2,0,0,0,2,2,2,2,2,2,2,3,3,2,2,2,2,2,2,2,6,6,6,6,6,2,2,2
2,2,2,2,2,2,2,2,2,2,2,2,2,2,2,2,2,2,2,2,2,2,2,2,2,2,2,0,0,0,2,2,2,2,2,2,2,3,3,2,2,2,2,6,6,6,6,6,6,6,2,2,2,2
2,2,2,2,2,2,2,2,2,2,2,2,2,2,2,2,2,2,2,2,2,2,2,2,2,2,2,0,0,0,2,2,2,2,2,2,2,2,2,2,2,2,2,2,6,6,6,6,6,6,2,2,2,2
2,2,2,2,2,2,2,2,2,2,2,5,5,5,2,2,2,2,2,2,2,2,2,2,2,2,2,2,2,2,2,2,2,2,2,2,2,2,2,2,2,2,2,2,2,6,6,6,6,2,2,2,2,2
2,2,2,2,2,2,2,2,5,5,5,5,5,5,5,2,2,2,2,2,2,2,2,2,2,2,2,2,2,2,2,2,2,2,2,2,2,2,2,5,5,5,5,5,5,2,2,2,2,2,2,2,2,2
2,2,2,2,2,2,2,5,5,5,5,5,5,5,2,2,2,2,2,2,2,2,2,2,2,2,2,2,2,2,2,2,2,2,2,2,2,2,2,5,5,5,5,5,5,5,5,5,2,2,2,2,2,2
2,2,2,2,2,5,5,5,5,5,5,5,5,5,2,2,2,2,2,2,2,2,2,2,2,2,2,2,2,2,2,2,2,2,2,2,2,2,2,2,5,5,5,5,5,5,5,5,2,2,2,2,2,2
2,2,2,2,5,5,5,5,5,5,8,8,2,2,2,2,2,2,2,2,2,2,2,2,2,2,2,2,2,2,2,2,2,2,2,2,2,2,2,2,2,2,5,5,5,5,5,5,2,2,2,2,2,2
2,2,2,2,7,7,5,5,5,5,5,8,2,2,2,2,2,2,2,2,2,2,2,2,2,2,2,2,2,2,2,2,2,2,2,2,2,2,2,2,2,2,2,2,2,2,2,2,2,2,2,2,2,2
2,2,2,2,7,7,7,7,5,5,5,2,2,2,2,2,2,2,2,2,2,2,2,2,2,2,2,2,2,2,2,2,2,2,2,2,2,2,2,2,2,2,2,2,2,2,2,2,2,2,2,2,2,2
2,2,2,2,7,7,7,7,7,5,5,2,2,2,2,2,2,2,2,2,2,2,2,2,2,2,2,2,2,2,2,2,2,2,2,2,2,2,2,2,2,2,2,2,2,2,2,7,7,7,7,2,2,2
2,2,2,2,7,7,7,7,7,2,2,2,2,2,2,2,2,3,3,2,2,2,2,4,2,2,2,2,2,2,2,2,2,2,2,2,2,2,2,2,2,2,2,2,2,2,7,7,7,7,7,2,2,2
2,2,2,2,2,2,2,2,2,2,2,2,2,2,2,2,2,3,3,2,2,2,2,4,2,2,2,2,2,2,2,2,2,2,2,2,2,2,2,2,2,2,2,2,2,2,7,7,7,7,7,2,2,2
2,2,2,2,2,2,2,2,2,2,2,2,2,2,2,2,2,2,2,2,2,2,2,4,4,2,2,2,2,2,2,2,2,2,2,2,2,2,2,2,2,2,2,2,2,7,7,7,7,7,7,2,2,2
2,2,2,2,2,2,2,2,2,2,2,2,2,2,2,2,2,2,2,2,2,2,2,2,2,2,2,2,2,2,2,2,2,2,2,2,2,2,2,2,2,2,2,2,2,2,2,2,2,2,2,2,2,2
2,2,2,2,2,2,2,2,2,2,2,2,2,2,2,2,2,2,2,2,2,2,2,2,2,2,2,2,2,2,2,2,2,2,2,2,2,2,2,2,2,2,2,2,2,2,2,2,2,2,2,2,2,2
2,2,2,2,2,2,2,2,2,2,2,2,2,2,2,2,2,2,2,2,2,2,2,2,2,2,2,2,2,2,2,2,2,2,2,2,2,2,2,2,2,2,2,2,2,2,2,2,2,2,2,2,2,2
:endlayer
layer: 7
2,2,2,2,2,2,2,2,2,2,2,2,2,2,2,2,2,2,2,2,2,2,2,2,2,2,2,2,2,2,2,2,2,2,2,2,2,2,2,2,2,2,2,2,6,2,2,2,2,2,2,2,2,2
2,2,2,2,2,2,2,2,2,2,2,2,2,2,2,2,2,2,2,2,2,2,2,2,2,2,2,2,2,2,3,2,2,2,2,2,2,2,2,2,2,2,2,2,6,6,6,6,6,6,2,2,2,2
2,2,2,2,2,2,2,2,2,2,5,5,2,2,2,2,2,2,2,2,2,2,2,2,2,2,2,2,2,2,3,2,2,2,2,2,2,2,2,2,2,2,2,2,6,6,6,6,6,6,6,6,2,2
2,2,2,2,2,2,2,2,2,5,5,5,2,2,2,2,3,3,2,2,2,2,2,2,2,2,2,13,13,2,2,2,2,2,2,2,2,2,2,2,2,2,2,2,2,6,6,6,6,6,6,6,6,6
2,2,2,2,2,2,2,2,8,5,5,5,5,2,2,2,3,3,2,2,2,2,2,2,2,2,2,2,13,2,2,2,2,2,2,2,2,2,2,2,2,2,2,2,2,2,2,2,6,6,6,6,6,6
2,2,2,2,2,2,2,2,2,0,0,0,5,2,2,2,2,2,2,2,2,2,2,2,2,2,2,2,2,2,2,2,2,2,2,2,2,2,2,2,2,2,2,2,2,3,2,2,2,2,6,6,6,6
2,2,2,2,2,2,2,2,2,0,5,5,5,2,2,2,2,2,2,2,2,2,2,2,2,2,2,2,2,2,2,2,2,2,2,2,2,2,2,2,2,2,2,2,3,2,2,2,2,2,6,6,6,6
2,2,2,2,2,2,2,2,2,0,5,0,5,3,2,2,4,4,4,2,2,2,2,2,2,2,2,2,2,2,2,2,2,2,2,2,2,2,2,2,2,2,2,2,2,2,2,2,2,2,6,6,6,6
2,2,2,2,2,2,2,2,2,5,5,5,5,3,3,2,4,4,2,2,2,2,2,2,2,2,2,2,2,2,2,2,2,2,2,2,2,2,2,2,8,8,2,2,2,3,3,2,2,6,6,6,6,6
2,2,2,2,2,2,2,2,2,5,5,5,5,2,2,4,4,4,2,2,2,2,2,2,2,2,2,2,2,2,2,2,2,2,2,2,2,2,2,2,8,8,8,2,2,3,3,2,2,6,6,6,6,6
2,2,2,2,2,2,2,2,2,2,5,5,5,2,2,4,4,4,2,2,2,2,2,2,2,2,2,2,2,2,2,2,2,2,2,2,2,2,2,2,2,8,8,2,2,2,2,2,2,3,6,6,6,6
2,2,2,2,2,2,2,2,2,2,2,5,2,2,2,2,2,2,2,2,2,2,2,2,2,2,2,2,2,2,2,2,2,2,2,2,2,2,2,2,2,2,2,2,2,2,2,2,2,2,6,6,6,6
2,2,2,2,2,2,2,2,2,2,2,2,2,2,2,2,2,2,2,2,2,2,2,2,7,7,7,7,7,2,2,2,2,6,6,6,2,2,2,2,2,2,2,2,2,2,2,2,2,2,6,6,6,6
2,2,2,2,2,2,2,2,2,2,2,2,2,2,2,2,2,2,2,2,2,7,7,7,7,7,7,7,7,2,2,2,2,6,6,6,6,2,2,2,2,2,2,2,2,2,2,2,2,2,2,6,6,6
2,2,2,2,2,2,3,3,2,2,2,2,2,2,2,2,2,2,2,2,7,7,7,7,7,7,7,7,2,2,2,2,2,2,6,6,6,6,2,2,2,2,2,2,2,2,2,2,2,2,2,6,6,6
2,2,2,2,7,2,3,3,2,2,2,2,2,2,2,2,2,2,2,2,7,7,7,7,7,7,7,7,2,2,2,2,2,2,6,6,6,6,2,2,2,2,2,2,2,2,2,2,6,6,6,6,6,6
2,2,2,2,7,2,2,2,2,2,2,2,2,2,2,2,2,2,2,2,2,7,7,2,7,7,7,7,2,2,2,2,2,2,2,6,6,6,2,2,2,2,2,2,2,2,2,6,6,6,6,6,6,6
2,2,2,2,7,2,2,2,2,2,2,2,2,2,2,2,2,2,2,2,2,2,2,2,7,7,0,0,30,2,2,2,2,2,2,6,6,6,6,2,2,2,2,2,2,2,2,6,6,6,6,6,6,6
2,2,2,2,2,2,2,2,2,2,2,2,2,2,2,2,2,2,2,2,2,2,2,2,0,0,0,0,30,2,2,2,2,2,2,6,6,6,6,2,2,2,2,2,2,2,2,6,6,6,6,6,6,6
2,2,2,2,2,2,2,2,2,2,2,2,2,2,2,2,2,2,2,2,2,2,2,0,0,0,0,0,30,2,2,2,2,2,2,6,6,6,6,2,2,2,2,2,2,2,6,6,6,6,6,6,6,6
2,2,2,2,2,2,2,2,2,2,2,2,2,2,2,2,2,2,2,2,2,2,0,0,0,0,0,0,21,21,21,20,19,2,2,6,5,6,6,2,2,2,2,2,2,2,6,6,6,6,6,2,6,6
2,2,2,2,2,2,2,2,2,2,3,2,2,2,2,2,2,2,2,2,2,0,0,0,0,0,0,0,21,0,0,0,14,2,2,6,6,5,6,7,7,7,7,2,2,6,6,6,2,2,2,2,6,6
2,2,2,2,2,2,2,2,2,2,3,2,2,2,2,2,2,2,2,2,2,0,0,0,0,0,0,0,21,0,0,0,0,0,20,6,6,5,6,7,7,7,7,7,6,6,6,6,6,6,6,6,6,6
2,2,2,2,0,0,0,0,0,0,0,0,0,0,0,0,0,0,0,0,29,0,0,0,0,0,0,0,22,0,0,0,0,0,2,6,6,6,6,6,7,7,7,7,7,6,6,6,6,6,6,6,6,6
2,2,2,2,0,0,0,0,0,0,0,0,0,0,0,0,0,0,0,0,0,0,0,0,0,0,0,0,23,0,0,0,0,0,0,2,6,6,6,6,7,7,7,7,7,7,6,6,6,6,6,6,6,6
2,2,2,2,0,0,0,0,0,0,2,2,2,2,2,2,2,2,2,2,0,0,0,0,0,0,0,0,0,0,0,0,0,0,0,20,6,6,6,6,6,2,2,2,2,2,7,6,6,6,6,7,2,6
2,2,2,2,0,0,0,2,2,2,2,2,2,2,2,2,2,2,2,2,2,0,0,0,0,0,0,0,0,0,0,0,0,0,0,7,6,6,6,6,6,6,2,2,2,2,2,7,7,7,2,2,2,2
2,2,2,2,0,8,8,2,2,2,2,2,2,2,2,2,2,2,2,2,2,2,2,2,0,0,0,0,0,0,0,0,0,0,0,7,6,5,6,6,6,6,6,2,2,2,2,2,2,2,2,2,2,2
2,2,2,2,2,8,8,2,2,2,2,6,6,2,2,2,2,2,2,2,2,2,2,2,0,0,0,0,0,0,0,0,0,0,2,2,6,6,6,6,6,6,6,6,2,2,2,2,2,2,2,2,2,2
2,2,2,2,2,2,2,2,2,2,6,6,6,2,2,2,2,2,2,2,2,2,0,0,0,0,0,0,0,0,0,0,0,26,2,2,6,6,6,6,6,6,6,6,2,2,2,2,2,2,2,2,2,2
2,2,2,2,9,2,2,2,2,2,6,6,6,2,2,2,2,2,2,2,2,2,0,0,0,0,0,0,0,0,0,0,0,2,2,2,2,6,6,6,6,6,6,6,6,6,6,6,2,2,2,2,2,2
2,2,2,2,8,8,2,2,2,2,6,6,6,2,2,2,2,2,2,2,2,2,0,0,0,0,0,0,0,0,0,2,2,2,2,2,2,2,6,6,6,6,6,6,6,6,6,6,2,2,2,2,2,2
2,2,2,2,8,8,2,2,2,2,2,2,2,2,2,2,2,2,2,2,2,2,2,0,0,0,5,0,0,0,2,2,2,2,2,2,2,2,6,6,6,6,6,6,6,6,6,2,2,2,2,2,2,2
2,2,2,2,2,2,2,2,2,2,2,2,2,2,2,2,2,2,2,2,2,2,2,2,2,5,5,0,0,0,5,2,2,2,2,6,6,6,6,6,6,6,6,6,6,6,6,2,2,2,2,2,2,2
2,2,2,2,2,2,2,2,2,2,2,2,2,2,2,2,2,2,2,2,2,2,2,2,2,2,2,0,0,0,8,2,2,2,2,6,6,6,6,6,6,6,6,6,6,6,2,2,2,2,2,2,2,2
2,2,2,2,2,2,2,2,2,2,2,2,2,2,2,2,2,2,2,2,2,2,2,2,2,2,2,0,0,0,2,2,2,2,6,6,6,6,6,2,6,6,6,6,6,2,2,2,2,2,2,2,2,2
2,2,2,2,2,2,2,2,2,2,2,2,2,2,2,2,2,2,2,2,2,2,2,2,2,2,2,0,0,0,2,2,2,2,2,6,6,6,2,2,2,6,6,6,2,2,2,2,2,2,2,2,2,2
2,2,2,2,2,2,2,2,2,2,2,2,2,2,2,2,2,2,2,2,2,2,2,2,2,2,2,0,0,0,2,2,2,2,2,2,2,2,2,2,6,6,6,6,6,2,2,6,6,6,6,2,2,2
2,2,2,2,2,2,2,2,2,2,2,2,2,2,2,2,2,2,2,2,2,2,2,2,2,2,2,0,0,0,2,2,2,2,2,2,2,2,3,2,6,6,6,6,2,2,6,6,6,6,6,2,2,2
2,2,2,2,2,2,2,2,2,2,2,2,2,2,2,2,2,2,2,2,2,2,2,2,2,2,2,0,0,0,2,2,2,2,2,2,2,2,2,6,6,6,6,6,2,2,6,6,6,6,2,2,2,2
2,2,2,2,2,2,2,2,2,2,2,2,2,2,2,2,2,2,2,2,2,2,2,2,2,2,2,2,20,2,2,2,2,2,2,2,2,2,2,6,6,6,6,2,2,2,2,2,2,2,2,2,2,2
2,2,2,2,2,2,2,2,5,5,5,5,5,2,2,2,2,2,2,2,2,2,2,2,2,2,2,2,20,2,2,2,2,2,2,2,2,2,2,6,6,6,5,5,5,2,2,2,2,2,2,2,2,2
2,2,2,2,2,2,2,5,5,5,5,5,5,2,2,2,2,2,2,2,2,2,2,2,2,2,2,2,2,2,2,2,2,2,2,2,2,2,2,6,6,5,5,5,5,5,5,5,2,2,2,2,2,2
2,2,2,2,2,5,5,5,5,5,5,5,5,2,2,2,2,2,2,2,2,2,2,2,2,2,2,2,2,2,2,2,2,2,2,2,2,2,2,2,2,5,5,5,5,5,5,5,5,2,2,2,2,2
2,2,2,2,5,5,5,5,5,5,5,5,2,2,2,2,2,2,2,2,2,2,2,2,2,2,2,2,2,2,2,2,2,2,2,2,2,2,2,2,2,2,5,5,5,5,5,5,5,2,2,2,2,2
2,2,2,2,5,5,5,5,5,2,2,2,2,2,2,2,2,2,2,2,2,2,2,2,8,2,2,2,2,2,2,2,2,2,2,2,2,2,2,2,2,2,2,2,2,2,5,2,2,2,2,2,2,2
2,2,2,2,5,5,5,5,5,5,2,2,2,2,2,2,2,2,2,2,2,2,2,2,2,2,2,2,2,2,2,2,2,2,2,2,2,2,2,2,2,2,2,2,2,2,2,2,2,7,7,7,2,2
2,2,2,2,5,5,5,5,5,2,2,2,2,2,2,2,2,2,2,2,2,2,2,2,2,2,2,2,2,2,2,2,2,2,2,2,2,2,2,2,2,2,2,2,2,2,2,7,7,7,7,7,2,2
2,2,2,2,2,2,2,2,2,2,2,2,2,2,2,2,2,2,2,2,2,2,2,2,2,2,2,2,2,2,2,2,2,2,2,2,2,2,2,2,2,2,2,2,2,2,7,7,7,7,7,7,2,2
2,2,2,2,2,2,2,2,2,2,2,2,2,2,2,2,2,2,2,2,2,2,2,2,2,2,2,2,2,2,2,2,2,2,2,2,2,2,2,2,2,2,2,2,2,2,7,7,7,7,7,2,2,2
2,2,2,2,2,2,2,2,2,2,2,2,2,2,2,2,2,2,2,2,2,2,2,2,2,2,2,2,2,2,2,2,2,2,2,2,2,2,2,2,2,2,2,2,2,7,7,7,7,7,7,2,2,2
2,2,2,2,2,2,2,2,2,2,2,2,2,2,2,2,2,2,2,2,2,2,2,2,2,2,2,2,2,2,2,2,2,2,2,2,2,2,2,2,2,2,2,2,2,2,2,2,2,2,2,2,2,2
2,2,2,2,2,2,2,2,2,2,2,2,2,2,2,2,2,2,2,2,2,2,2,2,2,2,2,2,2,2,2,2,2,2,2,2,2,2,2,2,2,2,2,2,2,2,2,2,2,2,2,2,2,2
2,2,2,2,2,2,2,2,2,2,2,2,2,2,2,2,2,2,2,2,2,2,2,2,2,2,2,2,2,2,2,2,2,2,2,2,2,2,2,2,2,2,2,2,2,2,2,2,2,2,2,2,2,2
:endlayer
layer: 8
2,2,2,2,2,2,2,2,2,2,2,2,2,2,2,2,2,2,2,2,2,2,2,2,2,2,2,2,6,2,2,2,2,2,2,2,2,2,2,2,2,2,2,2,2,2,2,2,2,2,2,2,2,2
2,2,2,2,2,2,2,2,2,2,2,2,2,2,2,2,2,2,2,2,2,2,2,2,2,2,2,2,6,6,2,2,2,2,2,2,2,2,2,2,2,2,2,2,2,6,6,6,6,2,2,2,2,2
2,2,2,2,2,2,2,2,2,2,2,2,2,2,2,2,2,2,2,2,2,2,2,2,2,2,2,2,6,2,3,2,2,2,2,2,2,2,2,2,2,2,2,2,2,6,6,6,6,6,6,6,2,2
2,2,2,2,2,2,2,2,2,8,5,5,2,2,2,2,2,2,2,2,2,2,2,2,2,2,2,2,2,2,2,2,2,2,2,2,2,2,2,2,2,2,2,2,2,2,6,6,6,6,6,6,6,6
2,2,2,2,2,2,2,2,8,5,5,5,2,2,2,2,2,3,2,2,2,2,2,2,2,2,2,2,13,2,2,2,2,2,2,2,2,2,2,2,2,2,2,2,2,2,2,2,2,2,6,6,6,6
2,2,2,2,2,2,2,2,2,0,0,0,2,2,2,2,2,2,2,2,2,2,2,2,2,2,2,2,2,2,2,3,2,2,2,2,2,2,2,2,2,2,2,2,2,2,2,2,2,2,6,6,6,6
2,2,2,2,2,2,2,2,2,0,0,5,5,2,2,2,2,2,2,2,2,2,2,2,2,2,2,2,2,2,2,2,2,2,2,2,2,2,2,2,2,2,2,2,2,2,2,2,2,2,6,6,6,6
2,2,2,2,2,2,2,2,2,0,5,0,5,2,2,2,4,4,4,2,2,2,2,2,2,2,2,2,2,2,2,2,2,2,2,2,2,2,2,8,2,2,2,2,2,2,2,2,2,2,6,6,6,6
2,2,2,2,2,2,2,2,2,5,5,5,5,2,2,2,4,4,2,2,2,2,2,2,2,2,2,2,2,2,2,2,2,2,2,2,2,2,2,8,2,2,2,2,2,2,2,2,2,6,6,6,6,6
2,2,2,2,2,2,2,2,2,5,5,5,5,2,2,4,4,4,2,2,2,2,2,2,2,2,2,2,2,2,2,2,2,2,2,2,2,2,2,2,2,2,2,2,2,2,2,2,2,6,6,6,6,6
2,2,2,2,2,2,2,2,2,2,5,5,5,2,2,4,4,4,2,2,2,2,2,2,2,2,2,2,2,2,2,2,2,2,2,2,2,2,2,2,2,2,2,2,2,2,2,2,2,2,6,6,6,6
2,2,2,2,2,2,2,2,2,2,2,5,2,2,2,2,2,2,2,2,2,2,2,2,2,7,7,7,7,2,2,2,2,2,2,2,2,2,2,2,2,2,2,2,2,2,2,2,2,2,6,6,6,6
2,2,2,2,2,2,2,2,2,2,2,2,2,2,2,2,2,2,2,2,2,2,2,2,7,7,7,7,7,2,2,2,2,2,2,2,2,2,2,2,2,2,2,2,2,2,2,2,2,2,6,6,6,6
2,2,2,2,7,2,2,2,2,2,2,2,2,2,2,2,2,2,2,2,2,7,7,7,7,7,7,7,7,2,5,2,2,2,2,6,2,2,2,2,2,2,2,2,2,2,2,2,2,2,2,6,6,6
2,2,2,2,7,2,3,3,2,2,2,2,2,2,2,2,2,2,2,2,7,7,7,7,7,7,7,7,7,2,2,2,2,2,2,6,6,2,2,2,2,2,2,2,2,2,2,2,2,2,2,2,6,6
2,2,2,2,7,7,3,3,2,2,2,2,2,2,2,2,2,2,2,2,7,7,7,7,7,7,7,7,2,2,2,2,2,2,2,6,6,6,2,2,2,2,2,2,2,2,2,2,2,6,6,6,6,2
2,2,2,2,7,7,2,2,2,2,2,2,2,2,2,2,2,2,2,2,2,7,7,7,7,7,0,7,2,2,2,2,2,2,2,6,6,6,2,2,2,2,2,2,2,2,2,2,6,6,6,6,6,6
2,2,2,2,7,7,2,2,2,2,2,2,2,2,2,2,2,2,2,2,2,2,2,2,2,7,0,0,0,30,20,2,2,2,2,6,6,6,6,2,2,2,2,2,2,2,2,6,6,6,6,6,6,6
2,2,2,2,7,2,2,2,2,2,2,2,2,2,2,2,2,2,2,2,2,2,2,2,0,0,0,0,0,30,20,2,2,2,2,6,6,6,6,2,2,2,2,2,2,2,2,6,6,6,6,6,6,6
2,2,2,2,7,2,2,2,2,2,2,2,2,2,2,2,2,2,2,2,2,2,2,0,0,0,0,0,0,30,20,2,2,2,2,6,6,6,6,2,2,2,2,2,2,2,6,6,6,6,6,6,6,6
2,2,2,2,2,2,2,2,2,2,2,2,2,2,2,2,2,2,2,2,2,2,0,0,0,0,0,0,21,21,21,2,2,2,2,31,5,6,6,2,2,2,2,2,2,2,6,6,6,6,6,2,6,6
2,2,2,2,2,2,2,2,2,2,2,3,2,2,2,2,2,2,2,2,2,0,0,0,0,0,0,0,22,0,0,0,0,2,2,31,31,5,6,7,7,7,7,2,6,6,6,6,8,2,2,7,7,6
2,2,2,2,2,2,2,2,2,2,2,3,2,2,2,2,2,2,2,2,2,0,0,0,0,0,0,0,23,0,0,0,0,0,2,31,31,5,6,7,7,7,7,7,6,6,6,6,8,3,7,7,7,7
2,2,2,2,0,0,0,0,0,0,0,0,0,0,0,0,0,0,0,0,29,0,0,0,0,0,0,0,0,0,0,0,0,0,2,31,31,31,6,7,7,7,7,7,6,6,6,6,7,7,7,7,7,6
2,2,2,2,0,0,0,0,0,0,0,0,0,0,0,0,0,0,0,0,0,0,0,0,0,0,0,0,0,0,0,0,0,0,0,2,31,31,6,6,7,7,7,7,6,6,6,6,7,7,7,7,7,6
2,2,2,2,0,0,0,0,0,0,2,2,2,2,2,2,2,2,2,0,0,0,0,0,0,0,0,0,0,0,0,0,0,0,0,2,31,31,6,6,6,2,2,6,6,6,6,7,7,7,7,7,7,6
2,2,2,2,0,0,0,0,2,2,2,2,2,2,2,2,2,2,2,2,0,0,0,0,0,0,0,0,0,0,0,0,0,0,0,7,6,6,6,6,6,6,2,6,6,6,6,7,7,7,2,2,2,2
2,2,2,2,0,0,8,0,0,7,2,2,2,2,2,2,2,2,2,2,2,2,2,2,0,0,0,0,0,0,0,0,0,0,0,20,6,5,6,6,6,6,6,6,6,6,6,2,2,2,2,2,2,2
2,2,2,2,0,0,8,0,0,7,6,6,6,2,2,2,2,2,2,2,2,2,2,2,0,0,0,0,0,0,0,0,0,0,2,2,6,6,6,6,6,6,6,6,6,6,6,2,2,2,2,2,2,2
2,2,2,2,0,0,0,0,0,7,6,6,6,6,2,2,2,2,2,8,2,2,0,0,0,0,0,0,0,0,0,0,0,26,2,2,6,6,6,6,6,6,6,6,6,6,6,2,2,2,2,2,2,2
2,2,2,2,0,0,0,0,0,2,6,6,6,6,2,2,2,2,2,2,2,2,0,0,0,0,0,0,0,0,0,0,0,2,2,2,2,6,6,6,6,6,6,6,6,6,2,2,2,2,2,2,2,2
2,2,2,2,0,0,0,0,2,2,2,6,6,2,2,2,2,2,2,2,2,2,0,0,0,0,0,0,0,0,0,2,2,2,2,2,2,6,6,6,6,6,6,6,6,6,6,2,2,2,2,2,2,2
2,2,2,2,2,2,0,2,2,2,2,2,2,2,2,2,2,2,2,2,2,2,2,0,0,0,5,0,2,2,2,2,2,2,2,2,6,6,6,6,6,6,6,6,6,6,6,2,2,2,2,2,2,2
2,2,2,2,2,2,2,2,2,2,2,2,2,2,2,2,2,2,2,2,2,2,2,2,2,2,2,3,2,8,8,2,2,2,6,6,6,6,6,6,6,6,6,6,6,6,6,2,2,2,2,2,2,2
2,2,2,2,2,2,2,2,2,2,2,2,2,2,2,7,7,2,2,2,2,2,2,2,2,2,2,2,2,8,8,2,2,2,6,6,6,6,6,6,6,6,6,6,6,6,2,2,2,2,2,2,2,2
2,2,2,2,2,2,2,2,2,2,2,2,2,2,7,7,7,2,2,2,2,2,2,2,2,2,2,2,2,2,2,2,2,6,6,6,6,6,6,6,6,6,6,6,6,2,2,2,2,2,2,2,2,2
2,2,2,2,2,2,2,2,2,2,2,2,2,2,7,7,7,2,2,2,2,2,2,2,2,2,2,2,2,2,2,2,6,6,6,6,6,6,6,6,6,6,6,6,6,6,2,2,2,2,2,2,2,2
2,2,2,2,2,2,2,2,2,2,2,2,2,2,7,7,2,2,2,2,2,2,2,2,3,2,2,2,2,2,2,2,6,6,6,6,6,6,2,2,6,6,6,6,6,6,2,2,6,6,6,2,2,6
2,2,2,2,2,2,2,2,2,2,2,2,2,2,7,2,2,2,2,2,2,2,2,2,2,2,2,2,2,2,2,2,6,6,6,6,6,2,2,6,6,6,6,6,6,6,2,2,6,6,2,2,2,2
2,2,2,2,2,2,2,2,2,2,2,2,2,7,2,2,2,2,2,2,2,2,2,2,2,2,2,2,2,2,2,6,6,6,6,6,2,2,2,6,6,6,6,6,6,2,2,2,2,2,2,2,2,2
2,2,2,2,2,2,2,2,2,2,2,2,2,2,2,2,2,2,2,2,2,2,2,2,2,2,2,2,2,2,2,6,6,6,6,6,2,2,6,6,6,6,6,6,6,2,2,2,2,2,2,2,2,2
2,2,2,2,2,2,2,2,2,2,2,2,2,2,2,2,2,2,2,2,2,2,2,2,2,2,2,2,6,6,6,6,6,6,6,6,2,6,6,6,6,6,6,6,2,2,2,2,2,2,2,2,2,2
2,2,2,2,2,2,2,2,5,5,5,2,2,2,2,2,2,2,2,2,2,2,2,2,2,2,2,6,6,6,6,6,6,6,6,6,6,6,6,6,6,6,6,6,5,5,5,5,2,2,2,2,2,2
2,2,2,2,3,2,2,5,5,5,5,2,2,2,2,2,2,2,2,2,2,2,2,2,2,2,2,6,6,6,6,6,6,6,6,6,6,6,6,6,6,6,6,5,5,5,5,5,5,2,2,2,2,2
2,2,2,2,5,2,5,5,2,5,2,2,2,2,2,2,2,2,2,2,2,2,2,2,8,8,2,2,6,6,6,6,6,6,6,6,6,6,6,6,6,6,2,2,2,5,5,5,5,2,2,2,2,2
2,2,2,2,5,5,5,5,2,2,2,2,2,2,2,2,2,2,2,2,2,2,2,2,8,8,2,2,2,2,2,2,2,2,6,6,6,6,6,2,2,2,2,2,2,2,2,2,2,2,2,2,2,2
2,2,2,2,5,5,5,5,9,2,2,2,2,2,2,2,2,2,2,2,2,2,2,2,2,2,2,2,2,2,2,2,2,2,2,2,2,2,2,2,2,2,2,2,2,2,2,2,2,7,7,7,2,2
2,2,2,2,4,4,2,9,9,2,2,2,2,2,2,2,2,2,2,2,2,2,2,2,2,2,2,2,2,2,2,2,2,2,2,2,2,2,2,2,2,2,2,2,2,2,2,2,7,7,7,7,2,2
2,2,2,2,4,2,2,2,2,2,2,2,2,2,2,2,2,2,2,2,2,2,2,2,2,2,2,2,2,2,2,2,2,2,2,2,2,2,2,2,2,2,2,2,2,2,2,7,7,7,7,7,2,2
2,2,2,2,2,2,2,2,2,2,2,2,2,2,2,2,2,2,2,2,2,2,2,2,2,2,2,2,2,2,2,2,2,2,2,2,2,2,2,2,2,2,2,2,2,2,7,7,7,7,7,2,2,2
2,2,2,2,2,2,2,31,6,2,2,2,2,2,2,2,2,2,2,2,2,2,2,2,2,2,2,2,2,2,2,2,2,2,2,2,2,2,2,2,2,2,2,2,2,2,7,7,7,7,2,2,2,2
2,2,2,2,2,2,2,2,2,2,2,2,2,2,2,2,2,2,2,2,2,2,2,2,2,2,2,2,2,2,2,2,2,2,2,2,2,2,2,2,2,2,2,2,2,2,2,2,2,2,2,2,2,2
2,2,2,2,2,2,2,2,2,2,2,2,2,2,2,2,2,2,2,2,2,2,2,2,2,2,2,2,2,2,2,2,2,2,2,2,2,2,2,2,2,2,2,2,2,2,2,2,2,2,2,2,2,2
2,2,2,2,2,2,2,2,2,2,2,2,2,2,2,2,2,2,2,2,2,2,2,2,2,2,2,2,2,2,2,2,2,2,2,2,2,2,2,2,2,2,2,2,2,2,2,2,2,2,2,2,2,2
:endlayer
layer: 9
2,2,2,2,2,2,2,2,2,2,2,2,2,2,2,2,2,2,2,2,2,2,2,2,2,2,2,2,6,6,6,6,4,4,2,2,2,2,2,2,2,2,2,2,2,2,2,2,2,2,2,2,2,2
2,2,2,2,2,2,2,2,2,2,2,2,2,2,2,2,2,2,2,2,2,2,2,2,4,2,2,2,6,6,6,4,4,4,8,8,2,2,2,2,2,2,2,2,2,2,2,2,2,2,2,2,2,2
2,2,2,2,2,2,2,2,2,2,2,2,2,2,2,2,2,2,2,2,2,2,2,2,4,4,2,2,6,6,2,2,2,2,8,8,2,2,2,2,2,2,2,2,2,2,2,2,2,2,2,2,2,2
2,2,2,2,2,2,2,2,2,2,2,2,2,2,2,2,2,2,2,2,2,2,2,2,2,2,2,2,6,2,2,2,2,2,2,2,2,2,2,2,2,2,2,2,2,2,2,2,2,2,3,2,2,2
2,2,2,2,2,2,2,2,2,2,2,2,2,2,2,2,2,2,2,2,2,2,2,2,2,2,2,2,2,2,2,2,2,2,2,2,2,2,2,2,2,2,2,2,2,2,2,2,2,2,2,3,6,6
2,2,2,2,2,2,2,2,2,2,2,2,2,2,2,2,2,2,7,7,7,2,2,2,2,2,2,2,2,2,2,3,2,2,2,2,2,2,2,2,2,2,2,2,2,2,2,2,2,2,2,6,6,6
2,2,2,2,2,2,2,2,2,2,0,0,2,2,2,2,2,2,7,7,7,2,2,2,2,2,2,2,2,2,2,2,2,2,2,2,2,2,2,2,2,2,2,2,2,2,2,2,2,2,2,6,6,6
2,2,2,2,2,2,2,2,2,2,0,0,2,2,2,2,2,2,7,7,2,2,2,2,2,2,2,2,2,2,2,2,2,2,2,2,2,2,2,2,2,2,2,2,2,2,2,2,2,2,6,6,6,6
2,2,2,2,2,2,2,2,2,2,5,5,2,2,2,2,2,2,7,7,2,2,2,2,2,2,2,2,2,2,2,2,2,2,2,2,2,2,2,2,2,2,2,2,2,2,2,2,2,2,6,6,6,6
2,2,2,2,2,2,2,2,2,2,5,5,2,2,2,2,2,2,2,2,2,2,2,2,2,2,2,2,2,2,2,2,2,2,2,2,2,2,2,2,2,2,2,2,2,2,2,2,2,2,6,6,6,6
2,2,2,2,31,2,2,2,2,2,2,2,2,2,2,2,2,8,2,2,2,2,2,2,2,5,5,5,5,2,2,2,2,2,2,2,2,2,2,2,2,2,2,2,2,2,2,2,2,2,6,6,6,6
2,2,2,2,31,2,2,2,2,2,2,2,2,2,2,2,2,2,2,2,2,2,2,2,2,5,7,7,7,5,5,2,2,2,2,2,2,2,2,2,2,2,2,2,2,2,2,2,2,2,2,6,6,6
2,2,2,2,31,2,2,2,2,2,2,2,2,2,2,2,2,2,2,2,2,2,2,2,7,7,7,7,7,5,5,5,2,2,2,2,2,2,2,2,2,2,2,2,2,2,2,2,2,2,2,6,6,6
2,2,2,2,7,2,2,2,2,2,2,2,2,2,2,2,2,2,2,2,2,2,2,7,7,7,7,7,7,5,5,5,5,2,2,2,2,2,2,2,2,2,2,2,2,2,2,2,2,2,2,2,6,6
2,2,2,2,7,2,2,2,2,2,2,2,2,2,2,2,2,2,2,2,2,7,7,7,7,7,7,7,2,5,5,5,5,2,2,2,2,2,2,2,2,2,2,2,2,2,2,2,2,2,2,2,2,2
2,2,2,2,7,7,2,2,2,2,2,2,2,2,2,2,2,2,2,2,2,7,7,7,7,7,7,2,31,31,31,5,5,2,2,2,2,2,2,2,2,2,2,2,2,2,2,2,2,2,2,2,2,2
2,2,2,2,7,7,2,2,2,2,2,2,2,2,2,2,2,2,2,2,2,2,2,2,2,2,2,2,31,31,31,31,31,2,2,2,2,2,2,2,2,2,2,2,2,2,2,2,2,6,6,2,2,31
2,2,2,2,7,7,2,2,2,2,2,2,2,2,2,2,2,2,2,2,2,2,2,2,2,2,0,0,0,0,0,0,2,2,2,2,6,6,2,2,2,2,2,2,2,2,2,2,6,31,31,31,31,31
2,2,2,2,7,2,2,2,2,2,2,2,2,2,2,2,2,2,2,2,2,2,2,2,0,0,0,0,0,0,0,0,2,2,2,2,6,6,2,2,2,2,2,2,2,2,2,6,31,31,31,31,31,31
2,2,2,2,7,2,2,2,2,2,2,2,2,2,2,2,2,2,2,2,2,2,2,0,0,0,0,0,0,0,0,0,0,0,0,2,6,6,2,2,2,2,2,2,2,2,6,31,31,31,31,31,31,31
2,2,2,2,2,2,2,2,2,2,2,2,2,2,2,2,2,2,2,2,2,2,0,0,0,0,0,0,32,24,24,24,24,33,0,0,5,6,2,2,2,2,2,2,2,2,31,31,31,31,31,31,31,31
2,2,2,2,2,2,2,2,2,2,2,2,2,2,2,2,2,2,2,2,2,0,0,0,0,0,0,0,0,0,0,0,0,34,33,0,0,5,7,7,7,7,2,2,6,6,6,6,2,2,2,2,7,31
2,2,2,2,2,2,2,2,2,2,2,2,2,2,2,2,2,2,2,2,2,0,0,0,0,0,0,0,0,0,0,0,0,0,23,0,0,5,7,7,7,7,7,2,6,6,6,6,2,2,2,7,7,31
2,2,2,2,0,0,0,0,0,0,0,0,0,0,0,0,0,0,0,0,29,0,0,0,0,0,0,0,0,0,0,0,0,0,23,0,0,0,7,7,7,7,7,2,6,6,6,6,7,7,7,7,7,31
2,2,2,2,0,0,0,0,0,0,0,0,0,0,0,0,0,0,0,0,0,0,0,0,0,0,0,0,0,0,0,0,0,0,0,0,0,0,2,2,7,7,7,6,6,6,6,6,7,7,7,7,7,31
2,2,2,2,0,0,0,0,2,2,2,2,2,2,2,2,2,2,2,2,0,0,0,0,0,0,0,0,0,0,0,0,0,0,0,35,35,35,7,6,2,2,2,6,6,6,6,6,7,7,7,2,2,2
2,2,2,2,0,0,0,0,7,7,7,2,2,2,2,2,2,2,2,2,0,0,0,0,0,0,0,0,0,0,0,0,0,0,0,2,31,31,6,6,6,2,2,6,6,6,6,2,2,2,2,2,2,2
2,2,2,2,0,0,0,0,0,7,7,2,2,2,2,2,2,2,2,2,2,2,2,2,0,0,0,0,0,0,0,0,0,0,0,2,2,5,6,6,6,6,2,6,6,6,6,2,2,2,2,2,2,2
2,2,2,2,0,0,0,0,0,7,2,31,31,6,2,2,2,2,8,8,2,2,2,2,0,0,0,0,0,0,0,0,0,0,2,2,2,6,6,6,6,6,6,6,6,6,6,2,2,2,2,2,2,2
2,2,2,2,0,0,0,0,0,7,31,31,31,31,2,2,2,2,8,8,2,0,0,0,0,0,0,0,0,0,0,0,0,14,19,2,2,6,6,6,6,6,6,6,6,6,6,2,2,2,2,2,2,2
2,2,2,2,0,0,0,0,0,7,6,31,31,31,2,2,2,2,2,2,2,2,0,0,0,0,0,0,0,0,0,0,0,2,2,2,2,6,6,6,6,6,6,6,6,6,2,2,2,2,2,2,2,2
2,2,2,2,0,0,0,0,0,2,2,6,31,2,2,2,2,2,2,2,2,2,0,0,0,0,0,0,0,0,0,2,2,2,2,2,2,6,6,6,6,6,6,6,6,6,2,2,2,2,2,2,2,2
2,2,2,2,0,0,0,0,2,2,2,2,2,2,2,2,7,2,2,2,2,2,2,0,0,0,2,2,2,2,2,2,2,2,2,2,6,6,6,6,6,6,6,6,6,6,2,2,2,2,2,2,2,2
2,2,2,2,0,0,2,2,2,2,2,2,2,2,2,7,7,7,2,2,2,2,2,2,2,2,2,3,2,2,2,2,2,2,6,6,6,6,6,6,6,6,6,6,6,6,2,2,2,2,2,2,2,2
2,2,2,2,2,2,2,2,2,2,2,2,2,2,7,7,7,7,2,2,2,2,2,2,2,2,2,3,2,2,2,2,2,6,6,6,6,6,6,6,6,6,6,6,6,6,2,2,2,2,2,2,2,2
2,2,2,2,2,2,2,2,2,2,2,2,2,2,7,7,7,7,2,2,2,2,2,2,2,2,2,2,2,2,2,2,2,6,6,6,6,6,6,6,6,6,6,6,6,6,2,2,2,2,2,2,2,2
2,2,2,2,2,2,2,2,2,2,2,2,2,7,7,7,7,2,2,2,2,2,2,3,3,2,2,2,2,2,2,2,6,6,6,6,6,6,6,6,6,6,6,6,6,6,2,2,2,2,2,2,2,2
2,2,2,2,2,2,2,2,2,6,6,6,2,7,7,7,7,2,3,3,2,2,2,3,3,2,2,2,2,2,2,2,6,6,6,6,6,6,2,2,2,6,6,6,6,6,2,2,2,2,2,2,2,6
2,2,2,2,2,2,2,2,2,2,6,6,2,7,7,7,2,2,3,3,2,2,2,2,2,2,2,2,2,2,2,6,6,6,6,6,6,2,2,2,6,6,6,6,6,6,2,2,2,2,2,2,2,2
2,2,2,2,2,2,2,2,2,6,6,6,7,7,7,2,2,2,2,2,2,2,2,2,2,2,2,2,2,2,2,6,6,6,6,6,6,2,2,6,6,6,6,6,6,6,2,2,2,2,2,2,2,2
2,2,2,2,2,2,2,2,6,6,6,6,2,7,7,2,2,2,2,2,2,2,2,2,2,2,2,2,2,2,2,6,6,6,6,6,9,9,6,6,6,6,6,6,6,6,2,2,2,2,2,2,2,2
2,2,2,2,2,2,2,6,6,6,6,6,2,7,2,2,2,2,2,2,2,2,2,2,6,6,6,6,6,6,6,6,6,6,6,6,6,6,6,6,6,6,6,6,6,6,2,2,2,2,2,2,2,2
2,2,2,2,3,3,6,6,6,6,6,2,2,2,2,2,2,2,2,2,2,2,2,5,6,6,6,6,6,6,6,6,6,6,6,6,6,6,6,6,6,6,6,6,6,2,2,2,2,2,2,2,2,2
2,2,2,2,3,3,6,6,6,6,2,2,2,2,2,2,2,2,3,2,2,2,2,2,6,6,6,6,6,6,6,6,6,6,6,6,6,6,6,6,6,6,6,6,2,2,5,2,2,2,2,2,2,2
2,2,2,2,2,2,6,31,31,31,2,2,2,2,2,2,2,2,2,2,2,2,2,2,8,8,6,6,6,6,6,6,7,7,6,6,6,6,6,6,6,6,6,2,2,2,2,2,2,2,2,2,2,2
2,2,2,2,2,2,31,5,31,31,2,2,2,2,2,2,2,2,2,2,2,2,2,2,8,8,2,2,2,2,2,2,7,7,7,6,6,6,6,6,2,2,2,2,2,2,2,2,2,2,2,2,2,2
2,2,2,2,4,4,5,5,5,5,2,2,2,2,2,2,2,2,2,2,2,2,2,2,2,2,2,2,2,2,2,2,2,2,2,8,8,2,2,2,2,2,2,2,2,2,2,2,2,2,2,2,2,2
2,2,2,2,4,4,5,5,31,31,2,2,2,2,2,2,2,2,2,2,2,2,2,2,2,2,2,2,2,2,2,2,2,2,2,8,8,2,2,2,2,2,2,2,2,2,2,2,2,7,7,2,2,2
2,2,2,2,4,2,31,31,31,31,2,2,2,2,2,2,2,2,2,2,2,2,2,2,2,2,2,2,2,2,2,2,2,2,2,2,2,2,2,2,2,2,2,2,2,2,2,2,2,7,2,2,2,2
2,2,2,2,2,2,31,31,31,31,2,2,2,2,2,2,2,2,2,2,2,2,2,2,2,2,2,2,2,2,2,2,2,2,2,2,2,2,2,2,2,2,2,2,2,2,2,2,7,7,2,2,2,2
2,2,2,2,2,2,2,31,31,31,2,2,2,2,2,2,2,2,2,2,2,2,2,2,2,2,2,2,2,2,2,2,2,2,2,2,2,2,2,2,2,2,2,2,2,2,2,2,2,2,2,2,2,2
2,2,2,2,2,2,2,2,2,2,2,2,2,2,2,2,2,2,2,2,2,2,2,2,2,2,2,2,2,2,2,2,2,2,2,2,2,2,2,2,2,2,2,2,2,2,2,2,2,2,2,2,2,2
2,2,2,2,2,2,2,2,2,2,2,2,2,2,2,2,2,2,2,2,2,2,2,2,2,2,2,2,2,2,2,2,2,2,2,2,2,2,2,2,2,2,2,2,2,2,2,2,2,2,2,2,2,2
2,2,2,2,2,2,2,2,2,2,2,2,2,2,2,2,2,2,2,2,2,2,2,2,2,2,2,2,2,2,2,2,2,2,2,2,2,2,2,2,2,2,2,2,2,2,2,2,2,2,2,2,2,2
:endlayer
layer: 10
2,2,2,2,2,2,2,2,2,2,2,2,2,2,2,2,2,2,2,2,2,2,2,2,2,2,2,2,0,0,0,0,4,4,2,2,2,2,2,2,2,2,2,2,2,2,2,2,2,2,2,2,2,2
2,2,2,2,2,2,2,2,2,2,2,2,2,2,2,2,2,2,2,2,2,2,2,2,4,2,2,2,0,0,0,0,4,4,8,2,2,2,2,2,2,2,2,2,2,2,2,2,2,2,2,2,2,2
2,2,2,2,2,2,2,2,2,2,2,2,2,2,8,2,2,2,2,2,2,2,2,2,4,4,4,2,0,0,2,2,4,2,10,2,2,2,2,2,2,2,2,2,2,2,2,2,2,2,2,2,2,2
2,2,2,2,2,2,2,2,2,2,2,2,2,8,2,2,2,2,2,7,7,2,2,2,2,4,4,4,2,2,2,2,2,10,2,2,2,2,2,2,2,2,2,2,2,2,2,2,2,2,2,2,2,2
2,2,2,2,2,2,2,2,2,2,2,2,2,2,2,2,2,2,7,7,7,2,2,2,2,2,4,4,2,2,2,2,2,2,2,2,2,2,2,2,2,2,2,2,2,2,2,2,2,2,2,2,2,2
2,2,2,2,2,2,2,2,2,2,2,2,2,2,2,2,2,2,7,7,7,2,2,2,2,2,2,2,2,2,2,2,2,2,2,2,2,2,2,2,2,2,2,2,2,2,2,2,2,2,2,2,2,0
2,2,2,2,2,2,2,2,2,2,2,2,2,2,0,0,2,7,7,7,7,7,2,2,2,2,2,2,2,2,2,2,3,2,2,2,2,2,2,2,2,2,2,2,2,2,2,2,2,2,2,2,0,0
2,2,2,2,2,2,2,2,2,2,2,2,2,0,0,0,0,0,0,7,7,2,2,2,2,2,2,2,2,2,2,2,2,2,2,2,2,2,2,2,2,2,2,2,2,2,2,2,2,2,2,2,0,0
2,2,2,2,2,2,2,0,0,0,2,2,2,0,0,0,0,0,0,0,7,2,2,2,2,2,2,2,2,2,2,2,2,2,2,2,2,2,2,2,2,2,2,2,0,2,2,2,2,2,2,2,0,0
2,2,2,2,27,0,0,0,0,0,0,0,2,2,0,0,0,0,0,0,0,2,2,2,2,2,2,2,2,2,2,2,2,2,2,2,2,2,2,2,2,2,2,2,0,2,2,2,2,2,2,0,0,0
2,2,2,2,28,0,0,0,0,0,0,0,0,2,2,0,0,0,0,0,2,2,2,2,2,5,5,5,5,5,2,2,2,2,2,2,2,2,2,2,2,2,2,2,0,0,2,2,2,2,2,0,0,0
2,2,2,2,36,0,0,0,0,0,0,0,2,2,2,2,0,0,0,2,2,2,2,2,2,5,5,5,5,5,5,5,2,2,2,2,2,2,2,2,2,2,2,2,0,0,2,2,2,2,2,0,0,0
2,2,2,2,37,0,0,0,0,0,0,2,2,2,2,2,2,2,2,2,2,2,2,2,2,2,7,7,5,5,5,5,5,2,2,2,2,2,2,2,2,2,2,2,0,2,2,2,2,2,2,2,2,0
2,2,2,2,38,0,0,0,0,0,2,2,2,2,2,2,2,2,2,2,2,2,2,2,2,7,7,7,5,5,5,0,0,5,2,2,2,2,2,2,2,2,2,2,2,2,2,2,2,2,2,2,2,2
2,2,2,2,0,0,0,2,2,2,2,2,2,2,2,2,2,2,2,2,2,2,2,2,2,2,7,2,2,5,5,0,0,5,2,2,2,2,2,2,2,2,2,2,2,2,0,0,2,2,2,2,2,2
2,2,2,2,7,2,2,2,2,2,2,2,2,2,2,2,2,2,2,2,2,2,2,2,2,2,2,2,0,0,0,0,0,5,2,2,2,2,2,2,2,2,2,2,2,0,0,0,0,2,2,2,2,2
2,2,2,2,7,7,2,2,2,2,2,2,2,2,2,2,2,2,2,2,2,2,2,2,2,2,2,2,0,0,0,0,0,2,2,2,2,2,2,2,2,2,2,2,2,0,0,0,0,0,2,2,2,0
2,2,2,2,7,2,2,2,2,3,2,2,2,2,2,2,2,2,2,2,0,0,0,2,2,2,0,0,0,0,0,0,2,2,2,2,2,2,2,2,2,2,2,2,2,0,0,0,0,0,0,0,0,0
2,2,2,2,7,2,2,2,2,2,2,2,2,2,2,2,2,2,2,2,0,0,0,2,0,0,0,0,0,0,0,0,2,2,2,2,2,2,2,2,2,2,2,2,2,2,0,0,0,0,0,0,0,0
2,2,2,2,7,2,2,2,2,2,2,2,2,2,2,2,2,2,2,2,0,0,2,0,0,0,0,0,0,0,0,0,0,0,0,2,2,2,2,2,2,2,2,2,2,2,2,0,0,0,0,0,0,0
2,2,2,2,2,2,2,2,2,2,2,2,2,2,2,2,2,2,2,2,2,2,0,0,0,0,0,0,0,0,0,0,0,0,0,0,2,2,2,2,2,2,2,2,2,2,0,0,0,0,0,0,0,0
2,2,2,2,2,2,2,2,2,2,2,2,2,2,2,2,2,2,2,2,2,0,0,0,0,0,0,0,0,0,0,0,0,0,0,0,0,2,2,2,2,2,2,2,2,0,0,8,2,2,2,2,2,0
2,2,2,2,2,2,2,2,2,2,2,2,2,2,2,2,2,2,2,2,2,0,0,0,0,0,0,0,0,0,0,0,0,0,0,0,0,2,2,2,2,2,2,2,0,0,0,2,2,2,2,2,7,0
2,2,2,2,0,0,2,2,2,2,2,2,2,2,2,2,2,2,2,2,29,0,0,0,0,0,0,0,0,0,0,0,0,0,0,0,0,0,2,2,2,2,2,2,0,0,0,2,2,2,2,7,7,0
2,2,2,2,0,0,2,2,2,2,2,2,2,2,2,2,2,2,2,2,0,0,0,0,0,0,0,0,0,0,0,0,0,0,0,0,0,0,2,2,2,2,2,2,0,0,0,2,2,2,2,2,7,0
2,2,2,2,0,0,2,2,2,2,2,2,2,2,2,2,2,2,2,2,0,0,0,0,0,0,0,0,0,0,0,0,0,0,0,0,0,0,2,2,2,2,2,2,0,0,0,2,2,2,2,2,2,0
2,2,2,2,0,0,2,2,7,7,7,2,2,2,2,2,2,2,2,2,0,0,0,0,0,0,0,0,0,0,0,0,0,0,0,35,35,35,2,2,2,2,2,0,0,0,0,2,2,2,2,2,2,0
2,2,2,2,0,0,0,0,0,7,7,0,20,39,2,2,2,2,2,2,2,2,2,0,0,0,0,0,0,0,0,0,0,0,21,2,2,2,2,2,2,2,2,0,0,0,0,2,2,2,2,2,2,2
2,2,2,2,0,0,0,0,0,7,2,0,0,20,0,0,2,2,8,2,2,2,2,0,0,0,0,0,0,0,0,0,0,0,2,2,2,2,2,2,2,2,0,0,0,0,0,2,2,2,2,2,2,2
2,2,2,2,0,0,0,0,0,7,0,0,0,0,0,0,2,2,2,2,2,0,0,0,0,0,0,0,0,0,0,0,0,0,2,2,2,2,2,2,2,2,0,0,0,0,0,2,2,2,2,2,2,2
2,2,2,2,0,0,0,0,0,7,2,0,0,0,0,2,2,2,2,2,2,0,0,0,0,0,0,0,0,0,0,0,0,2,2,2,2,2,2,0,0,0,0,0,0,0,2,2,2,2,2,2,2,2
2,2,2,2,0,0,0,0,0,2,2,2,0,2,2,2,2,2,2,2,2,2,0,0,0,0,0,0,0,0,0,2,2,2,2,2,2,2,0,0,0,0,0,0,0,0,2,2,2,2,2,2,2,2
2,2,2,2,0,0,0,0,2,2,2,2,2,2,2,2,7,2,2,2,2,2,2,21,21,21,2,2,2,2,2,2,2,2,2,2,0,0,0,0,0,0,0,0,2,2,2,2,2,2,2,2,2,2
2,2,2,2,0,0,2,2,2,2,2,2,2,2,2,7,7,7,2,2,2,2,2,2,2,2,2,2,2,2,2,2,2,2,2,0,0,0,0,0,0,0,0,0,0,2,2,2,2,2,2,2,2,2
2,2,2,2,2,2,2,2,2,2,2,2,2,2,7,7,7,7,2,2,2,2,2,2,2,2,5,2,2,2,2,2,2,2,0,0,0,0,0,0,0,0,0,0,0,2,2,2,2,2,2,2,2,2
2,2,2,2,2,2,2,2,2,2,2,2,2,2,7,7,7,7,2,2,2,2,2,2,2,2,5,2,2,2,2,2,2,0,0,0,0,0,0,0,0,0,0,0,0,2,2,2,2,2,2,2,2,2
2,2,2,2,2,2,2,2,2,2,2,2,2,7,7,7,7,2,2,2,2,2,2,3,2,2,2,2,2,2,2,2,0,0,0,0,0,0,0,0,0,0,0,0,0,2,2,2,2,2,2,2,2,2
2,2,2,2,2,2,2,2,2,0,0,0,2,7,7,7,7,2,2,2,2,2,2,2,2,2,2,2,2,2,2,2,0,0,0,0,0,0,2,2,2,2,0,0,0,0,2,2,2,2,2,2,2,2
2,2,2,2,2,2,2,2,2,0,0,0,2,7,7,7,2,2,2,2,2,2,2,2,2,2,2,2,2,2,2,0,0,0,0,0,0,2,2,2,2,2,0,0,0,0,2,2,2,2,2,2,2,2
2,2,2,2,2,2,2,2,2,0,0,0,7,7,7,2,2,2,2,2,2,2,2,2,2,2,2,2,2,2,2,0,0,0,0,0,2,2,2,2,0,0,0,0,0,0,2,2,2,2,2,2,2,2
2,2,2,2,2,2,2,2,0,0,0,0,2,7,7,0,0,2,2,2,2,0,2,2,0,0,2,2,2,2,2,0,0,0,0,0,9,9,2,0,0,0,0,0,0,0,2,2,2,2,2,2,2,2
2,2,2,2,2,2,2,0,0,0,0,0,2,7,2,2,2,2,2,0,0,5,5,0,0,0,0,0,0,0,0,0,0,0,0,0,0,0,0,0,0,0,0,0,0,0,2,2,2,2,2,2,2,2
2,2,2,2,2,3,0,0,0,0,0,0,2,2,2,2,2,2,2,0,0,5,5,5,0,0,0,0,0,0,0,0,0,0,0,0,0,0,0,0,0,0,0,0,0,2,2,2,2,2,2,2,2,2
2,2,2,2,2,2,0,0,0,0,0,0,2,2,2,2,2,2,2,0,0,5,5,5,0,0,0,0,0,0,0,0,0,0,0,0,0,0,0,0,0,0,0,0,2,2,2,2,2,2,2,2,2,2
2,2,2,2,2,2,0,0,0,0,0,2,2,2,2,2,2,2,2,2,2,0,0,0,0,0,0,0,0,0,0,0,0,0,0,0,0,0,0,0,0,0,0,2,2,2,2,2,2,2,2,2,2,2
2,2,2,2,2,2,0,0,0,0,0,2,2,2,2,2,2,2,2,2,2,0,0,0,0,0,0,0,2,2,2,2,7,7,0,0,0,0,0,0,2,2,2,2,2,2,2,2,2,2,2,2,2,2
2,2,2,2,2,2,0,0,0,0,0,2,0,0,0,2,2,2,2,2,2,0,0,0,0,20,20,20,2,2,2,2,2,0,0,40,0,0,7,0,2,2,2,2,2,2,2,2,2,2,2,2,2,2
2,2,2,2,2,2,0,0,0,0,0,2,0,0,0,2,2,2,2,2,2,2,2,2,0,0,0,17,2,2,2,2,2,2,2,2,2,2,2,0,0,0,0,0,0,0,0,0,0,0,0,0,0,0
2,2,2,2,2,2,0,0,0,0,0,2,0,0,0,2,2,2,2,2,2,2,2,2,2,0,17,16,2,2,2,2,2,2,2,2,2,2,2,2,2,2,0,2,2,2,2,2,0,2,2,2,2,2
2,2,2,2,2,2,0,0,0,0,0,2,2,0,2,2,2,2,2,2,2,2,2,3,3,0,16,18,2,2,2,2,2,2,2,2,2,2,2,2,2,2,0,2,2,2,2,2,0,2,2,2,2,2
2,2,2,2,2,2,2,0,0,0,0,2,2,2,2,2,2,2,2,2,2,2,2,2,2,2,18,11,2,2,2,2,2,2,41,0,2,2,2,2,2,2,0,2,2,2,2,2,0,2,2,2,2,2
2,2,2,2,2,2,2,2,2,2,2,2,2,2,2,2,2,2,2,2,2,2,2,2,2,2,2,2,2,2,2,2,2,2,2,2,2,2,2,2,2,2,2,2,2,2,2,2,2,2,2,2,2,2
2,2,2,2,2,2,2,2,2,2,2,2,2,2,2,2,2,2,2,2,2,2,2,2,2,2,2,2,2,2,2,2,2,2,2,2,2,2,2,2,2,2,2,2,2,2,2,2,2,2,2,2,2,2
2,2,2,2,2,2,2,2,2,2,2,2,2,2,2,2,2,2,2,2,2,2,2,2,2,2,2,2,2,2,2,2,2,2,2,2,2,2,2,2,2,2,2,2,2,2,2,2,2,2,2,2,2,2
:endlayer
layer: 11
2,2,2,2,2,2,2,2,2,2,2,2,2,2,2,2,2,2,2,2,2,2,2,2,2,2,2,7,7,0,0,0,4,2,2,2,2,2,2,2,2,2,2,2,2,2,2,2,2,2,2,2,2,2
2,2,2,2,2,2,2,2,2,2,2,2,2,2,2,2,2,2,2,2,2,2,2,2,2,2,2,2,0,0,0,7,4,2,2,2,2,2,2,2,2,2,2,2,2,2,2,2,2,2,2,2,2,2
2,2,2,2,2,2,2,2,2,2,2,2,2,2,8,2,2,2,2,2,2,2,2,2,2,2,2,2,2,2,2,2,2,2,10,2,2,2,2,2,2,2,2,2,2,2,2,2,2,2,2,2,2,2
2,2,2,2,2,2,2,2,2,2,2,2,2,8,2,2,2,2,2,7,7,2,2,2,2,2,4,4,2,2,2,2,2,10,2,2,2,2,2,2,2,2,2,2,2,2,2,2,2,2,2,2,2,2
2,2,2,2,2,2,2,2,2,2,2,2,2,2,2,2,2,2,7,7,7,2,2,2,2,2,2,4,2,2,2,2,2,2,2,2,2,2,2,2,2,2,2,2,2,2,2,2,2,2,2,2,2,2
2,2,2,2,2,2,2,2,2,2,2,0,0,0,0,0,2,7,7,7,7,7,0,2,2,2,2,2,2,2,2,2,2,2,2,2,2,2,2,2,2,2,2,2,2,2,2,2,2,2,2,2,2,0
2,2,2,2,2,2,2,2,2,2,2,2,0,0,0,0,0,7,0,0,0,0,0,0,0,2,2,2,2,2,2,2,3,2,2,2,2,2,2,2,2,2,2,2,2,2,2,2,2,2,2,2,0,0
2,2,2,2,2,2,2,2,2,2,2,2,0,0,0,0,0,0,0,0,0,0,0,0,0,2,2,2,2,2,2,2,2,2,2,2,2,2,2,2,2,2,2,2,0,2,2,2,2,2,2,2,0,0
2,2,2,2,0,0,0,0,0,0,0,0,2,0,0,0,0,0,0,0,0,0,0,0,0,2,2,2,2,2,2,2,2,2,2,2,2,2,2,2,2,2,2,2,0,2,2,2,2,2,2,2,0,0
2,2,2,2,0,0,0,0,0,0,0,0,2,0,0,0,0,0,0,0,0,0,0,0,2,2,2,2,2,2,2,2,2,2,2,2,2,2,2,2,2,2,2,2,0,0,2,2,8,8,2,0,0,0
2,2,2,2,0,0,0,0,0,0,0,0,0,2,0,0,0,0,0,0,0,2,2,2,2,2,2,5,5,2,2,2,2,2,2,2,2,2,2,2,2,2,2,2,0,0,2,2,8,8,2,0,0,0
2,2,2,2,0,0,0,0,0,0,0,0,2,2,2,0,0,0,0,0,2,2,2,2,2,2,5,5,5,5,5,2,2,2,2,2,2,2,2,2,2,2,2,2,0,0,0,2,2,2,2,0,0,0
2,2,2,2,0,0,0,0,0,0,0,0,2,2,2,0,0,0,0,0,2,2,2,2,2,2,5,5,5,5,5,0,0,2,2,2,2,2,2,2,2,2,2,2,0,0,0,2,2,2,2,0,0,0
2,2,2,2,0,0,0,0,0,0,0,0,2,2,2,2,0,0,0,0,0,2,2,2,2,2,2,2,5,5,5,0,0,0,2,2,2,2,2,2,2,2,2,2,0,0,0,2,2,7,2,2,0,0
2,2,2,2,0,0,0,0,0,0,2,2,2,2,2,2,0,0,0,0,0,2,2,2,2,2,2,2,2,5,5,0,0,0,2,2,2,2,2,2,2,2,2,2,0,0,0,0,2,7,7,7,2,2
2,2,2,2,2,2,2,2,2,2,2,2,2,2,2,2,2,0,0,0,0,0,2,2,2,2,2,2,0,0,0,0,0,5,2,2,2,2,2,2,2,2,2,2,0,0,0,0,0,7,7,7,7,2
2,2,2,2,2,2,2,2,2,2,2,2,2,2,2,2,2,2,0,0,0,0,0,2,2,2,2,2,0,0,0,0,0,2,2,2,2,2,2,2,2,3,2,2,0,0,0,0,0,0,0,7,7,2
2,2,2,2,2,2,2,2,2,3,3,2,2,2,2,2,2,2,2,0,0,0,0,2,2,2,0,0,0,0,0,0,2,2,2,2,2,2,2,2,2,2,2,2,2,0,0,0,0,0,0,0,0,0
2,2,2,2,2,2,2,2,2,3,3,2,2,2,2,2,2,2,2,0,0,0,0,2,0,0,0,0,0,0,0,0,2,2,2,2,2,2,2,2,2,2,2,2,2,5,0,0,0,0,0,0,0,0
2,2,2,2,2,2,2,2,2,2,2,2,2,2,2,2,2,2,2,0,0,0,5,0,0,0,0,0,0,0,0,0,0,0,0,2,2,2,2,2,2,2,2,2,2,2,2,2,0,0,0,0,0,0
2,2,2,2,2,2,2,2,2,2,2,2,2,2,2,2,2,2,2,0,0,5,0,0,0,0,0,0,0,0,0,0,0,0,0,0,2,2,2,2,2,2,2,2,2,2,2,2,0,0,0,0,0,0
2,2,2,2,2,2,2,2,2,2,2,2,2,2,2,2,2,2,2,2,2,0,0,0,0,0,0,0,0,0,0,0,0,0,0,0,0,2,2,2,2,2,2,2,2,2,2,2,2,2,2,2,2,0
2,2,2,2,2,2,2,2,2,2,2,2,2,2,2,2,2,2,2,2,2,0,0,0,0,0,0,0,0,0,0,0,0,0,0,0,0,2,2,2,2,2,2,2,2,2,2,2,2,2,2,2,2,0
2,2,2,2,0,0,2,2,2,2,2,2,2,2,2,2,2,2,26,14,27,0,0,0,0,0,0,0,0,0,0,0,0,0,0,0,0,0,2,2,2,2,2,2,2,2,2,2,2,2,2,2,2,0
2,2,2,2,0,0,2,2,2,2,2,2,0,11,2,2,2,2,2,2,0,0,0,0,0,0,0,0,0,0,0,0,0,0,0,0,0,0,2,2,2,2,2,2,2,2,2,2,2,2,2,2,2,0
2,2,2,2,0,0,2,2,2,2,2,2,0,18,2,2,2,2,2,20,0,0,0,0,0,0,0,0,0,0,0,0,0,0,0,0,0,0,2,2,2,2,2,2,2,2,2,2,2,2,2,2,2,0
2,2,2,2,0,0,2,2,2,2,2,2,0,16,2,2,2,2,2,20,0,0,0,0,0,0,0,0,0,0,0,0,0,0,0,0,0,0,2,2,2,2,2,2,2,0,2,2,2,2,2,2,2,0
2,2,2,2,0,0,2,0,7,7,2,0,0,17,0,0,7,5,5,2,0,2,2,0,0,0,0,0,0,0,0,0,0,0,23,0,0,0,2,2,2,2,2,2,0,2,2,2,2,2,2,2,2,2
2,2,2,2,0,0,0,0,0,7,2,0,0,0,0,0,7,5,5,5,0,2,2,0,0,0,0,0,0,0,0,0,0,0,23,0,0,0,2,2,2,2,2,0,0,0,2,2,2,4,2,2,2,2
2,2,2,2,0,0,0,0,7,7,2,0,0,0,0,0,7,5,5,5,5,0,0,0,0,0,0,0,0,0,0,0,0,0,23,0,0,2,2,2,2,2,0,0,0,0,2,2,2,4,10,2,2,2
2,2,2,2,0,0,0,0,7,2,2,0,0,0,0,0,7,5,2,2,2,0,0,0,0,0,0,0,0,0,0,0,0,32,42,0,0,2,2,2,2,2,0,0,0,0,2,2,4,4,2,10,2,2
2,2,2,2,0,0,0,0,2,2,2,2,0,0,2,2,2,2,2,2,2,2,0,0,0,0,0,0,0,0,0,32,24,42,0,0,2,2,2,2,0,0,0,0,0,2,2,2,2,2,2,2,2,2
2,2,2,2,2,2,0,2,2,2,2,2,2,2,2,2,2,2,2,2,2,2,2,0,0,21,21,21,21,43,24,42,0,0,0,2,2,2,2,0,0,0,3,3,2,2,2,2,2,2,2,2,2,2
2,2,2,2,2,2,2,2,2,2,2,2,2,2,2,2,2,2,2,2,2,2,2,2,2,5,2,44,0,0,0,0,0,0,2,2,2,2,2,0,2,2,2,2,2,2,2,2,2,2,2,2,2,2
2,2,2,2,2,2,2,2,2,2,2,2,2,2,2,7,7,2,2,2,2,2,2,5,5,5,5,44,0,0,0,0,2,2,2,0,0,0,2,0,0,0,0,0,2,2,2,2,2,2,2,2,2,2
2,2,2,2,2,2,2,2,2,2,2,2,2,2,7,7,7,2,2,2,2,2,5,5,5,2,5,2,2,2,2,2,2,2,0,0,0,0,0,0,0,0,0,0,2,2,2,2,2,2,2,2,2,2
2,2,2,2,2,2,2,2,2,2,2,2,2,2,7,7,7,2,2,2,2,2,2,5,2,2,2,2,2,2,2,2,2,0,0,0,0,0,0,0,0,0,0,0,2,2,2,2,2,2,2,2,2,2
2,2,2,2,2,2,2,2,2,0,0,0,2,2,7,7,2,2,2,2,2,2,2,2,2,2,2,2,2,2,2,2,0,0,0,0,0,2,2,2,2,2,0,0,0,2,2,2,2,2,2,2,2,2
2,2,2,2,2,2,2,2,2,0,0,0,2,2,7,2,2,2,2,2,2,2,2,2,2,2,2,2,2,2,2,2,0,0,0,0,2,2,2,2,2,2,0,0,0,2,2,2,2,2,2,2,2,2
2,2,2,2,2,2,2,2,2,0,0,0,2,7,0,0,0,2,2,2,2,2,2,2,2,2,2,2,0,2,2,2,0,0,0,0,2,2,2,2,2,2,0,0,0,0,2,2,2,2,2,2,2,2
2,2,2,2,2,2,2,2,0,0,0,0,2,0,0,0,0,0,0,0,0,0,2,0,0,2,2,2,5,2,2,2,0,0,0,0,2,2,2,2,2,2,0,0,0,2,2,2,2,2,2,2,2,2
2,2,2,2,2,2,2,0,0,0,0,0,0,0,0,0,2,0,0,0,0,5,5,0,0,0,0,0,2,2,0,0,0,0,0,0,0,2,0,2,0,0,0,0,0,2,2,2,2,2,2,2,2,2
2,2,2,2,2,2,2,0,0,0,0,0,0,0,0,2,2,0,0,0,0,5,5,5,0,0,0,0,0,0,0,0,0,0,0,0,0,0,0,0,0,0,0,0,2,2,2,2,2,2,2,2,2,2
2,2,2,2,2,2,0,0,0,0,0,0,0,0,0,2,2,0,0,0,0,5,5,5,0,0,0,0,0,0,0,0,0,0,0,0,0,0,0,0,0,0,0,0,2,2,2,2,2,2,2,2,2,2
2,2,2,2,2,2,0,0,0,0,0,2,0,0,0,2,0,0,0,0,0,0,0,0,0,0,0,0,2,0,0,0,0,0,0,0,0,0,0,0,0,0,2,2,2,2,2,2,2,2,2,2,2,2
2,2,2,2,2,2,0,0,0,0,0,2,0,0,2,2,0,0,0,45,0,0,0,0,0,0,0,0,2,7,0,0,7,7,0,0,0,0,0,0,2,2,2,2,2,2,2,2,2,2,2,2,2,2
2,2,2,2,2,2,0,0,0,0,0,2,0,0,0,2,0,0,0,0,0,0,0,0,0,0,20,20,2,2,20,2,2,0,0,0,0,7,0,0,2,2,2,2,2,2,2,2,2,2,2,2,2,2
2,2,2,2,2,2,0,0,0,0,0,2,0,0,0,2,2,2,2,2,2,2,2,2,0,0,0,0,2,2,2,7,7,7,2,2,2,2,2,0,0,40,0,0,0,0,0,0,0,0,40,0,0,0
2,2,2,2,2,2,0,0,0,0,0,2,0,0,0,2,2,2,2,2,2,2,2,2,2,0,0,0,2,2,2,41,41,41,2,2,2,2,2,2,2,2,0,2,2,2,2,2,0,2,2,2,2,2
2,2,2,2,2,2,2,0,0,0,0,2,2,40,9,2,2,2,2,2,2,2,2,2,2,0,0,0,2,2,2,41,41,41,41,41,2,2,2,2,2,2,0,2,2,2,2,2,0,2,2,2,2,2
2,2,2,2,2,2,2,0,0,0,0,2,2,2,2,2,2,2,2,2,2,2,2,3,3,2,0,18,6,2,2,2,41,41,0,0,41,2,2,2,2,2,0,2,2,2,2,2,0,2,2,2,2,2
2,2,2,2,2,2,2,2,2,2,2,2,2,2,2,2,2,2,2,2,2,2,2,2,2,2,2,2,2,2,2,2,2,2,2,2,2,2,2,2,2,2,2,2,2,2,2,2,2,2,2,2,2,2
2,2,2,2,2,2,2,2,2,2,2,2,2,2,2,2,2,2,2,2,2,2,2,2,2,2,2,2,2,2,2,2,2,2,2,2,2,2,2,2,2,2,2,2,2,2,2,2,2,2,2,2,2,2
2,2,2,2,2,2,2,2,2,2,2,2,2,2,2,2,2,2,2,2,2,2,2,2,2,2,2,2,2,2,2,2,2,2,2,2,2,2,2,2,2,2,2,2,2,2,2,2,2,2,2,2,2,2
:endlayer
layer: 12
2,2,2,2,2,2,2,2,2,2,2,2,2,2,2,2,2,2,2,2,2,2,2,2,2,2,2,7,7,7,7,7,2,2,2,2,2,2,3,3,2,2,2,2,2,2,2,2,2,2,2,2,2,2
2,2,2,2,2,2,2,2,2,2,2,2,2,2,2,2,2,2,2,2,2,2,2,2,2,2,2,2,2,7,7,7,2,2,2,2,2,2,2,3,2,2,2,2,2,2,2,2,2,2,2,2,2,2
2,2,2,2,2,2,2,2,2,2,2,2,2,2,2,2,2,2,2,2,2,2,2,2,2,2,2,2,2,2,2,2,2,2,2,2,2,2,2,2,2,2,2,2,2,2,2,2,2,2,2,2,2,2
2,2,2,2,2,2,2,2,2,3,3,2,2,2,2,2,2,2,2,2,2,2,2,2,2,2,2,2,2,2,2,2,2,2,2,2,2,2,2,2,2,2,2,2,2,2,2,2,2,2,2,2,2,2
2,2,2,2,2,2,2,2,2,3,3,2,2,2,2,2,2,2,2,7,2,2,2,2,2,2,2,2,2,2,2,2,2,2,2,2,3,2,2,2,2,2,2,2,2,2,2,2,2,2,2,2,2,2
2,2,2,2,2,2,2,2,2,2,0,0,0,0,0,0,2,2,7,7,7,0,0,0,2,2,2,2,2,2,2,2,2,2,2,2,2,2,8,8,2,2,2,2,2,2,2,2,2,2,2,2,2,2
2,2,2,2,2,2,2,2,2,2,2,0,0,0,0,0,0,2,0,0,0,0,0,0,0,2,2,2,2,2,2,2,2,2,2,2,2,2,8,8,2,2,2,2,2,2,2,2,2,2,2,2,2,0
2,2,2,2,2,2,2,2,0,0,0,0,0,0,0,0,0,0,0,0,0,0,0,0,0,0,0,2,0,0,2,2,2,2,2,2,2,2,2,2,2,2,2,2,0,2,2,2,2,2,2,2,0,0
2,2,2,2,0,0,0,0,0,0,0,0,2,0,0,0,0,0,0,0,0,0,0,0,0,0,0,0,0,0,0,2,2,2,2,2,2,2,2,2,2,2,2,2,0,2,2,2,2,2,2,2,0,0
2,2,2,2,0,0,0,0,0,0,0,0,2,0,0,0,0,0,0,0,0,0,0,0,0,0,0,0,0,0,0,0,0,2,2,2,2,2,2,2,2,2,2,2,0,0,2,2,8,8,2,2,0,0
2,2,2,2,0,0,0,0,0,0,0,0,2,2,0,0,0,0,0,0,0,0,2,2,0,0,0,0,0,0,0,0,0,0,0,2,2,2,2,2,2,2,2,2,0,0,2,2,8,4,2,0,0,0
2,2,2,2,0,0,0,0,0,0,0,0,2,2,2,0,0,0,0,0,2,2,2,2,0,0,0,0,0,0,0,0,0,0,0,0,2,2,2,2,2,7,7,7,0,0,0,4,4,4,0,0,0,0
2,2,2,2,0,0,0,0,0,0,0,0,2,2,2,0,0,0,0,0,2,2,2,2,2,2,0,0,2,0,0,0,0,0,0,0,2,2,2,2,2,7,7,7,0,0,0,4,7,0,0,0,0,0
2,2,2,2,0,0,0,0,0,0,0,0,2,2,2,2,0,0,0,0,0,2,8,2,2,2,2,2,2,5,5,0,0,0,0,2,2,2,2,2,2,2,7,7,0,0,0,0,7,0,0,0,0,0
2,2,2,2,0,0,0,0,0,0,0,2,2,2,2,2,0,0,0,0,0,2,2,2,2,2,2,2,2,2,2,0,0,2,2,2,2,2,2,2,2,2,2,7,0,0,0,0,0,0,0,0,0,7
2,2,2,2,2,2,2,2,2,2,2,2,2,2,2,2,0,0,0,0,0,0,2,2,2,2,2,2,2,2,2,2,2,2,2,2,2,2,2,2,2,2,2,2,0,0,0,0,0,7,7,7,7,7
2,2,2,2,2,2,2,2,2,2,2,2,2,2,2,2,2,2,0,0,0,0,0,2,2,2,2,2,2,2,2,2,2,2,2,2,2,2,2,2,2,3,2,2,0,0,0,0,0,0,7,7,7,7
2,2,2,2,2,2,2,2,2,2,2,2,2,2,2,2,2,2,0,0,0,0,0,2,2,2,0,0,0,0,0,0,2,2,2,2,2,2,2,2,2,2,3,2,0,0,0,0,0,0,0,0,7,7
2,2,2,2,2,2,2,2,2,2,3,2,2,2,2,2,2,2,2,0,0,0,0,2,0,0,0,0,0,0,0,0,2,2,2,2,2,2,2,2,2,2,2,2,2,5,0,0,0,0,0,0,0,7
2,2,2,2,2,2,2,2,2,2,2,2,2,2,2,2,2,2,2,0,0,0,5,0,0,0,0,0,0,0,0,0,0,0,0,2,2,2,2,2,2,2,2,2,2,2,2,2,0,0,0,0,0,7
2,2,2,2,2,2,2,2,2,2,2,2,2,2,2,2,2,2,2,0,0,5,0,0,0,0,0,0,0,0,0,0,0,0,0,0,2,2,2,2,2,2,2,2,2,2,2,2,2,0,0,0,2,0
2,2,2,2,2,2,2,2,2,2,2,2,2,2,2,2,2,2,2,2,2,0,0,0,0,0,0,0,0,0,0,0,0,0,0,0,0,2,2,2,2,2,2,2,2,2,2,2,2,2,2,2,2,0
2,2,2,2,2,2,2,2,2,2,2,2,2,2,2,2,2,2,2,2,2,0,0,0,0,0,0,0,0,0,0,0,0,0,0,0,0,2,2,2,2,2,2,2,2,2,2,2,2,2,2,2,2,0
2,2,2,2,2,2,2,2,2,2,2,2,0,11,2,2,2,29,14,0,0,0,0,0,0,0,0,0,0,0,0,0,0,0,0,0,0,0,2,2,2,2,2,2,2,2,2,2,2,2,2,2,2,0
2,2,2,2,0,2,2,2,2,2,2,2,0,18,0,2,2,2,2,2,0,0,0,0,0,0,0,0,0,0,0,0,0,0,0,0,0,0,2,2,2,2,2,2,2,2,2,2,2,2,2,2,2,0
2,2,2,2,0,2,2,2,2,2,2,2,0,0,0,2,2,2,2,2,0,0,0,0,0,0,0,0,0,0,0,0,0,0,0,0,0,0,2,2,2,2,2,2,2,2,2,2,2,2,2,2,2,2
2,2,2,2,0,2,2,2,2,2,2,2,0,0,0,2,2,2,2,2,0,0,0,0,0,0,0,0,0,0,0,0,0,0,0,0,0,0,2,2,2,2,2,2,2,2,2,2,2,2,2,2,2,2
2,2,2,2,0,2,2,2,2,2,2,0,0,0,0,0,7,7,7,7,0,2,2,0,0,0,0,0,0,0,0,0,0,0,0,0,0,0,2,2,2,2,2,2,2,2,2,2,2,2,2,2,2,7
2,2,2,2,2,2,2,2,2,2,2,0,0,0,0,0,7,5,5,5,0,2,2,0,0,0,0,0,0,0,0,0,0,0,0,0,0,0,2,2,2,2,2,2,2,13,2,2,4,4,2,2,7,7
2,2,2,2,0,2,0,7,2,2,2,0,0,0,0,0,7,5,5,5,5,0,0,0,0,0,0,0,0,0,0,0,0,0,0,0,0,2,2,2,2,2,2,2,2,13,2,2,4,4,10,7,7,7
2,2,2,2,2,0,0,7,7,2,2,2,0,0,0,0,7,5,5,5,5,0,0,0,0,0,0,0,0,0,0,0,0,0,0,0,0,2,2,2,2,2,2,2,2,2,2,4,4,4,2,7,7,7
2,2,2,2,2,0,0,7,7,2,2,2,0,2,2,2,7,2,2,2,2,2,0,0,0,0,0,0,0,0,0,0,0,0,0,0,2,2,2,2,2,2,2,2,2,2,2,2,4,4,2,2,2,2
2,2,2,2,2,0,0,7,7,2,2,2,2,2,2,7,7,2,2,2,2,2,2,0,0,21,21,43,24,0,0,0,0,0,0,2,2,2,2,2,2,2,2,3,2,2,2,2,4,2,2,2,2,2
2,2,2,2,2,0,0,7,2,2,2,2,2,2,7,7,7,2,2,2,2,2,2,5,5,5,44,0,0,0,0,0,0,0,2,2,2,2,2,2,2,2,2,2,2,2,2,2,3,3,2,2,2,2
2,2,2,2,2,0,0,7,2,2,2,2,2,2,7,7,7,2,2,2,2,2,5,5,5,5,44,0,0,0,0,0,2,2,2,2,2,2,2,2,2,2,2,2,2,2,2,2,3,3,2,2,2,2
2,2,2,2,2,2,2,2,2,2,2,2,2,2,7,7,2,2,2,2,2,5,5,5,5,5,44,2,2,2,2,2,2,2,2,2,2,2,2,2,2,2,2,2,2,3,3,2,2,2,2,2,2,2
2,2,2,2,2,2,2,2,2,2,2,2,2,2,2,2,2,2,2,2,2,5,5,5,5,2,2,2,2,2,2,2,2,2,2,2,0,0,2,2,2,2,2,2,2,2,3,2,2,2,2,2,2,2
2,2,2,2,2,2,2,2,2,0,0,0,2,2,2,2,2,0,2,2,2,5,5,5,2,2,2,2,2,2,2,2,2,2,2,2,2,2,2,2,2,2,2,2,2,2,2,2,2,2,2,2,2,2
2,2,2,2,2,2,2,2,2,2,0,0,2,2,0,0,0,0,0,2,2,2,2,2,2,2,2,2,0,2,2,2,2,2,2,2,2,2,2,2,2,2,2,2,2,2,2,2,2,2,2,2,2,2
2,2,2,2,2,2,2,2,2,2,0,0,2,0,0,0,0,0,0,2,2,2,2,2,2,2,2,2,0,0,4,2,2,2,2,2,2,2,2,2,2,2,2,2,2,2,2,2,2,2,2,2,2,2
2,2,2,2,2,2,2,2,2,0,0,0,2,0,0,0,0,0,0,0,0,0,2,2,2,2,2,2,5,0,0,2,2,2,2,2,2,2,2,2,2,2,2,2,2,2,2,2,2,2,2,2,2,2
2,2,2,2,2,2,2,2,0,0,0,0,0,0,0,0,0,0,0,0,0,0,5,0,0,0,2,2,0,0,0,0,0,0,0,0,2,2,2,2,2,2,2,2,2,2,2,2,2,2,2,2,2,2
2,2,2,2,2,2,2,0,0,0,2,0,0,0,0,2,2,0,0,0,0,0,5,0,0,0,0,2,0,0,0,0,0,0,0,0,0,2,2,2,2,2,2,2,2,2,2,2,2,2,2,2,2,2
2,2,2,2,2,2,2,0,0,2,2,0,0,0,0,45,0,0,0,0,0,0,0,0,0,0,2,2,0,0,0,0,0,0,0,0,0,0,2,2,2,2,2,2,2,2,2,2,2,2,2,2,2,2
2,2,2,2,2,2,2,2,2,2,2,2,0,0,0,0,0,0,0,0,0,0,0,0,0,0,2,2,0,0,0,0,0,0,0,0,0,2,2,2,2,2,2,2,2,2,2,2,2,2,2,2,2,2
2,2,2,2,2,2,2,0,2,2,2,2,2,0,0,0,0,0,0,0,0,0,0,0,0,0,0,0,0,7,0,0,0,0,2,2,0,0,0,0,2,2,2,2,2,2,2,2,2,2,2,2,2,2
2,2,2,2,2,0,0,2,0,2,2,2,2,0,0,0,0,0,0,0,0,0,0,0,0,0,0,20,2,20,20,20,20,2,2,2,2,0,0,0,2,2,2,2,2,2,2,2,2,2,2,2,2,2
2,2,2,2,2,0,0,0,2,2,2,2,2,40,2,2,2,2,2,2,2,2,2,2,0,0,0,0,2,41,41,41,41,41,2,2,2,2,2,2,2,2,2,2,2,2,2,2,2,2,2,2,2,2
2,2,2,2,2,2,0,4,2,2,2,2,2,2,2,2,2,2,2,2,2,2,2,2,2,0,0,0,2,2,41,0,0,0,41,2,2,2,2,2,2,2,2,2,2,2,2,2,2,2,2,2,2,2
2,2,2,2,2,2,2,2,2,2,2,2,2,2,9,2,2,2,2,2,2,2,2,2,2,2,0,0,2,2,2,0,0,0,0,0,2,2,2,2,2,2,2,2,2,2,2,2,2,2,2,2,2,2
2,2,2,2,2,2,2,2,2,2,2,2,2,2,2,2,2,2,2,2,2,2,2,2,2,2,0,0,2,2,2,2,0,0,0,0,0,2,2,2,2,2,2,2,2,2,2,2,2,2,2,2,2,2
2,2,2,2,2,2,2,2,2,2,2,2,2,2,2,2,2,2,2,2,2,2,2,2,2,2,2,2,2,2,2,2,2,2,2,2,2,2,2,2,2,2,2,2,2,2,2,2,2,2,2,2,2,2
2,2,2,2,2,2,2,2,2,2,2,2,2,2,2,2,2,2,2,2,2,2,2,2,2,2,2,2,2,2,2,2,2,2,2,2,2,2,2,2,2,2,2,2,2,2,2,2,2,2,2,2,2,2
2,2,2,2,2,2,2,2,2,2,2,2,2,2,2,2,2,2,2,2,2,2,2,2,2,2,2,2,2,2,2,2,2,2,2,2,2,2,2,2,2,2,2,2,2,2,2,2,2,2,2,2,2,2
:endlayer
layer: 13
2,2,2,2,2,2,2,2,2,2,2,2,2,2,2,2,2,2,2,2,2,2,2,2,2,2,2,2,2,7,7,2,2,2,2,2,2,2,3,3,2,2,2,2,2,2,2,2,2,2,2,2,2,2
2,2,2,2,2,2,2,2,2,2,2,2,2,2,2,2,2,2,2,2,2,2,2,2,2,2,2,2,2,2,2,2,2,2,2,2,2,2,3,3,2,2,2,2,2,2,2,2,2,2,2,2,2,2
2,2,2,2,2,2,2,2,2,2,2,2,2,2,2,2,2,2,2,2,2,2,2,2,2,2,2,2,2,2,2,2,2,2,2,2,2,2,2,2,2,2,2,2,2,2,2,2,2,2,2,2,2,2
2,2,2,2,2,2,2,2,2,2,2,2,2,2,2,2,2,2,2,2,2,2,2,2,2,2,2,0,2,2,2,2,2,2,2,2,2,2,2,2,2,2,2,2,2,2,2,2,2,2,2,2,2,2
2,2,2,2,2,2,2,2,2,2,3,2,2,2,2,2,2,2,2,2,2,2,2,2,2,0,0,0,2,2,2,2,2,2,2,3,3,2,2,2,2,2,2,2,2,2,2,2,2,2,2,2,2,2
2,2,2,2,2,2,2,2,2,2,0,0,0,0,0,0,2,2,2,2,2,0,0,0,0,2,2,2,2,2,2,2,2,2,2,3,3,2,8,8,2,2,2,2,2,2,2,2,2,2,2,2,2,2
2,2,2,2,2,2,2,2,2,2,2,0,0,0,0,0,2,2,0,0,0,0,0,0,0,2,2,2,0,2,2,2,2,2,2,2,2,2,8,8,2,2,2,2,2,2,2,2,2,2,2,2,2,2
2,2,2,2,2,2,2,2,0,0,0,0,0,0,0,0,0,0,0,0,0,0,0,0,0,0,0,2,0,0,0,2,2,2,2,2,2,2,2,2,2,2,2,2,0,2,2,2,2,2,2,2,2,2
2,2,2,2,0,0,0,0,0,0,0,0,2,0,0,0,0,0,0,0,0,0,0,0,0,0,0,0,0,0,0,0,2,2,2,2,2,2,2,2,2,2,2,2,0,2,2,2,2,2,2,2,2,2
2,2,2,2,0,0,0,0,0,0,0,0,2,0,0,0,0,0,0,0,0,0,0,0,0,0,0,0,0,0,0,0,0,0,0,2,0,2,2,2,2,2,2,2,0,0,2,2,2,2,2,2,2,2
2,2,2,2,0,0,0,0,0,0,0,0,2,2,0,0,0,0,0,0,0,2,2,0,0,0,0,0,0,0,0,0,0,0,0,0,0,0,0,2,7,7,7,7,0,0,2,2,2,4,2,0,0,0
2,2,2,2,0,0,0,0,0,0,0,0,2,2,2,0,0,0,0,0,2,2,2,2,0,0,0,0,0,0,0,0,0,0,0,0,0,0,0,0,7,7,7,7,0,0,0,4,4,4,0,0,0,0
2,2,2,2,0,0,0,0,0,0,0,0,2,2,2,2,0,0,0,0,2,2,2,2,2,0,0,0,0,0,0,0,0,0,0,0,0,0,0,0,2,7,7,7,0,0,0,4,0,0,0,0,0,0
2,2,2,2,0,0,0,0,0,0,0,0,2,2,2,2,2,0,0,0,2,2,8,8,2,2,2,2,2,2,5,0,0,0,0,0,0,0,0,2,2,7,7,7,0,0,0,0,0,0,0,0,0,0
2,2,2,2,0,0,0,0,0,0,0,0,2,2,3,2,2,0,0,0,0,2,8,8,2,2,2,2,2,2,2,2,2,0,2,2,2,2,0,0,0,5,7,7,0,0,0,0,0,0,0,0,0,0
2,2,2,2,2,2,2,2,2,2,2,2,2,2,2,2,2,2,0,0,0,2,2,2,2,2,2,2,2,2,2,2,2,2,2,2,2,2,0,5,5,5,5,7,0,0,0,0,0,0,0,0,7,7
2,2,2,2,2,2,2,2,2,2,2,2,2,2,2,2,2,2,0,0,0,0,2,2,2,2,2,2,2,2,2,2,2,2,2,2,2,2,2,5,5,5,5,5,0,0,0,0,0,7,7,7,7,7
2,2,2,2,2,2,2,2,2,2,2,2,2,2,2,2,2,2,2,0,0,0,0,2,2,2,0,0,0,0,0,0,2,2,2,2,2,2,2,2,5,5,5,5,0,0,0,0,0,2,7,7,7,7
2,2,2,2,2,2,2,2,2,2,2,2,2,2,2,2,2,2,2,2,0,0,0,2,0,0,0,0,0,0,0,0,2,2,2,2,2,2,2,2,2,5,5,5,5,5,0,0,0,0,7,7,7,7
2,2,2,2,2,2,2,2,2,2,2,2,2,2,2,2,2,2,2,2,0,0,5,0,0,0,0,0,0,0,0,0,0,0,0,2,2,2,2,2,2,2,0,0,5,5,2,2,2,2,2,7,7,7
2,2,2,2,2,2,2,2,2,2,2,2,2,2,2,2,2,2,2,2,0,5,0,0,0,0,0,0,0,0,0,0,0,0,0,0,2,2,2,3,2,2,2,2,0,0,0,8,8,2,2,2,2,0
2,2,2,2,2,2,2,2,2,2,2,2,2,2,2,2,2,2,2,2,2,0,0,0,0,0,0,0,0,0,0,0,0,0,0,0,0,2,3,2,2,2,2,2,2,0,0,0,8,2,2,2,2,0
2,2,2,2,2,2,2,2,2,2,2,2,2,2,2,2,2,2,2,2,2,0,0,0,0,0,0,0,0,0,0,0,0,0,0,0,0,2,2,2,2,2,2,2,2,2,0,2,2,2,2,2,2,0
2,2,2,2,2,2,2,2,2,2,2,2,0,11,0,2,2,29,2,2,0,0,0,0,0,0,0,0,0,0,0,0,0,0,0,0,0,0,2,2,2,2,2,2,2,2,2,2,2,2,2,2,2,0
2,2,2,2,2,2,2,2,2,2,2,2,0,0,0,0,2,2,2,2,0,0,0,0,0,0,0,0,0,0,0,0,0,0,0,0,0,0,2,2,2,2,2,2,2,2,2,2,2,2,2,2,2,2
2,2,2,2,2,2,2,2,2,2,2,2,0,0,0,0,7,2,2,2,0,0,0,0,0,0,0,0,0,0,0,0,0,0,0,0,0,0,2,2,2,2,2,2,2,2,2,2,2,2,2,2,2,2
2,2,2,2,2,2,2,2,2,2,2,2,0,0,0,0,7,46,46,21,0,0,0,0,0,0,0,0,0,0,0,0,0,0,0,0,0,0,2,2,2,2,2,2,2,2,2,2,2,2,2,2,2,2
2,2,2,2,2,2,2,7,7,2,2,0,0,0,0,0,7,0,0,22,0,2,2,0,0,0,0,0,0,0,0,0,0,0,0,0,0,0,2,2,2,2,2,2,2,2,2,2,2,2,2,2,7,7
2,2,2,2,2,2,2,7,7,2,2,0,0,0,0,0,7,0,0,23,0,2,2,0,0,0,0,0,0,0,0,0,0,0,0,0,0,0,2,2,2,2,2,2,2,2,2,2,2,2,2,7,7,7
2,2,2,2,2,2,0,7,7,2,2,0,0,0,0,0,0,7,0,34,33,0,0,0,0,0,0,0,0,0,0,0,0,0,0,0,0,2,2,2,2,2,2,2,13,2,2,2,4,2,7,7,7,7
2,2,2,2,2,0,0,7,7,7,2,2,0,0,2,7,7,7,0,0,23,0,0,0,0,0,0,0,0,0,0,0,0,0,0,0,0,2,2,2,2,2,2,2,2,2,2,2,4,4,7,7,7,7
2,2,2,2,2,0,0,7,7,7,2,2,2,2,7,7,7,7,0,0,34,33,0,0,0,0,0,0,0,0,0,0,0,0,0,0,2,2,2,2,2,2,2,2,2,2,2,2,4,7,7,7,7,7
2,2,2,2,0,0,0,7,7,2,2,2,2,2,7,7,7,7,7,0,0,34,33,0,0,32,24,0,0,0,0,0,0,0,0,2,2,2,2,2,2,2,2,2,2,2,2,2,4,2,7,2,2,2
2,2,2,2,0,0,0,7,7,2,2,2,2,2,7,7,7,7,7,7,0,0,34,24,24,42,0,0,0,0,0,0,0,0,2,2,2,2,2,2,2,2,2,2,2,2,2,2,3,3,2,2,2,2
2,2,2,2,2,0,0,7,2,2,2,2,2,7,7,7,7,7,2,2,2,0,0,0,0,0,0,0,0,0,0,0,2,2,2,2,0,0,2,2,2,2,2,2,2,2,2,2,3,3,2,2,2,2
2,2,2,2,2,7,7,2,2,2,2,2,2,7,7,7,7,2,2,2,2,5,0,0,0,0,0,0,2,2,2,2,2,2,2,2,0,0,0,2,2,2,2,2,2,3,3,2,2,2,2,2,2,2
2,2,2,2,2,7,7,2,2,2,2,2,2,7,7,7,7,2,2,2,5,5,5,0,0,0,0,2,2,2,2,2,2,2,2,2,0,0,0,2,2,2,2,2,2,2,3,2,2,2,2,2,2,2
2,2,2,2,2,2,2,2,2,2,0,0,2,2,7,2,0,0,47,2,5,5,5,5,5,2,2,2,2,2,2,2,2,2,2,2,2,2,2,2,2,2,2,2,2,2,2,2,2,2,2,2,2,2
2,2,2,2,2,2,2,2,2,2,2,0,2,2,2,0,0,0,0,0,5,5,2,2,2,2,2,2,0,2,2,2,2,2,2,2,2,2,2,2,2,2,2,2,2,2,2,2,2,2,2,2,2,2
2,2,2,2,2,2,2,2,2,2,2,2,2,2,0,0,0,0,0,0,0,0,2,2,2,2,2,2,0,0,4,4,2,2,2,2,2,2,2,2,2,2,2,2,2,2,2,2,2,2,2,2,2,2
2,2,2,2,2,2,2,2,2,2,2,2,2,0,0,0,0,0,0,0,0,0,2,2,2,2,2,2,0,0,0,4,2,2,2,2,2,2,2,2,2,2,2,2,2,2,2,2,2,2,2,2,2,2
2,2,2,2,2,2,2,2,2,2,2,2,2,0,0,0,0,0,0,0,0,0,0,2,2,2,2,2,0,0,0,0,0,2,2,2,2,2,2,2,2,2,2,2,2,2,2,2,2,2,2,2,2,2
2,2,2,2,2,2,2,2,2,2,2,2,2,0,2,2,0,0,0,0,0,0,0,0,2,2,2,2,0,0,0,0,0,0,0,2,2,2,2,2,2,2,2,2,2,2,2,2,2,2,2,2,2,2
2,2,2,2,2,2,2,2,2,2,2,2,2,2,0,0,0,0,0,0,0,0,0,0,2,2,2,2,0,0,0,0,0,0,0,2,2,2,2,2,2,2,2,2,2,2,2,2,2,2,2,2,2,2
2,2,2,2,2,2,2,2,2,2,2,2,2,0,0,0,0,0,0,0,0,0,0,0,0,0,2,2,0,0,0,0,0,0,2,2,2,2,2,2,2,2,2,2,2,2,2,2,2,2,2,2,2,2
2,2,2,2,4,4,2,2,2,2,2,2,2,0,0,0,0,0,0,0,0,0,0,0,0,0,0,0,0,7,0,0,0,2,2,2,0,0,2,2,2,2,2,2,2,2,2,2,2,2,2,2,2,2
2,2,2,2,2,0,0,2,2,2,2,2,0,2,0,0,0,0,0,0,0,0,0,0,0,0,0,0,2,20,20,20,20,20,2,2,0,0,0,2,2,2,2,2,2,2,2,2,2,2,2,2,2,2
2,2,2,2,2,0,0,2,2,2,2,2,2,2,2,2,2,2,2,2,2,2,2,2,0,0,0,0,2,0,0,47,0,0,2,2,2,2,2,2,2,2,2,2,2,2,2,2,2,2,2,2,2,2
2,2,2,2,2,2,2,2,2,2,2,2,7,7,2,2,2,2,2,2,2,2,2,2,2,2,0,0,2,2,0,0,0,0,0,2,2,2,2,2,2,2,2,2,2,2,2,2,2,2,2,2,2,2
2,2,2,2,2,2,2,2,2,2,2,2,7,7,2,2,2,2,2,2,2,2,2,2,2,2,2,0,2,2,2,0,0,0,0,0,2,2,2,2,2,2,2,2,2,2,2,2,2,2,2,2,2,2
2,2,2,2,2,2,2,2,2,2,2,2,2,7,7,2,2,2,2,2,2,2,2,2,2,2,2,2,2,2,2,2,0,0,0,0,2,2,2,2,2,2,2,2,2,2,2,2,2,2,2,2,2,2
2,2,2,2,2,2,2,2,2,2,2,2,2,2,2,2,2,2,2,2,2,2,2,2,2,2,2,2,2,2,2,2,2,2,2,2,2,2,2,2,2,2,2,2,2,2,2,2,2,2,2,2,2,2
2,2,2,2,2,2,2,2,2,2,2,2,2,2,2,2,2,2,2,2,2,2,2,2,2,2,2,2,2,2,2,2,2,2,2,2,2,2,2,2,2,2,2,2,2,2,2,2,2,2,2,2,2,2
2,2,2,2,2,2,2,2,2,2,2,2,2,2,2,2,2,2,2,2,2,2,2,2,2,2,2,2,2,2,2,2,2,2,2,2,2,2,2,2,2,2,2,2,2,2,2,2,2,2,2,2,2,2
:endlayer
layer: 14
2,2,2,2,2,2,7,7,7,7,2,2,2,2,2,2,2,2,2,2,2,2,2,2,2,2,7,7,7,5,5,2,2,2,2,2,2,2,2,2,2,5,5,5,2,2,2,2,2,2,2,2,2,2
2,2,2,2,7,7,7,7,7,7,2,2,2,2,2,2,2,2,2,2,2,2,2,2,2,2,4,4,4,4,2,2,2,2,2,2,2,2,2,2,2,5,5,5,5,2,2,2,2,2,2,2,2,2
2,2,2,2,7,7,7,7,7,2,2,2,2,2,2,2,2,2,2,2,2,2,2,2,2,2,4,0,4,2,2,2,2,2,2,2,2,2,2,2,2,5,5,5,5,3,2,2,2,2,2,2,2,2
2,2,2,2,7,7,7,7,2,2,2,2,2,2,2,2,2,2,2,2,2,2,2,2,2,2,0,0,2,2,2,2,2,2,2,2,2,2,2,2,2,2,5,5,5,2,2,2,2,2,2,2,2,2
2,2,2,2,7,2,2,2,2,2,2,2,2,2,2,2,2,2,2,2,2,2,2,2,2,0,0,0,2,2,2,2,2,2,2,2,2,2,2,2,2,2,2,5,5,5,2,2,2,2,2,2,2,2
2,2,2,2,2,2,2,2,2,2,2,0,0,0,0,2,2,2,2,2,2,2,0,0,2,2,2,2,2,2,2,2,2,2,2,3,2,2,2,2,2,2,2,2,5,2,2,2,2,2,2,2,2,2
2,2,2,2,2,2,2,2,2,2,2,2,0,0,0,0,2,2,2,0,0,0,0,0,0,2,2,2,0,2,2,2,2,2,2,2,2,2,2,2,2,2,2,2,2,2,2,2,0,0,0,0,0,0
2,2,2,2,2,2,2,2,2,0,0,0,0,0,0,0,2,2,0,0,0,0,0,0,0,0,0,2,0,0,0,2,2,2,2,2,2,2,2,2,2,2,2,2,2,2,2,0,0,0,0,0,0,0
2,2,2,2,2,0,0,0,0,0,0,0,2,2,0,0,0,0,0,0,0,0,0,0,0,0,0,0,0,0,0,0,0,2,2,2,2,2,2,2,0,0,2,2,0,2,0,0,0,0,0,0,0,0
2,2,2,2,0,0,0,0,0,0,0,0,2,2,2,0,0,0,0,0,0,0,0,0,0,0,0,0,0,0,0,0,0,0,0,0,0,0,0,0,0,0,0,2,0,2,0,0,0,0,0,0,0,0
2,2,2,2,0,0,0,0,0,0,0,0,2,2,2,2,0,0,0,0,2,2,2,0,0,0,0,0,0,0,0,0,0,0,0,0,0,0,0,0,0,0,0,7,0,0,0,0,0,2,2,2,0,0
2,2,2,2,0,0,0,0,0,0,0,0,2,2,2,2,2,0,0,2,2,2,2,2,0,0,0,0,0,0,0,0,0,0,0,0,0,0,0,0,0,0,0,7,0,0,2,4,0,2,2,0,0,2
2,2,2,2,0,0,0,0,0,0,0,0,2,2,2,2,2,0,0,0,2,2,2,2,2,0,0,0,0,0,0,0,0,0,0,0,0,0,0,0,0,0,7,7,0,0,0,0,0,0,0,0,0,0
2,2,2,2,0,0,0,0,0,0,0,0,2,2,2,2,2,2,0,0,2,2,2,2,2,2,2,2,2,2,5,0,0,0,0,0,0,0,0,0,0,7,7,7,0,0,0,0,0,0,0,0,0,0
2,2,2,2,0,0,0,0,0,0,0,0,2,2,3,2,2,2,2,0,2,2,2,8,2,2,2,2,2,2,2,2,2,0,0,0,0,0,0,0,0,0,7,7,0,0,0,0,0,0,0,0,0,2
2,2,2,2,2,2,2,2,2,2,2,2,2,2,2,2,2,2,2,0,0,2,2,2,2,2,2,2,2,2,2,2,2,2,2,2,2,0,0,0,0,5,5,7,0,0,0,0,0,0,0,0,7,2
2,2,2,2,2,2,2,2,2,2,2,2,2,2,2,2,2,2,2,0,0,2,2,2,2,2,2,2,2,2,2,2,2,2,2,2,2,2,0,5,5,5,5,5,7,7,0,0,2,7,7,7,7,2
2,2,2,2,2,2,2,2,2,2,2,2,2,2,2,2,2,2,2,2,0,8,8,2,2,2,0,0,0,0,0,0,2,2,2,2,2,2,2,5,5,5,5,5,0,7,7,7,2,2,7,7,7,2
2,2,2,2,2,2,2,2,2,2,2,2,2,2,2,2,2,2,2,2,0,8,8,2,0,0,0,0,0,0,0,0,2,2,2,2,2,2,2,2,2,5,5,5,5,0,2,2,2,2,2,7,7,2
2,2,2,2,2,2,2,2,2,2,2,2,2,2,2,4,4,2,2,2,0,2,2,0,0,0,0,0,0,0,0,0,0,0,0,2,2,2,2,2,2,2,0,0,5,5,2,2,2,2,2,2,2,2
2,2,2,2,2,2,2,2,2,2,2,2,2,2,2,4,4,2,2,2,2,2,0,0,0,0,0,0,0,0,0,0,0,0,0,0,2,2,2,3,2,2,2,0,0,0,0,8,8,2,2,2,2,0
2,2,2,2,2,2,2,8,8,2,2,2,2,2,2,4,4,2,2,2,2,0,0,0,0,0,0,0,0,0,0,0,0,0,0,0,0,2,5,5,2,2,2,2,2,0,0,0,8,2,2,2,2,0
2,2,2,2,2,2,2,8,8,2,2,2,2,2,2,2,2,2,2,2,2,0,0,0,0,0,0,0,0,0,0,0,0,0,0,0,0,2,5,5,5,0,0,2,2,2,0,2,2,2,2,2,2,0
2,2,2,2,2,2,2,2,2,2,2,2,0,11,0,2,2,29,2,2,0,0,0,0,0,0,0,0,0,0,0,0,0,0,0,0,0,0,5,5,0,0,0,0,2,2,2,2,2,2,2,2,2,0
2,2,2,2,2,2,2,2,2,2,2,2,0,0,0,0,2,5,5,2,0,0,0,0,0,0,0,0,0,0,0,0,0,0,0,0,0,0,2,0,0,45,0,0,2,2,2,2,2,2,2,2,2,2
2,2,2,2,2,2,2,2,2,2,2,2,0,0,0,0,7,46,46,21,0,0,0,0,0,0,0,0,0,0,0,0,0,0,0,0,0,0,2,2,0,0,0,2,2,2,2,2,2,2,2,2,2,2
2,2,2,2,2,2,2,2,2,2,2,2,0,0,0,0,7,0,0,22,0,0,0,0,0,0,0,0,0,0,0,0,0,0,0,0,0,0,2,2,2,2,2,2,2,2,2,2,2,2,2,2,2,2
2,2,2,2,2,2,2,7,7,2,2,2,0,0,0,0,7,0,0,0,0,2,2,0,0,0,0,0,0,0,0,0,0,0,0,0,0,0,2,2,2,2,2,2,2,2,2,2,2,2,2,2,7,7
2,2,2,2,2,2,2,7,7,2,2,0,0,0,0,0,7,0,0,0,0,2,2,0,0,0,0,0,0,0,0,0,0,0,0,0,0,0,2,2,2,2,2,2,2,2,2,2,2,2,2,7,7,7
2,2,2,2,2,2,7,7,7,2,2,2,0,0,0,0,7,7,0,0,0,0,0,0,0,0,0,0,0,0,0,0,0,0,0,0,0,2,2,2,2,2,2,2,2,2,2,2,2,2,7,7,7,7
2,2,2,2,2,7,7,7,7,7,2,2,2,2,2,0,7,7,0,0,0,0,0,0,0,0,0,0,0,0,0,0,0,0,0,0,0,2,2,2,2,2,2,2,2,2,2,2,2,2,7,7,7,7
2,2,2,2,2,0,0,7,7,7,2,2,2,2,7,7,7,7,0,0,0,0,0,0,0,0,0,0,0,0,0,0,0,0,0,0,2,2,2,2,2,2,2,2,2,2,2,2,2,7,7,7,7,7
2,2,2,2,0,0,0,7,7,2,2,2,2,2,7,7,7,7,7,0,0,0,0,0,0,0,0,0,0,0,0,0,0,0,0,2,0,0,0,2,2,2,2,2,2,2,2,2,2,2,7,2,2,2
2,2,2,2,0,0,0,7,7,2,2,2,2,7,7,7,7,7,7,7,0,0,0,0,0,0,0,0,0,0,0,0,0,0,2,2,0,0,0,2,2,2,2,2,2,2,2,2,2,2,2,2,2,2
2,2,2,2,2,0,0,7,2,2,2,2,2,7,7,7,7,7,7,7,2,0,0,0,0,0,0,0,0,0,0,0,2,2,2,2,0,0,0,2,2,2,2,2,2,2,2,2,2,2,2,2,2,2
2,2,2,2,2,7,7,2,2,2,2,2,2,7,7,7,7,7,2,2,2,5,0,0,0,0,0,0,2,2,2,2,2,2,2,2,0,0,0,2,2,2,2,2,2,2,2,2,2,2,2,2,2,2
2,2,2,2,2,7,7,2,2,2,2,2,2,7,7,7,7,2,2,2,5,5,5,0,0,0,0,2,2,2,2,2,2,2,2,2,0,0,0,2,2,2,2,2,2,2,2,2,2,2,2,2,2,2
2,2,2,2,2,2,2,2,2,2,2,2,2,2,7,7,3,2,2,2,5,5,5,5,7,7,0,2,2,2,2,2,2,2,2,2,2,2,2,2,2,2,2,2,2,2,2,2,2,2,2,2,2,2
2,2,2,2,2,2,2,2,2,2,2,2,2,2,2,0,0,0,0,0,5,7,7,7,7,7,7,7,2,2,2,2,2,2,2,2,2,2,2,2,2,2,2,2,2,2,2,2,2,2,2,2,2,2
2,2,2,2,2,2,2,2,2,2,2,2,2,2,2,0,0,0,0,0,0,0,7,7,7,7,7,7,0,4,4,4,4,4,2,2,2,2,2,2,2,2,2,2,2,2,2,2,2,2,2,2,2,2
2,2,2,2,2,2,2,2,2,2,2,2,2,2,2,0,0,0,0,0,0,48,2,7,7,7,2,2,0,0,4,4,4,4,2,2,2,2,2,2,2,2,2,2,2,2,2,2,2,2,2,2,2,2
2,2,2,2,2,2,2,2,2,2,2,2,2,2,2,0,0,0,0,0,0,0,0,5,5,5,2,2,0,0,0,2,2,2,2,2,2,2,2,2,2,2,2,2,2,2,2,2,2,2,2,2,2,2
2,2,2,2,2,2,8,2,2,2,2,2,2,2,2,2,2,0,0,0,0,0,0,0,5,2,2,2,0,0,0,0,2,2,2,2,2,2,2,2,2,2,2,2,2,2,2,2,2,2,2,2,2,2
2,2,2,2,2,2,2,2,2,2,2,2,2,2,2,2,2,2,2,2,0,0,0,0,0,0,2,2,0,0,0,0,0,2,2,2,2,2,2,2,2,2,2,2,2,2,2,2,2,2,2,2,2,2
2,2,2,2,2,2,2,2,2,2,2,2,2,2,0,0,0,0,0,2,2,0,0,0,0,0,2,2,2,0,0,0,2,2,2,2,2,2,2,2,2,2,2,2,2,2,2,2,2,2,2,2,2,2
2,2,2,2,4,4,2,2,2,2,2,2,0,2,0,0,0,0,0,2,8,4,0,0,0,0,0,0,2,20,20,20,2,2,2,2,0,2,2,2,2,2,2,2,2,2,2,2,2,2,2,2,2,2
2,2,2,2,2,2,2,2,2,2,2,7,0,2,0,0,0,2,2,8,8,4,0,0,0,0,0,0,0,0,0,0,0,0,0,0,0,0,2,2,2,2,2,2,2,2,2,2,2,2,2,2,2,2
2,2,2,2,2,2,2,2,2,2,2,7,7,7,2,2,2,2,2,2,2,2,4,4,0,0,0,0,2,2,20,20,20,20,2,2,2,2,2,2,2,2,2,2,2,2,2,2,2,2,2,2,2,2
2,2,2,2,2,2,2,2,2,2,2,7,7,7,7,2,2,2,2,2,2,2,2,4,4,2,0,0,2,2,2,0,0,0,2,2,2,2,2,2,2,2,2,2,2,2,2,2,2,2,2,2,2,2
2,2,2,2,2,2,2,2,2,2,2,7,7,7,7,2,2,2,2,2,2,2,2,2,2,2,2,2,2,2,2,0,0,0,2,2,2,2,2,2,2,2,2,2,2,2,2,2,2,2,2,2,2,2
2,2,2,2,2,2,2,2,2,2,2,7,7,7,7,7,2,2,2,2,2,2,2,2,2,2,2,2,2,2,2,2,2,2,0,8,2,2,2,2,2,2,2,2,2,2,2,2,2,2,2,2,2,2
2,2,2,2,2,2,2,2,2,2,2,2,2,2,2,2,2,2,2,2,2,2,2,2,2,2,2,2,2,2,2,2,2,2,2,2,2,2,2,2,2,2,2,2,2,2,2,2,2,2,2,2,2,2
2,2,2,2,2,2,2,2,2,2,2,2,2,2,2,2,2,2,2,2,2,2,2,2,2,2,2,2,2,2,2,2,2,2,2,2,2,2,2,2,2,2,2,2,2,2,2,2,2,2,2,2,2,2
2,2,2,2,2,2,2,2,2,2,2,2,2,2,2,2,2,2,2,2,2,2,2,2,2,2,2,2,2,2,2,2,2,2,2,2,2,2,2,2,2,2,2,2,2,2,2,2,2,2,2,2,2,2
:endlayer
layer: 15
2,2,2,2,2,7,7,7,7,7,7,7,2,2,2,2,2,2,2,2,2,5,5,5,5,7,7,7,7,7,5,5,2,2,2,2,2,2,2,2,5,5,5,5,0,0,0,2,2,2,2,2,2,2
2,2,2,2,7,7,7,7,7,7,7,2,2,2,2,2,2,2,2,2,2,5,5,5,5,7,7,7,7,5,5,2,2,2,2,2,2,2,2,2,5,5,5,5,0,0,2,2,2,2,2,2,2,2
2,2,2,2,0,7,7,7,7,7,2,2,2,2,2,2,2,2,2,2,2,2,5,5,5,2,4,0,5,2,2,2,2,2,2,2,2,2,2,2,2,5,5,5,0,5,2,2,2,2,2,2,2,2
2,2,2,2,0,7,7,7,7,2,2,2,2,2,2,2,2,2,2,2,2,2,5,5,5,2,0,0,2,2,2,2,2,2,2,2,2,2,2,2,2,5,5,5,0,5,2,2,2,2,2,2,2,2
2,2,2,2,0,7,7,2,2,2,2,2,2,2,2,2,2,2,2,2,2,2,2,5,2,0,0,0,2,2,2,2,2,2,2,2,2,7,2,2,2,2,5,5,5,5,2,2,2,2,2,2,2,2
2,2,2,2,2,2,2,2,2,2,2,2,2,2,2,2,2,2,2,2,2,2,2,2,2,2,2,2,2,2,2,2,2,2,2,2,7,7,2,2,2,2,2,5,5,5,2,2,2,2,0,0,2,2
2,2,2,2,2,2,2,2,2,2,2,2,2,2,2,2,2,2,2,2,2,2,0,0,2,2,2,2,2,2,2,2,2,2,2,2,7,7,2,2,2,2,2,2,0,0,2,0,0,0,0,0,0,0
2,2,2,2,2,2,2,2,2,2,2,0,2,2,2,2,2,2,2,2,2,0,0,0,2,2,2,2,0,0,2,2,2,2,2,7,7,7,7,2,2,0,0,0,0,0,0,0,0,0,0,0,0,0
2,2,2,2,2,2,2,2,0,0,0,0,2,2,2,2,2,2,2,2,2,2,0,0,0,0,0,0,0,0,0,0,2,2,2,2,7,7,2,0,0,0,0,0,0,0,0,0,0,0,0,0,0,0
2,2,2,2,0,0,0,0,0,0,0,0,2,2,2,2,2,2,2,2,2,2,2,2,0,0,0,0,0,0,0,0,0,0,0,0,0,0,0,0,0,0,0,0,0,0,0,0,0,0,0,0,0,0
2,2,2,2,0,0,0,0,0,0,0,0,2,2,2,2,2,2,2,2,2,2,2,2,0,0,0,0,0,0,0,0,0,0,0,0,0,0,0,0,0,0,0,0,0,0,0,0,0,0,2,2,0,0
2,2,2,2,0,0,0,0,0,0,0,0,2,2,2,2,2,2,2,2,2,2,2,2,2,0,0,0,0,0,0,0,0,0,0,0,0,0,0,0,0,0,0,0,0,0,0,0,0,2,2,2,2,2
2,2,2,2,0,0,0,0,0,0,0,0,2,2,2,2,2,2,2,2,2,2,2,2,2,2,0,0,0,0,0,0,0,0,0,0,0,0,0,0,0,0,0,7,0,0,0,0,0,0,0,2,2,2
2,2,2,2,0,0,0,0,0,0,0,0,2,3,2,2,2,2,2,2,2,2,2,2,2,2,2,2,5,5,5,0,7,0,0,0,0,0,0,0,0,2,7,7,0,0,0,0,0,0,0,0,2,2
2,2,2,2,2,2,2,2,2,2,2,2,2,2,2,2,2,2,2,2,2,2,2,2,2,2,0,0,49,7,7,0,7,0,0,0,0,0,0,0,0,0,2,7,0,0,0,0,0,0,0,0,2,2
2,2,2,2,2,2,2,2,2,2,2,2,2,2,2,2,2,2,2,2,2,2,2,0,0,0,0,0,49,7,7,0,2,2,2,2,0,0,0,0,0,0,5,2,7,7,0,0,0,0,0,2,2,2
2,2,2,2,2,2,2,2,2,2,2,2,2,2,2,2,2,2,2,2,2,2,0,32,24,24,24,50,21,2,2,2,2,2,2,2,2,2,0,0,0,5,5,5,2,2,2,2,2,2,2,2,2,2
2,2,2,2,2,2,2,2,2,2,2,2,2,2,2,2,2,2,2,2,2,0,0,23,0,0,0,0,0,0,0,0,2,2,2,2,2,2,2,5,0,5,5,0,2,2,2,2,2,2,2,2,2,2
2,2,2,2,2,2,2,2,2,2,2,2,2,2,2,2,2,2,2,2,0,32,24,42,0,0,0,0,0,0,0,0,2,2,2,2,2,5,2,2,2,5,0,0,5,0,2,2,2,2,2,2,2,2
2,2,2,2,2,2,2,2,2,2,2,2,2,2,2,4,4,2,2,0,0,23,0,0,0,0,0,0,0,0,0,0,0,0,0,2,2,5,5,2,2,2,2,2,0,0,2,2,2,2,2,2,2,0
2,2,2,2,2,2,2,2,2,2,2,2,2,2,2,4,4,2,0,32,24,42,0,0,0,0,0,0,0,0,0,0,0,0,0,0,2,5,5,5,2,2,2,2,2,2,2,2,2,2,2,2,2,0
2,2,2,2,2,2,2,2,2,2,2,2,2,2,2,4,4,2,0,23,0,0,0,0,0,0,0,0,0,0,0,0,0,0,0,0,0,5,5,7,7,7,7,7,2,2,2,2,2,2,2,2,2,0
2,2,2,2,2,2,2,8,2,2,2,2,2,6,2,4,4,2,0,23,0,0,0,0,0,0,0,0,0,0,0,0,0,0,0,0,0,5,7,7,7,0,0,7,7,2,2,2,2,2,2,2,2,0
2,2,2,2,2,2,2,2,2,2,2,2,0,18,2,2,2,29,0,23,0,0,0,0,0,0,0,0,0,0,0,0,0,0,0,0,0,0,7,0,0,0,0,0,2,2,2,2,2,2,2,2,2,0
2,2,2,2,2,2,2,2,2,2,2,2,0,0,0,0,7,0,0,23,0,0,0,0,0,0,0,0,0,0,0,0,0,0,0,0,0,0,7,0,0,0,0,0,2,2,2,2,2,2,2,2,2,2
2,2,2,2,2,2,2,2,2,2,2,2,0,0,0,0,7,0,0,23,0,0,0,0,0,0,0,0,0,0,0,0,0,0,0,0,0,0,2,0,0,0,0,2,2,2,2,2,2,2,2,2,2,2
2,2,2,2,2,2,2,2,2,2,2,2,0,0,0,0,7,0,0,0,0,0,0,0,0,0,0,0,0,0,0,0,0,0,0,0,0,0,2,0,0,0,2,2,2,2,2,2,2,2,2,2,2,2
2,2,2,2,2,2,2,2,2,2,2,2,0,0,0,0,7,0,0,0,0,2,2,0,0,0,0,0,0,0,0,0,0,0,0,0,0,0,2,2,2,2,2,2,2,2,2,2,2,2,2,2,2,7
2,2,2,2,2,2,2,2,2,2,2,2,0,0,0,0,7,0,0,0,0,2,2,0,0,0,0,0,0,0,0,0,0,0,0,0,0,0,2,2,2,2,2,2,2,2,2,2,2,2,2,2,7,7
2,2,2,2,2,2,7,7,2,2,2,2,0,0,0,0,0,7,0,0,0,0,0,0,0,0,0,0,0,0,0,0,0,0,0,0,0,2,2,2,2,2,2,2,2,2,2,2,2,2,2,7,7,7
2,2,2,2,2,2,7,7,7,2,2,2,2,0,0,0,0,7,0,0,0,0,0,0,0,0,0,0,0,0,0,0,0,0,0,0,0,2,2,2,2,2,2,2,2,2,2,2,2,2,2,7,7,7
2,2,2,2,2,7,7,7,7,2,2,2,2,2,7,7,7,7,0,0,0,0,0,0,0,0,0,0,0,0,0,0,0,0,0,0,2,2,2,2,2,2,2,2,2,2,2,2,2,2,2,2,2,2
2,2,2,2,2,7,7,7,7,2,2,2,2,2,7,7,7,7,7,0,0,0,0,0,0,0,0,0,0,0,0,0,0,0,0,2,0,0,0,2,2,2,2,2,2,2,2,2,2,2,2,2,2,2
2,2,2,2,2,7,7,7,2,2,2,2,2,2,7,7,7,7,7,7,0,0,0,0,0,0,0,0,0,0,0,0,0,0,2,2,0,0,0,2,2,2,2,2,2,2,2,2,2,2,2,2,2,2
2,2,2,2,2,7,7,7,2,2,2,2,2,7,7,7,7,7,7,7,2,0,0,0,0,0,0,0,0,0,0,0,2,2,2,2,0,0,0,2,2,2,2,4,4,2,2,2,2,2,2,2,2,2
2,2,2,2,2,2,2,2,2,2,2,2,7,7,7,7,7,7,2,2,2,2,0,0,0,0,0,0,2,2,2,2,2,2,2,2,0,0,2,2,2,2,2,4,4,2,2,2,2,2,2,2,2,2
2,2,2,2,2,2,2,2,2,2,2,2,7,7,0,0,2,2,2,2,2,5,5,0,0,0,0,2,2,2,2,2,2,3,3,2,2,0,2,2,2,2,2,4,4,2,0,0,0,2,2,2,2,2
2,2,2,2,2,2,2,2,2,2,2,2,2,0,0,0,0,2,2,2,2,5,7,7,7,7,7,7,7,2,2,2,2,3,3,2,2,2,2,2,2,2,2,2,2,2,0,0,0,2,2,2,2,2
2,2,2,2,2,2,2,2,2,2,2,2,2,0,0,0,0,0,2,2,2,7,7,7,7,7,7,7,7,7,2,2,2,2,2,2,2,2,2,2,2,2,2,2,2,2,0,0,0,0,2,2,2,2
2,2,2,2,2,2,2,2,2,2,2,2,2,2,0,0,0,0,0,2,0,7,7,7,7,7,7,7,7,7,13,13,4,2,2,2,2,2,2,2,2,2,2,2,2,2,0,0,0,0,2,2,2,2
2,2,2,2,2,2,2,2,2,2,2,2,2,2,2,0,0,0,0,0,0,0,7,7,7,7,7,7,0,2,13,13,4,4,2,2,2,2,2,2,2,2,2,2,2,2,0,0,0,0,2,2,2,2
2,2,2,2,2,8,8,2,2,2,2,2,2,2,2,2,0,0,2,2,0,0,0,5,5,5,5,2,2,2,2,2,2,2,2,2,2,2,2,2,2,2,2,2,2,2,2,0,0,0,0,2,2,2
2,2,2,2,2,8,8,2,2,2,2,2,2,2,2,2,2,2,2,2,2,0,0,48,5,5,5,2,2,2,2,2,2,2,2,2,2,2,2,2,2,2,2,2,2,2,2,0,0,0,0,2,2,2
2,2,2,2,2,2,2,2,2,2,2,2,2,2,2,2,2,2,2,2,2,0,0,0,2,0,0,2,2,2,2,2,2,2,2,2,2,2,2,2,2,2,2,2,2,2,2,0,0,0,0,0,0,0
2,2,2,2,2,2,2,2,2,2,2,7,2,2,2,2,2,2,2,2,2,0,0,0,0,0,7,2,2,2,2,2,2,2,2,2,2,2,2,2,2,2,2,2,2,2,2,2,0,0,0,0,0,0
2,2,2,2,2,2,2,2,2,2,2,7,7,2,2,2,2,2,2,2,8,4,0,0,0,0,0,20,0,2,2,2,2,2,2,2,2,2,2,2,2,2,2,2,2,2,2,2,2,0,0,0,0,0
2,2,2,2,2,2,2,2,2,2,2,7,7,7,2,2,2,2,2,8,8,4,4,0,0,0,0,0,0,0,0,0,0,47,0,0,0,2,2,2,2,2,2,2,2,2,2,2,2,2,2,0,2,2
2,2,2,2,2,2,2,2,2,2,2,7,7,7,7,2,2,2,2,2,2,2,4,4,4,0,0,2,2,2,2,2,2,2,2,2,2,2,2,2,2,2,2,2,2,2,2,2,2,2,2,2,2,2
2,2,2,2,2,2,2,2,2,2,2,7,7,7,7,2,2,2,2,2,2,2,2,4,4,2,2,2,2,2,2,2,2,2,2,2,2,2,2,2,2,2,2,2,2,2,2,2,2,2,2,2,2,2
2,2,2,2,2,2,2,2,2,2,2,7,7,7,7,2,2,2,2,2,2,2,2,2,2,2,2,2,2,2,2,2,2,2,2,2,2,2,2,2,2,2,2,2,2,2,2,2,2,2,2,2,2,2
2,2,2,2,2,2,2,2,2,2,2,7,7,7,7,7,2,2,2,2,2,2,2,2,2,2,2,3,3,2,2,2,2,2,2,2,2,2,2,2,2,2,2,2,2,2,2,2,2,2,2,2,2,2
2,2,2,2,2,2,2,2,2,2,2,2,2,2,2,2,2,2,2,2,2,2,2,2,2,2,2,2,2,2,2,2,2,2,2,2,2,2,2,2,2,2,2,2,2,2,2,2,2,2,2,2,2,2
2,2,2,2,2,2,2,2,2,2,2,2,2,2,2,2,2,2,2,2,2,2,2,2,2,2,2,2,2,2,2,2,2,2,2,2,2,2,2,2,2,2,2,2,2,2,2,2,2,2,2,2,2,2
2,2,2,2,2,2,2,2,2,2,2,2,2,2,2,2,2,2,2,2,2,2,2,2,2,2,2,2,2,2,2,2,2,2,2,2,2,2,2,2,2,2,2,2,2,2,2,2,2,2,2,2,2,2
:endlayer
layer: 16
2,2,2,2,2,7,7,7,7,7,7,7,2,2,2,2,2,2,2,2,2,5,5,5,7,7,7,7,7,7,5,5,2,2,2,2,2,2,2,2,5,5,5,5,0,0,0,0,0,0,0,2,2,2
2,2,2,2,7,7,7,7,7,7,7,2,2,2,2,2,2,2,2,2,2,5,5,5,7,7,7,7,7,5,5,2,2,2,2,2,2,2,2,2,5,5,5,5,0,0,4,4,2,2,2,2,2,2
2,2,2,2,0,7,7,7,7,7,2,2,2,2,2,2,2,2,2,2,2,5,5,5,7,7,7,0,5,5,2,2,2,2,2,2,2,2,2,2,2,5,5,5,0,0,4,4,2,2,2,2,2,2
2,2,2,2,0,7,7,7,7,2,2,2,2,2,2,2,2,2,2,2,2,5,5,5,5,2,0,0,5,2,2,2,2,2,2,2,7,7,2,2,2,5,5,5,0,0,4,4,2,2,2,2,2,2
2,2,2,2,0,0,0,2,2,2,2,2,2,2,2,2,2,2,2,2,2,2,5,5,5,2,0,0,2,2,2,0,2,2,2,2,7,7,7,2,2,2,5,5,0,0,4,4,2,2,2,2,2,2
2,2,2,2,0,0,0,2,2,2,2,2,2,2,2,2,2,2,2,2,2,2,2,5,5,2,2,2,2,2,2,2,2,2,2,7,7,7,7,2,2,2,2,5,0,5,4,2,2,2,2,2,2,2
2,2,2,2,0,0,0,2,2,2,2,2,2,2,2,2,2,2,2,2,2,2,2,2,2,2,2,2,2,2,2,2,2,2,2,7,7,7,7,2,2,2,2,0,0,0,2,0,0,0,0,0,0,0
2,2,2,2,0,0,13,2,2,2,2,2,2,2,2,2,2,2,2,2,2,2,2,2,2,2,2,2,2,2,2,2,2,2,2,7,7,7,7,2,0,0,0,0,0,0,0,0,0,0,0,0,0,0
2,2,2,2,2,2,2,2,2,2,0,0,2,2,2,2,2,2,2,2,2,2,2,2,2,2,2,2,0,0,2,2,2,2,2,7,7,7,7,0,0,0,0,0,0,0,0,0,0,0,0,0,0,0
2,2,2,2,2,2,2,2,0,0,0,0,2,2,2,2,2,2,2,2,2,2,2,2,2,2,2,2,0,0,0,7,2,2,2,7,7,0,0,0,0,0,0,0,0,0,0,0,0,0,0,0,0,0
2,2,2,2,2,2,2,0,0,0,0,0,2,2,2,2,2,2,2,2,2,2,2,2,2,2,0,2,0,0,0,7,7,7,0,0,0,0,0,0,0,0,0,0,0,0,0,0,0,0,2,2,2,0
2,2,2,2,2,2,2,0,0,0,0,0,2,2,2,2,2,2,2,2,2,8,8,2,2,2,2,0,2,7,7,7,7,7,0,0,0,0,0,0,0,0,0,0,0,0,0,0,2,2,2,2,2,2
2,2,2,2,2,2,2,2,0,0,0,0,2,2,2,2,2,2,2,2,2,2,8,2,2,2,2,2,0,7,7,7,7,7,0,0,0,0,0,0,0,0,0,2,0,0,0,0,0,2,2,2,2,2
2,2,2,2,2,2,2,2,2,2,2,2,2,3,2,2,2,2,2,2,2,2,2,2,2,2,2,5,5,5,5,0,7,7,0,0,0,0,0,0,0,2,2,2,0,0,0,0,0,0,2,2,2,2
2,2,2,2,2,2,2,2,2,2,2,2,2,2,2,2,2,2,2,2,2,2,2,2,2,2,0,0,0,49,7,7,7,7,7,0,0,0,0,0,0,0,2,2,0,0,0,0,0,0,2,2,2,2
2,2,2,2,2,2,2,2,2,2,2,2,2,2,2,2,2,2,2,2,2,2,2,0,0,0,0,0,0,49,7,7,7,2,2,2,2,0,0,0,0,0,0,5,0,0,0,0,0,2,2,2,2,2
2,2,2,2,2,2,2,2,2,2,2,2,2,2,2,2,2,2,2,2,2,2,0,0,0,0,0,0,50,21,7,2,2,2,2,2,2,2,2,0,0,0,0,0,2,2,2,2,2,2,2,2,2,2
2,2,2,2,2,2,2,2,2,2,2,2,2,2,2,2,2,2,2,2,2,0,0,0,0,0,0,0,0,0,0,0,2,2,2,2,2,5,2,0,0,0,0,0,5,5,2,2,2,2,2,2,2,2
2,2,2,2,2,2,2,2,2,2,2,2,2,2,2,2,2,2,2,2,0,0,0,0,0,0,0,0,0,0,0,0,2,2,2,2,5,5,5,2,5,0,0,0,0,0,2,2,2,2,2,2,2,2
2,2,2,2,2,2,2,2,2,2,2,2,2,2,2,2,2,2,2,0,0,0,0,0,0,0,0,0,0,0,0,0,0,0,0,2,5,5,5,5,2,2,2,5,0,0,2,2,2,2,2,2,2,2
2,2,2,2,2,2,2,2,2,2,2,2,2,2,2,4,4,2,0,0,0,0,0,0,0,0,0,0,0,0,0,0,0,0,0,0,5,5,5,5,2,2,2,2,2,2,2,2,2,2,2,2,2,0
2,2,2,2,2,2,2,2,2,2,2,0,2,2,2,4,4,2,0,0,0,0,0,0,0,0,0,0,0,0,0,0,0,0,0,0,0,5,7,7,7,7,7,7,7,2,2,2,2,2,2,2,2,0
2,2,2,2,2,2,2,2,2,2,2,2,2,2,2,4,4,2,0,0,0,0,0,0,0,0,0,0,0,0,0,0,0,0,0,0,0,7,7,7,7,7,7,7,7,7,2,2,2,2,2,2,2,0
2,2,2,2,2,2,2,2,2,2,2,2,2,2,2,2,2,29,0,0,0,0,0,0,0,0,0,0,0,0,0,0,0,0,0,0,0,0,7,7,7,0,0,7,7,2,2,2,2,2,2,2,2,2
2,2,2,2,2,2,2,2,2,2,2,2,0,0,0,0,7,0,0,0,0,0,0,0,0,0,0,0,0,0,0,0,0,0,0,0,0,0,7,7,7,0,0,2,2,2,2,2,2,2,2,2,2,2
2,2,2,2,2,2,2,2,2,2,2,2,0,0,0,0,7,0,0,0,0,0,0,0,0,0,0,0,0,0,0,0,0,0,0,0,0,0,21,0,0,0,0,2,2,2,2,2,2,2,2,2,2,2
2,2,2,2,2,2,2,2,2,2,2,2,0,0,0,0,7,0,0,0,0,0,0,0,0,0,0,0,0,0,0,0,0,0,0,0,0,0,7,0,0,0,2,2,2,2,2,2,2,2,2,2,2,2
2,2,2,2,2,2,2,2,2,2,2,2,0,0,0,0,7,0,0,0,0,2,2,0,0,0,0,0,0,0,0,0,0,0,0,0,0,0,7,0,0,2,2,2,2,2,2,2,2,2,2,2,2,2
2,2,2,2,2,3,3,2,2,2,2,2,0,0,0,0,7,0,0,0,0,2,2,0,0,0,0,0,0,0,0,0,0,0,0,0,0,0,7,2,2,2,2,2,2,2,2,2,2,2,2,2,2,2
2,2,2,2,2,3,3,2,2,2,2,2,0,0,0,0,0,7,0,0,0,0,0,0,0,0,0,0,0,0,0,0,0,0,0,0,0,2,2,2,2,2,2,2,2,2,2,2,2,2,2,2,2,2
2,2,2,2,2,2,2,2,2,2,2,2,2,0,0,0,0,7,0,0,0,0,0,0,0,0,0,0,0,0,0,0,0,0,0,0,0,2,2,2,2,2,2,2,2,2,2,2,2,2,2,2,2,2
2,2,2,2,2,2,2,2,2,2,2,2,2,2,2,7,7,2,0,0,0,0,0,0,0,0,0,0,0,0,0,0,0,0,0,0,2,2,2,2,2,2,2,2,2,2,2,2,2,2,2,2,2,2
2,2,2,2,2,2,2,2,2,2,2,2,2,2,2,7,7,7,7,0,0,0,0,0,0,0,0,0,0,0,0,0,0,0,0,2,2,2,2,2,2,2,2,2,2,2,0,2,2,2,2,7,7,7
2,2,2,2,2,2,2,2,2,2,2,2,2,2,7,7,7,7,7,7,0,0,0,0,0,0,0,0,0,0,0,0,0,0,2,2,2,2,2,2,2,2,2,4,4,0,0,0,2,2,7,7,7,38
2,2,2,2,2,2,2,2,2,2,2,2,2,7,7,7,7,7,7,7,2,0,0,0,0,0,0,0,0,0,0,0,2,2,2,2,2,2,2,2,2,2,2,4,4,0,0,0,2,2,2,7,0,51
2,2,2,2,2,2,2,2,2,2,2,2,7,7,7,7,7,7,2,2,2,2,0,0,0,0,0,0,2,5,5,5,2,2,2,2,2,2,2,2,2,2,2,4,4,0,0,0,0,2,2,2,0,0
2,2,2,2,2,2,2,2,2,2,2,2,7,7,0,0,2,2,2,2,2,2,2,0,0,0,0,2,2,2,0,0,2,2,2,2,2,2,3,2,2,2,2,4,4,0,0,0,0,2,2,2,0,0
2,2,2,2,2,2,2,2,2,2,2,2,2,0,0,0,0,2,2,2,2,2,7,7,7,7,7,7,7,2,2,2,2,2,2,2,2,3,2,2,2,2,2,4,4,0,0,0,0,2,2,2,0,0
2,2,2,2,2,2,2,2,2,2,2,2,2,0,0,0,0,2,2,2,2,7,7,7,7,7,7,7,7,7,2,2,2,2,2,2,2,2,2,2,2,2,2,2,2,2,0,0,0,0,2,2,0,0
2,2,2,2,2,2,2,2,2,2,2,2,2,0,0,0,0,2,2,2,2,7,7,7,7,7,7,7,7,7,13,2,2,2,2,2,2,2,2,2,2,2,2,2,2,2,0,0,0,0,2,2,0,0
2,2,2,2,2,2,2,2,2,2,2,2,2,2,2,2,2,2,2,2,2,7,7,7,7,7,7,7,0,2,2,2,2,2,2,2,2,2,2,2,2,2,2,2,2,2,0,0,0,0,2,2,0,0
2,2,2,2,2,8,2,2,2,2,2,2,2,2,2,2,2,2,2,2,2,0,0,5,5,5,5,2,2,2,2,2,2,2,2,2,2,2,2,2,2,2,2,2,2,2,2,0,0,0,0,2,0,0
2,2,2,2,2,2,2,2,2,2,2,2,2,2,2,2,2,2,2,2,5,0,0,0,5,5,5,2,2,2,2,2,2,2,2,2,2,2,2,2,2,2,2,2,2,2,2,0,0,0,0,0,0,0
