# Ancient Warfare Structure Template File
# auto-generated structure file. created on: 4/14/2014 at: 17:21:50
# Lines beginning with # denote comments

header:
version=2.0
name=CivCoachingInnMOH
size=51,37,40
offset=23,3,38
:endheader

#### VALIDATION ####
validation:
type=ground
survival=false
worldGenEnabled=true
unique=false
preserveBlocks=false
selectionWeight=10
clusterValue=10
minDuplicateDistance=120
dimensionWhiteList=false
dimensionList=
biomeWhiteList=true
biomeList=bop.meadow,highlands.meadow,heathland,moor,highlands_lowland,orchard,field,ebxl.meadow
leveling=9
fill=6
border=6
validTargetBlocks=clay,sand,lapis_ore,grass,lit_redstone_ore,stone,gravel,iron_ore,diamond_ore,stained_hardened_clay,dirt,coal_ore,redstone_ore,gold_ore
data:
:enddata
:endvalidation

#### LAYERS ####
layer: 0
1,1,1,1,1,1,1,1,1,1,1,1,1,1,1,1,1,1,1,1,1,1,1,1,1,1,1,1,1,1,1,1,1,1,1,1,1,1,1,1,1,1,1,1,1,1,1,1,1,1,1
1,1,1,1,1,1,1,1,1,1,1,1,1,1,1,1,1,1,1,1,1,1,1,1,1,1,1,1,1,1,1,1,1,1,1,1,1,1,1,1,1,1,1,1,1,1,1,1,1,1,1
1,1,1,1,1,1,1,1,1,1,1,1,1,1,1,1,1,1,1,1,1,1,1,1,1,1,1,1,1,1,1,1,1,1,1,1,1,1,1,1,1,1,1,1,1,1,1,1,1,1,1
1,1,1,1,1,1,1,1,1,1,1,1,1,1,1,1,1,1,1,1,1,1,1,1,1,1,1,1,1,1,1,1,1,1,1,1,1,1,1,1,1,1,1,1,1,1,1,1,1,1,1
1,1,1,1,1,1,1,1,1,1,1,1,1,1,1,1,1,1,1,1,1,1,1,1,1,1,1,1,1,1,1,1,1,1,1,1,1,1,1,1,1,1,1,1,1,1,1,1,1,1,1
1,1,1,1,1,1,1,1,1,1,1,1,1,1,1,1,1,1,1,1,1,1,1,1,1,1,1,1,1,1,1,1,1,1,1,1,1,1,1,1,1,1,1,1,1,1,1,1,1,1,1
1,1,1,1,1,1,1,1,1,1,1,1,1,1,1,1,1,1,1,1,1,1,1,1,1,1,1,1,1,1,1,1,1,1,1,1,1,1,1,1,1,1,1,1,1,1,1,1,1,1,1
1,1,1,1,1,1,1,1,1,1,1,1,1,1,1,1,1,1,1,1,1,1,1,1,1,1,1,1,1,1,1,1,1,1,1,1,1,1,1,1,1,1,1,1,1,1,1,1,1,1,1
1,1,1,1,1,1,1,1,1,1,1,1,1,1,1,1,1,1,1,1,1,1,1,1,1,1,1,1,1,1,1,1,1,1,1,1,1,1,1,1,1,1,1,1,1,1,1,1,1,1,1
1,1,1,1,1,1,1,1,1,1,1,1,1,1,1,1,1,1,1,1,1,1,1,1,1,1,1,1,1,1,1,1,1,1,1,1,1,1,1,1,1,1,1,1,1,1,1,1,1,1,1
1,1,1,1,1,1,1,1,1,1,1,1,1,1,1,1,1,1,1,1,1,1,1,1,1,1,1,1,1,1,1,1,1,1,1,1,1,1,1,1,1,1,1,1,1,1,1,1,1,1,1
1,1,1,1,1,1,1,1,1,1,1,1,1,1,1,1,1,1,1,1,1,1,1,1,1,1,1,1,1,1,1,1,1,1,1,1,1,1,1,1,1,1,1,1,1,1,1,1,1,1,1
1,1,1,1,1,1,1,1,1,1,1,1,1,1,1,1,1,1,1,1,1,1,1,1,1,1,1,1,1,1,1,1,1,1,1,1,1,1,1,1,1,1,1,1,1,1,1,1,1,1,1
1,1,1,1,1,1,1,1,1,1,1,1,1,1,1,1,1,1,1,1,1,1,1,1,1,1,1,1,1,1,1,1,1,1,1,1,1,1,1,1,1,1,1,1,1,1,1,1,1,1,1
1,1,1,1,1,1,1,1,1,1,1,1,1,1,1,1,1,1,1,1,1,1,1,1,1,1,1,1,1,1,1,1,1,1,1,1,1,1,1,1,1,1,1,1,1,1,1,1,1,1,1
1,1,1,1,1,1,1,1,1,1,1,1,1,1,1,1,1,1,1,1,1,1,1,1,1,1,1,1,1,1,1,1,1,1,1,1,1,1,1,1,1,1,1,1,1,1,1,1,1,1,1
1,1,1,1,1,1,1,1,1,1,1,1,1,1,1,1,1,1,1,1,1,1,1,1,1,1,1,1,1,1,1,1,1,1,1,1,1,1,1,1,1,1,1,1,1,1,1,1,1,1,1
1,1,1,1,1,1,1,1,1,1,1,1,1,1,1,1,1,1,1,1,1,1,1,1,1,1,1,1,1,1,1,1,1,1,1,1,1,1,1,1,1,1,1,1,1,1,1,1,1,1,1
1,1,1,1,1,1,1,1,1,1,1,1,1,1,1,1,1,1,1,1,1,1,1,1,1,1,1,1,1,1,1,1,1,1,1,1,1,1,1,1,1,1,1,1,1,1,1,1,1,1,1
1,1,1,1,1,1,1,1,1,1,1,1,1,1,1,1,1,1,1,1,1,1,1,1,1,1,1,1,1,1,1,1,1,1,1,1,1,1,1,1,1,1,1,1,1,1,1,1,1,1,1
1,1,1,1,1,1,1,1,1,1,1,1,1,1,1,1,1,1,1,1,1,1,1,1,1,1,1,1,1,1,1,1,1,1,1,1,1,1,1,1,1,1,1,1,1,1,1,1,1,1,1
1,1,1,1,1,1,1,1,1,1,1,1,1,1,1,1,1,1,1,1,1,1,1,1,1,1,1,1,1,1,1,1,1,1,1,1,1,1,1,1,1,1,1,1,1,1,1,1,1,1,1
1,1,1,1,1,1,1,1,1,1,1,1,1,1,1,1,1,1,1,1,1,1,1,1,1,1,1,1,1,1,1,1,1,1,1,1,1,1,1,1,1,1,1,1,1,1,1,1,1,1,1
1,1,1,1,1,1,1,1,1,1,1,1,1,1,1,1,1,1,1,1,1,1,1,1,1,1,1,1,1,1,1,1,1,1,1,1,1,1,1,1,1,1,1,1,1,1,1,1,1,1,2
1,1,1,1,1,1,1,1,1,1,1,1,1,1,1,1,1,1,1,1,1,1,1,1,1,1,1,1,1,1,1,1,1,1,1,1,1,1,1,1,1,1,1,1,1,1,1,1,1,1,1
1,1,1,1,1,1,1,1,1,1,1,1,1,1,1,1,1,1,1,1,1,1,1,1,1,1,1,1,1,1,1,1,1,1,1,1,1,1,1,1,1,1,1,1,1,1,1,1,1,1,1
1,1,1,1,1,1,1,1,1,1,1,1,1,1,1,1,1,1,1,1,1,1,1,1,1,1,1,1,1,1,1,1,1,1,1,1,1,1,1,1,1,1,1,1,1,1,1,1,1,1,1
1,1,1,1,1,1,1,1,1,1,1,1,1,1,1,1,1,1,1,1,1,1,1,1,1,1,1,1,1,1,1,1,1,1,1,1,1,1,1,1,1,1,1,1,1,1,1,1,1,1,1
1,1,1,1,1,1,1,1,1,1,1,1,1,1,1,1,1,1,1,1,1,1,1,1,1,1,1,1,1,1,1,1,1,1,1,1,1,1,1,1,1,1,1,1,1,1,1,1,1,1,1
1,1,1,1,1,1,1,1,1,1,1,1,1,1,1,1,1,1,1,1,1,1,1,1,1,1,1,1,1,1,1,1,1,1,1,1,1,1,1,1,1,1,1,1,1,1,1,1,1,1,1
1,1,1,1,1,1,1,1,1,1,1,1,1,1,1,1,1,1,1,1,1,1,1,1,1,1,1,1,1,1,1,1,1,1,1,1,1,1,1,1,1,1,1,1,1,1,1,1,1,1,1
1,1,1,1,1,1,1,1,1,1,1,1,1,1,1,1,1,1,1,1,1,1,1,1,1,1,1,1,1,1,1,1,1,1,1,1,1,1,1,1,1,1,1,1,1,1,1,1,1,1,1
1,1,1,1,1,1,1,1,1,1,1,1,1,1,1,1,1,1,1,1,1,1,1,1,1,1,1,1,1,1,1,1,1,1,1,1,1,1,1,1,1,1,1,1,1,1,1,1,1,1,1
1,1,1,1,1,1,1,1,1,1,1,1,1,1,1,1,1,1,1,1,1,1,1,1,1,1,1,1,1,1,1,1,1,1,1,1,1,1,1,1,1,1,1,1,1,1,1,1,1,1,1
1,1,1,1,1,1,1,1,1,1,1,1,1,1,1,1,1,1,1,1,1,1,1,1,1,1,1,1,1,1,1,1,1,1,1,1,1,1,1,1,1,1,1,1,1,1,1,1,1,1,1
1,1,1,1,1,1,1,1,1,1,1,1,1,1,1,1,1,1,1,1,1,1,1,1,1,1,1,1,1,1,1,1,1,1,1,1,1,1,1,1,1,1,1,1,1,1,1,1,1,1,1
1,1,1,1,1,1,1,1,1,1,1,1,1,1,1,1,1,1,1,1,1,1,1,1,1,1,1,1,1,1,1,1,1,1,1,1,1,1,1,1,1,1,1,1,1,1,1,1,1,1,1
1,1,1,1,1,1,1,1,1,1,1,1,1,1,1,1,1,1,1,1,1,1,1,1,1,1,1,1,1,1,1,1,1,1,1,1,1,1,1,1,1,1,1,1,1,1,1,1,1,1,1
1,1,1,1,1,1,1,1,1,1,1,1,1,1,1,1,1,1,1,1,1,1,1,1,1,1,1,1,1,1,1,1,1,1,1,1,1,1,1,1,1,1,1,1,1,1,1,1,1,1,1
1,1,1,1,1,1,1,1,1,1,1,1,1,1,1,1,1,1,1,1,1,1,1,1,1,1,1,1,1,1,1,1,1,1,1,1,1,1,1,1,1,1,1,1,1,1,1,1,1,1,1
:endlayer
layer: 1
1,1,1,1,1,1,1,1,1,1,1,1,1,1,1,1,1,1,1,1,1,1,1,1,1,1,1,1,1,1,1,1,1,1,1,1,1,1,1,1,1,1,1,1,1,1,1,1,1,1,1
1,1,1,1,1,1,1,1,1,1,1,1,1,1,1,1,1,1,1,1,1,1,1,1,1,1,1,1,1,1,1,1,1,1,1,1,1,1,1,1,1,1,1,1,1,1,1,1,1,1,1
1,1,1,1,1,1,1,1,1,1,1,1,1,1,1,1,1,1,1,1,1,1,1,1,1,1,1,1,1,1,1,1,1,1,1,1,1,1,1,1,1,1,1,1,1,1,1,1,1,1,1
1,1,1,1,1,1,1,1,1,1,1,1,1,1,1,1,1,1,1,1,1,1,1,1,1,1,1,1,1,1,1,1,1,1,1,1,1,1,1,1,1,1,1,1,1,1,1,1,1,1,1
1,1,1,1,1,1,1,1,1,1,1,1,1,1,1,1,1,1,1,1,1,1,1,1,1,1,1,1,1,1,1,1,1,1,1,1,1,1,1,1,1,1,1,1,1,1,1,1,1,1,1
1,1,1,1,1,1,1,1,1,1,1,1,1,1,1,1,1,1,1,1,1,1,1,1,1,1,1,1,1,1,1,1,1,1,1,1,1,1,1,1,1,1,1,1,1,1,1,1,1,1,1
1,1,1,1,1,1,1,1,1,1,1,1,1,1,1,1,1,1,1,1,1,1,1,1,1,1,1,1,1,1,1,1,1,1,1,1,1,1,1,1,1,1,1,1,1,1,1,1,1,1,1
1,1,1,1,1,1,1,1,1,1,1,1,1,1,1,1,1,1,1,1,1,1,1,1,1,1,1,1,1,1,1,1,1,1,1,1,1,1,1,1,1,1,1,1,1,1,1,1,1,1,1
1,1,1,1,1,1,1,1,1,1,1,1,1,1,1,1,1,1,1,1,1,1,1,1,1,1,1,1,1,1,1,1,1,1,1,1,1,1,1,1,1,1,1,1,1,1,1,1,1,1,1
1,1,1,1,1,1,1,1,1,1,1,1,1,1,1,1,1,1,1,1,1,1,1,1,1,1,1,1,1,1,1,1,1,1,1,1,1,1,1,1,1,1,1,1,1,1,1,1,1,1,1
1,1,1,1,1,1,1,1,1,1,1,1,1,1,1,1,1,1,1,1,1,1,1,1,1,1,1,1,1,1,1,1,1,1,1,1,1,1,1,1,1,1,1,1,1,1,1,1,1,1,1
1,1,1,1,1,1,1,1,1,1,1,1,1,1,1,1,1,1,1,1,1,1,1,1,1,1,1,1,1,1,1,1,1,1,1,1,1,1,1,1,1,1,1,1,1,1,1,1,1,1,1
1,1,1,1,1,1,1,1,1,1,1,1,1,1,1,1,1,1,1,1,1,1,1,1,1,1,1,1,1,1,1,1,1,1,1,1,1,1,1,1,1,1,1,1,1,1,1,1,1,1,1
1,1,1,1,1,1,1,1,1,1,1,1,1,1,1,1,1,1,1,1,1,1,1,1,1,1,1,1,1,1,1,1,1,1,1,1,1,1,1,1,1,1,1,1,1,1,1,1,1,1,1
1,1,1,1,1,1,1,1,1,1,1,1,1,1,1,1,1,1,1,1,1,1,1,1,1,1,1,1,1,1,1,1,1,1,1,1,1,1,1,1,1,1,1,1,1,1,1,1,1,1,1
1,1,1,1,1,1,1,1,1,1,1,1,1,1,1,1,1,1,1,1,1,1,1,1,1,1,1,1,1,1,1,1,1,1,1,1,1,1,1,1,1,1,1,1,1,1,1,1,1,1,1
1,1,1,1,1,1,1,1,1,1,1,1,1,1,1,1,1,1,1,1,1,1,1,1,1,1,1,1,1,1,1,1,1,1,1,1,1,1,1,1,1,1,1,1,1,1,1,1,1,1,1
1,1,1,1,1,1,1,1,1,1,1,1,1,1,1,1,1,1,1,1,1,1,1,1,1,1,1,1,1,1,1,1,1,1,1,1,1,1,1,1,1,1,1,1,1,1,1,1,1,1,1
1,1,1,1,1,1,1,1,1,1,1,1,1,1,1,1,1,1,1,1,1,1,1,1,1,1,1,1,1,1,1,1,1,1,1,1,1,1,1,1,1,1,1,1,1,1,1,1,1,1,1
1,1,1,1,1,1,1,1,1,1,1,1,1,1,1,1,1,1,1,3,3,1,1,1,1,1,1,1,1,1,1,1,1,1,1,1,1,1,1,1,1,1,1,1,1,1,1,1,1,1,1
1,1,1,1,1,1,1,1,1,1,1,1,1,1,1,1,1,1,3,4,4,3,1,1,1,1,1,1,1,1,1,1,1,1,1,1,1,1,1,1,1,1,1,1,1,1,1,1,1,1,1
1,1,1,1,1,1,1,1,1,1,1,1,1,1,1,1,1,1,3,4,4,3,1,1,1,1,1,1,1,1,1,1,1,1,1,1,1,1,1,1,1,1,1,1,1,1,1,1,1,1,1
1,1,1,1,1,1,1,1,1,1,1,1,1,1,1,1,1,1,1,3,3,1,1,1,1,1,1,1,1,1,1,1,1,1,1,1,1,1,1,1,1,1,1,1,1,1,1,1,1,1,1
1,1,1,1,1,1,1,1,1,1,1,1,1,1,1,1,1,1,1,1,1,1,1,1,1,1,1,1,1,1,1,1,1,1,1,1,1,1,1,1,1,1,1,1,1,1,1,1,1,1,2
1,1,1,1,1,1,1,1,1,1,1,1,1,1,1,1,1,1,1,1,1,1,1,1,1,1,1,1,1,1,1,1,1,1,1,1,1,1,1,1,1,1,1,1,1,1,1,1,1,1,1
1,1,1,1,1,1,1,1,1,1,1,1,1,1,1,1,1,1,1,1,1,1,1,1,1,1,1,1,1,1,1,1,1,1,1,1,1,1,1,1,1,1,1,1,1,1,1,1,1,1,1
1,1,1,1,1,1,1,1,1,1,1,1,1,1,1,1,1,1,1,1,1,1,1,1,1,1,1,1,1,1,1,1,1,1,1,1,1,1,1,1,1,1,1,1,1,1,1,1,1,1,1
1,1,1,1,1,1,1,1,1,1,1,1,1,1,1,1,1,1,1,1,1,1,1,1,1,1,1,1,1,1,1,1,1,1,1,1,1,1,1,1,1,1,1,1,1,1,1,1,1,1,1
1,1,1,1,1,1,1,1,1,1,1,1,1,1,1,1,1,1,1,1,1,1,1,1,1,1,1,1,1,1,1,1,1,1,1,1,1,1,1,1,1,1,1,1,1,1,1,1,1,1,1
1,1,1,1,1,1,1,1,1,1,1,1,1,1,1,1,1,1,1,1,1,1,1,1,1,1,1,1,1,1,1,1,1,1,1,1,1,1,1,1,1,1,1,1,1,1,1,1,1,1,1
1,1,1,1,1,1,1,1,1,1,1,1,1,1,1,1,1,1,1,1,1,1,1,1,1,1,1,1,1,1,1,1,1,1,1,1,1,1,1,1,1,1,1,1,1,1,1,1,1,1,1
1,1,1,1,1,1,1,1,1,1,1,1,1,1,1,1,1,1,1,1,1,1,1,1,1,1,1,1,1,1,1,1,1,1,1,1,1,1,1,1,1,1,1,1,1,1,1,1,1,1,1
1,1,1,1,1,1,1,1,1,1,1,1,1,1,1,1,1,1,1,1,1,1,1,1,1,1,1,1,1,1,1,1,1,1,1,1,1,1,1,1,1,1,1,1,1,1,1,1,1,1,1
1,1,1,1,1,1,1,1,1,1,1,1,1,1,1,1,1,1,1,1,1,1,1,1,1,1,1,1,1,1,1,1,1,1,1,1,1,1,1,1,1,1,1,1,1,1,1,1,1,1,1
1,1,1,1,1,1,1,1,1,1,1,1,1,1,1,1,1,1,1,1,1,1,1,1,1,1,1,1,1,1,1,1,1,1,1,1,1,1,1,1,1,1,1,1,1,1,1,1,1,1,1
1,1,1,1,1,1,1,1,1,1,1,1,1,1,1,1,1,1,1,1,1,1,1,1,1,1,1,1,1,1,1,1,1,1,1,1,1,1,1,1,1,1,1,1,1,1,1,1,1,1,1
1,1,1,1,1,1,1,1,1,1,1,1,1,1,1,1,1,1,1,1,1,1,1,1,1,1,1,1,1,1,1,1,1,1,1,1,1,1,1,1,1,1,1,1,1,1,1,1,1,1,1
1,1,1,1,1,1,1,1,1,1,1,1,1,1,1,1,1,1,1,1,1,1,1,1,1,1,1,1,1,1,1,1,1,1,1,1,1,1,1,1,1,1,1,1,1,1,1,1,1,1,1
1,1,1,1,1,1,1,1,1,1,1,1,1,1,1,1,1,1,1,1,1,1,1,1,1,1,1,1,1,1,1,1,1,1,1,1,1,1,1,1,1,1,1,1,1,1,1,1,1,1,1
1,1,1,1,1,1,1,1,1,1,1,1,1,1,1,1,1,1,1,1,1,1,1,1,1,1,1,1,1,1,1,1,1,1,1,1,1,1,1,1,1,1,1,1,1,1,1,1,1,1,1
:endlayer
layer: 2
5,5,5,5,5,5,5,5,5,5,5,5,5,5,5,5,5,5,5,5,5,5,5,5,5,5,5,3,3,5,5,5,5,5,5,5,5,5,5,5,5,5,5,5,5,5,5,5,5,5,5
5,5,5,5,5,5,5,5,5,5,5,5,5,5,5,5,5,5,5,5,5,5,5,5,5,5,5,3,3,5,5,5,5,5,5,5,5,5,5,5,5,5,5,5,5,5,5,5,5,5,5
5,5,5,6,6,6,6,6,6,6,6,6,6,6,6,1,1,1,1,1,1,1,1,1,1,1,1,6,6,1,1,1,1,1,1,1,1,1,1,1,1,1,1,1,1,1,1,1,1,5,5
5,5,5,6,3,3,3,3,3,3,3,3,6,3,3,1,1,1,1,1,1,1,5,5,5,5,5,3,3,3,3,3,3,3,3,3,3,5,1,3,3,3,3,3,3,1,5,5,1,5,5
5,5,5,6,3,3,3,3,3,3,3,3,6,3,3,1,1,1,1,1,1,1,1,3,3,3,3,3,3,3,3,3,3,3,3,3,3,5,1,3,3,3,3,3,3,7,3,5,1,5,5
5,5,5,6,3,3,3,3,3,3,3,3,6,3,3,1,1,1,1,1,1,1,5,5,5,5,5,3,3,3,3,3,3,3,3,3,3,5,1,3,3,3,3,3,3,3,3,5,1,5,5
5,5,5,6,3,3,3,3,3,3,3,3,6,3,3,1,1,1,1,1,1,1,5,5,5,5,5,5,5,5,5,5,5,5,3,3,3,5,3,3,3,3,3,3,3,3,3,5,1,5,5
5,5,5,6,3,3,3,3,3,3,3,3,6,3,3,1,1,1,1,1,1,1,1,1,1,1,1,1,1,1,1,1,1,5,3,3,3,5,1,3,3,3,3,3,3,3,3,5,1,5,5
5,5,5,6,3,3,3,3,3,3,3,3,6,3,3,1,1,1,1,1,1,1,1,1,1,1,1,1,1,1,1,1,1,5,3,3,3,5,1,1,1,3,3,3,3,7,3,5,1,5,5
5,5,5,6,3,3,3,3,3,3,3,3,6,3,3,1,1,1,1,1,1,1,1,1,1,1,1,1,1,1,1,1,1,5,3,3,3,3,3,3,3,3,3,3,3,3,3,5,1,5,5
5,5,5,6,3,3,3,3,3,3,3,3,6,3,3,1,1,1,1,1,1,1,1,1,1,1,1,1,1,1,1,1,1,5,3,3,3,3,3,3,3,3,3,3,3,3,3,5,1,5,5
5,5,5,6,3,3,3,3,3,3,3,3,6,3,3,1,1,1,1,1,1,1,1,1,1,1,1,1,1,1,1,1,1,5,3,3,3,3,3,3,3,3,3,3,3,3,3,5,1,5,5
5,5,5,6,3,3,3,3,3,3,3,3,6,3,3,1,1,1,1,1,1,1,1,1,1,1,1,1,1,1,1,1,1,5,3,3,3,3,3,3,3,3,3,3,3,3,3,5,1,5,5
5,5,5,6,3,3,3,3,3,3,3,3,6,5,5,5,5,5,5,5,5,1,5,5,5,5,1,5,5,5,5,5,5,5,3,3,3,3,1,3,3,3,3,3,3,1,3,5,1,5,5
5,5,5,6,3,3,3,3,3,3,3,3,6,5,5,5,3,3,3,3,3,3,3,3,3,3,3,3,3,3,3,3,3,3,3,3,3,3,3,3,3,3,3,3,3,3,3,1,1,5,5
5,5,5,6,3,3,3,3,3,3,3,3,6,5,5,5,3,3,3,3,3,3,3,3,3,3,3,3,3,3,3,3,3,3,3,3,3,3,3,3,3,3,3,3,3,3,3,1,5,5,5
5,5,5,6,3,3,3,3,3,3,3,3,6,5,5,5,3,3,3,3,3,3,3,3,3,3,3,3,3,3,3,3,3,3,3,3,3,3,3,3,3,3,3,3,3,3,3,3,3,3,3
5,5,5,6,3,3,3,3,3,3,3,3,6,5,5,5,3,3,3,3,3,3,3,3,3,3,3,3,3,3,3,3,3,3,3,3,3,3,3,3,3,3,3,3,3,3,3,3,3,3,3
5,5,5,6,3,3,3,3,3,3,3,3,6,5,5,5,3,3,3,3,3,3,3,3,3,3,3,3,3,3,3,3,3,3,3,3,3,3,3,3,5,5,5,5,5,5,5,1,5,5,5
5,5,5,6,6,1,1,6,6,6,6,6,6,6,6,6,3,3,6,6,6,6,3,3,3,3,3,5,1,5,5,5,5,5,5,5,5,1,3,3,1,1,1,1,1,1,1,1,1,5,5
5,5,5,6,3,3,3,3,3,3,3,3,3,3,3,6,3,3,6,8,8,6,3,3,3,3,3,1,1,1,1,1,1,1,1,1,3,3,3,3,1,1,1,1,1,1,1,1,1,5,5
5,5,5,6,3,3,3,3,3,3,3,3,3,3,3,6,3,3,6,8,8,6,3,3,3,3,3,3,1,3,3,3,3,3,3,3,3,3,3,3,1,1,1,1,1,1,1,1,1,5,5
5,5,5,6,3,3,3,3,3,3,3,3,3,3,3,6,3,3,6,6,6,6,3,3,3,3,3,3,3,3,3,3,3,3,3,3,3,3,3,3,1,1,1,1,1,1,1,1,1,5,5
5,5,5,6,3,3,3,3,3,3,3,3,3,3,3,6,3,3,3,3,3,3,3,3,3,3,3,3,1,3,3,3,3,3,3,3,3,3,3,3,1,1,1,1,1,1,1,1,1,5,5
5,5,5,6,3,3,3,3,3,3,3,3,3,3,3,6,3,3,3,3,3,3,3,3,3,3,3,1,1,3,3,3,3,3,3,3,1,1,6,1,1,1,1,1,1,1,1,1,1,5,5
5,5,5,6,3,3,3,3,3,3,3,3,3,3,3,6,3,3,3,3,3,3,3,3,3,3,3,3,3,6,3,3,3,3,3,3,3,3,3,3,1,1,1,1,1,1,1,1,1,5,5
5,5,5,6,3,3,3,3,3,3,3,3,3,3,3,6,3,3,3,3,3,3,3,3,3,3,3,3,3,6,3,3,3,3,3,3,3,3,3,3,1,1,1,1,1,1,1,1,1,5,5
5,5,5,6,3,3,3,3,3,3,3,3,3,3,3,6,3,3,3,3,3,3,3,3,3,3,3,3,3,1,3,3,3,3,3,3,3,3,3,3,1,1,1,1,1,1,1,1,1,5,5
5,5,5,6,3,3,3,3,3,3,3,3,3,3,3,3,3,3,3,3,3,3,3,3,3,1,3,3,3,1,3,3,3,3,3,3,3,3,3,3,3,3,3,3,3,1,1,1,1,5,5
5,5,5,6,3,3,3,3,3,3,3,3,3,3,3,3,3,3,3,3,3,3,3,1,1,1,1,1,1,1,3,3,3,3,3,3,3,3,3,3,3,3,3,3,3,1,1,1,1,5,5
5,5,5,6,3,3,3,3,3,3,3,3,3,3,3,3,3,3,3,3,3,3,3,1,1,1,1,1,1,1,3,3,3,3,3,3,3,3,3,3,3,3,3,3,3,1,1,1,1,5,5
5,5,5,6,3,3,3,3,3,3,3,3,3,3,3,3,3,3,3,3,3,3,3,1,1,1,1,1,1,1,3,3,3,3,3,3,3,3,3,3,3,3,3,3,3,1,1,1,1,5,5
5,5,5,6,3,3,3,3,3,3,3,3,3,3,3,6,6,6,6,1,3,3,1,1,1,1,1,1,1,1,3,3,3,3,3,3,3,3,3,3,3,3,3,3,3,1,1,1,1,5,5
5,5,5,6,6,6,6,6,6,6,6,6,6,6,6,6,1,1,1,5,3,3,5,1,1,1,1,1,1,1,1,1,1,1,1,1,1,1,1,1,1,1,1,1,1,1,1,1,1,5,5
5,5,5,5,5,5,5,9,9,9,9,5,5,5,5,5,5,5,5,9,9,9,9,5,5,5,5,5,5,5,5,5,5,5,5,5,5,5,5,5,5,5,5,5,5,5,5,5,5,5,5
5,5,5,5,5,5,5,9,9,9,9,5,5,5,5,5,5,5,5,9,9,9,9,5,5,5,5,5,5,5,5,5,5,5,5,5,5,5,5,5,5,5,5,5,5,5,5,5,5,5,5
5,5,5,5,5,5,5,9,9,9,9,9,9,9,9,9,9,9,9,9,9,9,9,5,5,5,5,5,5,5,5,5,5,5,5,5,5,5,5,5,5,5,5,5,5,5,5,5,5,5,5
5,5,5,5,5,5,5,9,9,9,9,9,9,9,9,9,9,9,9,9,9,9,9,5,5,5,5,5,5,5,5,5,5,5,5,5,5,5,5,5,5,5,5,5,5,5,5,5,5,5,5
5,5,5,5,5,5,5,9,9,9,9,9,9,9,9,9,9,9,9,9,9,9,9,5,5,5,5,5,5,5,5,5,5,5,5,5,5,5,5,5,5,5,5,5,5,5,5,5,5,5,5
5,5,5,5,5,5,5,9,9,9,9,5,5,5,5,5,5,5,5,9,9,9,9,5,5,5,5,5,5,5,5,5,5,5,5,5,5,5,5,5,5,5,5,5,5,5,5,5,5,5,5
:endlayer
layer: 3
0,0,0,0,10,0,10,0,0,10,10,0,10,0,10,10,10,0,0,10,10,10,0,10,10,10,10,0,0,0,0,0,10,10,0,0,0,10,10,10,0,0,0,0,0,0,0,0,10,0,10
10,0,10,10,10,10,0,0,10,10,10,10,10,10,0,10,0,0,10,10,10,0,10,10,10,10,10,0,0,0,0,0,10,10,0,0,0,10,10,10,0,0,0,0,0,0,0,0,0,10,10
10,0,0,6,6,6,6,6,6,6,6,6,6,6,6,6,6,6,6,6,6,6,6,6,6,6,6,11,12,6,6,6,6,6,6,6,6,6,6,6,6,6,6,6,6,6,6,6,6,10,10
10,0,10,6,13,0,0,14,15,16,0,17,6,18,18,18,18,18,18,18,18,6,0,0,0,0,0,0,0,0,0,0,0,0,0,0,0,0,7,0,0,0,0,0,0,7,0,0,6,10,10
10,10,0,6,19,0,0,0,0,0,0,20,6,18,18,18,18,18,18,18,18,6,21,0,0,0,0,0,0,0,0,0,0,0,0,0,0,0,6,0,0,0,0,0,0,6,0,0,6,0,10
10,0,10,6,0,0,0,0,0,0,0,0,6,18,18,18,18,18,18,18,18,6,0,0,0,0,0,0,0,0,0,0,0,0,0,0,0,0,6,0,0,0,0,0,0,6,0,0,6,0,0
0,0,0,6,22,0,0,0,0,0,0,0,6,18,18,18,18,18,18,18,18,6,0,0,0,0,0,0,0,0,0,0,0,0,0,0,0,0,6,0,0,0,0,0,23,6,0,0,6,0,0
10,0,0,6,24,24,24,24,0,0,24,24,6,18,18,18,18,18,18,18,18,6,6,6,6,6,6,6,6,6,6,6,6,0,0,0,0,0,6,0,0,0,0,0,6,6,0,0,6,10,0
10,10,10,6,0,0,0,24,0,0,0,0,6,18,18,18,18,18,18,18,18,18,18,6,6,6,6,6,6,6,6,6,6,0,0,0,0,0,7,6,6,25,6,6,6,7,0,0,6,10,10
10,10,10,6,0,0,0,26,0,0,0,0,6,18,18,18,18,18,18,18,18,18,18,6,6,6,6,6,6,6,6,6,6,0,0,0,0,0,6,0,0,0,0,0,0,6,0,0,6,10,10
10,10,10,6,24,24,24,24,0,0,24,24,6,18,18,18,18,18,18,18,18,18,18,6,6,6,6,6,6,6,6,6,6,0,0,0,0,0,6,0,0,0,0,0,0,6,0,0,6,10,0
10,10,10,6,0,0,0,24,0,0,0,0,6,18,18,18,18,18,18,18,18,18,18,6,6,6,6,6,6,6,6,6,6,0,0,0,0,0,27,0,0,0,0,0,0,6,0,0,6,0,0
10,10,10,6,0,0,0,26,0,0,0,0,6,6,6,6,6,6,6,6,6,6,6,6,6,6,6,6,6,6,6,6,6,0,0,0,0,0,6,0,0,0,0,0,0,6,0,0,6,10,0
10,10,10,6,24,24,24,24,0,0,24,24,6,0,0,0,0,0,0,0,0,28,0,0,0,0,28,0,0,0,0,0,0,0,0,0,0,0,7,6,6,6,6,6,6,7,0,0,6,0,10
10,10,10,6,0,0,0,24,0,0,0,0,6,0,0,0,0,0,0,0,0,0,0,0,0,0,0,0,0,0,0,0,0,0,0,0,0,0,0,0,0,0,0,0,0,0,0,6,6,10,10
0,10,0,6,0,0,0,26,0,0,0,0,6,0,0,0,0,0,0,0,0,0,0,0,0,0,0,0,0,0,0,0,0,0,0,0,0,0,0,0,0,0,0,0,0,0,0,6,10,10,10
0,10,10,6,24,24,24,24,0,0,24,24,6,0,0,0,0,0,0,0,0,0,0,0,0,0,0,0,0,0,0,0,0,0,0,0,0,0,0,0,0,0,0,0,0,0,0,29,0,0,0
10,10,10,6,0,0,0,26,0,0,0,0,6,0,0,0,0,0,0,0,0,0,0,0,0,0,0,0,0,0,0,0,0,0,0,0,0,0,0,0,0,0,0,0,0,0,0,30,0,0,0
0,10,10,6,0,0,0,24,0,0,0,0,6,0,0,0,0,0,0,0,0,0,0,0,0,0,0,0,0,0,0,0,0,0,0,0,0,0,0,0,20,23,23,23,23,23,23,6,0,0,0
0,10,10,6,6,6,6,6,0,0,6,6,6,6,6,6,0,0,6,6,6,6,0,0,0,0,0,0,6,23,23,23,23,23,23,23,23,6,0,0,6,6,6,6,6,6,6,6,6,0,0
10,0,0,6,31,32,0,0,0,0,0,0,0,0,0,6,0,0,6,0,0,6,0,0,0,0,0,6,6,6,6,6,6,6,6,6,6,6,0,0,6,3,3,3,3,6,3,3,6,0,0
0,10,0,6,33,33,0,0,0,0,0,0,0,0,0,34,0,0,6,0,0,6,0,0,0,0,0,0,6,0,0,35,35,35,35,0,0,6,0,0,6,3,3,3,3,6,3,3,6,0,0
10,10,0,6,31,0,0,0,0,0,0,0,0,0,0,6,0,0,6,6,6,6,0,0,0,0,0,0,27,0,0,0,0,0,0,0,0,6,0,0,6,3,3,3,3,6,3,3,6,10,0
0,10,10,6,0,0,0,0,0,0,0,0,0,0,0,6,0,0,0,0,0,0,0,0,0,0,0,0,6,0,0,0,0,0,24,36,0,6,23,23,6,3,3,3,3,6,3,3,6,10,0
10,10,0,6,0,0,0,0,0,0,0,0,0,0,0,6,0,0,0,0,0,0,0,0,0,0,0,6,6,37,0,0,37,24,0,36,6,6,6,6,3,3,3,3,3,6,3,3,6,10,10
10,10,10,6,0,0,0,0,0,0,0,0,0,0,0,6,0,0,0,0,0,0,0,0,0,0,0,0,6,6,0,0,0,38,0,0,39,3,3,3,6,3,3,3,3,6,3,3,6,10,10
0,0,10,6,0,0,0,0,0,0,0,0,0,0,0,6,0,0,0,0,0,0,0,0,0,0,0,0,0,6,38,0,0,0,0,0,39,3,3,3,3,3,3,3,3,6,3,3,6,0,0
10,10,0,6,0,0,0,0,0,0,0,0,0,6,6,6,6,6,6,0,0,0,0,0,0,0,0,0,0,6,18,0,0,0,0,0,39,3,3,3,6,3,3,6,6,6,3,3,6,0,0
10,10,0,6,40,0,0,0,0,0,0,0,0,6,0,41,0,0,42,0,0,0,0,0,0,23,0,0,0,6,18,37,24,36,0,0,0,18,0,0,6,3,3,3,3,3,3,3,6,0,10
10,10,10,6,0,0,0,0,0,0,0,0,0,0,0,0,0,0,43,0,0,0,0,6,6,6,6,6,6,6,18,37,0,36,0,0,0,18,0,0,20,3,3,3,3,3,3,3,6,10,10
10,10,10,6,0,0,0,0,0,0,0,0,0,0,0,0,23,23,6,0,0,0,0,6,6,6,6,6,6,6,37,0,0,0,0,0,0,18,0,0,6,3,3,3,3,3,3,3,6,10,10
0,10,10,6,0,0,0,0,0,0,0,0,0,6,16,6,44,44,6,0,0,0,0,6,6,6,6,6,6,6,37,0,24,0,0,0,0,18,0,0,6,3,3,3,3,3,3,3,6,10,10
10,10,10,6,0,0,0,0,0,0,0,0,0,6,6,6,6,6,6,6,45,46,6,6,6,6,6,6,6,6,18,38,38,0,0,0,0,47,0,0,6,3,3,3,3,3,3,3,6,0,10
0,10,10,6,6,6,6,0,0,0,0,0,6,6,6,6,6,6,6,0,0,0,0,6,6,6,6,6,6,6,6,6,6,6,6,6,6,6,6,6,6,6,6,6,6,6,6,6,6,0,0
10,10,10,24,0,0,0,0,0,0,0,0,0,0,10,10,0,10,0,0,0,0,0,24,0,0,0,0,0,0,0,0,0,0,0,0,0,0,0,0,0,0,0,0,0,0,0,0,24,0,0
0,0,10,24,10,0,0,0,0,0,0,0,10,10,10,10,0,10,0,0,0,0,0,24,0,0,0,0,0,0,0,0,0,0,10,0,10,0,0,0,0,0,10,0,0,0,0,0,24,0,0
10,10,0,24,10,0,0,0,0,0,0,0,0,0,0,0,0,0,0,0,0,0,0,48,10,0,0,0,0,10,0,0,0,0,0,0,0,0,0,0,0,0,0,10,0,0,0,0,26,10,10
10,0,10,24,0,0,0,0,0,0,0,0,0,0,0,0,0,0,0,0,0,0,0,24,0,10,0,10,0,0,0,10,0,0,0,0,0,0,0,0,0,10,0,0,0,0,10,0,24,0,10
10,10,10,24,24,24,24,0,0,0,0,0,0,0,0,0,0,0,0,0,0,0,0,24,24,24,24,24,24,24,24,24,24,24,24,24,24,24,24,24,24,24,24,24,24,24,24,24,24,10,10
0,10,10,10,10,0,0,0,0,0,0,0,0,0,10,0,0,0,0,0,0,0,0,10,10,10,10,0,0,10,10,10,10,10,0,0,0,0,0,10,10,10,10,10,0,10,0,10,0,10,0
:endlayer
layer: 4
0,0,0,0,0,0,0,0,0,0,0,0,0,0,0,0,0,0,0,0,0,0,0,0,0,0,0,0,0,0,0,0,0,0,0,0,0,0,0,0,0,0,0,0,0,0,0,0,0,0,0
0,0,0,0,0,0,0,0,0,0,0,0,0,0,0,0,0,0,0,0,0,0,0,0,0,0,0,0,0,0,0,0,0,0,0,0,0,0,0,0,0,0,0,0,0,0,0,0,0,0,0
0,0,0,7,6,6,6,6,6,6,6,6,7,6,6,6,6,6,6,6,6,7,6,6,6,6,6,49,50,6,6,6,6,6,6,6,6,6,6,6,6,6,6,6,6,6,6,6,6,0,0
0,0,0,6,0,0,0,0,15,0,0,0,6,0,0,18,51,52,53,16,54,6,0,0,0,0,0,0,0,0,0,0,0,0,0,0,0,0,7,0,0,0,0,0,0,7,0,0,6,0,0
0,0,0,6,0,0,0,0,0,0,0,0,27,0,0,34,0,0,0,0,0,34,0,0,0,0,0,0,0,0,0,0,0,0,0,0,0,0,6,0,0,0,0,0,0,6,55,0,6,0,0
0,0,0,6,0,0,0,0,0,0,0,0,6,18,18,18,0,0,0,0,0,6,0,0,0,0,0,0,0,0,0,0,0,0,0,0,0,0,6,0,0,0,0,0,0,6,0,0,6,0,0
0,0,0,6,0,0,0,0,0,0,0,0,6,18,18,18,56,57,57,57,57,6,0,0,0,0,0,0,0,0,0,0,0,0,0,0,0,0,58,0,0,0,0,0,0,58,0,0,6,0,0
0,0,0,6,0,0,24,24,0,0,24,0,6,0,35,18,0,0,0,0,0,6,6,6,6,6,6,6,6,6,6,6,6,0,0,0,0,0,6,0,0,0,0,0,23,6,0,0,6,0,0
0,0,0,6,0,0,0,24,0,0,0,0,6,0,0,18,0,0,0,0,0,0,59,0,6,0,0,0,0,60,61,62,6,0,0,0,0,0,7,6,6,63,6,6,6,7,0,0,6,0,0
0,0,0,6,0,0,0,0,0,0,0,0,6,0,0,18,56,57,57,0,0,0,57,0,6,0,0,0,0,0,0,64,6,0,0,0,0,0,6,0,0,0,0,0,0,6,0,0,6,0,0
0,0,0,6,0,0,24,24,0,0,24,0,6,0,0,34,0,0,57,0,0,0,57,0,6,0,0,0,0,0,0,64,6,0,0,0,0,0,6,0,0,0,0,0,0,65,0,0,6,0,0
0,0,0,6,0,0,0,24,0,0,0,0,6,0,0,18,66,0,57,0,0,0,57,67,6,0,0,0,0,68,61,62,6,0,0,0,0,0,69,0,0,0,0,0,0,6,0,0,6,0,0
0,0,0,6,0,0,0,0,0,0,0,0,6,6,6,6,6,6,6,6,6,25,6,6,6,6,25,6,6,6,6,6,6,0,0,0,0,0,6,0,0,0,0,0,0,6,0,0,6,0,0
0,0,0,6,0,0,24,24,0,0,24,0,6,0,0,0,0,0,0,0,0,0,0,0,0,0,0,0,0,0,0,0,0,0,0,0,0,0,7,6,6,65,6,6,6,7,0,0,6,0,0
0,0,0,6,0,0,0,24,0,0,0,0,6,0,0,0,0,0,0,0,0,0,0,0,0,0,0,0,0,0,0,0,0,0,0,0,0,0,0,0,0,0,0,0,0,0,0,6,6,0,0
0,0,0,6,0,0,0,0,0,0,0,0,6,0,0,0,0,0,0,0,0,0,0,0,0,0,0,0,0,0,0,0,0,0,0,0,0,0,0,0,0,0,0,0,0,0,0,6,0,0,0
0,0,0,6,0,0,0,24,0,0,24,0,6,0,0,0,0,0,0,0,0,0,0,0,0,0,0,0,0,0,0,0,0,0,0,0,0,0,0,0,0,0,0,0,0,0,0,70,0,0,0
0,0,0,6,0,0,0,0,0,0,0,0,6,0,0,0,0,0,0,0,0,0,0,0,0,0,0,0,0,0,0,0,0,0,0,0,0,0,0,0,0,0,0,0,0,0,0,71,0,0,0
0,0,0,6,0,0,0,24,0,0,0,0,6,0,0,0,0,0,0,0,0,0,0,0,0,0,0,0,0,0,0,0,0,0,0,0,0,0,0,0,0,0,0,0,0,0,0,6,0,0,0
0,0,0,7,6,6,6,6,0,0,6,6,6,6,6,7,0,0,24,0,0,24,0,0,0,0,0,0,6,0,0,0,0,0,0,0,0,6,0,0,7,6,6,6,6,7,72,6,6,0,0
0,0,0,6,32,32,0,0,0,0,0,0,0,0,0,6,0,0,0,0,0,0,0,0,0,0,0,6,6,6,6,6,6,6,6,6,6,6,0,0,6,0,0,0,0,6,0,0,6,0,0
0,0,0,6,33,0,0,0,0,0,0,0,0,0,0,73,0,0,0,0,0,0,0,0,0,0,0,0,6,0,0,0,0,0,0,0,0,6,0,0,6,0,0,0,0,6,0,0,6,0,0
0,0,0,6,0,0,0,0,0,0,0,0,0,0,0,6,0,0,24,0,0,24,0,0,0,0,0,0,74,0,0,0,0,0,0,0,0,6,0,0,6,0,0,0,0,6,0,0,6,0,0
0,0,0,6,0,0,0,0,0,0,0,0,0,0,0,75,0,0,0,0,0,0,0,0,0,0,0,0,6,0,0,0,0,0,76,0,0,6,0,0,6,0,0,0,0,6,0,0,6,0,0
0,0,0,6,0,0,0,0,0,0,0,0,0,0,0,6,0,0,0,0,0,0,0,0,0,0,0,6,6,0,0,0,0,76,0,0,6,6,77,78,6,0,0,0,0,6,0,0,6,0,0
0,0,0,6,0,0,0,0,0,0,0,0,0,0,0,7,0,0,0,0,0,0,0,0,0,0,0,0,6,6,0,0,0,0,0,0,0,0,0,0,6,0,0,0,64,6,0,0,6,0,0
0,0,0,7,0,0,0,0,0,0,0,0,0,0,0,6,0,0,0,0,0,0,0,0,0,0,0,0,0,7,0,0,0,0,0,0,0,0,0,0,27,0,0,36,18,6,0,0,6,0,0
0,0,0,6,0,0,0,0,0,0,0,0,0,6,6,6,6,6,6,0,0,0,0,0,0,0,0,0,0,6,38,0,0,0,0,0,0,18,18,18,6,79,6,6,6,6,0,0,6,0,0
0,0,0,6,40,0,0,0,0,0,0,0,0,6,0,0,0,0,80,0,0,0,0,0,0,0,0,0,0,6,18,0,76,0,0,0,0,0,0,0,6,0,0,0,0,6,0,0,6,0,0
0,0,0,6,0,0,0,0,0,0,0,0,0,0,0,0,0,0,81,0,0,0,0,7,18,78,18,18,7,6,18,0,0,0,0,0,0,0,0,0,0,27,0,0,0,27,0,0,6,0,0
0,0,0,6,0,0,0,0,0,0,0,0,0,0,0,0,0,0,6,0,0,0,0,18,0,0,0,0,0,6,0,0,0,0,0,0,0,0,0,0,6,0,0,0,0,6,0,0,6,0,0
0,0,0,6,0,0,0,0,0,0,0,0,0,6,0,6,0,0,6,0,0,0,0,18,0,0,0,0,0,6,0,0,76,0,0,0,0,0,0,0,6,0,0,0,0,6,0,0,6,0,0
0,0,0,6,0,0,0,0,0,0,0,0,82,6,6,6,6,6,6,6,83,84,6,18,24,0,0,0,0,6,18,0,0,0,0,0,0,0,0,0,6,85,86,18,16,6,0,0,6,0,0
0,0,0,7,6,6,7,0,0,0,0,0,7,6,6,7,6,6,7,0,0,0,0,7,6,6,6,6,6,7,6,6,6,6,6,6,6,6,6,6,7,6,6,6,6,7,6,6,6,0,0
0,0,0,0,0,0,0,0,0,0,0,0,87,0,0,0,0,0,0,0,0,0,0,0,0,0,0,0,0,0,0,0,0,0,0,0,0,0,0,0,0,0,0,0,0,0,0,0,0,0,0
0,0,0,0,0,0,0,0,0,0,0,0,0,0,0,0,0,0,0,0,0,0,0,0,0,0,0,0,0,0,0,0,0,0,0,0,0,0,0,0,0,0,0,0,0,0,0,0,0,0,0
0,0,0,0,0,0,0,0,0,0,0,0,0,0,0,0,0,0,0,0,0,0,0,0,0,0,0,0,0,0,0,0,0,0,0,0,0,0,0,0,0,0,0,0,0,0,0,0,0,0,0
0,0,0,0,0,0,0,0,0,0,0,0,0,0,0,0,0,0,0,0,0,0,0,0,0,0,0,0,0,0,0,0,0,0,0,0,0,0,0,0,0,0,0,0,0,0,0,0,0,0,0
0,0,0,88,0,0,88,0,0,0,0,0,0,0,0,0,0,0,0,0,0,0,0,88,0,0,0,0,0,0,0,0,0,0,0,0,0,0,0,0,0,0,0,0,0,0,0,0,88,0,0
0,0,0,0,0,0,0,0,0,0,0,0,0,0,0,0,0,0,0,0,0,0,0,0,0,0,0,0,0,0,0,0,0,0,0,0,0,0,0,0,0,0,0,0,0,0,0,0,0,0,0
:endlayer
layer: 5
0,0,0,0,0,0,0,0,0,0,0,0,0,0,0,0,0,0,0,0,0,0,0,0,0,0,0,0,0,0,0,0,0,0,0,0,0,0,0,0,0,0,0,0,0,0,0,0,0,0,0
0,0,0,0,0,0,0,0,0,0,0,0,0,0,0,89,0,0,0,0,0,0,0,0,0,0,89,0,0,89,0,0,0,0,0,0,0,0,0,0,0,0,0,0,0,0,0,0,0,0,0
0,0,0,7,6,6,6,6,6,6,6,6,7,6,6,6,6,6,6,6,6,7,6,24,24,24,6,90,91,6,24,24,24,24,24,24,24,38,38,38,38,38,38,38,38,38,38,0,88,0,0
0,0,0,6,55,0,0,0,15,0,0,92,6,0,93,18,0,0,0,0,0,6,55,0,0,0,93,0,0,93,0,0,0,0,0,0,0,0,7,93,0,0,0,0,92,7,0,0,0,0,0
0,0,0,6,0,0,0,0,0,0,0,0,94,0,0,95,0,0,0,0,0,96,0,0,0,0,0,0,0,0,0,0,0,0,0,0,0,0,6,0,0,0,0,0,0,6,0,0,0,0,0
0,0,0,65,0,0,0,0,0,0,0,0,6,18,18,18,0,0,0,0,0,6,0,0,0,0,0,0,0,0,0,0,0,0,0,0,0,0,6,0,0,0,0,0,0,6,0,0,0,0,0
0,0,0,6,0,0,0,0,0,0,0,0,6,18,35,18,0,0,0,0,0,6,0,0,89,0,0,0,0,0,0,0,0,0,0,0,0,0,6,0,0,0,0,0,0,6,0,0,0,0,0
0,0,0,6,24,24,24,24,0,0,24,24,6,0,0,18,0,0,0,0,0,18,6,6,6,18,65,65,18,65,65,18,6,0,0,0,0,0,6,0,89,0,0,89,0,6,0,0,0,0,0
0,0,0,65,0,0,0,24,0,0,0,92,6,0,0,18,0,0,0,0,0,0,0,0,18,0,0,0,0,0,0,0,18,0,0,0,0,92,7,6,6,6,6,6,23,7,55,0,0,0,0
0,0,0,6,55,0,0,0,0,0,0,0,6,0,0,18,0,0,0,0,0,0,0,0,18,0,0,0,0,0,0,0,65,0,0,0,0,0,6,55,0,0,0,0,92,6,0,0,0,0,0
0,0,0,6,24,24,24,24,0,0,24,24,6,0,0,97,0,0,0,0,0,0,0,0,18,0,0,0,0,0,0,0,65,0,0,0,0,0,6,0,0,0,0,0,0,6,0,0,0,0,0
0,0,0,65,0,0,0,24,0,0,0,92,6,0,89,18,0,0,0,0,0,0,0,0,18,0,0,0,0,0,0,0,18,0,0,0,0,0,6,0,0,0,0,0,0,6,0,0,0,0,0
0,0,0,6,55,0,0,0,0,0,0,0,6,6,6,6,18,7,65,7,18,98,18,6,6,18,99,18,65,65,65,18,6,0,0,0,0,0,6,89,0,0,0,0,92,6,0,0,0,0,0
0,0,0,6,24,24,24,24,0,0,24,24,6,0,93,0,0,0,0,0,0,0,93,0,0,0,0,0,0,0,0,0,0,0,0,0,0,92,7,6,6,6,6,6,6,7,55,0,0,0,0
0,0,0,65,0,0,0,24,0,0,0,92,6,0,0,0,0,0,0,0,0,0,0,0,0,0,0,0,0,0,0,0,0,0,0,0,0,0,93,0,0,0,0,0,0,93,0,0,88,0,0
0,0,0,6,55,0,0,0,0,0,0,0,65,0,0,0,0,0,0,0,0,0,0,0,0,0,0,0,0,0,0,0,0,0,0,0,0,0,0,0,0,0,0,0,0,0,0,6,55,0,0
0,0,0,6,24,24,24,24,0,0,24,24,6,0,0,0,0,0,0,0,0,0,0,0,0,0,0,0,0,0,0,0,0,0,0,0,0,0,0,0,0,0,0,0,0,0,0,91,0,0,0
0,0,0,65,0,0,0,0,0,0,0,0,6,55,0,0,0,0,0,0,0,0,0,0,0,0,0,0,0,0,0,0,0,0,0,0,0,0,0,0,0,0,0,0,0,0,0,100,0,0,0
0,0,0,6,55,0,0,24,0,0,0,0,6,0,0,89,0,0,0,0,0,0,0,0,0,0,0,0,0,0,0,0,0,0,0,0,0,0,0,0,0,0,0,0,0,0,0,6,55,0,0
0,0,0,7,6,6,6,6,0,0,6,6,6,6,6,7,55,0,24,0,0,24,0,0,0,0,0,0,6,0,0,0,0,0,0,0,0,6,0,0,7,18,65,65,18,7,0,0,0,0,0
0,0,0,6,33,33,93,0,0,0,0,0,0,0,0,6,0,0,0,0,0,0,0,0,0,0,0,6,6,6,65,6,6,6,65,6,6,6,0,0,18,0,0,0,0,18,0,0,0,0,0
0,0,0,6,0,0,0,0,0,0,0,0,0,0,92,6,0,0,0,0,0,0,0,0,0,0,0,92,6,0,0,0,0,0,0,0,0,6,0,0,65,0,0,0,0,65,0,0,0,0,0
0,0,0,6,0,0,0,0,0,0,0,0,0,0,0,6,0,0,24,0,0,24,0,0,0,0,0,0,6,0,0,0,0,0,0,0,0,65,0,0,65,0,0,0,0,65,0,0,0,0,0
0,0,0,6,0,0,0,0,0,0,0,0,0,0,0,6,0,0,0,0,0,0,0,0,0,0,0,92,6,0,0,0,0,0,0,0,0,6,0,0,18,0,0,0,0,18,0,0,88,0,0
0,0,0,6,0,0,0,0,0,0,0,0,0,0,0,6,0,0,0,0,0,0,0,0,0,0,0,6,6,0,0,0,0,0,0,0,6,6,101,102,6,0,0,0,0,18,0,0,0,0,0
0,0,0,6,0,0,0,0,0,0,0,0,0,0,92,7,55,0,0,0,0,0,0,0,0,0,0,0,6,6,0,0,0,0,0,0,0,0,0,0,6,0,0,0,64,18,0,0,0,0,0
0,0,0,7,0,0,0,0,0,0,0,0,0,0,0,6,0,0,89,0,0,0,0,0,0,0,0,0,0,7,0,0,0,0,0,0,0,0,0,0,103,0,0,0,36,18,0,0,0,0,0
0,0,0,6,0,0,0,0,0,0,0,0,0,6,6,6,75,75,6,55,0,0,0,0,0,0,0,0,0,6,0,0,0,0,0,0,0,18,24,24,6,104,6,6,6,6,0,0,0,0,0
0,0,0,6,40,0,0,0,0,0,0,0,92,6,55,0,0,0,75,0,0,0,0,89,0,0,89,0,0,6,38,0,0,0,0,0,0,0,0,0,6,0,0,0,0,6,0,0,88,0,0
0,0,0,6,0,0,0,0,0,0,0,0,0,0,0,0,0,0,75,0,0,0,0,7,18,105,18,18,7,6,18,0,0,0,0,0,0,0,0,0,0,106,0,0,0,107,0,0,0,0,0
0,0,0,6,0,0,0,0,0,0,0,0,0,0,0,75,75,75,6,0,0,0,0,18,0,0,0,0,0,6,18,0,0,0,0,0,0,0,0,0,6,0,0,0,0,6,0,0,0,0,0
0,0,0,6,0,0,0,0,0,0,0,0,92,6,89,6,0,0,6,89,0,0,89,65,0,0,0,0,0,6,18,0,0,0,0,0,0,0,0,92,6,0,0,0,0,65,0,0,0,0,0
0,0,0,6,0,89,0,0,0,0,0,0,0,6,6,6,6,6,6,6,91,91,6,18,76,0,0,0,0,6,18,0,0,0,0,0,0,0,0,0,6,0,0,0,0,6,0,0,0,0,0
0,0,0,7,6,6,7,0,0,0,0,0,7,6,6,7,6,6,7,93,0,0,93,7,6,6,6,6,6,7,6,6,6,65,6,65,6,65,6,6,7,6,6,65,6,7,0,0,88,0,0
0,0,0,0,0,0,0,0,0,0,0,0,0,0,0,0,0,0,0,0,0,0,0,0,0,0,0,0,0,0,0,0,0,0,0,0,0,0,0,0,0,0,0,0,0,0,0,0,0,0,0
0,0,0,0,0,0,0,0,0,0,0,0,0,0,0,0,0,0,0,0,0,0,0,0,0,0,0,0,0,0,0,0,0,0,0,0,0,0,0,0,0,0,0,0,0,0,0,0,0,0,0
0,0,0,0,0,0,0,0,0,0,0,0,0,0,0,0,0,0,0,0,0,0,0,0,0,0,0,0,0,0,0,0,0,0,0,0,0,0,0,0,0,0,0,0,0,0,0,0,0,0,0
0,0,0,0,0,0,0,0,0,0,0,0,0,0,0,0,0,0,0,0,0,0,0,0,0,0,0,0,0,0,0,0,0,0,0,0,0,0,0,0,0,0,0,0,0,0,0,0,0,0,0
0,0,0,0,0,0,0,0,0,0,0,0,0,0,0,0,0,0,0,0,0,0,0,0,0,0,0,0,0,0,0,0,0,0,0,0,0,0,0,0,0,0,0,0,0,0,0,0,0,0,0
0,0,0,0,0,0,0,0,0,0,0,0,0,0,0,0,0,0,0,0,0,0,0,0,0,0,0,0,0,0,0,0,0,0,0,0,0,0,0,0,0,0,0,0,0,0,0,0,0,0,0
:endlayer
layer: 6
0,0,0,0,0,0,0,0,0,0,0,0,0,0,0,0,0,0,0,0,0,0,0,0,0,0,0,0,0,0,0,0,0,0,0,0,0,0,0,0,0,0,0,0,0,0,0,0,0,0,0
0,0,0,89,0,0,0,0,0,0,0,0,0,0,0,0,0,0,0,0,0,0,37,0,0,0,38,38,38,38,0,0,0,0,0,0,0,0,0,0,0,0,0,0,0,0,0,0,0,0,0
0,0,92,7,6,6,6,6,6,6,6,6,7,7,7,7,7,7,7,7,7,7,37,0,0,0,6,6,6,6,0,0,0,0,0,0,0,0,0,0,0,0,0,0,0,0,0,0,0,0,0
0,0,0,6,18,18,18,18,15,18,18,18,6,18,18,18,55,0,0,0,92,6,37,0,0,0,35,35,35,35,0,0,0,0,0,0,0,38,38,38,38,38,38,38,38,38,38,0,0,0,0
0,0,0,6,18,18,18,18,18,18,18,18,6,18,18,18,0,0,0,0,0,6,37,0,0,0,0,0,0,0,0,0,0,0,0,0,0,0,7,3,3,3,3,3,3,7,0,0,0,0,0
0,0,0,6,18,18,18,18,18,18,18,18,6,18,35,18,0,0,0,0,0,6,37,0,0,0,0,0,0,0,0,0,0,0,0,0,0,0,7,3,3,3,3,3,0,7,0,0,0,0,0
0,0,0,6,18,18,18,18,0,0,18,18,6,18,0,18,0,0,0,0,0,6,37,0,0,0,0,0,0,0,0,0,0,0,0,0,0,0,7,3,3,3,3,3,0,7,0,0,0,0,0
0,0,0,6,18,18,18,18,0,0,18,18,6,0,0,18,0,0,0,0,0,18,6,6,6,18,18,18,18,18,18,18,6,0,0,0,0,0,7,3,3,3,3,3,0,7,0,0,0,0,0
0,0,0,6,18,18,18,18,0,0,18,18,6,0,0,18,0,0,0,0,0,0,0,0,18,0,0,0,0,0,0,0,18,0,0,0,0,0,7,3,3,3,3,3,0,7,0,0,0,0,0
0,0,0,6,18,18,18,18,0,0,18,18,6,0,0,18,0,0,0,0,0,0,0,0,18,0,0,0,0,0,0,0,65,0,0,0,0,0,7,3,3,3,3,3,23,7,0,0,0,0,0
0,0,92,6,18,18,18,18,0,0,18,18,6,0,0,18,0,0,0,0,0,0,0,0,18,0,0,0,0,0,0,0,65,0,0,0,0,0,7,3,3,3,3,3,3,7,0,0,0,0,0
0,0,0,6,18,18,18,18,0,0,18,18,6,0,0,18,89,0,0,0,0,89,0,0,18,0,0,0,0,0,0,0,18,0,0,0,0,0,7,3,3,3,3,3,3,7,0,0,0,0,0
0,0,0,6,18,18,18,18,0,0,18,18,6,6,6,6,18,18,18,18,18,18,18,6,6,18,18,18,65,65,65,18,6,55,0,0,0,0,7,3,3,3,3,3,3,7,0,0,0,0,0
0,0,0,6,18,18,18,18,0,0,18,18,6,35,35,35,35,35,35,35,35,35,35,35,0,0,93,0,0,0,0,0,93,0,0,0,0,0,7,7,7,7,7,7,7,7,0,0,0,0,0
0,0,0,6,18,18,18,18,0,0,18,18,6,0,0,0,0,0,0,0,0,0,0,0,0,0,0,0,0,0,0,0,0,0,0,0,0,108,108,108,108,108,108,108,108,108,108,0,0,0,0
0,0,0,6,18,18,18,18,0,0,18,18,6,0,0,0,0,0,0,0,0,0,0,0,0,0,0,0,0,0,0,0,0,0,0,0,0,0,0,0,0,0,0,0,0,0,36,6,37,0,0
0,0,92,6,18,18,18,18,0,0,18,18,6,0,0,0,0,0,0,0,0,0,0,0,0,0,0,0,0,0,0,0,0,0,0,0,0,0,0,0,0,0,0,0,0,0,36,6,37,0,0
0,0,0,6,18,18,18,18,18,18,18,18,6,0,0,0,0,0,0,0,0,0,0,0,0,0,0,0,0,0,0,0,0,0,0,0,0,0,0,0,0,0,0,0,0,0,36,6,37,0,0
0,0,0,6,18,18,18,18,18,18,18,18,6,0,0,0,0,0,89,0,0,89,0,0,0,0,0,0,0,0,0,0,0,0,0,0,0,0,0,0,89,0,0,0,0,0,36,6,37,0,0
0,0,0,7,6,6,6,6,6,6,6,6,6,6,6,7,0,0,6,6,6,6,55,0,0,0,0,0,6,0,0,0,89,0,0,0,89,6,0,92,7,18,65,65,18,7,0,0,0,0,0
0,0,0,6,0,33,0,0,0,0,0,0,0,0,0,6,0,0,6,6,6,6,0,0,0,0,0,6,6,6,65,6,6,6,65,6,6,6,0,0,18,93,0,0,0,18,0,0,0,0,0
0,0,0,6,0,0,0,0,0,0,0,0,0,0,0,6,0,0,6,6,6,6,0,0,0,0,0,0,6,0,0,0,0,0,0,93,0,6,0,0,65,0,0,0,0,18,0,0,0,0,0
0,0,0,6,0,0,0,0,0,0,0,0,0,0,0,6,0,0,6,6,6,6,55,0,0,0,0,0,6,55,0,0,0,0,0,0,0,65,0,0,65,0,0,0,0,18,0,0,0,0,0
0,0,0,6,0,0,0,0,0,0,0,0,0,0,0,6,0,0,0,0,0,0,0,0,0,0,0,0,6,0,0,0,0,0,0,0,0,6,89,89,18,0,0,0,0,18,0,0,0,0,0
0,0,0,6,0,0,0,0,0,0,0,0,0,0,0,6,0,0,0,0,0,0,0,0,0,0,0,6,6,89,0,0,0,0,0,92,6,6,6,6,6,0,0,0,0,18,0,0,0,0,0
0,0,0,6,0,0,0,0,0,0,0,0,0,0,0,7,0,0,0,0,0,0,0,0,0,0,0,0,6,6,55,0,0,0,0,0,93,0,93,0,6,0,0,0,35,18,0,0,0,0,0
0,0,0,7,0,0,0,0,0,0,0,0,0,0,0,6,0,0,0,0,0,0,0,0,0,0,0,0,0,7,0,0,0,0,0,0,0,0,0,92,6,0,0,0,0,18,0,0,0,0,0
0,0,0,6,0,0,0,0,0,0,0,0,0,6,6,6,6,6,6,0,0,0,0,0,0,0,0,0,0,6,0,0,0,0,0,0,0,18,24,24,6,6,6,6,6,6,55,0,0,0,0
0,0,0,6,40,0,0,0,0,0,0,0,0,6,6,6,0,0,6,109,109,109,109,109,109,109,109,109,109,6,0,0,0,0,0,0,0,93,0,0,6,0,0,93,0,6,0,0,0,0,0
0,0,0,6,0,0,0,0,0,0,0,0,0,6,6,6,0,0,6,0,0,0,92,7,18,18,18,18,7,6,38,0,0,0,0,0,0,0,0,0,6,0,0,0,92,6,0,0,0,0,0
0,0,0,6,0,0,0,0,0,0,0,0,0,6,6,6,75,75,6,0,0,0,0,18,0,0,0,0,0,6,18,0,0,0,0,0,0,0,0,0,6,0,0,0,0,6,0,0,0,0,0
0,0,0,6,0,0,0,0,0,0,0,0,0,6,6,6,0,0,6,0,0,0,0,18,0,0,0,0,0,6,18,0,0,0,0,0,0,0,0,0,6,0,0,0,0,65,0,0,0,0,0
0,0,0,6,0,0,0,0,0,0,0,0,0,6,6,6,6,6,6,6,6,6,6,18,0,0,0,0,0,6,18,0,89,0,89,0,89,0,89,0,6,0,0,0,89,6,0,0,0,0,0
0,0,0,7,6,6,7,0,0,0,0,0,7,6,6,7,6,6,7,0,0,0,0,7,6,6,6,6,6,7,6,6,6,65,6,65,6,65,6,6,7,6,6,65,6,7,0,0,0,0,0
0,0,0,0,0,93,0,0,0,0,0,0,0,93,0,0,0,0,0,0,0,0,0,0,0,0,0,0,0,0,0,93,0,0,0,0,0,0,0,0,93,0,0,0,0,0,0,0,0,0,0
0,0,0,0,0,0,0,0,0,0,0,0,0,0,0,0,0,0,0,0,0,0,0,0,0,0,0,0,0,0,0,0,0,0,0,0,0,0,0,0,0,0,0,0,0,0,0,0,0,0,0
0,0,0,0,0,0,0,0,0,0,0,0,0,0,0,0,0,0,0,0,0,0,0,0,0,0,0,0,0,0,0,0,0,0,0,0,0,0,0,0,0,0,0,0,0,0,0,0,0,0,0
0,0,0,0,0,0,0,0,0,0,0,0,0,0,0,0,0,0,0,0,0,0,0,0,0,0,0,0,0,0,0,0,0,0,0,0,0,0,0,0,0,0,0,0,0,0,0,0,0,0,0
0,0,0,0,0,0,0,0,0,0,0,0,0,0,0,0,0,0,0,0,0,0,0,0,0,0,0,0,0,0,0,0,0,0,0,0,0,0,0,0,0,0,0,0,0,0,0,0,0,0,0
0,0,0,0,0,0,0,0,0,0,0,0,0,0,0,0,0,0,0,0,0,0,0,0,0,0,0,0,0,0,0,0,0,0,0,0,0,0,0,0,0,0,0,0,0,0,0,0,0,0,0
:endlayer
layer: 7
0,0,0,0,0,0,0,0,0,0,0,0,0,0,0,0,0,0,0,0,0,0,0,0,0,0,0,0,0,0,0,0,0,0,0,0,0,0,0,0,0,0,0,0,0,0,0,0,0,0,0
0,0,36,0,0,0,0,0,0,0,0,0,0,0,0,0,0,0,0,0,0,37,0,0,0,0,0,0,0,0,0,0,0,0,0,0,0,0,0,0,0,0,0,0,0,0,0,0,0,0,0
0,0,36,7,7,7,7,7,7,7,7,7,7,18,18,18,18,18,65,18,18,37,0,0,0,0,110,110,110,110,0,0,0,0,0,0,0,0,0,0,0,0,0,0,0,0,0,0,0,0,0
0,0,36,6,0,0,0,0,15,0,0,0,6,0,0,18,0,0,0,0,0,37,0,0,0,0,0,0,0,0,0,0,0,0,0,0,0,0,0,0,0,0,0,0,0,0,0,0,0,0,0
0,0,36,6,0,0,0,0,0,0,0,0,6,0,0,36,0,0,0,0,0,37,0,0,0,0,0,0,0,0,0,0,0,0,0,0,0,38,38,38,38,38,38,38,38,38,38,0,0,0,0
0,0,36,6,0,0,0,24,24,24,24,0,6,0,0,18,0,0,0,0,0,37,0,0,0,0,0,0,0,0,0,0,0,0,0,0,0,110,6,0,0,0,0,3,0,6,0,0,0,0,0
0,0,36,6,0,0,0,24,0,0,24,0,6,0,0,18,0,0,0,0,0,37,0,0,0,0,0,0,0,0,0,0,89,0,0,0,0,110,6,111,112,0,0,24,0,6,0,0,0,0,0
0,0,36,6,0,0,0,24,0,0,24,0,6,0,0,18,0,0,0,0,0,18,38,6,6,18,18,18,18,18,18,18,6,55,0,0,0,110,6,0,0,0,0,24,0,6,0,0,0,0,0
0,0,36,6,0,0,0,24,0,0,24,0,6,0,0,18,0,0,0,0,0,0,0,93,18,93,0,0,0,0,0,93,18,0,0,0,0,110,6,0,0,0,0,0,0,6,0,0,0,0,0
0,0,36,6,0,0,0,24,0,0,24,0,6,0,0,18,0,0,0,0,0,0,0,0,18,0,0,0,0,0,0,0,18,0,0,0,0,110,6,37,0,0,0,0,0,6,0,0,0,0,0
0,0,36,6,0,0,0,24,0,0,24,0,6,0,0,18,0,0,0,0,0,0,0,0,18,0,0,0,0,0,0,0,18,0,0,0,0,110,6,0,0,113,113,0,0,6,0,0,0,0,0
0,0,36,6,0,0,0,24,0,0,24,0,6,0,0,18,0,0,0,0,0,0,0,0,18,89,0,0,0,0,0,89,18,0,0,0,0,110,6,114,0,115,115,0,116,6,0,0,0,0,0
0,0,36,6,0,0,0,24,0,0,24,0,6,18,35,35,35,35,35,35,35,35,35,6,6,18,18,18,18,18,18,18,6,0,0,0,0,110,6,6,6,6,6,6,6,6,0,0,0,0,0
0,0,36,6,0,0,0,24,0,0,24,0,6,37,0,0,0,0,0,0,0,0,0,0,0,0,0,0,0,0,0,0,0,0,0,0,0,35,35,35,35,35,35,35,35,35,35,0,0,0,0
0,0,36,6,0,0,0,24,0,0,24,0,6,37,0,0,0,0,0,0,0,0,0,0,0,0,0,0,0,0,0,0,0,0,0,0,0,0,0,0,0,0,0,0,0,0,0,0,0,0,0
0,0,36,6,0,0,0,24,0,0,24,0,6,37,0,0,0,0,0,0,0,0,0,0,0,0,0,0,0,0,0,0,0,0,0,0,0,0,0,0,0,0,0,0,0,0,0,110,0,0,0
0,0,36,6,0,0,0,24,0,0,24,0,6,37,0,0,0,0,0,0,0,0,0,0,0,0,0,0,0,0,0,0,0,0,0,0,0,0,0,0,0,0,0,0,0,0,0,110,0,0,0
0,0,36,6,0,0,0,24,24,24,24,0,6,37,0,0,0,0,0,0,0,0,0,0,0,0,0,0,0,0,0,0,0,0,0,0,0,0,0,0,0,0,0,0,0,0,0,110,0,0,0
0,0,36,6,0,0,0,0,0,0,0,0,6,37,0,0,0,0,0,0,0,0,0,0,0,0,0,0,0,0,0,0,0,0,0,0,0,0,0,0,0,0,0,0,0,89,0,110,0,0,0
0,0,92,7,6,38,6,6,6,6,6,6,6,6,6,7,0,0,88,0,0,88,0,0,0,0,0,0,6,0,0,0,0,0,0,0,0,6,0,0,7,18,18,18,18,7,55,0,0,0,0
0,0,0,6,0,33,0,0,0,0,0,0,0,0,0,6,0,0,0,0,0,0,0,0,0,0,117,6,6,6,6,6,6,6,6,6,6,6,6,6,18,18,18,18,18,18,0,0,0,0,0
0,0,0,6,0,0,0,0,0,0,0,0,0,0,0,6,0,0,0,0,0,0,0,0,0,0,117,6,6,6,6,6,118,0,0,0,118,6,0,0,18,18,18,18,18,18,0,0,0,0,0
0,0,0,6,0,0,0,0,0,0,0,0,0,0,0,6,0,0,88,0,0,88,0,0,0,0,117,6,6,6,6,6,118,0,0,0,118,6,0,0,18,18,18,18,18,18,0,0,0,0,0
0,0,0,6,0,0,0,0,0,0,0,0,0,0,0,6,0,0,0,0,0,0,0,0,0,0,117,6,6,6,6,6,118,0,0,0,118,6,0,0,18,18,18,18,18,18,0,0,0,0,0
0,0,0,6,0,0,0,0,0,0,0,0,0,0,0,6,0,0,0,0,0,0,0,0,0,0,117,6,6,119,119,119,119,119,119,119,6,6,6,6,6,18,18,18,35,18,0,0,0,0,0
0,0,0,6,0,0,0,0,0,0,0,0,0,0,0,7,0,0,0,0,0,0,0,0,0,0,0,0,6,6,0,0,0,0,0,0,0,0,0,0,18,18,18,0,0,18,0,0,0,0,0
0,0,92,7,0,0,0,0,0,0,0,0,0,0,0,6,0,0,0,0,0,0,0,0,0,0,0,0,0,7,0,0,0,0,0,0,0,0,0,0,18,18,18,0,0,18,0,0,0,0,0
0,0,0,6,0,0,0,0,0,0,0,0,0,6,6,6,23,23,23,0,0,0,0,0,0,0,0,0,0,6,0,0,0,0,0,0,0,18,24,24,6,6,6,6,6,6,0,0,0,0,0
0,0,0,6,40,0,0,0,0,0,0,0,0,6,6,6,6,6,6,0,0,0,0,0,0,0,0,0,0,6,0,0,0,0,0,0,0,0,0,0,6,18,18,18,18,6,0,0,0,0,0
0,0,0,6,0,0,0,0,0,0,0,0,0,6,6,6,6,6,6,38,38,38,38,38,38,38,38,38,38,6,0,0,0,0,0,0,0,0,0,0,6,18,18,18,18,6,0,0,0,0,0
0,0,0,6,0,0,0,0,0,0,0,0,0,6,6,6,6,6,6,6,6,6,6,7,7,7,7,0,110,6,38,0,0,0,0,0,0,0,0,0,6,18,18,18,18,6,0,0,0,0,0
0,0,0,6,0,0,0,0,0,0,0,0,0,6,6,6,0,0,6,6,6,6,6,7,7,7,7,37,110,6,18,0,0,0,0,0,0,0,0,0,6,18,18,18,18,6,0,0,0,0,0
0,0,0,6,0,0,0,0,0,0,0,0,0,6,6,6,6,6,6,6,6,6,6,7,7,7,7,0,110,6,18,0,0,0,0,0,0,0,0,0,6,18,18,18,18,6,0,0,0,0,0
0,0,92,7,6,6,7,6,6,6,6,6,7,6,6,7,28,28,28,35,35,35,35,35,35,35,35,35,35,7,6,6,6,65,6,65,6,65,6,6,7,6,6,6,6,7,0,0,0,0,0
0,0,0,93,0,0,0,0,0,0,0,0,0,0,0,93,0,0,0,0,0,0,0,0,0,0,0,0,0,0,0,0,0,0,0,0,0,0,0,0,0,0,0,0,0,0,0,0,0,0,0
0,0,0,0,0,0,0,0,0,0,0,0,0,0,0,0,0,0,0,0,0,0,0,0,0,0,0,0,0,0,0,0,0,0,0,0,0,0,0,0,0,0,0,0,0,0,0,0,0,0,0
0,0,0,0,0,0,0,0,0,0,0,0,0,0,0,0,0,0,0,0,0,0,0,0,0,0,0,0,0,0,0,0,0,0,0,0,0,0,0,0,0,0,0,0,0,0,0,0,0,0,0
0,0,0,0,0,0,0,0,0,0,0,0,0,0,0,0,0,0,0,0,0,0,0,0,0,0,0,0,0,0,0,0,0,0,0,0,0,0,0,0,0,0,0,0,0,0,0,0,0,0,0
0,0,0,0,0,0,0,0,0,0,0,0,0,0,0,0,0,0,0,0,0,0,0,0,0,0,0,0,0,0,0,0,0,0,0,0,0,0,0,0,0,0,0,0,0,0,0,0,0,0,0
0,0,0,0,0,0,0,0,0,0,0,0,0,0,0,0,0,0,0,0,0,0,0,0,0,0,0,0,0,0,0,0,0,0,0,0,0,0,0,0,0,0,0,0,0,0,0,0,0,0,0
:endlayer
layer: 8
0,0,0,0,0,0,0,0,0,0,0,0,0,0,0,0,0,0,0,0,0,0,0,0,0,0,0,0,0,0,0,0,0,0,0,0,0,0,0,0,0,0,0,0,0,0,0,0,0,0,0
0,0,0,36,0,0,0,0,0,0,0,0,0,0,0,0,0,0,0,0,37,0,0,0,0,0,0,0,0,0,0,0,0,0,0,0,0,0,0,0,0,0,0,0,0,0,0,0,0,0,0
0,0,0,36,18,18,18,18,18,18,18,18,18,18,65,18,18,18,18,18,37,0,0,0,0,0,0,0,0,0,0,0,0,0,0,0,0,0,0,0,0,0,0,0,0,0,0,0,0,0,0
0,0,0,36,0,93,0,0,0,0,93,0,18,0,0,18,18,18,18,18,37,0,0,0,0,0,0,0,0,0,0,0,0,0,0,0,0,0,0,0,0,0,0,0,0,0,0,0,0,0,0
0,0,0,36,0,0,0,0,0,0,0,0,18,0,0,0,36,18,18,18,37,0,0,0,0,0,0,0,0,0,0,0,0,0,0,0,0,0,0,0,0,0,0,0,0,0,0,0,0,0,0
0,0,0,36,0,0,0,0,0,0,0,0,18,0,0,18,18,18,18,18,37,0,0,0,0,0,0,0,0,0,0,0,0,0,0,0,0,38,38,38,38,38,38,38,38,38,38,0,0,0,0
0,0,0,36,0,0,0,0,0,0,0,0,18,89,0,18,18,18,18,18,37,0,0,38,38,38,38,38,38,38,38,38,38,38,0,0,0,0,6,0,0,0,0,0,0,6,0,0,0,0,0
0,0,0,36,0,0,0,0,0,0,0,0,18,18,18,18,18,18,18,18,37,0,0,0,6,6,6,6,6,6,6,6,6,0,0,0,0,0,6,0,0,0,0,0,0,6,0,0,0,0,0
0,0,0,36,0,0,0,0,0,0,0,0,18,18,18,18,18,18,18,18,18,38,38,38,6,6,6,6,6,6,6,6,6,0,0,0,0,0,58,0,0,0,0,0,0,58,0,0,0,0,0
0,0,0,36,0,0,0,0,0,0,0,0,18,18,18,18,18,18,18,18,18,18,18,18,6,6,6,6,6,6,6,6,6,0,0,0,0,0,58,0,0,0,0,0,0,58,0,0,0,0,0
0,0,0,36,0,0,0,0,0,0,0,0,18,18,18,18,18,18,18,18,18,18,18,18,6,6,6,6,6,6,6,6,6,0,0,0,0,0,6,0,0,0,0,0,0,6,0,0,0,0,0
0,0,0,36,0,0,0,0,0,0,0,0,18,35,35,35,35,35,35,35,35,35,35,35,6,6,6,6,6,6,6,6,6,0,0,0,0,0,6,55,0,0,0,0,92,6,0,0,0,0,0
0,0,0,36,55,0,0,0,0,0,0,92,37,0,0,0,0,0,0,0,0,0,0,0,6,6,6,6,6,6,6,6,6,0,0,0,0,35,35,35,35,6,6,35,35,35,35,0,0,0,0
0,0,0,36,0,0,0,0,0,0,0,0,37,0,0,0,0,0,0,0,0,0,0,35,35,35,35,35,35,35,35,35,35,35,0,0,0,0,0,0,0,0,0,0,0,0,0,0,0,0,0
0,0,0,36,0,0,0,0,0,0,0,0,37,0,0,0,0,0,0,0,0,0,0,0,0,0,0,0,0,0,0,0,0,0,0,0,0,0,0,0,0,0,0,0,0,0,0,0,0,0,0
0,0,0,36,0,0,0,0,0,0,0,0,37,0,0,0,0,0,0,0,0,0,0,0,0,0,0,0,0,0,0,0,0,0,0,0,0,0,0,0,0,0,0,0,0,0,0,0,0,0,0
0,0,0,36,0,0,0,0,0,0,0,0,37,0,0,0,0,0,0,0,0,0,0,0,0,0,0,0,0,0,0,0,0,0,0,0,0,0,0,0,0,0,0,0,0,0,0,0,0,0,0
0,0,0,36,0,0,0,0,0,0,0,0,37,0,0,0,0,0,0,0,0,0,0,0,0,0,0,0,0,0,0,0,0,0,0,0,0,0,0,0,0,0,0,0,0,0,0,0,0,0,0
0,0,0,36,0,0,0,0,0,0,89,0,37,0,0,0,0,0,0,0,0,0,0,0,0,0,0,0,0,0,0,0,0,0,0,0,0,0,0,0,0,0,0,0,0,0,37,0,0,0,0
0,0,0,7,6,0,6,6,6,6,6,6,7,7,7,7,0,0,0,0,0,0,0,0,0,0,0,120,23,23,23,23,23,23,23,23,23,23,23,23,7,6,6,6,6,7,37,0,0,0,0
0,0,0,7,18,38,18,18,18,18,18,18,18,18,18,7,0,0,0,0,0,0,0,0,0,0,0,20,6,6,6,6,6,6,6,6,6,6,6,6,3,0,0,0,121,18,37,0,0,0,0
0,0,0,7,18,18,18,18,18,18,18,18,18,18,18,7,0,0,0,0,0,0,0,0,0,0,0,20,6,0,0,0,6,6,6,6,6,6,6,6,3,0,0,0,0,18,37,0,0,0,0
0,0,0,7,18,18,18,18,18,18,18,18,18,18,18,7,0,0,0,0,0,0,0,0,0,0,0,20,6,0,0,0,6,6,6,6,6,6,6,6,3,0,0,0,0,18,37,0,0,0,0
0,0,0,7,18,18,18,18,18,18,18,18,18,18,18,7,0,0,0,0,0,0,0,0,0,0,0,20,6,0,0,122,6,6,6,6,6,6,6,6,3,0,0,0,0,18,37,0,0,0,0
0,0,0,7,18,18,18,18,18,18,18,18,18,18,18,7,0,0,0,0,0,0,0,0,0,0,0,20,6,6,0,6,6,6,6,6,6,6,6,6,3,0,24,24,0,18,37,0,0,0,0
0,0,0,7,18,18,0,0,0,0,0,0,0,18,18,7,0,0,0,0,0,0,0,0,0,0,0,120,20,6,6,6,6,6,6,6,6,6,6,6,3,0,24,0,0,18,37,0,0,0,0
0,0,0,7,18,18,0,0,0,0,0,0,0,18,18,7,0,0,0,0,0,0,0,0,0,0,0,0,20,7,119,119,119,119,119,119,119,119,119,119,6,0,24,0,89,18,37,0,0,0,0
0,0,0,7,18,18,0,0,0,0,0,0,0,18,18,7,0,0,0,0,0,0,0,0,0,0,0,0,20,6,0,118,0,0,0,0,0,18,24,24,6,123,6,6,6,6,37,0,0,0,0
0,0,0,7,40,18,0,0,0,0,0,0,0,18,18,7,0,0,0,0,0,0,0,0,0,0,0,0,20,6,0,118,0,0,89,0,89,0,0,0,6,0,0,0,0,6,37,0,0,0,0
0,0,0,7,18,18,0,0,0,0,0,0,0,18,18,7,0,0,0,0,0,0,0,0,0,0,0,0,20,6,0,118,119,119,119,119,119,119,119,119,6,0,0,0,0,6,37,0,0,0,0
0,0,0,7,18,18,0,0,0,0,0,0,0,18,18,7,23,6,23,38,38,38,38,38,38,38,38,38,18,6,0,118,0,0,93,0,93,0,0,0,6,0,0,0,0,6,37,0,0,0,0
0,0,0,7,18,18,18,18,18,18,18,18,18,18,18,7,6,0,6,18,18,18,18,18,18,18,18,18,18,6,38,118,0,0,89,0,0,89,0,0,6,0,0,0,0,6,37,0,0,0,0
0,0,0,7,18,18,18,18,18,18,18,18,18,18,18,7,28,6,28,35,35,35,35,35,35,35,35,35,18,6,18,119,119,119,119,119,119,119,119,119,6,0,0,0,0,6,37,0,0,0,0
0,0,0,7,7,7,7,7,7,7,7,7,7,7,7,7,0,0,0,0,0,0,0,0,0,0,0,0,20,7,6,6,6,6,6,6,6,6,6,6,7,6,6,6,6,6,37,0,0,0,0
0,0,0,0,0,0,0,0,0,108,0,0,0,0,0,0,0,0,0,0,0,0,0,0,0,0,0,0,120,28,28,28,28,28,28,28,28,28,28,28,6,28,28,28,28,18,37,0,0,0,0
0,0,0,0,0,0,0,0,0,0,0,0,0,0,0,0,0,0,0,0,0,0,0,0,0,0,0,0,0,0,0,0,0,0,0,0,0,0,0,0,0,0,0,0,0,0,0,0,0,0,0
0,0,0,0,0,0,0,0,0,0,0,0,0,0,0,0,0,0,0,0,0,0,0,0,0,0,0,0,0,0,0,0,0,0,0,0,0,0,0,0,0,0,0,0,0,0,0,0,0,0,0
0,0,0,0,0,0,0,0,0,0,0,0,0,0,0,0,0,0,0,0,0,0,0,0,0,0,0,0,0,0,0,0,0,0,0,0,0,0,0,0,0,0,0,0,0,0,0,0,0,0,0
0,0,0,0,0,0,0,0,0,0,0,0,0,0,0,0,0,0,0,0,0,0,0,0,0,0,0,0,0,0,0,0,0,0,0,0,0,0,0,0,0,0,0,0,0,0,0,0,0,0,0
0,0,0,0,0,0,0,0,0,0,0,0,0,0,0,0,0,0,0,0,0,0,0,0,0,0,0,0,0,0,0,0,0,0,0,0,0,0,0,0,0,0,0,0,0,0,0,0,0,0,0
:endlayer
layer: 9
0,0,0,0,0,0,0,0,0,0,0,0,0,0,0,0,0,0,0,0,0,0,0,0,0,0,0,0,0,0,0,0,0,0,0,0,0,0,0,0,0,0,0,0,0,0,0,0,0,0,0
0,0,0,0,18,0,0,0,0,0,0,18,124,110,110,110,110,110,110,110,0,0,0,0,0,0,0,0,0,0,0,0,0,0,0,0,0,0,0,0,0,0,0,0,0,0,0,0,0,0,0
0,0,0,0,18,18,65,18,18,65,18,18,18,7,18,18,18,18,18,7,0,0,0,0,0,0,0,0,0,0,0,0,0,0,0,0,0,0,0,0,0,0,0,0,0,0,0,0,0,0,0
0,0,0,0,18,0,0,0,0,0,0,18,18,0,93,24,0,0,0,18,0,0,0,0,0,0,0,0,0,0,0,0,0,0,0,0,0,0,0,0,0,0,0,0,0,0,0,0,0,0,0
0,0,0,0,18,0,0,0,0,0,0,18,18,0,0,0,0,0,0,18,0,0,0,0,0,0,0,0,0,0,0,0,0,0,0,0,0,0,0,0,0,0,0,0,0,0,0,0,0,0,0
0,0,0,0,18,0,0,0,0,0,0,18,18,0,0,24,0,0,0,18,0,0,0,0,0,0,0,0,0,0,0,0,0,0,0,0,0,0,0,0,0,0,0,0,0,0,0,0,0,0,0
0,0,0,0,18,0,0,0,0,0,0,18,18,0,0,24,0,0,0,18,0,0,0,0,0,0,0,0,0,0,0,0,0,0,0,0,0,38,38,38,38,38,38,38,38,38,38,0,0,0,0
0,0,0,0,18,0,0,0,0,0,0,18,18,24,24,24,0,0,0,18,0,0,0,38,38,38,38,38,38,38,38,38,38,38,0,0,0,0,6,55,0,0,0,0,0,6,0,0,0,0,0
0,0,0,0,18,0,0,0,0,0,0,18,18,0,0,0,0,113,113,18,0,0,0,0,6,6,6,6,6,6,6,6,6,0,0,0,0,0,6,0,0,0,0,0,0,6,55,0,0,0,0
0,0,0,0,18,0,0,0,0,0,0,18,18,0,0,0,0,115,115,18,38,38,38,38,6,6,6,6,6,6,6,6,6,0,0,0,0,0,6,0,0,0,0,0,0,6,55,0,0,0,0
0,0,0,0,18,0,0,0,0,0,0,18,18,7,18,18,18,18,18,7,35,35,35,35,6,6,6,6,6,6,6,6,6,0,0,0,0,0,6,0,0,0,0,0,0,6,0,0,0,0,0
0,0,0,0,18,0,0,0,0,0,0,18,0,0,0,0,0,0,0,0,0,0,0,0,6,6,6,6,6,6,6,6,6,0,0,0,0,35,35,35,35,35,35,35,35,35,35,0,0,0,0
0,0,0,0,18,0,0,0,0,0,0,18,0,0,0,0,0,0,0,0,0,0,0,35,35,35,35,35,35,35,35,35,35,35,0,0,0,0,0,0,0,6,6,0,0,0,0,0,0,0,0
0,0,0,0,18,0,0,0,0,0,0,18,0,0,0,0,0,0,0,0,0,0,0,0,0,0,0,0,0,0,0,0,0,0,0,0,0,0,0,0,0,0,0,0,0,0,0,0,0,0,0
0,0,0,0,18,0,0,0,0,0,0,18,0,0,0,0,0,0,0,0,0,0,0,0,0,0,0,0,0,0,0,0,0,0,0,0,0,0,0,0,0,0,0,0,0,0,0,0,0,0,0
0,0,0,0,18,0,0,0,0,0,0,18,0,0,0,0,0,0,0,0,0,0,0,0,0,0,0,0,0,0,0,0,0,0,0,0,0,0,0,0,0,0,0,0,0,0,0,0,0,0,0
0,0,0,0,18,0,0,0,0,0,0,18,0,0,0,0,0,0,0,0,0,0,0,0,0,0,0,0,0,0,0,0,0,0,0,0,0,0,0,0,0,0,0,0,0,0,0,0,0,0,0
0,0,0,0,18,0,0,0,0,0,0,18,0,0,0,0,0,0,0,0,0,0,0,0,0,0,0,0,0,0,0,0,0,0,0,0,0,0,0,0,0,0,0,0,0,0,0,0,0,0,0
0,0,0,0,18,0,89,0,0,0,0,18,0,0,89,0,0,0,0,0,0,0,0,0,0,0,0,0,0,0,0,0,0,0,0,0,0,0,0,0,36,0,0,0,0,37,0,0,0,0,0
0,0,0,18,18,0,18,18,18,18,18,18,18,18,18,18,0,0,0,0,0,0,0,0,0,0,0,0,0,0,0,0,0,0,0,0,0,0,0,0,36,6,65,65,6,37,0,0,0,0,0
0,0,0,18,31,0,0,0,0,0,32,32,31,0,0,18,0,0,0,0,0,0,0,0,0,0,0,0,7,6,65,6,6,6,6,6,6,6,6,6,7,0,0,0,0,37,0,0,0,0,0
0,0,0,18,31,0,0,31,33,0,33,0,0,0,0,18,0,0,0,0,0,0,0,0,0,0,0,0,6,0,0,0,6,18,18,18,18,18,18,18,6,0,0,0,0,37,0,0,0,0,0
0,0,0,18,31,0,0,31,31,0,0,0,0,0,0,18,0,0,0,0,0,0,0,0,0,0,0,0,65,0,0,0,6,18,18,18,18,18,18,18,6,0,0,0,0,37,0,0,0,0,0
0,0,0,18,0,0,0,0,0,0,0,32,31,0,0,18,0,0,0,0,0,0,0,0,0,0,0,0,6,0,0,122,6,18,18,18,18,18,18,18,6,0,0,0,0,37,0,0,0,0,0
0,0,0,18,0,24,24,24,24,0,24,24,24,24,0,18,0,0,0,0,0,0,0,0,0,0,0,0,7,6,0,6,18,18,18,18,18,18,18,18,6,0,0,0,0,37,0,0,0,0,0
0,0,0,18,0,24,0,0,0,0,0,0,0,24,0,18,0,0,0,0,0,0,0,0,0,0,0,0,0,6,0,6,18,18,18,18,18,18,18,18,6,0,0,0,0,37,0,0,0,0,0
0,0,0,18,0,24,0,0,0,0,0,0,0,0,0,18,0,0,0,0,0,0,0,0,0,0,0,0,0,7,0,6,18,18,18,18,18,18,18,18,6,0,0,0,0,37,0,0,0,0,0
0,0,0,18,0,24,0,0,0,0,0,0,0,0,31,18,0,0,0,0,0,0,0,0,0,0,0,0,0,6,38,18,18,18,18,18,18,18,18,18,6,125,6,6,6,37,0,0,0,0,0
0,0,0,18,40,24,0,0,0,0,0,0,0,0,0,18,0,0,0,0,0,0,0,0,0,0,0,0,0,6,6,6,18,18,18,18,18,18,18,18,6,0,0,0,93,37,0,0,0,0,0
0,0,0,18,0,24,0,0,0,0,0,0,0,0,0,18,0,0,0,0,0,0,0,0,0,0,0,0,0,6,0,18,18,18,18,18,18,18,18,18,6,0,0,0,0,37,0,0,0,0,0
0,0,0,18,0,24,0,0,0,0,0,0,0,24,0,18,0,6,0,0,0,0,0,0,0,0,0,0,0,6,0,18,18,18,18,18,18,18,18,18,6,0,0,0,0,37,0,0,0,0,0
0,0,0,18,0,24,24,24,24,0,24,24,24,24,0,18,6,0,6,0,0,0,0,0,0,0,0,88,0,6,0,18,18,18,18,18,18,18,18,18,6,0,0,0,0,37,0,0,0,0,0
0,0,0,18,0,0,0,0,0,0,0,0,0,0,0,18,0,6,0,0,0,0,0,0,0,0,0,0,0,6,0,36,18,18,18,18,18,18,18,18,6,89,0,0,0,37,0,0,0,0,0
0,0,0,18,18,18,18,18,18,0,18,18,18,18,18,18,0,0,0,0,0,0,0,0,0,0,0,0,0,7,6,6,6,6,6,6,6,6,6,6,7,6,65,65,6,37,0,0,0,0,0
0,0,0,0,0,0,0,0,0,0,0,0,0,0,0,0,0,0,0,0,0,0,0,0,0,0,0,0,0,0,0,0,0,0,0,0,0,0,0,0,36,0,0,0,0,37,0,0,0,0,0
0,0,0,0,0,0,0,0,0,0,0,0,0,0,0,0,0,0,0,0,0,0,0,0,0,0,0,0,0,0,0,0,0,0,0,0,0,0,0,0,0,0,0,0,0,0,0,0,0,0,0
0,0,0,0,0,0,0,0,0,0,0,0,0,0,0,0,0,0,0,0,0,0,0,0,0,0,0,0,0,0,0,0,0,0,0,0,0,0,0,0,0,0,0,0,0,0,0,0,0,0,0
0,0,0,0,0,0,0,0,0,0,0,0,0,0,0,0,0,0,0,0,0,0,0,0,0,0,0,0,0,0,0,0,0,0,0,0,0,0,0,0,0,0,0,0,0,0,0,0,0,0,0
0,0,0,0,0,0,0,0,0,0,0,0,0,0,0,0,0,0,0,0,0,0,0,0,0,0,0,0,0,0,0,0,0,0,0,0,0,0,0,0,0,0,0,0,0,0,0,0,0,0,0
0,0,0,0,0,0,0,0,0,0,0,0,0,0,0,0,0,0,0,0,0,0,0,0,0,0,0,0,0,0,0,0,0,0,0,0,0,0,0,0,0,0,0,0,0,0,0,0,0,0,0
:endlayer
layer: 10
0,0,0,0,0,0,0,0,0,0,0,0,0,0,0,0,0,0,0,0,0,0,0,0,0,0,0,0,0,0,0,0,0,0,0,0,0,0,0,0,0,0,0,0,0,0,0,0,0,0,0
0,0,0,0,36,0,0,0,0,0,0,37,0,0,0,0,0,0,0,0,0,0,0,0,0,0,0,0,0,0,0,0,0,0,0,0,0,0,0,0,0,0,0,0,0,0,0,0,0,0,0
0,0,0,0,36,18,18,18,18,18,18,37,18,7,18,18,18,65,18,7,0,0,0,0,0,0,0,0,0,0,0,0,0,0,0,0,0,0,0,0,0,0,0,0,0,0,0,0,0,0,0
0,0,0,0,36,0,0,0,0,0,0,37,18,0,0,0,0,0,0,18,0,0,0,0,0,0,0,0,0,0,0,0,0,0,0,0,0,0,0,0,0,0,0,0,0,0,0,0,0,0,0
0,0,0,0,36,0,0,0,0,0,0,37,18,0,0,0,0,0,0,18,0,0,0,0,0,0,0,0,0,0,0,0,0,0,0,0,0,0,0,0,0,0,0,0,0,0,0,0,0,0,0
0,0,0,0,36,0,0,0,0,0,0,37,18,0,0,0,0,0,0,65,0,0,0,0,0,0,0,0,0,0,0,0,0,0,0,0,0,0,0,0,0,0,0,0,0,0,0,0,0,0,0
0,0,0,0,36,0,0,0,0,0,0,37,18,0,0,0,0,0,0,18,0,0,0,0,0,0,0,0,0,0,0,0,0,0,0,0,0,0,0,0,0,0,0,0,0,0,0,0,0,0,0
0,0,0,0,36,0,0,0,0,0,0,37,18,0,0,0,0,0,0,18,0,0,0,0,0,0,0,0,0,0,0,0,0,0,0,0,0,126,126,126,126,126,126,126,126,126,126,0,0,0,0
0,0,0,0,36,0,0,0,0,0,0,37,18,0,0,0,0,0,0,65,0,0,0,38,38,38,38,38,38,38,38,38,38,38,0,0,0,38,38,38,38,38,38,38,38,38,38,0,0,0,0
0,0,0,0,36,0,0,0,0,0,0,37,18,0,0,0,0,0,0,18,0,0,0,0,6,6,6,6,6,6,6,6,6,0,0,0,0,35,35,35,35,35,35,35,35,35,35,0,0,0,0
0,0,0,0,36,0,0,0,0,0,0,37,18,7,18,65,18,65,18,7,0,0,0,92,6,6,6,6,6,6,6,6,6,0,0,0,0,126,126,126,126,126,126,126,126,126,126,0,0,0,0
0,0,0,0,36,0,0,0,0,0,0,37,0,0,0,0,93,0,0,0,0,0,0,35,35,35,35,35,35,35,35,35,35,35,0,0,0,0,0,0,0,89,89,0,0,0,0,0,0,0,0
0,0,0,0,36,0,0,0,0,0,0,37,0,0,0,0,0,0,0,0,0,0,0,0,0,0,0,0,0,0,0,0,0,0,0,0,0,0,0,0,0,6,6,0,0,0,0,0,0,0,0
0,0,0,0,36,0,0,0,0,0,0,37,0,0,0,0,0,0,0,0,0,0,0,0,0,0,0,0,0,0,0,0,0,0,0,0,0,0,0,0,0,0,0,0,0,0,0,0,0,0,0
0,0,0,0,36,0,0,0,0,0,0,37,0,0,0,0,0,0,0,0,0,0,0,0,0,0,0,0,0,0,0,0,0,0,0,0,0,0,0,0,0,0,0,0,0,0,0,0,0,0,0
0,0,0,0,36,0,0,0,0,0,0,37,0,0,0,0,0,0,0,0,0,0,0,0,0,0,0,0,0,0,0,0,0,0,0,0,0,0,0,0,0,0,0,0,0,0,0,0,0,0,0
0,0,0,0,36,0,0,0,0,0,0,37,0,0,0,0,0,0,0,0,0,0,0,0,0,0,0,0,0,0,0,0,0,0,0,0,0,0,0,0,0,0,0,0,0,0,0,0,0,0,0
0,0,0,0,36,0,0,0,0,0,0,37,0,0,0,0,0,0,0,0,0,0,0,0,0,0,0,0,0,0,0,0,0,0,0,0,0,0,0,0,0,0,0,0,0,0,0,0,0,0,0
0,0,0,0,36,0,0,0,0,0,0,37,0,0,0,0,37,0,0,0,0,0,0,0,0,0,0,0,0,0,0,0,0,0,0,0,0,0,0,0,0,36,0,0,37,0,0,0,0,0,0
0,0,36,18,18,0,18,18,18,18,18,18,18,18,18,18,37,0,0,0,0,0,0,0,0,0,0,0,0,0,0,0,0,0,0,0,0,0,0,0,0,18,6,6,37,0,0,0,0,0,0
0,0,36,18,31,0,0,0,0,0,32,32,31,0,0,18,37,0,0,0,0,0,0,0,0,0,0,0,7,6,65,6,6,6,6,6,6,6,6,6,7,0,93,0,37,0,0,0,0,0,0
0,0,36,18,31,0,0,31,31,0,31,0,0,0,0,18,37,0,0,0,0,0,0,0,0,0,0,0,6,0,0,0,6,127,0,128,18,127,0,129,6,0,0,0,37,0,0,0,0,0,0
0,0,36,18,0,0,0,31,31,0,0,0,0,0,0,18,37,0,0,0,0,0,0,0,0,0,0,0,65,0,0,0,6,130,0,0,18,130,0,0,6,0,0,0,37,0,0,0,0,0,0
0,0,36,18,0,0,0,0,0,0,0,31,31,0,0,18,37,0,0,0,0,0,0,0,0,0,0,0,6,0,0,122,6,0,0,0,18,0,0,0,6,0,0,0,37,0,0,0,0,0,0
0,0,36,18,0,0,0,0,0,0,0,0,0,0,0,18,37,0,0,0,0,0,0,0,0,0,0,0,7,6,0,6,18,18,25,18,18,18,25,18,6,0,0,0,37,0,0,0,0,0,0
0,0,36,18,0,0,0,0,0,0,0,0,0,0,0,18,37,0,0,0,0,0,0,0,0,0,0,0,0,0,0,6,0,0,0,0,0,0,0,0,6,0,0,0,37,0,0,0,0,0,0
0,0,36,18,0,0,0,0,0,0,0,0,0,0,0,18,37,0,0,0,0,0,0,0,0,0,0,0,0,7,0,6,0,0,0,18,18,18,18,18,6,0,0,89,37,0,0,0,0,0,0
0,0,36,18,0,0,0,0,0,0,0,0,0,0,31,18,37,0,0,0,0,0,0,0,0,0,0,0,0,6,0,34,0,0,0,18,0,0,0,131,6,18,6,6,37,0,0,0,0,0,0
0,0,36,18,40,0,0,0,0,0,0,0,0,0,0,18,37,0,0,0,0,0,0,0,0,0,0,0,0,6,6,6,0,0,0,18,0,0,0,0,6,0,0,0,37,0,0,0,0,0,0
0,0,36,18,0,0,0,0,0,0,0,0,0,0,0,18,37,0,0,0,0,0,0,0,0,0,0,0,0,6,0,24,0,0,0,27,0,0,0,0,6,0,0,0,37,0,0,0,0,0,0
0,0,36,18,0,0,0,0,0,0,0,0,0,0,0,18,37,6,0,0,0,0,0,0,0,0,0,0,0,6,0,24,0,0,0,18,18,18,18,18,6,0,0,0,37,0,0,0,0,0,0
0,0,36,18,0,0,0,0,0,0,0,0,0,0,0,18,6,0,6,0,0,0,0,0,0,0,0,0,0,6,0,24,0,0,0,27,0,0,0,132,6,0,0,0,37,0,0,0,0,0,0
0,0,36,18,0,0,0,0,0,0,0,0,0,0,0,18,37,6,0,0,0,0,0,0,0,0,0,0,0,6,0,0,0,0,0,18,0,0,0,0,6,0,0,0,37,0,0,0,0,0,0
0,0,36,18,18,18,18,18,18,0,18,18,18,18,18,18,37,0,0,0,0,0,0,0,0,0,0,0,0,7,6,6,6,6,6,6,6,6,6,6,7,18,6,6,37,0,0,0,0,0,0
0,0,36,0,0,0,0,0,0,0,0,0,0,0,0,0,37,0,0,0,0,0,0,0,0,0,0,0,0,0,0,0,0,0,0,0,0,0,0,0,0,36,0,0,37,0,0,0,0,0,0
0,0,0,0,0,0,0,0,0,0,0,0,0,0,0,0,0,0,0,0,0,0,0,0,0,0,0,0,0,0,0,0,0,0,0,0,0,0,0,0,0,0,0,0,0,0,0,0,0,0,0
0,0,0,0,0,0,0,0,0,0,0,0,0,0,0,0,0,0,0,0,0,0,0,0,0,0,0,0,0,0,0,0,0,0,0,0,0,0,0,0,0,0,0,0,0,0,0,0,0,0,0
0,0,0,0,0,0,0,0,0,0,0,0,0,0,0,0,0,0,0,0,0,0,0,0,0,0,0,0,0,0,0,0,0,0,0,0,0,0,0,0,0,0,0,0,0,0,0,0,0,0,0
0,0,0,0,0,0,0,0,0,0,0,0,0,0,0,0,0,0,0,0,0,0,0,0,0,0,0,0,0,0,0,0,0,0,0,0,0,0,0,0,0,0,0,0,0,0,0,0,0,0,0
0,0,0,0,0,0,0,0,0,0,0,0,0,0,0,0,0,0,0,0,0,0,0,0,0,0,0,0,0,0,0,0,0,0,0,0,0,0,0,0,0,0,0,0,0,0,0,0,0,0,0
:endlayer
layer: 11
0,0,0,0,0,0,0,0,0,0,0,0,0,0,0,0,0,0,0,0,0,0,0,0,0,0,0,0,0,0,0,0,0,0,0,0,0,0,0,0,0,0,0,0,0,0,0,0,0,0,0
0,0,0,0,0,18,0,0,0,0,18,0,0,0,0,0,0,0,0,0,37,0,0,0,0,0,0,0,0,0,0,0,0,0,0,0,0,0,0,0,0,0,0,0,0,0,0,0,0,0,0
0,0,0,0,0,18,18,18,18,18,18,0,36,7,7,7,7,7,7,7,37,0,0,0,0,0,0,0,0,0,0,0,0,0,0,0,0,0,0,0,0,0,0,0,0,0,0,0,0,0,0
0,0,0,0,0,18,0,0,0,0,18,0,36,18,0,0,0,93,0,18,37,0,0,0,0,0,0,0,0,0,0,0,0,0,0,0,0,0,0,0,0,0,0,0,0,0,0,0,0,0,0
0,0,0,0,0,18,0,0,0,0,18,0,36,18,0,0,0,0,0,18,37,0,0,0,0,0,0,0,0,0,0,0,0,0,0,0,0,0,0,0,0,0,0,0,0,0,0,0,0,0,0
0,0,0,0,0,18,0,0,0,0,18,0,36,18,0,0,0,0,0,18,37,0,0,0,0,0,0,0,0,0,0,0,0,0,0,0,0,0,0,0,0,0,0,0,0,0,0,0,0,0,0
0,0,0,0,0,18,0,0,0,0,18,0,36,18,0,0,0,0,0,18,37,0,0,0,0,0,0,0,0,0,0,0,0,0,0,0,0,0,0,0,0,0,0,0,0,0,0,0,0,0,0
0,0,0,0,0,18,0,0,0,0,18,0,36,18,55,0,0,0,0,18,37,0,0,0,0,0,0,0,0,0,0,0,0,0,0,0,0,0,0,0,0,0,0,0,0,0,0,0,0,0,0
0,0,0,0,0,18,0,0,0,0,18,0,36,18,0,0,0,0,0,18,37,0,0,0,0,0,0,0,0,0,0,0,0,0,0,0,0,0,0,0,0,0,0,0,0,0,0,0,0,0,0
0,0,0,0,0,18,0,0,0,0,18,0,36,18,0,0,0,0,89,18,37,0,0,38,38,38,38,38,38,38,38,38,38,38,0,0,0,0,0,0,0,0,0,0,0,0,0,0,0,0,0
0,0,0,0,0,18,0,0,0,0,18,0,36,7,7,7,7,7,7,7,37,0,0,35,35,35,35,35,35,35,35,35,35,35,0,0,0,0,0,0,0,0,0,0,0,0,0,0,0,0,0
0,0,0,0,0,18,0,0,0,0,18,0,36,0,0,0,0,0,0,0,37,0,0,0,0,0,0,0,0,0,0,0,0,0,0,0,0,0,0,0,0,0,0,0,0,0,0,0,0,0,0
0,0,0,0,0,18,0,0,0,0,18,0,0,0,0,0,0,0,0,0,0,0,0,0,0,0,0,0,0,0,0,0,0,0,0,0,0,0,0,0,0,6,6,0,0,0,0,0,0,0,0
0,0,0,0,0,18,0,0,0,0,18,0,0,0,0,0,0,0,0,0,0,0,0,0,0,0,0,0,0,0,0,0,0,0,0,0,0,0,0,0,0,0,0,0,0,0,0,0,0,0,0
0,0,0,0,0,18,0,0,0,0,18,0,0,0,0,0,0,0,0,0,0,0,0,0,0,0,0,0,0,0,0,0,0,0,0,0,0,0,0,0,0,0,0,0,0,0,0,0,0,0,0
0,0,0,0,0,18,0,0,0,0,18,0,0,0,0,0,0,0,0,0,0,0,0,0,0,0,0,0,0,0,0,0,0,0,0,0,0,0,0,0,0,0,0,0,0,0,0,0,0,0,0
0,0,0,0,0,18,0,0,0,0,18,0,0,0,0,0,0,0,0,0,0,0,0,0,0,0,0,0,0,0,0,0,0,0,0,0,0,0,0,0,0,0,0,0,0,0,0,0,0,0,0
0,0,0,0,0,18,0,0,0,0,18,0,0,0,0,0,0,0,0,0,0,0,0,0,0,0,0,0,0,0,0,0,0,0,0,0,0,0,0,0,0,0,0,0,0,0,0,0,0,0,0
0,0,0,0,0,18,0,0,0,0,18,18,18,18,18,37,0,0,0,0,0,0,0,0,0,0,0,0,0,0,0,0,0,0,0,0,0,0,0,0,0,0,36,37,0,0,0,0,0,0,0
0,0,0,36,18,18,18,18,18,18,18,18,18,18,18,37,0,0,0,0,0,0,0,0,0,0,0,0,0,0,0,0,0,0,0,0,0,0,0,0,0,0,36,37,0,0,0,0,0,0,0
0,0,0,36,0,93,0,0,0,0,33,33,33,93,0,37,0,0,0,0,0,0,0,0,0,0,0,0,7,6,6,6,6,6,65,6,6,6,65,6,7,110,36,37,0,0,0,0,0,0,0
0,0,0,36,31,0,0,0,0,0,0,0,0,0,0,37,0,0,0,0,0,0,0,0,0,0,0,0,6,0,0,0,6,0,0,0,18,0,0,0,6,110,36,37,0,0,0,0,0,0,0
0,0,0,36,0,0,0,0,0,0,0,0,0,0,0,37,0,0,0,0,0,0,0,0,0,0,0,0,6,55,0,0,6,55,0,0,18,0,0,0,65,110,36,37,0,0,0,0,0,0,0
0,0,0,36,0,0,0,0,0,0,0,0,0,0,0,37,0,0,0,0,0,0,0,0,0,0,0,0,6,0,0,122,6,0,0,0,18,0,0,0,6,110,36,37,0,0,0,0,0,0,0
0,0,0,36,0,0,0,0,0,0,0,0,0,0,0,37,0,0,0,0,0,0,0,0,0,0,0,0,7,6,6,6,18,18,133,18,18,18,134,18,6,110,36,37,0,0,0,0,0,0,0
0,0,0,36,0,0,0,0,0,0,0,0,0,0,0,37,0,0,0,0,0,0,0,0,0,0,0,0,0,0,93,6,0,0,0,0,0,0,0,0,6,110,36,37,0,0,0,0,0,0,0
0,0,0,36,0,0,0,0,0,0,0,0,0,0,0,37,0,0,0,0,0,0,0,0,0,0,0,0,0,7,0,6,0,0,0,18,18,18,18,18,6,110,36,37,0,0,0,0,0,0,0
0,0,0,36,0,0,0,0,0,0,0,0,0,0,0,37,0,0,0,0,0,0,0,0,0,0,0,0,0,6,0,135,0,0,0,18,0,0,0,0,65,110,36,37,0,0,0,0,0,0,0
0,0,0,36,55,0,0,0,0,0,0,0,0,0,92,37,0,0,0,0,0,0,0,0,0,0,0,0,0,6,6,6,0,0,0,18,0,0,0,0,6,110,36,37,0,0,0,0,0,0,0
0,0,0,36,0,0,0,0,0,0,0,0,0,0,0,37,0,89,0,0,0,0,0,0,0,0,0,0,0,6,0,0,0,0,0,136,0,0,0,0,65,110,36,37,0,0,0,0,0,0,0
0,0,0,36,0,0,0,0,0,0,0,0,0,0,0,37,0,6,0,0,0,0,0,0,0,0,0,0,0,65,0,0,0,0,0,18,18,18,18,18,6,110,36,37,0,0,0,0,0,0,0
0,0,0,36,0,0,0,0,0,0,0,0,0,0,0,37,6,0,6,55,0,0,0,0,0,0,0,0,0,65,0,0,0,0,0,137,0,0,0,0,6,110,36,37,0,0,0,0,0,0,0
0,0,0,36,0,0,0,0,89,0,89,0,0,0,0,37,0,6,0,0,0,0,0,0,0,0,0,0,0,6,0,0,0,0,0,18,0,0,0,0,6,110,36,37,0,0,0,0,0,0,0
0,0,0,36,18,18,18,18,18,18,18,18,18,18,18,37,0,93,0,0,0,0,0,0,0,0,0,0,0,7,6,6,65,6,65,6,65,6,65,6,7,0,36,37,0,0,0,0,0,0,0
0,0,0,36,0,0,0,0,0,24,0,0,0,0,0,37,0,0,0,0,0,0,0,0,0,0,0,0,0,0,0,0,0,0,0,0,0,0,0,0,0,0,36,37,0,0,0,0,0,0,0
0,0,0,0,0,0,0,0,0,0,0,0,0,0,0,0,0,0,0,0,0,0,0,0,0,0,0,0,0,0,0,0,0,0,0,0,0,0,0,0,0,0,0,0,0,0,0,0,0,0,0
0,0,0,0,0,0,0,0,0,0,0,0,0,0,0,0,0,0,0,0,0,0,0,0,0,0,0,0,0,0,0,0,0,0,0,0,0,0,0,0,0,0,0,0,0,0,0,0,0,0,0
0,0,0,0,0,0,0,0,0,0,0,0,0,0,0,0,0,0,0,0,0,0,0,0,0,0,0,0,0,0,0,0,0,0,0,0,0,0,0,0,0,0,0,0,0,0,0,0,0,0,0
0,0,0,0,0,0,0,0,0,0,0,0,0,0,0,0,0,0,0,0,0,0,0,0,0,0,0,0,0,0,0,0,0,0,0,0,0,0,0,0,0,0,0,0,0,0,0,0,0,0,0
0,0,0,0,0,0,0,0,0,0,0,0,0,0,0,0,0,0,0,0,0,0,0,0,0,0,0,0,0,0,0,0,0,0,0,0,0,0,0,0,0,0,0,0,0,0,0,0,0,0,0
:endlayer
layer: 12
0,0,0,0,0,0,0,0,0,0,0,0,0,0,0,0,0,0,0,0,0,0,0,0,0,0,0,0,0,0,0,0,0,0,0,0,0,0,0,0,0,0,0,0,0,0,0,0,0,0,0
0,0,0,0,0,0,36,0,0,37,0,0,0,0,0,0,0,0,0,37,0,0,0,0,0,0,0,0,0,0,0,0,0,0,0,0,0,0,0,0,0,0,0,0,0,0,0,0,0,0,0
0,0,0,0,0,0,36,18,18,37,0,0,0,36,18,18,18,18,18,37,0,0,0,0,0,0,0,0,0,0,0,0,0,0,0,0,0,0,0,0,0,0,0,0,0,0,0,0,0,0,0
0,0,0,0,0,0,36,0,0,37,0,0,0,36,0,0,0,0,0,37,0,0,0,0,0,0,0,0,0,0,0,0,0,0,0,0,0,0,0,0,0,0,0,0,0,0,0,0,0,0,0
0,0,0,0,0,0,36,0,0,37,0,0,0,36,0,0,0,0,0,37,0,0,0,0,0,0,0,0,0,0,0,0,0,0,0,0,0,0,0,0,0,0,0,0,0,0,0,0,0,0,0
0,0,0,0,0,0,36,0,0,37,0,0,0,36,0,0,0,0,0,37,0,0,0,0,0,0,0,0,0,0,0,0,0,0,0,0,0,0,0,0,0,0,0,0,0,0,0,0,0,0,0
0,0,0,0,0,0,36,0,0,37,0,0,0,36,0,0,0,0,0,37,0,0,0,0,0,0,0,0,0,0,0,0,0,0,0,0,0,0,0,0,0,0,0,0,0,0,0,0,0,0,0
0,0,0,0,0,0,36,0,0,37,0,0,0,36,0,0,0,0,0,37,0,0,0,0,0,0,0,0,0,0,0,0,0,0,0,0,0,0,0,0,0,0,0,0,0,0,0,0,0,0,0
0,0,0,0,0,0,36,0,0,37,0,0,0,36,0,0,0,0,0,37,0,0,0,0,0,0,0,0,0,0,0,0,0,0,0,0,0,0,0,0,0,0,0,0,0,0,0,0,0,0,0
0,0,0,0,0,0,36,0,0,37,0,0,0,36,0,0,0,0,0,37,0,0,0,0,0,0,0,0,0,0,0,0,0,0,0,0,0,0,0,0,0,0,0,0,0,0,0,0,0,0,0
0,0,0,0,0,0,36,0,0,37,0,0,0,36,18,18,18,18,18,37,0,0,0,0,0,0,0,0,0,0,0,0,0,0,0,0,0,0,0,0,0,0,0,0,0,0,0,0,0,0,0
0,0,0,0,0,0,36,0,0,37,0,0,0,36,0,0,0,0,0,37,0,0,0,0,0,0,0,0,0,0,0,0,0,0,0,0,0,0,0,0,0,0,0,0,0,0,0,0,0,0,0
0,0,0,0,0,0,36,0,0,37,0,0,0,0,0,0,0,0,0,0,0,0,0,0,0,0,0,0,0,0,0,0,0,0,0,0,0,0,0,0,0,6,0,0,0,0,0,0,0,0,0
0,0,0,0,0,0,36,0,0,37,0,0,0,0,0,0,0,0,0,0,0,0,0,0,0,0,0,0,0,0,0,0,0,0,0,0,0,0,0,0,0,0,0,0,0,0,0,0,0,0,0
0,0,0,0,0,0,36,0,0,37,0,0,0,0,0,0,0,0,0,0,0,0,0,0,0,0,0,0,0,0,0,0,0,0,0,0,0,0,0,0,0,0,0,0,0,0,0,0,0,0,0
0,0,0,0,0,0,36,0,0,37,0,0,0,0,0,0,0,0,0,0,0,0,0,0,0,0,0,0,0,0,0,0,0,0,0,0,0,0,0,0,0,0,0,0,0,0,0,0,0,0,0
0,0,0,0,0,0,36,0,0,37,0,0,0,0,0,0,0,0,0,0,0,0,0,0,0,0,0,0,0,0,0,0,0,0,0,0,0,0,0,0,0,0,0,0,0,0,0,0,0,0,0
0,0,0,0,0,0,36,0,0,37,0,0,0,0,0,0,0,0,0,0,0,0,0,0,0,0,0,0,0,0,0,0,0,0,0,0,0,0,0,0,0,0,0,0,0,0,0,0,0,0,0
0,0,0,0,0,0,36,0,0,37,0,0,0,0,0,0,0,0,0,0,0,0,0,0,0,0,0,0,0,0,0,0,0,0,0,0,0,0,0,0,0,0,0,0,0,0,0,0,0,0,0
0,0,0,0,18,18,18,18,18,18,18,18,18,18,18,0,0,0,0,0,0,0,0,0,0,0,0,0,0,0,0,0,0,0,0,0,0,0,0,0,0,0,0,0,0,0,0,0,0,0,0
0,0,0,0,18,0,0,0,0,0,31,33,0,0,18,0,0,0,0,0,0,0,0,0,0,0,0,0,7,6,6,6,6,6,65,6,6,6,65,6,7,0,0,0,0,0,0,0,0,0,0
0,0,0,0,18,0,0,0,0,0,0,0,0,0,18,0,0,0,0,0,0,0,0,0,0,0,0,0,6,6,6,6,6,0,0,0,18,0,0,0,6,0,0,0,0,0,0,0,0,0,0
0,0,0,0,18,0,0,0,0,0,0,0,0,0,18,0,0,0,0,0,0,0,0,0,0,0,0,0,6,6,6,6,6,0,0,0,18,0,0,0,65,0,0,0,0,0,0,0,0,0,0
0,0,0,0,18,0,0,0,0,0,0,0,0,0,18,0,0,0,0,0,0,0,0,0,0,0,0,0,6,6,6,122,6,0,0,0,18,0,0,0,6,0,0,0,0,0,0,0,0,0,0
0,0,0,0,18,0,0,0,0,0,0,0,0,0,18,0,0,0,0,0,0,0,0,0,0,0,0,0,7,6,6,6,18,18,18,18,18,18,18,18,6,0,0,0,0,0,0,0,0,0,0
0,0,0,0,18,0,0,0,0,0,0,0,0,0,18,0,0,0,0,0,0,0,0,0,0,0,0,0,0,6,6,6,0,0,0,0,0,0,0,92,6,0,0,0,0,0,0,0,0,0,0
0,0,0,0,18,0,0,0,0,0,0,0,0,0,18,0,0,0,0,0,0,0,0,0,0,0,0,0,0,7,6,6,0,0,0,18,18,18,18,18,6,55,0,0,0,0,0,0,0,0,0
0,0,0,0,18,0,0,0,0,0,0,0,0,0,18,0,0,0,0,0,0,0,0,0,0,0,0,0,0,6,89,6,55,0,0,18,0,0,0,0,65,0,0,0,0,0,0,0,0,0,0
0,0,0,0,18,0,0,0,0,0,0,0,0,0,18,0,0,0,0,0,0,0,0,0,0,0,0,0,0,6,6,6,0,0,0,18,0,0,0,0,6,0,0,0,0,0,0,0,0,0,0
0,0,0,0,18,0,0,0,0,0,0,0,0,0,18,0,0,0,0,0,0,0,0,0,0,0,0,0,0,6,93,0,0,0,0,18,0,0,0,0,65,0,0,0,0,0,0,0,0,0,0
0,0,0,0,18,0,0,0,0,0,0,0,0,0,18,0,0,6,0,0,0,0,0,0,0,0,0,0,0,65,0,0,0,0,0,18,18,18,18,18,6,0,0,0,0,0,0,0,0,0,0
0,0,0,0,18,0,0,0,0,0,0,0,0,0,18,0,6,0,6,0,0,0,0,0,0,0,0,0,0,65,0,0,0,0,0,18,0,0,0,0,6,0,0,0,0,0,0,0,0,0,0
0,0,0,0,18,0,0,0,0,0,0,0,0,0,18,0,0,6,0,0,0,0,0,0,0,0,0,0,0,6,0,89,0,89,0,18,0,0,0,89,6,0,0,0,0,0,0,0,0,0,0
0,0,0,0,18,18,18,18,18,18,18,18,18,18,18,0,0,0,0,0,0,0,0,0,0,0,0,0,0,7,6,6,65,6,65,6,65,6,65,6,7,55,0,0,0,0,0,0,0,0,0
0,0,0,0,36,0,0,0,0,0,0,0,0,0,37,0,0,0,0,0,0,0,0,0,0,0,0,0,0,0,0,0,0,0,0,0,0,0,0,0,93,0,0,0,0,0,0,0,0,0,0
0,0,0,0,0,0,0,0,0,0,0,0,0,0,0,0,0,0,0,0,0,0,0,0,0,0,0,0,0,0,0,0,0,0,0,0,0,0,0,0,0,0,0,0,0,0,0,0,0,0,0
0,0,0,0,0,0,0,0,0,0,0,0,0,0,0,0,0,0,0,0,0,0,0,0,0,0,0,0,0,0,0,0,0,0,0,0,0,0,0,0,0,0,0,0,0,0,0,0,0,0,0
0,0,0,0,0,0,0,0,0,0,0,0,0,0,0,0,0,0,0,0,0,0,0,0,0,0,0,0,0,0,0,0,0,0,0,0,0,0,0,0,0,0,0,0,0,0,0,0,0,0,0
0,0,0,0,0,0,0,0,0,0,0,0,0,0,0,0,0,0,0,0,0,0,0,0,0,0,0,0,0,0,0,0,0,0,0,0,0,0,0,0,0,0,0,0,0,0,0,0,0,0,0
0,0,0,0,0,0,0,0,0,0,0,0,0,0,0,0,0,0,0,0,0,0,0,0,0,0,0,0,0,0,0,0,0,0,0,0,0,0,0,0,0,0,0,0,0,0,0,0,0,0,0
:endlayer
layer: 13
0,0,0,0,0,0,0,0,0,0,0,0,0,0,0,0,0,0,0,0,0,0,0,0,0,0,0,0,0,0,0,0,0,0,0,0,0,0,0,0,0,0,0,0,0,0,0,0,0,0,0
0,0,0,0,0,0,0,18,18,0,0,0,0,0,36,0,0,0,37,0,0,0,0,0,0,0,0,0,0,0,0,0,0,0,0,0,0,0,0,0,0,0,0,0,0,0,0,0,0,0,0
0,0,0,0,0,0,0,36,37,0,0,0,0,0,36,18,18,18,37,0,0,0,0,0,0,0,0,0,0,0,0,0,0,0,0,0,0,0,0,0,0,0,0,0,0,0,0,0,0,0,0
0,0,0,0,0,0,0,36,37,0,0,0,0,0,36,0,0,0,37,0,0,0,0,0,0,0,0,0,0,0,0,0,0,0,0,0,0,0,0,0,0,0,0,0,0,0,0,0,0,0,0
0,0,0,0,0,0,0,36,37,0,0,0,0,0,36,0,0,0,37,0,0,0,0,0,0,0,0,0,0,0,0,0,0,0,0,0,0,0,0,0,0,0,0,0,0,0,0,0,0,0,0
0,0,0,0,0,0,0,36,37,0,0,0,0,0,36,0,0,0,37,0,0,0,0,0,0,0,0,0,0,0,0,0,0,0,0,0,0,0,0,0,0,0,0,0,0,0,0,0,0,0,0
0,0,0,0,0,0,0,36,37,0,0,0,0,0,36,0,0,0,37,0,0,0,0,0,0,0,0,0,0,0,0,0,0,0,0,0,0,0,0,0,0,0,0,0,0,0,0,0,0,0,0
0,0,0,0,0,0,0,36,37,0,0,0,0,0,36,0,0,0,37,0,0,0,0,0,0,0,0,0,0,0,0,0,0,0,0,0,0,0,0,0,0,0,0,0,0,0,0,0,0,0,0
0,0,0,0,0,0,0,36,37,0,0,0,0,0,36,0,0,0,37,0,0,0,0,0,0,0,0,0,0,0,0,0,0,0,0,0,0,0,0,0,0,0,0,0,0,0,0,0,0,0,0
0,0,0,0,0,0,0,36,37,0,0,0,0,0,36,0,0,0,37,0,0,0,0,0,0,0,0,0,0,0,0,0,0,0,0,0,0,0,0,0,0,0,0,0,0,0,0,0,0,0,0
0,0,0,0,0,0,0,36,37,0,0,0,0,0,36,18,18,18,37,0,0,0,0,0,0,0,0,0,0,0,0,0,0,0,0,0,0,0,0,0,0,0,0,0,0,0,0,0,0,0,0
0,0,0,0,0,0,0,36,37,0,0,0,0,0,36,0,0,0,37,0,0,0,0,0,0,0,0,0,0,0,0,0,0,0,0,0,0,0,0,0,0,0,0,0,0,0,0,0,0,0,0
0,0,0,0,0,0,0,36,37,0,0,0,0,0,0,0,0,0,0,0,0,0,0,0,0,0,0,0,0,0,0,0,0,0,0,0,0,0,0,0,0,138,0,0,0,0,0,0,0,0,0
0,0,0,0,0,0,0,36,37,0,0,0,0,0,0,0,0,0,0,0,0,0,0,0,0,0,0,0,0,0,0,0,0,0,0,0,0,0,0,0,0,0,0,0,0,0,0,0,0,0,0
0,0,0,0,0,0,0,36,37,0,0,0,0,0,0,0,0,0,0,0,0,0,0,0,0,0,0,0,0,0,0,0,0,0,0,0,0,0,0,0,0,0,0,0,0,0,0,0,0,0,0
0,0,0,0,0,0,0,36,37,0,0,0,0,0,0,0,0,0,0,0,0,0,0,0,0,0,0,0,0,0,0,0,0,0,0,0,0,0,0,0,0,0,0,0,0,0,0,0,0,0,0
0,0,0,0,0,0,0,36,37,0,0,0,0,0,0,0,0,0,0,0,0,0,0,0,0,0,0,0,0,0,0,0,0,0,0,0,0,0,0,0,0,0,0,0,0,0,0,0,0,0,0
0,0,0,0,0,0,0,36,37,0,0,0,0,0,0,0,0,0,0,0,0,0,0,0,0,0,0,0,0,0,0,0,0,0,0,0,0,0,0,0,0,0,0,0,0,0,0,0,0,0,0
0,0,0,0,0,0,0,36,37,0,0,0,0,0,0,0,0,0,0,0,0,0,0,0,0,0,0,0,0,0,0,0,0,0,0,0,0,0,0,0,0,0,0,0,0,0,0,0,0,0,0
0,0,0,0,0,36,18,18,18,65,18,18,18,37,0,0,0,0,0,0,0,0,0,0,0,0,0,110,38,38,38,38,38,38,38,38,38,38,38,38,38,110,0,0,0,0,0,0,0,0,0
0,0,0,0,0,36,0,0,0,0,33,0,0,37,0,0,0,0,0,0,0,0,0,0,0,0,0,36,6,6,6,6,6,6,6,6,6,6,6,6,6,37,0,0,0,0,0,0,0,0,0
0,0,0,0,0,36,0,0,0,0,0,0,0,37,0,0,0,0,0,0,0,0,0,0,0,0,0,36,6,0,0,0,6,0,0,0,18,0,0,0,6,37,0,0,0,0,0,0,0,0,0
0,0,0,0,0,36,0,0,0,0,0,0,0,37,0,0,0,0,0,0,0,0,0,0,0,0,0,36,6,0,0,0,6,0,0,0,18,0,0,0,6,37,0,0,0,0,0,0,0,0,0
0,0,0,0,0,36,0,0,0,0,0,0,0,37,0,0,0,0,0,0,0,0,0,0,0,0,0,36,6,0,0,0,6,0,0,0,18,0,0,0,6,37,0,0,0,0,0,0,0,0,0
0,0,0,0,0,36,0,0,0,0,0,0,0,37,0,0,0,0,0,0,0,0,0,0,0,0,0,36,6,0,6,0,6,18,18,18,18,18,18,18,6,37,0,0,0,0,0,0,0,0,0
0,0,0,0,0,36,0,0,0,0,0,0,0,37,0,0,0,0,0,0,0,0,0,0,0,0,0,110,36,0,0,6,0,0,0,118,0,0,118,0,6,37,0,0,0,0,0,0,0,0,0
0,0,0,0,0,36,0,0,0,0,0,0,0,37,0,0,0,0,0,0,0,0,0,0,0,0,0,0,36,6,6,6,0,0,0,18,18,18,18,18,6,37,0,0,0,0,0,0,0,0,0
0,0,0,0,0,36,0,0,0,0,0,0,0,37,0,0,0,0,0,0,0,0,0,0,0,0,0,0,36,6,6,6,0,0,0,18,0,0,0,0,6,37,0,0,0,0,0,0,0,0,0
0,0,0,0,0,36,0,0,0,0,0,0,0,37,0,0,0,0,0,0,0,0,0,0,0,0,0,0,36,6,6,6,0,0,0,18,0,0,0,0,6,37,0,0,0,0,0,0,0,0,0
0,0,0,0,0,36,0,0,0,0,0,0,0,37,0,0,0,0,0,0,0,0,0,0,0,0,0,0,36,6,0,0,0,0,0,18,0,0,0,0,6,37,0,0,0,0,0,0,0,0,0
0,0,0,0,0,36,0,0,0,0,0,0,0,37,0,0,0,0,0,0,0,0,0,0,0,0,0,0,36,6,0,0,0,0,0,18,18,18,18,18,6,37,0,0,0,0,0,0,0,0,0
0,0,0,0,0,36,0,0,0,0,0,0,0,37,0,0,0,0,0,0,0,0,0,0,0,0,0,0,36,6,0,0,0,0,0,18,0,0,0,0,6,37,0,0,0,0,0,0,0,0,0
0,0,0,0,0,36,0,0,0,0,0,0,0,37,0,0,0,0,0,0,0,0,0,0,0,0,0,0,36,6,0,0,0,0,0,18,0,0,0,0,6,37,0,0,0,0,0,0,0,0,0
0,0,0,0,0,36,18,18,18,65,18,18,18,37,0,0,0,0,0,0,0,0,0,0,0,0,0,0,36,6,6,6,6,6,6,6,6,6,6,6,6,37,0,0,0,0,0,0,0,0,0
0,0,0,0,0,36,0,0,0,0,0,0,0,37,0,0,0,0,0,0,0,0,0,0,0,0,0,0,110,35,35,35,35,35,35,35,35,35,35,35,35,110,0,0,0,0,0,0,0,0,0
0,0,0,0,0,0,0,0,0,0,0,0,0,0,0,0,0,0,0,0,0,0,0,0,0,0,0,0,0,0,0,0,0,0,0,0,0,0,0,0,0,0,0,0,0,0,0,0,0,0,0
0,0,0,0,0,0,0,0,0,0,0,0,0,0,0,0,0,0,0,0,0,0,0,0,0,0,0,0,0,0,0,0,0,0,0,0,0,0,0,0,0,0,0,0,0,0,0,0,0,0,0
0,0,0,0,0,0,0,0,0,0,0,0,0,0,0,0,0,0,0,0,0,0,0,0,0,0,0,0,0,0,0,0,0,0,0,0,0,0,0,0,0,0,0,0,0,0,0,0,0,0,0
0,0,0,0,0,0,0,0,0,0,0,0,0,0,0,0,0,0,0,0,0,0,0,0,0,0,0,0,0,0,0,0,0,0,0,0,0,0,0,0,0,0,0,0,0,0,0,0,0,0,0
0,0,0,0,0,0,0,0,0,0,0,0,0,0,0,0,0,0,0,0,0,0,0,0,0,0,0,0,0,0,0,0,0,0,0,0,0,0,0,0,0,0,0,0,0,0,0,0,0,0,0
:endlayer
layer: 14
0,0,0,0,0,0,0,0,0,0,0,0,0,0,0,0,0,0,0,0,0,0,0,0,0,0,0,0,0,0,0,0,0,0,0,0,0,0,0,0,0,0,0,0,0,0,0,0,0,0,0
0,0,0,0,0,0,0,88,88,0,0,0,0,0,0,36,18,37,0,0,0,0,0,0,0,0,0,0,0,0,0,0,0,0,0,0,0,0,0,0,0,0,0,0,0,0,0,0,0,0,0
0,0,0,0,0,0,0,0,0,0,0,0,0,0,0,36,18,37,0,0,0,0,0,0,0,0,0,0,0,0,0,0,0,0,0,0,0,0,0,0,0,0,0,0,0,0,0,0,0,0,0
0,0,0,0,0,0,0,0,0,0,0,0,0,0,0,36,18,37,0,0,0,0,0,0,0,0,0,0,0,0,0,0,0,0,0,0,0,0,0,0,0,0,0,0,0,0,0,0,0,0,0
0,0,0,0,0,0,0,0,0,0,0,0,0,0,0,36,18,37,0,0,0,0,0,0,0,0,0,0,0,0,0,0,0,0,0,0,0,0,0,0,0,0,0,0,0,0,0,0,0,0,0
0,0,0,0,0,0,0,0,0,0,0,0,0,0,0,36,18,37,0,0,0,0,0,0,0,0,0,0,0,0,0,0,0,0,0,0,0,0,0,0,0,0,0,0,0,0,0,0,0,0,0
0,0,0,0,0,0,0,0,0,0,0,0,0,0,0,36,18,37,0,0,0,0,0,0,0,0,0,0,0,0,0,0,0,0,0,0,0,0,0,0,0,0,0,0,0,0,0,0,0,0,0
0,0,0,0,0,0,0,0,0,0,0,0,0,0,0,36,18,37,0,0,0,0,0,0,0,0,0,0,0,0,0,0,0,0,0,0,0,0,0,0,0,0,0,0,0,0,0,0,0,0,0
0,0,0,0,0,0,0,0,0,0,0,0,0,0,0,36,18,37,0,0,0,0,0,0,0,0,0,0,0,0,0,0,0,0,0,0,0,0,0,0,0,0,0,0,0,0,0,0,0,0,0
0,0,0,0,0,0,0,0,0,0,0,0,0,0,0,36,18,37,0,0,0,0,0,0,0,0,0,0,0,0,0,0,0,0,0,0,0,0,0,0,0,0,0,0,0,0,0,0,0,0,0
0,0,0,0,0,0,0,0,0,0,0,0,0,0,0,36,18,37,0,0,0,0,0,0,0,0,0,0,0,0,0,0,0,0,0,0,0,0,0,0,0,0,0,0,0,0,0,0,0,0,0
0,0,0,0,0,0,0,0,0,0,0,0,0,0,0,36,18,37,0,0,0,0,0,0,0,0,0,0,0,0,0,0,0,0,0,0,0,0,0,0,0,0,0,0,0,0,0,0,0,0,0
0,0,0,0,0,0,0,0,0,0,0,0,0,0,0,0,0,0,0,0,0,0,0,0,0,0,0,0,0,0,0,0,0,0,0,0,0,0,0,0,0,0,0,0,0,0,0,0,0,0,0
0,0,0,0,0,0,0,0,0,0,0,0,0,0,0,0,0,0,0,0,0,0,0,0,0,0,0,0,0,0,0,0,0,0,0,0,0,0,0,0,0,0,0,0,0,0,0,0,0,0,0
0,0,0,0,0,0,0,0,0,0,0,0,0,0,0,0,0,0,0,0,0,0,0,0,0,0,0,0,0,0,0,0,0,0,0,0,0,0,0,0,0,0,0,0,0,0,0,0,0,0,0
0,0,0,0,0,0,0,0,0,0,0,0,0,0,0,0,0,0,0,0,0,0,0,0,0,0,0,0,0,0,0,0,0,0,0,0,0,0,0,0,0,0,0,0,0,0,0,0,0,0,0
0,0,0,0,0,0,0,0,0,0,0,0,0,0,0,0,0,0,0,0,0,0,0,0,0,0,0,0,0,0,0,0,0,0,0,0,0,0,0,0,0,0,0,0,0,0,0,0,0,0,0
0,0,0,0,0,0,0,0,0,0,0,0,0,0,0,0,0,0,0,0,0,0,0,0,0,0,0,0,0,0,0,0,0,0,0,0,0,0,0,0,0,0,0,0,0,0,0,0,0,0,0
0,0,0,0,0,0,0,0,0,0,0,0,0,0,0,0,0,0,0,0,0,0,0,0,0,0,0,0,0,0,0,0,0,0,0,0,0,0,0,0,0,0,0,0,0,0,0,0,0,0,0
0,0,0,0,0,0,18,18,18,18,18,18,18,0,0,0,0,0,0,0,0,0,0,0,0,0,0,0,0,0,0,0,0,0,0,0,0,0,0,0,0,0,0,0,0,0,0,0,0,0,0
0,0,0,0,0,0,18,18,18,0,18,18,18,0,0,0,0,0,0,0,0,0,0,0,0,0,0,0,6,0,6,0,6,110,110,110,110,110,110,110,18,0,0,0,0,0,0,0,0,0,0
0,0,0,0,0,0,18,18,0,0,0,18,18,0,0,0,0,0,0,0,0,0,0,0,0,0,0,0,0,0,0,0,0,110,110,110,110,110,110,110,110,0,0,0,0,0,0,0,0,0,0
0,0,0,0,0,0,18,18,0,0,0,18,18,0,0,0,0,0,0,0,0,0,0,0,0,0,0,0,6,0,0,0,6,110,110,110,110,110,110,110,110,0,0,0,0,0,0,0,0,0,0
0,0,0,0,0,0,18,18,0,0,0,18,18,0,0,0,0,0,0,0,0,0,0,0,0,0,0,0,0,0,0,0,0,110,110,110,110,110,110,110,110,0,0,0,0,0,0,0,0,0,0
0,0,0,0,0,0,18,18,0,0,0,18,18,0,0,0,0,0,0,0,0,0,0,0,0,0,0,0,6,0,6,0,6,110,110,110,110,110,110,110,110,0,0,0,0,0,0,0,0,0,0
0,0,0,0,0,0,18,18,0,0,0,18,18,0,0,0,0,0,0,0,0,0,0,0,0,0,0,0,0,0,0,0,6,110,110,110,110,110,110,110,110,0,0,0,0,0,0,0,0,0,0
0,0,0,0,0,0,18,18,0,0,0,18,18,0,0,0,0,0,0,0,0,0,0,0,0,0,0,0,0,110,38,38,38,38,38,38,38,38,38,38,38,0,0,0,0,0,0,0,0,0,0
0,0,0,0,0,0,18,18,0,0,0,18,18,0,0,0,0,0,0,0,0,0,0,0,0,0,0,0,0,36,18,18,18,18,18,18,18,18,18,18,37,0,0,0,0,0,0,0,0,0,0
0,0,0,0,0,0,18,18,0,0,0,18,18,0,0,0,0,0,0,0,0,0,0,0,0,0,0,0,0,36,18,6,119,119,119,18,0,0,0,18,37,0,0,0,0,0,0,0,0,0,0
0,0,0,0,0,0,18,18,0,0,0,18,18,0,0,0,0,0,0,0,0,0,0,0,0,0,0,0,0,36,18,0,0,0,0,18,0,0,0,18,37,0,0,0,0,0,0,0,0,0,0
0,0,0,0,0,0,18,18,0,0,0,18,18,0,0,0,0,0,0,0,0,0,0,0,0,0,0,0,0,36,18,0,0,0,0,18,18,18,18,18,37,0,0,0,0,0,0,0,0,0,0
0,0,0,0,0,0,18,18,0,0,0,18,18,0,0,0,0,0,0,0,0,0,0,0,0,0,0,0,0,36,18,119,119,119,119,18,0,0,0,18,37,0,0,0,0,0,0,0,0,0,0
0,0,0,0,0,0,18,18,18,0,18,18,18,0,0,0,0,0,0,0,0,0,0,0,0,0,0,0,0,36,18,18,18,18,18,18,18,18,18,18,37,0,0,0,0,0,0,0,0,0,0
0,0,0,0,0,0,18,18,18,18,18,18,18,0,0,0,0,0,0,0,0,0,0,0,0,0,0,0,0,110,35,35,35,35,35,35,35,35,35,35,110,0,0,0,0,0,0,0,0,0,0
0,0,0,0,0,0,36,108,108,0,108,108,37,0,0,0,0,0,0,0,0,0,0,0,0,0,0,0,0,0,0,0,0,0,0,0,0,0,0,0,0,0,0,0,0,0,0,0,0,0,0
0,0,0,0,0,0,0,0,0,0,0,0,0,0,0,0,0,0,0,0,0,0,0,0,0,0,0,0,0,0,0,0,0,0,0,0,0,0,0,0,0,0,0,0,0,0,0,0,0,0,0
0,0,0,0,0,0,0,0,0,0,0,0,0,0,0,0,0,0,0,0,0,0,0,0,0,0,0,0,0,0,0,0,0,0,0,0,0,0,0,0,0,0,0,0,0,0,0,0,0,0,0
0,0,0,0,0,0,0,0,0,0,0,0,0,0,0,0,0,0,0,0,0,0,0,0,0,0,0,0,0,0,0,0,0,0,0,0,0,0,0,0,0,0,0,0,0,0,0,0,0,0,0
0,0,0,0,0,0,0,0,0,0,0,0,0,0,0,0,0,0,0,0,0,0,0,0,0,0,0,0,0,0,0,0,0,0,0,0,0,0,0,0,0,0,0,0,0,0,0,0,0,0,0
0,0,0,0,0,0,0,0,0,0,0,0,0,0,0,0,0,0,0,0,0,0,0,0,0,0,0,0,0,0,0,0,0,0,0,0,0,0,0,0,0,0,0,0,0,0,0,0,0,0,0
:endlayer
layer: 15
0,0,0,0,0,0,0,0,0,0,0,0,0,0,0,0,0,0,0,0,0,0,0,0,0,0,0,0,0,0,0,0,0,0,0,0,0,0,0,0,0,0,0,0,0,0,0,0,0,0,0
0,0,0,0,0,0,0,0,0,0,0,0,0,0,0,0,88,0,0,0,0,0,0,0,0,0,0,0,0,0,0,0,0,0,0,0,0,0,0,0,0,0,0,0,0,0,0,0,0,0,0
0,0,0,0,0,0,0,0,0,0,0,0,0,0,0,0,0,0,0,0,0,0,0,0,0,0,0,0,0,0,0,0,0,0,0,0,0,0,0,0,0,0,0,0,0,0,0,0,0,0,0
0,0,0,0,0,0,0,0,0,0,0,0,0,0,0,0,0,0,0,0,0,0,0,0,0,0,0,0,0,0,0,0,0,0,0,0,0,0,0,0,0,0,0,0,0,0,0,0,0,0,0
0,0,0,0,0,0,0,0,0,0,0,0,0,0,0,0,0,0,0,0,0,0,0,0,0,0,0,0,0,0,0,0,0,0,0,0,0,0,0,0,0,0,0,0,0,0,0,0,0,0,0
0,0,0,0,0,0,0,0,0,0,0,0,0,0,0,0,0,0,0,0,0,0,0,0,0,0,0,0,0,0,0,0,0,0,0,0,0,0,0,0,0,0,0,0,0,0,0,0,0,0,0
0,0,0,0,0,0,0,0,0,0,0,0,0,0,0,0,0,0,0,0,0,0,0,0,0,0,0,0,0,0,0,0,0,0,0,0,0,0,0,0,0,0,0,0,0,0,0,0,0,0,0
0,0,0,0,0,0,0,0,0,0,0,0,0,0,0,0,0,0,0,0,0,0,0,0,0,0,0,0,0,0,0,0,0,0,0,0,0,0,0,0,0,0,0,0,0,0,0,0,0,0,0
0,0,0,0,0,0,0,0,0,0,0,0,0,0,0,0,0,0,0,0,0,0,0,0,0,0,0,0,0,0,0,0,0,0,0,0,0,0,0,0,0,0,0,0,0,0,0,0,0,0,0
0,0,0,0,0,0,0,0,0,0,0,0,0,0,0,0,0,0,0,0,0,0,0,0,0,0,0,0,0,0,0,0,0,0,0,0,0,0,0,0,0,0,0,0,0,0,0,0,0,0,0
0,0,0,0,0,0,0,0,0,0,0,0,0,0,0,0,0,0,0,0,0,0,0,0,0,0,0,0,0,0,0,0,0,0,0,0,0,0,0,0,0,0,0,0,0,0,0,0,0,0,0
0,0,0,0,0,0,0,0,0,0,0,0,0,0,0,0,88,0,0,0,0,0,0,0,0,0,0,0,0,0,0,0,0,0,0,0,0,0,0,0,0,0,0,0,0,0,0,0,0,0,0
0,0,0,0,0,0,0,0,0,0,0,0,0,0,0,0,0,0,0,0,0,0,0,0,0,0,0,0,0,0,0,0,0,0,0,0,0,0,0,0,0,0,0,0,0,0,0,0,0,0,0
0,0,0,0,0,0,0,0,0,0,0,0,0,0,0,0,0,0,0,0,0,0,0,0,0,0,0,0,0,0,0,0,0,0,0,0,0,0,0,0,0,0,0,0,0,0,0,0,0,0,0
0,0,0,0,0,0,0,0,0,0,0,0,0,0,0,0,0,0,0,0,0,0,0,0,0,0,0,0,0,0,0,0,0,0,0,0,0,0,0,0,0,0,0,0,0,0,0,0,0,0,0
0,0,0,0,0,0,0,0,0,0,0,0,0,0,0,0,0,0,0,0,0,0,0,0,0,0,0,0,0,0,0,0,0,0,0,0,0,0,0,0,0,0,0,0,0,0,0,0,0,0,0
0,0,0,0,0,0,0,0,0,0,0,0,0,0,0,0,0,0,0,0,0,0,0,0,0,0,0,0,0,0,0,0,0,0,0,0,0,0,0,0,0,0,0,0,0,0,0,0,0,0,0
0,0,0,0,0,0,0,0,0,0,0,0,0,0,0,0,0,0,0,0,0,0,0,0,0,0,0,0,0,0,0,0,0,0,0,0,0,0,0,0,0,0,0,0,0,0,0,0,0,0,0
0,0,0,0,0,0,0,0,0,0,0,0,0,0,0,0,0,0,0,0,0,0,0,0,0,0,0,0,0,0,0,0,0,0,0,0,0,0,0,0,0,0,0,0,0,0,0,0,0,0,0
0,0,0,0,0,0,0,0,110,18,110,0,0,0,0,0,0,0,0,0,0,0,0,0,0,0,0,0,0,0,0,0,0,0,0,0,0,0,0,0,0,0,0,0,0,0,0,0,0,0,0
0,0,0,0,0,0,0,0,36,18,37,0,0,0,0,0,0,0,0,0,0,0,0,0,0,0,0,0,6,0,6,0,6,0,0,0,0,0,0,0,88,0,0,0,0,0,0,0,0,0,0
0,0,0,0,0,0,0,0,36,18,37,0,0,0,0,0,0,0,0,0,0,0,0,0,0,0,0,0,0,0,0,0,0,0,0,0,0,0,0,0,0,0,0,0,0,0,0,0,0,0,0
0,0,0,0,0,0,0,0,36,18,37,0,0,0,0,0,0,0,0,0,0,0,0,0,0,0,0,0,6,0,0,0,6,0,0,0,0,0,0,0,0,0,0,0,0,0,0,0,0,0,0
0,0,0,0,0,0,0,0,36,18,37,0,0,0,0,0,0,0,0,0,0,0,0,0,0,0,0,0,0,0,0,0,0,0,0,0,0,0,0,0,0,0,0,0,0,0,0,0,0,0,0
0,0,0,0,0,0,0,0,36,18,37,0,0,0,0,0,0,0,0,0,0,0,0,0,0,0,0,0,6,0,6,0,6,0,0,0,0,0,0,0,0,0,0,0,0,0,0,0,0,0,0
0,0,0,0,0,0,0,0,36,18,37,0,0,0,0,0,0,0,0,0,0,0,0,0,0,0,0,0,0,0,0,0,0,0,0,0,0,0,0,0,0,0,0,0,0,0,0,0,0,0,0
0,0,0,0,0,0,0,0,36,18,37,0,0,0,0,0,0,0,0,0,0,0,0,0,0,0,0,0,0,0,0,0,0,0,0,0,0,0,0,0,0,0,0,0,0,0,0,0,0,0,0
0,0,0,0,0,0,0,0,36,18,37,0,0,0,0,0,0,0,0,0,0,0,0,0,0,0,0,0,0,0,110,38,38,38,38,38,38,38,38,37,0,0,0,0,0,0,0,0,0,0,0
0,0,0,0,0,0,0,0,36,18,37,0,0,0,0,0,0,0,0,0,0,0,0,0,0,0,0,0,0,0,36,18,18,18,18,18,18,18,18,37,0,0,0,0,0,0,0,0,0,0,0
0,0,0,0,0,0,0,0,36,18,37,0,0,0,0,0,0,0,0,0,0,0,0,0,0,0,0,0,0,0,36,18,0,0,18,18,18,18,18,37,0,0,0,0,0,0,0,0,0,0,0
0,0,0,0,0,0,0,0,36,18,37,0,0,0,0,0,0,0,0,0,0,0,0,0,0,0,0,0,0,0,36,18,0,0,18,18,18,18,18,37,0,0,0,0,0,0,0,0,0,0,0
0,0,0,0,0,0,0,0,36,18,37,0,0,0,0,0,0,0,0,0,0,0,0,0,0,0,0,0,0,0,36,18,18,18,18,18,18,18,18,37,0,0,0,0,0,0,0,0,0,0,0
0,0,0,0,0,0,0,0,36,18,37,0,0,0,0,0,0,0,0,0,0,0,0,0,0,0,0,0,0,0,110,35,35,35,35,35,35,35,35,110,0,0,0,0,0,0,0,0,0,0,0
0,0,0,0,0,0,0,0,110,18,110,0,0,0,0,0,0,0,0,0,0,0,0,0,0,0,0,0,0,0,0,0,0,0,0,0,0,0,0,0,0,0,0,0,0,0,0,0,0,0,0
0,0,0,0,0,0,0,0,110,18,110,0,0,0,0,0,0,0,0,0,0,0,0,0,0,0,0,0,0,0,0,0,0,0,0,0,0,0,0,0,0,0,0,0,0,0,0,0,0,0,0
0,0,0,0,0,0,0,0,0,0,0,0,0,0,0,0,0,0,0,0,0,0,0,0,0,0,0,0,0,0,0,0,0,0,0,0,0,0,0,0,0,0,0,0,0,0,0,0,0,0,0
0,0,0,0,0,0,0,0,0,0,0,0,0,0,0,0,0,0,0,0,0,0,0,0,0,0,0,0,0,0,0,0,0,0,0,0,0,0,0,0,0,0,0,0,0,0,0,0,0,0,0
0,0,0,0,0,0,0,0,0,0,0,0,0,0,0,0,0,0,0,0,0,0,0,0,0,0,0,0,0,0,0,0,0,0,0,0,0,0,0,0,0,0,0,0,0,0,0,0,0,0,0
0,0,0,0,0,0,0,0,0,0,0,0,0,0,0,0,0,0,0,0,0,0,0,0,0,0,0,0,0,0,0,0,0,0,0,0,0,0,0,0,0,0,0,0,0,0,0,0,0,0,0
0,0,0,0,0,0,0,0,0,0,0,0,0,0,0,0,0,0,0,0,0,0,0,0,0,0,0,0,0,0,0,0,0,0,0,0,0,0,0,0,0,0,0,0,0,0,0,0,0,0,0
:endlayer
layer: 16
0,0,0,0,0,0,0,0,0,0,0,0,0,0,0,0,0,0,0,0,0,0,0,0,0,0,0,0,0,0,0,0,0,0,0,0,0,0,0,0,0,0,0,0,0,0,0,0,0,0,0
0,0,0,0,0,0,0,0,0,0,0,0,0,0,0,0,0,0,0,0,0,0,0,0,0,0,0,0,0,0,0,0,0,0,0,0,0,0,0,0,0,0,0,0,0,0,0,0,0,0,0
0,0,0,0,0,0,0,0,0,0,0,0,0,0,0,0,0,0,0,0,0,0,0,0,0,0,0,0,0,0,0,0,0,0,0,0,0,0,0,0,0,0,0,0,0,0,0,0,0,0,0
0,0,0,0,0,0,0,0,0,0,0,0,0,0,0,0,0,0,0,0,0,0,0,0,0,0,0,0,0,0,0,0,0,0,0,0,0,0,0,0,0,0,0,0,0,0,0,0,0,0,0
0,0,0,0,0,0,0,0,0,0,0,0,0,0,0,0,0,0,0,0,0,0,0,0,0,0,0,0,0,0,0,0,0,0,0,0,0,0,0,0,0,0,0,0,0,0,0,0,0,0,0
0,0,0,0,0,0,0,0,0,0,0,0,0,0,0,0,0,0,0,0,0,0,0,0,0,0,0,0,0,0,0,0,0,0,0,0,0,0,0,0,0,0,0,0,0,0,0,0,0,0,0
0,0,0,0,0,0,0,0,0,0,0,0,0,0,0,0,0,0,0,0,0,0,0,0,0,0,0,0,0,0,0,0,0,0,0,0,0,0,0,0,0,0,0,0,0,0,0,0,0,0,0
0,0,0,0,0,0,0,0,0,0,0,0,0,0,0,0,0,0,0,0,0,0,0,0,0,0,0,0,0,0,0,0,0,0,0,0,0,0,0,0,0,0,0,0,0,0,0,0,0,0,0
0,0,0,0,0,0,0,0,0,0,0,0,0,0,0,0,0,0,0,0,0,0,0,0,0,0,0,0,0,0,0,0,0,0,0,0,0,0,0,0,0,0,0,0,0,0,0,0,0,0,0
0,0,0,0,0,0,0,0,0,0,0,0,0,0,0,0,0,0,0,0,0,0,0,0,0,0,0,0,0,0,0,0,0,0,0,0,0,0,0,0,0,0,0,0,0,0,0,0,0,0,0
0,0,0,0,0,0,0,0,0,0,0,0,0,0,0,0,0,0,0,0,0,0,0,0,0,0,0,0,0,0,0,0,0,0,0,0,0,0,0,0,0,0,0,0,0,0,0,0,0,0,0
0,0,0,0,0,0,0,0,0,0,0,0,0,0,0,0,0,0,0,0,0,0,0,0,0,0,0,0,0,0,0,0,0,0,0,0,0,0,0,0,0,0,0,0,0,0,0,0,0,0,0
0,0,0,0,0,0,0,0,0,0,0,0,0,0,0,0,0,0,0,0,0,0,0,0,0,0,0,0,0,0,0,0,0,0,0,0,0,0,0,0,0,0,0,0,0,0,0,0,0,0,0
0,0,0,0,0,0,0,0,0,0,0,0,0,0,0,0,0,0,0,0,0,0,0,0,0,0,0,0,0,0,0,0,0,0,0,0,0,0,0,0,0,0,0,0,0,0,0,0,0,0,0
0,0,0,0,0,0,0,0,0,0,0,0,0,0,0,0,0,0,0,0,0,0,0,0,0,0,0,0,0,0,0,0,0,0,0,0,0,0,0,0,0,0,0,0,0,0,0,0,0,0,0
0,0,0,0,0,0,0,0,0,0,0,0,0,0,0,0,0,0,0,0,0,0,0,0,0,0,0,0,0,0,0,0,0,0,0,0,0,0,0,0,0,0,0,0,0,0,0,0,0,0,0
0,0,0,0,0,0,0,0,0,0,0,0,0,0,0,0,0,0,0,0,0,0,0,0,0,0,0,0,0,0,0,0,0,0,0,0,0,0,0,0,0,0,0,0,0,0,0,0,0,0,0
0,0,0,0,0,0,0,0,0,0,0,0,0,0,0,0,0,0,0,0,0,0,0,0,0,0,0,0,0,0,0,0,0,0,0,0,0,0,0,0,0,0,0,0,0,0,0,0,0,0,0
0,0,0,0,0,0,0,0,0,0,0,0,0,0,0,0,0,0,0,0,0,0,0,0,0,0,0,0,0,0,0,0,0,0,0,0,0,0,0,0,0,0,0,0,0,0,0,0,0,0,0
0,0,0,0,0,0,0,0,0,88,0,0,0,0,0,0,0,0,0,0,0,0,0,0,0,0,0,36,38,38,38,38,38,37,0,0,0,0,0,0,0,0,0,0,0,0,0,0,0,0,0
0,0,0,0,0,0,0,0,0,0,0,0,0,0,0,0,0,0,0,0,0,0,0,0,0,0,0,36,6,6,6,6,6,37,0,0,0,0,0,0,0,0,0,0,0,0,0,0,0,0,0
0,0,0,0,0,0,0,0,0,0,0,0,0,0,0,0,0,0,0,0,0,0,0,0,0,0,0,36,6,0,0,0,6,37,0,0,0,0,0,0,0,0,0,0,0,0,0,0,0,0,0
0,0,0,0,0,0,0,0,0,0,0,0,0,0,0,0,0,0,0,0,0,0,0,0,0,0,0,36,6,55,0,0,6,37,0,0,0,0,0,0,0,0,0,0,0,0,0,0,0,0,0
0,0,0,0,0,0,0,0,0,0,0,0,0,0,0,0,0,0,0,0,0,0,0,0,0,0,0,36,6,0,89,0,6,37,0,0,0,0,0,0,0,0,0,0,0,0,0,0,0,0,0
0,0,0,0,0,0,0,0,0,0,0,0,0,0,0,0,0,0,0,0,0,0,0,0,0,0,0,36,6,6,6,6,6,37,0,0,0,0,0,0,0,0,0,0,0,0,0,0,0,0,0
0,0,0,0,0,0,0,0,0,0,0,0,0,0,0,0,0,0,0,0,0,0,0,0,0,0,0,36,35,35,35,35,35,37,0,0,0,0,0,0,0,0,0,0,0,0,0,0,0,0,0
0,0,0,0,0,0,0,0,0,0,0,0,0,0,0,0,0,0,0,0,0,0,0,0,0,0,0,0,0,0,0,0,0,0,0,0,0,0,0,0,0,0,0,0,0,0,0,0,0,0,0
0,0,0,0,0,0,0,0,0,0,0,0,0,0,0,0,0,0,0,0,0,0,0,0,0,0,0,0,0,0,0,0,0,0,0,0,0,0,0,0,0,0,0,0,0,0,0,0,0,0,0
0,0,0,0,0,0,0,0,0,0,0,0,0,0,0,0,0,0,0,0,0,0,0,0,0,0,0,0,0,0,0,110,38,38,38,38,38,38,37,0,0,0,0,0,0,0,0,0,0,0,0
0,0,0,0,0,0,0,0,0,0,0,0,0,0,0,0,0,0,0,0,0,0,0,0,0,0,0,0,0,0,0,36,18,18,18,18,18,18,37,0,0,0,0,0,0,0,0,0,0,0,0
0,0,0,0,0,0,0,0,0,0,0,0,0,0,0,0,0,0,0,0,0,0,0,0,0,0,0,0,0,0,0,36,18,18,18,18,18,18,37,0,0,0,0,0,0,0,0,0,0,0,0
0,0,0,0,0,0,0,0,0,0,0,0,0,0,0,0,0,0,0,0,0,0,0,0,0,0,0,0,0,0,0,110,35,35,35,35,35,35,110,0,0,0,0,0,0,0,0,0,0,0,0
0,0,0,0,0,0,0,0,0,0,0,0,0,0,0,0,0,0,0,0,0,0,0,0,0,0,0,0,0,0,0,0,0,0,0,0,0,0,0,0,0,0,0,0,0,0,0,0,0,0,0
0,0,0,0,0,0,0,0,0,0,0,0,0,0,0,0,0,0,0,0,0,0,0,0,0,0,0,0,0,0,0,0,0,0,0,0,0,0,0,0,0,0,0,0,0,0,0,0,0,0,0
0,0,0,0,0,0,0,0,0,88,0,0,0,0,0,0,0,0,0,0,0,0,0,0,0,0,0,0,0,0,0,0,0,0,0,0,0,0,0,0,0,0,0,0,0,0,0,0,0,0,0
0,0,0,0,0,0,0,0,0,0,0,0,0,0,0,0,0,0,0,0,0,0,0,0,0,0,0,0,0,0,0,0,0,0,0,0,0,0,0,0,0,0,0,0,0,0,0,0,0,0,0
0,0,0,0,0,0,0,0,0,0,0,0,0,0,0,0,0,0,0,0,0,0,0,0,0,0,0,0,0,0,0,0,0,0,0,0,0,0,0,0,0,0,0,0,0,0,0,0,0,0,0
0,0,0,0,0,0,0,0,0,0,0,0,0,0,0,0,0,0,0,0,0,0,0,0,0,0,0,0,0,0,0,0,0,0,0,0,0,0,0,0,0,0,0,0,0,0,0,0,0,0,0
0,0,0,0,0,0,0,0,0,0,0,0,0,0,0,0,0,0,0,0,0,0,0,0,0,0,0,0,0,0,0,0,0,0,0,0,0,0,0,0,0,0,0,0,0,0,0,0,0,0,0
0,0,0,0,0,0,0,0,0,0,0,0,0,0,0,0,0,0,0,0,0,0,0,0,0,0,0,0,0,0,0,0,0,0,0,0,0,0,0,0,0,0,0,0,0,0,0,0,0,0,0
:endlayer
layer: 17
0,0,0,0,0,0,0,0,0,0,0,0,0,0,0,0,0,0,0,0,0,0,0,0,0,0,0,0,0,0,0,0,0,0,0,0,0,0,0,0,0,0,0,0,0,0,0,0,0,0,0
0,0,0,0,0,0,0,0,0,0,0,0,0,0,0,0,0,0,0,0,0,0,0,0,0,0,0,0,0,0,0,0,0,0,0,0,0,0,0,0,0,0,0,0,0,0,0,0,0,0,0
0,0,0,0,0,0,0,0,0,0,0,0,0,0,0,0,0,0,0,0,0,0,0,0,0,0,0,0,0,0,0,0,0,0,0,0,0,0,0,0,0,0,0,0,0,0,0,0,0,0,0
0,0,0,0,0,0,0,0,0,0,0,0,0,0,0,0,0,0,0,0,0,0,0,0,0,0,0,0,0,0,0,0,0,0,0,0,0,0,0,0,0,0,0,0,0,0,0,0,0,0,0
0,0,0,0,0,0,0,0,0,0,0,0,0,0,0,0,0,0,0,0,0,0,0,0,0,0,0,0,0,0,0,0,0,0,0,0,0,0,0,0,0,0,0,0,0,0,0,0,0,0,0
0,0,0,0,0,0,0,0,0,0,0,0,0,0,0,0,0,0,0,0,0,0,0,0,0,0,0,0,0,0,0,0,0,0,0,0,0,0,0,0,0,0,0,0,0,0,0,0,0,0,0
0,0,0,0,0,0,0,0,0,0,0,0,0,0,0,0,0,0,0,0,0,0,0,0,0,0,0,0,0,0,0,0,0,0,0,0,0,0,0,0,0,0,0,0,0,0,0,0,0,0,0
0,0,0,0,0,0,0,0,0,0,0,0,0,0,0,0,0,0,0,0,0,0,0,0,0,0,0,0,0,0,0,0,0,0,0,0,0,0,0,0,0,0,0,0,0,0,0,0,0,0,0
0,0,0,0,0,0,0,0,0,0,0,0,0,0,0,0,0,0,0,0,0,0,0,0,0,0,0,0,0,0,0,0,0,0,0,0,0,0,0,0,0,0,0,0,0,0,0,0,0,0,0
0,0,0,0,0,0,0,0,0,0,0,0,0,0,0,0,0,0,0,0,0,0,0,0,0,0,0,0,0,0,0,0,0,0,0,0,0,0,0,0,0,0,0,0,0,0,0,0,0,0,0
0,0,0,0,0,0,0,0,0,0,0,0,0,0,0,0,0,0,0,0,0,0,0,0,0,0,0,0,0,0,0,0,0,0,0,0,0,0,0,0,0,0,0,0,0,0,0,0,0,0,0
0,0,0,0,0,0,0,0,0,0,0,0,0,0,0,0,0,0,0,0,0,0,0,0,0,0,0,0,0,0,0,0,0,0,0,0,0,0,0,0,0,0,0,0,0,0,0,0,0,0,0
0,0,0,0,0,0,0,0,0,0,0,0,0,0,0,0,0,0,0,0,0,0,0,0,0,0,0,0,0,0,0,0,0,0,0,0,0,0,0,0,0,0,0,0,0,0,0,0,0,0,0
0,0,0,0,0,0,0,0,0,0,0,0,0,0,0,0,0,0,0,0,0,0,0,0,0,0,0,0,0,0,0,0,0,0,0,0,0,0,0,0,0,0,0,0,0,0,0,0,0,0,0
0,0,0,0,0,0,0,0,0,0,0,0,0,0,0,0,0,0,0,0,0,0,0,0,0,0,0,0,0,0,0,0,0,0,0,0,0,0,0,0,0,0,0,0,0,0,0,0,0,0,0
0,0,0,0,0,0,0,0,0,0,0,0,0,0,0,0,0,0,0,0,0,0,0,0,0,0,0,0,0,0,0,0,0,0,0,0,0,0,0,0,0,0,0,0,0,0,0,0,0,0,0
0,0,0,0,0,0,0,0,0,0,0,0,0,0,0,0,0,0,0,0,0,0,0,0,0,0,0,0,0,0,0,0,0,0,0,0,0,0,0,0,0,0,0,0,0,0,0,0,0,0,0
0,0,0,0,0,0,0,0,0,0,0,0,0,0,0,0,0,0,0,0,0,0,0,0,0,0,0,0,0,0,0,0,0,0,0,0,0,0,0,0,0,0,0,0,0,0,0,0,0,0,0
0,0,0,0,0,0,0,0,0,0,0,0,0,0,0,0,0,0,0,0,0,0,0,0,0,0,0,0,0,0,0,0,0,0,0,0,0,0,0,0,0,0,0,0,0,0,0,0,0,0,0
0,0,0,0,0,0,0,0,0,0,0,0,0,0,0,0,0,0,0,0,0,0,0,0,0,0,0,0,0,0,0,0,0,0,0,0,0,0,0,0,0,0,0,0,0,0,0,0,0,0,0
0,0,0,0,0,0,0,0,0,0,0,0,0,0,0,0,0,0,0,0,0,0,0,0,0,0,0,0,38,38,38,38,37,0,0,0,0,0,0,0,0,0,0,0,0,0,0,0,0,0,0
0,0,0,0,0,0,0,0,0,0,0,0,0,0,0,0,0,0,0,0,0,0,0,0,0,0,0,0,36,18,0,18,37,0,0,0,0,0,0,0,0,0,0,0,0,0,0,0,0,0,0
0,0,0,0,0,0,0,0,0,0,0,0,0,0,0,0,0,0,0,0,0,0,0,0,0,0,0,0,36,0,0,0,37,0,0,0,0,0,0,0,0,0,0,0,0,0,0,0,0,0,0
0,0,0,0,0,0,0,0,0,0,0,0,0,0,0,0,0,0,0,0,0,0,0,0,0,0,0,0,36,18,0,18,37,0,0,0,0,0,0,0,0,0,0,0,0,0,0,0,0,0,0
0,0,0,0,0,0,0,0,0,0,0,0,0,0,0,0,0,0,0,0,0,0,0,0,0,0,0,0,36,35,35,35,35,0,0,0,0,0,0,0,0,0,0,0,0,0,0,0,0,0,0
0,0,0,0,0,0,0,0,0,0,0,0,0,0,0,0,0,0,0,0,0,0,0,0,0,0,0,0,0,0,0,0,0,0,0,0,0,0,0,0,0,0,0,0,0,0,0,0,0,0,0
0,0,0,0,0,0,0,0,0,0,0,0,0,0,0,0,0,0,0,0,0,0,0,0,0,0,0,0,0,0,0,0,0,0,0,0,0,0,0,0,0,0,0,0,0,0,0,0,0,0,0
0,0,0,0,0,0,0,0,0,0,0,0,0,0,0,0,0,0,0,0,0,0,0,0,0,0,0,0,0,0,0,0,0,0,0,0,0,0,0,0,0,0,0,0,0,0,0,0,0,0,0
0,0,0,0,0,0,0,0,0,0,0,0,0,0,0,0,0,0,0,0,0,0,0,0,0,0,0,0,0,0,0,0,0,0,0,0,0,0,0,0,0,0,0,0,0,0,0,0,0,0,0
0,0,0,0,0,0,0,0,0,0,0,0,0,0,0,0,0,0,0,0,0,0,0,0,0,0,0,0,0,0,0,0,110,38,38,38,38,110,0,0,0,0,0,0,0,0,0,0,0,0,0
0,0,0,0,0,0,0,0,0,0,0,0,0,0,0,0,0,0,0,0,0,0,0,0,0,0,0,0,0,0,0,0,110,35,35,35,35,110,0,0,0,0,0,0,0,0,0,0,0,0,0
0,0,0,0,0,0,0,0,0,0,0,0,0,0,0,0,0,0,0,0,0,0,0,0,0,0,0,0,0,0,0,0,0,0,0,0,0,0,0,0,0,0,0,0,0,0,0,0,0,0,0
0,0,0,0,0,0,0,0,0,0,0,0,0,0,0,0,0,0,0,0,0,0,0,0,0,0,0,0,0,0,0,0,0,0,0,0,0,0,0,0,0,0,0,0,0,0,0,0,0,0,0
0,0,0,0,0,0,0,0,0,0,0,0,0,0,0,0,0,0,0,0,0,0,0,0,0,0,0,0,0,0,0,0,0,0,0,0,0,0,0,0,0,0,0,0,0,0,0,0,0,0,0
0,0,0,0,0,0,0,0,0,0,0,0,0,0,0,0,0,0,0,0,0,0,0,0,0,0,0,0,0,0,0,0,0,0,0,0,0,0,0,0,0,0,0,0,0,0,0,0,0,0,0
0,0,0,0,0,0,0,0,0,0,0,0,0,0,0,0,0,0,0,0,0,0,0,0,0,0,0,0,0,0,0,0,0,0,0,0,0,0,0,0,0,0,0,0,0,0,0,0,0,0,0
0,0,0,0,0,0,0,0,0,0,0,0,0,0,0,0,0,0,0,0,0,0,0,0,0,0,0,0,0,0,0,0,0,0,0,0,0,0,0,0,0,0,0,0,0,0,0,0,0,0,0
0,0,0,0,0,0,0,0,0,0,0,0,0,0,0,0,0,0,0,0,0,0,0,0,0,0,0,0,0,0,0,0,0,0,0,0,0,0,0,0,0,0,0,0,0,0,0,0,0,0,0
0,0,0,0,0,0,0,0,0,0,0,0,0,0,0,0,0,0,0,0,0,0,0,0,0,0,0,0,0,0,0,0,0,0,0,0,0,0,0,0,0,0,0,0,0,0,0,0,0,0,0
0,0,0,0,0,0,0,0,0,0,0,0,0,0,0,0,0,0,0,0,0,0,0,0,0,0,0,0,0,0,0,0,0,0,0,0,0,0,0,0,0,0,0,0,0,0,0,0,0,0,0
:endlayer
layer: 18
0,0,0,0,0,0,0,0,0,0,0,0,0,0,0,0,0,0,0,0,0,0,0,0,0,0,0,0,0,0,0,0,0,0,0,0,0,0,0,0,0,0,0,0,0,0,0,0,0,0,0
0,0,0,0,0,0,0,0,0,0,0,0,0,0,0,0,0,0,0,0,0,0,0,0,0,0,0,0,0,0,0,0,0,0,0,0,0,0,0,0,0,0,0,0,0,0,0,0,0,0,0
0,0,0,0,0,0,0,0,0,0,0,0,0,0,0,0,0,0,0,0,0,0,0,0,0,0,0,0,0,0,0,0,0,0,0,0,0,0,0,0,0,0,0,0,0,0,0,0,0,0,0
0,0,0,0,0,0,0,0,0,0,0,0,0,0,0,0,0,0,0,0,0,0,0,0,0,0,0,0,0,0,0,0,0,0,0,0,0,0,0,0,0,0,0,0,0,0,0,0,0,0,0
0,0,0,0,0,0,0,0,0,0,0,0,0,0,0,0,0,0,0,0,0,0,0,0,0,0,0,0,0,0,0,0,0,0,0,0,0,0,0,0,0,0,0,0,0,0,0,0,0,0,0
0,0,0,0,0,0,0,0,0,0,0,0,0,0,0,0,0,0,0,0,0,0,0,0,0,0,0,0,0,0,0,0,0,0,0,0,0,0,0,0,0,0,0,0,0,0,0,0,0,0,0
0,0,0,0,0,0,0,0,0,0,0,0,0,0,0,0,0,0,0,0,0,0,0,0,0,0,0,0,0,0,0,0,0,0,0,0,0,0,0,0,0,0,0,0,0,0,0,0,0,0,0
0,0,0,0,0,0,0,0,0,0,0,0,0,0,0,0,0,0,0,0,0,0,0,0,0,0,0,0,0,0,0,0,0,0,0,0,0,0,0,0,0,0,0,0,0,0,0,0,0,0,0
0,0,0,0,0,0,0,0,0,0,0,0,0,0,0,0,0,0,0,0,0,0,0,0,0,0,0,0,0,0,0,0,0,0,0,0,0,0,0,0,0,0,0,0,0,0,0,0,0,0,0
0,0,0,0,0,0,0,0,0,0,0,0,0,0,0,0,0,0,0,0,0,0,0,0,0,0,0,0,0,0,0,0,0,0,0,0,0,0,0,0,0,0,0,0,0,0,0,0,0,0,0
0,0,0,0,0,0,0,0,0,0,0,0,0,0,0,0,0,0,0,0,0,0,0,0,0,0,0,0,0,0,0,0,0,0,0,0,0,0,0,0,0,0,0,0,0,0,0,0,0,0,0
0,0,0,0,0,0,0,0,0,0,0,0,0,0,0,0,0,0,0,0,0,0,0,0,0,0,0,0,0,0,0,0,0,0,0,0,0,0,0,0,0,0,0,0,0,0,0,0,0,0,0
0,0,0,0,0,0,0,0,0,0,0,0,0,0,0,0,0,0,0,0,0,0,0,0,0,0,0,0,0,0,0,0,0,0,0,0,0,0,0,0,0,0,0,0,0,0,0,0,0,0,0
0,0,0,0,0,0,0,0,0,0,0,0,0,0,0,0,0,0,0,0,0,0,0,0,0,0,0,0,0,0,0,0,0,0,0,0,0,0,0,0,0,0,0,0,0,0,0,0,0,0,0
0,0,0,0,0,0,0,0,0,0,0,0,0,0,0,0,0,0,0,0,0,0,0,0,0,0,0,0,0,0,0,0,0,0,0,0,0,0,0,0,0,0,0,0,0,0,0,0,0,0,0
0,0,0,0,0,0,0,0,0,0,0,0,0,0,0,0,0,0,0,0,0,0,0,0,0,0,0,0,0,0,0,0,0,0,0,0,0,0,0,0,0,0,0,0,0,0,0,0,0,0,0
0,0,0,0,0,0,0,0,0,0,0,0,0,0,0,0,0,0,0,0,0,0,0,0,0,0,0,0,0,0,0,0,0,0,0,0,0,0,0,0,0,0,0,0,0,0,0,0,0,0,0
0,0,0,0,0,0,0,0,0,0,0,0,0,0,0,0,0,0,0,0,0,0,0,0,0,0,0,0,0,0,0,0,0,0,0,0,0,0,0,0,0,0,0,0,0,0,0,0,0,0,0
0,0,0,0,0,0,0,0,0,0,0,0,0,0,0,0,0,0,0,0,0,0,0,0,0,0,0,0,0,0,0,0,0,0,0,0,0,0,0,0,0,0,0,0,0,0,0,0,0,0,0
0,0,0,0,0,0,0,0,0,0,0,0,0,0,0,0,0,0,0,0,0,0,0,0,0,0,0,0,0,0,0,0,0,0,0,0,0,0,0,0,0,0,0,0,0,0,0,0,0,0,0
0,0,0,0,0,0,0,0,0,0,0,0,0,0,0,0,0,0,0,0,0,0,0,0,0,0,0,0,0,0,0,0,0,0,0,0,0,0,0,0,0,0,0,0,0,0,0,0,0,0,0
0,0,0,0,0,0,0,0,0,0,0,0,0,0,0,0,0,0,0,0,0,0,0,0,0,0,0,0,0,38,38,38,0,0,0,0,0,0,0,0,0,0,0,0,0,0,0,0,0,0,0
0,0,0,0,0,0,0,0,0,0,0,0,0,0,0,0,0,0,0,0,0,0,0,0,0,0,0,0,0,36,18,37,0,0,0,0,0,0,0,0,0,0,0,0,0,0,0,0,0,0,0
0,0,0,0,0,0,0,0,0,0,0,0,0,0,0,0,0,0,0,0,0,0,0,0,0,0,0,0,0,35,35,35,0,0,0,0,0,0,0,0,0,0,0,0,0,0,0,0,0,0,0
0,0,0,0,0,0,0,0,0,0,0,0,0,0,0,0,0,0,0,0,0,0,0,0,0,0,0,0,0,0,0,0,0,0,0,0,0,0,0,0,0,0,0,0,0,0,0,0,0,0,0
0,0,0,0,0,0,0,0,0,0,0,0,0,0,0,0,0,0,0,0,0,0,0,0,0,0,0,0,0,0,0,0,0,0,0,0,0,0,0,0,0,0,0,0,0,0,0,0,0,0,0
0,0,0,0,0,0,0,0,0,0,0,0,0,0,0,0,0,0,0,0,0,0,0,0,0,0,0,0,0,0,0,0,0,0,0,0,0,0,0,0,0,0,0,0,0,0,0,0,0,0,0
0,0,0,0,0,0,0,0,0,0,0,0,0,0,0,0,0,0,0,0,0,0,0,0,0,0,0,0,0,0,0,0,0,0,0,0,0,0,0,0,0,0,0,0,0,0,0,0,0,0,0
0,0,0,0,0,0,0,0,0,0,0,0,0,0,0,0,0,0,0,0,0,0,0,0,0,0,0,0,0,0,0,0,0,0,0,0,0,0,0,0,0,0,0,0,0,0,0,0,0,0,0
0,0,0,0,0,0,0,0,0,0,0,0,0,0,0,0,0,0,0,0,0,0,0,0,0,0,0,0,0,0,0,0,0,0,0,0,0,0,0,0,0,0,0,0,0,0,0,0,0,0,0
0,0,0,0,0,0,0,0,0,0,0,0,0,0,0,0,0,0,0,0,0,0,0,0,0,0,0,0,0,0,0,0,0,0,0,0,0,0,0,0,0,0,0,0,0,0,0,0,0,0,0
0,0,0,0,0,0,0,0,0,0,0,0,0,0,0,0,0,0,0,0,0,0,0,0,0,0,0,0,0,0,0,0,0,0,0,0,0,0,0,0,0,0,0,0,0,0,0,0,0,0,0
0,0,0,0,0,0,0,0,0,0,0,0,0,0,0,0,0,0,0,0,0,0,0,0,0,0,0,0,0,0,0,0,0,0,0,0,0,0,0,0,0,0,0,0,0,0,0,0,0,0,0
0,0,0,0,0,0,0,0,0,0,0,0,0,0,0,0,0,0,0,0,0,0,0,0,0,0,0,0,0,0,0,0,0,0,0,0,0,0,0,0,0,0,0,0,0,0,0,0,0,0,0
0,0,0,0,0,0,0,0,0,0,0,0,0,0,0,0,0,0,0,0,0,0,0,0,0,0,0,0,0,0,0,0,0,0,0,0,0,0,0,0,0,0,0,0,0,0,0,0,0,0,0
0,0,0,0,0,0,0,0,0,0,0,0,0,0,0,0,0,0,0,0,0,0,0,0,0,0,0,0,0,0,0,0,0,0,0,0,0,0,0,0,0,0,0,0,0,0,0,0,0,0,0
0,0,0,0,0,0,0,0,0,0,0,0,0,0,0,0,0,0,0,0,0,0,0,0,0,0,0,0,0,0,0,0,0,0,0,0,0,0,0,0,0,0,0,0,0,0,0,0,0,0,0
0,0,0,0,0,0,0,0,0,0,0,0,0,0,0,0,0,0,0,0,0,0,0,0,0,0,0,0,0,0,0,0,0,0,0,0,0,0,0,0,0,0,0,0,0,0,0,0,0,0,0
0,0,0,0,0,0,0,0,0,0,0,0,0,0,0,0,0,0,0,0,0,0,0,0,0,0,0,0,0,0,0,0,0,0,0,0,0,0,0,0,0,0,0,0,0,0,0,0,0,0,0
0,0,0,0,0,0,0,0,0,0,0,0,0,0,0,0,0,0,0,0,0,0,0,0,0,0,0,0,0,0,0,0,0,0,0,0,0,0,0,0,0,0,0,0,0,0,0,0,0,0,0
:endlayer
layer: 19
0,0,0,0,0,0,0,0,0,0,0,0,0,0,0,0,0,0,0,0,0,0,0,0,0,0,0,0,0,0,0,0,0,0,0,0,0,0,0,0,0,0,0,0,0,0,0,0,0,0,0
0,0,0,0,0,0,0,0,0,0,0,0,0,0,0,0,0,0,0,0,0,0,0,0,0,0,0,0,0,0,0,0,0,0,0,0,0,0,0,0,0,0,0,0,0,0,0,0,0,0,0
0,0,0,0,0,0,0,0,0,0,0,0,0,0,0,0,0,0,0,0,0,0,0,0,0,0,0,0,0,0,0,0,0,0,0,0,0,0,0,0,0,0,0,0,0,0,0,0,0,0,0
0,0,0,0,0,0,0,0,0,0,0,0,0,0,0,0,0,0,0,0,0,0,0,0,0,0,0,0,0,0,0,0,0,0,0,0,0,0,0,0,0,0,0,0,0,0,0,0,0,0,0
0,0,0,0,0,0,0,0,0,0,0,0,0,0,0,0,0,0,0,0,0,0,0,0,0,0,0,0,0,0,0,0,0,0,0,0,0,0,0,0,0,0,0,0,0,0,0,0,0,0,0
0,0,0,0,0,0,0,0,0,0,0,0,0,0,0,0,0,0,0,0,0,0,0,0,0,0,0,0,0,0,0,0,0,0,0,0,0,0,0,0,0,0,0,0,0,0,0,0,0,0,0
0,0,0,0,0,0,0,0,0,0,0,0,0,0,0,0,0,0,0,0,0,0,0,0,0,0,0,0,0,0,0,0,0,0,0,0,0,0,0,0,0,0,0,0,0,0,0,0,0,0,0
0,0,0,0,0,0,0,0,0,0,0,0,0,0,0,0,0,0,0,0,0,0,0,0,0,0,0,0,0,0,0,0,0,0,0,0,0,0,0,0,0,0,0,0,0,0,0,0,0,0,0
0,0,0,0,0,0,0,0,0,0,0,0,0,0,0,0,0,0,0,0,0,0,0,0,0,0,0,0,0,0,0,0,0,0,0,0,0,0,0,0,0,0,0,0,0,0,0,0,0,0,0
0,0,0,0,0,0,0,0,0,0,0,0,0,0,0,0,0,0,0,0,0,0,0,0,0,0,0,0,0,0,0,0,0,0,0,0,0,0,0,0,0,0,0,0,0,0,0,0,0,0,0
0,0,0,0,0,0,0,0,0,0,0,0,0,0,0,0,0,0,0,0,0,0,0,0,0,0,0,0,0,0,0,0,0,0,0,0,0,0,0,0,0,0,0,0,0,0,0,0,0,0,0
0,0,0,0,0,0,0,0,0,0,0,0,0,0,0,0,0,0,0,0,0,0,0,0,0,0,0,0,0,0,0,0,0,0,0,0,0,0,0,0,0,0,0,0,0,0,0,0,0,0,0
0,0,0,0,0,0,0,0,0,0,0,0,0,0,0,0,0,0,0,0,0,0,0,0,0,0,0,0,0,0,0,0,0,0,0,0,0,0,0,0,0,0,0,0,0,0,0,0,0,0,0
0,0,0,0,0,0,0,0,0,0,0,0,0,0,0,0,0,0,0,0,0,0,0,0,0,0,0,0,0,0,0,0,0,0,0,0,0,0,0,0,0,0,0,0,0,0,0,0,0,0,0
0,0,0,0,0,0,0,0,0,0,0,0,0,0,0,0,0,0,0,0,0,0,0,0,0,0,0,0,0,0,0,0,0,0,0,0,0,0,0,0,0,0,0,0,0,0,0,0,0,0,0
0,0,0,0,0,0,0,0,0,0,0,0,0,0,0,0,0,0,0,0,0,0,0,0,0,0,0,0,0,0,0,0,0,0,0,0,0,0,0,0,0,0,0,0,0,0,0,0,0,0,0
0,0,0,0,0,0,0,0,0,0,0,0,0,0,0,0,0,0,0,0,0,0,0,0,0,0,0,0,0,0,0,0,0,0,0,0,0,0,0,0,0,0,0,0,0,0,0,0,0,0,0
0,0,0,0,0,0,0,0,0,0,0,0,0,0,0,0,0,0,0,0,0,0,0,0,0,0,0,0,0,0,0,0,0,0,0,0,0,0,0,0,0,0,0,0,0,0,0,0,0,0,0
0,0,0,0,0,0,0,0,0,0,0,0,0,0,0,0,0,0,0,0,0,0,0,0,0,0,0,0,0,0,0,0,0,0,0,0,0,0,0,0,0,0,0,0,0,0,0,0,0,0,0
0,0,0,0,0,0,0,0,0,0,0,0,0,0,0,0,0,0,0,0,0,0,0,0,0,0,0,0,0,0,0,0,0,0,0,0,0,0,0,0,0,0,0,0,0,0,0,0,0,0,0
0,0,0,0,0,0,0,0,0,0,0,0,0,0,0,0,0,0,0,0,0,0,0,0,0,0,0,0,0,0,0,0,0,0,0,0,0,0,0,0,0,0,0,0,0,0,0,0,0,0,0
0,0,0,0,0,0,0,0,0,0,0,0,0,0,0,0,0,0,0,0,0,0,0,0,0,0,0,0,0,0,0,0,0,0,0,0,0,0,0,0,0,0,0,0,0,0,0,0,0,0,0
0,0,0,0,0,0,0,0,0,0,0,0,0,0,0,0,0,0,0,0,0,0,0,0,0,0,0,0,0,0,18,0,0,0,0,0,0,0,0,0,0,0,0,0,0,0,0,0,0,0,0
0,0,0,0,0,0,0,0,0,0,0,0,0,0,0,0,0,0,0,0,0,0,0,0,0,0,0,0,0,0,0,0,0,0,0,0,0,0,0,0,0,0,0,0,0,0,0,0,0,0,0
0,0,0,0,0,0,0,0,0,0,0,0,0,0,0,0,0,0,0,0,0,0,0,0,0,0,0,0,0,0,0,0,0,0,0,0,0,0,0,0,0,0,0,0,0,0,0,0,0,0,0
0,0,0,0,0,0,0,0,0,0,0,0,0,0,0,0,0,0,0,0,0,0,0,0,0,0,0,0,0,0,0,0,0,0,0,0,0,0,0,0,0,0,0,0,0,0,0,0,0,0,0
0,0,0,0,0,0,0,0,0,0,0,0,0,0,0,0,0,0,0,0,0,0,0,0,0,0,0,0,0,0,0,0,0,0,0,0,0,0,0,0,0,0,0,0,0,0,0,0,0,0,0
0,0,0,0,0,0,0,0,0,0,0,0,0,0,0,0,0,0,0,0,0,0,0,0,0,0,0,0,0,0,0,0,0,0,0,0,0,0,0,0,0,0,0,0,0,0,0,0,0,0,0
0,0,0,0,0,0,0,0,0,0,0,0,0,0,0,0,0,0,0,0,0,0,0,0,0,0,0,0,0,0,0,0,0,0,0,0,0,0,0,0,0,0,0,0,0,0,0,0,0,0,0
0,0,0,0,0,0,0,0,0,0,0,0,0,0,0,0,0,0,0,0,0,0,0,0,0,0,0,0,0,0,0,0,0,0,0,0,0,0,0,0,0,0,0,0,0,0,0,0,0,0,0
0,0,0,0,0,0,0,0,0,0,0,0,0,0,0,0,0,0,0,0,0,0,0,0,0,0,0,0,0,0,0,0,0,0,0,0,0,0,0,0,0,0,0,0,0,0,0,0,0,0,0
0,0,0,0,0,0,0,0,0,0,0,0,0,0,0,0,0,0,0,0,0,0,0,0,0,0,0,0,0,0,0,0,0,0,0,0,0,0,0,0,0,0,0,0,0,0,0,0,0,0,0
0,0,0,0,0,0,0,0,0,0,0,0,0,0,0,0,0,0,0,0,0,0,0,0,0,0,0,0,0,0,0,0,0,0,0,0,0,0,0,0,0,0,0,0,0,0,0,0,0,0,0
0,0,0,0,0,0,0,0,0,0,0,0,0,0,0,0,0,0,0,0,0,0,0,0,0,0,0,0,0,0,0,0,0,0,0,0,0,0,0,0,0,0,0,0,0,0,0,0,0,0,0
0,0,0,0,0,0,0,0,0,0,0,0,0,0,0,0,0,0,0,0,0,0,0,0,0,0,0,0,0,0,0,0,0,0,0,0,0,0,0,0,0,0,0,0,0,0,0,0,0,0,0
0,0,0,0,0,0,0,0,0,0,0,0,0,0,0,0,0,0,0,0,0,0,0,0,0,0,0,0,0,0,0,0,0,0,0,0,0,0,0,0,0,0,0,0,0,0,0,0,0,0,0
0,0,0,0,0,0,0,0,0,0,0,0,0,0,0,0,0,0,0,0,0,0,0,0,0,0,0,0,0,0,0,0,0,0,0,0,0,0,0,0,0,0,0,0,0,0,0,0,0,0,0
0,0,0,0,0,0,0,0,0,0,0,0,0,0,0,0,0,0,0,0,0,0,0,0,0,0,0,0,0,0,0,0,0,0,0,0,0,0,0,0,0,0,0,0,0,0,0,0,0,0,0
0,0,0,0,0,0,0,0,0,0,0,0,0,0,0,0,0,0,0,0,0,0,0,0,0,0,0,0,0,0,0,0,0,0,0,0,0,0,0,0,0,0,0,0,0,0,0,0,0,0,0
0,0,0,0,0,0,0,0,0,0,0,0,0,0,0,0,0,0,0,0,0,0,0,0,0,0,0,0,0,0,0,0,0,0,0,0,0,0,0,0,0,0,0,0,0,0,0,0,0,0,0
:endlayer
layer: 20
0,0,0,0,0,0,0,0,0,0,0,0,0,0,0,0,0,0,0,0,0,0,0,0,0,0,0,0,0,0,0,0,0,0,0,0,0,0,0,0,0,0,0,0,0,0,0,0,0,0,0
0,0,0,0,0,0,0,0,0,0,0,0,0,0,0,0,0,0,0,0,0,0,0,0,0,0,0,0,0,0,0,0,0,0,0,0,0,0,0,0,0,0,0,0,0,0,0,0,0,0,0
0,0,0,0,0,0,0,0,0,0,0,0,0,0,0,0,0,0,0,0,0,0,0,0,0,0,0,0,0,0,0,0,0,0,0,0,0,0,0,0,0,0,0,0,0,0,0,0,0,0,0
0,0,0,0,0,0,0,0,0,0,0,0,0,0,0,0,0,0,0,0,0,0,0,0,0,0,0,0,0,0,0,0,0,0,0,0,0,0,0,0,0,0,0,0,0,0,0,0,0,0,0
0,0,0,0,0,0,0,0,0,0,0,0,0,0,0,0,0,0,0,0,0,0,0,0,0,0,0,0,0,0,0,0,0,0,0,0,0,0,0,0,0,0,0,0,0,0,0,0,0,0,0
0,0,0,0,0,0,0,0,0,0,0,0,0,0,0,0,0,0,0,0,0,0,0,0,0,0,0,0,0,0,0,0,0,0,0,0,0,0,0,0,0,0,0,0,0,0,0,0,0,0,0
0,0,0,0,0,0,0,0,0,0,0,0,0,0,0,0,0,0,0,0,0,0,0,0,0,0,0,0,0,0,0,0,0,0,0,0,0,0,0,0,0,0,0,0,0,0,0,0,0,0,0
0,0,0,0,0,0,0,0,0,0,0,0,0,0,0,0,0,0,0,0,0,0,0,0,0,0,0,0,0,0,0,0,0,0,0,0,0,0,0,0,0,0,0,0,0,0,0,0,0,0,0
0,0,0,0,0,0,0,0,0,0,0,0,0,0,0,0,0,0,0,0,0,0,0,0,0,0,0,0,0,0,0,0,0,0,0,0,0,0,0,0,0,0,0,0,0,0,0,0,0,0,0
0,0,0,0,0,0,0,0,0,0,0,0,0,0,0,0,0,0,0,0,0,0,0,0,0,0,0,0,0,0,0,0,0,0,0,0,0,0,0,0,0,0,0,0,0,0,0,0,0,0,0
0,0,0,0,0,0,0,0,0,0,0,0,0,0,0,0,0,0,0,0,0,0,0,0,0,0,0,0,0,0,0,0,0,0,0,0,0,0,0,0,0,0,0,0,0,0,0,0,0,0,0
0,0,0,0,0,0,0,0,0,0,0,0,0,0,0,0,0,0,0,0,0,0,0,0,0,0,0,0,0,0,0,0,0,0,0,0,0,0,0,0,0,0,0,0,0,0,0,0,0,0,0
0,0,0,0,0,0,0,0,0,0,0,0,0,0,0,0,0,0,0,0,0,0,0,0,0,0,0,0,0,0,0,0,0,0,0,0,0,0,0,0,0,0,0,0,0,0,0,0,0,0,0
0,0,0,0,0,0,0,0,0,0,0,0,0,0,0,0,0,0,0,0,0,0,0,0,0,0,0,0,0,0,0,0,0,0,0,0,0,0,0,0,0,0,0,0,0,0,0,0,0,0,0
0,0,0,0,0,0,0,0,0,0,0,0,0,0,0,0,0,0,0,0,0,0,0,0,0,0,0,0,0,0,0,0,0,0,0,0,0,0,0,0,0,0,0,0,0,0,0,0,0,0,0
0,0,0,0,0,0,0,0,0,0,0,0,0,0,0,0,0,0,0,0,0,0,0,0,0,0,0,0,0,0,0,0,0,0,0,0,0,0,0,0,0,0,0,0,0,0,0,0,0,0,0
0,0,0,0,0,0,0,0,0,0,0,0,0,0,0,0,0,0,0,0,0,0,0,0,0,0,0,0,0,0,0,0,0,0,0,0,0,0,0,0,0,0,0,0,0,0,0,0,0,0,0
0,0,0,0,0,0,0,0,0,0,0,0,0,0,0,0,0,0,0,0,0,0,0,0,0,0,0,0,0,0,0,0,0,0,0,0,0,0,0,0,0,0,0,0,0,0,0,0,0,0,0
0,0,0,0,0,0,0,0,0,0,0,0,0,0,0,0,0,0,0,0,0,0,0,0,0,0,0,0,0,0,0,0,0,0,0,0,0,0,0,0,0,0,0,0,0,0,0,0,0,0,0
0,0,0,0,0,0,0,0,0,0,0,0,0,0,0,0,0,0,0,0,0,0,0,0,0,0,0,0,0,0,0,0,0,0,0,0,0,0,0,0,0,0,0,0,0,0,0,0,0,0,0
0,0,0,0,0,0,0,0,0,0,0,0,0,0,0,0,0,0,0,0,0,0,0,0,0,0,0,0,0,0,0,0,0,0,0,0,0,0,0,0,0,0,0,0,0,0,0,0,0,0,0
0,0,0,0,0,0,0,0,0,0,0,0,0,0,0,0,0,0,0,0,0,0,0,0,0,0,0,0,0,0,89,0,0,0,0,0,0,0,0,0,0,0,0,0,0,0,0,0,0,0,0
0,0,0,0,0,0,0,0,0,0,0,0,0,0,0,0,0,0,0,0,0,0,0,0,0,0,0,0,0,0,18,55,0,0,0,0,0,0,0,0,0,0,0,0,0,0,0,0,0,0,0
0,0,0,0,0,0,0,0,0,0,0,0,0,0,0,0,0,0,0,0,0,0,0,0,0,0,0,0,0,0,0,0,0,0,0,0,0,0,0,0,0,0,0,0,0,0,0,0,0,0,0
0,0,0,0,0,0,0,0,0,0,0,0,0,0,0,0,0,0,0,0,0,0,0,0,0,0,0,0,0,0,0,0,0,0,0,0,0,0,0,0,0,0,0,0,0,0,0,0,0,0,0
0,0,0,0,0,0,0,0,0,0,0,0,0,0,0,0,0,0,0,0,0,0,0,0,0,0,0,0,0,0,0,0,0,0,0,0,0,0,0,0,0,0,0,0,0,0,0,0,0,0,0
0,0,0,0,0,0,0,0,0,0,0,0,0,0,0,0,0,0,0,0,0,0,0,0,0,0,0,0,0,0,0,0,0,0,0,0,0,0,0,0,0,0,0,0,0,0,0,0,0,0,0
0,0,0,0,0,0,0,0,0,0,0,0,0,0,0,0,0,0,0,0,0,0,0,0,0,0,0,0,0,0,0,0,0,0,0,0,0,0,0,0,0,0,0,0,0,0,0,0,0,0,0
0,0,0,0,0,0,0,0,0,0,0,0,0,0,0,0,0,0,0,0,0,0,0,0,0,0,0,0,0,0,0,0,0,0,0,0,0,0,0,0,0,0,0,0,0,0,0,0,0,0,0
0,0,0,0,0,0,0,0,0,0,0,0,0,0,0,0,0,0,0,0,0,0,0,0,0,0,0,0,0,0,0,0,0,0,0,0,0,0,0,0,0,0,0,0,0,0,0,0,0,0,0
0,0,0,0,0,0,0,0,0,0,0,0,0,0,0,0,0,0,0,0,0,0,0,0,0,0,0,0,0,0,0,0,0,0,0,0,0,0,0,0,0,0,0,0,0,0,0,0,0,0,0
0,0,0,0,0,0,0,0,0,0,0,0,0,0,0,0,0,0,0,0,0,0,0,0,0,0,0,0,0,0,0,0,0,0,0,0,0,0,0,0,0,0,0,0,0,0,0,0,0,0,0
0,0,0,0,0,0,0,0,0,0,0,0,0,0,0,0,0,0,0,0,0,0,0,0,0,0,0,0,0,0,0,0,0,0,0,0,0,0,0,0,0,0,0,0,0,0,0,0,0,0,0
0,0,0,0,0,0,0,0,0,0,0,0,0,0,0,0,0,0,0,0,0,0,0,0,0,0,0,0,0,0,0,0,0,0,0,0,0,0,0,0,0,0,0,0,0,0,0,0,0,0,0
0,0,0,0,0,0,0,0,0,0,0,0,0,0,0,0,0,0,0,0,0,0,0,0,0,0,0,0,0,0,0,0,0,0,0,0,0,0,0,0,0,0,0,0,0,0,0,0,0,0,0
0,0,0,0,0,0,0,0,0,0,0,0,0,0,0,0,0,0,0,0,0,0,0,0,0,0,0,0,0,0,0,0,0,0,0,0,0,0,0,0,0,0,0,0,0,0,0,0,0,0,0
0,0,0,0,0,0,0,0,0,0,0,0,0,0,0,0,0,0,0,0,0,0,0,0,0,0,0,0,0,0,0,0,0,0,0,0,0,0,0,0,0,0,0,0,0,0,0,0,0,0,0
0,0,0,0,0,0,0,0,0,0,0,0,0,0,0,0,0,0,0,0,0,0,0,0,0,0,0,0,0,0,0,0,0,0,0,0,0,0,0,0,0,0,0,0,0,0,0,0,0,0,0
0,0,0,0,0,0,0,0,0,0,0,0,0,0,0,0,0,0,0,0,0,0,0,0,0,0,0,0,0,0,0,0,0,0,0,0,0,0,0,0,0,0,0,0,0,0,0,0,0,0,0
0,0,0,0,0,0,0,0,0,0,0,0,0,0,0,0,0,0,0,0,0,0,0,0,0,0,0,0,0,0,0,0,0,0,0,0,0,0,0,0,0,0,0,0,0,0,0,0,0,0,0
:endlayer
layer: 21
0,0,0,0,0,0,0,0,0,0,0,0,0,0,0,0,0,0,0,0,0,0,0,0,0,0,0,0,0,0,0,0,0,0,0,0,0,0,0,0,0,0,0,0,0,0,0,0,0,0,0
0,0,0,0,0,0,0,0,0,0,0,0,0,0,0,0,0,0,0,0,0,0,0,0,0,0,0,0,0,0,0,0,0,0,0,0,0,0,0,0,0,0,0,0,0,0,0,0,0,0,0
0,0,0,0,0,0,0,0,0,0,0,0,0,0,0,0,0,0,0,0,0,0,0,0,0,0,0,0,0,0,0,0,0,0,0,0,0,0,0,0,0,0,0,0,0,0,0,0,0,0,0
0,0,0,0,0,0,0,0,0,0,0,0,0,0,0,0,0,0,0,0,0,0,0,0,0,0,0,0,0,0,0,0,0,0,0,0,0,0,0,0,0,0,0,0,0,0,0,0,0,0,0
0,0,0,0,0,0,0,0,0,0,0,0,0,0,0,0,0,0,0,0,0,0,0,0,0,0,0,0,0,0,0,0,0,0,0,0,0,0,0,0,0,0,0,0,0,0,0,0,0,0,0
0,0,0,0,0,0,0,0,0,0,0,0,0,0,0,0,0,0,0,0,0,0,0,0,0,0,0,0,0,0,0,0,0,0,0,0,0,0,0,0,0,0,0,0,0,0,0,0,0,0,0
0,0,0,0,0,0,0,0,0,0,0,0,0,0,0,0,0,0,0,0,0,0,0,0,0,0,0,0,0,0,0,0,0,0,0,0,0,0,0,0,0,0,0,0,0,0,0,0,0,0,0
0,0,0,0,0,0,0,0,0,0,0,0,0,0,0,0,0,0,0,0,0,0,0,0,0,0,0,0,0,0,0,0,0,0,0,0,0,0,0,0,0,0,0,0,0,0,0,0,0,0,0
0,0,0,0,0,0,0,0,0,0,0,0,0,0,0,0,0,0,0,0,0,0,0,0,0,0,0,0,0,0,0,0,0,0,0,0,0,0,0,0,0,0,0,0,0,0,0,0,0,0,0
0,0,0,0,0,0,0,0,0,0,0,0,0,0,0,0,0,0,0,0,0,0,0,0,0,0,0,0,0,0,0,0,0,0,0,0,0,0,0,0,0,0,0,0,0,0,0,0,0,0,0
0,0,0,0,0,0,0,0,0,0,0,0,0,0,0,0,0,0,0,0,0,0,0,0,0,0,0,0,0,0,0,0,0,0,0,0,0,0,0,0,0,0,0,0,0,0,0,0,0,0,0
0,0,0,0,0,0,0,0,0,0,0,0,0,0,0,0,0,0,0,0,0,0,0,0,0,0,0,0,0,0,0,0,0,0,0,0,0,0,0,0,0,0,0,0,0,0,0,0,0,0,0
0,0,0,0,0,0,0,0,0,0,0,0,0,0,0,0,0,0,0,0,0,0,0,0,0,0,0,0,0,0,0,0,0,0,0,0,0,0,0,0,0,0,0,0,0,0,0,0,0,0,0
0,0,0,0,0,0,0,0,0,0,0,0,0,0,0,0,0,0,0,0,0,0,0,0,0,0,0,0,0,0,0,0,0,0,0,0,0,0,0,0,0,0,0,0,0,0,0,0,0,0,0
0,0,0,0,0,0,0,0,0,0,0,0,0,0,0,0,0,0,0,0,0,0,0,0,0,0,0,0,0,0,0,0,0,0,0,0,0,0,0,0,0,0,0,0,0,0,0,0,0,0,0
0,0,0,0,0,0,0,0,0,0,0,0,0,0,0,0,0,0,0,0,0,0,0,0,0,0,0,0,0,0,0,0,0,0,0,0,0,0,0,0,0,0,0,0,0,0,0,0,0,0,0
0,0,0,0,0,0,0,0,0,0,0,0,0,0,0,0,0,0,0,0,0,0,0,0,0,0,0,0,0,0,0,0,0,0,0,0,0,0,0,0,0,0,0,0,0,0,0,0,0,0,0
0,0,0,0,0,0,0,0,0,0,0,0,0,0,0,0,0,0,0,0,0,0,0,0,0,0,0,0,0,0,0,0,0,0,0,0,0,0,0,0,0,0,0,0,0,0,0,0,0,0,0
0,0,0,0,0,0,0,0,0,0,0,0,0,0,0,0,0,0,0,0,0,0,0,0,0,0,0,0,0,0,0,0,0,0,0,0,0,0,0,0,0,0,0,0,0,0,0,0,0,0,0
0,0,0,0,0,0,0,0,0,0,0,0,0,0,0,0,0,0,0,0,0,0,0,0,0,0,0,0,0,0,0,0,0,0,0,0,0,0,0,0,0,0,0,0,0,0,0,0,0,0,0
0,0,0,0,0,0,0,0,0,0,0,0,0,0,0,0,0,0,0,0,0,0,0,0,0,0,0,0,0,0,0,0,0,0,0,0,0,0,0,0,0,0,0,0,0,0,0,0,0,0,0
0,0,0,0,0,0,0,0,0,0,0,0,0,0,0,0,0,0,0,0,0,0,0,0,0,0,0,0,0,0,0,0,0,0,0,0,0,0,0,0,0,0,0,0,0,0,0,0,0,0,0
0,0,0,0,0,0,0,0,0,0,0,0,0,0,0,0,0,0,0,0,0,0,0,0,0,0,0,0,0,0,24,0,0,0,0,0,0,0,0,0,0,0,0,0,0,0,0,0,0,0,0
0,0,0,0,0,0,0,0,0,0,0,0,0,0,0,0,0,0,0,0,0,0,0,0,0,0,0,0,0,0,0,0,0,0,0,0,0,0,0,0,0,0,0,0,0,0,0,0,0,0,0
0,0,0,0,0,0,0,0,0,0,0,0,0,0,0,0,0,0,0,0,0,0,0,0,0,0,0,0,0,0,0,0,0,0,0,0,0,0,0,0,0,0,0,0,0,0,0,0,0,0,0
0,0,0,0,0,0,0,0,0,0,0,0,0,0,0,0,0,0,0,0,0,0,0,0,0,0,0,0,0,0,0,0,0,0,0,0,0,0,0,0,0,0,0,0,0,0,0,0,0,0,0
0,0,0,0,0,0,0,0,0,0,0,0,0,0,0,0,0,0,0,0,0,0,0,0,0,0,0,0,0,0,0,0,0,0,0,0,0,0,0,0,0,0,0,0,0,0,0,0,0,0,0
0,0,0,0,0,0,0,0,0,0,0,0,0,0,0,0,0,0,0,0,0,0,0,0,0,0,0,0,0,0,0,0,0,0,0,0,0,0,0,0,0,0,0,0,0,0,0,0,0,0,0
0,0,0,0,0,0,0,0,0,0,0,0,0,0,0,0,0,0,0,0,0,0,0,0,0,0,0,0,0,0,0,0,0,0,0,0,0,0,0,0,0,0,0,0,0,0,0,0,0,0,0
0,0,0,0,0,0,0,0,0,0,0,0,0,0,0,0,0,0,0,0,0,0,0,0,0,0,0,0,0,0,0,0,0,0,0,0,0,0,0,0,0,0,0,0,0,0,0,0,0,0,0
0,0,0,0,0,0,0,0,0,0,0,0,0,0,0,0,0,0,0,0,0,0,0,0,0,0,0,0,0,0,0,0,0,0,0,0,0,0,0,0,0,0,0,0,0,0,0,0,0,0,0
0,0,0,0,0,0,0,0,0,0,0,0,0,0,0,0,0,0,0,0,0,0,0,0,0,0,0,0,0,0,0,0,0,0,0,0,0,0,0,0,0,0,0,0,0,0,0,0,0,0,0
0,0,0,0,0,0,0,0,0,0,0,0,0,0,0,0,0,0,0,0,0,0,0,0,0,0,0,0,0,0,0,0,0,0,0,0,0,0,0,0,0,0,0,0,0,0,0,0,0,0,0
0,0,0,0,0,0,0,0,0,0,0,0,0,0,0,0,0,0,0,0,0,0,0,0,0,0,0,0,0,0,0,0,0,0,0,0,0,0,0,0,0,0,0,0,0,0,0,0,0,0,0
0,0,0,0,0,0,0,0,0,0,0,0,0,0,0,0,0,0,0,0,0,0,0,0,0,0,0,0,0,0,0,0,0,0,0,0,0,0,0,0,0,0,0,0,0,0,0,0,0,0,0
0,0,0,0,0,0,0,0,0,0,0,0,0,0,0,0,0,0,0,0,0,0,0,0,0,0,0,0,0,0,0,0,0,0,0,0,0,0,0,0,0,0,0,0,0,0,0,0,0,0,0
0,0,0,0,0,0,0,0,0,0,0,0,0,0,0,0,0,0,0,0,0,0,0,0,0,0,0,0,0,0,0,0,0,0,0,0,0,0,0,0,0,0,0,0,0,0,0,0,0,0,0
0,0,0,0,0,0,0,0,0,0,0,0,0,0,0,0,0,0,0,0,0,0,0,0,0,0,0,0,0,0,0,0,0,0,0,0,0,0,0,0,0,0,0,0,0,0,0,0,0,0,0
0,0,0,0,0,0,0,0,0,0,0,0,0,0,0,0,0,0,0,0,0,0,0,0,0,0,0,0,0,0,0,0,0,0,0,0,0,0,0,0,0,0,0,0,0,0,0,0,0,0,0
0,0,0,0,0,0,0,0,0,0,0,0,0,0,0,0,0,0,0,0,0,0,0,0,0,0,0,0,0,0,0,0,0,0,0,0,0,0,0,0,0,0,0,0,0,0,0,0,0,0,0
:endlayer
layer: 22
0,0,0,0,0,0,0,0,0,0,0,0,0,0,0,0,0,0,0,0,0,0,0,0,0,0,0,0,0,0,0,0,0,0,0,0,0,0,0,0,0,0,0,0,0,0,0,0,0,0,0
0,0,0,0,0,0,0,0,0,0,0,0,0,0,0,0,0,0,0,0,0,0,0,0,0,0,0,0,0,0,0,0,0,0,0,0,0,0,0,0,0,0,0,0,0,0,0,0,0,0,0
0,0,0,0,0,0,0,0,0,0,0,0,0,0,0,0,0,0,0,0,0,0,0,0,0,0,0,0,0,0,0,0,0,0,0,0,0,0,0,0,0,0,0,0,0,0,0,0,0,0,0
0,0,0,0,0,0,0,0,0,0,0,0,0,0,0,0,0,0,0,0,0,0,0,0,0,0,0,0,0,0,0,0,0,0,0,0,0,0,0,0,0,0,0,0,0,0,0,0,0,0,0
0,0,0,0,0,0,0,0,0,0,0,0,0,0,0,0,0,0,0,0,0,0,0,0,0,0,0,0,0,0,0,0,0,0,0,0,0,0,0,0,0,0,0,0,0,0,0,0,0,0,0
0,0,0,0,0,0,0,0,0,0,0,0,0,0,0,0,0,0,0,0,0,0,0,0,0,0,0,0,0,0,0,0,0,0,0,0,0,0,0,0,0,0,0,0,0,0,0,0,0,0,0
0,0,0,0,0,0,0,0,0,0,0,0,0,0,0,0,0,0,0,0,0,0,0,0,0,0,0,0,0,0,0,0,0,0,0,0,0,0,0,0,0,0,0,0,0,0,0,0,0,0,0
0,0,0,0,0,0,0,0,0,0,0,0,0,0,0,0,0,0,0,0,0,0,0,0,0,0,0,0,0,0,0,0,0,0,0,0,0,0,0,0,0,0,0,0,0,0,0,0,0,0,0
0,0,0,0,0,0,0,0,0,0,0,0,0,0,0,0,0,0,0,0,0,0,0,0,0,0,0,0,0,0,0,0,0,0,0,0,0,0,0,0,0,0,0,0,0,0,0,0,0,0,0
0,0,0,0,0,0,0,0,0,0,0,0,0,0,0,0,0,0,0,0,0,0,0,0,0,0,0,0,0,0,0,0,0,0,0,0,0,0,0,0,0,0,0,0,0,0,0,0,0,0,0
0,0,0,0,0,0,0,0,0,0,0,0,0,0,0,0,0,0,0,0,0,0,0,0,0,0,0,0,0,0,0,0,0,0,0,0,0,0,0,0,0,0,0,0,0,0,0,0,0,0,0
0,0,0,0,0,0,0,0,0,0,0,0,0,0,0,0,0,0,0,0,0,0,0,0,0,0,0,0,0,0,0,0,0,0,0,0,0,0,0,0,0,0,0,0,0,0,0,0,0,0,0
0,0,0,0,0,0,0,0,0,0,0,0,0,0,0,0,0,0,0,0,0,0,0,0,0,0,0,0,0,0,0,0,0,0,0,0,0,0,0,0,0,0,0,0,0,0,0,0,0,0,0
0,0,0,0,0,0,0,0,0,0,0,0,0,0,0,0,0,0,0,0,0,0,0,0,0,0,0,0,0,0,0,0,0,0,0,0,0,0,0,0,0,0,0,0,0,0,0,0,0,0,0
0,0,0,0,0,0,0,0,0,0,0,0,0,0,0,0,0,0,0,0,0,0,0,0,0,0,0,0,0,0,0,0,0,0,0,0,0,0,0,0,0,0,0,0,0,0,0,0,0,0,0
0,0,0,0,0,0,0,0,0,0,0,0,0,0,0,0,0,0,0,0,0,0,0,0,0,0,0,0,0,0,0,0,0,0,0,0,0,0,0,0,0,0,0,0,0,0,0,0,0,0,0
0,0,0,0,0,0,0,0,0,0,0,0,0,0,0,0,0,0,0,0,0,0,0,0,0,0,0,0,0,0,0,0,0,0,0,0,0,0,0,0,0,0,0,0,0,0,0,0,0,0,0
0,0,0,0,0,0,0,0,0,0,0,0,0,0,0,0,0,0,0,0,0,0,0,0,0,0,0,0,0,0,0,0,0,0,0,0,0,0,0,0,0,0,0,0,0,0,0,0,0,0,0
0,0,0,0,0,0,0,0,0,0,0,0,0,0,0,0,0,0,0,0,0,0,0,0,0,0,0,0,0,0,0,0,0,0,0,0,0,0,0,0,0,0,0,0,0,0,0,0,0,0,0
0,0,0,0,0,0,0,0,0,0,0,0,0,0,0,0,0,0,0,0,0,0,0,0,0,0,0,0,0,0,0,0,0,0,0,0,0,0,0,0,0,0,0,0,0,0,0,0,0,0,0
0,0,0,0,0,0,0,0,0,0,0,0,0,0,0,0,0,0,0,0,0,0,0,0,0,0,0,0,0,0,0,0,0,0,0,0,0,0,0,0,0,0,0,0,0,0,0,0,0,0,0
0,0,0,0,0,0,0,0,0,0,0,0,0,0,0,0,0,0,0,0,0,0,0,0,0,0,0,0,0,0,0,0,0,0,0,0,0,0,0,0,0,0,0,0,0,0,0,0,0,0,0
0,0,0,0,0,0,0,0,0,0,0,0,0,0,0,0,0,0,0,0,0,0,0,0,0,0,0,0,0,0,24,0,0,0,0,0,0,0,0,0,0,0,0,0,0,0,0,0,0,0,0
0,0,0,0,0,0,0,0,0,0,0,0,0,0,0,0,0,0,0,0,0,0,0,0,0,0,0,0,0,0,0,0,0,0,0,0,0,0,0,0,0,0,0,0,0,0,0,0,0,0,0
0,0,0,0,0,0,0,0,0,0,0,0,0,0,0,0,0,0,0,0,0,0,0,0,0,0,0,0,0,0,0,0,0,0,0,0,0,0,0,0,0,0,0,0,0,0,0,0,0,0,0
0,0,0,0,0,0,0,0,0,0,0,0,0,0,0,0,0,0,0,0,0,0,0,0,0,0,0,0,0,0,0,0,0,0,0,0,0,0,0,0,0,0,0,0,0,0,0,0,0,0,0
0,0,0,0,0,0,0,0,0,0,0,0,0,0,0,0,0,0,0,0,0,0,0,0,0,0,0,0,0,0,0,0,0,0,0,0,0,0,0,0,0,0,0,0,0,0,0,0,0,0,0
0,0,0,0,0,0,0,0,0,0,0,0,0,0,0,0,0,0,0,0,0,0,0,0,0,0,0,0,0,0,0,0,0,0,0,0,0,0,0,0,0,0,0,0,0,0,0,0,0,0,0
0,0,0,0,0,0,0,0,0,0,0,0,0,0,0,0,0,0,0,0,0,0,0,0,0,0,0,0,0,0,0,0,0,0,0,0,0,0,0,0,0,0,0,0,0,0,0,0,0,0,0
0,0,0,0,0,0,0,0,0,0,0,0,0,0,0,0,0,0,0,0,0,0,0,0,0,0,0,0,0,0,0,0,0,0,0,0,0,0,0,0,0,0,0,0,0,0,0,0,0,0,0
0,0,0,0,0,0,0,0,0,0,0,0,0,0,0,0,0,0,0,0,0,0,0,0,0,0,0,0,0,0,0,0,0,0,0,0,0,0,0,0,0,0,0,0,0,0,0,0,0,0,0
0,0,0,0,0,0,0,0,0,0,0,0,0,0,0,0,0,0,0,0,0,0,0,0,0,0,0,0,0,0,0,0,0,0,0,0,0,0,0,0,0,0,0,0,0,0,0,0,0,0,0
0,0,0,0,0,0,0,0,0,0,0,0,0,0,0,0,0,0,0,0,0,0,0,0,0,0,0,0,0,0,0,0,0,0,0,0,0,0,0,0,0,0,0,0,0,0,0,0,0,0,0
0,0,0,0,0,0,0,0,0,0,0,0,0,0,0,0,0,0,0,0,0,0,0,0,0,0,0,0,0,0,0,0,0,0,0,0,0,0,0,0,0,0,0,0,0,0,0,0,0,0,0
0,0,0,0,0,0,0,0,0,0,0,0,0,0,0,0,0,0,0,0,0,0,0,0,0,0,0,0,0,0,0,0,0,0,0,0,0,0,0,0,0,0,0,0,0,0,0,0,0,0,0
0,0,0,0,0,0,0,0,0,0,0,0,0,0,0,0,0,0,0,0,0,0,0,0,0,0,0,0,0,0,0,0,0,0,0,0,0,0,0,0,0,0,0,0,0,0,0,0,0,0,0
0,0,0,0,0,0,0,0,0,0,0,0,0,0,0,0,0,0,0,0,0,0,0,0,0,0,0,0,0,0,0,0,0,0,0,0,0,0,0,0,0,0,0,0,0,0,0,0,0,0,0
0,0,0,0,0,0,0,0,0,0,0,0,0,0,0,0,0,0,0,0,0,0,0,0,0,0,0,0,0,0,0,0,0,0,0,0,0,0,0,0,0,0,0,0,0,0,0,0,0,0,0
0,0,0,0,0,0,0,0,0,0,0,0,0,0,0,0,0,0,0,0,0,0,0,0,0,0,0,0,0,0,0,0,0,0,0,0,0,0,0,0,0,0,0,0,0,0,0,0,0,0,0
0,0,0,0,0,0,0,0,0,0,0,0,0,0,0,0,0,0,0,0,0,0,0,0,0,0,0,0,0,0,0,0,0,0,0,0,0,0,0,0,0,0,0,0,0,0,0,0,0,0,0
:endlayer
layer: 23
0,0,0,0,0,0,0,0,0,0,0,0,0,0,0,0,0,0,0,0,0,0,0,0,0,0,0,0,0,0,0,0,0,0,0,0,0,0,0,0,0,0,0,0,0,0,0,0,0,0,0
0,0,0,0,0,0,0,0,0,0,0,0,0,0,0,0,0,0,0,0,0,0,0,0,0,0,0,0,0,0,0,0,0,0,0,0,0,0,0,0,0,0,0,0,0,0,0,0,0,0,0
0,0,0,0,0,0,0,0,0,0,0,0,0,0,0,0,0,0,0,0,0,0,0,0,0,0,0,0,0,0,0,0,0,0,0,0,0,0,0,0,0,0,0,0,0,0,0,0,0,0,0
0,0,0,0,0,0,0,0,0,0,0,0,0,0,0,0,0,0,0,0,0,0,0,0,0,0,0,0,0,0,0,0,0,0,0,0,0,0,0,0,0,0,0,0,0,0,0,0,0,0,0
0,0,0,0,0,0,0,0,0,0,0,0,0,0,0,0,0,0,0,0,0,0,0,0,0,0,0,0,0,0,0,0,0,0,0,0,0,0,0,0,0,0,0,0,0,0,0,0,0,0,0
0,0,0,0,0,0,0,0,0,0,0,0,0,0,0,0,0,0,0,0,0,0,0,0,0,0,0,0,0,0,0,0,0,0,0,0,0,0,0,0,0,0,0,0,0,0,0,0,0,0,0
0,0,0,0,0,0,0,0,0,0,0,0,0,0,0,0,0,0,0,0,0,0,0,0,0,0,0,0,0,0,0,0,0,0,0,0,0,0,0,0,0,0,0,0,0,0,0,0,0,0,0
0,0,0,0,0,0,0,0,0,0,0,0,0,0,0,0,0,0,0,0,0,0,0,0,0,0,0,0,0,0,0,0,0,0,0,0,0,0,0,0,0,0,0,0,0,0,0,0,0,0,0
0,0,0,0,0,0,0,0,0,0,0,0,0,0,0,0,0,0,0,0,0,0,0,0,0,0,0,0,0,0,0,0,0,0,0,0,0,0,0,0,0,0,0,0,0,0,0,0,0,0,0
0,0,0,0,0,0,0,0,0,0,0,0,0,0,0,0,0,0,0,0,0,0,0,0,0,0,0,0,0,0,0,0,0,0,0,0,0,0,0,0,0,0,0,0,0,0,0,0,0,0,0
