# Ancient Warfare Structure Template File
# auto-generated structure file. created on: 4/15/2014 at: 20:26:30
# Lines beginning with # denote comments

header:
version=2.0
name=CivTavernSlaughteredLambMOH
size=24,22,19
offset=13,2,17
:endheader

#### VALIDATION ####
validation:
type=ground
survival=false
worldGenEnabled=true
unique=false
preserveBlocks=false
selectionWeight=25
clusterValue=25
minDuplicateDistance=90
dimensionWhiteList=false
dimensionList=
biomeWhiteList=true
biomeList=highlands.meadow,bop.meadow,ebxl.meadow,field,orchard
leveling=9
fill=5
border=5
validTargetBlocks=clay,sand,lapis_ore,grass,lit_redstone_ore,stone,gravel,iron_ore,diamond_ore,stained_hardened_clay,dirt,coal_ore,redstone_ore,gold_ore
data:
:enddata
:endvalidation

#### LAYERS ####
layer: 0
1,1,1,1,1,1,1,1,1,1,1,1,1,1,1,1,1,1,1,1,1,1,1,1
1,1,1,1,1,1,1,1,1,1,1,1,1,1,1,1,1,1,1,1,1,1,1,1
1,1,1,1,1,1,1,1,1,1,1,1,1,1,1,1,1,1,1,1,1,1,1,1
1,1,1,1,1,1,1,1,1,1,1,1,1,1,1,1,1,1,1,1,1,1,1,1
1,1,1,1,1,1,1,1,1,1,1,1,1,1,1,1,1,1,1,1,1,1,1,1
1,1,1,1,1,1,1,1,1,1,1,1,1,1,1,1,1,1,1,1,1,1,1,1
1,1,1,1,1,1,1,1,1,1,1,1,1,1,1,1,1,1,1,1,1,1,1,1
1,1,1,1,1,1,1,1,1,1,1,1,1,1,1,1,1,1,1,1,1,1,1,2
1,1,1,1,1,1,1,1,1,1,1,1,1,1,1,1,1,1,1,1,1,1,1,1
1,1,1,1,1,1,1,1,1,1,1,1,1,1,1,1,1,1,1,1,1,1,1,1
1,1,1,1,1,1,1,1,1,1,1,1,1,1,1,1,1,1,1,1,1,1,1,1
1,1,1,1,1,1,1,1,1,1,1,1,1,1,1,1,1,1,1,1,1,1,1,1
1,1,1,1,1,1,1,1,1,1,1,1,1,1,1,1,1,1,1,1,1,1,1,1
1,1,1,1,1,1,1,1,1,1,1,1,1,1,1,1,1,1,1,1,1,1,2,1
1,1,1,1,1,1,1,1,1,1,1,1,1,1,1,1,1,1,1,1,1,1,1,1
1,1,1,1,1,1,1,1,1,1,1,1,1,1,1,1,1,1,1,1,1,1,1,1
1,1,1,1,1,1,1,1,1,1,1,1,1,1,1,1,1,1,1,1,1,1,2,2
1,1,1,1,1,1,1,1,1,1,1,1,1,1,1,1,1,1,1,1,1,1,1,1
1,1,1,1,1,1,1,1,1,1,1,1,1,1,1,1,1,1,1,1,1,1,1,1
:endlayer
layer: 1
2,2,2,2,2,2,2,2,2,2,2,2,2,2,2,2,2,2,2,2,2,2,2,2
2,2,2,2,2,2,2,2,2,2,2,2,2,2,2,2,2,2,2,2,2,2,2,2
2,2,2,2,2,2,2,2,2,2,2,2,2,2,2,1,2,2,2,2,2,2,2,2
2,2,1,1,1,1,1,1,1,1,1,1,1,1,1,1,1,1,1,1,1,2,2,2
2,2,1,1,1,1,1,1,1,1,1,1,1,1,1,1,1,1,1,1,1,2,2,2
2,2,1,1,1,1,1,1,1,1,1,1,1,1,1,1,1,1,1,1,1,2,2,2
2,2,1,1,1,1,1,1,1,1,1,1,1,1,1,1,1,1,1,1,1,2,2,2
2,2,1,1,1,1,1,1,1,1,1,1,1,1,1,1,1,1,1,1,1,2,2,2
2,2,1,1,1,1,1,1,1,1,1,1,1,1,1,1,1,1,1,1,1,2,2,2
2,2,1,1,1,1,1,1,1,1,1,1,1,1,1,1,1,1,1,1,1,2,2,2
2,2,1,1,1,1,1,1,1,1,1,1,1,1,1,1,1,1,1,1,1,2,2,2
2,2,1,1,1,1,1,1,1,1,1,1,1,1,1,1,1,1,1,1,1,2,2,2
2,2,1,1,1,1,1,1,1,1,1,1,1,1,1,1,1,1,1,1,1,2,2,2
2,2,1,1,1,1,1,1,1,1,1,1,1,1,1,1,1,1,1,1,1,2,2,2
2,2,2,1,2,2,1,2,2,2,2,2,2,2,4,1,2,1,1,2,2,2,2,2
2,2,2,2,3,3,2,2,2,2,2,2,2,2,4,1,2,1,1,2,2,2,2,2
2,2,2,2,3,3,3,3,3,3,3,3,3,3,3,3,2,2,2,2,2,2,2,2
2,2,2,2,3,3,2,2,2,2,2,2,2,2,3,3,2,2,2,2,2,2,2,2
2,2,2,2,3,3,2,2,2,2,2,2,2,2,3,3,2,2,2,2,2,2,2,2
:endlayer
layer: 2
5,5,5,0,5,5,0,5,5,5,0,0,5,5,0,0,0,5,0,0,0,5,0,5
5,5,5,5,0,5,5,5,5,0,0,5,5,5,0,0,0,5,5,0,5,5,5,5
5,0,0,0,0,0,5,5,5,0,0,0,5,5,5,14,5,5,5,0,5,5,0,0
5,0,10,10,10,10,10,10,10,10,10,10,10,10,10,12,10,10,10,10,10,5,5,5
5,0,10,13,13,13,13,13,13,13,13,13,10,4,4,4,4,4,4,4,12,5,0,0
0,0,10,13,13,13,13,13,13,13,13,13,10,4,4,4,4,4,4,4,12,0,0,0
5,5,10,13,13,13,13,13,13,13,13,13,10,4,4,4,4,4,4,4,12,0,5,0
5,5,10,13,13,13,13,13,13,13,13,13,10,4,4,4,4,4,4,4,12,0,0,0
5,5,10,13,13,13,13,10,10,13,10,10,10,12,4,4,4,4,4,4,12,0,0,0
0,0,10,13,13,13,13,13,13,13,13,13,13,12,4,4,4,4,4,4,12,0,0,0
0,0,10,13,13,13,13,13,13,13,13,13,13,12,4,4,4,4,4,4,12,0,0,5
0,0,10,13,13,13,13,13,13,13,13,13,13,12,4,4,4,4,4,4,12,5,5,5
0,5,10,13,13,13,13,10,12,12,12,13,13,12,4,4,4,4,4,4,12,5,5,5
0,5,10,10,13,13,10,10,10,10,10,10,10,10,12,12,10,10,10,10,10,5,0,5
0,0,0,10,11,11,10,0,0,0,0,0,0,0,9,9,0,7,7,0,5,5,5,0
0,5,5,0,0,0,0,0,0,0,0,0,0,0,8,8,0,7,7,0,0,6,5,5
5,6,0,0,0,0,0,0,0,0,0,0,0,0,0,0,0,0,0,0,5,6,5,5
0,6,6,6,0,0,6,6,6,6,6,6,6,6,0,0,0,0,0,6,6,6,5,0
5,0,0,0,0,0,0,0,0,5,5,5,5,5,0,0,0,0,0,5,5,0,0,0
:endlayer
layer: 3
0,0,0,0,0,0,0,0,0,0,0,0,0,0,0,0,0,0,0,0,0,0,0,0
0,0,0,0,0,0,0,0,0,0,0,0,0,0,0,0,0,0,0,0,0,0,0,0
0,0,0,0,0,0,0,0,0,0,0,0,0,0,0,0,0,0,0,0,0,0,0,0
0,0,10,12,12,12,12,10,12,12,12,12,10,10,12,30,12,12,12,12,10,0,0,0
0,0,12,29,29,29,0,29,29,0,29,29,12,23,0,0,0,0,0,0,12,0,0,0
0,0,12,6,6,6,0,6,0,0,6,28,12,0,0,0,6,6,6,6,12,0,0,0
0,0,12,26,26,26,0,0,0,0,6,28,12,27,0,0,0,0,0,0,12,0,0,0
0,0,12,17,11,11,0,0,0,0,26,26,12,25,0,0,6,6,6,6,12,0,0,0
0,0,10,17,0,0,0,10,12,16,12,12,10,12,0,0,0,0,0,0,12,0,0,0
0,0,12,24,0,0,0,0,0,0,0,0,23,12,0,0,6,6,6,6,12,0,0,0
0,0,12,11,0,0,0,21,0,0,0,0,22,12,0,0,0,0,0,0,12,0,0,0
0,0,12,6,0,0,0,21,0,20,0,0,0,19,0,0,6,6,6,6,12,0,0,0
0,0,12,18,0,0,18,12,12,12,13,17,0,12,0,0,0,0,0,0,12,0,0,0
0,0,10,12,16,15,12,10,12,12,12,12,12,12,16,15,12,12,12,12,10,0,0,0
0,0,0,0,0,0,0,0,0,0,0,0,0,0,0,0,0,7,7,0,0,0,0,0
0,0,0,0,0,0,0,0,0,0,0,0,0,0,0,0,0,0,0,0,0,0,0,0
0,0,0,0,0,0,0,0,0,0,0,0,0,0,0,0,0,0,0,0,0,0,0,0
0,0,0,0,0,0,0,0,0,0,0,0,0,0,0,0,0,0,0,0,0,0,0,0
0,0,0,0,0,0,0,0,0,0,0,0,0,0,0,0,0,0,0,0,0,0,0,0
:endlayer
layer: 4
0,0,0,0,0,0,0,0,0,0,0,0,0,0,0,0,0,0,0,0,0,0,0,0
0,0,0,0,0,0,0,0,0,0,0,0,0,0,0,0,0,0,0,0,0,0,0,0
0,0,0,0,0,0,0,0,0,0,0,0,0,0,0,0,0,0,0,0,0,0,0,0
0,0,10,12,12,12,12,10,12,12,12,12,10,10,12,41,12,6,12,12,10,0,0,0
0,0,12,0,0,0,0,0,0,0,0,0,12,0,0,0,0,0,0,0,13,0,0,0
0,0,12,40,40,40,0,40,0,0,40,0,12,0,0,0,6,6,6,6,12,0,0,0
0,0,12,0,0,0,0,0,0,0,40,0,12,0,0,0,0,0,0,0,13,0,0,0
0,0,12,0,0,0,0,0,0,0,0,0,12,0,0,0,6,6,6,6,12,0,0,0
0,0,10,0,0,0,39,10,12,38,12,12,10,12,0,0,0,0,0,0,13,0,0,0
0,0,12,0,0,0,0,37,0,0,0,0,0,12,0,0,6,6,6,6,12,0,0,0
0,0,12,0,0,0,0,0,0,0,0,0,0,12,0,0,0,0,0,0,13,0,0,0
0,0,12,36,0,0,0,0,0,0,0,0,0,35,0,0,6,6,6,6,12,0,0,0
0,0,12,0,0,0,0,12,12,13,17,0,0,12,0,0,0,0,0,0,13,0,0,0
0,0,10,12,34,33,12,10,12,12,12,12,12,12,32,31,12,12,6,12,10,0,0,0
0,0,0,0,0,0,0,0,0,0,0,0,0,0,0,0,0,7,0,0,0,0,0,0
0,0,0,0,0,0,0,0,0,0,0,0,0,0,0,0,0,0,0,0,0,0,0,0
0,0,0,0,0,0,0,0,0,0,0,0,0,0,0,0,0,0,0,0,0,0,0,0
0,0,0,0,0,0,0,0,0,0,0,0,0,0,0,0,0,0,0,0,0,0,0,0
0,0,0,0,0,0,0,0,0,0,0,0,0,0,0,0,0,0,0,0,0,0,0,0
:endlayer
layer: 5
0,0,0,0,0,0,0,0,0,0,0,0,0,0,0,0,0,0,0,0,0,0,0,0
0,0,0,0,0,0,0,0,0,0,0,0,0,0,0,0,0,0,0,0,0,0,0,0
0,0,45,0,0,0,0,45,0,0,0,0,45,0,0,45,0,0,0,0,45,0,0,0
0,44,10,12,12,12,12,10,12,12,12,12,10,10,12,12,12,12,12,12,10,43,0,0
0,0,12,43,0,0,0,0,0,0,0,44,12,0,0,42,0,0,0,0,6,0,0,0
0,0,12,0,0,0,0,0,0,0,0,0,12,0,0,0,6,0,0,6,12,0,0,0
0,0,12,0,0,0,0,0,0,0,0,0,12,0,0,0,0,0,0,0,6,0,0,0
0,0,12,0,0,0,0,0,0,0,0,44,12,45,0,0,6,0,0,6,12,0,0,0
0,44,10,0,0,0,0,10,12,12,12,12,10,12,43,0,0,0,0,0,6,0,0,0
0,0,12,0,0,0,0,0,0,0,0,0,42,12,0,0,6,0,0,6,12,0,0,0
0,0,12,0,0,0,0,0,0,0,0,0,0,12,0,0,0,0,0,0,6,0,0,0
0,0,12,0,0,0,0,0,0,0,0,0,0,12,43,0,6,0,0,6,12,0,0,0
0,0,12,43,0,0,44,12,12,17,0,0,0,12,0,0,0,0,0,0,6,0,0,0
0,44,10,12,12,12,12,10,12,12,12,12,12,12,6,6,12,12,12,12,10,43,0,0
0,0,42,0,42,42,0,42,0,0,0,0,0,42,0,0,42,0,0,0,42,0,0,0
0,0,0,0,0,0,0,0,0,0,0,0,0,0,0,0,0,0,0,0,0,0,0,0
0,0,0,0,0,0,0,0,0,0,0,0,0,0,0,0,0,0,0,0,0,0,0,0
0,0,0,0,0,0,0,0,0,0,0,0,0,0,0,0,0,0,0,0,0,0,0,0
0,0,0,0,0,0,0,0,0,0,0,0,0,0,0,0,0,0,0,0,0,0,0,0
:endlayer
layer: 6
0,0,0,0,0,0,0,0,0,0,0,0,0,0,0,0,0,0,0,0,0,0,0,0
0,0,0,0,0,0,0,0,0,0,0,0,0,0,0,0,0,0,0,0,0,0,0,0
0,49,0,0,0,0,6,10,6,6,6,6,10,6,0,0,0,0,0,0,0,0,0,0
0,49,10,10,10,10,10,10,10,10,10,10,10,10,12,12,12,12,12,12,10,0,0,0
0,49,10,0,0,0,0,0,0,0,0,0,10,0,0,0,0,0,0,42,12,0,0,0
0,49,10,0,0,0,0,0,0,0,0,0,10,0,0,0,6,0,0,6,12,0,0,0
0,49,10,0,0,0,0,0,0,0,0,0,10,0,0,0,0,0,0,0,12,0,0,0
0,49,10,0,0,0,0,0,0,0,0,0,10,0,0,0,6,0,0,6,12,0,0,0
0,49,10,10,10,10,10,10,10,10,10,10,10,10,0,0,0,0,0,0,12,0,0,0
0,49,10,0,0,0,0,10,12,6,6,6,0,10,0,0,6,0,0,6,12,0,0,0
0,49,10,0,0,0,0,10,13,0,0,0,0,12,0,0,0,0,0,0,12,0,0,0
0,49,10,0,0,0,0,10,11,0,0,0,0,12,0,0,6,0,0,6,12,0,0,0
0,49,10,0,0,0,0,10,0,0,0,0,0,12,0,0,0,0,0,45,12,0,0,0
0,49,10,10,10,10,10,10,12,12,12,12,12,12,12,12,12,12,12,12,10,0,0,0
0,49,0,0,6,0,0,0,0,0,0,0,0,0,0,0,0,0,0,0,0,0,0,0
0,0,0,0,6,0,0,0,0,0,0,0,0,0,0,0,0,0,0,0,0,0,0,0
0,0,0,48,13,47,0,0,0,0,0,0,0,0,0,0,0,0,0,0,0,0,0,0
0,0,0,0,46,0,0,0,0,0,0,0,0,0,0,0,0,0,0,0,0,0,0,0
0,0,0,0,0,0,0,0,0,0,0,0,0,0,0,0,0,0,0,0,0,0,0,0
:endlayer
layer: 7
0,0,0,0,0,0,0,0,0,0,0,0,0,0,0,0,0,0,0,0,0,0,0,0
0,0,0,0,0,0,0,0,0,0,0,0,0,0,0,0,0,0,0,0,0,0,0,0
0,0,49,0,0,0,6,10,10,10,10,10,10,6,0,0,0,0,0,0,0,0,0,0
0,0,49,10,51,51,10,13,13,13,13,13,13,10,10,10,10,10,10,10,10,0,0,0
0,0,49,0,0,0,10,13,13,13,13,13,13,13,13,13,13,13,13,13,10,0,0,0
0,0,49,0,0,0,10,13,13,13,13,13,13,13,13,13,13,13,13,13,10,0,0,0
0,0,49,0,0,0,10,13,13,13,13,13,13,13,13,13,13,13,13,13,10,0,0,0
0,0,49,0,0,0,10,13,13,13,13,13,13,13,13,13,13,13,13,13,10,0,0,0
0,0,49,10,0,0,10,13,13,13,13,13,13,10,13,13,13,13,13,13,10,0,0,0
0,0,49,0,0,0,0,10,13,10,13,13,13,10,13,13,13,13,13,13,10,0,0,0
0,0,49,0,0,0,0,13,11,13,13,13,13,12,13,13,13,13,13,13,10,0,0,0
0,0,49,0,0,0,0,13,0,13,13,13,13,12,13,13,13,13,13,13,10,0,0,0
0,0,49,0,0,0,0,13,0,0,0,13,13,12,13,13,13,13,13,13,10,0,0,0
0,0,49,10,51,51,10,10,12,12,12,12,12,10,10,10,10,10,10,10,10,0,0,0
0,0,49,0,0,0,0,17,0,0,0,0,0,0,0,0,0,0,0,0,0,0,0,0
0,0,0,0,0,0,0,0,0,0,0,0,0,0,0,0,0,0,0,0,0,0,0,0
0,0,0,0,50,0,0,0,0,0,0,0,0,0,0,0,0,0,0,0,0,0,0,0
0,0,0,0,0,0,0,0,0,0,0,0,0,0,0,0,0,0,0,0,0,0,0,0
0,0,0,0,0,0,0,0,0,0,0,0,0,0,0,0,0,0,0,0,0,0,0,0
:endlayer
layer: 8
0,0,0,0,0,0,0,0,0,0,0,0,0,0,0,0,0,0,0,0,0,0,0,0
0,0,0,0,0,0,0,0,0,0,0,0,0,0,0,0,0,0,0,0,0,0,0,0
0,0,0,49,52,52,17,10,13,51,51,13,10,6,0,0,0,0,0,0,0,0,0,0
0,0,0,49,10,10,10,67,0,0,0,0,66,10,13,13,13,13,13,13,10,0,0,0
0,0,0,49,0,0,13,65,0,0,0,0,0,0,0,0,13,64,62,61,13,0,0,0
0,0,0,49,0,0,13,0,0,0,0,0,0,0,0,0,59,0,0,0,13,0,0,0
0,0,0,49,0,0,13,10,0,0,0,0,0,0,0,0,13,13,13,13,10,0,0,0
0,0,0,49,0,0,13,60,0,0,0,0,57,0,0,0,13,63,62,61,13,0,0,0
0,0,0,49,10,10,10,60,0,0,0,0,54,10,0,0,59,0,0,0,13,0,0,0
0,0,0,49,0,0,58,10,0,10,0,0,0,10,30,13,13,13,13,13,13,0,0,0
0,0,0,49,0,0,13,13,0,6,0,0,0,13,0,0,0,0,0,0,10,0,0,0
0,0,0,49,0,0,13,13,0,6,6,6,0,13,0,0,57,57,0,0,13,0,0,0
0,0,0,49,0,0,13,13,0,0,0,6,56,13,0,55,54,54,53,0,13,0,0,0
0,0,0,49,10,10,13,10,13,13,13,13,13,10,13,13,13,13,13,13,10,0,0,0
0,0,0,49,52,52,17,0,0,0,0,0,0,0,0,0,0,0,0,0,0,0,0,0
0,0,0,0,0,0,0,0,0,0,0,0,0,0,0,0,0,0,0,0,0,0,0,0
0,0,0,0,0,0,0,0,0,0,0,0,0,0,0,0,0,0,0,0,0,0,0,0
0,0,0,0,0,0,0,0,0,0,0,0,0,0,0,0,0,0,0,0,0,0,0,0
0,0,0,0,0,0,0,0,0,0,0,0,0,0,0,0,0,0,0,0,0,0,0,0
:endlayer
layer: 9
0,0,0,0,0,0,0,0,0,0,0,0,0,0,0,0,0,0,0,0,0,0,0,0
0,0,0,0,0,0,0,0,0,0,0,0,0,0,0,0,0,0,0,0,0,0,0,0
0,0,0,0,0,0,6,10,13,51,51,13,10,6,0,0,0,0,0,0,0,0,0,0
0,0,0,0,68,68,10,0,0,0,0,0,0,10,13,13,13,13,51,13,10,0,0,0
0,0,0,0,49,17,13,0,0,0,0,0,0,0,0,0,13,0,0,0,13,0,0,0
0,0,0,0,49,17,13,0,0,0,0,0,0,0,0,0,71,0,0,0,13,0,0,0
0,0,0,0,49,17,13,10,0,0,0,0,0,0,0,0,13,13,13,13,10,0,0,0
0,0,0,0,49,17,13,60,0,0,0,0,0,0,0,0,13,0,0,0,13,0,0,0
0,0,0,0,49,17,10,60,0,0,0,0,0,10,0,0,70,0,0,0,51,0,0,0
0,0,0,0,49,17,13,10,0,10,0,0,0,10,69,13,13,13,13,13,13,0,0,0
0,0,0,0,49,17,13,13,0,0,0,0,0,13,0,0,0,0,0,0,10,0,0,0
0,0,0,0,49,17,0,13,0,0,0,6,0,13,0,0,0,0,0,0,13,0,0,0
0,0,0,0,49,17,0,13,0,0,0,0,0,13,0,0,0,0,0,0,13,0,0,0
0,0,0,0,68,68,0,10,13,51,13,51,13,10,13,51,13,51,13,13,10,0,0,0
0,0,0,0,0,0,0,0,0,0,0,0,0,0,0,0,0,0,0,0,0,0,0,0
0,0,0,0,0,0,0,0,0,0,0,0,0,0,0,0,0,0,0,0,0,0,0,0
0,0,0,0,0,0,0,0,0,0,0,0,0,0,0,0,0,0,0,0,0,0,0,0
0,0,0,0,0,0,0,0,0,0,0,0,0,0,0,0,0,0,0,0,0,0,0,0
0,0,0,0,0,0,0,0,0,0,0,0,0,0,0,0,0,0,0,0,0,0,0,0
:endlayer
layer: 10
0,0,0,0,0,0,0,0,0,0,0,0,0,0,0,0,0,0,0,0,0,0,0,0
0,0,0,0,0,0,0,0,0,0,0,0,0,0,0,0,0,0,0,0,0,0,0,0
0,0,0,0,0,0,6,10,13,51,51,13,10,6,17,18,18,76,0,76,18,0,0,0
0,0,0,0,0,0,10,0,0,0,0,0,0,10,13,13,13,13,51,13,10,17,0,0
0,0,0,0,0,0,13,0,0,0,0,0,0,0,42,0,13,0,0,44,13,17,0,0
0,0,0,0,0,0,13,0,0,0,0,0,0,0,0,44,13,43,0,0,13,17,0,0
0,0,0,0,0,0,13,10,0,0,0,0,0,0,0,0,13,13,13,13,10,17,0,0
0,0,0,0,0,0,13,60,0,0,0,0,0,0,0,0,13,0,0,44,13,74,0,0
0,0,0,0,0,0,10,60,45,0,0,0,0,10,0,45,13,43,0,0,51,0,0,0
0,0,0,0,0,0,13,10,75,10,0,0,0,10,13,13,13,13,13,13,13,74,0,0
0,0,0,0,0,0,13,13,0,0,0,0,0,13,42,0,0,0,0,42,10,17,0,0
0,0,0,0,0,0,0,13,0,0,0,6,0,13,0,0,0,0,0,0,13,17,0,0
0,0,0,0,0,0,0,13,45,0,0,0,45,13,45,0,0,0,0,44,13,17,0,0
0,0,0,0,0,0,0,13,13,13,13,13,13,13,13,51,13,51,13,13,10,17,0,0
0,0,0,0,0,0,0,73,73,73,73,73,73,73,73,0,72,0,72,11,11,0,0,0
0,0,0,0,0,0,0,0,0,0,0,0,0,0,0,0,0,0,0,0,0,0,0,0
0,0,0,0,0,0,0,0,0,0,0,0,0,0,0,0,0,0,0,0,0,0,0,0
0,0,0,0,0,0,0,0,0,0,0,0,0,0,0,0,0,0,0,0,0,0,0,0
0,0,0,0,0,0,0,0,0,0,0,0,0,0,0,0,0,0,0,0,0,0,0,0
:endlayer
layer: 11
0,0,0,0,0,0,0,0,0,0,0,0,0,0,0,0,0,0,0,0,0,0,0,0
0,0,0,0,0,18,18,18,18,18,18,18,18,18,18,0,0,0,0,0,0,0,0,0
0,0,0,0,0,0,10,10,10,10,10,10,10,10,0,0,0,0,77,0,0,0,0,0
0,0,0,0,0,44,10,42,0,0,0,0,42,10,17,18,18,18,18,18,17,0,0,0
0,0,0,0,0,0,10,0,0,0,0,0,0,10,13,13,13,13,13,13,17,0,0,0
0,0,0,0,0,0,10,0,0,0,0,0,0,10,13,13,13,13,13,13,17,0,0,0
0,0,0,0,0,0,10,68,0,0,0,0,0,10,13,13,13,13,13,13,17,0,0,0
0,0,0,0,0,0,10,68,0,0,0,0,0,10,13,13,13,13,13,13,17,0,0,0
0,0,0,0,0,44,10,68,0,0,0,0,0,10,13,13,13,13,13,13,17,77,0,0
0,0,0,0,0,0,10,10,10,10,10,10,10,10,13,13,13,13,13,13,17,0,0,0
0,0,0,0,0,11,11,11,11,11,11,11,11,11,13,13,13,13,13,13,17,0,0,0
0,0,0,0,0,0,0,77,77,77,77,77,77,77,13,13,13,13,13,13,17,0,0,0
0,0,0,0,0,0,0,77,77,77,77,77,77,77,13,13,13,13,13,13,17,0,0,0
0,0,0,0,0,0,0,77,77,77,13,77,77,77,11,11,11,11,11,11,17,0,0,0
0,0,0,0,0,0,0,0,0,0,42,0,0,0,0,77,0,77,0,0,0,0,0,0
0,0,0,0,0,0,0,0,0,0,0,0,0,0,0,0,0,0,0,0,0,0,0,0
0,0,0,0,0,0,0,0,0,0,0,0,0,0,0,0,0,0,0,0,0,0,0,0
0,0,0,0,0,0,0,0,0,0,0,0,0,0,0,0,0,0,0,0,0,0,0,0
0,0,0,0,0,0,0,0,0,0,0,0,0,0,0,0,0,0,0,0,0,0,0,0
:endlayer
layer: 12
0,0,0,0,0,0,0,0,0,0,0,0,0,0,0,0,0,0,0,0,0,0,0,0
0,0,0,0,0,0,0,0,0,0,0,0,0,0,0,0,0,0,0,0,0,0,0,0
0,0,0,0,0,18,18,18,18,18,18,18,18,18,18,0,0,0,0,0,0,0,0,0
0,0,0,0,0,0,10,0,0,0,0,0,0,10,0,0,0,0,0,0,0,0,0,0
0,0,0,0,0,0,13,0,0,0,0,0,0,13,6,6,6,6,6,6,0,0,0,0
0,0,0,0,0,0,51,0,0,0,0,0,0,51,0,0,0,0,0,6,0,0,0,0
0,0,0,0,0,0,51,0,0,0,0,0,0,51,0,0,0,0,0,6,0,0,0,0
0,0,0,0,0,0,13,0,0,0,0,0,0,13,0,0,0,0,0,6,0,0,0,0
0,0,0,0,0,0,10,0,0,0,0,0,0,10,0,0,0,0,0,6,0,0,0,0
0,0,0,0,0,11,11,11,11,11,11,11,11,11,11,0,0,0,0,6,0,0,0,0
0,0,0,0,0,0,0,0,0,0,0,0,0,0,0,0,0,0,0,6,0,0,0,0
0,0,0,0,0,0,0,0,0,0,0,0,0,0,6,0,0,0,0,6,0,0,0,0
0,0,0,0,0,0,0,0,0,0,0,0,0,0,6,6,6,6,6,6,0,0,0,0
0,0,0,0,0,0,0,0,0,0,50,0,0,0,0,0,0,0,0,0,0,0,0,0
0,0,0,0,0,0,0,0,0,0,0,0,0,0,0,0,0,0,0,0,0,0,0,0
0,0,0,0,0,0,0,0,0,0,0,0,0,0,0,0,0,0,0,0,0,0,0,0
0,0,0,0,0,0,0,0,0,0,0,0,0,0,0,0,0,0,0,0,0,0,0,0
0,0,0,0,0,0,0,0,0,0,0,0,0,0,0,0,0,0,0,0,0,0,0,0
0,0,0,0,0,0,0,0,0,0,0,0,0,0,0,0,0,0,0,0,0,0,0,0
:endlayer
layer: 13
0,0,0,0,0,0,0,0,0,0,0,0,0,0,0,0,0,0,0,0,0,0,0,0
0,0,0,0,0,0,0,0,0,0,0,0,0,0,0,0,0,0,0,0,0,0,0,0
0,0,0,0,0,0,0,0,0,0,0,0,0,0,0,0,0,0,0,0,0,0,0,0
0,0,0,0,0,18,18,18,18,18,18,18,18,18,18,0,0,0,0,0,0,0,0,0
0,0,0,0,0,0,10,0,0,0,0,0,0,10,0,0,0,0,0,50,0,0,0,0
0,0,0,0,0,0,51,0,0,0,0,0,0,51,0,0,0,0,0,0,0,0,0,0
0,0,0,0,0,0,51,0,0,0,0,0,0,51,0,0,0,0,0,0,0,0,0,0
0,0,0,0,0,0,10,0,0,0,0,0,0,10,0,0,0,0,0,0,0,0,0,0
0,0,0,0,0,11,11,11,11,11,11,11,11,11,11,0,0,0,0,0,0,0,0,0
0,0,0,0,0,0,0,0,0,0,0,0,0,0,0,0,0,0,0,0,0,0,0,0
0,0,0,0,0,0,0,0,0,0,0,0,0,0,0,0,0,0,0,0,0,0,0,0
0,0,0,0,0,0,0,0,0,0,0,0,0,0,0,0,0,0,0,0,0,0,0,0
0,0,0,0,0,0,0,0,0,0,0,0,0,0,50,0,0,0,0,50,0,0,0,0
0,0,0,0,0,0,0,0,0,0,0,0,0,0,0,0,0,0,0,0,0,0,0,0
0,0,0,0,0,0,0,0,0,0,0,0,0,0,0,0,0,0,0,0,0,0,0,0
0,0,0,0,0,0,0,0,0,0,0,0,0,0,0,0,0,0,0,0,0,0,0,0
0,0,0,0,0,0,0,0,0,0,0,0,0,0,0,0,0,0,0,0,0,0,0,0
0,0,0,0,0,0,0,0,0,0,0,0,0,0,0,0,0,0,0,0,0,0,0,0
0,0,0,0,0,0,0,0,0,0,0,0,0,0,0,0,0,0,0,0,0,0,0,0
:endlayer
layer: 14
0,0,0,0,0,0,0,0,0,0,0,0,0,0,0,0,0,0,0,0,0,0,0,0
0,0,0,0,0,0,0,0,0,0,0,0,0,0,0,0,0,0,0,0,0,0,0,0
0,0,0,0,0,0,0,0,0,0,0,0,0,0,0,0,0,0,0,0,0,0,0,0
0,0,0,0,0,0,0,0,0,0,0,0,0,0,0,0,0,0,0,0,0,0,0,0
0,0,0,0,0,18,18,18,18,18,18,18,18,18,18,0,0,0,0,0,0,0,0,0
0,0,0,0,0,0,10,0,0,0,0,0,0,10,73,0,0,0,0,0,0,0,0,0
0,0,0,0,0,0,10,0,0,0,0,0,0,10,73,0,0,0,0,0,0,0,0,0
0,0,0,0,0,11,11,11,11,11,11,11,11,11,11,0,0,0,0,0,0,0,0,0
0,0,0,0,0,0,0,0,0,0,0,0,0,0,0,0,0,0,0,0,0,0,0,0
0,0,0,0,0,0,0,0,0,0,0,0,0,0,0,0,0,0,0,0,0,0,0,0
0,0,0,0,0,0,0,0,0,0,0,0,0,0,0,0,0,0,0,0,0,0,0,0
0,0,0,0,0,0,0,0,0,0,0,0,0,0,0,0,0,0,0,0,0,0,0,0
0,0,0,0,0,0,0,0,0,0,0,0,0,0,0,0,0,0,0,0,0,0,0,0
0,0,0,0,0,0,0,0,0,0,0,0,0,0,0,0,0,0,0,0,0,0,0,0
0,0,0,0,0,0,0,0,0,0,0,0,0,0,0,0,0,0,0,0,0,0,0,0
0,0,0,0,0,0,0,0,0,0,0,0,0,0,0,0,0,0,0,0,0,0,0,0
0,0,0,0,0,0,0,0,0,0,0,0,0,0,0,0,0,0,0,0,0,0,0,0
0,0,0,0,0,0,0,0,0,0,0,0,0,0,0,0,0,0,0,0,0,0,0,0
0,0,0,0,0,0,0,0,0,0,0,0,0,0,0,0,0,0,0,0,0,0,0,0
:endlayer
layer: 15
0,0,0,0,0,0,0,0,0,0,0,0,0,0,0,0,0,0,0,0,0,0,0,0
0,0,0,0,0,0,0,0,0,0,0,0,0,0,0,0,0,0,0,0,0,0,0,0
0,0,0,0,0,0,0,0,0,0,0,0,0,0,0,0,0,0,0,0,0,0,0,0
0,0,0,0,0,0,0,0,0,0,0,0,0,0,0,0,0,0,0,0,0,0,0,0
0,0,0,0,0,0,0,0,0,0,0,0,0,0,0,0,0,0,0,0,0,0,0,0
0,0,0,0,0,8,18,18,18,18,18,18,18,18,0,0,0,0,0,0,0,0,0,0
0,0,0,0,0,8,11,11,11,11,11,11,11,11,0,0,0,0,0,0,0,0,0,0
0,0,0,0,0,0,0,0,0,0,0,0,0,0,0,0,0,0,0,0,0,0,0,0
0,0,0,0,0,0,0,0,0,0,0,0,0,0,0,0,0,0,0,0,0,0,0,0
0,0,0,0,0,0,0,0,0,0,0,0,0,0,0,0,0,0,0,0,0,0,0,0
0,0,0,0,0,0,0,0,0,0,0,0,0,0,0,0,0,0,0,0,0,0,0,0
0,0,0,0,0,0,0,0,0,0,0,0,0,0,0,0,0,0,0,0,0,0,0,0
0,0,0,0,0,0,0,0,0,0,0,0,0,0,0,0,0,0,0,0,0,0,0,0
0,0,0,0,0,0,0,0,0,0,0,0,0,0,0,0,0,0,0,0,0,0,0,0
0,0,0,0,0,0,0,0,0,0,0,0,0,0,0,0,0,0,0,0,0,0,0,0
0,0,0,0,0,0,0,0,0,0,0,0,0,0,0,0,0,0,0,0,0,0,0,0
0,0,0,0,0,0,0,0,0,0,0,0,0,0,0,0,0,0,0,0,0,0,0,0
0,0,0,0,0,0,0,0,0,0,0,0,0,0,0,0,0,0,0,0,0,0,0,0
0,0,0,0,0,0,0,0,0,0,0,0,0,0,0,0,0,0,0,0,0,0,0,0
:endlayer
layer: 16
0,0,0,0,0,0,0,0,0,0,0,0,0,0,0,0,0,0,0,0,0,0,0,0
0,0,0,0,0,0,0,0,0,0,0,0,0,0,0,0,0,0,0,0,0,0,0,0
0,0,0,0,0,0,0,0,0,0,0,0,0,0,0,0,0,0,0,0,0,0,0,0
0,0,0,0,0,0,0,0,0,0,0,0,0,0,0,0,0,0,0,0,0,0,0,0
0,0,0,0,0,0,0,0,0,0,0,0,0,0,0,0,0,0,0,0,0,0,0,0
0,0,0,0,0,0,0,0,0,0,0,0,0,0,0,0,0,0,0,0,0,0,0,0
0,0,0,0,0,0,0,0,0,0,0,0,0,0,0,0,0,0,0,0,0,0,0,0
0,0,0,0,0,0,0,0,0,0,0,0,0,0,0,0,0,0,0,0,0,0,0,0
0,0,0,0,0,0,0,0,0,0,0,0,0,0,0,0,0,0,0,0,0,0,0,0
0,0,0,0,0,0,0,0,0,0,0,0,0,0,0,0,0,0,0,0,0,0,0,0
0,0,0,0,0,0,0,0,0,0,0,0,0,0,0,0,0,0,0,0,0,0,0,0
0,0,0,0,0,0,0,0,0,0,0,0,0,0,0,0,0,0,0,0,0,0,0,0
0,0,0,0,0,0,0,0,0,0,0,0,0,0,0,0,0,0,0,0,0,0,0,0
0,0,0,0,0,0,0,0,0,0,0,0,0,0,0,0,0,0,0,0,0,0,0,0
0,0,0,0,0,0,0,0,0,0,0,0,0,0,0,0,0,0,0,0,0,0,0,0
0,0,0,0,0,0,0,0,0,0,0,0,0,0,0,0,0,0,0,0,0,0,0,0
0,0,0,0,0,0,0,0,0,0,0,0,0,0,0,0,0,0,0,0,0,0,0,0
0,0,0,0,0,0,0,0,0,0,0,0,0,0,0,0,0,0,0,0,0,0,0,0
0,0,0,0,0,0,0,0,0,0,0,0,0,0,0,0,0,0,0,0,0,0,0,0
:endlayer
layer: 17
0,0,0,0,0,0,0,0,0,0,0,0,0,0,0,0,0,0,0,0,0,0,0,0
0,0,0,0,0,0,0,0,0,0,0,0,0,0,0,0,0,0,0,0,0,0,0,0
0,0,0,0,0,0,0,0,0,0,0,0,0,0,0,0,0,0,0,0,0,0,0,0
0,0,0,0,0,0,0,0,0,0,0,0,0,0,0,0,0,0,0,0,0,0,0,0
0,0,0,0,0,0,0,0,0,0,0,0,0,0,0,0,0,0,0,0,0,0,0,0
0,0,0,0,0,0,0,0,0,0,0,0,0,0,0,0,0,0,0,0,0,0,0,0
0,0,0,0,0,0,0,0,0,0,0,0,0,0,0,0,0,0,0,0,0,0,0,0
0,0,0,0,0,0,0,0,0,0,0,0,0,0,0,0,0,0,0,0,0,0,0,0
0,0,0,0,0,0,0,0,0,0,0,0,0,0,0,0,0,0,0,0,0,0,0,0
0,0,0,0,0,0,0,0,0,0,0,0,0,0,0,0,0,0,0,0,0,0,0,0
0,0,0,0,0,0,0,0,0,0,0,0,0,0,0,0,0,0,0,0,0,0,0,0
0,0,0,0,0,0,0,0,0,0,0,0,0,0,0,0,0,0,0,0,0,0,0,0
0,0,0,0,0,0,0,0,0,0,0,0,0,0,0,0,0,0,0,0,0,0,0,0
0,0,0,0,0,0,0,0,0,0,0,0,0,0,0,0,0,0,0,0,0,0,0,0
0,0,0,0,0,0,0,0,0,0,0,0,0,0,0,0,0,0,0,0,0,0,0,0
0,0,0,0,0,0,0,0,0,0,0,0,0,0,0,0,0,0,0,0,0,0,0,0
0,0,0,0,0,0,0,0,0,0,0,0,0,0,0,0,0,0,0,0,0,0,0,0
0,0,0,0,0,0,0,0,0,0,0,0,0,0,0,0,0,0,0,0,0,0,0,0
0,0,0,0,0,0,0,0,0,0,0,0,0,0,0,0,0,0,0,0,0,0,0,0
:endlayer
layer: 18
0,0,0,0,0,0,0,0,0,0,0,0,0,0,0,0,0,0,0,0,0,0,0,0
0,0,0,0,0,0,0,0,0,0,0,0,0,0,0,0,0,0,0,0,0,0,0,0
0,0,0,0,0,0,0,0,0,0,0,0,0,0,0,0,0,0,0,0,0,0,0,0
0,0,0,0,0,0,0,0,0,0,0,0,0,0,0,0,0,0,0,0,0,0,0,0
0,0,0,0,0,0,0,0,0,0,0,0,0,0,0,0,0,0,0,0,0,0,0,0
0,0,0,0,0,0,0,0,0,0,0,0,0,0,0,0,0,0,0,0,0,0,0,0
0,0,0,0,0,0,0,0,0,0,0,0,0,0,0,0,0,0,0,0,0,0,0,0
0,0,0,0,0,0,0,0,0,0,0,0,0,0,0,0,0,0,0,0,0,0,0,0
0,0,0,0,0,0,0,0,0,0,0,0,0,0,0,0,0,0,0,0,0,0,0,0
0,0,0,0,0,0,0,0,0,0,0,0,0,0,0,0,0,0,0,0,0,0,0,0
0,0,0,0,0,0,0,0,0,0,0,0,0,0,0,0,0,0,0,0,0,0,0,0
0,0,0,0,0,0,0,0,0,0,0,0,0,0,0,0,0,0,0,0,0,0,0,0
0,0,0,0,0,0,0,0,0,0,0,0,0,0,0,0,0,0,0,0,0,0,0,0
0,0,0,0,0,0,0,0,0,0,0,0,0,0,0,0,0,0,0,0,0,0,0,0
0,0,0,0,0,0,0,0,0,0,0,0,0,0,0,0,0,0,0,0,0,0,0,0
0,0,0,0,0,0,0,0,0,0,0,0,0,0,0,0,0,0,0,0,0,0,0,0
0,0,0,0,0,0,0,0,0,0,0,0,0,0,0,0,0,0,0,0,0,0,0,0
0,0,0,0,0,0,0,0,0,0,0,0,0,0,0,0,0,0,0,0,0,0,0,0
0,0,0,0,0,0,0,0,0,0,0,0,0,0,0,0,0,0,0,0,0,0,0,0
:endlayer
layer: 19
0,0,0,0,0,0,0,0,0,0,0,0,0,0,0,0,0,0,0,0,0,0,0,0
0,0,0,0,0,0,0,0,0,0,0,0,0,0,0,0,0,0,0,0,0,0,0,0
0,0,0,0,0,0,0,0,0,0,0,0,0,0,0,0,0,0,0,0,0,0,0,0
0,0,0,0,0,0,0,0,0,0,0,0,0,0,0,0,0,0,0,0,0,0,0,0
0,0,0,0,0,0,0,0,0,0,0,0,0,0,0,0,0,0,0,0,0,0,0,0
0,0,0,0,0,0,0,0,0,0,0,0,0,0,0,0,0,0,0,0,0,0,0,0
0,0,0,0,0,0,0,0,0,0,0,0,0,0,0,0,0,0,0,0,0,0,0,0
0,0,0,0,0,0,0,0,0,0,0,0,0,0,0,0,0,0,0,0,0,0,0,0
0,0,0,0,0,0,0,0,0,0,0,0,0,0,0,0,0,0,0,0,0,0,0,0
0,0,0,0,0,0,0,0,0,0,0,0,0,0,0,0,0,0,0,0,0,0,0,0
0,0,0,0,0,0,0,0,0,0,0,0,0,0,0,0,0,0,0,0,0,0,0,0
0,0,0,0,0,0,0,0,0,0,0,0,0,0,0,0,0,0,0,0,0,0,0,0
0,0,0,0,0,0,0,0,0,0,0,0,0,0,0,0,0,0,0,0,0,0,0,0
0,0,0,0,0,0,0,0,0,0,0,0,0,0,0,0,0,0,0,0,0,0,0,0
0,0,0,0,0,0,0,0,0,0,0,0,0,0,0,0,0,0,0,0,0,0,0,0
0,0,0,0,0,0,0,0,0,0,0,0,0,0,0,0,0,0,0,0,0,0,0,0
0,0,0,0,0,0,0,0,0,0,0,0,0,0,0,0,0,0,0,0,0,0,0,0
0,0,0,0,0,0,0,0,0,0,0,0,0,0,0,0,0,0,0,0,0,0,0,0
0,0,0,0,0,0,0,0,0,0,0,0,0,0,0,0,0,0,0,0,0,0,0,0
:endlayer
layer: 20
0,0,0,0,0,0,0,0,0,0,0,0,0,0,0,0,0,0,0,0,0,0,0,0
0,0,0,0,0,0,0,0,0,0,0,0,0,0,0,0,0,0,0,0,0,0,0,0
0,0,0,0,0,0,0,0,0,0,0,0,0,0,0,0,0,0,0,0,0,0,0,0
0,0,0,0,0,0,0,0,0,0,0,0,0,0,0,0,0,0,0,0,0,0,0,0
0,0,0,0,0,0,0,0,0,0,0,0,0,0,0,0,0,0,0,0,0,0,0,0
0,0,0,0,0,0,0,0,0,0,0,0,0,0,0,0,0,0,0,0,0,0,0,0
0,0,0,0,0,0,0,0,0,0,0,0,0,0,0,0,0,0,0,0,0,0,0,0
0,0,0,0,0,0,0,0,0,0,0,0,0,0,0,0,0,0,0,0,0,0,0,0
0,0,0,0,0,0,0,0,0,0,0,0,0,0,0,0,0,0,0,0,0,0,0,0
0,0,0,0,0,0,0,0,0,0,0,0,0,0,0,0,0,0,0,0,0,0,0,0
0,0,0,0,0,0,0,0,0,0,0,0,0,0,0,0,0,0,0,0,0,0,0,0
0,0,0,0,0,0,0,0,0,0,0,0,0,0,0,0,0,0,0,0,0,0,0,0
0,0,0,0,0,0,0,0,0,0,0,0,0,0,0,0,0,0,0,0,0,0,0,0
0,0,0,0,0,0,0,0,0,0,0,0,0,0,0,0,0,0,0,0,0,0,0,0
0,0,0,0,0,0,0,0,0,0,0,0,0,0,0,0,0,0,0,0,0,0,0,0
0,0,0,0,0,0,0,0,0,0,0,0,0,0,0,0,0,0,0,0,0,0,0,0
0,0,0,0,0,0,0,0,0,0,0,0,0,0,0,0,0,0,0,0,0,0,0,0
0,0,0,0,0,0,0,0,0,0,0,0,0,0,0,0,0,0,0,0,0,0,0,0
0,0,0,0,0,0,0,0,0,0,0,0,0,0,0,0,0,0,0,0,0,0,0,0
:endlayer
layer: 21
0,0,0,0,0,0,0,0,0,0,0,0,0,0,0,0,0,0,0,0,0,0,0,0
0,0,0,0,0,0,0,0,0,0,0,0,0,0,0,0,0,0,0,0,0,0,0,0
0,0,0,0,0,0,0,0,0,0,0,0,0,0,0,0,0,0,0,0,0,0,0,0
0,0,0,0,0,0,0,0,0,0,0,0,0,0,0,0,0,0,0,0,0,0,0,0
0,0,0,0,0,0,0,0,0,0,0,0,0,0,0,0,0,0,0,0,0,0,0,0
0,0,0,0,0,0,0,0,0,0,0,0,0,0,0,0,0,0,0,0,0,0,0,0
0,0,0,0,0,0,0,0,0,0,0,0,0,0,0,0,0,0,0,0,0,0,0,0
0,0,0,0,0,0,0,0,0,0,0,0,0,0,0,0,0,0,0,0,0,0,0,0
0,0,0,0,0,0,0,0,0,0,0,0,0,0,0,0,0,0,0,0,0,0,0,0
0,0,0,0,0,0,0,0,0,0,0,0,0,0,0,0,0,0,0,0,0,0,0,0
0,0,0,0,0,0,0,0,0,0,0,0,0,0,0,0,0,0,0,0,0,0,0,0
0,0,0,0,0,0,0,0,0,0,0,0,0,0,0,0,0,0,0,0,0,0,0,0
0,0,0,0,0,0,0,0,0,0,0,0,0,0,0,0,0,0,0,0,0,0,0,0
0,0,0,0,0,0,0,0,0,0,0,0,0,0,0,0,0,0,0,0,0,0,0,0
0,0,0,0,0,0,0,0,0,0,0,0,0,0,0,0,0,0,0,0,0,0,0,0
0,0,0,0,0,0,0,0,0,0,0,0,0,0,0,0,0,0,0,0,0,0,0,0
0,0,0,0,0,0,0,0,0,0,0,0,0,0,0,0,0,0,0,0,0,0,0,0
0,0,0,0,0,0,0,0,0,0,0,0,0,0,0,0,0,0,0,0,0,0,0,0
0,0,0,0,0,0,0,0,0,0,0,0,0,0,0,0,0,0,0,0,0,0,0,0
:endlayer

#### RULES ####
rule:
plugin=vanillaBlocks
number=1
data:
tag:
TAG=10={
TAG=8=blockName{dirt}
TAG=3=meta{0}
TAG=3=buildPass{0}
}
:endtag
:enddata
:endrule

rule:
plugin=vanillaBlocks
number=2
data:
tag:
TAG=10={
TAG=8=blockName{grass}
TAG=3=meta{0}
TAG=3=buildPass{0}
}
:endtag
:enddata
:endrule

rule:
plugin=vanillaBlocks
number=3
data:
tag:
TAG=10={
TAG=8=blockName{gravel}
TAG=3=meta{0}
TAG=3=buildPass{1}
}
:endtag
:enddata
:endrule

rule:
plugin=vanillaBlocks
number=4
data:
tag:
TAG=10={
TAG=8=blockName{cobblestone}
TAG=3=meta{0}
TAG=3=buildPass{0}
}
:endtag
:enddata
:endrule

rule:
plugin=vanillaBlocks
number=5
data:
tag:
TAG=10={
TAG=8=blockName{tallgrass}
TAG=3=meta{1}
TAG=3=buildPass{0}
}
:endtag
:enddata
:endrule

rule:
plugin=vanillaBlocks
number=6
data:
tag:
TAG=10={
TAG=8=blockName{fence}
TAG=3=meta{0}
TAG=3=buildPass{0}
}
:endtag
:enddata
:endrule

rule:
plugin=vanillaBlocks
number=7
data:
tag:
TAG=10={
TAG=8=blockName{hay_block}
TAG=3=meta{0}
TAG=3=buildPass{0}
}
:endtag
:enddata
:endrule

rule:
plugin=vanillaBlocks
number=8
data:
tag:
TAG=10={
TAG=8=blockName{stone_slab}
TAG=3=meta{3}
TAG=3=buildPass{0}
}
:endtag
:enddata
:endrule

rule:
plugin=vanillaBlocks
number=9
data:
tag:
TAG=10={
TAG=8=blockName{double_stone_slab}
TAG=3=meta{3}
TAG=3=buildPass{0}
}
:endtag
:enddata
:endrule

rule:
plugin=vanillaBlocks
number=10
data:
tag:
TAG=10={
TAG=8=blockName{log}
TAG=3=meta{0}
TAG=3=buildPass{0}
}
:endtag
:enddata
:endrule

rule:
plugin=vanillaBlocks
number=11
data:
tag:
TAG=10={
TAG=8=blockName{oak_stairs}
TAG=3=meta{3}
TAG=3=buildPass{0}
}
:endtag
:enddata
:endrule

rule:
plugin=vanillaBlocks
number=12
data:
tag:
TAG=10={
TAG=8=blockName{stonebrick}
TAG=3=meta{0}
TAG=3=buildPass{0}
}
:endtag
:enddata
:endrule

rule:
plugin=vanillaBlocks
number=13
data:
tag:
TAG=10={
TAG=8=blockName{planks}
TAG=3=meta{0}
TAG=3=buildPass{0}
}
:endtag
:enddata
:endrule

rule:
plugin=vanillaBlocks
number=14
data:
tag:
TAG=10={
TAG=8=blockName{stone_brick_stairs}
TAG=3=meta{2}
TAG=3=buildPass{0}
}
:endtag
:enddata
:endrule

rule:
plugin=vanillaDoors
number=15
data:
tag:
TAG=10={
TAG=1=sideFlag{9}
TAG=8=blockName{wooden_door}
TAG=3=meta{3}
TAG=3=buildPass{1}
}
:endtag
:enddata
:endrule

rule:
plugin=vanillaDoors
number=16
data:
tag:
TAG=10={
TAG=1=sideFlag{8}
TAG=8=blockName{wooden_door}
TAG=3=meta{3}
TAG=3=buildPass{1}
}
:endtag
:enddata
:endrule

rule:
plugin=vanillaBlocks
number=17
data:
tag:
TAG=10={
TAG=8=blockName{oak_stairs}
TAG=3=meta{1}
TAG=3=buildPass{0}
}
:endtag
:enddata
:endrule

rule:
plugin=vanillaBlocks
number=18
data:
tag:
TAG=10={
TAG=8=blockName{oak_stairs}
TAG=3=meta{2}
TAG=3=buildPass{0}
}
:endtag
:enddata
:endrule

rule:
plugin=vanillaDoors
number=19
data:
tag:
TAG=10={
TAG=1=sideFlag{8}
TAG=8=blockName{wooden_door}
TAG=3=meta{2}
TAG=3=buildPass{1}
}
:endtag
:enddata
:endrule

rule:
plugin=vanillaInventory
number=20
data:
tag:
TAG=10={
TAG=3=lootLevel{0}
TAG=10=teData{
TAG=9=Items{
TAG=10={
TAG=2=id{296}
TAG=2=Damage{0}
TAG=1=Count{2}
TAG=1=Slot{6}
}
TAG=10={
TAG=2=id{296}
TAG=2=Damage{0}
TAG=1=Count{4}
TAG=1=Slot{8}
}
TAG=10={
TAG=2=id{9265}
TAG=2=Damage{24}
TAG=1=Count{4}
TAG=1=Slot{20}
}
}
TAG=8=id{Chest}
}
TAG=8=blockName{chest}
TAG=3=meta{2}
TAG=3=buildPass{0}
}
:endtag
:enddata
:endrule

rule:
plugin=vanillaBlocks
number=21
data:
tag:
TAG=10={
TAG=8=blockName{planks}
TAG=3=meta{1}
TAG=3=buildPass{0}
}
:endtag
:enddata
:endrule

rule:
plugin=awAdvancedSpawner
number=22
data:
tag:
TAG=10={
TAG=10=teData{
TAG=9=Items{
}
TAG=8=id{Furnace}
TAG=2=BurnTime{0}
TAG=3=z{-333}
TAG=2=CookTime{0}
TAG=3=y{10}
TAG=3=x{970}
}
TAG=8=blockName{furnace}
TAG=3=meta{4}
TAG=3=buildPass{0}
}
:endtag
:enddata
:endrule

rule:
plugin=vanillaBlocks
number=23
data:
tag:
TAG=10={
TAG=8=blockName{crafting_table}
TAG=3=meta{0}
TAG=3=buildPass{0}
}
:endtag
:enddata
:endrule

rule:
plugin=vanillaBlocks
number=24
data:
tag:
TAG=10={
TAG=8=blockName{jukebox}
TAG=3=meta{0}
TAG=3=buildPass{0}
}
:endtag
:enddata
:endrule

rule:
plugin=vanillaInventory
number=25
data:
tag:
TAG=10={
TAG=3=lootLevel{0}
TAG=10=teData{
TAG=9=Items{
TAG=10={
TAG=2=id{265}
TAG=2=Damage{0}
TAG=1=Count{1}
TAG=1=Slot{9}
}
TAG=10={
TAG=2=id{329}
TAG=2=Damage{0}
TAG=1=Count{1}
TAG=1=Slot{20}
}
TAG=10={
TAG=2=id{296}
TAG=2=Damage{0}
TAG=1=Count{1}
TAG=1=Slot{21}
}
}
TAG=8=id{Chest}
}
TAG=8=blockName{chest}
TAG=3=meta{5}
TAG=3=buildPass{0}
}
:endtag
:enddata
:endrule

rule:
plugin=vanillaBlocks
number=26
data:
tag:
TAG=10={
TAG=8=blockName{jungle_stairs}
TAG=3=meta{2}
TAG=3=buildPass{0}
}
:endtag
:enddata
:endrule

rule:
plugin=vanillaInventory
number=27
data:
tag:
TAG=10={
TAG=3=lootLevel{0}
TAG=10=teData{
TAG=9=Items{
TAG=10={
TAG=2=id{325}
TAG=2=Damage{0}
TAG=1=Count{1}
TAG=1=Slot{14}
}
TAG=10={
TAG=2=id{2256}
TAG=2=Damage{0}
TAG=1=Count{1}
TAG=1=Slot{24}
}
TAG=10={
TAG=2=id{2257}
TAG=2=Damage{0}
TAG=1=Count{1}
TAG=1=Slot{25}
}
}
TAG=8=id{Chest}
}
TAG=8=blockName{chest}
TAG=3=meta{5}
TAG=3=buildPass{0}
}
:endtag
:enddata
:endrule

rule:
plugin=vanillaBlocks
number=28
data:
tag:
TAG=10={
TAG=8=blockName{jungle_stairs}
TAG=3=meta{0}
TAG=3=buildPass{0}
}
:endtag
:enddata
:endrule

rule:
plugin=vanillaBlocks
number=29
data:
tag:
TAG=10={
TAG=8=blockName{jungle_stairs}
TAG=3=meta{3}
TAG=3=buildPass{0}
}
:endtag
:enddata
:endrule

rule:
plugin=vanillaDoors
number=30
data:
tag:
TAG=10={
TAG=1=sideFlag{8}
TAG=8=blockName{wooden_door}
TAG=3=meta{1}
TAG=3=buildPass{1}
}
:endtag
:enddata
:endrule

rule:
plugin=vanillaDoors
number=31
data:
tag:
TAG=10={
TAG=1=sideFlag{0}
TAG=8=blockName{wooden_door}
TAG=3=meta{1}
TAG=3=buildPass{1}
}
:endtag
:enddata
:endrule

rule:
plugin=vanillaDoors
number=32
data:
tag:
TAG=10={
TAG=1=sideFlag{0}
TAG=8=blockName{wooden_door}
TAG=3=meta{8}
TAG=3=buildPass{1}
}
:endtag
:enddata
:endrule

rule:
plugin=vanillaDoors
number=33
data:
tag:
TAG=10={
TAG=1=sideFlag{0}
TAG=8=blockName{wooden_door}
TAG=3=meta{1}
TAG=3=buildPass{1}
}
:endtag
:enddata
:endrule

rule:
plugin=vanillaDoors
number=34
data:
tag:
TAG=10={
TAG=1=sideFlag{0}
TAG=8=blockName{wooden_door}
TAG=3=meta{8}
TAG=3=buildPass{1}
}
:endtag
:enddata
:endrule

rule:
plugin=vanillaDoors
number=35
data:
tag:
TAG=10={
TAG=1=sideFlag{0}
TAG=8=blockName{wooden_door}
TAG=3=meta{8}
TAG=3=buildPass{1}
}
:endtag
:enddata
:endrule

rule:
plugin=vanillaBlocks
number=36
data:
tag:
TAG=10={
TAG=8=blockName{stone_pressure_plate}
TAG=3=meta{0}
TAG=3=buildPass{0}
}
:endtag
:enddata
:endrule

rule:
plugin=vanillaBlocks
number=37
data:
tag:
TAG=10={
TAG=8=blockName{trapdoor}
TAG=3=meta{0}
TAG=3=buildPass{0}
}
:endtag
:enddata
:endrule

rule:
plugin=vanillaDoors
number=38
data:
tag:
TAG=10={
TAG=1=sideFlag{0}
TAG=8=blockName{wooden_door}
TAG=3=meta{8}
TAG=3=buildPass{1}
}
:endtag
:enddata
:endrule

rule:
plugin=vanillaSign
number=39
data:
tag:
TAG=10={
TAG=8=signContents1{}
TAG=8=blockName{wall_sign}
TAG=8=signContents2{}
TAG=8=signContents0{}
TAG=8=signContents3{}
TAG=3=meta{4}
TAG=3=buildPass{1}
}
:endtag
:enddata
:endrule

rule:
plugin=vanillaBlocks
number=40
data:
tag:
TAG=10={
TAG=8=blockName{wooden_pressure_plate}
TAG=3=meta{0}
TAG=3=buildPass{0}
}
:endtag
:enddata
:endrule

rule:
plugin=vanillaDoors
number=41
data:
tag:
TAG=10={
TAG=1=sideFlag{0}
TAG=8=blockName{wooden_door}
TAG=3=meta{8}
TAG=3=buildPass{1}
}
:endtag
:enddata
:endrule

rule:
plugin=vanillaBlocks
number=42
data:
tag:
TAG=10={
TAG=8=blockName{torch}
TAG=3=meta{3}
TAG=3=buildPass{1}
}
:endtag
:enddata
:endrule

rule:
plugin=vanillaBlocks
number=43
data:
tag:
TAG=10={
TAG=8=blockName{torch}
TAG=3=meta{1}
TAG=3=buildPass{1}
}
:endtag
:enddata
:endrule

rule:
plugin=vanillaBlocks
number=44
data:
tag:
TAG=10={
TAG=8=blockName{torch}
TAG=3=meta{2}
TAG=3=buildPass{1}
}
:endtag
:enddata
:endrule

rule:
plugin=vanillaBlocks
number=45
data:
tag:
TAG=10={
TAG=8=blockName{torch}
TAG=3=meta{4}
TAG=3=buildPass{1}
}
:endtag
:enddata
:endrule

rule:
plugin=vanillaSign
number=46
data:
tag:
TAG=10={
TAG=8=signContents1{}
TAG=8=blockName{wall_sign}
TAG=8=signContents2{}
TAG=8=signContents0{Tavern}
TAG=8=signContents3{}
TAG=3=meta{3}
TAG=3=buildPass{1}
}
:endtag
:enddata
:endrule

rule:
plugin=vanillaSign
number=47
data:
tag:
TAG=10={
TAG=8=signContents1{Lamb}
TAG=8=blockName{wall_sign}
TAG=8=signContents2{}
TAG=8=signContents0{Slaughtered}
TAG=8=signContents3{}
TAG=3=meta{5}
TAG=3=buildPass{1}
}
:endtag
:enddata
:endrule

rule:
plugin=vanillaSign
number=48
data:
tag:
TAG=10={
TAG=8=signContents1{Lamb}
TAG=8=blockName{wall_sign}
TAG=8=signContents2{}
TAG=8=signContents0{Slaughtered}
TAG=8=signContents3{}
TAG=3=meta{4}
TAG=3=buildPass{1}
}
:endtag
:enddata
:endrule

rule:
plugin=vanillaBlocks
number=49
data:
tag:
TAG=10={
TAG=8=blockName{oak_stairs}
TAG=3=meta{0}
TAG=3=buildPass{0}
}
:endtag
:enddata
:endrule

rule:
plugin=vanillaBlocks
number=50
data:
tag:
TAG=10={
TAG=8=blockName{torch}
TAG=3=meta{5}
TAG=3=buildPass{1}
}
:endtag
:enddata
:endrule

rule:
plugin=vanillaBlocks
number=51
data:
tag:
TAG=10={
TAG=8=blockName{glass_pane}
TAG=3=meta{0}
TAG=3=buildPass{0}
}
:endtag
:enddata
:endrule

rule:
plugin=vanillaBlocks
number=52
data:
tag:
TAG=10={
TAG=8=blockName{stone_slab}
TAG=3=meta{10}
TAG=3=buildPass{0}
}
:endtag
:enddata
:endrule

rule:
plugin=vanillaInventory
number=53
data:
tag:
TAG=10={
TAG=3=lootLevel{0}
TAG=10=teData{
TAG=9=Items{
TAG=10={
TAG=2=id{287}
TAG=2=Damage{0}
TAG=1=Count{1}
TAG=1=Slot{3}
}
TAG=10={
TAG=2=id{329}
TAG=2=Damage{0}
TAG=1=Count{1}
TAG=1=Slot{17}
}
TAG=10={
TAG=2=id{9265}
TAG=2=Damage{24}
TAG=1=Count{5}
TAG=1=Slot{22}
}
}
TAG=8=id{Chest}
}
TAG=8=blockName{chest}
TAG=3=meta{2}
TAG=3=buildPass{0}
}
:endtag
:enddata
:endrule

rule:
plugin=vanillaBlocks
number=54
data:
tag:
TAG=10={
TAG=8=blockName{bed}
TAG=3=meta{8}
TAG=3=buildPass{0}
}
:endtag
:enddata
:endrule

rule:
plugin=vanillaInventory
number=55
data:
tag:
TAG=10={
TAG=3=lootLevel{0}
TAG=10=teData{
TAG=9=Items{
TAG=10={
TAG=2=id{296}
TAG=2=Damage{0}
TAG=1=Count{4}
TAG=1=Slot{8}
}
TAG=10={
TAG=2=id{2256}
TAG=2=Damage{0}
TAG=1=Count{1}
TAG=1=Slot{24}
}
TAG=10={
TAG=2=id{417}
TAG=2=Damage{0}
TAG=1=Count{1}
TAG=1=Slot{26}
}
}
TAG=8=id{Chest}
}
TAG=8=blockName{chest}
TAG=3=meta{2}
TAG=3=buildPass{0}
}
:endtag
:enddata
:endrule

rule:
plugin=vanillaInventory
number=56
data:
tag:
TAG=10={
TAG=3=lootLevel{0}
TAG=10=teData{
TAG=9=Items{
TAG=10={
TAG=2=id{297}
TAG=2=Damage{0}
TAG=1=Count{1}
TAG=1=Slot{3}
}
TAG=10={
TAG=2=id{421}
TAG=2=Damage{0}
TAG=1=Count{1}
TAG=1=Slot{4}
}
TAG=10={
TAG=2=id{418}
TAG=2=Damage{0}
TAG=1=Count{1}
TAG=1=Slot{20}
}
}
TAG=8=id{Chest}
}
TAG=8=blockName{chest}
TAG=3=meta{2}
TAG=3=buildPass{0}
}
:endtag
:enddata
:endrule

rule:
plugin=vanillaBlocks
number=57
data:
tag:
TAG=10={
TAG=8=blockName{bed}
TAG=3=meta{0}
TAG=3=buildPass{0}
}
:endtag
:enddata
:endrule

rule:
plugin=vanillaBlocks
number=58
data:
tag:
TAG=10={
TAG=8=blockName{double_stone_slab}
TAG=3=meta{2}
TAG=3=buildPass{0}
}
:endtag
:enddata
:endrule

rule:
plugin=vanillaDoors
number=59
data:
tag:
TAG=10={
TAG=1=sideFlag{8}
TAG=8=blockName{wooden_door}
TAG=3=meta{0}
TAG=3=buildPass{1}
}
:endtag
:enddata
:endrule

rule:
plugin=vanillaBlocks
number=60
data:
tag:
TAG=10={
TAG=8=blockName{bookshelf}
TAG=3=meta{0}
TAG=3=buildPass{0}
}
:endtag
:enddata
:endrule

rule:
plugin=vanillaBlocks
number=61
data:
tag:
TAG=10={
TAG=8=blockName{bed}
TAG=3=meta{11}
TAG=3=buildPass{0}
}
:endtag
:enddata
:endrule

rule:
plugin=vanillaBlocks
number=62
data:
tag:
TAG=10={
TAG=8=blockName{bed}
TAG=3=meta{3}
TAG=3=buildPass{0}
}
:endtag
:enddata
:endrule

rule:
plugin=vanillaInventory
number=63
data:
tag:
TAG=10={
TAG=3=lootLevel{0}
TAG=10=teData{
TAG=9=Items{
TAG=10={
TAG=2=id{1204}
TAG=2=Damage{0}
TAG=1=Count{1}
TAG=1=Slot{0}
}
TAG=10={
TAG=2=id{1204}
TAG=2=Damage{0}
TAG=1=Count{1}
TAG=1=Slot{9}
}
}
TAG=8=id{Chest}
}
TAG=8=blockName{chest}
TAG=3=meta{5}
TAG=3=buildPass{0}
}
:endtag
:enddata
:endrule

rule:
plugin=vanillaInventory
number=64
data:
tag:
TAG=10={
TAG=3=lootLevel{0}
TAG=10=teData{
TAG=9=Items{
TAG=10={
TAG=2=id{1204}
TAG=2=Damage{0}
TAG=1=Count{1}
TAG=1=Slot{0}
}
TAG=10={
TAG=2=id{287}
TAG=2=Damage{0}
TAG=1=Count{2}
TAG=1=Slot{6}
}
TAG=10={
TAG=2=id{331}
TAG=2=Damage{0}
TAG=1=Count{2}
TAG=1=Slot{9}
}
}
TAG=8=id{Chest}
}
TAG=8=blockName{chest}
TAG=3=meta{5}
TAG=3=buildPass{0}
}
:endtag
:enddata
:endrule

rule:
plugin=vanillaInventory
number=65
data:
tag:
TAG=10={
TAG=3=lootLevel{0}
TAG=10=teData{
TAG=9=Items{
TAG=10={
TAG=2=id{296}
TAG=2=Damage{0}
TAG=1=Count{3}
TAG=1=Slot{6}
}
TAG=10={
TAG=2=id{9265}
TAG=2=Damage{24}
TAG=1=Count{5}
TAG=1=Slot{16}
}
TAG=10={
TAG=2=id{331}
TAG=2=Damage{0}
TAG=1=Count{1}
TAG=1=Slot{23}
}
}
TAG=8=id{Chest}
}
TAG=8=blockName{chest}
TAG=3=meta{5}
TAG=3=buildPass{0}
}
:endtag
:enddata
:endrule

rule:
plugin=vanillaBlocks
number=66
data:
tag:
TAG=10={
TAG=8=blockName{cauldron}
TAG=3=meta{3}
TAG=3=buildPass{0}
}
:endtag
:enddata
:endrule

rule:
plugin=vanillaInventory
number=67
data:
tag:
TAG=10={
TAG=3=lootLevel{0}
TAG=10=teData{
TAG=9=Items{
TAG=10={
TAG=2=id{329}
TAG=2=Damage{0}
TAG=1=Count{1}
TAG=1=Slot{6}
}
TAG=10={
TAG=2=id{417}
TAG=2=Damage{0}
TAG=1=Count{1}
TAG=1=Slot{13}
}
TAG=10={
TAG=2=id{2257}
TAG=2=Damage{0}
TAG=1=Count{1}
TAG=1=Slot{19}
}
}
TAG=8=id{Chest}
}
TAG=8=blockName{chest}
TAG=3=meta{5}
TAG=3=buildPass{0}
}
:endtag
:enddata
:endrule

rule:
plugin=vanillaBlocks
number=68
data:
tag:
TAG=10={
TAG=8=blockName{stone_slab}
TAG=3=meta{2}
TAG=3=buildPass{0}
}
:endtag
:enddata
:endrule

rule:
plugin=vanillaDoors
number=69
data:
tag:
TAG=10={
TAG=1=sideFlag{0}
TAG=8=blockName{wooden_door}
TAG=3=meta{8}
TAG=3=buildPass{1}
}
:endtag
:enddata
:endrule

rule:
plugin=vanillaDoors
number=70
data:
tag:
TAG=10={
TAG=1=sideFlag{0}
TAG=8=blockName{wooden_door}
TAG=3=meta{8}
TAG=3=buildPass{1}
}
:endtag
:enddata
:endrule

rule:
plugin=vanillaDoors
number=71
data:
tag:
TAG=10={
TAG=1=sideFlag{0}
TAG=8=blockName{wooden_door}
TAG=3=meta{8}
TAG=3=buildPass{1}
}
:endtag
:enddata
:endrule

rule:
plugin=vanillaBlocks
number=72
data:
tag:
TAG=10={
TAG=8=blockName{oak_stairs}
TAG=3=meta{7}
TAG=3=buildPass{0}
}
:endtag
:enddata
:endrule

rule:
plugin=vanillaBlocks
number=73
data:
tag:
TAG=10={
TAG=8=blockName{wooden_slab}
TAG=3=meta{8}
TAG=3=buildPass{0}
}
:endtag
:enddata
:endrule

rule:
plugin=vanillaBlocks
number=74
data:
tag:
TAG=10={
TAG=8=blockName{oak_stairs}
TAG=3=meta{5}
TAG=3=buildPass{0}
}
:endtag
:enddata
:endrule

rule:
plugin=vanillaBlocks
number=75
data:
tag:
TAG=10={
TAG=8=blockName{log}
TAG=3=meta{4}
TAG=3=buildPass{0}
}
:endtag
:enddata
:endrule

rule:
plugin=vanillaBlocks
number=76
data:
tag:
TAG=10={
TAG=8=blockName{oak_stairs}
TAG=3=meta{6}
TAG=3=buildPass{0}
}
:endtag
:enddata
:endrule

rule:
plugin=vanillaBlocks
number=77
data:
tag:
TAG=10={
TAG=8=blockName{wooden_slab}
TAG=3=meta{0}
TAG=3=buildPass{0}
}
:endtag
:enddata
:endrule

#### ENTITIES ####
entity:
plugin=vanillaLogicEntity
number=0
data:
position=23,2,17
tag:
TAG=10={
TAG=10=entityData{
TAG=9=DropChances{
TAG=5=0{0.085}
TAG=5=1{0.085}
TAG=5=2{0.085}
TAG=5=3{0.085}
TAG=5=4{0.085}
}
TAG=3=Age{0}
TAG=9=Attributes{
TAG=10={
TAG=8=Name{generic.maxHealth}
TAG=6=Base{20.0}
}
TAG=10={
TAG=8=Name{generic.knockbackResistance}
TAG=6=Base{0.0}
}
TAG=10={
TAG=8=Name{generic.movementSpeed}
TAG=6=Base{0.5}
}
TAG=10={
TAG=8=Name{generic.followRange}
TAG=6=Base{16.0}
TAG=9=Modifiers{
TAG=10={
TAG=8=Name{Random spawn bonus}
TAG=4=UUIDLeast{-7632238059639883786}
TAG=3=Operation{1}
TAG=6=Amount{-0.036144774471082004}
TAG=4=UUIDMost{-8781533089602712853}
}
}
}
}
TAG=9=Motion{
TAG=6={0.0}
TAG=6={-0.0784000015258789}
TAG=6={0.0}
}
TAG=8=CustomName{}
TAG=2=Health{20}
TAG=5=HealF{20.0}
TAG=1=CustomNameVisible{0}
TAG=3=Riches{0}
TAG=2=AttackTime{0}
TAG=2=Fire{-1}
TAG=1=Invulnerable{0}
TAG=2=DeathTime{0}
TAG=10=ForgeData{
TAG=1=MP|Init{1}
}
TAG=5=AbsorptionAmount{0.0}
TAG=9=Equipment{
TAG=10={
}
TAG=10={
}
TAG=10={
}
TAG=10={
}
TAG=10={
}
}
TAG=1=OnGround{1}
TAG=2=HurtTime{0}
TAG=3=Profession{45}
TAG=3=Dimension{0}
TAG=2=Air{300}
TAG=9=Pos{
TAG=6={959.5577781795176}
TAG=6={9.0}
TAG=6={-339.21936689556753}
}
TAG=1=CanPickUpLoot{0}
TAG=3=PortalCooldown{0}
TAG=1=PersistenceRequired{0}
TAG=1=Leashed{0}
TAG=5=FallDistance{0.0}
TAG=9=Rotation{
TAG=5={1969.5026}
TAG=5={0.0}
}
}
TAG=5=yOffset{0.0}
TAG=5=xOffset{0.44222182}
TAG=5=zOffset{0.21936691}
TAG=8=mobID{Villager}
TAG=5=rotation{349.50244}
}
:endtag
:enddata
:endentity

entity:
plugin=vanillaLogicEntity
number=1
data:
position=16,2,14
tag:
TAG=10={
TAG=10=entityData{
TAG=9=DropChances{
TAG=5=0{0.085}
TAG=5=1{0.085}
TAG=5=2{0.085}
TAG=5=3{0.085}
TAG=5=4{0.085}
}
TAG=3=Age{0}
TAG=9=Attributes{
TAG=10={
TAG=8=Name{generic.maxHealth}
TAG=6=Base{20.0}
}
TAG=10={
TAG=8=Name{generic.knockbackResistance}
TAG=6=Base{0.0}
}
TAG=10={
TAG=8=Name{generic.movementSpeed}
TAG=6=Base{0.5}
}
TAG=10={
TAG=8=Name{generic.followRange}
TAG=6=Base{16.0}
TAG=9=Modifiers{
TAG=10={
TAG=8=Name{Random spawn bonus}
TAG=4=UUIDLeast{-4973093533341948153}
TAG=3=Operation{1}
TAG=6=Amount{0.025968098008838904}
TAG=4=UUIDMost{8153633202456514054}
}
}
}
}
TAG=9=Motion{
TAG=6={0.0}
TAG=6={-0.0784000015258789}
TAG=6={0.0}
}
TAG=8=CustomName{}
TAG=2=Health{19}
TAG=5=HealF{19.0}
TAG=1=CustomNameVisible{0}
TAG=3=Riches{0}
TAG=2=AttackTime{0}
TAG=2=Fire{-1}
TAG=1=Invulnerable{0}
TAG=2=DeathTime{0}
TAG=10=ForgeData{
TAG=1=MP|Init{1}
}
TAG=5=AbsorptionAmount{0.0}
TAG=9=Equipment{
TAG=10={
}
TAG=10={
}
TAG=10={
}
TAG=10={
}
TAG=10={
}
}
TAG=1=OnGround{1}
TAG=2=HurtTime{0}
TAG=3=Profession{42}
TAG=3=Dimension{0}
TAG=2=Air{300}
TAG=9=Pos{
TAG=6={966.3067942848429}
TAG=6={9.0}
TAG=6={-336.30000001192093}
}
TAG=1=CanPickUpLoot{0}
TAG=3=PortalCooldown{0}
TAG=1=PersistenceRequired{0}
TAG=1=Leashed{0}
TAG=5=FallDistance{0.0}
TAG=9=Rotation{
TAG=5={308.26886}
TAG=5={0.0}
}
}
TAG=5=yOffset{0.0}
TAG=5=xOffset{0.6932057}
TAG=5=zOffset{0.3}
TAG=8=mobID{Villager}
TAG=5=rotation{128.26886}
}
:endtag
:enddata
:endentity

