# Ancient Warfare Structure Template File
# auto-generated structure file. created on: 4/15/2014 at: 13:33:8
# Lines beginning with # denote comments

header:
version=2.0
name=WatchPrisonTowerHostileMOH
size=19,46,31
offset=8,6,29
:endheader

#### VALIDATION ####
validation:
type=ground
survival=false
worldGenEnabled=true
unique=false
preserveBlocks=false
selectionWeight=10
clusterValue=10
minDuplicateDistance=100
dimensionWhiteList=false
dimensionList=
biomeWhiteList=true
biomeList=highlands.meadow,bop.meadow,ebxl.meadow,field,orchard
leveling=9
fill=3
border=3
validTargetBlocks=clay,lapis_ore,sand,grass,lit_redstone_ore,stone,gravel,iron_ore,diamond_ore,stained_hardened_clay,dirt,coal_ore,gold_ore,redstone_ore
data:
:enddata
:endvalidation

#### LAYERS ####
layer: 0
1,3,3,3,3,3,3,3,3,3,3,3,3,3,3,3,3,3,3
1,3,3,3,3,3,3,2,2,2,2,2,2,2,2,2,2,2,3
1,3,3,3,3,3,3,2,2,2,2,2,2,2,2,2,2,2,3
1,3,3,3,3,3,3,2,2,2,2,2,2,2,2,2,2,2,3
1,3,3,3,3,3,3,2,2,2,2,2,2,2,2,2,2,2,3
1,3,3,3,3,3,3,2,2,2,2,2,2,2,2,2,2,2,3
1,3,3,3,3,3,3,2,2,2,2,2,2,2,2,2,2,2,3
1,3,3,3,3,3,3,2,2,2,2,2,2,2,2,2,2,2,3
1,3,3,3,3,3,3,2,2,2,2,2,2,2,2,2,2,2,3
1,3,3,3,3,3,3,2,2,2,2,2,2,2,2,2,2,2,3
1,2,2,2,2,2,3,2,2,2,2,2,2,2,2,2,2,2,3
1,2,2,2,2,2,3,2,2,2,2,2,2,2,2,2,2,2,3
1,2,2,2,2,2,3,2,2,2,2,2,2,2,2,2,2,2,3
1,2,2,2,2,2,3,2,2,2,2,2,2,2,2,2,2,2,3
1,2,2,2,2,2,3,2,2,2,2,2,2,2,2,2,2,2,3
1,2,2,2,2,2,3,2,2,2,2,2,2,2,2,2,2,2,3
1,2,2,2,2,2,3,3,3,3,3,3,3,3,3,3,3,3,3
1,2,2,2,2,2,2,2,2,2,2,2,2,2,2,2,2,2,1
1,2,2,2,2,2,2,2,2,2,2,2,2,2,2,2,2,2,1
1,2,2,2,2,2,2,2,2,2,2,2,2,2,2,2,2,2,1
1,2,2,2,2,2,2,2,2,2,2,2,2,2,2,2,2,2,1
1,2,2,2,2,2,2,2,2,2,2,2,2,2,2,2,2,2,1
1,2,2,2,2,2,2,2,2,2,2,2,2,2,2,2,2,2,1
1,2,2,2,2,2,2,2,2,2,2,2,2,2,2,2,2,2,1
1,2,2,2,2,2,2,2,2,2,2,2,2,2,2,2,2,2,1
1,2,2,2,2,2,2,2,2,2,2,2,2,2,2,2,2,2,1
1,2,2,2,2,2,2,2,2,2,2,2,2,2,2,2,2,2,1
1,2,2,2,2,2,2,2,2,2,2,2,2,2,2,2,2,2,1
1,2,2,2,2,2,2,2,2,2,2,2,2,2,2,2,2,2,1
1,2,2,2,2,2,2,2,2,2,2,2,2,2,2,2,2,2,1
1,2,2,2,2,2,2,2,2,2,2,2,2,2,2,2,2,2,1
:endlayer
layer: 1
1,3,3,3,3,3,3,3,3,3,3,3,3,3,3,3,3,3,3
1,3,3,3,3,3,3,2,2,2,2,2,2,2,2,2,2,2,3
1,3,3,3,3,3,3,2,2,2,2,2,2,2,2,2,2,2,3
1,3,3,3,3,3,3,2,2,2,2,2,2,2,2,2,2,2,3
1,3,3,3,3,3,3,2,2,2,2,2,2,2,2,2,2,2,3
1,3,3,3,3,3,3,2,2,2,2,2,2,2,2,2,2,2,3
1,3,3,3,3,3,3,2,2,2,2,0,6,2,2,2,2,2,3
1,3,3,3,3,3,3,2,2,2,2,0,2,2,2,2,2,2,3
1,3,3,3,3,3,3,2,2,2,0,0,0,0,0,0,2,2,3
1,3,3,3,3,3,3,2,2,2,0,0,0,0,0,0,2,2,3
1,2,2,2,2,2,3,2,2,2,0,0,0,0,0,0,2,2,3
1,2,2,2,2,2,3,2,2,2,0,0,0,0,0,0,2,2,3
1,2,2,2,2,2,3,2,2,2,0,0,0,0,0,0,2,2,3
1,2,2,2,2,2,3,2,2,2,0,0,0,0,0,0,2,2,3
1,2,2,2,2,2,3,2,2,2,5,2,2,2,2,2,2,2,3
1,2,2,2,2,2,3,2,2,2,2,2,2,2,2,2,2,2,3
1,2,2,2,2,2,3,3,3,3,4,3,3,3,3,3,3,3,3
1,2,2,2,2,2,2,2,2,2,2,2,2,2,2,2,2,2,1
1,2,2,2,2,2,2,2,2,2,2,2,2,2,2,2,2,2,1
1,2,2,2,2,2,2,2,2,2,2,2,2,2,2,2,2,2,1
1,2,2,2,2,2,2,2,2,2,2,2,2,2,2,2,2,2,1
1,2,2,2,2,2,2,2,2,2,2,2,2,2,2,2,2,2,1
1,2,2,2,2,2,2,2,2,2,2,2,2,2,2,2,2,2,1
1,2,2,2,2,2,2,2,2,2,2,2,2,2,2,2,2,2,1
1,2,2,2,2,2,2,2,2,2,2,2,2,2,2,2,2,2,1
1,2,2,2,2,2,2,2,2,2,2,2,2,2,2,2,2,2,1
1,2,2,2,2,2,2,2,2,2,2,2,2,2,2,2,2,2,1
1,2,2,2,2,2,2,2,2,2,2,2,2,2,2,2,2,2,1
1,2,2,2,2,2,2,2,2,2,2,2,2,2,2,2,2,2,1
1,2,2,2,2,2,2,2,2,2,2,2,2,2,2,2,2,2,1
1,2,2,2,2,2,2,2,2,2,2,2,2,2,2,2,2,2,1
:endlayer
layer: 2
1,3,3,3,3,3,3,3,3,3,3,3,3,3,3,3,3,3,3
1,3,3,3,3,3,3,2,2,2,2,2,2,2,2,2,2,2,3
1,3,3,3,3,3,3,2,2,2,2,2,2,2,2,2,2,2,3
1,3,3,3,3,3,3,2,2,2,2,2,2,2,2,2,2,2,3
1,3,3,3,3,3,3,2,2,2,2,2,2,2,2,2,2,2,3
1,3,3,3,3,3,3,2,2,2,2,2,2,2,2,2,2,2,3
1,3,3,3,3,3,3,2,2,2,2,0,0,6,2,2,2,2,3
1,3,3,3,3,3,3,2,2,2,2,0,2,2,2,2,2,2,3
1,3,3,3,3,3,3,2,2,2,0,0,0,0,0,0,2,2,3
1,3,3,3,3,3,3,2,2,2,0,0,0,0,0,0,2,2,3
1,2,2,2,2,2,3,2,2,2,0,0,0,0,0,0,2,2,3
1,2,2,2,2,2,3,2,2,2,0,0,0,0,0,0,2,2,3
1,2,2,2,2,2,3,2,2,2,0,0,0,0,0,0,2,2,3
1,2,2,2,2,2,3,2,2,2,0,0,0,0,0,0,2,2,3
1,2,2,2,2,2,3,2,2,2,0,2,2,2,2,2,2,2,3
1,2,2,2,2,2,3,2,2,2,0,2,2,2,2,2,2,2,3
1,2,2,2,2,2,3,3,3,4,0,4,3,3,3,3,3,3,3
1,4,4,4,4,4,4,4,4,4,0,4,4,4,4,4,4,4,1
1,4,4,4,4,4,4,4,4,4,0,4,4,4,4,4,4,4,1
1,4,4,4,4,4,4,4,4,4,13,4,4,4,4,4,4,4,1
1,4,4,4,4,12,0,0,0,0,0,0,2,11,10,4,4,4,1
1,4,4,4,4,4,2,2,2,0,0,0,7,0,0,4,4,4,1
1,4,4,4,4,4,0,0,9,0,0,0,2,2,2,4,4,4,1
1,4,4,4,4,4,2,2,2,0,0,0,2,11,10,4,4,4,1
1,4,4,4,4,4,0,0,9,0,0,0,7,0,0,4,4,4,1
1,4,4,4,4,4,2,2,2,0,0,0,2,2,2,4,4,4,1
1,4,4,4,4,4,0,0,9,0,0,0,7,0,0,4,4,4,1
1,4,4,4,4,4,2,2,2,0,0,0,2,2,2,4,4,4,1
1,4,4,4,4,4,0,0,9,0,8,0,7,0,0,4,4,4,1
1,4,4,4,4,4,4,4,4,4,4,4,4,4,4,4,4,4,1
1,4,4,4,4,4,4,4,4,4,4,4,4,4,4,4,4,4,1
:endlayer
layer: 3
1,3,3,3,3,3,3,3,3,3,3,3,3,3,3,3,3,3,3
1,3,3,3,3,3,3,2,2,2,2,2,2,2,2,2,2,2,3
1,3,3,3,3,3,3,2,2,2,2,2,2,2,2,2,2,2,3
1,3,3,3,3,3,3,2,2,2,2,2,2,2,2,2,2,2,3
1,3,3,3,3,3,3,2,2,2,2,2,2,2,2,2,2,2,3
1,3,3,3,3,3,3,2,2,2,2,2,2,2,2,2,2,2,3
1,3,3,3,3,3,3,2,2,2,2,23,0,0,6,2,2,2,3
1,3,3,3,3,3,3,2,2,2,2,0,2,2,2,2,2,2,3
1,3,3,3,3,3,3,2,2,2,0,0,0,0,0,0,2,2,3
1,3,3,3,3,3,3,2,2,2,0,0,0,0,0,0,2,2,3
1,2,2,2,2,2,3,2,2,2,0,0,0,0,0,0,2,2,3
1,2,2,2,2,2,3,2,2,2,0,0,0,0,0,0,2,2,3
1,2,2,2,2,2,3,2,2,2,0,0,0,0,0,0,2,2,3
1,2,2,2,2,2,3,2,2,2,0,0,0,0,0,0,2,2,3
1,2,2,2,2,2,3,2,2,2,0,2,2,2,2,2,2,2,3
1,2,2,2,2,2,3,2,2,2,0,2,2,2,2,2,2,2,3
1,2,2,2,2,2,3,3,3,4,0,4,3,3,3,3,3,3,3
1,4,4,4,4,4,4,4,4,4,0,4,4,4,4,4,4,4,1
1,4,4,4,4,4,4,4,4,4,0,4,4,4,4,4,4,4,1
1,4,4,4,4,4,4,4,4,4,22,4,4,4,4,4,4,4,1
1,4,4,4,0,0,0,0,0,0,0,0,2,0,0,4,4,4,1
1,4,4,4,0,4,2,2,2,0,0,0,21,0,0,4,4,4,1
1,4,4,4,5,4,0,0,20,0,0,0,2,2,2,4,4,4,1
1,4,4,4,4,4,2,2,2,0,0,0,2,0,0,4,4,4,1
1,4,4,4,4,4,0,0,19,0,0,0,18,0,0,4,4,4,1
1,4,4,4,4,4,2,2,2,0,0,0,2,2,2,4,4,4,1
1,4,4,4,4,4,0,0,17,0,0,0,16,0,0,4,4,4,1
1,4,4,4,4,4,2,2,2,0,0,0,2,2,2,4,4,4,1
1,4,4,4,4,4,0,0,15,0,0,0,14,0,0,4,4,4,1
1,4,4,4,4,4,4,4,4,4,4,4,4,4,4,4,4,4,1
1,4,4,4,4,4,4,4,4,4,4,4,4,4,4,4,4,4,1
:endlayer
layer: 4
1,3,3,3,3,3,3,3,3,3,3,3,3,3,3,3,3,3,3
1,3,3,3,3,3,3,2,2,2,2,2,2,2,2,2,2,2,3
1,3,3,3,3,3,3,2,2,2,2,2,2,2,2,2,2,2,3
1,3,3,3,3,3,3,2,2,2,2,2,2,2,2,2,2,2,3
1,3,3,3,3,3,3,2,2,2,2,2,2,2,2,2,2,2,3
1,3,3,3,3,3,3,2,2,2,2,2,2,2,12,0,2,2,3
1,3,3,3,3,3,3,2,2,2,2,0,0,0,0,0,2,2,3
1,3,3,3,3,3,3,2,2,2,2,2,2,2,2,2,2,2,3
1,3,3,3,3,3,3,2,2,2,2,31,0,0,0,30,2,2,3
1,3,3,3,3,3,3,2,2,2,2,31,0,0,0,30,2,2,3
1,2,2,2,2,2,3,2,2,2,2,31,0,0,0,30,2,2,3
1,2,2,2,2,2,3,2,2,2,2,31,0,0,0,30,2,2,3
1,2,2,2,2,2,3,2,2,2,2,31,0,0,0,30,2,2,3
1,2,2,2,2,2,2,2,2,2,2,2,2,2,2,2,2,2,3
1,2,2,2,2,2,2,2,2,2,2,2,2,2,2,2,2,2,3
1,2,2,2,2,2,2,2,2,2,2,2,2,2,2,2,2,2,3
1,2,2,2,2,2,2,2,2,2,2,2,2,2,2,2,3,3,3
1,4,4,2,2,2,2,2,2,2,2,2,2,2,2,2,4,4,1
1,4,4,2,2,2,2,2,2,2,2,2,2,2,2,2,4,4,1
1,4,4,4,4,4,4,4,4,4,4,4,4,4,4,4,4,4,1
1,4,4,4,0,0,0,0,0,0,29,28,2,0,0,4,4,4,1
1,4,4,4,0,4,2,2,2,0,0,25,2,0,24,4,4,4,1
1,4,4,4,0,4,23,0,2,27,0,0,2,2,2,4,4,4,1
1,4,4,4,5,4,2,2,2,0,0,0,2,0,0,4,4,4,1
1,4,4,4,4,4,23,0,2,27,0,25,2,0,24,4,4,4,1
1,4,4,4,4,4,2,2,2,0,0,0,2,2,2,4,4,4,1
1,4,4,4,4,4,23,0,2,27,0,25,2,0,24,4,4,4,1
1,4,4,4,4,4,2,2,2,0,0,0,2,2,2,4,4,4,1
1,4,4,4,4,4,23,0,2,27,26,25,2,0,24,4,4,4,1
1,4,4,4,4,4,4,4,4,4,4,4,4,4,4,4,4,4,1
1,4,4,4,4,4,4,4,4,4,4,4,4,4,4,4,4,4,1
:endlayer
layer: 5
32,32,32,32,32,32,32,32,32,32,32,32,32,32,32,32,32,32,32
32,1,1,1,1,1,1,1,2,2,2,2,2,2,2,2,2,2,32
32,1,4,2,2,2,3,2,2,2,2,2,2,2,2,2,2,2,32
32,1,4,2,2,2,3,2,2,2,2,2,2,2,2,2,2,2,32
32,1,4,2,2,2,3,2,2,2,2,2,2,2,2,2,2,2,32
32,1,4,2,2,2,3,2,2,2,2,2,12,0,0,0,2,2,32
32,1,4,2,2,2,3,2,2,2,2,2,0,0,0,0,2,2,32
32,1,4,2,2,2,3,2,2,2,2,2,33,2,33,2,2,2,32
32,1,4,2,2,2,3,2,2,2,2,2,0,0,0,2,2,2,32
32,1,4,2,2,2,3,2,2,2,2,2,0,0,0,2,2,2,32
32,1,4,2,2,2,3,2,2,2,2,2,2,2,2,2,2,2,32
32,1,4,2,2,2,3,2,2,2,2,2,2,2,2,2,2,1,32
32,1,4,2,2,2,3,2,2,2,2,2,2,2,2,2,2,1,32
32,1,4,2,2,2,2,2,2,2,2,2,2,2,2,2,2,1,32
32,1,4,2,2,2,2,2,2,2,2,2,2,2,2,2,2,1,32
32,4,4,2,2,2,2,2,2,2,2,2,2,2,2,2,2,1,32
32,4,4,2,2,2,2,2,2,2,2,2,2,2,2,2,2,1,32
32,4,4,2,2,2,2,2,2,2,2,2,2,2,2,2,2,4,32
32,4,2,2,2,2,2,2,2,2,2,2,2,2,2,2,2,4,32
32,4,4,2,2,2,2,2,2,2,2,2,2,2,2,2,4,4,32
32,4,4,2,0,2,4,4,4,4,4,4,4,4,4,2,4,4,32
32,4,4,2,0,2,4,4,4,4,4,4,4,4,4,2,4,4,32
32,4,4,2,0,2,4,4,4,4,4,4,4,4,4,2,4,4,32
32,4,4,2,0,2,4,4,4,4,4,4,4,4,4,2,4,4,32
32,4,4,2,5,2,4,4,4,4,4,4,4,4,4,2,4,4,32
32,4,4,2,4,4,4,4,4,4,4,4,4,4,4,2,4,4,32
32,4,4,2,4,4,4,4,4,4,4,4,4,4,4,2,4,4,32
32,4,4,2,2,2,2,2,2,2,2,2,2,2,2,2,4,4,32
32,4,2,4,4,4,4,4,2,2,2,4,4,4,4,4,2,4,32
32,4,4,4,4,4,4,4,2,2,2,4,4,4,4,4,4,4,32
32,4,4,4,4,4,4,4,4,4,4,4,4,4,4,4,4,4,32
:endlayer
layer: 6
34,34,0,0,0,0,0,0,0,0,34,0,0,0,0,34,0,0,0
0,32,32,32,32,32,32,32,32,32,32,32,32,32,32,32,32,32,0
34,32,2,2,2,2,1,1,2,4,2,2,4,2,2,4,2,32,0
0,32,2,2,2,2,1,1,4,1,44,44,1,44,44,1,4,32,0
0,32,2,2,2,2,1,1,2,44,2,2,2,2,2,2,2,32,0
0,32,2,2,2,2,1,1,2,2,2,12,0,0,0,0,2,32,0
0,32,2,2,2,2,1,1,4,2,2,2,0,0,0,0,2,32,0
0,32,2,2,2,2,1,1,2,2,2,2,2,2,2,2,2,32,0
34,32,2,2,2,2,1,1,2,2,2,2,0,0,0,2,2,32,0
34,32,2,2,2,2,1,1,2,2,2,2,0,0,0,2,2,32,0
0,32,2,2,2,2,1,1,2,2,0,2,2,2,2,4,2,32,0
0,32,2,2,2,2,1,1,1,2,2,2,2,2,2,2,2,32,0
0,32,2,2,2,2,1,1,1,1,1,2,2,2,2,2,2,32,0
34,32,2,2,2,2,2,2,2,2,2,2,2,2,2,2,2,32,0
0,32,2,2,2,2,2,2,2,2,2,2,2,2,2,2,2,32,0
34,0,2,2,2,2,2,2,2,2,2,2,2,2,2,2,2,32,34
34,0,2,2,2,2,2,2,2,2,2,2,2,2,2,2,2,32,0
0,0,2,2,2,2,2,35,2,2,2,2,2,2,2,2,2,0,0
0,0,2,2,2,2,2,0,2,2,2,2,2,2,2,2,2,0,34
0,0,2,2,2,2,2,13,2,2,2,2,2,2,2,2,2,0,34
0,0,2,2,0,2,0,0,0,2,43,42,2,12,0,2,2,0,34
0,0,2,2,0,2,0,0,0,0,0,0,0,0,0,2,2,0,0
0,0,2,2,0,2,0,0,0,0,0,0,0,0,0,2,2,0,34
34,0,2,2,0,2,0,0,0,0,0,0,0,0,0,2,2,0,34
0,0,2,2,0,2,0,0,0,0,0,0,0,0,0,2,2,0,34
34,0,2,2,0,9,0,0,0,0,0,0,0,0,0,2,2,0,0
0,0,2,2,41,2,40,39,5,5,5,38,0,37,36,2,2,0,34
0,0,2,2,2,2,2,2,2,2,2,2,2,2,2,2,2,0,34
34,0,2,2,2,2,2,0,6,2,12,0,2,2,2,2,2,0,34
0,0,0,0,0,0,0,0,35,35,12,0,0,0,0,0,0,0,34
0,0,0,0,0,0,0,0,0,0,0,0,0,0,0,0,0,0,0
:endlayer
layer: 7
0,0,0,0,0,0,0,0,0,0,0,0,0,0,0,0,0,0,0
0,34,34,0,0,0,0,34,34,0,34,0,0,34,34,34,34,34,0
0,0,2,2,2,2,2,2,2,4,2,2,4,2,2,4,2,34,0
0,0,2,2,2,2,2,2,2,1,44,44,1,44,44,1,4,34,0
0,0,2,2,2,2,2,2,2,44,2,2,2,2,2,2,2,34,0
0,0,2,2,2,2,2,2,2,2,0,0,0,0,0,2,2,0,0
0,34,2,2,2,2,2,2,2,2,5,2,0,0,0,2,4,34,0
0,0,2,2,2,2,2,2,2,2,2,2,2,2,2,44,2,0,0
0,34,2,2,2,2,2,2,2,2,2,2,2,2,2,44,2,34,0
0,34,2,2,2,2,2,2,2,2,2,2,2,2,2,2,2,0,0
0,0,2,2,2,2,2,2,2,2,0,2,1,1,1,4,2,34,0
0,0,2,2,2,2,2,2,2,2,2,1,1,1,2,2,2,34,0
0,0,2,2,2,2,2,2,2,2,2,2,2,2,2,2,2,34,0
0,0,2,2,2,2,2,2,2,2,2,2,2,2,2,2,2,0,0
0,34,2,2,2,2,2,2,2,2,2,2,2,2,2,2,2,0,0
0,0,2,2,2,2,2,2,2,2,2,2,2,2,2,2,2,34,0
0,0,2,2,2,2,2,35,2,2,2,2,2,2,2,2,2,34,0
0,0,2,2,2,2,2,0,2,2,2,2,2,2,2,2,2,0,0
0,0,2,2,2,2,2,0,2,2,2,2,2,2,2,2,2,0,0
0,0,6,2,2,2,2,47,2,2,2,2,2,2,2,2,12,0,0
0,0,6,2,0,2,0,0,0,2,46,30,12,0,0,2,12,0,0
0,0,6,2,0,2,0,0,0,0,0,0,0,0,0,2,12,0,0
0,0,2,2,0,2,0,0,0,0,0,0,0,0,0,2,2,0,0
0,0,6,2,0,2,0,0,0,0,0,0,0,0,0,2,12,0,0
0,0,2,2,0,2,0,0,0,0,0,0,0,0,0,2,2,0,0
0,0,6,2,0,45,0,0,0,0,0,0,0,0,0,2,12,0,0
0,0,6,2,0,2,0,0,0,0,0,0,0,0,0,2,12,0,0
0,0,6,2,2,2,2,2,2,13,2,2,2,2,2,2,12,0,0
0,0,2,35,35,35,2,0,0,0,0,0,2,35,35,35,2,0,0
0,0,0,0,0,0,0,0,0,0,0,0,0,0,0,0,0,0,0
0,0,0,0,0,0,0,0,0,0,0,0,0,0,0,0,0,0,0
:endlayer
layer: 8
0,0,0,0,0,0,0,0,0,0,0,0,0,0,0,0,0,0,0
0,0,0,0,0,0,0,0,0,0,0,0,0,0,0,0,0,0,0
0,0,5,5,5,5,5,5,5,4,5,5,4,5,5,4,12,0,0
0,0,2,2,2,2,2,2,2,4,44,44,4,44,44,4,4,0,0
0,0,2,2,2,2,2,2,2,44,4,4,4,4,4,44,12,0,0
0,0,2,2,2,2,2,2,2,44,0,0,0,4,4,44,12,0,0
0,0,2,2,2,2,2,2,2,2,0,4,4,4,4,4,4,0,0
0,0,2,2,2,2,2,2,2,44,5,4,4,4,4,44,12,0,0
0,0,2,2,2,2,2,2,2,44,2,4,4,4,4,44,12,0,0
0,0,2,2,2,2,2,2,2,1,44,44,44,44,44,1,2,0,0
0,0,2,2,2,2,2,2,2,4,2,2,2,2,2,4,2,0,0
0,0,2,2,2,2,2,2,2,2,2,2,2,2,2,2,2,0,0
0,0,2,2,2,2,2,2,2,2,2,2,2,2,2,2,2,0,0
0,0,2,2,2,0,0,0,0,0,6,2,2,2,2,2,2,0,0
0,0,2,2,2,0,0,0,0,0,6,2,2,2,2,2,2,0,0
0,0,2,2,2,0,0,0,0,0,5,2,2,2,2,2,2,0,0
0,0,2,2,2,0,2,0,2,0,2,0,2,0,2,2,2,0,0
0,0,2,2,2,0,2,0,2,0,0,0,0,0,0,2,2,0,0
0,0,2,2,2,0,2,0,2,0,0,0,0,0,0,2,2,0,0
0,0,0,2,2,2,2,51,2,2,2,2,2,2,2,2,0,0,0
0,0,0,2,0,2,0,0,0,2,30,12,0,50,0,2,0,0,0
0,0,0,2,0,2,0,0,0,0,0,0,0,0,0,2,0,0,0
0,0,2,2,0,2,0,0,0,0,0,0,0,0,0,2,2,0,0
0,0,0,2,0,2,0,0,0,0,0,0,0,0,0,2,0,0,0
0,0,2,2,0,2,0,0,0,0,0,0,0,0,0,2,2,0,0
0,0,0,2,0,49,0,0,0,0,0,0,0,0,0,2,0,0,0
0,0,0,2,0,2,0,0,0,0,0,0,0,0,0,2,0,0,0
0,0,0,2,2,2,2,2,2,48,2,2,2,2,2,2,0,0,0
0,0,2,0,0,0,2,0,0,0,0,0,2,0,0,0,2,0,0
0,0,0,0,0,0,0,0,0,0,0,0,0,0,0,0,0,0,0
0,0,0,0,0,0,0,0,0,0,0,0,0,0,0,0,0,0,0
:endlayer
layer: 9
0,0,0,0,0,0,0,0,0,0,0,0,0,0,0,0,0,0,0
0,0,0,0,0,0,0,0,0,0,0,0,0,0,0,0,0,0,0
0,0,0,0,0,0,0,0,0,4,0,0,4,0,0,4,0,0,0
0,0,2,2,2,2,2,2,2,4,44,44,4,44,44,4,4,0,0
0,0,2,2,2,2,2,2,2,44,2,2,2,2,2,44,0,0,0
0,0,2,2,2,2,2,2,2,44,0,2,2,35,35,44,0,0,0
0,0,2,2,2,2,2,2,2,2,0,0,0,0,0,2,4,0,0
0,0,2,2,2,2,2,2,2,44,0,0,0,0,0,44,0,0,0
0,0,2,2,2,2,2,2,2,44,0,0,5,0,0,44,0,0,0
0,0,2,2,2,2,2,2,2,4,44,44,44,44,44,1,2,0,0
0,0,2,2,2,2,2,2,2,2,2,2,2,2,2,4,2,0,0
0,0,2,2,2,2,2,2,2,2,2,2,2,2,2,2,2,0,0
0,0,2,2,2,2,2,2,2,2,2,2,2,2,2,2,2,0,0
0,0,2,2,2,0,0,0,0,0,0,6,2,2,2,2,2,0,0
0,0,2,2,2,0,0,0,0,0,0,6,2,2,2,2,2,0,0
0,0,2,2,2,0,0,0,0,0,0,6,2,2,2,2,2,0,0
0,0,2,2,2,0,2,0,2,0,2,0,2,0,2,2,2,0,0
0,0,2,2,2,0,33,0,33,0,0,0,0,0,0,2,2,0,0
0,0,2,2,2,0,2,26,2,0,0,26,0,0,0,2,2,0,0
0,0,24,2,2,2,2,2,2,2,2,2,2,2,2,2,23,0,0
0,0,0,2,28,2,28,0,0,2,12,0,0,0,28,2,0,0,0
0,0,0,2,0,2,0,0,0,28,0,0,0,0,0,2,0,0,0
0,0,2,2,0,2,0,0,0,0,0,0,0,0,0,2,2,0,0
0,0,24,2,23,2,23,0,0,0,0,0,0,0,0,2,23,0,0
0,0,2,2,0,2,0,0,0,0,0,0,0,0,0,2,2,0,0
0,0,0,2,0,2,52,0,0,0,0,0,0,0,0,2,0,0,0
0,0,0,2,26,2,0,0,26,0,26,0,0,0,26,2,0,0,0
0,0,24,2,2,2,2,2,2,51,2,2,2,2,2,2,23,0,0
0,0,2,28,0,0,2,0,28,0,28,0,2,0,0,28,2,0,0
0,0,0,0,0,0,0,0,0,0,0,0,0,0,0,0,0,0,0
0,0,0,0,0,0,0,0,0,0,0,0,0,0,0,0,0,0,0
:endlayer
layer: 10
0,0,0,0,0,0,0,0,0,0,0,0,0,0,0,0,0,0,0
0,0,0,0,0,0,0,0,0,0,0,0,0,0,0,0,0,0,0
0,0,0,0,0,0,0,0,0,5,0,0,5,0,0,5,0,0,0
0,0,2,2,2,2,2,2,2,4,44,44,4,44,2,4,12,0,0
0,0,2,2,2,2,2,2,2,44,2,2,12,0,0,44,0,0,0
0,0,2,2,2,2,2,2,2,44,0,2,2,0,0,44,0,0,0
0,0,2,2,2,2,2,2,2,2,0,0,0,0,0,2,12,0,0
0,0,2,2,2,2,2,2,2,44,0,0,0,0,0,44,0,0,0
0,0,2,2,2,2,35,35,35,44,0,0,0,0,0,44,0,0,0
0,0,2,2,2,0,0,0,0,4,44,44,13,44,44,4,2,0,0
0,0,2,2,2,0,0,0,0,0,0,0,0,0,0,2,2,0,0
0,0,2,2,2,0,0,0,0,0,0,0,0,0,0,2,2,0,0
0,0,2,2,2,33,33,33,33,33,33,2,0,0,0,2,2,0,0
0,0,2,2,2,0,0,0,0,0,0,0,0,0,0,2,2,0,0
0,0,2,2,2,0,0,0,0,0,0,0,0,0,0,2,2,0,0
0,0,2,2,2,0,0,0,0,0,0,0,0,0,0,2,2,0,0
0,0,2,2,2,0,2,0,2,0,2,0,2,0,2,2,2,0,0
0,0,2,2,2,0,2,0,2,0,0,0,0,0,24,2,2,0,0
0,0,2,2,2,0,2,0,2,0,0,0,0,0,0,2,2,0,0
0,0,0,2,2,2,2,2,2,2,2,2,2,2,2,2,0,0,0
0,0,0,2,2,2,2,2,2,12,0,0,0,30,2,2,0,0,0
0,0,0,2,2,2,2,2,2,2,2,2,2,2,2,2,0,0,0
0,0,2,2,2,2,2,2,2,2,2,2,2,2,2,2,2,0,0
0,0,0,2,2,2,2,2,2,2,2,2,2,2,2,2,0,0,0
0,0,2,2,2,2,2,2,2,2,2,2,2,2,2,2,2,0,0
0,0,0,2,2,2,2,2,2,2,2,2,2,2,2,2,0,0,0
0,0,0,2,2,2,2,2,2,2,2,2,2,2,2,2,0,0,0
0,0,0,2,2,2,2,2,2,2,2,2,2,2,2,2,0,0,0
0,0,2,0,0,0,2,0,0,53,0,0,2,0,0,0,2,0,0
0,0,0,0,0,0,0,0,0,0,0,0,0,0,0,0,0,0,0
0,0,0,0,0,0,0,0,0,0,0,0,0,0,0,0,0,0,0
:endlayer
layer: 11
0,0,0,0,0,0,0,0,0,0,0,0,0,0,0,0,0,0,0
0,0,0,0,0,0,0,0,0,0,0,0,0,0,0,0,0,0,0
0,0,26,0,0,0,0,0,0,26,0,0,26,0,0,26,0,0,0
0,24,2,2,2,2,2,2,2,2,44,44,4,44,44,2,23,0,0
0,0,2,2,2,2,2,2,2,44,2,12,0,0,0,44,0,0,0
0,0,2,2,2,2,2,2,2,44,2,2,2,0,0,44,0,0,0
0,0,2,2,2,2,2,2,2,2,0,0,0,0,0,2,23,0,0
0,0,2,2,2,2,35,35,35,44,0,0,0,0,0,44,0,0,0
0,0,2,2,2,2,0,0,0,44,23,0,0,0,24,44,0,0,0
0,0,2,2,2,0,0,0,24,2,44,44,72,25,44,2,2,0,0
0,0,2,2,2,0,0,0,0,0,0,0,0,0,0,2,2,0,0
0,0,2,2,2,0,0,0,0,0,0,0,0,0,0,2,2,0,0
0,0,2,2,2,0,0,0,0,0,0,71,0,0,0,2,2,0,0
0,0,2,2,2,0,0,0,0,0,0,0,0,0,0,2,2,0,0
0,0,2,2,2,23,0,0,0,0,0,0,0,0,0,2,2,0,0
0,0,2,2,2,0,0,0,0,0,0,0,0,0,0,2,2,0,0
0,0,2,2,2,2,2,2,2,2,2,2,2,2,2,2,2,0,0
0,0,2,2,2,2,2,2,2,2,2,2,2,2,2,2,2,0,0
0,0,2,2,2,2,2,2,2,2,2,2,2,2,2,2,2,0,0
0,0,2,35,70,0,70,0,0,0,69,68,0,0,67,2,2,0,0
0,0,2,0,65,66,65,64,0,0,0,0,0,63,0,2,2,0,0
0,0,2,0,0,0,0,0,0,0,62,62,62,61,0,35,2,0,0
0,0,2,0,0,0,0,0,0,0,0,0,0,0,0,0,2,0,0
0,0,2,0,0,0,0,0,0,0,0,0,0,0,0,0,2,0,0
0,0,2,0,0,0,0,0,0,0,0,0,0,0,0,0,2,0,0
0,0,2,0,60,0,60,0,60,0,60,0,60,0,0,0,2,0,0
0,0,2,0,55,59,55,58,55,57,55,56,55,54,0,0,2,0,0
0,0,2,0,0,0,0,0,0,0,0,0,0,0,0,0,2,0,0
0,0,2,2,2,2,2,2,2,2,2,2,2,2,2,2,2,0,0
0,0,0,0,0,0,0,0,0,0,0,0,0,0,0,0,0,0,0
0,0,0,0,0,0,0,0,0,0,0,0,0,0,0,0,0,0,0
:endlayer
layer: 12
0,0,0,0,0,0,0,0,0,0,0,0,0,0,0,0,0,0,0
0,0,0,0,0,0,0,0,0,0,0,0,0,0,0,0,0,0,0
0,0,0,0,0,0,0,0,0,75,0,0,75,0,0,75,0,0,0
0,0,2,2,2,2,2,2,2,2,2,2,2,2,2,2,31,0,0
0,0,2,0,0,0,0,0,0,2,12,0,0,0,74,2,0,0,0
0,0,2,0,0,0,0,0,0,2,5,74,74,74,74,2,0,0,0
0,0,2,0,0,0,0,0,0,2,74,74,74,74,74,2,31,0,0
0,0,2,0,0,0,0,0,0,2,74,74,74,74,74,2,0,0,0
0,0,2,0,0,2,0,0,0,2,74,74,74,74,74,2,0,0,0
0,0,2,0,0,0,0,0,0,2,2,2,2,2,2,2,2,0,0
0,0,2,0,0,0,0,0,0,0,0,0,28,0,0,0,2,0,0
0,0,2,0,0,0,0,0,0,0,0,0,0,0,0,0,2,0,0
0,0,2,0,0,0,0,0,0,0,0,0,0,0,0,0,2,0,0
0,0,2,0,0,0,0,0,0,0,0,0,0,0,0,0,2,0,0
0,0,2,0,0,0,0,0,0,0,0,0,0,0,0,0,2,0,0
0,0,2,0,0,0,0,0,0,0,0,0,0,0,0,0,2,0,0
0,0,2,0,0,0,0,0,0,0,0,0,0,0,0,0,2,0,0
0,0,2,0,0,0,0,0,0,0,0,0,0,0,0,0,2,0,0
0,0,2,13,2,73,2,73,2,73,2,2,2,2,2,2,2,0,0
0,0,73,0,0,0,0,0,0,0,0,0,0,0,30,2,2,0,0
0,0,2,0,0,0,0,0,0,0,0,0,0,0,0,35,2,0,0
0,0,73,0,0,0,0,0,0,0,71,0,71,0,0,0,73,0,0
0,0,2,0,0,0,0,0,0,0,0,0,0,0,0,0,2,0,0
0,0,73,0,0,0,0,0,0,0,0,0,0,0,0,0,73,0,0
0,0,2,0,0,0,0,0,0,0,0,0,0,0,0,0,2,0,0
0,0,73,0,0,0,0,0,0,0,0,0,0,0,0,0,73,0,0
0,0,2,0,0,0,0,0,0,0,0,0,0,0,0,0,2,0,0
0,0,73,0,0,0,0,0,0,0,0,0,0,0,0,0,73,0,0
0,0,2,73,2,73,2,73,2,73,2,73,2,73,2,73,2,0,0
0,0,0,0,0,0,0,0,0,0,0,0,0,0,0,0,0,0,0
0,0,0,0,0,0,0,0,0,0,0,0,0,0,0,0,0,0,0
:endlayer
layer: 13
0,0,0,0,0,0,0,0,0,0,0,0,0,0,0,0,0,0,0
0,0,0,0,0,0,0,0,0,0,0,0,0,0,0,0,0,0,0
0,0,0,0,0,0,0,0,0,0,0,0,0,0,0,0,0,0,0
0,0,77,0,77,0,77,0,77,2,4,4,2,4,4,2,0,0,0
0,0,0,0,0,0,0,0,0,4,0,0,0,12,0,4,0,0,0
0,0,77,0,0,0,0,0,0,2,0,0,0,0,0,4,0,0,0
0,0,0,0,0,0,0,0,0,2,33,33,33,2,79,2,0,0,0
0,0,77,0,0,0,0,0,0,4,0,0,0,0,0,4,0,0,0
0,0,0,0,0,71,0,0,0,4,0,0,0,0,0,4,0,0,0
0,0,77,0,0,0,0,0,0,2,4,4,2,4,4,2,77,0,0
0,0,0,0,0,0,0,0,0,0,0,78,78,78,0,0,0,0,0
0,0,77,0,0,0,0,0,0,0,0,0,0,0,0,0,77,0,0
0,0,0,0,0,0,0,0,0,0,0,0,0,0,0,0,0,0,0
0,0,77,0,0,0,0,0,0,0,0,0,0,0,0,0,77,0,0
0,0,0,0,0,0,0,0,0,0,0,0,0,0,0,0,0,0,0
0,0,77,0,0,0,0,0,0,0,0,0,0,0,0,0,77,0,0
0,0,0,0,0,0,0,0,0,0,0,0,0,0,0,0,0,0,0
0,0,77,0,0,0,0,0,0,0,0,0,0,0,0,0,77,0,0
0,0,2,76,2,73,2,73,2,73,2,2,2,2,2,2,2,0,0
0,0,73,0,0,0,0,0,0,0,0,0,28,30,12,0,2,0,0
0,0,2,0,0,0,0,0,0,0,0,0,0,0,0,0,2,0,0
0,0,73,0,0,0,0,0,0,0,0,0,0,0,0,0,73,0,0
0,0,2,0,0,0,0,0,0,0,0,0,0,0,0,0,2,0,0
0,0,73,0,0,0,0,0,0,0,0,0,0,0,0,0,73,0,0
0,0,2,0,0,0,0,0,0,0,0,0,0,0,0,0,2,0,0
0,0,73,0,0,0,0,0,0,0,0,0,0,0,0,0,73,0,0
0,0,2,0,0,0,0,0,0,0,0,0,0,0,0,0,2,0,0
0,0,73,0,0,0,0,0,0,0,0,0,0,0,0,0,73,0,0
0,0,2,73,2,73,2,73,2,73,2,73,2,73,2,73,2,0,0
0,0,0,0,0,0,0,0,0,0,0,0,0,0,0,0,0,0,0
0,0,0,0,0,0,0,0,0,0,0,0,0,0,0,0,0,0,0
:endlayer
layer: 14
0,0,0,0,0,0,0,0,0,0,0,0,0,0,0,0,0,0,0
0,0,0,0,0,0,0,0,0,0,0,0,0,0,0,0,0,0,0
0,0,0,0,0,0,0,0,0,0,0,0,0,0,0,0,0,0,0
0,0,0,0,0,0,0,0,0,2,33,33,2,33,33,2,0,0,0
0,0,0,0,0,0,0,0,0,33,0,0,12,0,0,33,0,0,0
0,0,0,0,0,0,0,0,0,2,0,0,0,0,0,33,0,0,0
0,0,0,0,0,0,0,0,0,2,33,33,33,2,80,2,0,0,0
0,0,0,0,0,0,0,0,0,33,0,0,0,0,0,33,0,0,0
0,0,0,0,0,0,0,0,0,33,0,0,0,0,0,33,0,0,0
0,0,0,0,0,0,0,0,0,2,33,33,2,33,33,2,0,0,0
0,0,0,0,0,0,0,0,0,0,0,0,0,0,0,0,0,0,0
0,0,0,0,0,0,0,0,0,0,0,0,0,0,0,0,0,0,0
0,0,0,0,0,0,0,0,0,0,0,0,0,0,0,0,0,0,0
0,0,0,0,0,0,0,0,0,0,0,0,0,0,0,0,0,0,0
0,0,0,0,0,0,0,0,0,0,0,0,0,0,0,0,0,0,0
0,0,0,0,0,0,0,0,0,0,0,0,0,0,0,0,0,0,0
0,0,0,0,0,0,0,0,0,0,0,0,0,0,0,0,0,0,0
0,0,0,0,26,0,26,0,26,0,26,0,26,0,26,0,0,0,0
0,0,2,51,2,73,2,73,2,73,2,2,2,2,2,2,2,0,0
0,0,73,0,0,0,0,0,0,0,0,0,30,12,0,0,2,0,0
0,0,2,0,0,0,0,0,0,0,0,0,0,0,0,0,2,0,0
0,0,73,0,0,0,0,0,0,0,0,0,0,0,0,0,73,0,0
0,0,2,0,0,0,0,0,0,0,0,0,0,0,0,0,2,0,0
0,0,73,0,0,0,0,0,0,0,0,0,0,0,0,0,73,0,0
0,0,2,0,0,0,0,0,0,0,0,0,0,0,0,0,2,0,0
0,0,73,0,0,0,0,0,0,0,0,0,0,0,0,0,73,0,0
0,0,2,0,0,0,0,0,0,0,0,0,0,0,0,0,2,0,0
0,0,73,0,0,0,0,0,0,0,0,0,0,0,0,0,73,0,0
0,0,2,73,2,73,2,73,2,73,2,73,2,73,2,73,2,0,0
0,0,0,0,0,0,0,0,0,0,0,0,0,0,0,0,0,0,0
0,0,0,0,0,0,0,0,0,0,0,0,0,0,0,0,0,0,0
:endlayer
layer: 15
0,0,0,0,0,0,0,0,0,0,0,0,0,0,0,0,0,0,0
0,0,0,0,0,0,0,0,0,0,0,0,0,0,0,0,0,0,0
0,0,0,0,0,0,0,0,0,75,0,0,0,0,0,75,0,0,0
0,0,0,0,0,0,0,0,30,44,4,4,44,4,4,44,31,0,0
0,0,0,0,0,0,0,0,0,4,0,12,0,0,0,4,0,0,0
0,0,0,0,0,0,0,0,0,4,23,0,0,0,81,4,0,0,0
0,0,0,0,0,0,0,0,0,44,33,33,33,2,2,44,0,0,0
0,0,0,0,0,0,0,0,0,4,0,0,0,0,0,4,0,0,0
0,0,0,0,0,0,0,0,0,4,0,0,0,0,0,4,0,0,0
0,0,0,0,0,0,0,0,30,44,4,4,44,4,4,44,31,0,0
0,0,0,0,0,0,0,0,0,78,0,0,0,0,0,78,0,0,0
0,0,0,0,0,0,0,0,0,0,0,0,0,0,0,0,0,0,0
0,0,0,0,0,0,0,0,0,0,0,0,0,0,0,0,0,0,0
0,0,0,0,0,0,0,0,0,0,0,0,0,0,0,0,0,0,0
0,0,0,0,0,0,0,0,0,0,0,0,0,0,0,0,0,0,0
0,0,0,0,0,0,0,0,0,0,0,0,0,0,0,0,0,0,0
0,0,0,0,0,0,0,0,0,0,0,0,0,0,0,0,0,0,0
0,0,26,0,0,0,0,0,0,0,0,0,0,0,0,0,26,0,0
0,24,2,2,2,2,2,2,2,2,2,2,2,2,2,2,2,23,0
0,0,2,28,0,0,28,0,0,28,0,30,12,0,0,24,2,0,0
0,0,2,0,0,0,0,0,0,0,0,0,0,0,0,0,2,0,0
0,0,2,0,0,0,0,0,0,0,0,0,0,0,0,0,2,0,0
0,0,2,0,0,0,0,0,0,0,0,0,0,0,0,0,2,0,0
0,0,2,0,0,0,0,0,0,0,0,0,0,0,0,24,2,0,0
0,0,2,23,0,0,0,0,0,0,0,0,0,0,0,0,2,0,0
0,0,2,0,0,0,0,0,0,0,0,0,0,0,0,0,2,0,0
0,0,2,0,0,0,0,0,0,0,0,0,0,0,0,0,2,0,0
0,0,2,26,0,0,26,0,0,26,0,0,26,0,0,26,2,0,0
0,24,2,2,2,2,2,2,2,2,2,2,2,2,2,2,2,23,0
0,0,28,0,0,0,0,0,0,0,0,0,0,0,0,0,28,0,0
0,0,0,0,0,0,0,0,0,0,0,0,0,0,0,0,0,0,0
:endlayer
layer: 16
0,0,0,0,0,0,0,0,0,0,0,0,0,0,0,0,0,0,0
0,0,0,0,0,0,0,0,0,0,0,0,0,0,0,0,0,0,0
0,0,0,0,0,0,0,0,0,0,0,0,0,0,0,0,0,0,0
0,0,0,0,0,0,0,0,0,44,4,4,44,4,4,44,0,0,0
0,0,0,0,0,0,0,0,0,4,12,0,0,0,28,4,0,0,0
0,0,0,0,0,0,0,0,0,4,0,0,0,0,0,4,0,0,0
0,0,0,0,0,0,0,0,0,44,33,33,33,2,2,44,0,0,0
0,0,0,0,0,0,0,0,0,4,0,0,0,0,0,4,0,0,0
0,0,0,0,0,0,0,0,0,4,26,0,0,0,0,4,0,0,0
0,0,0,0,0,0,0,0,0,44,4,4,44,4,4,44,0,0,0
0,0,0,0,0,0,0,0,0,0,0,0,0,0,0,0,0,0,0
0,0,0,0,0,0,0,0,0,0,0,0,0,0,0,0,0,0,0
0,0,0,0,0,0,0,0,0,0,0,0,0,0,0,0,0,0,0
0,0,0,0,0,0,0,0,0,0,0,0,0,0,0,0,0,0,0
0,0,0,0,0,0,0,0,0,0,0,0,0,0,0,0,0,0,0
0,0,0,0,0,0,0,0,0,0,0,0,0,0,0,0,0,0,0
0,0,0,0,0,0,0,0,0,0,0,0,0,0,0,0,0,0,0
0,30,75,75,75,75,75,75,75,75,75,75,75,75,75,75,75,75,0
0,30,2,2,2,2,2,2,2,2,2,2,2,2,2,2,2,31,0
0,30,2,2,2,2,2,2,2,2,2,12,0,0,0,30,2,31,0
0,30,2,2,2,2,2,2,2,2,2,2,2,2,2,2,2,31,0
0,30,2,2,2,2,2,2,2,2,2,2,2,2,2,2,2,31,0
0,30,2,2,2,2,2,2,2,2,2,2,2,2,2,2,2,31,0
0,30,2,2,2,2,2,2,2,2,2,2,2,2,2,2,2,31,0
0,30,2,2,2,2,2,2,2,2,2,2,2,2,2,2,2,31,0
0,30,2,2,2,2,2,2,2,2,2,2,2,2,2,2,2,31,0
0,30,2,2,2,2,2,2,2,2,2,2,2,2,2,2,2,31,0
0,30,2,2,2,2,2,2,2,2,2,2,2,2,2,2,2,31,0
0,30,2,2,2,2,2,2,2,2,2,2,2,2,2,2,2,31,0
0,30,78,78,78,78,78,78,78,78,78,78,78,78,78,78,78,31,0
0,0,0,0,0,0,0,0,0,0,0,0,0,0,0,0,0,0,0
:endlayer
layer: 17
0,0,0,0,0,0,0,0,0,0,0,0,0,0,0,0,0,0,0
0,0,0,0,0,0,0,0,0,0,0,0,0,0,0,0,0,0,0
0,0,0,0,0,0,0,0,0,0,0,0,0,0,0,0,0,0,0
0,0,0,0,0,0,0,0,0,44,4,4,44,4,4,44,0,0,0
0,0,0,0,0,0,0,0,0,4,0,0,0,74,74,4,0,0,0
0,0,0,0,0,0,0,0,0,4,5,74,74,74,74,4,0,0,0
0,0,0,0,0,0,0,0,0,44,74,74,74,2,74,44,0,0,0
0,0,0,0,0,0,0,0,0,4,74,74,74,74,74,4,0,0,0
0,0,0,0,0,0,0,0,0,4,74,74,74,74,74,4,0,0,0
0,0,0,0,0,0,0,0,0,44,4,4,44,4,4,44,0,0,0
0,0,0,0,0,0,0,0,0,0,0,0,0,0,0,0,0,0,0
0,0,0,0,0,0,0,0,0,0,0,0,0,0,0,0,0,0,0
0,0,0,0,0,0,0,0,0,0,0,0,0,0,0,0,0,0,0
0,0,0,0,0,0,0,0,0,0,0,0,0,0,0,0,0,0,0
0,0,0,0,0,0,0,0,0,0,0,0,0,0,0,0,0,0,0
0,0,0,0,0,0,0,0,0,0,0,0,0,0,0,0,0,0,0
0,0,0,0,0,0,0,0,0,0,0,0,0,0,0,0,0,0,0
0,2,2,2,2,2,2,2,2,2,2,2,2,2,2,2,2,2,0
0,2,0,0,0,0,0,0,0,0,0,62,0,0,0,62,0,2,0
0,2,0,0,0,0,0,0,0,0,0,0,0,0,0,62,0,2,0
0,2,0,0,0,0,0,0,0,0,0,62,62,62,62,62,0,2,0
0,2,0,0,0,0,0,0,0,0,0,0,0,0,0,0,0,2,0
0,2,0,0,0,0,0,0,0,26,0,0,0,0,0,0,0,2,0
0,2,0,0,0,0,0,0,24,2,23,0,0,0,0,0,0,2,0
0,2,0,0,0,0,0,0,0,28,0,0,0,0,0,0,0,2,0
0,2,0,0,0,0,0,0,0,0,0,0,0,0,0,0,0,2,0
0,2,0,0,0,0,0,0,0,0,0,0,0,0,0,0,0,2,0
0,2,0,0,0,0,0,0,0,0,0,0,0,0,0,0,0,2,0
0,2,0,0,0,0,0,0,0,0,0,0,0,0,0,0,0,2,0
0,2,2,2,2,2,2,2,2,2,2,2,2,2,2,2,2,2,0
0,0,0,0,0,0,0,0,0,0,0,0,0,0,0,0,0,0,0
:endlayer
layer: 18
0,0,0,0,0,0,0,0,0,0,0,0,0,0,0,0,0,0,0
0,0,0,0,0,0,0,0,0,0,0,0,0,0,0,0,0,0,0
0,0,0,0,0,0,0,0,0,0,0,0,0,0,0,0,0,0,0
0,0,0,0,0,0,0,0,0,44,4,4,44,4,4,44,0,0,0
0,0,0,0,0,0,0,0,0,4,0,0,0,12,0,4,0,0,0
0,0,0,0,0,0,0,0,0,4,0,0,0,0,0,4,0,0,0
0,0,0,0,0,0,0,0,0,44,33,33,33,2,79,44,0,0,0
0,0,0,0,0,0,0,0,0,4,0,0,0,0,0,4,0,0,0
0,0,0,0,0,0,0,0,0,4,0,0,0,0,0,4,0,0,0
0,0,0,0,0,0,0,0,0,44,4,4,44,4,4,44,0,0,0
0,0,0,0,0,0,0,0,0,0,0,0,0,0,0,0,0,0,0
0,0,0,0,0,0,0,0,0,0,0,0,0,0,0,0,0,0,0
0,0,0,0,0,0,0,0,0,0,0,0,0,0,0,0,0,0,0
0,0,0,0,0,0,0,0,0,0,0,0,0,0,0,0,0,0,0
0,0,0,0,0,0,0,0,0,0,0,0,0,0,0,0,0,0,0
0,0,0,0,0,0,0,0,0,0,0,0,0,0,0,0,0,0,0
0,0,0,0,0,0,0,0,0,0,0,0,0,0,0,0,0,0,0
0,2,0,77,0,77,0,77,0,77,0,77,0,77,0,77,0,2,0
0,0,0,0,0,0,0,0,0,0,0,62,0,0,0,62,0,0,0
0,77,0,0,0,0,0,0,0,0,0,0,0,0,0,0,0,77,0
0,0,0,0,0,0,0,0,0,0,0,62,0,0,0,62,0,0,0
0,77,0,0,0,0,0,0,0,0,0,0,0,0,0,0,0,77,0
0,0,0,0,0,0,0,0,0,0,0,0,0,0,0,0,0,0,0
0,77,0,0,0,0,0,0,0,62,0,0,0,0,0,0,0,77,0
0,0,0,0,0,0,0,0,0,0,0,0,0,0,0,0,0,0,0
0,77,0,0,0,0,0,0,0,0,0,0,0,0,0,0,0,77,0
0,0,0,0,0,0,0,0,0,0,0,0,0,0,0,0,0,0,0
0,77,0,0,0,0,0,0,0,0,0,0,0,0,0,0,0,77,0
0,0,0,0,0,0,0,0,0,0,0,0,0,0,0,0,0,0,0
0,2,0,77,0,77,0,77,0,77,0,77,0,77,0,77,0,2,0
0,0,0,0,0,0,0,0,0,0,0,0,0,0,0,0,0,0,0
:endlayer
layer: 19
0,0,0,0,0,0,0,0,0,0,0,0,0,0,0,0,0,0,0
0,0,0,0,0,0,0,0,0,0,0,0,0,0,0,0,0,0,0
0,0,0,0,0,0,0,0,0,0,0,0,0,0,0,0,0,0,0
0,0,0,0,0,0,0,0,0,2,33,33,2,33,33,2,0,0,0
0,0,0,0,0,0,0,0,0,33,0,0,12,0,0,33,0,0,0
0,0,0,0,0,0,0,0,0,33,0,0,0,0,0,33,0,0,0
0,0,0,0,0,0,0,0,0,2,33,33,33,2,82,2,0,0,0
0,0,0,0,0,0,0,0,0,33,0,0,0,0,0,33,0,0,0
0,0,0,0,0,0,0,0,0,33,0,0,0,0,0,33,0,0,0
0,0,0,0,0,0,0,0,0,2,33,33,2,33,33,2,0,0,0
0,0,0,0,0,0,0,0,0,0,0,0,0,0,0,0,0,0,0
0,0,0,0,0,0,0,0,0,0,0,0,0,0,0,0,0,0,0
0,0,0,0,0,0,0,0,0,0,0,0,0,0,0,0,0,0,0
0,0,0,0,0,0,0,0,0,0,0,0,0,0,0,0,0,0,0
0,0,0,0,0,0,0,0,0,0,0,0,0,0,0,0,0,0,0
0,0,0,0,0,0,0,0,0,0,0,0,0,0,0,0,0,0,0
0,0,0,0,0,0,0,0,0,0,0,0,0,0,0,0,0,0,0
0,71,0,0,0,0,0,0,0,0,0,0,0,0,0,0,0,71,0
0,0,0,0,0,0,0,0,0,0,0,62,0,0,0,62,0,0,0
0,0,0,0,0,0,0,0,0,0,0,0,0,0,0,0,0,0,0
0,0,0,0,0,0,0,0,0,0,0,62,0,0,0,62,0,0,0
0,0,0,0,0,0,0,0,0,0,0,0,0,0,0,0,0,0,0
0,0,0,0,0,0,0,0,0,0,0,0,0,0,0,0,0,0,0
0,0,0,0,0,0,0,0,0,62,0,0,0,0,0,0,0,0,0
0,0,0,0,0,0,0,0,0,0,0,0,0,0,0,0,0,0,0
0,0,0,0,0,0,0,0,0,0,0,0,0,0,0,0,0,0,0
0,0,0,0,0,0,0,0,0,0,0,0,0,0,0,0,0,0,0
0,0,0,0,0,0,0,0,0,0,0,0,0,0,0,0,0,0,0
0,0,0,0,0,0,0,0,0,0,0,0,0,0,0,0,0,0,0
0,71,0,0,0,0,0,0,0,0,0,0,0,0,0,0,0,71,0
0,0,0,0,0,0,0,0,0,0,0,0,0,0,0,0,0,0,0
:endlayer
layer: 20
0,0,0,0,0,0,0,0,0,0,0,0,0,0,0,0,0,0,0
0,0,0,0,0,0,0,0,0,0,0,0,0,0,0,0,0,0,0
0,0,0,0,0,0,0,0,0,0,0,0,0,0,0,0,0,0,0
0,0,0,0,0,0,0,0,0,44,4,4,44,4,4,44,0,0,0
0,0,0,0,0,0,0,0,0,4,0,12,0,0,0,4,0,0,0
0,0,0,0,0,0,0,0,0,4,23,0,0,0,81,4,0,0,0
0,0,0,0,0,0,0,0,0,44,33,33,33,2,2,44,0,0,0
0,0,0,0,0,0,0,0,0,4,0,0,0,0,0,4,0,0,0
0,0,0,0,0,0,0,0,0,4,26,0,0,0,0,4,0,0,0
0,0,0,0,0,0,0,0,0,44,4,4,44,4,4,44,0,0,0
0,0,0,0,0,0,0,0,0,0,0,0,0,0,0,0,0,0,0
0,0,0,0,0,0,0,0,0,0,0,0,0,0,0,0,0,0,0
0,0,0,0,0,0,0,0,0,0,0,0,0,0,0,0,0,0,0
0,0,0,0,0,0,0,0,0,0,0,0,0,0,0,0,0,0,0
0,0,0,0,0,0,0,0,0,0,0,0,0,0,0,0,0,0,0
0,0,0,0,0,0,0,0,0,0,0,0,0,0,0,0,0,0,0
0,0,0,0,0,0,0,0,0,0,0,0,0,0,0,0,0,0,0
0,0,0,0,0,0,0,0,0,0,0,0,0,0,0,0,0,0,0
0,0,0,0,0,0,0,0,0,0,0,83,83,83,83,83,0,0,0
0,0,0,0,0,0,0,0,0,0,0,83,83,83,83,83,0,0,0
0,0,0,0,0,0,0,0,0,0,0,83,83,83,83,83,0,0,0
0,0,0,0,0,0,0,0,0,0,0,0,0,0,0,0,0,0,0
0,0,0,0,0,0,0,0,0,0,0,0,0,0,0,0,0,0,0
0,0,0,0,0,0,0,0,0,62,0,0,0,0,0,0,0,0,0
0,0,0,0,0,0,0,0,0,0,0,0,0,0,0,0,0,0,0
0,0,0,0,0,0,0,0,0,0,0,0,0,0,0,0,0,0,0
0,0,0,0,0,0,0,0,0,0,0,0,0,0,0,0,0,0,0
0,0,0,0,0,0,0,0,0,0,0,0,0,0,0,0,0,0,0
0,0,0,0,0,0,0,0,0,0,0,0,0,0,0,0,0,0,0
0,0,0,0,0,0,0,0,0,0,0,0,0,0,0,0,0,0,0
0,0,0,0,0,0,0,0,0,0,0,0,0,0,0,0,0,0,0
:endlayer
layer: 21
0,0,0,0,0,0,0,0,0,0,0,0,0,0,0,0,0,0,0
0,0,0,0,0,0,0,0,0,0,0,0,0,0,0,0,0,0,0
0,0,0,0,0,0,0,0,0,0,0,0,0,0,0,0,0,0,0
0,0,0,0,0,0,0,0,0,44,4,4,44,4,4,44,0,0,0
0,0,0,0,0,0,0,0,0,4,12,0,0,0,0,4,0,0,0
0,0,0,0,0,0,0,0,0,4,0,0,0,0,0,4,0,0,0
0,0,0,0,0,0,0,0,0,44,33,33,33,33,2,44,0,0,0
0,0,0,0,0,0,0,0,0,4,0,0,0,0,0,4,0,0,0
0,0,0,0,0,0,0,0,0,4,0,0,0,0,0,4,0,0,0
0,0,0,0,0,0,0,0,0,44,4,4,44,4,4,44,0,0,0
0,0,0,0,0,0,0,0,0,0,0,0,0,0,0,0,0,0,0
0,0,0,0,0,0,0,0,0,0,0,0,0,0,0,0,0,0,0
0,0,0,0,0,0,0,0,0,0,0,0,0,0,0,0,0,0,0
0,0,0,0,0,0,0,0,0,0,0,0,0,0,0,0,0,0,0
0,0,0,0,0,0,0,0,0,0,0,0,0,0,0,0,0,0,0
0,0,0,0,0,0,0,0,0,0,0,0,0,0,0,0,0,0,0
0,0,0,0,0,0,0,0,0,0,0,0,0,0,0,0,0,0,0
0,0,0,0,0,0,0,0,0,0,0,0,0,0,0,0,0,0,0
0,0,0,0,0,0,0,0,0,0,0,0,0,0,0,0,0,0,0
0,0,0,0,0,0,0,0,0,0,0,0,0,0,0,0,0,0,0
0,0,0,0,0,0,0,0,0,0,0,0,0,0,0,0,0,0,0
0,0,0,0,0,0,0,0,0,0,0,0,0,0,0,0,0,0,0
0,0,0,0,0,0,0,0,0,0,0,0,0,0,0,0,0,0,0
0,0,0,0,0,0,0,0,0,62,0,0,0,0,0,0,0,0,0
0,0,0,0,0,0,0,0,0,0,0,0,0,0,0,0,0,0,0
0,0,0,0,0,0,0,0,0,0,0,0,0,0,0,0,0,0,0
0,0,0,0,0,0,0,0,0,0,0,0,0,0,0,0,0,0,0
0,0,0,0,0,0,0,0,0,0,0,0,0,0,0,0,0,0,0
0,0,0,0,0,0,0,0,0,0,0,0,0,0,0,0,0,0,0
0,0,0,0,0,0,0,0,0,0,0,0,0,0,0,0,0,0,0
0,0,0,0,0,0,0,0,0,0,0,0,0,0,0,0,0,0,0
:endlayer
layer: 22
0,0,0,0,0,0,0,0,0,0,0,0,0,0,0,0,0,0,0
0,0,0,0,0,0,0,0,0,0,0,0,0,0,0,0,0,0,0
0,0,0,0,0,0,0,0,0,0,0,0,0,0,0,0,0,0,0
0,0,0,0,0,0,0,0,0,44,4,4,44,4,4,44,0,0,0
0,0,0,0,0,0,0,0,0,4,0,0,0,74,74,4,0,0,0
0,0,0,0,0,0,0,0,0,4,5,74,74,74,74,4,0,0,0
0,0,0,0,0,0,0,0,0,44,74,74,74,74,74,44,0,0,0
0,0,0,0,0,0,0,0,0,4,74,74,74,74,74,4,0,0,0
0,0,0,0,0,0,0,0,0,4,74,74,74,74,74,4,0,0,0
0,0,0,0,0,0,0,0,0,44,4,4,44,4,4,44,0,0,0
0,0,0,0,0,0,0,0,0,0,0,0,0,0,0,0,0,0,0
0,0,0,0,0,0,0,0,0,0,0,0,0,0,0,0,0,0,0
0,0,0,0,0,0,0,0,0,0,0,0,0,0,0,0,0,0,0
0,0,0,0,0,0,0,0,0,0,0,0,0,0,0,0,0,0,0
0,0,0,0,0,0,0,0,0,0,0,0,0,0,0,0,0,0,0
0,0,0,0,0,0,0,0,0,0,0,0,0,0,0,0,0,0,0
0,0,0,0,0,0,0,0,0,0,0,0,0,0,0,0,0,0,0
0,0,0,0,0,0,0,0,0,0,0,0,0,0,0,0,0,0,0
0,0,0,0,0,0,0,0,0,0,0,0,0,0,0,0,0,0,0
0,0,0,0,0,0,0,0,0,0,0,0,0,0,0,0,0,0,0
0,0,0,0,0,0,0,0,0,0,0,0,0,0,0,0,0,0,0
0,0,0,0,0,0,0,0,0,0,0,0,0,0,0,0,0,0,0
0,0,0,0,0,0,0,0,0,0,0,0,0,0,0,0,0,0,0
0,0,0,0,0,0,0,0,0,62,0,0,0,0,0,0,0,0,0
0,0,0,0,0,0,0,0,0,0,0,0,0,0,0,0,0,0,0
0,0,0,0,0,0,0,0,0,0,0,0,0,0,0,0,0,0,0
0,0,0,0,0,0,0,0,0,0,0,0,0,0,0,0,0,0,0
0,0,0,0,0,0,0,0,0,0,0,0,0,0,0,0,0,0,0
0,0,0,0,0,0,0,0,0,0,0,0,0,0,0,0,0,0,0
0,0,0,0,0,0,0,0,0,0,0,0,0,0,0,0,0,0,0
0,0,0,0,0,0,0,0,0,0,0,0,0,0,0,0,0,0,0
:endlayer
layer: 23
0,0,0,0,0,0,0,0,0,0,0,0,0,0,0,0,0,0,0
0,0,0,0,0,0,0,0,0,0,0,0,0,0,0,0,0,0,0
0,0,0,0,0,0,0,0,0,0,0,0,0,0,0,0,0,0,0
0,0,0,0,0,0,0,0,0,44,4,4,44,4,4,44,0,0,0
0,0,0,0,0,0,0,0,0,4,0,0,0,12,0,4,0,0,0
0,0,0,0,0,0,0,0,0,4,0,0,0,0,0,4,0,0,0
0,0,0,0,0,0,0,0,0,44,33,33,33,2,85,44,0,0,0
0,0,0,0,0,0,0,0,0,4,0,0,0,0,0,4,0,0,0
0,0,0,0,0,0,0,0,0,4,84,0,0,0,0,4,0,0,0
0,0,0,0,0,0,0,0,0,44,4,4,44,4,4,44,0,0,0
0,0,0,0,0,0,0,0,0,0,0,0,0,0,0,0,0,0,0
0,0,0,0,0,0,0,0,0,0,0,0,0,0,0,0,0,0,0
0,0,0,0,0,0,0,0,0,0,0,0,0,0,0,0,0,0,0
0,0,0,0,0,0,0,0,0,0,0,0,0,0,0,0,0,0,0
0,0,0,0,0,0,0,0,0,0,0,0,0,0,0,0,0,0,0
0,0,0,0,0,0,0,0,0,0,0,0,0,0,0,0,0,0,0
0,0,0,0,0,0,0,0,0,0,0,0,0,0,0,0,0,0,0
0,0,0,0,0,0,0,0,0,0,0,0,0,0,0,0,0,0,0
0,0,0,0,0,0,0,0,0,0,0,0,0,0,0,0,0,0,0
0,0,0,0,0,0,0,0,0,0,0,0,0,0,0,0,0,0,0
0,0,0,0,0,0,0,0,0,0,0,0,0,0,0,0,0,0,0
0,0,0,0,0,0,0,0,0,0,0,0,0,0,0,0,0,0,0
0,0,0,0,0,0,0,0,0,0,0,0,0,0,0,0,0,0,0
0,0,0,0,0,0,0,0,0,62,0,0,0,0,0,0,0,0,0
0,0,0,0,0,0,0,0,0,0,0,0,0,0,0,0,0,0,0
0,0,0,0,0,0,0,0,0,0,0,0,0,0,0,0,0,0,0
0,0,0,0,0,0,0,0,0,0,0,0,0,0,0,0,0,0,0
0,0,0,0,0,0,0,0,0,0,0,0,0,0,0,0,0,0,0
0,0,0,0,0,0,0,0,0,0,0,0,0,0,0,0,0,0,0
0,0,0,0,0,0,0,0,0,0,0,0,0,0,0,0,0,0,0
0,0,0,0,0,0,0,0,0,0,0,0,0,0,0,0,0,0,0
:endlayer
layer: 24
0,0,0,0,0,0,0,0,0,0,0,0,0,0,0,0,0,0,0
0,0,0,0,0,0,0,0,0,0,0,0,0,0,0,0,0,0,0
0,0,0,0,0,0,0,0,0,0,0,0,0,0,0,0,0,0,0
0,0,0,0,0,0,0,0,0,2,33,33,2,33,33,2,0,0,0
0,0,0,0,0,0,0,0,0,33,0,0,12,0,0,33,0,0,0
0,0,0,0,0,0,0,0,0,33,0,0,0,0,0,33,0,0,0
0,0,0,0,0,0,0,0,0,2,33,33,33,2,86,2,0,0,0
0,0,0,0,0,0,0,0,0,33,0,0,0,0,0,33,0,0,0
0,0,0,0,0,0,0,0,0,33,0,0,0,0,0,33,0,0,0
0,0,0,0,0,0,0,0,0,2,33,33,2,33,33,2,0,0,0
0,0,0,0,0,0,0,0,0,0,0,0,0,0,0,0,0,0,0
0,0,0,0,0,0,0,0,0,0,0,0,0,0,0,0,0,0,0
0,0,0,0,0,0,0,0,0,0,0,0,0,0,0,0,0,0,0
0,0,0,0,0,0,0,0,0,0,0,0,0,0,0,0,0,0,0
0,0,0,0,0,0,0,0,0,0,0,0,0,0,0,0,0,0,0
0,0,0,0,0,0,0,0,0,0,0,0,0,0,0,0,0,0,0
0,0,0,0,0,0,0,0,0,0,0,0,0,0,0,0,0,0,0
0,0,0,0,0,0,0,0,0,0,0,0,0,0,0,0,0,0,0
0,0,0,0,0,0,0,0,0,0,0,0,0,0,0,0,0,0,0
0,0,0,0,0,0,0,0,0,0,0,0,0,0,0,0,0,0,0
0,0,0,0,0,0,0,0,0,0,0,0,0,0,0,0,0,0,0
0,0,0,0,0,0,0,0,0,0,0,0,0,0,0,0,0,0,0
0,0,0,0,0,0,0,0,0,0,0,0,0,0,0,0,0,0,0
0,0,0,0,0,0,0,0,0,71,0,0,0,0,0,0,0,0,0
0,0,0,0,0,0,0,0,0,0,0,0,0,0,0,0,0,0,0
0,0,0,0,0,0,0,0,0,0,0,0,0,0,0,0,0,0,0
0,0,0,0,0,0,0,0,0,0,0,0,0,0,0,0,0,0,0
0,0,0,0,0,0,0,0,0,0,0,0,0,0,0,0,0,0,0
0,0,0,0,0,0,0,0,0,0,0,0,0,0,0,0,0,0,0
0,0,0,0,0,0,0,0,0,0,0,0,0,0,0,0,0,0,0
0,0,0,0,0,0,0,0,0,0,0,0,0,0,0,0,0,0,0
:endlayer
layer: 25
0,0,0,0,0,0,0,0,0,0,0,0,0,0,0,0,0,0,0
0,0,0,0,0,0,0,0,0,0,0,0,0,0,0,0,0,0,0
0,0,0,0,0,0,0,0,0,0,0,0,0,0,0,0,0,0,0
0,0,0,0,0,0,0,0,0,44,4,4,44,4,4,44,0,0,0
0,0,0,0,0,0,0,0,0,4,0,12,0,0,0,4,0,0,0
0,0,0,0,0,0,0,0,0,4,23,0,0,0,87,4,0,0,0
0,0,0,0,0,0,0,0,0,44,33,33,33,2,2,44,0,0,0
0,0,0,0,0,0,0,0,0,4,23,0,0,0,0,4,0,0,0
0,0,0,0,0,0,0,0,0,4,0,0,0,0,0,4,0,0,0
0,0,0,0,0,0,0,0,0,44,4,4,44,4,4,44,0,0,0
0,0,0,0,0,0,0,0,0,0,0,0,0,0,0,0,0,0,0
0,0,0,0,0,0,0,0,0,0,0,0,0,0,0,0,0,0,0
0,0,0,0,0,0,0,0,0,0,0,0,0,0,0,0,0,0,0
0,0,0,0,0,0,0,0,0,0,0,0,0,0,0,0,0,0,0
0,0,0,0,0,0,0,0,0,0,0,0,0,0,0,0,0,0,0
0,0,0,0,0,0,0,0,0,0,0,0,0,0,0,0,0,0,0
0,0,0,0,0,0,0,0,0,0,0,0,0,0,0,0,0,0,0
0,0,0,0,0,0,0,0,0,0,0,0,0,0,0,0,0,0,0
0,0,0,0,0,0,0,0,0,0,0,0,0,0,0,0,0,0,0
0,0,0,0,0,0,0,0,0,0,0,0,0,0,0,0,0,0,0
0,0,0,0,0,0,0,0,0,0,0,0,0,0,0,0,0,0,0
0,0,0,0,0,0,0,0,0,0,0,0,0,0,0,0,0,0,0
0,0,0,0,0,0,0,0,0,0,0,0,0,0,0,0,0,0,0
0,0,0,0,0,0,0,0,0,0,0,0,0,0,0,0,0,0,0
0,0,0,0,0,0,0,0,0,0,0,0,0,0,0,0,0,0,0
0,0,0,0,0,0,0,0,0,0,0,0,0,0,0,0,0,0,0
0,0,0,0,0,0,0,0,0,0,0,0,0,0,0,0,0,0,0
0,0,0,0,0,0,0,0,0,0,0,0,0,0,0,0,0,0,0
0,0,0,0,0,0,0,0,0,0,0,0,0,0,0,0,0,0,0
0,0,0,0,0,0,0,0,0,0,0,0,0,0,0,0,0,0,0
0,0,0,0,0,0,0,0,0,0,0,0,0,0,0,0,0,0,0
:endlayer
layer: 26
0,0,0,0,0,0,0,0,0,0,0,0,0,0,0,0,0,0,0
0,0,0,0,0,0,0,0,0,0,0,0,0,0,0,0,0,0,0
0,0,0,0,0,0,0,0,0,0,0,0,0,0,0,0,0,0,0
0,0,0,0,0,0,0,0,0,44,4,4,44,4,4,44,0,0,0
0,0,0,0,0,0,0,0,0,4,12,0,0,0,0,4,0,0,0
0,0,0,0,0,0,0,0,0,4,0,0,0,0,0,4,0,0,0
0,0,0,0,0,0,0,0,0,44,33,33,33,2,2,44,0,0,0
0,0,0,0,0,0,0,0,0,4,0,0,0,0,0,4,0,0,0
0,0,0,0,0,0,0,0,0,4,0,0,0,0,0,4,0,0,0
0,0,0,0,0,0,0,0,0,44,4,4,44,4,4,44,0,0,0
0,0,0,0,0,0,0,0,0,0,0,0,0,0,0,0,0,0,0
0,0,0,0,0,0,0,0,0,0,0,0,0,0,0,0,0,0,0
0,0,0,0,0,0,0,0,0,0,0,0,0,0,0,0,0,0,0
0,0,0,0,0,0,0,0,0,0,0,0,0,0,0,0,0,0,0
0,0,0,0,0,0,0,0,0,0,0,0,0,0,0,0,0,0,0
0,0,0,0,0,0,0,0,0,0,0,0,0,0,0,0,0,0,0
0,0,0,0,0,0,0,0,0,0,0,0,0,0,0,0,0,0,0
0,0,0,0,0,0,0,0,0,0,0,0,0,0,0,0,0,0,0
0,0,0,0,0,0,0,0,0,0,0,0,0,0,0,0,0,0,0
0,0,0,0,0,0,0,0,0,0,0,0,0,0,0,0,0,0,0
0,0,0,0,0,0,0,0,0,0,0,0,0,0,0,0,0,0,0
0,0,0,0,0,0,0,0,0,0,0,0,0,0,0,0,0,0,0
0,0,0,0,0,0,0,0,0,0,0,0,0,0,0,0,0,0,0
0,0,0,0,0,0,0,0,0,0,0,0,0,0,0,0,0,0,0
0,0,0,0,0,0,0,0,0,0,0,0,0,0,0,0,0,0,0
0,0,0,0,0,0,0,0,0,0,0,0,0,0,0,0,0,0,0
0,0,0,0,0,0,0,0,0,0,0,0,0,0,0,0,0,0,0
0,0,0,0,0,0,0,0,0,0,0,0,0,0,0,0,0,0,0
0,0,0,0,0,0,0,0,0,0,0,0,0,0,0,0,0,0,0
0,0,0,0,0,0,0,0,0,0,0,0,0,0,0,0,0,0,0
0,0,0,0,0,0,0,0,0,0,0,0,0,0,0,0,0,0,0
:endlayer
layer: 27
0,0,0,0,0,0,0,0,0,0,0,0,0,0,0,0,0,0,0
0,0,0,0,0,0,0,0,0,0,0,0,0,0,0,0,0,0,0
0,0,0,0,0,0,0,0,0,0,0,0,0,0,0,0,0,0,0
0,0,0,0,0,0,0,0,0,44,4,4,44,4,4,44,0,0,0
0,0,0,0,0,0,0,0,0,4,0,0,0,74,74,4,0,0,0
0,0,0,0,0,0,0,0,0,4,5,74,74,74,74,4,0,0,0
0,0,0,0,0,0,0,0,0,44,74,74,74,74,74,44,0,0,0
0,0,0,0,0,0,0,0,0,4,74,74,74,74,74,4,0,0,0
0,0,0,0,0,0,0,0,0,4,74,74,74,74,74,4,0,0,0
0,0,0,0,0,0,0,0,0,44,4,4,44,4,4,44,0,0,0
0,0,0,0,0,0,0,0,0,0,0,0,0,0,0,0,0,0,0
0,0,0,0,0,0,0,0,0,0,0,0,0,0,0,0,0,0,0
0,0,0,0,0,0,0,0,0,0,0,0,0,0,0,0,0,0,0
0,0,0,0,0,0,0,0,0,0,0,0,0,0,0,0,0,0,0
0,0,0,0,0,0,0,0,0,0,0,0,0,0,0,0,0,0,0
0,0,0,0,0,0,0,0,0,0,0,0,0,0,0,0,0,0,0
0,0,0,0,0,0,0,0,0,0,0,0,0,0,0,0,0,0,0
0,0,0,0,0,0,0,0,0,0,0,0,0,0,0,0,0,0,0
0,0,0,0,0,0,0,0,0,0,0,0,0,0,0,0,0,0,0
0,0,0,0,0,0,0,0,0,0,0,0,0,0,0,0,0,0,0
0,0,0,0,0,0,0,0,0,0,0,0,0,0,0,0,0,0,0
0,0,0,0,0,0,0,0,0,0,0,0,0,0,0,0,0,0,0
0,0,0,0,0,0,0,0,0,0,0,0,0,0,0,0,0,0,0
0,0,0,0,0,0,0,0,0,0,0,0,0,0,0,0,0,0,0
0,0,0,0,0,0,0,0,0,0,0,0,0,0,0,0,0,0,0
0,0,0,0,0,0,0,0,0,0,0,0,0,0,0,0,0,0,0
0,0,0,0,0,0,0,0,0,0,0,0,0,0,0,0,0,0,0
0,0,0,0,0,0,0,0,0,0,0,0,0,0,0,0,0,0,0
0,0,0,0,0,0,0,0,0,0,0,0,0,0,0,0,0,0,0
0,0,0,0,0,0,0,0,0,0,0,0,0,0,0,0,0,0,0
0,0,0,0,0,0,0,0,0,0,0,0,0,0,0,0,0,0,0
:endlayer
layer: 28
0,0,0,0,0,0,0,0,0,0,0,0,0,0,0,0,0,0,0
0,0,0,0,0,0,0,0,0,0,0,0,0,0,0,0,0,0,0
0,0,0,0,0,0,0,0,0,0,0,0,0,0,0,0,0,0,0
0,0,0,0,0,0,0,0,0,44,4,4,44,4,4,44,0,0,0
0,0,0,0,0,0,0,0,0,4,0,0,0,12,0,4,0,0,0
0,0,0,0,0,0,0,0,0,4,0,0,0,0,0,4,0,0,0
0,0,0,0,0,0,0,0,0,44,33,33,33,2,79,44,0,0,0
0,0,0,0,0,0,0,0,0,4,0,0,0,0,0,4,0,0,0
0,0,0,0,0,0,0,0,0,4,0,0,0,0,0,4,0,0,0
0,0,0,0,0,0,0,0,0,44,4,4,44,4,4,44,0,0,0
0,0,0,0,0,0,0,0,0,0,0,0,0,0,0,0,0,0,0
0,0,0,0,0,0,0,0,0,0,0,0,0,0,0,0,0,0,0
0,0,0,0,0,0,0,0,0,0,0,0,0,0,0,0,0,0,0
0,0,0,0,0,0,0,0,0,0,0,0,0,0,0,0,0,0,0
0,0,0,0,0,0,0,0,0,0,0,0,0,0,0,0,0,0,0
0,0,0,0,0,0,0,0,0,0,0,0,0,0,0,0,0,0,0
0,0,0,0,0,0,0,0,0,0,0,0,0,0,0,0,0,0,0
0,0,0,0,0,0,0,0,0,0,0,0,0,0,0,0,0,0,0
0,0,0,0,0,0,0,0,0,0,0,0,0,0,0,0,0,0,0
0,0,0,0,0,0,0,0,0,0,0,0,0,0,0,0,0,0,0
0,0,0,0,0,0,0,0,0,0,0,0,0,0,0,0,0,0,0
0,0,0,0,0,0,0,0,0,0,0,0,0,0,0,0,0,0,0
0,0,0,0,0,0,0,0,0,0,0,0,0,0,0,0,0,0,0
0,0,0,0,0,0,0,0,0,0,0,0,0,0,0,0,0,0,0
0,0,0,0,0,0,0,0,0,0,0,0,0,0,0,0,0,0,0
0,0,0,0,0,0,0,0,0,0,0,0,0,0,0,0,0,0,0
0,0,0,0,0,0,0,0,0,0,0,0,0,0,0,0,0,0,0
0,0,0,0,0,0,0,0,0,0,0,0,0,0,0,0,0,0,0
0,0,0,0,0,0,0,0,0,0,0,0,0,0,0,0,0,0,0
0,0,0,0,0,0,0,0,0,0,0,0,0,0,0,0,0,0,0
0,0,0,0,0,0,0,0,0,0,0,0,0,0,0,0,0,0,0
:endlayer
layer: 29
0,0,0,0,0,0,0,0,0,0,0,0,0,0,0,0,0,0,0
0,0,0,0,0,0,0,0,0,0,0,0,0,0,0,0,0,0,0
0,0,0,0,0,0,0,0,0,0,0,0,0,0,0,0,0,0,0
0,0,0,0,0,0,0,0,0,2,33,33,2,33,33,2,0,0,0
0,0,0,0,0,0,0,0,0,33,0,0,12,0,0,33,0,0,0
0,0,0,0,0,0,0,0,0,33,0,0,0,0,0,33,0,0,0
0,0,0,0,0,0,0,0,0,2,33,33,33,2,88,2,0,0,0
0,0,0,0,0,0,0,0,0,33,0,0,0,0,0,33,0,0,0
0,0,0,0,0,0,0,0,0,33,0,0,0,0,0,33,0,0,0
0,0,0,0,0,0,0,0,0,2,33,33,2,33,33,2,0,0,0
0,0,0,0,0,0,0,0,0,0,0,0,0,0,0,0,0,0,0
0,0,0,0,0,0,0,0,0,0,0,0,0,0,0,0,0,0,0
0,0,0,0,0,0,0,0,0,0,0,0,0,0,0,0,0,0,0
0,0,0,0,0,0,0,0,0,0,0,0,0,0,0,0,0,0,0
0,0,0,0,0,0,0,0,0,0,0,0,0,0,0,0,0,0,0
0,0,0,0,0,0,0,0,0,0,0,0,0,0,0,0,0,0,0
0,0,0,0,0,0,0,0,0,0,0,0,0,0,0,0,0,0,0
0,0,0,0,0,0,0,0,0,0,0,0,0,0,0,0,0,0,0
0,0,0,0,0,0,0,0,0,0,0,0,0,0,0,0,0,0,0
0,0,0,0,0,0,0,0,0,0,0,0,0,0,0,0,0,0,0
0,0,0,0,0,0,0,0,0,0,0,0,0,0,0,0,0,0,0
0,0,0,0,0,0,0,0,0,0,0,0,0,0,0,0,0,0,0
0,0,0,0,0,0,0,0,0,0,0,0,0,0,0,0,0,0,0
0,0,0,0,0,0,0,0,0,0,0,0,0,0,0,0,0,0,0
0,0,0,0,0,0,0,0,0,0,0,0,0,0,0,0,0,0,0
0,0,0,0,0,0,0,0,0,0,0,0,0,0,0,0,0,0,0
0,0,0,0,0,0,0,0,0,0,0,0,0,0,0,0,0,0,0
0,0,0,0,0,0,0,0,0,0,0,0,0,0,0,0,0,0,0
0,0,0,0,0,0,0,0,0,0,0,0,0,0,0,0,0,0,0
0,0,0,0,0,0,0,0,0,0,0,0,0,0,0,0,0,0,0
0,0,0,0,0,0,0,0,0,0,0,0,0,0,0,0,0,0,0
:endlayer
layer: 30
0,0,0,0,0,0,0,0,0,0,0,0,0,0,0,0,0,0,0
0,0,0,0,0,0,0,0,0,0,0,0,0,0,0,0,0,0,0
0,0,0,0,0,0,0,0,0,0,0,0,0,0,0,0,0,0,0
0,0,0,0,0,0,0,0,0,44,4,4,44,4,4,44,0,0,0
0,0,0,0,0,0,0,0,0,4,0,12,0,0,0,4,0,0,0
0,0,0,0,0,0,0,0,0,4,23,0,0,0,81,4,0,0,0
0,0,0,0,0,0,0,0,0,44,33,33,33,2,2,44,0,0,0
0,0,0,0,0,0,0,0,0,4,0,0,0,0,0,4,0,0,0
0,0,0,0,0,0,0,0,0,4,0,0,0,0,0,4,0,0,0
0,0,0,0,0,0,0,0,0,44,4,4,44,4,4,44,0,0,0
0,0,0,0,0,0,0,0,0,0,0,0,0,0,0,0,0,0,0
0,0,0,0,0,0,0,0,0,0,0,0,0,0,0,0,0,0,0
0,0,0,0,0,0,0,0,0,0,0,0,0,0,0,0,0,0,0
0,0,0,0,0,0,0,0,0,0,0,0,0,0,0,0,0,0,0
0,0,0,0,0,0,0,0,0,0,0,0,0,0,0,0,0,0,0
0,0,0,0,0,0,0,0,0,0,0,0,0,0,0,0,0,0,0
0,0,0,0,0,0,0,0,0,0,0,0,0,0,0,0,0,0,0
0,0,0,0,0,0,0,0,0,0,0,0,0,0,0,0,0,0,0
0,0,0,0,0,0,0,0,0,0,0,0,0,0,0,0,0,0,0
0,0,0,0,0,0,0,0,0,0,0,0,0,0,0,0,0,0,0
0,0,0,0,0,0,0,0,0,0,0,0,0,0,0,0,0,0,0
0,0,0,0,0,0,0,0,0,0,0,0,0,0,0,0,0,0,0
0,0,0,0,0,0,0,0,0,0,0,0,0,0,0,0,0,0,0
0,0,0,0,0,0,0,0,0,0,0,0,0,0,0,0,0,0,0
0,0,0,0,0,0,0,0,0,0,0,0,0,0,0,0,0,0,0
0,0,0,0,0,0,0,0,0,0,0,0,0,0,0,0,0,0,0
0,0,0,0,0,0,0,0,0,0,0,0,0,0,0,0,0,0,0
0,0,0,0,0,0,0,0,0,0,0,0,0,0,0,0,0,0,0
0,0,0,0,0,0,0,0,0,0,0,0,0,0,0,0,0,0,0
0,0,0,0,0,0,0,0,0,0,0,0,0,0,0,0,0,0,0
0,0,0,0,0,0,0,0,0,0,0,0,0,0,0,0,0,0,0
:endlayer
layer: 31
0,0,0,0,0,0,0,0,0,0,0,0,0,0,0,0,0,0,0
0,0,0,0,0,0,0,0,0,0,0,0,0,0,0,0,0,0,0
0,0,0,0,0,0,0,0,0,0,0,0,0,0,0,0,0,0,0
0,0,0,0,0,0,0,0,0,44,4,4,44,4,4,44,0,0,0
0,0,0,0,0,0,0,0,0,4,12,0,0,0,0,4,0,0,0
0,0,0,0,0,0,0,0,0,4,0,0,0,0,0,4,0,0,0
0,0,0,0,0,0,0,0,0,44,33,33,33,2,2,44,0,0,0
0,0,0,0,0,0,0,0,0,4,0,0,0,0,0,4,0,0,0
0,0,0,0,0,0,0,0,0,4,0,0,0,0,0,4,0,0,0
0,0,0,0,0,0,0,0,0,44,4,4,44,4,4,44,0,0,0
0,0,0,0,0,0,0,0,0,0,0,0,0,0,0,0,0,0,0
0,0,0,0,0,0,0,0,0,0,0,0,0,0,0,0,0,0,0
0,0,0,0,0,0,0,0,0,0,0,0,0,0,0,0,0,0,0
0,0,0,0,0,0,0,0,0,0,0,0,0,0,0,0,0,0,0
0,0,0,0,0,0,0,0,0,0,0,0,0,0,0,0,0,0,0
0,0,0,0,0,0,0,0,0,0,0,0,0,0,0,0,0,0,0
0,0,0,0,0,0,0,0,0,0,0,0,0,0,0,0,0,0,0
0,0,0,0,0,0,0,0,0,0,0,0,0,0,0,0,0,0,0
0,0,0,0,0,0,0,0,0,0,0,0,0,0,0,0,0,0,0
0,0,0,0,0,0,0,0,0,0,0,0,0,0,0,0,0,0,0
0,0,0,0,0,0,0,0,0,0,0,0,0,0,0,0,0,0,0
0,0,0,0,0,0,0,0,0,0,0,0,0,0,0,0,0,0,0
0,0,0,0,0,0,0,0,0,0,0,0,0,0,0,0,0,0,0
0,0,0,0,0,0,0,0,0,0,0,0,0,0,0,0,0,0,0
0,0,0,0,0,0,0,0,0,0,0,0,0,0,0,0,0,0,0
0,0,0,0,0,0,0,0,0,0,0,0,0,0,0,0,0,0,0
0,0,0,0,0,0,0,0,0,0,0,0,0,0,0,0,0,0,0
0,0,0,0,0,0,0,0,0,0,0,0,0,0,0,0,0,0,0
0,0,0,0,0,0,0,0,0,0,0,0,0,0,0,0,0,0,0
0,0,0,0,0,0,0,0,0,0,0,0,0,0,0,0,0,0,0
0,0,0,0,0,0,0,0,0,0,0,0,0,0,0,0,0,0,0
:endlayer
layer: 32
0,0,0,0,0,0,0,0,0,0,0,0,0,0,0,0,0,0,0
0,0,0,0,0,0,0,0,0,0,0,0,0,0,0,0,0,0,0
0,0,0,0,0,0,0,0,0,0,0,0,0,0,0,0,0,0,0
0,0,0,0,0,0,0,0,0,44,4,4,44,4,4,44,0,0,0
0,0,0,0,0,0,0,0,0,4,0,0,0,74,74,4,0,0,0
0,0,0,0,0,0,0,0,0,4,5,74,74,74,74,4,0,0,0
0,0,0,0,0,0,0,0,0,44,74,74,74,74,74,44,0,0,0
0,0,0,0,0,0,0,0,0,4,74,74,74,74,74,4,0,0,0
0,0,0,0,0,0,0,0,0,4,74,74,74,74,74,4,0,0,0
0,0,0,0,0,0,0,0,0,44,4,4,44,4,4,44,0,0,0
0,0,0,0,0,0,0,0,0,0,0,0,0,0,0,0,0,0,0
0,0,0,0,0,0,0,0,0,0,0,0,0,0,0,0,0,0,0
0,0,0,0,0,0,0,0,0,0,0,0,0,0,0,0,0,0,0
0,0,0,0,0,0,0,0,0,0,0,0,0,0,0,0,0,0,0
0,0,0,0,0,0,0,0,0,0,0,0,0,0,0,0,0,0,0
0,0,0,0,0,0,0,0,0,0,0,0,0,0,0,0,0,0,0
0,0,0,0,0,0,0,0,0,0,0,0,0,0,0,0,0,0,0
0,0,0,0,0,0,0,0,0,0,0,0,0,0,0,0,0,0,0
0,0,0,0,0,0,0,0,0,0,0,0,0,0,0,0,0,0,0
0,0,0,0,0,0,0,0,0,0,0,0,0,0,0,0,0,0,0
0,0,0,0,0,0,0,0,0,0,0,0,0,0,0,0,0,0,0
0,0,0,0,0,0,0,0,0,0,0,0,0,0,0,0,0,0,0
0,0,0,0,0,0,0,0,0,0,0,0,0,0,0,0,0,0,0
0,0,0,0,0,0,0,0,0,0,0,0,0,0,0,0,0,0,0
0,0,0,0,0,0,0,0,0,0,0,0,0,0,0,0,0,0,0
0,0,0,0,0,0,0,0,0,0,0,0,0,0,0,0,0,0,0
0,0,0,0,0,0,0,0,0,0,0,0,0,0,0,0,0,0,0
0,0,0,0,0,0,0,0,0,0,0,0,0,0,0,0,0,0,0
0,0,0,0,0,0,0,0,0,0,0,0,0,0,0,0,0,0,0
0,0,0,0,0,0,0,0,0,0,0,0,0,0,0,0,0,0,0
0,0,0,0,0,0,0,0,0,0,0,0,0,0,0,0,0,0,0
:endlayer
layer: 33
0,0,0,0,0,0,0,0,0,0,0,0,0,0,0,0,0,0,0
0,0,0,0,0,0,0,0,0,0,0,0,0,0,0,0,0,0,0
0,0,0,0,0,0,0,0,0,0,0,0,0,0,0,0,0,0,0
0,0,0,0,0,0,0,0,0,44,4,4,44,4,4,44,0,0,0
0,0,0,0,0,0,0,0,0,4,0,0,0,12,0,4,0,0,0
0,0,0,0,0,0,0,0,0,4,0,0,0,0,0,4,0,0,0
0,0,0,0,0,0,0,0,0,44,33,33,33,2,85,44,0,0,0
0,0,0,0,0,0,0,0,0,4,0,0,0,0,0,4,0,0,0
0,0,0,0,0,0,0,0,0,4,89,0,0,0,0,4,0,0,0
0,0,0,0,0,0,0,0,0,44,4,4,44,4,4,44,0,0,0
0,0,0,0,0,0,0,0,0,0,0,0,0,0,0,0,0,0,0
0,0,0,0,0,0,0,0,0,0,0,0,0,0,0,0,0,0,0
0,0,0,0,0,0,0,0,0,0,0,0,0,0,0,0,0,0,0
0,0,0,0,0,0,0,0,0,0,0,0,0,0,0,0,0,0,0
0,0,0,0,0,0,0,0,0,0,0,0,0,0,0,0,0,0,0
0,0,0,0,0,0,0,0,0,0,0,0,0,0,0,0,0,0,0
0,0,0,0,0,0,0,0,0,0,0,0,0,0,0,0,0,0,0
0,0,0,0,0,0,0,0,0,0,0,0,0,0,0,0,0,0,0
0,0,0,0,0,0,0,0,0,0,0,0,0,0,0,0,0,0,0
0,0,0,0,0,0,0,0,0,0,0,0,0,0,0,0,0,0,0
0,0,0,0,0,0,0,0,0,0,0,0,0,0,0,0,0,0,0
0,0,0,0,0,0,0,0,0,0,0,0,0,0,0,0,0,0,0
0,0,0,0,0,0,0,0,0,0,0,0,0,0,0,0,0,0,0
0,0,0,0,0,0,0,0,0,0,0,0,0,0,0,0,0,0,0
0,0,0,0,0,0,0,0,0,0,0,0,0,0,0,0,0,0,0
0,0,0,0,0,0,0,0,0,0,0,0,0,0,0,0,0,0,0
0,0,0,0,0,0,0,0,0,0,0,0,0,0,0,0,0,0,0
0,0,0,0,0,0,0,0,0,0,0,0,0,0,0,0,0,0,0
0,0,0,0,0,0,0,0,0,0,0,0,0,0,0,0,0,0,0
0,0,0,0,0,0,0,0,0,0,0,0,0,0,0,0,0,0,0
0,0,0,0,0,0,0,0,0,0,0,0,0,0,0,0,0,0,0
:endlayer
layer: 34
0,0,0,0,0,0,0,0,0,0,0,0,0,0,0,0,0,0,0
0,0,0,0,0,0,0,0,0,0,0,0,0,0,0,0,0,0,0
0,0,0,0,0,0,0,0,0,0,0,0,0,0,0,0,0,0,0
0,0,0,0,0,0,0,0,0,2,33,33,2,33,33,2,0,0,0
0,0,0,0,0,0,0,0,0,33,0,0,12,0,0,33,0,0,0
0,0,0,0,0,0,0,0,0,33,0,0,0,0,0,33,0,0,0
0,0,0,0,0,0,0,0,0,2,33,33,33,2,90,2,0,0,0
0,0,0,0,0,0,0,0,0,33,0,0,0,0,0,33,0,0,0
0,0,0,0,0,0,0,0,0,33,0,0,0,0,0,33,0,0,0
0,0,0,0,0,0,0,0,0,2,33,33,2,33,33,2,0,0,0
0,0,0,0,0,0,0,0,0,0,0,0,0,0,0,0,0,0,0
0,0,0,0,0,0,0,0,0,0,0,0,0,0,0,0,0,0,0
0,0,0,0,0,0,0,0,0,0,0,0,0,0,0,0,0,0,0
0,0,0,0,0,0,0,0,0,0,0,0,0,0,0,0,0,0,0
0,0,0,0,0,0,0,0,0,0,0,0,0,0,0,0,0,0,0
0,0,0,0,0,0,0,0,0,0,0,0,0,0,0,0,0,0,0
0,0,0,0,0,0,0,0,0,0,0,0,0,0,0,0,0,0,0
0,0,0,0,0,0,0,0,0,0,0,0,0,0,0,0,0,0,0
0,0,0,0,0,0,0,0,0,0,0,0,0,0,0,0,0,0,0
0,0,0,0,0,0,0,0,0,0,0,0,0,0,0,0,0,0,0
0,0,0,0,0,0,0,0,0,0,0,0,0,0,0,0,0,0,0
0,0,0,0,0,0,0,0,0,0,0,0,0,0,0,0,0,0,0
0,0,0,0,0,0,0,0,0,0,0,0,0,0,0,0,0,0,0
0,0,0,0,0,0,0,0,0,0,0,0,0,0,0,0,0,0,0
0,0,0,0,0,0,0,0,0,0,0,0,0,0,0,0,0,0,0
0,0,0,0,0,0,0,0,0,0,0,0,0,0,0,0,0,0,0
0,0,0,0,0,0,0,0,0,0,0,0,0,0,0,0,0,0,0
0,0,0,0,0,0,0,0,0,0,0,0,0,0,0,0,0,0,0
0,0,0,0,0,0,0,0,0,0,0,0,0,0,0,0,0,0,0
0,0,0,0,0,0,0,0,0,0,0,0,0,0,0,0,0,0,0
0,0,0,0,0,0,0,0,0,0,0,0,0,0,0,0,0,0,0
:endlayer
layer: 35
0,0,0,0,0,0,0,0,0,0,0,0,0,0,0,0,0,0,0
0,0,0,0,0,0,0,0,0,0,0,0,0,0,0,0,0,0,0
0,0,0,0,0,0,0,0,44,0,44,0,44,0,44,0,44,0,0
0,0,0,0,0,0,0,0,0,44,4,4,44,4,4,44,0,0,0
0,0,0,0,0,0,0,0,44,4,0,12,0,0,0,4,44,0,0
0,0,0,0,0,0,0,0,0,4,23,0,0,0,87,4,0,0,0
0,0,0,0,0,0,0,0,44,44,33,33,33,2,2,44,44,0,0
0,0,0,0,0,0,0,0,0,4,23,0,0,0,28,4,0,0,0
0,0,0,0,0,0,0,0,44,4,0,0,0,0,0,4,44,0,0
0,0,0,0,0,0,0,0,0,44,4,4,44,4,4,44,0,0,0
0,0,0,0,0,0,0,0,44,0,44,0,44,0,44,0,44,0,0
0,0,0,0,0,0,0,0,0,0,0,0,0,0,0,0,0,0,0
0,0,0,0,0,0,0,0,0,0,0,0,0,0,0,0,0,0,0
0,0,0,0,0,0,0,0,0,0,0,0,0,0,0,0,0,0,0
0,0,0,0,0,0,0,0,0,0,0,0,0,0,0,0,0,0,0
0,0,0,0,0,0,0,0,0,0,0,0,0,0,0,0,0,0,0
0,0,0,0,0,0,0,0,0,0,0,0,0,0,0,0,0,0,0
0,0,0,0,0,0,0,0,0,0,0,0,0,0,0,0,0,0,0
0,0,0,0,0,0,0,0,0,0,0,0,0,0,0,0,0,0,0
0,0,0,0,0,0,0,0,0,0,0,0,0,0,0,0,0,0,0
0,0,0,0,0,0,0,0,0,0,0,0,0,0,0,0,0,0,0
0,0,0,0,0,0,0,0,0,0,0,0,0,0,0,0,0,0,0
0,0,0,0,0,0,0,0,0,0,0,0,0,0,0,0,0,0,0
0,0,0,0,0,0,0,0,0,0,0,0,0,0,0,0,0,0,0
0,0,0,0,0,0,0,0,0,0,0,0,0,0,0,0,0,0,0
0,0,0,0,0,0,0,0,0,0,0,0,0,0,0,0,0,0,0
0,0,0,0,0,0,0,0,0,0,0,0,0,0,0,0,0,0,0
0,0,0,0,0,0,0,0,0,0,0,0,0,0,0,0,0,0,0
0,0,0,0,0,0,0,0,0,0,0,0,0,0,0,0,0,0,0
0,0,0,0,0,0,0,0,0,0,0,0,0,0,0,0,0,0,0
0,0,0,0,0,0,0,0,0,0,0,0,0,0,0,0,0,0,0
:endlayer
layer: 36
0,0,0,0,0,0,0,0,0,0,0,0,0,0,0,0,0,0,0
0,0,0,0,0,0,0,0,44,0,44,0,44,0,44,0,44,0,0
0,0,0,0,0,0,0,44,44,0,44,0,44,0,44,0,44,44,0
0,0,0,0,0,0,0,0,0,44,4,4,44,4,4,44,0,0,0
0,0,0,0,0,0,0,44,44,4,12,0,0,0,0,4,44,44,0
0,0,0,0,0,0,0,0,0,4,0,0,0,0,0,4,0,0,0
0,0,0,0,0,0,0,44,44,44,33,33,33,2,2,44,44,44,0
0,0,0,0,0,0,0,0,0,4,0,0,0,0,0,4,0,0,0
0,0,0,0,0,0,0,44,44,4,0,0,0,0,0,4,44,44,0
0,0,0,0,0,0,0,0,0,44,4,4,44,4,4,44,0,0,0
0,0,0,0,0,0,0,44,44,0,44,0,44,0,44,0,44,44,0
0,0,0,0,0,0,0,0,44,0,44,0,44,0,44,0,44,0,0
0,0,0,0,0,0,0,0,0,0,0,0,0,0,0,0,0,0,0
0,0,0,0,0,0,0,0,0,0,0,0,0,0,0,0,0,0,0
0,0,0,0,0,0,0,0,0,0,0,0,0,0,0,0,0,0,0
0,0,0,0,0,0,0,0,0,0,0,0,0,0,0,0,0,0,0
0,0,0,0,0,0,0,0,0,0,0,0,0,0,0,0,0,0,0
0,0,0,0,0,0,0,0,0,0,0,0,0,0,0,0,0,0,0
0,0,0,0,0,0,0,0,0,0,0,0,0,0,0,0,0,0,0
0,0,0,0,0,0,0,0,0,0,0,0,0,0,0,0,0,0,0
0,0,0,0,0,0,0,0,0,0,0,0,0,0,0,0,0,0,0
0,0,0,0,0,0,0,0,0,0,0,0,0,0,0,0,0,0,0
0,0,0,0,0,0,0,0,0,0,0,0,0,0,0,0,0,0,0
0,0,0,0,0,0,0,0,0,0,0,0,0,0,0,0,0,0,0
0,0,0,0,0,0,0,0,0,0,0,0,0,0,0,0,0,0,0
0,0,0,0,0,0,0,0,0,0,0,0,0,0,0,0,0,0,0
0,0,0,0,0,0,0,0,0,0,0,0,0,0,0,0,0,0,0
0,0,0,0,0,0,0,0,0,0,0,0,0,0,0,0,0,0,0
0,0,0,0,0,0,0,0,0,0,0,0,0,0,0,0,0,0,0
0,0,0,0,0,0,0,0,0,0,0,0,0,0,0,0,0,0,0
0,0,0,0,0,0,0,0,0,0,0,0,0,0,0,0,0,0,0
:endlayer
layer: 37
0,0,0,0,0,0,0,0,0,0,0,0,0,0,0,0,0,0,0
0,0,0,0,0,0,0,44,44,44,44,44,44,44,44,44,44,44,0
0,0,0,0,0,0,0,44,44,44,44,44,44,44,44,44,44,44,0
0,0,0,0,0,0,0,44,44,74,74,74,44,74,74,74,44,44,0
0,0,0,0,0,0,0,44,44,12,0,0,0,74,74,74,44,44,0
0,0,0,0,0,0,0,44,44,74,74,74,74,74,74,74,44,44,0
0,0,0,0,0,0,0,44,44,74,74,74,74,74,74,74,44,44,0
0,0,0,0,0,0,0,44,44,74,74,74,74,74,74,74,44,44,0
0,0,0,0,0,0,0,44,44,74,74,74,74,74,74,74,44,44,0
0,0,0,0,0,0,0,44,44,74,74,74,74,74,74,74,44,44,0
0,0,0,0,0,0,0,44,44,44,44,44,44,44,44,44,44,44,0
0,0,0,0,0,0,0,44,44,44,44,44,44,44,44,44,44,44,0
0,0,0,0,0,0,0,0,0,0,0,0,0,0,0,0,0,0,0
0,0,0,0,0,0,0,0,0,0,0,0,0,0,0,0,0,0,0
0,0,0,0,0,0,0,0,0,0,0,0,0,0,0,0,0,0,0
0,0,0,0,0,0,0,0,0,0,0,0,0,0,0,0,0,0,0
0,0,0,0,0,0,0,0,0,0,0,0,0,0,0,0,0,0,0
0,0,0,0,0,0,0,0,0,0,0,0,0,0,0,0,0,0,0
0,0,0,0,0,0,0,0,0,0,0,0,0,0,0,0,0,0,0
0,0,0,0,0,0,0,0,0,0,0,0,0,0,0,0,0,0,0
0,0,0,0,0,0,0,0,0,0,0,0,0,0,0,0,0,0,0
0,0,0,0,0,0,0,0,0,0,0,0,0,0,0,0,0,0,0
0,0,0,0,0,0,0,0,0,0,0,0,0,0,0,0,0,0,0
0,0,0,0,0,0,0,0,0,0,0,0,0,0,0,0,0,0,0
0,0,0,0,0,0,0,0,0,0,0,0,0,0,0,0,0,0,0
0,0,0,0,0,0,0,0,0,0,0,0,0,0,0,0,0,0,0
0,0,0,0,0,0,0,0,0,0,0,0,0,0,0,0,0,0,0
0,0,0,0,0,0,0,0,0,0,0,0,0,0,0,0,0,0,0
0,0,0,0,0,0,0,0,0,0,0,0,0,0,0,0,0,0,0
0,0,0,0,0,0,0,0,0,0,0,0,0,0,0,0,0,0,0
0,0,0,0,0,0,0,0,0,0,0,0,0,0,0,0,0,0,0
:endlayer
layer: 38
0,0,0,0,0,0,0,0,0,0,0,0,0,0,0,0,0,0,0
0,0,0,0,0,0,0,44,44,44,44,44,44,44,44,44,44,44,0
0,0,0,0,0,0,0,44,77,77,77,77,77,77,77,77,77,44,0
0,0,0,0,0,0,0,44,77,44,0,0,44,0,0,44,77,44,0
0,0,0,0,0,0,0,44,77,0,0,0,0,0,0,0,77,44,0
0,0,0,0,0,0,0,44,77,0,0,0,0,0,0,0,77,44,0
0,0,0,0,0,0,0,44,77,44,0,0,0,0,0,44,77,44,0
0,0,0,0,0,0,0,44,77,0,0,0,92,0,0,0,77,44,0
0,0,0,0,0,0,0,44,77,0,0,0,91,0,0,0,77,44,0
0,0,0,0,0,0,0,44,77,44,0,0,44,0,0,44,77,44,0
0,0,0,0,0,0,0,44,77,77,77,77,77,77,77,77,77,44,0
0,0,0,0,0,0,0,44,44,44,44,44,44,44,44,44,44,44,0
0,0,0,0,0,0,0,0,0,0,0,0,0,0,0,0,0,0,0
0,0,0,0,0,0,0,0,0,0,0,0,0,0,0,0,0,0,0
0,0,0,0,0,0,0,0,0,0,0,0,0,0,0,0,0,0,0
0,0,0,0,0,0,0,0,0,0,0,0,0,0,0,0,0,0,0
0,0,0,0,0,0,0,0,0,0,0,0,0,0,0,0,0,0,0
0,0,0,0,0,0,0,0,0,0,0,0,0,0,0,0,0,0,0
0,0,0,0,0,0,0,0,0,0,0,0,0,0,0,0,0,0,0
0,0,0,0,0,0,0,0,0,0,0,0,0,0,0,0,0,0,0
0,0,0,0,0,0,0,0,0,0,0,0,0,0,0,0,0,0,0
0,0,0,0,0,0,0,0,0,0,0,0,0,0,0,0,0,0,0
0,0,0,0,0,0,0,0,0,0,0,0,0,0,0,0,0,0,0
0,0,0,0,0,0,0,0,0,0,0,0,0,0,0,0,0,0,0
0,0,0,0,0,0,0,0,0,0,0,0,0,0,0,0,0,0,0
0,0,0,0,0,0,0,0,0,0,0,0,0,0,0,0,0,0,0
0,0,0,0,0,0,0,0,0,0,0,0,0,0,0,0,0,0,0
0,0,0,0,0,0,0,0,0,0,0,0,0,0,0,0,0,0,0
0,0,0,0,0,0,0,0,0,0,0,0,0,0,0,0,0,0,0
0,0,0,0,0,0,0,0,0,0,0,0,0,0,0,0,0,0,0
0,0,0,0,0,0,0,0,0,0,0,0,0,0,0,0,0,0,0
:endlayer
layer: 39
0,0,0,0,0,0,0,0,0,0,0,0,0,0,0,0,0,0,0
0,0,0,0,0,0,0,2,0,2,0,2,0,2,0,2,0,2,0
0,0,0,0,0,0,0,0,0,0,0,0,0,0,0,0,0,0,0
0,0,0,0,0,0,0,2,0,2,0,0,2,0,0,2,0,2,0
0,0,0,0,0,0,0,0,0,0,0,0,28,0,0,0,0,0,0
0,0,0,0,0,0,0,2,0,0,0,0,0,0,0,0,0,2,0
0,0,0,0,0,0,0,0,0,2,23,0,0,0,0,2,0,0,0
0,0,0,0,0,0,0,2,0,0,0,0,0,0,0,0,0,2,0
0,0,0,0,0,0,0,0,0,0,0,0,91,0,0,0,0,0,0
0,0,0,0,0,0,0,2,0,2,0,0,2,0,0,2,0,2,0
0,0,0,0,0,0,0,0,0,0,0,0,0,0,0,0,0,0,0
0,0,0,0,0,0,0,2,0,2,0,2,0,2,0,2,0,2,0
0,0,0,0,0,0,0,0,0,0,0,0,0,0,0,0,0,0,0
0,0,0,0,0,0,0,0,0,0,0,0,0,0,0,0,0,0,0
0,0,0,0,0,0,0,0,0,0,0,0,0,0,0,0,0,0,0
0,0,0,0,0,0,0,0,0,0,0,0,0,0,0,0,0,0,0
0,0,0,0,0,0,0,0,0,0,0,0,0,0,0,0,0,0,0
0,0,0,0,0,0,0,0,0,0,0,0,0,0,0,0,0,0,0
0,0,0,0,0,0,0,0,0,0,0,0,0,0,0,0,0,0,0
0,0,0,0,0,0,0,0,0,0,0,0,0,0,0,0,0,0,0
0,0,0,0,0,0,0,0,0,0,0,0,0,0,0,0,0,0,0
0,0,0,0,0,0,0,0,0,0,0,0,0,0,0,0,0,0,0
0,0,0,0,0,0,0,0,0,0,0,0,0,0,0,0,0,0,0
0,0,0,0,0,0,0,0,0,0,0,0,0,0,0,0,0,0,0
0,0,0,0,0,0,0,0,0,0,0,0,0,0,0,0,0,0,0
0,0,0,0,0,0,0,0,0,0,0,0,0,0,0,0,0,0,0
0,0,0,0,0,0,0,0,0,0,0,0,0,0,0,0,0,0,0
0,0,0,0,0,0,0,0,0,0,0,0,0,0,0,0,0,0,0
0,0,0,0,0,0,0,0,0,0,0,0,0,0,0,0,0,0,0
0,0,0,0,0,0,0,0,0,0,0,0,0,0,0,0,0,0,0
0,0,0,0,0,0,0,0,0,0,0,0,0,0,0,0,0,0,0
:endlayer
layer: 40
0,0,0,0,0,0,0,0,0,0,0,0,0,0,0,0,0,0,0
0,0,0,0,0,0,0,71,0,0,0,0,0,0,0,0,0,71,0
0,0,0,0,0,0,0,0,0,0,0,0,0,0,0,0,0,0,0
0,0,0,0,0,0,0,0,0,44,0,0,44,0,0,44,0,0,0
0,0,0,0,0,0,0,0,0,0,0,0,0,0,0,0,0,0,0
0,0,0,0,0,0,0,0,0,0,0,0,0,0,0,0,0,0,0
0,0,0,0,0,0,0,0,0,44,0,0,0,0,0,44,0,0,0
0,0,0,0,0,0,0,0,0,0,0,0,0,0,0,0,0,0,0
0,0,0,0,0,0,0,0,0,0,0,0,91,0,0,0,0,0,0
0,0,0,0,0,0,0,0,0,44,0,0,44,0,0,44,0,0,0
0,0,0,0,0,0,0,0,0,0,0,0,0,0,0,0,0,0,0
0,0,0,0,0,0,0,71,0,0,0,0,0,0,0,0,0,71,0
0,0,0,0,0,0,0,0,0,0,0,0,0,0,0,0,0,0,0
0,0,0,0,0,0,0,0,0,0,0,0,0,0,0,0,0,0,0
0,0,0,0,0,0,0,0,0,0,0,0,0,0,0,0,0,0,0
0,0,0,0,0,0,0,0,0,0,0,0,0,0,0,0,0,0,0
0,0,0,0,0,0,0,0,0,0,0,0,0,0,0,0,0,0,0
0,0,0,0,0,0,0,0,0,0,0,0,0,0,0,0,0,0,0
0,0,0,0,0,0,0,0,0,0,0,0,0,0,0,0,0,0,0
0,0,0,0,0,0,0,0,0,0,0,0,0,0,0,0,0,0,0
0,0,0,0,0,0,0,0,0,0,0,0,0,0,0,0,0,0,0
0,0,0,0,0,0,0,0,0,0,0,0,0,0,0,0,0,0,0
0,0,0,0,0,0,0,0,0,0,0,0,0,0,0,0,0,0,0
0,0,0,0,0,0,0,0,0,0,0,0,0,0,0,0,0,0,0
0,0,0,0,0,0,0,0,0,0,0,0,0,0,0,0,0,0,0
0,0,0,0,0,0,0,0,0,0,0,0,0,0,0,0,0,0,0
0,0,0,0,0,0,0,0,0,0,0,0,0,0,0,0,0,0,0
0,0,0,0,0,0,0,0,0,0,0,0,0,0,0,0,0,0,0
0,0,0,0,0,0,0,0,0,0,0,0,0,0,0,0,0,0,0
0,0,0,0,0,0,0,0,0,0,0,0,0,0,0,0,0,0,0
0,0,0,0,0,0,0,0,0,0,0,0,0,0,0,0,0,0,0
:endlayer
layer: 41
0,0,0,0,0,0,0,0,0,0,0,0,0,0,0,0,0,0,0
0,0,0,0,0,0,0,0,0,0,0,0,0,0,0,0,0,0,0
0,0,0,0,0,0,0,0,0,0,0,0,0,0,0,0,0,0,0
0,0,0,0,0,0,0,0,0,2,2,2,2,2,2,44,0,0,0
0,0,0,0,0,0,0,0,0,2,74,74,74,74,74,44,0,0,0
0,0,0,0,0,0,0,0,0,2,74,74,74,74,74,44,0,0,0
0,0,0,0,0,0,0,0,0,2,74,74,74,74,74,44,0,0,0
0,0,0,0,0,0,0,0,0,2,74,74,74,74,74,44,0,0,0
0,0,0,0,0,0,0,0,0,2,74,74,91,74,74,44,0,0,0
0,0,0,0,0,0,0,0,0,44,44,44,44,44,44,44,0,0,0
0,0,0,0,0,0,0,0,0,0,0,0,0,0,0,0,0,0,0
0,0,0,0,0,0,0,0,0,0,0,0,0,0,0,0,0,0,0
0,0,0,0,0,0,0,0,0,0,0,0,0,0,0,0,0,0,0
0,0,0,0,0,0,0,0,0,0,0,0,0,0,0,0,0,0,0
0,0,0,0,0,0,0,0,0,0,0,0,0,0,0,0,0,0,0
0,0,0,0,0,0,0,0,0,0,0,0,0,0,0,0,0,0,0
0,0,0,0,0,0,0,0,0,0,0,0,0,0,0,0,0,0,0
0,0,0,0,0,0,0,0,0,0,0,0,0,0,0,0,0,0,0
0,0,0,0,0,0,0,0,0,0,0,0,0,0,0,0,0,0,0
0,0,0,0,0,0,0,0,0,0,0,0,0,0,0,0,0,0,0
0,0,0,0,0,0,0,0,0,0,0,0,0,0,0,0,0,0,0
0,0,0,0,0,0,0,0,0,0,0,0,0,0,0,0,0,0,0
0,0,0,0,0,0,0,0,0,0,0,0,0,0,0,0,0,0,0
0,0,0,0,0,0,0,0,0,0,0,0,0,0,0,0,0,0,0
0,0,0,0,0,0,0,0,0,0,0,0,0,0,0,0,0,0,0
0,0,0,0,0,0,0,0,0,0,0,0,0,0,0,0,0,0,0
0,0,0,0,0,0,0,0,0,0,0,0,0,0,0,0,0,0,0
0,0,0,0,0,0,0,0,0,0,0,0,0,0,0,0,0,0,0
0,0,0,0,0,0,0,0,0,0,0,0,0,0,0,0,0,0,0
0,0,0,0,0,0,0,0,0,0,0,0,0,0,0,0,0,0,0
0,0,0,0,0,0,0,0,0,0,0,0,0,0,0,0,0,0,0
:endlayer
layer: 42
0,0,0,0,0,0,0,0,0,0,0,0,0,0,0,0,0,0,0
0,0,0,0,0,0,0,0,0,0,0,0,0,0,0,0,0,0,0
0,0,0,0,0,0,0,0,0,0,0,0,0,0,0,0,0,0,0
0,0,0,0,0,0,0,0,0,2,0,0,2,0,0,2,0,0,0
0,0,0,0,0,0,0,0,0,0,0,0,0,0,0,0,0,0,0
0,0,0,0,0,0,0,0,0,0,0,0,0,0,0,0,0,0,0
0,0,0,0,0,0,0,0,0,2,0,0,0,0,0,2,0,0,0
0,0,0,0,0,0,0,0,0,0,0,0,0,0,0,0,0,0,0
0,0,0,0,0,0,0,0,0,0,0,0,91,0,0,0,0,0,0
0,0,0,0,0,0,0,0,0,2,0,0,2,0,0,2,0,0,0
0,0,0,0,0,0,0,0,0,0,0,0,0,0,0,0,0,0,0
0,0,0,0,0,0,0,0,0,0,0,0,0,0,0,0,0,0,0
0,0,0,0,0,0,0,0,0,0,0,0,0,0,0,0,0,0,0
0,0,0,0,0,0,0,0,0,0,0,0,0,0,0,0,0,0,0
0,0,0,0,0,0,0,0,0,0,0,0,0,0,0,0,0,0,0
0,0,0,0,0,0,0,0,0,0,0,0,0,0,0,0,0,0,0
0,0,0,0,0,0,0,0,0,0,0,0,0,0,0,0,0,0,0
0,0,0,0,0,0,0,0,0,0,0,0,0,0,0,0,0,0,0
0,0,0,0,0,0,0,0,0,0,0,0,0,0,0,0,0,0,0
0,0,0,0,0,0,0,0,0,0,0,0,0,0,0,0,0,0,0
0,0,0,0,0,0,0,0,0,0,0,0,0,0,0,0,0,0,0
0,0,0,0,0,0,0,0,0,0,0,0,0,0,0,0,0,0,0
0,0,0,0,0,0,0,0,0,0,0,0,0,0,0,0,0,0,0
0,0,0,0,0,0,0,0,0,0,0,0,0,0,0,0,0,0,0
0,0,0,0,0,0,0,0,0,0,0,0,0,0,0,0,0,0,0
0,0,0,0,0,0,0,0,0,0,0,0,0,0,0,0,0,0,0
0,0,0,0,0,0,0,0,0,0,0,0,0,0,0,0,0,0,0
0,0,0,0,0,0,0,0,0,0,0,0,0,0,0,0,0,0,0
0,0,0,0,0,0,0,0,0,0,0,0,0,0,0,0,0,0,0
0,0,0,0,0,0,0,0,0,0,0,0,0,0,0,0,0,0,0
0,0,0,0,0,0,0,0,0,0,0,0,0,0,0,0,0,0,0
:endlayer
layer: 43
0,0,0,0,0,0,0,0,0,0,0,0,0,0,0,0,0,0,0
0,0,0,0,0,0,0,0,0,0,0,0,0,0,0,0,0,0,0
0,0,0,0,0,0,0,0,0,0,0,0,0,0,0,0,0,0,0
0,0,0,0,0,0,0,0,0,71,0,0,71,0,0,71,0,0,0
0,0,0,0,0,0,0,0,0,0,0,0,0,0,0,0,0,0,0
0,0,0,0,0,0,0,0,0,0,0,0,0,0,0,0,0,0,0
0,0,0,0,0,0,0,0,0,71,0,0,0,0,0,71,0,0,0
0,0,0,0,0,0,0,0,0,0,0,0,0,0,0,0,0,0,0
0,0,0,0,0,0,0,0,0,0,0,0,0,0,0,0,0,0,0
0,0,0,0,0,0,0,0,0,71,0,0,71,0,0,71,0,0,0
0,0,0,0,0,0,0,0,0,0,0,0,0,0,0,0,0,0,0
0,0,0,0,0,0,0,0,0,0,0,0,0,0,0,0,0,0,0
0,0,0,0,0,0,0,0,0,0,0,0,0,0,0,0,0,0,0
0,0,0,0,0,0,0,0,0,0,0,0,0,0,0,0,0,0,0
0,0,0,0,0,0,0,0,0,0,0,0,0,0,0,0,0,0,0
0,0,0,0,0,0,0,0,0,0,0,0,0,0,0,0,0,0,0
0,0,0,0,0,0,0,0,0,0,0,0,0,0,0,0,0,0,0
0,0,0,0,0,0,0,0,0,0,0,0,0,0,0,0,0,0,0
0,0,0,0,0,0,0,0,0,0,0,0,0,0,0,0,0,0,0
0,0,0,0,0,0,0,0,0,0,0,0,0,0,0,0,0,0,0
0,0,0,0,0,0,0,0,0,0,0,0,0,0,0,0,0,0,0
0,0,0,0,0,0,0,0,0,0,0,0,0,0,0,0,0,0,0
0,0,0,0,0,0,0,0,0,0,0,0,0,0,0,0,0,0,0
0,0,0,0,0,0,0,0,0,0,0,0,0,0,0,0,0,0,0
0,0,0,0,0,0,0,0,0,0,0,0,0,0,0,0,0,0,0
0,0,0,0,0,0,0,0,0,0,0,0,0,0,0,0,0,0,0
0,0,0,0,0,0,0,0,0,0,0,0,0,0,0,0,0,0,0
0,0,0,0,0,0,0,0,0,0,0,0,0,0,0,0,0,0,0
0,0,0,0,0,0,0,0,0,0,0,0,0,0,0,0,0,0,0
0,0,0,0,0,0,0,0,0,0,0,0,0,0,0,0,0,0,0
0,0,0,0,0,0,0,0,0,0,0,0,0,0,0,0,0,0,0
:endlayer
layer: 44
0,0,0,0,0,0,0,0,0,0,0,0,0,0,0,0,0,0,0
0,0,0,0,0,0,0,0,0,0,0,0,0,0,0,0,0,0,0
0,0,0,0,0,0,0,0,0,0,0,0,0,0,0,0,0,0,0
0,0,0,0,0,0,0,0,0,0,0,0,0,0,0,0,0,0,0
0,0,0,0,0,0,0,0,0,0,0,0,0,0,0,0,0,0,0
0,0,0,0,0,0,0,0,0,0,0,0,0,0,0,0,0,0,0
0,0,0,0,0,0,0,0,0,0,0,0,0,0,0,0,0,0,0
0,0,0,0,0,0,0,0,0,0,0,0,0,0,0,0,0,0,0
0,0,0,0,0,0,0,0,0,0,0,0,0,0,0,0,0,0,0
0,0,0,0,0,0,0,0,0,0,0,0,0,0,0,0,0,0,0
0,0,0,0,0,0,0,0,0,0,0,0,0,0,0,0,0,0,0
0,0,0,0,0,0,0,0,0,0,0,0,0,0,0,0,0,0,0
0,0,0,0,0,0,0,0,0,0,0,0,0,0,0,0,0,0,0
0,0,0,0,0,0,0,0,0,0,0,0,0,0,0,0,0,0,0
0,0,0,0,0,0,0,0,0,0,0,0,0,0,0,0,0,0,0
0,0,0,0,0,0,0,0,0,0,0,0,0,0,0,0,0,0,0
0,0,0,0,0,0,0,0,0,0,0,0,0,0,0,0,0,0,0
0,0,0,0,0,0,0,0,0,0,0,0,0,0,0,0,0,0,0
0,0,0,0,0,0,0,0,0,0,0,0,0,0,0,0,0,0,0
0,0,0,0,0,0,0,0,0,0,0,0,0,0,0,0,0,0,0
0,0,0,0,0,0,0,0,0,0,0,0,0,0,0,0,0,0,0
0,0,0,0,0,0,0,0,0,0,0,0,0,0,0,0,0,0,0
0,0,0,0,0,0,0,0,0,0,0,0,0,0,0,0,0,0,0
0,0,0,0,0,0,0,0,0,0,0,0,0,0,0,0,0,0,0
0,0,0,0,0,0,0,0,0,0,0,0,0,0,0,0,0,0,0
0,0,0,0,0,0,0,0,0,0,0,0,0,0,0,0,0,0,0
0,0,0,0,0,0,0,0,0,0,0,0,0,0,0,0,0,0,0
0,0,0,0,0,0,0,0,0,0,0,0,0,0,0,0,0,0,0
0,0,0,0,0,0,0,0,0,0,0,0,0,0,0,0,0,0,0
0,0,0,0,0,0,0,0,0,0,0,0,0,0,0,0,0,0,0
0,0,0,0,0,0,0,0,0,0,0,0,0,0,0,0,0,0,0
:endlayer
layer: 45
0,0,0,0,0,0,0,0,0,0,0,0,0,0,0,0,0,0,0
0,0,0,0,0,0,0,0,0,0,0,0,0,0,0,0,0,0,0
0,0,0,0,0,0,0,0,0,0,0,0,0,0,0,0,0,0,0
0,0,0,0,0,0,0,0,0,0,0,0,0,0,0,0,0,0,0
0,0,0,0,0,0,0,0,0,0,0,0,0,0,0,0,0,0,0
0,0,0,0,0,0,0,0,0,0,0,0,0,0,0,0,0,0,0
0,0,0,0,0,0,0,0,0,0,0,0,0,0,0,0,0,0,0
0,0,0,0,0,0,0,0,0,0,0,0,0,0,0,0,0,0,0
0,0,0,0,0,0,0,0,0,0,0,0,0,0,0,0,0,0,0
0,0,0,0,0,0,0,0,0,0,0,0,0,0,0,0,0,0,0
0,0,0,0,0,0,0,0,0,0,0,0,0,0,0,0,0,0,0
0,0,0,0,0,0,0,0,0,0,0,0,0,0,0,0,0,0,0
0,0,0,0,0,0,0,0,0,0,0,0,0,0,0,0,0,0,0
0,0,0,0,0,0,0,0,0,0,0,0,0,0,0,0,0,0,0
0,0,0,0,0,0,0,0,0,0,0,0,0,0,0,0,0,0,0
0,0,0,0,0,0,0,0,0,0,0,0,0,0,0,0,0,0,0
0,0,0,0,0,0,0,0,0,0,0,0,0,0,0,0,0,0,0
0,0,0,0,0,0,0,0,0,0,0,0,0,0,0,0,0,0,0
0,0,0,0,0,0,0,0,0,0,0,0,0,0,0,0,0,0,0
0,0,0,0,0,0,0,0,0,0,0,0,0,0,0,0,0,0,0
0,0,0,0,0,0,0,0,0,0,0,0,0,0,0,0,0,0,0
0,0,0,0,0,0,0,0,0,0,0,0,0,0,0,0,0,0,0
0,0,0,0,0,0,0,0,0,0,0,0,0,0,0,0,0,0,0
0,0,0,0,0,0,0,0,0,0,0,0,0,0,0,0,0,0,0
0,0,0,0,0,0,0,0,0,0,0,0,0,0,0,0,0,0,0
0,0,0,0,0,0,0,0,0,0,0,0,0,0,0,0,0,0,0
0,0,0,0,0,0,0,0,0,0,0,0,0,0,0,0,0,0,0
0,0,0,0,0,0,0,0,0,0,0,0,0,0,0,0,0,0,0
0,0,0,0,0,0,0,0,0,0,0,0,0,0,0,0,0,0,0
0,0,0,0,0,0,0,0,0,0,0,0,0,0,0,0,0,0,0
0,0,0,0,0,0,0,0,0,0,0,0,0,0,0,0,0,0,0
:endlayer

#### RULES ####
rule:
plugin=vanillaBlocks
number=1
data:
tag:
TAG=10={
TAG=8=blockName{dirt}
TAG=3=meta{0}
TAG=3=buildPass{0}
}
:endtag
:enddata
:endrule

rule:
plugin=vanillaBlocks
number=2
data:
tag:
TAG=10={
TAG=8=blockName{stonebrick}
TAG=3=meta{0}
TAG=3=buildPass{0}
}
:endtag
:enddata
:endrule

rule:
plugin=vanillaBlocks
number=3
data:
tag:
TAG=10={
TAG=8=blockName{stone}
TAG=3=meta{0}
TAG=3=buildPass{0}
}
:endtag
:enddata
:endrule

rule:
plugin=vanillaBlocks
number=4
data:
tag:
TAG=10={
TAG=8=blockName{cobblestone}
TAG=3=meta{0}
TAG=3=buildPass{0}
}
:endtag
:enddata
:endrule

rule:
plugin=vanillaBlocks
number=5
data:
tag:
TAG=10={
TAG=8=blockName{stone_brick_stairs}
TAG=3=meta{2}
TAG=3=buildPass{0}
}
:endtag
:enddata
:endrule

rule:
plugin=vanillaBlocks
number=6
data:
tag:
TAG=10={
TAG=8=blockName{stone_brick_stairs}
TAG=3=meta{0}
TAG=3=buildPass{0}
}
:endtag
:enddata
:endrule

rule:
plugin=vanillaDoors
number=7
data:
tag:
TAG=10={
TAG=1=sideFlag{8}
TAG=8=blockName{iron_door}
TAG=3=meta{0}
TAG=3=buildPass{1}
}
:endtag
:enddata
:endrule

rule:
plugin=vanillaInventory
number=8
data:
tag:
TAG=10={
TAG=3=lootLevel{0}
TAG=10=teData{
TAG=9=Items{
}
TAG=8=id{Chest}
}
TAG=8=blockName{chest}
TAG=3=meta{4}
TAG=3=buildPass{0}
}
:endtag
:enddata
:endrule

rule:
plugin=vanillaDoors
number=9
data:
tag:
TAG=10={
TAG=1=sideFlag{8}
TAG=8=blockName{iron_door}
TAG=3=meta{2}
TAG=3=buildPass{1}
}
:endtag
:enddata
:endrule

rule:
plugin=vanillaBlocks
number=10
data:
tag:
TAG=10={
TAG=8=blockName{bed}
TAG=3=meta{11}
TAG=3=buildPass{0}
}
:endtag
:enddata
:endrule

rule:
plugin=vanillaBlocks
number=11
data:
tag:
TAG=10={
TAG=8=blockName{bed}
TAG=3=meta{3}
TAG=3=buildPass{0}
}
:endtag
:enddata
:endrule

rule:
plugin=vanillaBlocks
number=12
data:
tag:
TAG=10={
TAG=8=blockName{stone_brick_stairs}
TAG=3=meta{1}
TAG=3=buildPass{0}
}
:endtag
:enddata
:endrule

rule:
plugin=vanillaDoors
number=13
data:
tag:
TAG=10={
TAG=1=sideFlag{8}
TAG=8=blockName{iron_door}
TAG=3=meta{3}
TAG=3=buildPass{1}
}
:endtag
:enddata
:endrule

rule:
plugin=vanillaDoors
number=14
data:
tag:
TAG=10={
TAG=1=sideFlag{0}
TAG=8=blockName{iron_door}
TAG=3=meta{8}
TAG=3=buildPass{1}
}
:endtag
:enddata
:endrule

rule:
plugin=vanillaDoors
number=15
data:
tag:
TAG=10={
TAG=1=sideFlag{0}
TAG=8=blockName{iron_door}
TAG=3=meta{8}
TAG=3=buildPass{1}
}
:endtag
:enddata
:endrule

rule:
plugin=vanillaDoors
number=16
data:
tag:
TAG=10={
TAG=1=sideFlag{0}
TAG=8=blockName{iron_door}
TAG=3=meta{8}
TAG=3=buildPass{1}
}
:endtag
:enddata
:endrule

rule:
plugin=vanillaDoors
number=17
data:
tag:
TAG=10={
TAG=1=sideFlag{0}
TAG=8=blockName{iron_door}
TAG=3=meta{8}
TAG=3=buildPass{1}
}
:endtag
:enddata
:endrule

rule:
plugin=vanillaDoors
number=18
data:
tag:
TAG=10={
TAG=1=sideFlag{0}
TAG=8=blockName{iron_door}
TAG=3=meta{8}
TAG=3=buildPass{1}
}
:endtag
:enddata
:endrule

rule:
plugin=vanillaDoors
number=19
data:
tag:
TAG=10={
TAG=1=sideFlag{0}
TAG=8=blockName{iron_door}
TAG=3=meta{8}
TAG=3=buildPass{1}
}
:endtag
:enddata
:endrule

rule:
plugin=vanillaDoors
number=20
data:
tag:
TAG=10={
TAG=1=sideFlag{0}
TAG=8=blockName{iron_door}
TAG=3=meta{8}
TAG=3=buildPass{1}
}
:endtag
:enddata
:endrule

rule:
plugin=vanillaDoors
number=21
data:
tag:
TAG=10={
TAG=1=sideFlag{0}
TAG=8=blockName{iron_door}
TAG=3=meta{8}
TAG=3=buildPass{1}
}
:endtag
:enddata
:endrule

rule:
plugin=vanillaDoors
number=22
data:
tag:
TAG=10={
TAG=1=sideFlag{0}
TAG=8=blockName{iron_door}
TAG=3=meta{8}
TAG=3=buildPass{1}
}
:endtag
:enddata
:endrule

rule:
plugin=vanillaBlocks
number=23
data:
tag:
TAG=10={
TAG=8=blockName{torch}
TAG=3=meta{1}
TAG=3=buildPass{1}
}
:endtag
:enddata
:endrule

rule:
plugin=vanillaBlocks
number=24
data:
tag:
TAG=10={
TAG=8=blockName{torch}
TAG=3=meta{2}
TAG=3=buildPass{1}
}
:endtag
:enddata
:endrule

rule:
plugin=vanillaBlocks
number=25
data:
tag:
TAG=10={
TAG=8=blockName{lever}
TAG=3=meta{2}
TAG=3=buildPass{1}
}
:endtag
:enddata
:endrule

rule:
plugin=vanillaBlocks
number=26
data:
tag:
TAG=10={
TAG=8=blockName{torch}
TAG=3=meta{4}
TAG=3=buildPass{1}
}
:endtag
:enddata
:endrule

rule:
plugin=vanillaBlocks
number=27
data:
tag:
TAG=10={
TAG=8=blockName{lever}
TAG=3=meta{1}
TAG=3=buildPass{1}
}
:endtag
:enddata
:endrule

rule:
plugin=vanillaBlocks
number=28
data:
tag:
TAG=10={
TAG=8=blockName{torch}
TAG=3=meta{3}
TAG=3=buildPass{1}
}
:endtag
:enddata
:endrule

rule:
plugin=vanillaBlocks
number=29
data:
tag:
TAG=10={
TAG=8=blockName{lever}
TAG=3=meta{3}
TAG=3=buildPass{1}
}
:endtag
:enddata
:endrule

rule:
plugin=vanillaBlocks
number=30
data:
tag:
TAG=10={
TAG=8=blockName{stone_brick_stairs}
TAG=3=meta{4}
TAG=3=buildPass{0}
}
:endtag
:enddata
:endrule

rule:
plugin=vanillaBlocks
number=31
data:
tag:
TAG=10={
TAG=8=blockName{stone_brick_stairs}
TAG=3=meta{5}
TAG=3=buildPass{0}
}
:endtag
:enddata
:endrule

rule:
plugin=vanillaBlocks
number=32
data:
tag:
TAG=10={
TAG=8=blockName{grass}
TAG=3=meta{0}
TAG=3=buildPass{0}
}
:endtag
:enddata
:endrule

rule:
plugin=vanillaBlocks
number=33
data:
tag:
TAG=10={
TAG=8=blockName{iron_bars}
TAG=3=meta{0}
TAG=3=buildPass{0}
}
:endtag
:enddata
:endrule

rule:
plugin=vanillaBlocks
number=34
data:
tag:
TAG=10={
TAG=8=blockName{tallgrass}
TAG=3=meta{1}
TAG=3=buildPass{0}
}
:endtag
:enddata
:endrule

rule:
plugin=vanillaBlocks
number=35
data:
tag:
TAG=10={
TAG=8=blockName{stone_brick_stairs}
TAG=3=meta{3}
TAG=3=buildPass{0}
}
:endtag
:enddata
:endrule

rule:
plugin=vanillaInventory
number=36
data:
tag:
TAG=10={
TAG=3=lootLevel{0}
TAG=10=teData{
TAG=9=Items{
}
TAG=8=id{Chest}
}
TAG=8=blockName{chest}
TAG=3=meta{2}
TAG=3=buildPass{0}
}
:endtag
:enddata
:endrule

rule:
plugin=vanillaInventory
number=37
data:
tag:
TAG=10={
TAG=3=lootLevel{0}
TAG=10=teData{
TAG=9=Items{
}
TAG=8=id{Chest}
}
TAG=8=blockName{chest}
TAG=3=meta{2}
TAG=3=buildPass{0}
}
:endtag
:enddata
:endrule

rule:
plugin=vanillaInventory
number=38
data:
tag:
TAG=10={
TAG=3=lootLevel{0}
TAG=10=teData{
TAG=9=Items{
}
TAG=8=id{Chest}
}
TAG=8=blockName{chest}
TAG=3=meta{2}
TAG=3=buildPass{0}
}
:endtag
:enddata
:endrule

rule:
plugin=vanillaInventory
number=39
data:
tag:
TAG=10={
TAG=3=lootLevel{0}
TAG=10=teData{
TAG=9=Items{
}
TAG=8=id{Chest}
}
TAG=8=blockName{chest}
TAG=3=meta{2}
TAG=3=buildPass{0}
}
:endtag
:enddata
:endrule

rule:
plugin=vanillaInventory
number=40
data:
tag:
TAG=10={
TAG=3=lootLevel{0}
TAG=10=teData{
TAG=9=Items{
}
TAG=8=id{Chest}
}
TAG=8=blockName{chest}
TAG=3=meta{2}
TAG=3=buildPass{0}
}
:endtag
:enddata
:endrule

rule:
plugin=vanillaInventory
number=41
data:
tag:
TAG=10={
TAG=3=lootLevel{0}
TAG=10=teData{
TAG=9=Items{
}
TAG=8=id{Chest}
}
TAG=8=blockName{chest}
TAG=3=meta{5}
TAG=3=buildPass{0}
}
:endtag
:enddata
:endrule

rule:
plugin=vanillaBlocks
number=42
data:
tag:
TAG=10={
TAG=8=blockName{crafting_table}
TAG=3=meta{0}
TAG=3=buildPass{0}
}
:endtag
:enddata
:endrule

rule:
plugin=awAdvancedSpawner
number=43
data:
tag:
TAG=10={
TAG=10=teData{
TAG=9=Items{
}
TAG=8=id{Furnace}
TAG=2=BurnTime{0}
TAG=3=z{95}
TAG=2=CookTime{0}
TAG=3=y{70}
TAG=3=x{204}
}
TAG=8=blockName{furnace}
TAG=3=meta{3}
TAG=3=buildPass{0}
}
:endtag
:enddata
:endrule

rule:
plugin=vanillaBlocks
number=44
data:
tag:
TAG=10={
TAG=8=blockName{double_stone_slab}
TAG=3=meta{5}
TAG=3=buildPass{0}
}
:endtag
:enddata
:endrule

rule:
plugin=vanillaDoors
number=45
data:
tag:
TAG=10={
TAG=1=sideFlag{0}
TAG=8=blockName{iron_door}
TAG=3=meta{8}
TAG=3=buildPass{1}
}
:endtag
:enddata
:endrule

rule:
plugin=awAdvancedSpawner
number=46
data:
tag:
TAG=10={
TAG=10=teData{
TAG=9=Items{
}
TAG=8=id{Furnace}
TAG=2=BurnTime{0}
TAG=3=z{95}
TAG=2=CookTime{0}
TAG=3=y{71}
TAG=3=x{204}
}
TAG=8=blockName{furnace}
TAG=3=meta{3}
TAG=3=buildPass{0}
}
:endtag
:enddata
:endrule

rule:
plugin=vanillaDoors
number=47
data:
tag:
TAG=10={
TAG=1=sideFlag{0}
TAG=8=blockName{iron_door}
TAG=3=meta{8}
TAG=3=buildPass{1}
}
:endtag
:enddata
:endrule

rule:
plugin=vanillaDoors
number=48
data:
tag:
TAG=10={
TAG=1=sideFlag{0}
TAG=8=blockName{iron_door}
TAG=3=meta{8}
TAG=3=buildPass{1}
}
:endtag
:enddata
:endrule

rule:
plugin=vanillaBlocks
number=49
data:
tag:
TAG=10={
TAG=8=blockName{lever}
TAG=3=meta{0}
TAG=3=buildPass{1}
}
:endtag
:enddata
:endrule

rule:
plugin=vanillaSign
number=50
data:
tag:
TAG=10={
TAG=8=signContents1{}
TAG=8=blockName{wall_sign}
TAG=8=signContents2{}
TAG=8=signContents0{Barracks}
TAG=8=signContents3{}
TAG=3=meta{3}
TAG=3=buildPass{1}
}
:endtag
:enddata
:endrule

rule:
plugin=vanillaBlocks
number=51
data:
tag:
TAG=10={
TAG=8=blockName{lever}
TAG=3=meta{7}
TAG=3=buildPass{1}
}
:endtag
:enddata
:endrule

rule:
plugin=vanillaSign
number=52
data:
tag:
TAG=10={
TAG=8=signContents1{}
TAG=8=blockName{wall_sign}
TAG=8=signContents2{}
TAG=8=signContents0{Cells}
TAG=8=signContents3{}
TAG=3=meta{5}
TAG=3=buildPass{1}
}
:endtag
:enddata
:endrule

rule:
plugin=vanillaSign
number=53
data:
tag:
TAG=10={
TAG=8=signContents1{of}
TAG=8=blockName{wall_sign}
TAG=8=signContents2{Askyerdad}
TAG=8=signContents0{Prison}
TAG=8=signContents3{}
TAG=3=meta{3}
TAG=3=buildPass{1}
}
:endtag
:enddata
:endrule

rule:
plugin=vanillaInventory
number=54
data:
tag:
TAG=10={
TAG=3=lootLevel{0}
TAG=10=teData{
TAG=9=Items{
}
TAG=8=id{Chest}
}
TAG=8=blockName{chest}
TAG=3=meta{2}
TAG=3=buildPass{0}
}
:endtag
:enddata
:endrule

rule:
plugin=vanillaBlocks
number=55
data:
tag:
TAG=10={
TAG=8=blockName{bed}
TAG=3=meta{8}
TAG=3=buildPass{0}
}
:endtag
:enddata
:endrule

rule:
plugin=vanillaInventory
number=56
data:
tag:
TAG=10={
TAG=3=lootLevel{0}
TAG=10=teData{
TAG=9=Items{
}
TAG=8=id{Chest}
}
TAG=8=blockName{chest}
TAG=3=meta{2}
TAG=3=buildPass{0}
}
:endtag
:enddata
:endrule

rule:
plugin=vanillaInventory
number=57
data:
tag:
TAG=10={
TAG=3=lootLevel{0}
TAG=10=teData{
TAG=9=Items{
}
TAG=8=id{Chest}
}
TAG=8=blockName{chest}
TAG=3=meta{2}
TAG=3=buildPass{0}
}
:endtag
:enddata
:endrule

rule:
plugin=vanillaInventory
number=58
data:
tag:
TAG=10={
TAG=3=lootLevel{0}
TAG=10=teData{
TAG=9=Items{
}
TAG=8=id{Chest}
}
TAG=8=blockName{chest}
TAG=3=meta{2}
TAG=3=buildPass{0}
}
:endtag
:enddata
:endrule

rule:
plugin=vanillaInventory
number=59
data:
tag:
TAG=10={
TAG=3=lootLevel{0}
TAG=10=teData{
TAG=9=Items{
}
TAG=8=id{Chest}
}
TAG=8=blockName{chest}
TAG=3=meta{2}
TAG=3=buildPass{0}
}
:endtag
:enddata
:endrule

rule:
plugin=vanillaBlocks
number=60
data:
tag:
TAG=10={
TAG=8=blockName{bed}
TAG=3=meta{0}
TAG=3=buildPass{0}
}
:endtag
:enddata
:endrule

rule:
plugin=vanillaInventory
number=61
data:
tag:
TAG=10={
TAG=3=lootLevel{0}
TAG=10=teData{
TAG=9=Items{
}
TAG=8=id{Chest}
}
TAG=8=blockName{chest}
TAG=3=meta{4}
TAG=3=buildPass{0}
}
:endtag
:enddata
:endrule

rule:
plugin=vanillaBlocks
number=62
data:
tag:
TAG=10={
TAG=8=blockName{fence}
TAG=3=meta{0}
TAG=3=buildPass{0}
}
:endtag
:enddata
:endrule

rule:
plugin=vanillaInventory
number=63
data:
tag:
TAG=10={
TAG=3=lootLevel{0}
TAG=10=teData{
TAG=9=Items{
}
TAG=8=id{Chest}
}
TAG=8=blockName{chest}
TAG=3=meta{4}
TAG=3=buildPass{0}
}
:endtag
:enddata
:endrule

rule:
plugin=vanillaInventory
number=64
data:
tag:
TAG=10={
TAG=3=lootLevel{0}
TAG=10=teData{
TAG=9=Items{
}
TAG=8=id{Chest}
}
TAG=8=blockName{chest}
TAG=3=meta{2}
TAG=3=buildPass{0}
}
:endtag
:enddata
:endrule

rule:
plugin=vanillaBlocks
number=65
data:
tag:
TAG=10={
TAG=8=blockName{bed}
TAG=3=meta{2}
TAG=3=buildPass{0}
}
:endtag
:enddata
:endrule

rule:
plugin=vanillaInventory
number=66
data:
tag:
TAG=10={
TAG=3=lootLevel{0}
TAG=10=teData{
TAG=9=Items{
}
TAG=8=id{Chest}
}
TAG=8=blockName{chest}
TAG=3=meta{2}
TAG=3=buildPass{0}
}
:endtag
:enddata
:endrule

rule:
plugin=vanillaInventory
number=67
data:
tag:
TAG=10={
TAG=3=lootLevel{0}
TAG=10=teData{
TAG=9=Items{
}
TAG=8=id{Chest}
}
TAG=8=blockName{chest}
TAG=3=meta{3}
TAG=3=buildPass{0}
}
:endtag
:enddata
:endrule

rule:
plugin=vanillaInventory
number=68
data:
tag:
TAG=10={
TAG=3=lootLevel{0}
TAG=10=teData{
TAG=9=Items{
}
TAG=8=id{Chest}
}
TAG=8=blockName{chest}
TAG=3=meta{3}
TAG=3=buildPass{0}
}
:endtag
:enddata
:endrule

rule:
plugin=vanillaInventory
number=69
data:
tag:
TAG=10={
TAG=3=lootLevel{0}
TAG=10=teData{
TAG=9=Items{
}
TAG=8=id{Chest}
}
TAG=8=blockName{chest}
TAG=3=meta{3}
TAG=3=buildPass{0}
}
:endtag
:enddata
:endrule

rule:
plugin=vanillaBlocks
number=70
data:
tag:
TAG=10={
TAG=8=blockName{bed}
TAG=3=meta{10}
TAG=3=buildPass{0}
}
:endtag
:enddata
:endrule

rule:
plugin=vanillaBlocks
number=71
data:
tag:
TAG=10={
TAG=8=blockName{torch}
TAG=3=meta{5}
TAG=3=buildPass{1}
}
:endtag
:enddata
:endrule

rule:
plugin=vanillaDoors
number=72
data:
tag:
TAG=10={
TAG=1=sideFlag{0}
TAG=8=blockName{iron_door}
TAG=3=meta{8}
TAG=3=buildPass{1}
}
:endtag
:enddata
:endrule

rule:
plugin=vanillaBlocks
number=73
data:
tag:
TAG=10={
TAG=8=blockName{glass_pane}
TAG=3=meta{0}
TAG=3=buildPass{0}
}
:endtag
:enddata
:endrule

rule:
plugin=vanillaBlocks
number=74
data:
tag:
TAG=10={
TAG=8=blockName{planks}
TAG=3=meta{0}
TAG=3=buildPass{0}
}
:endtag
:enddata
:endrule

rule:
plugin=vanillaBlocks
number=75
data:
tag:
TAG=10={
TAG=8=blockName{stone_brick_stairs}
TAG=3=meta{6}
TAG=3=buildPass{0}
}
:endtag
:enddata
:endrule

rule:
plugin=vanillaDoors
number=76
data:
tag:
TAG=10={
TAG=1=sideFlag{0}
TAG=8=blockName{iron_door}
TAG=3=meta{8}
TAG=3=buildPass{1}
}
:endtag
:enddata
:endrule

rule:
plugin=vanillaBlocks
number=77
data:
tag:
TAG=10={
TAG=8=blockName{stone_slab}
TAG=3=meta{5}
TAG=3=buildPass{0}
}
:endtag
:enddata
:endrule

rule:
plugin=vanillaBlocks
number=78
data:
tag:
TAG=10={
TAG=8=blockName{stone_brick_stairs}
TAG=3=meta{7}
TAG=3=buildPass{0}
}
:endtag
:enddata
:endrule

rule:
plugin=vanillaDoors
number=79
data:
tag:
TAG=10={
TAG=1=sideFlag{8}
TAG=8=blockName{iron_door}
TAG=3=meta{1}
TAG=3=buildPass{1}
}
:endtag
:enddata
:endrule

rule:
plugin=vanillaDoors
number=80
data:
tag:
TAG=10={
TAG=1=sideFlag{0}
TAG=8=blockName{iron_door}
TAG=3=meta{8}
TAG=3=buildPass{1}
}
:endtag
:enddata
:endrule

rule:
plugin=vanillaBlocks
number=81
data:
tag:
TAG=10={
TAG=8=blockName{lever}
TAG=3=meta{4}
TAG=3=buildPass{1}
}
:endtag
:enddata
:endrule

rule:
plugin=vanillaDoors
number=82
data:
tag:
TAG=10={
TAG=1=sideFlag{0}
TAG=8=blockName{iron_door}
TAG=3=meta{8}
TAG=3=buildPass{1}
}
:endtag
:enddata
:endrule

rule:
plugin=vanillaBlocks
number=83
data:
tag:
TAG=10={
TAG=8=blockName{wooden_slab}
TAG=3=meta{0}
TAG=3=buildPass{0}
}
:endtag
:enddata
:endrule

rule:
plugin=vanillaInventory
number=84
data:
tag:
TAG=10={
TAG=3=lootLevel{0}
TAG=10=teData{
TAG=9=Items{
}
TAG=8=id{Chest}
}
TAG=8=blockName{chest}
TAG=3=meta{5}
TAG=3=buildPass{0}
}
:endtag
:enddata
:endrule

rule:
plugin=vanillaDoors
number=85
data:
tag:
TAG=10={
TAG=1=sideFlag{8}
TAG=8=blockName{iron_door}
TAG=3=meta{5}
TAG=3=buildPass{1}
}
:endtag
:enddata
:endrule

rule:
plugin=vanillaDoors
number=86
data:
tag:
TAG=10={
TAG=1=sideFlag{0}
TAG=8=blockName{iron_door}
TAG=3=meta{8}
TAG=3=buildPass{1}
}
:endtag
:enddata
:endrule

rule:
plugin=vanillaBlocks
number=87
data:
tag:
TAG=10={
TAG=8=blockName{lever}
TAG=3=meta{12}
TAG=3=buildPass{1}
}
:endtag
:enddata
:endrule

rule:
plugin=vanillaDoors
number=88
data:
tag:
TAG=10={
TAG=1=sideFlag{0}
TAG=8=blockName{iron_door}
TAG=3=meta{8}
TAG=3=buildPass{1}
}
:endtag
:enddata
:endrule

rule:
plugin=vanillaInventory
number=89
data:
tag:
TAG=10={
TAG=3=lootLevel{0}
TAG=10=teData{
TAG=9=Items{
}
TAG=8=id{Chest}
}
TAG=8=blockName{chest}
TAG=3=meta{5}
TAG=3=buildPass{0}
}
:endtag
:enddata
:endrule

rule:
plugin=vanillaDoors
number=90
data:
tag:
TAG=10={
TAG=1=sideFlag{0}
TAG=8=blockName{iron_door}
TAG=3=meta{8}
TAG=3=buildPass{1}
}
:endtag
:enddata
:endrule

rule:
plugin=vanillaBlocks
number=91
data:
tag:
TAG=10={
TAG=8=blockName{ladder}
TAG=3=meta{2}
TAG=3=buildPass{1}
}
:endtag
:enddata
:endrule

rule:
plugin=vanillaInventory
number=92
data:
tag:
TAG=10={
TAG=3=lootLevel{0}
TAG=10=teData{
TAG=9=Items{
}
TAG=8=id{Chest}
}
TAG=8=blockName{chest}
TAG=3=meta{2}
TAG=3=buildPass{0}
}
:endtag
:enddata
:endrule

#### ENTITIES ####
entity:
plugin=vanillaLogicEntity
number=0
data:
position=13,2,24
tag:
TAG=10={
TAG=10=entityData{
TAG=9=DropChances{
TAG=5=0{0.085}
TAG=5=1{0.085}
TAG=5=2{0.085}
TAG=5=3{0.085}
TAG=5=4{0.085}
}
TAG=3=Age{0}
TAG=9=Attributes{
TAG=10={
TAG=8=Name{generic.maxHealth}
TAG=6=Base{20.0}
}
TAG=10={
TAG=8=Name{generic.knockbackResistance}
TAG=6=Base{0.0}
}
TAG=10={
TAG=8=Name{generic.movementSpeed}
TAG=6=Base{0.5}
}
TAG=10={
TAG=8=Name{generic.followRange}
TAG=6=Base{16.0}
}
}
TAG=9=Motion{
TAG=6={0.0}
TAG=6={-0.0784000015258789}
TAG=6={0.0}
}
TAG=8=CustomName{}
TAG=2=Health{20}
TAG=5=HealF{20.0}
TAG=1=CustomNameVisible{0}
TAG=3=Riches{0}
TAG=2=AttackTime{0}
TAG=2=Fire{-1}
TAG=1=Invulnerable{0}
TAG=2=DeathTime{0}
TAG=10=ForgeData{
TAG=1=MP|Init{1}
}
TAG=5=AbsorptionAmount{0.0}
TAG=9=Equipment{
TAG=10={
}
TAG=10={
}
TAG=10={
}
TAG=10={
}
TAG=10={
}
}
TAG=1=OnGround{1}
TAG=2=HurtTime{0}
TAG=3=Profession{2}
TAG=3=Dimension{0}
TAG=2=Air{300}
TAG=9=Pos{
TAG=6={201.03206361937552}
TAG=6={66.0}
TAG=6={91.30000001192093}
}
TAG=1=CanPickUpLoot{0}
TAG=3=PortalCooldown{0}
TAG=1=PersistenceRequired{0}
TAG=1=Leashed{0}
TAG=5=FallDistance{0.0}
TAG=9=Rotation{
TAG=5={-430.14093}
TAG=5={0.0}
}
}
TAG=5=yOffset{0.0}
TAG=5=xOffset{0.9679364}
TAG=5=zOffset{0.7}
TAG=8=mobID{Villager}
TAG=5=rotation{-250.14093}
}
:endtag
:enddata
:endentity

entity:
plugin=vanillaLogicEntity
number=1
data:
position=13,2,20
tag:
TAG=10={
TAG=10=entityData{
TAG=9=DropChances{
TAG=5=0{0.085}
TAG=5=1{0.085}
TAG=5=2{0.085}
TAG=5=3{0.085}
TAG=5=4{0.085}
}
TAG=3=Age{0}
TAG=9=Attributes{
TAG=10={
TAG=8=Name{generic.maxHealth}
TAG=6=Base{20.0}
}
TAG=10={
TAG=8=Name{generic.knockbackResistance}
TAG=6=Base{0.0}
}
TAG=10={
TAG=8=Name{generic.movementSpeed}
TAG=6=Base{0.5}
}
TAG=10={
TAG=8=Name{generic.followRange}
TAG=6=Base{16.0}
}
}
TAG=9=Motion{
TAG=6={0.0}
TAG=6={-0.0784000015258789}
TAG=6={0.0}
}
TAG=8=CustomName{}
TAG=2=Health{20}
TAG=5=HealF{20.0}
TAG=1=CustomNameVisible{0}
TAG=3=Riches{0}
TAG=2=AttackTime{0}
TAG=2=Fire{-1}
TAG=1=Invulnerable{0}
TAG=2=DeathTime{0}
TAG=10=ForgeData{
TAG=1=MP|Init{1}
}
TAG=5=AbsorptionAmount{0.0}
TAG=9=Equipment{
TAG=10={
}
TAG=10={
}
TAG=10={
}
TAG=10={
}
TAG=10={
}
}
TAG=1=OnGround{1}
TAG=2=HurtTime{0}
TAG=3=Profession{1}
TAG=3=Dimension{0}
TAG=2=Air{300}
TAG=9=Pos{
TAG=6={201.18779501668578}
TAG=6={66.5625}
TAG=6={95.52127088717361}
}
TAG=1=CanPickUpLoot{0}
TAG=3=PortalCooldown{0}
TAG=1=PersistenceRequired{0}
TAG=1=Leashed{0}
TAG=5=FallDistance{0.0}
TAG=9=Rotation{
TAG=5={279.24524}
TAG=5={0.0}
}
}
TAG=5=yOffset{0.5625}
TAG=5=xOffset{0.81220496}
TAG=5=zOffset{0.47872913}
TAG=8=mobID{Villager}
TAG=5=rotation{99.24524}
}
:endtag
:enddata
:endentity

entity:
plugin=vanillaLogicEntity
number=2
data:
position=13,2,28
tag:
TAG=10={
TAG=10=entityData{
TAG=9=DropChances{
TAG=5=0{0.085}
TAG=5=1{0.085}
TAG=5=2{0.085}
TAG=5=3{0.085}
TAG=5=4{0.085}
}
TAG=3=Age{0}
TAG=9=Attributes{
TAG=10={
TAG=8=Name{generic.maxHealth}
TAG=6=Base{20.0}
}
TAG=10={
TAG=8=Name{generic.knockbackResistance}
TAG=6=Base{0.0}
}
TAG=10={
TAG=8=Name{generic.movementSpeed}
TAG=6=Base{0.5}
}
TAG=10={
TAG=8=Name{generic.followRange}
TAG=6=Base{16.0}
}
}
TAG=9=Motion{
TAG=6={0.0}
TAG=6={-0.0784000015258789}
TAG=6={0.0}
}
TAG=8=CustomName{}
TAG=2=Health{20}
TAG=5=HealF{20.0}
TAG=1=CustomNameVisible{0}
TAG=3=Riches{0}
TAG=2=AttackTime{0}
TAG=2=Fire{-1}
TAG=1=Invulnerable{0}
TAG=2=DeathTime{0}
TAG=10=ForgeData{
TAG=1=MP|Init{1}
}
TAG=5=AbsorptionAmount{0.0}
TAG=9=Equipment{
TAG=10={
}
TAG=10={
}
TAG=10={
}
TAG=10={
}
TAG=10={
}
}
TAG=1=OnGround{1}
TAG=2=HurtTime{0}
TAG=3=Profession{42}
TAG=3=Dimension{0}
TAG=2=Air{300}
TAG=9=Pos{
TAG=6={201.16120983264318}
TAG=6={66.0}
TAG=6={87.6565587697538}
}
TAG=1=CanPickUpLoot{0}
TAG=3=PortalCooldown{0}
TAG=1=PersistenceRequired{0}
TAG=1=Leashed{0}
TAG=5=FallDistance{0.0}
TAG=9=Rotation{
TAG=5={-105.49512}
TAG=5={0.0}
}
}
TAG=5=yOffset{0.0}
TAG=5=xOffset{0.8387902}
TAG=5=zOffset{0.34344125}
TAG=8=mobID{Villager}
TAG=5=rotation{74.50488}
}
:endtag
:enddata
:endentity

entity:
plugin=awNpcOld
number=3
data:
position=11,6,23
tag:
TAG=10={
TAG=5=yOffset{0.0}
TAG=5=xOffset{0.24735075}
TAG=5=zOffset{0.25217938}
TAG=5=rotation{282.27142}
TAG=3=npcLevel{0}
TAG=3=npcType{2}
TAG=3=npcTeam{17}
}
:endtag
:enddata
:endentity

entity:
plugin=awNpcOld
number=4
data:
position=7,11,22
tag:
TAG=10={
TAG=5=yOffset{0.0}
TAG=5=xOffset{0.5}
TAG=5=zOffset{0.5}
TAG=5=rotation{103.4707}
TAG=3=npcLevel{1}
TAG=3=npcType{2}
TAG=3=npcTeam{17}
}
:endtag
:enddata
:endentity

entity:
plugin=awNpcOld
number=5
data:
position=7,11,23
tag:
TAG=10={
TAG=5=yOffset{0.0}
TAG=5=xOffset{0.5}
TAG=5=zOffset{0.5}
TAG=5=rotation{67.92029}
TAG=3=npcLevel{1}
TAG=3=npcType{2}
TAG=3=npcTeam{17}
}
:endtag
:enddata
:endentity

entity:
plugin=awNpcOld
number=6
data:
position=15,17,27
tag:
TAG=10={
TAG=5=yOffset{0.0}
TAG=5=xOffset{0.5}
TAG=5=zOffset{0.5}
TAG=5=rotation{280.62207}
TAG=3=npcLevel{1}
TAG=3=npcType{3}
TAG=3=npcTeam{17}
}
:endtag
:enddata
:endentity

entity:
plugin=vanillaLogicEntity
number=7
data:
position=10,13,8
tag:
TAG=10={
TAG=10=entityData{
TAG=9=DropChances{
TAG=5=0{0.085}
TAG=5=1{0.085}
TAG=5=2{0.085}
TAG=5=3{0.085}
TAG=5=4{0.085}
}
TAG=3=Age{0}
TAG=9=Attributes{
TAG=10={
TAG=8=Name{generic.maxHealth}
TAG=6=Base{20.0}
}
TAG=10={
TAG=8=Name{generic.knockbackResistance}
TAG=6=Base{0.0}
}
TAG=10={
TAG=8=Name{generic.movementSpeed}
TAG=6=Base{0.5}
}
TAG=10={
TAG=8=Name{generic.followRange}
TAG=6=Base{16.0}
TAG=9=Modifiers{
TAG=10={
TAG=8=Name{Random spawn bonus}
TAG=4=UUIDLeast{-7526165461131280869}
TAG=3=Operation{1}
TAG=6=Amount{-0.06993033185146634}
TAG=4=UUIDMost{8043966431802510866}
}
}
}
}
TAG=9=Motion{
TAG=6={0.0}
TAG=6={-0.0784000015258789}
TAG=6={0.0}
}
TAG=8=CustomName{}
TAG=2=Health{20}
TAG=5=HealF{20.0}
TAG=1=CustomNameVisible{0}
TAG=3=Riches{0}
TAG=2=AttackTime{0}
TAG=2=Fire{-1}
TAG=1=Invulnerable{0}
TAG=2=DeathTime{0}
TAG=10=ForgeData{
TAG=1=MP|Init{1}
}
TAG=5=AbsorptionAmount{0.0}
TAG=9=Equipment{
TAG=10={
}
TAG=10={
}
TAG=10={
}
TAG=10={
}
TAG=10={
}
}
TAG=1=OnGround{1}
TAG=2=HurtTime{0}
TAG=3=Profession{385}
TAG=3=Dimension{0}
TAG=2=Air{300}
TAG=9=Pos{
TAG=6={204.13352877603552}
TAG=6={77.0}
TAG=6={107.50175117975648}
}
TAG=1=CanPickUpLoot{0}
TAG=3=PortalCooldown{0}
TAG=1=PersistenceRequired{0}
TAG=1=Leashed{0}
TAG=5=FallDistance{0.0}
TAG=9=Rotation{
TAG=5={269.8561}
TAG=5={30.402285}
}
}
TAG=5=yOffset{0.0}
TAG=5=xOffset{0.86647123}
TAG=5=zOffset{0.49824882}
TAG=8=mobID{Villager}
TAG=5=rotation{89.85611}
}
:endtag
:enddata
:endentity

entity:
plugin=awNpcOld
number=8
data:
position=14,10,4
tag:
TAG=10={
TAG=5=yOffset{0.0}
TAG=5=xOffset{0.5}
TAG=5=zOffset{0.5}
TAG=5=rotation{219.12216}
TAG=3=npcLevel{0}
TAG=3=npcType{2}
TAG=3=npcTeam{17}
}
:endtag
:enddata
:endentity

entity:
plugin=awNpcOld
number=9
data:
position=15,4,6
tag:
TAG=10={
TAG=5=yOffset{0.0}
TAG=5=xOffset{0.5}
TAG=5=zOffset{0.5}
TAG=5=rotation{298.32208}
TAG=3=npcLevel{0}
TAG=3=npcType{2}
TAG=3=npcTeam{17}
}
:endtag
:enddata
:endentity

entity:
plugin=vanillaLogicEntity
number=10
data:
position=14,18,8
tag:
TAG=10={
TAG=10=entityData{
TAG=9=DropChances{
TAG=5=0{0.085}
TAG=5=1{0.085}
TAG=5=2{0.085}
TAG=5=3{0.085}
TAG=5=4{0.085}
}
TAG=3=Age{0}
TAG=9=Attributes{
TAG=10={
TAG=8=Name{generic.maxHealth}
TAG=6=Base{20.0}
}
TAG=10={
TAG=8=Name{generic.knockbackResistance}
TAG=6=Base{0.0}
}
TAG=10={
TAG=8=Name{generic.movementSpeed}
TAG=6=Base{0.5}
}
TAG=10={
TAG=8=Name{generic.followRange}
TAG=6=Base{16.0}
TAG=9=Modifiers{
TAG=10={
TAG=8=Name{Random spawn bonus}
TAG=4=UUIDLeast{-6565784771884801149}
TAG=3=Operation{1}
TAG=6=Amount{-0.03601671738579281}
TAG=4=UUIDMost{-3873857245753228118}
}
}
}
}
TAG=9=Motion{
TAG=6={0.0}
TAG=6={-0.0784000015258789}
TAG=6={0.0}
}
TAG=8=CustomName{}
TAG=2=Health{20}
TAG=5=HealF{20.0}
TAG=1=CustomNameVisible{0}
TAG=3=Riches{0}
TAG=2=AttackTime{0}
TAG=2=Fire{-1}
TAG=1=Invulnerable{0}
TAG=2=DeathTime{0}
TAG=10=ForgeData{
TAG=1=MP|Init{1}
}
TAG=5=AbsorptionAmount{0.0}
TAG=9=Equipment{
TAG=10={
}
TAG=10={
}
TAG=10={
}
TAG=10={
}
TAG=10={
}
}
TAG=1=OnGround{1}
TAG=2=HurtTime{0}
TAG=3=Profession{0}
TAG=3=Dimension{0}
TAG=2=Air{300}
TAG=9=Pos{
TAG=6={200.77943389470852}
TAG=6={82.0}
TAG=6={107.49234308004742}
}
TAG=1=CanPickUpLoot{0}
TAG=3=PortalCooldown{0}
TAG=1=PersistenceRequired{0}
TAG=1=Leashed{0}
TAG=5=FallDistance{0.0}
TAG=9=Rotation{
TAG=5={-270.71555}
TAG=5={0.0}
}
}
TAG=5=yOffset{0.0}
TAG=5=xOffset{0.2205661}
TAG=5=zOffset{0.50765693}
TAG=8=mobID{Villager}
TAG=5=rotation{-90.715546}
}
:endtag
:enddata
:endentity

entity:
plugin=vanillaLogicEntity
number=11
data:
position=10,28,7
tag:
TAG=10={
TAG=10=entityData{
TAG=9=DropChances{
TAG=5=0{0.085}
TAG=5=1{0.085}
TAG=5=2{0.085}
TAG=5=3{0.085}
TAG=5=4{0.085}
}
TAG=3=Age{0}
TAG=9=Attributes{
TAG=10={
TAG=8=Name{generic.maxHealth}
TAG=6=Base{20.0}
}
TAG=10={
TAG=8=Name{generic.knockbackResistance}
TAG=6=Base{0.0}
}
TAG=10={
TAG=8=Name{generic.movementSpeed}
TAG=6=Base{0.5}
}
TAG=10={
TAG=8=Name{generic.followRange}
TAG=6=Base{16.0}
TAG=9=Modifiers{
TAG=10={
TAG=8=Name{Random spawn bonus}
TAG=4=UUIDLeast{-5924123024799154141}
TAG=3=Operation{1}
TAG=6=Amount{-0.02347445011070416}
TAG=4=UUIDMost{-5113750352974951002}
}
}
}
}
TAG=9=Motion{
TAG=6={0.0}
TAG=6={-0.0784000015258789}
TAG=6={0.0}
}
TAG=8=CustomName{}
TAG=2=Health{20}
TAG=5=HealF{20.0}
TAG=1=CustomNameVisible{0}
TAG=3=Riches{0}
TAG=2=AttackTime{0}
TAG=2=Fire{-1}
TAG=1=Invulnerable{0}
TAG=2=DeathTime{0}
TAG=10=ForgeData{
TAG=1=MP|Init{1}
}
TAG=5=AbsorptionAmount{0.0}
TAG=9=Equipment{
TAG=10={
}
TAG=10={
}
TAG=10={
}
TAG=10={
}
TAG=10={
}
}
TAG=1=OnGround{1}
TAG=2=HurtTime{0}
TAG=3=Profession{45}
TAG=3=Dimension{0}
TAG=2=Air{300}
TAG=9=Pos{
TAG=6={204.18449146694982}
TAG=6={92.0}
TAG=6={108.50087859885316}
}
TAG=1=CanPickUpLoot{0}
TAG=3=PortalCooldown{0}
TAG=1=PersistenceRequired{0}
TAG=1=Leashed{0}
TAG=5=FallDistance{0.0}
TAG=9=Rotation{
TAG=5={-450.07748}
TAG=5={0.0}
}
}
TAG=5=yOffset{0.0}
TAG=5=xOffset{0.81550854}
TAG=5=zOffset{0.49912143}
TAG=8=mobID{Villager}
TAG=5=rotation{-270.07748}
}
:endtag
:enddata
:endentity

entity:
plugin=awNpcOld
number=12
data:
position=15,38,7
tag:
TAG=10={
TAG=5=yOffset{0.0}
TAG=5=xOffset{0.5}
TAG=5=zOffset{0.5}
TAG=5=rotation{134.97192}
TAG=3=npcLevel{1}
TAG=3=npcType{3}
TAG=3=npcTeam{17}
}
:endtag
:enddata
:endentity

entity:
plugin=awNpcOld
number=13
data:
position=11,42,5
tag:
TAG=10={
TAG=5=yOffset{0.0}
TAG=5=xOffset{0.5}
TAG=5=zOffset{0.5}
TAG=5=rotation{64.921875}
TAG=3=npcLevel{0}
TAG=3=npcType{3}
TAG=3=npcTeam{17}
}
:endtag
:enddata
:endentity

entity:
plugin=vanillaLogicEntity
number=14
data:
position=6,2,28
tag:
TAG=10={
TAG=10=entityData{
TAG=9=DropChances{
TAG=5=0{0.085}
TAG=5=1{0.085}
TAG=5=2{0.085}
TAG=5=3{0.085}
TAG=5=4{0.085}
}
TAG=3=Age{0}
TAG=9=Attributes{
TAG=10={
TAG=8=Name{generic.maxHealth}
TAG=6=Base{20.0}
}
TAG=10={
TAG=8=Name{generic.knockbackResistance}
TAG=6=Base{0.0}
}
TAG=10={
TAG=8=Name{generic.movementSpeed}
TAG=6=Base{0.5}
}
TAG=10={
TAG=8=Name{generic.followRange}
TAG=6=Base{16.0}
}
}
TAG=9=Motion{
TAG=6={0.0}
TAG=6={-0.0784000015258789}
TAG=6={0.0}
}
TAG=8=CustomName{}
TAG=2=Health{20}
TAG=5=HealF{20.0}
TAG=1=CustomNameVisible{0}
TAG=3=Riches{0}
TAG=2=AttackTime{0}
TAG=2=Fire{-1}
TAG=1=Invulnerable{0}
TAG=2=DeathTime{0}
TAG=10=ForgeData{
TAG=1=MP|Init{1}
}
TAG=5=AbsorptionAmount{0.0}
TAG=9=Equipment{
TAG=10={
}
TAG=10={
}
TAG=10={
}
TAG=10={
}
TAG=10={
}
}
TAG=1=OnGround{1}
TAG=2=HurtTime{0}
TAG=3=Profession{3}
TAG=3=Dimension{0}
TAG=2=Air{300}
TAG=9=Pos{
TAG=6={208.11996668097908}
TAG=6={66.0}
TAG=6={87.65553782837469}
}
TAG=1=CanPickUpLoot{0}
TAG=3=PortalCooldown{0}
TAG=1=PersistenceRequired{0}
TAG=1=Leashed{0}
TAG=5=FallDistance{0.0}
TAG=9=Rotation{
TAG=5={-105.86504}
TAG=5={0.0}
}
}
TAG=5=yOffset{0.0}
TAG=5=xOffset{0.8800333}
TAG=5=zOffset{0.34446216}
TAG=8=mobID{Villager}
TAG=5=rotation{74.13496}
}
:endtag
:enddata
:endentity

entity:
plugin=vanillaLogicEntity
number=15
data:
position=6,2,24
tag:
TAG=10={
TAG=10=entityData{
TAG=9=DropChances{
TAG=5=0{0.085}
TAG=5=1{0.085}
TAG=5=2{0.085}
TAG=5=3{0.085}
TAG=5=4{0.085}
}
TAG=3=Age{0}
TAG=9=Attributes{
TAG=10={
TAG=8=Name{generic.maxHealth}
TAG=6=Base{20.0}
}
TAG=10={
TAG=8=Name{generic.knockbackResistance}
TAG=6=Base{0.0}
}
TAG=10={
TAG=8=Name{generic.movementSpeed}
TAG=6=Base{0.5}
}
TAG=10={
TAG=8=Name{generic.followRange}
TAG=6=Base{16.0}
}
}
TAG=9=Motion{
TAG=6={0.0}
TAG=6={-0.0784000015258789}
TAG=6={0.0}
}
TAG=8=CustomName{}
TAG=2=Health{20}
TAG=5=HealF{20.0}
TAG=1=CustomNameVisible{0}
TAG=3=Riches{0}
TAG=2=AttackTime{0}
TAG=2=Fire{-1}
TAG=1=Invulnerable{0}
TAG=2=DeathTime{0}
TAG=10=ForgeData{
TAG=1=MP|Init{1}
}
TAG=5=AbsorptionAmount{0.0}
TAG=9=Equipment{
TAG=10={
}
TAG=10={
}
TAG=10={
}
TAG=10={
}
TAG=10={
}
}
TAG=1=OnGround{1}
TAG=2=HurtTime{0}
TAG=3=Profession{0}
TAG=3=Dimension{0}
TAG=2=Air{300}
TAG=9=Pos{
TAG=6={208.21958113611333}
TAG=6={66.0}
TAG=6={91.6565587697538}
}
TAG=1=CanPickUpLoot{0}
TAG=3=PortalCooldown{0}
TAG=1=PersistenceRequired{0}
TAG=1=Leashed{0}
TAG=5=FallDistance{0.0}
TAG=9=Rotation{
TAG=5={-105.49414}
TAG=5={0.0}
}
}
TAG=5=yOffset{0.0}
TAG=5=xOffset{0.7804189}
TAG=5=zOffset{0.34344125}
TAG=8=mobID{Villager}
TAG=5=rotation{74.50586}
}
:endtag
:enddata
:endentity

entity:
plugin=awNpcOld
number=16
data:
position=3,17,19
tag:
TAG=10={
TAG=5=yOffset{0.0}
TAG=5=xOffset{0.5}
TAG=5=zOffset{0.5}
TAG=5=rotation{136.92181}
TAG=3=npcLevel{0}
TAG=3=npcType{3}
TAG=3=npcTeam{17}
}
:endtag
:enddata
:endentity

