# Ancient Warfare Structure Template File
# auto-generated structure file. created on: 4/15/2014 at: 13:52:1
# Lines beginning with # denote comments

header:
version=2.0
name=CivWatchBorderTowerHostileMOH
size=19,45,13
offset=4,3,11
:endheader

#### VALIDATION ####
validation:
type=ground
survival=false
worldGenEnabled=true
unique=false
preserveBlocks=false
selectionWeight=10
clusterValue=10
minDuplicateDistance=80
dimensionWhiteList=false
dimensionList=
biomeWhiteList=true
biomeList=highlands.meadow,bop.meadow,ebxl.meadow,field,orchard
leveling=6
fill=3
border=3
validTargetBlocks=clay,lapis_ore,sand,grass,lit_redstone_ore,stone,iron_ore,gravel,diamond_ore,stained_hardened_clay,dirt,coal_ore,redstone_ore,gold_ore
data:
:enddata
:endvalidation

#### LAYERS ####
layer: 0
1,1,1,1,1,1,1,1,1,1,1,1,1,1,1,1,1,1,1
1,1,1,1,1,1,1,2,2,2,2,2,2,2,2,2,2,1,1
1,1,1,1,1,1,1,2,2,2,2,2,2,2,2,2,2,1,1
1,1,1,1,1,1,1,2,2,2,2,2,2,2,2,2,2,1,1
1,1,1,1,1,1,1,2,2,2,2,2,2,2,2,2,2,1,1
1,1,1,1,1,1,1,2,2,2,2,2,2,2,2,2,2,1,1
1,1,1,1,1,1,1,2,2,2,2,2,2,2,2,2,2,1,1
1,1,1,1,1,1,1,2,2,2,2,2,2,2,2,2,2,1,1
1,1,1,1,1,1,1,2,2,2,2,2,2,2,2,2,2,1,1
1,1,1,1,1,1,1,2,2,2,2,2,2,2,2,2,2,1,1
1,1,1,1,1,1,1,1,1,1,1,1,1,1,1,1,1,1,1
1,1,1,1,1,1,1,1,1,1,1,1,1,1,1,1,1,1,1
1,1,1,1,1,1,1,1,1,1,1,1,1,1,1,1,1,1,1
:endlayer
layer: 1
1,1,1,1,1,1,1,1,1,1,1,1,1,1,1,1,1,1,1
1,1,1,1,1,1,1,2,1,1,1,2,1,1,1,1,1,1,1
1,1,1,1,1,1,1,2,2,2,2,2,2,2,2,2,1,1,1
1,1,1,1,1,1,1,2,2,0,0,0,0,0,0,2,1,1,1
1,1,1,1,1,1,1,2,2,0,0,0,0,0,0,2,2,1,1
1,1,1,1,1,1,1,2,2,0,0,0,0,0,0,2,2,1,1
1,1,1,1,1,1,1,2,2,0,0,0,0,0,0,2,2,1,1
1,1,1,1,1,1,1,2,2,0,0,0,2,2,2,2,2,1,1
1,1,1,1,1,1,1,2,2,0,0,0,3,2,2,2,2,1,1
1,1,1,1,1,1,1,2,2,2,2,2,2,2,2,2,2,1,1
1,1,1,1,1,1,1,1,1,1,1,1,1,1,1,1,1,1,1
1,1,1,1,1,1,1,1,1,1,1,1,1,1,1,1,1,1,1
1,1,1,1,1,1,1,1,1,1,1,1,1,1,1,1,1,1,1
:endlayer
layer: 2
4,4,4,4,4,4,4,4,4,4,4,4,4,4,4,4,4,4,4
4,1,1,1,1,1,1,1,1,1,1,2,1,1,1,1,1,1,4
4,1,1,1,1,1,1,2,2,2,2,2,2,2,2,2,1,1,4
4,1,1,1,1,1,1,2,2,0,0,0,0,0,0,2,1,1,4
4,1,1,1,1,1,1,2,2,0,0,0,0,0,0,2,2,1,4
4,1,1,1,1,1,1,2,2,0,0,0,0,0,0,2,2,1,4
4,1,1,1,1,1,1,2,2,0,0,0,0,0,0,2,2,1,4
4,1,1,1,1,1,1,2,2,0,0,0,2,2,2,2,2,1,4
4,1,1,1,1,1,1,2,2,0,0,0,0,3,2,1,1,1,4
4,1,1,1,1,1,1,2,2,2,2,2,2,2,1,1,1,1,4
4,1,1,1,1,1,1,1,1,1,1,1,1,1,1,1,1,1,4
4,1,1,1,1,1,1,1,1,1,1,1,1,1,1,1,1,1,4
4,4,4,4,4,4,4,4,4,4,4,4,4,4,4,4,4,4,4
:endlayer
layer: 3
0,0,0,0,0,0,0,0,0,0,0,0,0,0,0,0,0,0,0
0,4,4,4,4,9,9,9,4,4,4,4,4,4,4,4,4,4,0
0,4,1,1,1,4,4,2,2,2,2,2,2,2,2,2,1,4,0
0,4,1,10,10,10,10,2,2,7,0,0,0,0,0,2,1,4,0
0,4,1,10,10,10,10,2,2,0,0,0,0,0,0,2,2,4,0
0,4,1,10,10,10,10,2,2,0,0,0,0,0,0,2,2,4,0
0,4,1,10,10,10,10,2,2,0,0,0,0,0,5,2,2,4,0
0,4,1,10,10,10,10,2,2,0,0,0,2,2,6,2,2,4,0
0,4,1,10,10,10,10,2,2,8,0,0,0,0,0,2,1,4,0
0,4,1,10,10,10,10,2,2,2,2,2,2,2,2,2,1,4,0
0,4,1,1,1,4,4,4,1,1,1,1,1,1,1,1,1,4,0
0,4,4,4,4,6,6,6,4,4,4,4,4,4,4,4,4,4,0
0,0,0,0,0,0,0,0,0,0,0,0,0,0,0,0,0,0,0
:endlayer
layer: 4
0,0,0,0,0,0,0,0,0,0,0,0,0,0,0,0,0,0,0
0,0,0,0,0,0,0,0,0,0,0,0,0,0,0,0,0,0,0
0,0,2,2,2,9,9,9,2,2,2,2,2,2,2,2,2,0,0
0,0,2,2,2,2,2,2,2,2,2,2,2,2,2,2,2,0,0
0,0,2,2,2,11,11,11,11,2,2,2,2,2,2,2,2,0,0
0,0,2,2,2,11,11,11,11,2,2,2,2,2,2,2,2,0,0
0,0,2,2,2,11,11,11,11,2,2,2,2,2,6,2,2,0,0
0,0,2,2,2,11,11,11,11,2,2,2,2,2,0,2,2,0,0
0,0,2,2,2,11,11,11,11,2,2,2,0,0,0,2,2,0,0
0,0,2,2,2,2,2,2,2,2,2,2,2,2,2,2,2,0,0
0,0,2,2,2,6,6,6,2,2,2,2,2,2,2,2,2,0,0
0,0,0,0,0,0,0,0,0,0,0,0,0,0,0,0,0,0,0
0,0,0,0,0,0,0,0,0,0,0,0,0,0,0,0,0,0,0
:endlayer
layer: 5
0,0,0,0,0,0,0,0,0,0,0,0,0,0,0,0,0,0,0
0,0,0,0,0,0,0,0,0,0,0,0,0,0,0,0,0,0,0
0,0,2,2,15,0,0,0,15,2,2,2,2,2,2,2,2,0,0
0,0,2,2,2,0,0,0,2,2,2,2,2,2,2,2,2,0,0
0,0,2,2,2,0,0,0,0,2,14,0,0,0,12,2,2,0,0
0,0,2,2,2,0,0,0,0,0,0,0,0,0,0,2,2,0,0
0,0,2,2,2,0,0,0,0,0,0,0,0,0,0,2,2,0,0
0,0,2,2,2,0,0,0,0,0,0,0,0,2,0,2,2,0,0
0,0,2,2,2,0,0,0,16,2,0,3,13,0,0,2,2,0,0
0,0,2,2,2,0,0,0,2,2,2,2,2,2,2,2,2,0,0
0,0,2,2,15,0,0,0,15,2,2,2,2,2,2,2,2,0,0
0,0,0,0,0,0,0,0,0,0,0,0,0,0,0,0,0,0,0
0,0,0,0,0,0,0,0,0,0,0,0,0,0,0,0,0,0,0
:endlayer
layer: 6
0,0,0,0,0,0,0,0,0,0,0,0,0,0,0,0,0,0,0
0,0,0,0,0,0,0,0,0,0,0,0,0,0,0,0,0,0,0
0,0,9,9,18,0,0,0,0,9,9,9,9,9,9,9,17,0,0
0,0,3,2,2,0,0,0,2,2,2,2,2,2,2,2,17,0,0
0,0,3,2,0,0,0,0,0,2,0,0,0,0,0,2,17,0,0
0,0,3,2,0,0,0,0,0,0,0,0,0,0,0,2,17,0,0
0,0,3,2,0,0,0,0,0,0,0,0,0,0,0,2,17,0,0
0,0,3,2,0,0,0,0,0,0,0,0,0,2,0,2,17,0,0
0,0,3,2,0,0,0,0,0,2,0,0,3,13,0,2,17,0,0
0,0,3,2,2,0,0,0,2,2,2,2,2,2,2,2,17,0,0
0,0,3,6,19,0,0,0,0,6,6,6,6,6,6,6,17,0,0
0,0,0,0,0,0,0,0,0,0,0,0,0,0,0,0,0,0,0
0,0,0,0,0,0,0,0,0,0,0,0,0,0,0,0,0,0,0
:endlayer
layer: 7
0,0,0,0,0,0,0,0,0,0,0,0,0,0,0,0,0,0,0
0,0,0,0,0,0,0,0,0,0,0,0,0,0,0,0,0,0,0
0,0,0,0,0,0,0,0,0,0,0,0,0,0,0,0,0,0,0
0,0,0,2,2,0,0,0,2,2,2,2,2,2,2,2,0,0,0
0,0,0,2,19,0,0,0,5,2,0,0,0,0,0,2,0,0,0
0,0,0,0,0,0,0,0,0,0,0,0,0,0,0,2,0,0,0
0,0,0,2,0,0,0,0,0,0,0,0,0,0,5,2,0,0,0
0,0,0,0,0,0,0,0,0,0,0,0,0,2,20,2,0,0,0
0,0,0,2,18,0,0,0,5,2,0,0,0,3,13,2,0,0,0
0,0,0,2,2,0,0,0,2,2,2,2,2,2,2,2,0,0,0
0,0,0,0,0,0,0,0,0,0,0,0,0,0,0,0,0,0,0
0,0,0,0,0,0,0,0,0,0,0,0,0,0,0,0,0,0,0
0,0,0,0,0,0,0,0,0,0,0,0,0,0,0,0,0,0,0
:endlayer
layer: 8
0,0,0,0,0,0,0,0,0,0,0,0,0,0,0,0,0,0,0
0,0,0,0,0,0,0,0,0,0,0,0,0,0,0,0,0,0,0
0,0,0,21,0,0,0,0,0,21,0,0,0,0,0,21,0,0,0
0,0,5,2,2,0,0,0,2,2,2,2,2,2,2,2,8,0,0
0,0,0,2,0,0,0,0,0,2,0,0,7,0,0,2,0,0,0
0,0,0,2,0,0,0,0,0,2,0,0,0,0,20,2,0,0,0
0,0,0,2,8,0,0,0,0,2,0,0,0,0,22,2,0,0,0
0,0,0,2,0,0,0,0,0,2,0,0,0,2,6,2,0,0,0
0,0,0,2,0,0,0,0,0,2,0,0,21,0,0,2,0,0,0
0,0,5,2,2,0,0,0,2,2,2,2,2,2,2,2,8,0,0
0,0,0,7,0,0,0,0,0,7,0,0,0,0,0,7,0,0,0
0,0,0,0,0,0,0,0,0,0,0,0,0,0,0,0,0,0,0
0,0,0,0,0,0,0,0,0,0,0,0,0,0,0,0,0,0,0
:endlayer
layer: 9
0,0,0,0,0,0,0,0,0,0,0,0,0,0,0,0,0,0,0
0,0,0,0,0,0,0,0,0,0,0,0,0,0,0,0,0,0,0
0,0,22,22,22,22,22,22,22,13,0,0,0,0,0,0,0,0,0
0,0,24,2,2,2,2,2,2,2,2,2,2,2,2,2,0,0,0
0,0,24,2,2,2,2,2,2,2,2,2,2,2,2,2,0,0,0
0,0,24,2,2,2,2,2,2,2,2,2,2,2,2,2,0,0,0
0,0,24,2,2,2,2,2,2,2,2,2,2,2,6,2,0,0,0
0,0,24,2,2,2,2,2,2,2,2,2,2,2,0,2,0,0,0
0,0,24,2,2,2,2,2,2,2,2,13,0,0,0,2,0,0,0
0,0,24,2,2,2,2,2,2,2,2,2,2,2,2,2,0,0,0
0,0,24,23,23,23,23,23,23,13,0,0,0,0,0,0,0,0,0
0,0,0,0,0,0,0,0,0,0,0,0,0,0,0,0,0,0,0
0,0,0,0,0,0,0,0,0,0,0,0,0,0,0,0,0,0,0
:endlayer
layer: 10
0,0,0,0,0,0,0,0,0,0,0,0,0,0,0,0,0,0,0
0,0,0,0,0,0,0,0,0,0,0,0,0,0,0,0,0,0,0
0,0,2,2,2,2,2,2,2,2,0,0,0,0,0,0,0,0,0
0,0,2,25,25,25,25,25,25,2,2,2,2,2,2,2,0,0,0
0,0,2,25,0,0,0,0,0,2,26,0,2,2,2,2,0,0,0
0,0,2,25,0,0,0,0,0,2,0,0,0,0,6,2,0,0,0
0,0,2,25,0,0,0,0,0,27,0,0,0,0,0,2,0,0,0
0,0,2,25,0,0,0,0,0,2,0,0,0,0,0,2,0,0,0
0,0,2,25,0,0,0,0,0,2,0,0,25,0,0,2,0,0,0
0,0,2,25,25,25,25,25,25,2,2,2,2,2,2,2,0,0,0
0,0,2,2,2,2,2,2,2,2,0,0,0,0,0,0,0,0,0
0,0,0,0,0,0,0,0,0,0,0,0,0,0,0,0,0,0,0
0,0,0,0,0,0,0,0,0,0,0,0,0,0,0,0,0,0,0
:endlayer
layer: 11
0,0,0,0,0,0,0,0,0,0,0,0,0,0,0,0,0,0,0
0,0,0,0,0,0,0,0,0,0,0,0,0,0,0,0,0,0,0
0,0,2,0,25,0,25,0,25,2,0,0,0,0,0,0,0,0,0
0,0,0,0,0,0,0,0,0,2,2,0,2,2,2,2,0,0,0
0,0,25,0,0,0,0,0,0,2,0,0,2,17,0,2,0,0,0
0,0,0,0,0,0,0,0,0,2,0,0,0,0,0,2,0,0,0
0,0,25,0,0,0,0,0,0,28,0,0,0,0,0,0,0,0,0
0,0,0,0,0,0,0,0,0,2,0,0,0,0,0,2,0,0,0
0,0,25,0,0,0,0,0,0,2,0,0,0,0,0,2,0,0,0
0,0,0,0,0,0,0,0,0,2,2,2,0,2,2,2,0,0,0
0,0,2,0,25,0,25,0,25,2,0,0,0,0,0,0,0,0,0
0,0,0,0,0,0,0,0,0,0,0,0,0,0,0,0,0,0,0
0,0,0,0,0,0,0,0,0,0,0,0,0,0,0,0,0,0,0
:endlayer
layer: 12
0,0,0,0,0,0,0,0,0,0,0,0,0,0,0,0,0,0,0
0,0,0,0,0,0,0,0,0,0,0,0,0,0,0,0,0,0,0
0,0,15,0,0,0,0,0,0,15,0,0,0,0,0,0,0,0,0
0,0,0,0,0,0,0,0,0,2,2,2,2,2,2,2,0,0,0
0,0,0,0,0,0,0,0,0,2,2,2,17,0,0,2,0,0,0
0,0,0,0,0,0,0,0,0,2,0,0,0,0,0,2,0,0,0
0,0,0,0,0,0,0,0,5,2,0,0,0,0,5,2,0,0,0
0,0,0,0,0,0,0,0,0,2,0,0,0,0,0,2,0,0,0
0,0,0,0,0,0,0,0,0,2,0,0,21,0,0,2,0,0,0
0,0,0,0,0,0,0,0,0,2,2,2,2,2,2,2,0,0,0
0,0,15,0,0,0,0,0,0,15,0,0,0,0,0,0,0,0,0
0,0,0,0,0,0,0,0,0,0,0,0,0,0,0,0,0,0,0
0,0,0,0,0,0,0,0,0,0,0,0,0,0,0,0,0,0,0
:endlayer
layer: 13
0,0,0,0,0,0,0,0,0,0,0,0,0,0,0,0,0,0,0
0,0,0,0,0,0,0,0,0,0,0,0,0,0,0,0,0,0,0
0,0,0,0,0,0,0,0,0,0,0,0,0,0,0,0,0,0,0
0,0,0,0,0,0,0,0,0,2,2,2,2,2,2,2,0,0,0
0,0,0,0,0,0,0,0,0,2,2,17,0,0,0,2,0,0,0
0,0,0,0,0,0,0,0,0,2,2,2,2,2,22,2,0,0,0
0,0,0,0,0,0,0,0,0,2,2,2,2,2,2,2,0,0,0
0,0,0,0,0,0,0,0,0,2,2,2,2,2,2,2,0,0,0
0,0,0,0,0,0,0,0,0,2,2,2,2,2,2,2,0,0,0
0,0,0,0,0,0,0,0,0,2,2,2,2,2,2,2,0,0,0
0,0,0,0,0,0,0,0,0,0,0,0,0,0,0,0,0,0,0
0,0,0,0,0,0,0,0,0,0,0,0,0,0,0,0,0,0,0
0,0,0,0,0,0,0,0,0,0,0,0,0,0,0,0,0,0,0
:endlayer
layer: 14
0,0,0,0,0,0,0,0,0,0,0,0,0,0,0,0,0,0,0
0,0,0,0,0,0,0,0,0,0,0,0,0,0,0,0,0,0,0
0,0,0,0,0,0,0,0,0,0,0,0,0,0,0,0,0,0,0
0,0,0,0,0,0,0,0,0,2,2,2,2,2,2,2,0,0,0
0,0,0,0,0,0,0,0,0,2,0,0,0,0,0,2,0,0,0
0,0,0,0,0,0,0,0,0,2,0,0,0,0,0,2,0,0,0
0,0,0,0,0,0,0,0,0,2,9,0,0,0,0,2,0,0,0
0,0,0,0,0,0,0,0,0,2,2,0,0,0,0,2,0,0,0
0,0,0,0,0,0,0,0,0,2,2,2,0,0,29,2,0,0,0
0,0,0,0,0,0,0,0,0,2,2,2,2,2,2,2,0,0,0
0,0,0,0,0,0,0,0,0,0,0,0,0,0,0,0,0,0,0
0,0,0,0,0,0,0,0,0,0,0,0,0,0,0,0,0,0,0
0,0,0,0,0,0,0,0,0,0,0,0,0,0,0,0,0,0,0
:endlayer
layer: 15
0,0,0,0,0,0,0,0,0,0,0,0,0,0,0,0,0,0,0
0,0,0,0,0,0,0,0,0,0,0,0,0,0,0,0,0,0,0
0,0,0,0,0,0,0,0,0,0,0,0,0,0,0,0,0,0,0
0,0,0,0,0,0,0,0,0,2,2,2,0,2,2,2,0,0,0
0,0,0,0,0,0,0,0,0,2,0,0,0,0,0,2,0,0,0
0,0,0,0,0,0,0,0,0,2,0,0,0,0,0,2,0,0,0
0,0,0,0,0,0,0,0,0,0,0,0,0,0,0,0,0,0,0
0,0,0,0,0,0,0,0,0,2,9,0,0,0,0,2,0,0,0
0,0,0,0,0,0,0,0,0,2,2,2,0,0,0,2,0,0,0
0,0,0,0,0,0,0,0,0,2,2,2,0,2,2,2,0,0,0
0,0,0,0,0,0,0,0,0,0,0,0,0,0,0,0,0,0,0
0,0,0,0,0,0,0,0,0,0,0,0,0,0,0,0,0,0,0
0,0,0,0,0,0,0,0,0,0,0,0,0,0,0,0,0,0,0
:endlayer
layer: 16
0,0,0,0,0,0,0,0,0,0,0,0,0,0,0,0,0,0,0
0,0,0,0,0,0,0,0,0,0,0,0,0,0,0,0,0,0,0
0,0,0,0,0,0,0,0,24,22,22,22,22,22,22,22,13,0,0
0,0,0,0,0,0,0,0,24,2,2,2,2,2,2,2,13,0,0
0,0,0,0,0,0,0,0,24,2,0,0,7,0,0,2,13,0,0
0,0,0,0,0,0,0,0,24,2,0,0,0,0,0,2,13,0,0
0,0,0,0,0,0,0,0,24,2,0,0,0,0,0,2,13,0,0
0,0,0,0,0,0,0,0,24,2,0,0,0,0,0,2,13,0,0
0,0,0,0,0,0,0,0,24,2,0,3,21,0,0,2,13,0,0
0,0,0,0,0,0,0,0,24,2,2,2,2,2,2,2,13,0,0
0,0,0,0,0,0,0,0,24,23,23,23,23,23,23,23,13,0,0
0,0,0,0,0,0,0,0,0,0,0,0,0,0,0,0,0,0,0
0,0,0,0,0,0,0,0,0,0,0,0,0,0,0,0,0,0,0
:endlayer
layer: 17
0,0,0,0,0,0,0,0,0,0,0,0,0,0,0,0,0,0,0
0,0,0,0,0,0,0,0,0,0,0,0,0,0,0,0,0,0,0
0,0,0,0,0,0,0,0,2,2,2,2,2,2,2,2,2,0,0
0,0,0,0,0,0,0,0,2,2,2,2,2,2,2,2,2,0,0
0,0,0,0,0,0,0,0,2,2,2,2,2,2,2,2,2,0,0
0,0,0,0,0,0,0,0,2,2,2,2,2,2,2,2,2,0,0
0,0,0,0,0,0,0,0,2,2,0,2,2,2,2,2,2,0,0
0,0,0,0,0,0,0,0,2,2,0,2,2,2,2,2,2,0,0
0,0,0,0,0,0,0,0,2,2,0,0,3,2,2,2,2,0,0
0,0,0,0,0,0,0,0,2,2,2,2,2,2,2,2,2,0,0
0,0,0,0,0,0,0,0,2,2,2,2,2,2,2,2,2,0,0
0,0,0,0,0,0,0,0,0,0,0,0,0,0,0,0,0,0,0
0,0,0,0,0,0,0,0,0,0,0,0,0,0,0,0,0,0,0
:endlayer
layer: 18
0,0,0,0,0,0,0,0,0,0,0,0,0,0,0,0,0,0,0
0,0,0,0,0,0,0,0,0,0,0,0,0,0,0,0,0,0,0
0,0,0,0,0,0,0,0,2,2,2,2,2,2,2,2,2,0,0
0,0,0,0,0,0,0,0,2,25,25,25,25,25,25,25,2,0,0
0,0,0,0,0,0,0,0,2,25,0,0,0,0,0,25,2,0,0
0,0,0,0,0,0,0,0,2,25,0,0,0,0,0,25,2,0,0
0,0,0,0,0,0,0,0,2,25,0,0,0,0,0,25,2,0,0
0,0,0,0,0,0,0,0,2,25,0,0,0,0,0,25,2,0,0
0,0,0,0,0,0,0,0,2,25,0,0,0,0,0,25,2,0,0
0,0,0,0,0,0,0,0,2,25,25,25,25,25,25,25,2,0,0
0,0,0,0,0,0,0,0,2,2,2,2,2,2,2,2,2,0,0
0,0,0,0,0,0,0,0,0,0,0,0,0,0,0,0,0,0,0
0,0,0,0,0,0,0,0,0,0,0,0,0,0,0,0,0,0,0
:endlayer
layer: 19
0,0,0,0,0,0,0,0,0,0,0,0,0,0,0,0,0,0,0
0,0,0,0,0,0,0,0,0,0,0,0,0,0,0,0,0,0,0
0,0,0,0,0,0,0,0,2,0,2,0,2,0,2,0,2,0,0
0,0,0,0,0,0,0,0,0,0,0,0,0,0,0,0,0,0,0
0,0,0,0,0,0,0,0,2,0,0,0,0,0,0,0,2,0,0
0,0,0,0,0,0,0,0,0,0,0,0,0,0,0,0,0,0,0
0,0,0,0,0,0,0,0,2,0,0,0,0,0,0,0,2,0,0
0,0,0,0,0,0,0,0,0,0,0,0,0,0,0,0,0,0,0
0,0,0,0,0,0,0,0,2,0,0,0,0,0,0,0,2,0,0
0,0,0,0,0,0,0,0,0,0,0,0,0,0,0,0,0,0,0
0,0,0,0,0,0,0,0,2,0,2,0,2,0,2,0,2,0,0
0,0,0,0,0,0,0,0,0,0,0,0,0,0,0,0,0,0,0
0,0,0,0,0,0,0,0,0,0,0,0,0,0,0,0,0,0,0
:endlayer
layer: 20
0,0,0,0,0,0,0,0,0,0,0,0,0,0,0,0,0,0,0
0,0,0,0,0,0,0,0,0,0,0,0,0,0,0,0,0,0,0
0,0,0,0,0,0,0,0,2,0,2,0,2,0,2,0,2,0,0
0,0,0,0,0,0,0,0,0,0,0,0,0,0,0,0,0,0,0
0,0,0,0,0,0,0,0,2,0,0,0,0,0,0,0,2,0,0
0,0,0,0,0,0,0,0,0,0,0,0,0,0,0,0,0,0,0
0,0,0,0,0,0,0,0,2,0,0,0,0,0,0,0,2,0,0
0,0,0,0,0,0,0,0,0,0,0,0,0,0,0,0,0,0,0
0,0,0,0,0,0,0,0,2,0,0,0,0,0,0,0,2,0,0
0,0,0,0,0,0,0,0,0,0,0,0,0,0,0,0,0,0,0
0,0,0,0,0,0,0,0,2,0,2,0,2,0,2,0,2,0,0
0,0,0,0,0,0,0,0,0,0,0,0,0,0,0,0,0,0,0
0,0,0,0,0,0,0,0,0,0,0,0,0,0,0,0,0,0,0
:endlayer
layer: 21
0,0,0,0,0,0,0,0,0,0,0,0,0,0,0,0,0,0,0
0,0,0,0,0,0,0,0,0,0,0,0,0,0,0,0,0,0,0
0,0,0,0,0,0,0,0,2,0,2,0,2,0,2,0,2,0,0
0,0,0,0,0,0,0,0,0,0,0,0,0,0,0,0,0,0,0
0,0,0,0,0,0,0,0,2,0,0,0,0,0,0,0,2,0,0
0,0,0,0,0,0,0,0,0,0,0,0,0,0,0,0,0,0,0
0,0,0,0,0,0,0,0,2,0,0,0,0,0,0,0,2,0,0
0,0,0,0,0,0,0,0,0,0,0,0,0,0,0,0,0,0,0
0,0,0,0,0,0,0,0,2,0,0,0,0,0,0,0,2,0,0
0,0,0,0,0,0,0,0,0,0,0,0,0,0,0,0,0,0,0
0,0,0,0,0,0,0,0,2,0,2,0,2,0,2,0,2,0,0
0,0,0,0,0,0,0,0,0,0,0,0,0,0,0,0,0,0,0
0,0,0,0,0,0,0,0,0,0,0,0,0,0,0,0,0,0,0
:endlayer
layer: 22
0,0,0,0,0,0,0,0,0,0,0,0,0,0,0,0,0,0,0
0,0,0,0,0,0,0,33,30,30,30,30,30,30,30,30,30,30,0
0,0,0,0,0,0,0,33,2,2,2,2,2,2,2,2,2,31,0
0,0,0,0,0,0,0,33,2,7,0,0,0,0,0,7,2,31,0
0,0,0,0,0,0,0,33,2,0,0,0,0,0,0,0,2,31,0
0,0,0,0,0,0,0,33,2,0,0,0,0,0,0,0,2,31,0
0,0,0,0,0,0,0,33,2,0,0,0,0,0,0,0,2,31,0
0,0,0,0,0,0,0,33,2,0,0,0,0,0,0,0,2,31,0
0,0,0,0,0,0,0,33,2,0,0,0,0,0,0,0,2,31,0
0,0,0,0,0,0,0,33,2,21,0,0,0,0,0,21,2,31,0
0,0,0,0,0,0,0,33,2,2,2,2,2,2,2,2,2,31,0
0,0,0,0,0,0,0,33,32,32,32,32,32,32,32,32,32,31,0
0,0,0,0,0,0,0,0,0,0,0,0,0,0,0,0,0,0,0
:endlayer
layer: 23
0,0,0,0,0,0,0,0,0,0,0,0,0,0,0,0,0,0,0
0,0,0,0,0,0,0,0,0,0,0,0,0,0,0,0,0,0,0
0,0,0,0,0,0,0,0,33,30,30,30,30,30,30,30,31,0,0
0,0,0,0,0,0,0,0,33,34,0,0,0,0,0,34,31,0,0
0,0,0,0,0,0,0,0,33,0,0,0,0,0,0,0,31,0,0
0,0,0,0,0,0,0,0,33,0,0,0,0,0,0,0,31,0,0
0,0,0,0,0,0,0,0,33,0,0,0,0,0,0,0,31,0,0
0,0,0,0,0,0,0,0,33,0,0,0,0,0,0,0,31,0,0
0,0,0,0,0,0,0,0,33,0,0,0,0,0,0,0,31,0,0
0,0,0,0,0,0,0,0,33,34,0,0,0,0,0,34,31,0,0
0,0,0,0,0,0,0,0,33,32,32,32,32,32,32,32,32,0,0
0,0,0,0,0,0,0,0,0,0,0,0,0,0,0,0,0,0,0
0,0,0,0,0,0,0,0,0,0,0,0,0,0,0,0,0,0,0
:endlayer
layer: 24
0,0,0,0,0,0,0,0,0,0,0,0,0,0,0,0,0,0,0
0,0,0,0,0,0,0,0,0,0,0,0,0,0,0,0,0,0,0
0,0,0,0,0,0,0,0,0,0,0,0,0,0,0,0,0,0,0
0,0,0,0,0,0,0,0,0,33,30,30,30,30,30,31,0,0,0
0,0,0,0,0,0,0,0,0,33,34,0,0,0,34,31,0,0,0
0,0,0,0,0,0,0,0,0,33,0,0,0,0,0,31,0,0,0
0,0,0,0,0,0,0,0,0,33,0,0,0,0,0,31,0,0,0
0,0,0,0,0,0,0,0,0,33,0,0,0,0,0,31,0,0,0
0,0,0,0,0,0,0,0,0,33,34,0,0,0,34,31,0,0,0
0,0,0,0,0,0,0,0,0,33,32,32,32,32,32,32,0,0,0
0,0,0,0,0,0,0,0,0,0,0,0,0,0,0,0,0,0,0
0,0,0,0,0,0,0,0,0,0,0,0,0,0,0,0,0,0,0
0,0,0,0,0,0,0,0,0,0,0,0,0,0,0,0,0,0,0
:endlayer
layer: 25
0,0,0,0,0,0,0,0,0,0,0,0,0,0,0,0,0,0,0
0,0,0,0,0,0,0,0,0,0,0,0,0,0,0,0,0,0,0
0,0,0,0,0,0,0,0,0,0,0,0,0,0,0,0,0,0,0
0,0,0,0,0,0,0,0,0,0,0,0,0,0,0,0,0,0,0
0,0,0,0,0,0,0,0,0,0,30,30,30,30,31,0,0,0,0
0,0,0,0,0,0,0,0,0,0,33,34,0,34,31,0,0,0,0
0,0,0,0,0,0,0,0,0,0,33,0,0,0,31,0,0,0,0
0,0,0,0,0,0,0,0,0,0,33,34,0,34,31,0,0,0,0
0,0,0,0,0,0,0,0,0,0,33,32,32,32,31,0,0,0,0
0,0,0,0,0,0,0,0,0,0,0,0,0,0,0,0,0,0,0
0,0,0,0,0,0,0,0,0,0,0,0,0,0,0,0,0,0,0
0,0,0,0,0,0,0,0,0,0,0,0,0,0,0,0,0,0,0
0,0,0,0,0,0,0,0,0,0,0,0,0,0,0,0,0,0,0
:endlayer
layer: 26
0,0,0,0,0,0,0,0,0,0,0,0,0,0,0,0,0,0,0
0,0,0,0,0,0,0,0,0,0,0,0,0,0,0,0,0,0,0
0,0,0,0,0,0,0,0,0,0,0,0,0,0,0,0,0,0,0
0,0,0,0,0,0,0,0,0,0,0,0,0,0,0,0,0,0,0
0,0,0,0,0,0,0,0,0,0,0,0,0,0,0,0,0,0,0
0,0,0,0,0,0,0,0,0,0,0,30,30,31,0,0,0,0,0
0,0,0,0,0,0,0,0,0,0,0,33,34,31,0,0,0,0,0
0,0,0,0,0,0,0,0,0,0,0,32,32,32,0,0,0,0,0
0,0,0,0,0,0,0,0,0,0,0,0,0,0,0,0,0,0,0
0,0,0,0,0,0,0,0,0,0,0,0,0,0,0,0,0,0,0
0,0,0,0,0,0,0,0,0,0,0,0,0,0,0,0,0,0,0
0,0,0,0,0,0,0,0,0,0,0,0,0,0,0,0,0,0,0
0,0,0,0,0,0,0,0,0,0,0,0,0,0,0,0,0,0,0
:endlayer
layer: 27
0,0,0,0,0,0,0,0,0,0,0,0,0,0,0,0,0,0,0
0,0,0,0,0,0,0,0,0,0,0,0,0,0,0,0,0,0,0
0,0,0,0,0,0,0,0,0,0,0,0,0,0,0,0,0,0,0
0,0,0,0,0,0,0,0,0,0,0,0,0,0,0,0,0,0,0
0,0,0,0,0,0,0,0,0,0,0,0,0,0,0,0,0,0,0
0,0,0,0,0,0,0,0,0,0,0,0,0,0,0,0,0,0,0
0,0,0,0,0,0,0,0,0,0,0,0,35,0,0,0,0,0,0
0,0,0,0,0,0,0,0,0,0,0,0,0,0,0,0,0,0,0
0,0,0,0,0,0,0,0,0,0,0,0,0,0,0,0,0,0,0
0,0,0,0,0,0,0,0,0,0,0,0,0,0,0,0,0,0,0
0,0,0,0,0,0,0,0,0,0,0,0,0,0,0,0,0,0,0
0,0,0,0,0,0,0,0,0,0,0,0,0,0,0,0,0,0,0
0,0,0,0,0,0,0,0,0,0,0,0,0,0,0,0,0,0,0
:endlayer
layer: 28
0,0,0,0,0,0,0,0,0,0,0,0,0,0,0,0,0,0,0
0,0,0,0,0,0,0,0,0,0,0,0,0,0,0,0,0,0,0
0,0,0,0,0,0,0,0,0,0,0,0,0,0,0,0,0,0,0
0,0,0,0,0,0,0,0,0,0,0,0,0,0,0,0,0,0,0
0,0,0,0,0,0,0,0,0,0,0,0,0,0,0,0,0,0,0
0,0,0,0,0,0,0,0,0,0,0,0,0,0,0,0,0,0,0
0,0,0,0,0,0,0,0,0,0,0,0,35,0,0,0,0,0,0
0,0,0,0,0,0,0,0,0,0,0,0,0,0,0,0,0,0,0
0,0,0,0,0,0,0,0,0,0,0,0,0,0,0,0,0,0,0
0,0,0,0,0,0,0,0,0,0,0,0,0,0,0,0,0,0,0
0,0,0,0,0,0,0,0,0,0,0,0,0,0,0,0,0,0,0
0,0,0,0,0,0,0,0,0,0,0,0,0,0,0,0,0,0,0
0,0,0,0,0,0,0,0,0,0,0,0,0,0,0,0,0,0,0
:endlayer
layer: 29
0,0,0,0,0,0,0,0,0,0,0,0,0,0,0,0,0,0,0
0,0,0,0,0,0,0,0,0,0,0,0,0,0,0,0,0,0,0
0,0,0,0,0,0,0,0,0,0,0,0,0,0,0,0,0,0,0
0,0,0,0,0,0,0,0,0,0,0,0,0,0,0,0,0,0,0
0,0,0,0,0,0,0,0,0,0,0,0,0,0,0,0,0,0,0
0,0,0,0,0,0,0,0,0,0,0,0,0,0,0,0,0,0,0
0,0,0,0,0,0,0,0,0,0,0,0,35,0,0,0,0,0,0
0,0,0,0,0,0,0,0,0,0,0,0,0,0,0,0,0,0,0
0,0,0,0,0,0,0,0,0,0,0,0,0,0,0,0,0,0,0
0,0,0,0,0,0,0,0,0,0,0,0,0,0,0,0,0,0,0
0,0,0,0,0,0,0,0,0,0,0,0,0,0,0,0,0,0,0
0,0,0,0,0,0,0,0,0,0,0,0,0,0,0,0,0,0,0
0,0,0,0,0,0,0,0,0,0,0,0,0,0,0,0,0,0,0
:endlayer
layer: 30
0,0,0,0,0,0,0,0,0,0,0,0,0,0,0,0,0,0,0
0,0,0,0,0,0,0,0,0,0,0,0,0,0,0,0,0,0,0
0,0,0,0,0,0,0,0,0,0,0,0,0,0,0,0,0,0,0
0,0,0,0,0,0,0,0,0,0,0,0,0,0,0,0,0,0,0
0,0,0,0,0,0,0,0,0,0,0,0,0,0,0,0,0,0,0
0,0,0,0,0,0,0,0,0,0,0,0,0,0,0,0,0,0,0
0,0,0,0,0,0,0,0,0,0,0,0,15,0,0,0,0,0,0
0,0,0,0,0,0,0,0,0,0,0,0,0,0,0,0,0,0,0
0,0,0,0,0,0,0,0,0,0,0,0,0,0,0,0,0,0,0
0,0,0,0,0,0,0,0,0,0,0,0,0,0,0,0,0,0,0
0,0,0,0,0,0,0,0,0,0,0,0,0,0,0,0,0,0,0
0,0,0,0,0,0,0,0,0,0,0,0,0,0,0,0,0,0,0
0,0,0,0,0,0,0,0,0,0,0,0,0,0,0,0,0,0,0
:endlayer
layer: 31
0,0,0,0,0,0,0,0,0,0,0,0,0,0,0,0,0,0,0
0,0,0,0,0,0,0,0,0,0,0,0,0,0,0,0,0,0,0
0,0,0,0,0,0,0,0,0,0,0,0,0,0,0,0,0,0,0
0,0,0,0,0,0,0,0,0,0,0,0,0,0,0,0,0,0,0
0,0,0,0,0,0,0,0,0,0,0,0,0,0,0,0,0,0,0
0,0,0,0,0,0,0,0,0,0,0,0,0,0,0,0,0,0,0
0,0,0,0,0,0,0,0,0,0,0,0,0,0,0,0,0,0,0
0,0,0,0,0,0,0,0,0,0,0,0,0,0,0,0,0,0,0
0,0,0,0,0,0,0,0,0,0,0,0,0,0,0,0,0,0,0
0,0,0,0,0,0,0,0,0,0,0,0,0,0,0,0,0,0,0
0,0,0,0,0,0,0,0,0,0,0,0,0,0,0,0,0,0,0
0,0,0,0,0,0,0,0,0,0,0,0,0,0,0,0,0,0,0
0,0,0,0,0,0,0,0,0,0,0,0,0,0,0,0,0,0,0
:endlayer
layer: 32
0,0,0,0,0,0,0,0,0,0,0,0,0,0,0,0,0,0,0
0,0,0,0,0,0,0,0,0,0,0,0,0,0,0,0,0,0,0
0,0,0,0,0,0,0,0,0,0,0,0,0,0,0,0,0,0,0
0,0,0,0,0,0,0,0,0,0,0,0,0,0,0,0,0,0,0
0,0,0,0,0,0,0,0,0,0,0,0,0,0,0,0,0,0,0
0,0,0,0,0,0,0,0,0,0,0,0,0,0,0,0,0,0,0
0,0,0,0,0,0,0,0,0,0,0,0,0,0,0,0,0,0,0
0,0,0,0,0,0,0,0,0,0,0,0,0,0,0,0,0,0,0
0,0,0,0,0,0,0,0,0,0,0,0,0,0,0,0,0,0,0
0,0,0,0,0,0,0,0,0,0,0,0,0,0,0,0,0,0,0
0,0,0,0,0,0,0,0,0,0,0,0,0,0,0,0,0,0,0
0,0,0,0,0,0,0,0,0,0,0,0,0,0,0,0,0,0,0
0,0,0,0,0,0,0,0,0,0,0,0,0,0,0,0,0,0,0
:endlayer
layer: 33
0,0,0,0,0,0,0,0,0,0,0,0,0,0,0,0,0,0,0
0,0,0,0,0,0,0,0,0,0,0,0,0,0,0,0,0,0,0
0,0,0,0,0,0,0,0,0,0,0,0,0,0,0,0,0,0,0
0,0,0,0,0,0,0,0,0,0,0,0,0,0,0,0,0,0,0
0,0,0,0,0,0,0,0,0,0,0,0,0,0,0,0,0,0,0
0,0,0,0,0,0,0,0,0,0,0,0,0,0,0,0,0,0,0
0,0,0,0,0,0,0,0,0,0,0,0,0,0,0,0,0,0,0
0,0,0,0,0,0,0,0,0,0,0,0,0,0,0,0,0,0,0
0,0,0,0,0,0,0,0,0,0,0,0,0,0,0,0,0,0,0
0,0,0,0,0,0,0,0,0,0,0,0,0,0,0,0,0,0,0
0,0,0,0,0,0,0,0,0,0,0,0,0,0,0,0,0,0,0
0,0,0,0,0,0,0,0,0,0,0,0,0,0,0,0,0,0,0
0,0,0,0,0,0,0,0,0,0,0,0,0,0,0,0,0,0,0
:endlayer
layer: 34
0,0,0,0,0,0,0,0,0,0,0,0,0,0,0,0,0,0,0
0,0,0,0,0,0,0,0,0,0,0,0,0,0,0,0,0,0,0
0,0,0,0,0,0,0,0,0,0,0,0,0,0,0,0,0,0,0
0,0,0,0,0,0,0,0,0,0,0,0,0,0,0,0,0,0,0
0,0,0,0,0,0,0,0,0,0,0,0,0,0,0,0,0,0,0
0,0,0,0,0,0,0,0,0,0,0,0,0,0,0,0,0,0,0
0,0,0,0,0,0,0,0,0,0,0,0,0,0,0,0,0,0,0
0,0,0,0,0,0,0,0,0,0,0,0,0,0,0,0,0,0,0
0,0,0,0,0,0,0,0,0,0,0,0,0,0,0,0,0,0,0
0,0,0,0,0,0,0,0,0,0,0,0,0,0,0,0,0,0,0
0,0,0,0,0,0,0,0,0,0,0,0,0,0,0,0,0,0,0
0,0,0,0,0,0,0,0,0,0,0,0,0,0,0,0,0,0,0
0,0,0,0,0,0,0,0,0,0,0,0,0,0,0,0,0,0,0
:endlayer
layer: 35
0,0,0,0,0,0,0,0,0,0,0,0,0,0,0,0,0,0,0
0,0,0,0,0,0,0,0,0,0,0,0,0,0,0,0,0,0,0
0,0,0,0,0,0,0,0,0,0,0,0,0,0,0,0,0,0,0
0,0,0,0,0,0,0,0,0,0,0,0,0,0,0,0,0,0,0
0,0,0,0,0,0,0,0,0,0,0,0,0,0,0,0,0,0,0
0,0,0,0,0,0,0,0,0,0,0,0,0,0,0,0,0,0,0
0,0,0,0,0,0,0,0,0,0,0,0,0,0,0,0,0,0,0
0,0,0,0,0,0,0,0,0,0,0,0,0,0,0,0,0,0,0
0,0,0,0,0,0,0,0,0,0,0,0,0,0,0,0,0,0,0
0,0,0,0,0,0,0,0,0,0,0,0,0,0,0,0,0,0,0
0,0,0,0,0,0,0,0,0,0,0,0,0,0,0,0,0,0,0
0,0,0,0,0,0,0,0,0,0,0,0,0,0,0,0,0,0,0
0,0,0,0,0,0,0,0,0,0,0,0,0,0,0,0,0,0,0
:endlayer
layer: 36
0,0,0,0,0,0,0,0,0,0,0,0,0,0,0,0,0,0,0
0,0,0,0,0,0,0,0,0,0,0,0,0,0,0,0,0,0,0
0,0,0,0,0,0,0,0,0,0,0,0,0,0,0,0,0,0,0
0,0,0,0,0,0,0,0,0,0,0,0,0,0,0,0,0,0,0
0,0,0,0,0,0,0,0,0,0,0,0,0,0,0,0,0,0,0
0,0,0,0,0,0,0,0,0,0,0,0,0,0,0,0,0,0,0
0,0,0,0,0,0,0,0,0,0,0,0,0,0,0,0,0,0,0
0,0,0,0,0,0,0,0,0,0,0,0,0,0,0,0,0,0,0
0,0,0,0,0,0,0,0,0,0,0,0,0,0,0,0,0,0,0
0,0,0,0,0,0,0,0,0,0,0,0,0,0,0,0,0,0,0
0,0,0,0,0,0,0,0,0,0,0,0,0,0,0,0,0,0,0
0,0,0,0,0,0,0,0,0,0,0,0,0,0,0,0,0,0,0
0,0,0,0,0,0,0,0,0,0,0,0,0,0,0,0,0,0,0
:endlayer
layer: 37
0,0,0,0,0,0,0,0,0,0,0,0,0,0,0,0,0,0,0
0,0,0,0,0,0,0,0,0,0,0,0,0,0,0,0,0,0,0
0,0,0,0,0,0,0,0,0,0,0,0,0,0,0,0,0,0,0
0,0,0,0,0,0,0,0,0,0,0,0,0,0,0,0,0,0,0
0,0,0,0,0,0,0,0,0,0,0,0,0,0,0,0,0,0,0
0,0,0,0,0,0,0,0,0,0,0,0,0,0,0,0,0,0,0
0,0,0,0,0,0,0,0,0,0,0,0,0,0,0,0,0,0,0
0,0,0,0,0,0,0,0,0,0,0,0,0,0,0,0,0,0,0
0,0,0,0,0,0,0,0,0,0,0,0,0,0,0,0,0,0,0
0,0,0,0,0,0,0,0,0,0,0,0,0,0,0,0,0,0,0
0,0,0,0,0,0,0,0,0,0,0,0,0,0,0,0,0,0,0
0,0,0,0,0,0,0,0,0,0,0,0,0,0,0,0,0,0,0
0,0,0,0,0,0,0,0,0,0,0,0,0,0,0,0,0,0,0
:endlayer
layer: 38
0,0,0,0,0,0,0,0,0,0,0,0,0,0,0,0,0,0,0
0,0,0,0,0,0,0,0,0,0,0,0,0,0,0,0,0,0,0
0,0,0,0,0,0,0,0,0,0,0,0,0,0,0,0,0,0,0
0,0,0,0,0,0,0,0,0,0,0,0,0,0,0,0,0,0,0
0,0,0,0,0,0,0,0,0,0,0,0,0,0,0,0,0,0,0
0,0,0,0,0,0,0,0,0,0,0,0,0,0,0,0,0,0,0
0,0,0,0,0,0,0,0,0,0,0,0,0,0,0,0,0,0,0
0,0,0,0,0,0,0,0,0,0,0,0,0,0,0,0,0,0,0
0,0,0,0,0,0,0,0,0,0,0,0,0,0,0,0,0,0,0
0,0,0,0,0,0,0,0,0,0,0,0,0,0,0,0,0,0,0
0,0,0,0,0,0,0,0,0,0,0,0,0,0,0,0,0,0,0
0,0,0,0,0,0,0,0,0,0,0,0,0,0,0,0,0,0,0
0,0,0,0,0,0,0,0,0,0,0,0,0,0,0,0,0,0,0
:endlayer
layer: 39
0,0,0,0,0,0,0,0,0,0,0,0,0,0,0,0,0,0,0
0,0,0,0,0,0,0,0,0,0,0,0,0,0,0,0,0,0,0
0,0,0,0,0,0,0,0,0,0,0,0,0,0,0,0,0,0,0
0,0,0,0,0,0,0,0,0,0,0,0,0,0,0,0,0,0,0
0,0,0,0,0,0,0,0,0,0,0,0,0,0,0,0,0,0,0
0,0,0,0,0,0,0,0,0,0,0,0,0,0,0,0,0,0,0
0,0,0,0,0,0,0,0,0,0,0,0,0,0,0,0,0,0,0
0,0,0,0,0,0,0,0,0,0,0,0,0,0,0,0,0,0,0
0,0,0,0,0,0,0,0,0,0,0,0,0,0,0,0,0,0,0
0,0,0,0,0,0,0,0,0,0,0,0,0,0,0,0,0,0,0
0,0,0,0,0,0,0,0,0,0,0,0,0,0,0,0,0,0,0
0,0,0,0,0,0,0,0,0,0,0,0,0,0,0,0,0,0,0
0,0,0,0,0,0,0,0,0,0,0,0,0,0,0,0,0,0,0
:endlayer
layer: 40
0,0,0,0,0,0,0,0,0,0,0,0,0,0,0,0,0,0,0
0,0,0,0,0,0,0,0,0,0,0,0,0,0,0,0,0,0,0
0,0,0,0,0,0,0,0,0,0,0,0,0,0,0,0,0,0,0
0,0,0,0,0,0,0,0,0,0,0,0,0,0,0,0,0,0,0
0,0,0,0,0,0,0,0,0,0,0,0,0,0,0,0,0,0,0
0,0,0,0,0,0,0,0,0,0,0,0,0,0,0,0,0,0,0
0,0,0,0,0,0,0,0,0,0,0,0,0,0,0,0,0,0,0
0,0,0,0,0,0,0,0,0,0,0,0,0,0,0,0,0,0,0
0,0,0,0,0,0,0,0,0,0,0,0,0,0,0,0,0,0,0
0,0,0,0,0,0,0,0,0,0,0,0,0,0,0,0,0,0,0
0,0,0,0,0,0,0,0,0,0,0,0,0,0,0,0,0,0,0
0,0,0,0,0,0,0,0,0,0,0,0,0,0,0,0,0,0,0
0,0,0,0,0,0,0,0,0,0,0,0,0,0,0,0,0,0,0
:endlayer
layer: 41
0,0,0,0,0,0,0,0,0,0,0,0,0,0,0,0,0,0,0
0,0,0,0,0,0,0,0,0,0,0,0,0,0,0,0,0,0,0
0,0,0,0,0,0,0,0,0,0,0,0,0,0,0,0,0,0,0
0,0,0,0,0,0,0,0,0,0,0,0,0,0,0,0,0,0,0
0,0,0,0,0,0,0,0,0,0,0,0,0,0,0,0,0,0,0
0,0,0,0,0,0,0,0,0,0,0,0,0,0,0,0,0,0,0
0,0,0,0,0,0,0,0,0,0,0,0,0,0,0,0,0,0,0
0,0,0,0,0,0,0,0,0,0,0,0,0,0,0,0,0,0,0
0,0,0,0,0,0,0,0,0,0,0,0,0,0,0,0,0,0,0
0,0,0,0,0,0,0,0,0,0,0,0,0,0,0,0,0,0,0
0,0,0,0,0,0,0,0,0,0,0,0,0,0,0,0,0,0,0
0,0,0,0,0,0,0,0,0,0,0,0,0,0,0,0,0,0,0
0,0,0,0,0,0,0,0,0,0,0,0,0,0,0,0,0,0,0
:endlayer
layer: 42
0,0,0,0,0,0,0,0,0,0,0,0,0,0,0,0,0,0,0
0,0,0,0,0,0,0,0,0,0,0,0,0,0,0,0,0,0,0
0,0,0,0,0,0,0,0,0,0,0,0,0,0,0,0,0,0,0
0,0,0,0,0,0,0,0,0,0,0,0,0,0,0,0,0,0,0
0,0,0,0,0,0,0,0,0,0,0,0,0,0,0,0,0,0,0
0,0,0,0,0,0,0,0,0,0,0,0,0,0,0,0,0,0,0
0,0,0,0,0,0,0,0,0,0,0,0,0,0,0,0,0,0,0
0,0,0,0,0,0,0,0,0,0,0,0,0,0,0,0,0,0,0
0,0,0,0,0,0,0,0,0,0,0,0,0,0,0,0,0,0,0
0,0,0,0,0,0,0,0,0,0,0,0,0,0,0,0,0,0,0
0,0,0,0,0,0,0,0,0,0,0,0,0,0,0,0,0,0,0
0,0,0,0,0,0,0,0,0,0,0,0,0,0,0,0,0,0,0
0,0,0,0,0,0,0,0,0,0,0,0,0,0,0,0,0,0,0
:endlayer
layer: 43
0,0,0,0,0,0,0,0,0,0,0,0,0,0,0,0,0,0,0
0,0,0,0,0,0,0,0,0,0,0,0,0,0,0,0,0,0,0
0,0,0,0,0,0,0,0,0,0,0,0,0,0,0,0,0,0,0
0,0,0,0,0,0,0,0,0,0,0,0,0,0,0,0,0,0,0
0,0,0,0,0,0,0,0,0,0,0,0,0,0,0,0,0,0,0
0,0,0,0,0,0,0,0,0,0,0,0,0,0,0,0,0,0,0
0,0,0,0,0,0,0,0,0,0,0,0,0,0,0,0,0,0,0
0,0,0,0,0,0,0,0,0,0,0,0,0,0,0,0,0,0,0
0,0,0,0,0,0,0,0,0,0,0,0,0,0,0,0,0,0,0
0,0,0,0,0,0,0,0,0,0,0,0,0,0,0,0,0,0,0
0,0,0,0,0,0,0,0,0,0,0,0,0,0,0,0,0,0,0
0,0,0,0,0,0,0,0,0,0,0,0,0,0,0,0,0,0,0
0,0,0,0,0,0,0,0,0,0,0,0,0,0,0,0,0,0,0
:endlayer
layer: 44
0,0,0,0,0,0,0,0,0,0,0,0,0,0,0,0,0,0,0
0,0,0,0,0,0,0,0,0,0,0,0,0,0,0,0,0,0,0
0,0,0,0,0,0,0,0,0,0,0,0,0,0,0,0,0,0,0
0,0,0,0,0,0,0,0,0,0,0,0,0,0,0,0,0,0,0
0,0,0,0,0,0,0,0,0,0,0,0,0,0,0,0,0,0,0
0,0,0,0,0,0,0,0,0,0,0,0,0,0,0,0,0,0,0
0,0,0,0,0,0,0,0,0,0,0,0,0,0,0,0,0,0,0
0,0,0,0,0,0,0,0,0,0,0,0,0,0,0,0,0,0,0
0,0,0,0,0,0,0,0,0,0,0,0,0,0,0,0,0,0,0
0,0,0,0,0,0,0,0,0,0,0,0,0,0,0,0,0,0,0
0,0,0,0,0,0,0,0,0,0,0,0,0,0,0,0,0,0,0
0,0,0,0,0,0,0,0,0,0,0,0,0,0,0,0,0,0,0
0,0,0,0,0,0,0,0,0,0,0,0,0,0,0,0,0,0,0
:endlayer

#### RULES ####
rule:
plugin=vanillaBlocks
number=1
data:
tag:
TAG=10={
TAG=8=blockName{dirt}
TAG=3=meta{0}
TAG=3=buildPass{0}
}
:endtag
:enddata
:endrule

rule:
plugin=vanillaBlocks
number=2
data:
tag:
TAG=10={
TAG=8=blockName{stonebrick}
TAG=3=meta{0}
TAG=3=buildPass{0}
}
:endtag
:enddata
:endrule

rule:
plugin=vanillaBlocks
number=3
data:
tag:
TAG=10={
TAG=8=blockName{stone_brick_stairs}
TAG=3=meta{0}
TAG=3=buildPass{0}
}
:endtag
:enddata
:endrule

rule:
plugin=vanillaBlocks
number=4
data:
tag:
TAG=10={
TAG=8=blockName{grass}
TAG=3=meta{0}
TAG=3=buildPass{0}
}
:endtag
:enddata
:endrule

rule:
plugin=vanillaBlocks
number=5
data:
tag:
TAG=10={
TAG=8=blockName{torch}
TAG=3=meta{2}
TAG=3=buildPass{1}
}
:endtag
:enddata
:endrule

rule:
plugin=vanillaBlocks
number=6
data:
tag:
TAG=10={
TAG=8=blockName{stone_brick_stairs}
TAG=3=meta{3}
TAG=3=buildPass{0}
}
:endtag
:enddata
:endrule

rule:
plugin=vanillaBlocks
number=7
data:
tag:
TAG=10={
TAG=8=blockName{torch}
TAG=3=meta{3}
TAG=3=buildPass{1}
}
:endtag
:enddata
:endrule

rule:
plugin=vanillaBlocks
number=8
data:
tag:
TAG=10={
TAG=8=blockName{torch}
TAG=3=meta{1}
TAG=3=buildPass{1}
}
:endtag
:enddata
:endrule

rule:
plugin=vanillaBlocks
number=9
data:
tag:
TAG=10={
TAG=8=blockName{stone_brick_stairs}
TAG=3=meta{2}
TAG=3=buildPass{0}
}
:endtag
:enddata
:endrule

rule:
plugin=vanillaBlocks
number=10
data:
tag:
TAG=10={
TAG=8=blockName{stone}
TAG=3=meta{0}
TAG=3=buildPass{0}
}
:endtag
:enddata
:endrule

rule:
plugin=vanillaBlocks
number=11
data:
tag:
TAG=10={
TAG=8=blockName{cobblestone}
TAG=3=meta{0}
TAG=3=buildPass{0}
}
:endtag
:enddata
:endrule

rule:
plugin=vanillaInventory
number=12
data:
tag:
TAG=10={
TAG=3=lootLevel{0}
TAG=10=teData{
TAG=9=Items{
}
TAG=8=id{Chest}
}
TAG=8=blockName{chest}
TAG=3=meta{3}
TAG=3=buildPass{0}
}
:endtag
:enddata
:endrule

rule:
plugin=vanillaBlocks
number=13
data:
tag:
TAG=10={
TAG=8=blockName{stone_brick_stairs}
TAG=3=meta{5}
TAG=3=buildPass{0}
}
:endtag
:enddata
:endrule

rule:
plugin=vanillaBlocks
number=14
data:
tag:
TAG=10={
TAG=8=blockName{lever}
TAG=3=meta{1}
TAG=3=buildPass{1}
}
:endtag
:enddata
:endrule

rule:
plugin=vanillaBlocks
number=15
data:
tag:
TAG=10={
TAG=8=blockName{torch}
TAG=3=meta{5}
TAG=3=buildPass{1}
}
:endtag
:enddata
:endrule

rule:
plugin=vanillaBlocks
number=16
data:
tag:
TAG=10={
TAG=8=blockName{stone_button}
TAG=3=meta{2}
TAG=3=buildPass{0}
}
:endtag
:enddata
:endrule

rule:
plugin=vanillaBlocks
number=17
data:
tag:
TAG=10={
TAG=8=blockName{stone_brick_stairs}
TAG=3=meta{1}
TAG=3=buildPass{0}
}
:endtag
:enddata
:endrule

rule:
plugin=vanillaBlocks
number=18
data:
tag:
TAG=10={
TAG=8=blockName{lever}
TAG=3=meta{4}
TAG=3=buildPass{1}
}
:endtag
:enddata
:endrule

rule:
plugin=vanillaBlocks
number=19
data:
tag:
TAG=10={
TAG=8=blockName{lever}
TAG=3=meta{3}
TAG=3=buildPass{1}
}
:endtag
:enddata
:endrule

rule:
plugin=vanillaBlocks
number=20
data:
tag:
TAG=10={
TAG=8=blockName{stone_slab}
TAG=3=meta{13}
TAG=3=buildPass{0}
}
:endtag
:enddata
:endrule

rule:
plugin=vanillaBlocks
number=21
data:
tag:
TAG=10={
TAG=8=blockName{torch}
TAG=3=meta{4}
TAG=3=buildPass{1}
}
:endtag
:enddata
:endrule

rule:
plugin=vanillaBlocks
number=22
data:
tag:
TAG=10={
TAG=8=blockName{stone_brick_stairs}
TAG=3=meta{6}
TAG=3=buildPass{0}
}
:endtag
:enddata
:endrule

rule:
plugin=vanillaBlocks
number=23
data:
tag:
TAG=10={
TAG=8=blockName{stone_brick_stairs}
TAG=3=meta{7}
TAG=3=buildPass{0}
}
:endtag
:enddata
:endrule

rule:
plugin=vanillaBlocks
number=24
data:
tag:
TAG=10={
TAG=8=blockName{stone_brick_stairs}
TAG=3=meta{4}
TAG=3=buildPass{0}
}
:endtag
:enddata
:endrule

rule:
plugin=vanillaBlocks
number=25
data:
tag:
TAG=10={
TAG=8=blockName{stone_slab}
TAG=3=meta{5}
TAG=3=buildPass{0}
}
:endtag
:enddata
:endrule

rule:
plugin=vanillaInventory
number=26
data:
tag:
TAG=10={
TAG=3=lootLevel{0}
TAG=10=teData{
TAG=9=Items{
}
TAG=8=id{Chest}
}
TAG=8=blockName{chest}
TAG=3=meta{3}
TAG=3=buildPass{0}
}
:endtag
:enddata
:endrule

rule:
plugin=vanillaDoors
number=27
data:
tag:
TAG=10={
TAG=1=sideFlag{8}
TAG=8=blockName{wooden_door}
TAG=3=meta{6}
TAG=3=buildPass{1}
}
:endtag
:enddata
:endrule

rule:
plugin=vanillaDoors
number=28
data:
tag:
TAG=10={
TAG=1=sideFlag{0}
TAG=8=blockName{wooden_door}
TAG=3=meta{8}
TAG=3=buildPass{1}
}
:endtag
:enddata
:endrule

rule:
plugin=vanillaInventory
number=29
data:
tag:
TAG=10={
TAG=3=lootLevel{0}
TAG=10=teData{
TAG=9=Items{
}
TAG=8=id{Chest}
}
TAG=8=blockName{chest}
TAG=3=meta{4}
TAG=3=buildPass{0}
}
:endtag
:enddata
:endrule

rule:
plugin=vanillaBlocks
number=30
data:
tag:
TAG=10={
TAG=8=blockName{oak_stairs}
TAG=3=meta{2}
TAG=3=buildPass{0}
}
:endtag
:enddata
:endrule

rule:
plugin=vanillaBlocks
number=31
data:
tag:
TAG=10={
TAG=8=blockName{oak_stairs}
TAG=3=meta{1}
TAG=3=buildPass{0}
}
:endtag
:enddata
:endrule

rule:
plugin=vanillaBlocks
number=32
data:
tag:
TAG=10={
TAG=8=blockName{oak_stairs}
TAG=3=meta{3}
TAG=3=buildPass{0}
}
:endtag
:enddata
:endrule

rule:
plugin=vanillaBlocks
number=33
data:
tag:
TAG=10={
TAG=8=blockName{oak_stairs}
TAG=3=meta{0}
TAG=3=buildPass{0}
}
:endtag
:enddata
:endrule

rule:
plugin=vanillaBlocks
number=34
data:
tag:
TAG=10={
TAG=8=blockName{planks}
TAG=3=meta{0}
TAG=3=buildPass{0}
}
:endtag
:enddata
:endrule

rule:
plugin=vanillaBlocks
number=35
data:
tag:
TAG=10={
TAG=8=blockName{fence}
TAG=3=meta{0}
TAG=3=buildPass{0}
}
:endtag
:enddata
:endrule

#### ENTITIES ####
entity:
plugin=awGates
number=0
data:
position=9,5,6
tag:
TAG=10={
TAG=10=pos1{
TAG=3=z{-1}
TAG=3=y{0}
TAG=3=x{0}
}
TAG=1=orientation{3}
TAG=10=pos2{
TAG=3=z{1}
TAG=3=y{2}
TAG=3=x{0}
}
TAG=8=gateType{gate.verticalIron}
}
:endtag
:enddata
:endentity

entity:
plugin=awGates
number=1
data:
position=6,5,3
tag:
TAG=10={
TAG=10=pos1{
TAG=3=z{0}
TAG=3=y{0}
TAG=3=x{1}
}
TAG=1=orientation{2}
TAG=10=pos2{
TAG=3=z{0}
TAG=3=y{3}
TAG=3=x{-1}
}
TAG=8=gateType{gate.verticalIron}
}
:endtag
:enddata
:endentity

entity:
plugin=awGates
number=2
data:
position=6,5,9
tag:
TAG=10={
TAG=10=pos1{
TAG=3=z{0}
TAG=3=y{0}
TAG=3=x{1}
}
TAG=1=orientation{2}
TAG=10=pos2{
TAG=3=z{0}
TAG=3=y{3}
TAG=3=x{-1}
}
TAG=8=gateType{gate.verticalIron}
}
:endtag
:enddata
:endentity

entity:
plugin=awNpcOld
number=3
data:
position=12,10,8
tag:
TAG=10={
TAG=5=yOffset{0.5}
TAG=5=xOffset{0.76413196}
TAG=5=zOffset{0.4550719}
TAG=5=rotation{-91.677795}
TAG=3=npcLevel{1}
TAG=3=npcType{2}
TAG=3=npcTeam{17}
}
:endtag
:enddata
:endentity

entity:
plugin=awNpcOld
number=4
data:
position=13,5,6
tag:
TAG=10={
TAG=5=yOffset{0.0}
TAG=5=xOffset{0.22160709}
TAG=5=zOffset{0.7}
TAG=5=rotation{-123.628815}
TAG=3=npcLevel{1}
TAG=3=npcType{2}
TAG=3=npcTeam{17}
}
:endtag
:enddata
:endentity

entity:
plugin=awVehicleOld
number=5
data:
position=5,10,6
tag:
TAG=10={
TAG=3=vehicleTeam{0}
TAG=3=vehicleLevel{1}
TAG=5=yOffset{0.0}
TAG=10=vehicleInventory{
TAG=10=inv{
TAG=10=amI{
TAG=9=Items{
TAG=10={
TAG=2=id{31966}
TAG=2=Damage{44}
TAG=1=Count{64}
TAG=1=Slot{0}
}
}
}
TAG=10=arI{
TAG=9=Items{
}
}
TAG=10=sI{
TAG=9=Items{
}
}
TAG=10=uI{
TAG=9=Items{
}
}
}
}
TAG=5=xOffset{0.5}
TAG=5=zOffset{0.5}
TAG=5=rotation{267.7782}
TAG=3=vehicleType{5}
}
:endtag
:enddata
:endentity

entity:
plugin=awNpcOld
number=6
data:
position=5,10,8
tag:
TAG=10={
TAG=5=yOffset{0.5}
TAG=5=xOffset{0.6333983}
TAG=5=zOffset{0.7563134}
TAG=5=rotation{-152.65498}
TAG=3=npcLevel{1}
TAG=3=npcType{4}
TAG=3=npcTeam{17}
}
:endtag
:enddata
:endentity

entity:
plugin=awNpcOld
number=7
data:
position=15,18,3
tag:
TAG=10={
TAG=5=yOffset{0.5}
TAG=5=xOffset{0.5}
TAG=5=zOffset{0.5}
TAG=5=rotation{-125.87799}
TAG=3=npcLevel{0}
TAG=3=npcType{3}
TAG=3=npcTeam{17}
}
:endtag
:enddata
:endentity

entity:
plugin=awNpcOld
number=8
data:
position=10,18,9
tag:
TAG=10={
TAG=5=yOffset{0.5}
TAG=5=xOffset{0.5}
TAG=5=zOffset{0.5}
TAG=5=rotation{39.87216}
TAG=3=npcLevel{1}
TAG=3=npcType{3}
TAG=3=npcTeam{17}
}
:endtag
:enddata
:endentity

