# Ancient Warfare Structure Template File
# auto-generated structure file. created on: 4/21/2014 at: 17:10:0
# Lines beginning with # denote comments

header:
version=2.0
name=fortress1
size=49,25,56
offset=24,6,55
:endheader

#### VALIDATION ####
validation:
type=ground
survival=false
worldGenEnabled=true
unique=false
preserveBlocks=false
selectionWeight=1
clusterValue=200
minDuplicateDistance=40
dimensionWhiteList=false
dimensionList=
biomeWhiteList=false
biomeList=
leveling=19
fill=6
border=6
validTargetBlocks=clay,lapis_ore,lit_redstone_ore,stone,carpet,tile.bop.mud,gravel,coal_block,diamond_ore,ice,snow,netherrack,tile.bop.longGrass,tile.bop.generic.hard_dirt,tile.bop.redRocks,dirt,redstone_ore,mycelium,tile.bop.holyStone,sand,grass,tile.bop.ash,iron_ore,soul_sand,snow_layer,stained_hardened_clay,coal_ore,gold_ore,tile.bop.generic.hard_sand
data:
:enddata
:endvalidation

#### LAYERS ####
layer: 0
1,1,1,2,1,1,1,1,1,1,1,1,1,1,1,1,1,1,1,4,4,4,4,1,5,5,1,1,1,1,1,1,1,1,1,1,1,1,1,1,1,1,1,1,1,1,1,1,1
1,1,1,2,1,1,1,1,1,1,1,1,1,1,1,1,1,1,4,4,4,4,1,1,1,5,1,1,1,1,1,1,1,1,1,1,1,1,1,1,1,1,1,1,1,1,1,1,1
1,1,1,1,1,1,1,1,1,1,1,1,1,1,1,1,1,1,4,4,4,4,1,1,1,1,1,1,1,1,1,1,1,1,1,1,1,1,5,5,1,1,1,1,1,1,1,1,1
1,1,1,1,1,1,1,1,1,1,1,1,1,1,1,1,1,4,4,4,4,1,1,1,1,1,1,1,1,1,1,1,1,1,1,1,1,1,1,2,1,1,1,1,1,1,1,1,1
1,1,4,4,4,4,1,1,1,1,1,1,1,1,1,1,1,4,4,4,1,1,1,1,1,1,1,1,1,1,1,1,1,1,1,1,1,1,2,2,1,1,1,1,1,1,1,1,1
1,1,4,4,4,4,4,4,1,1,1,1,1,1,1,1,1,1,1,1,1,1,1,1,1,1,1,1,1,1,1,1,1,1,1,1,1,1,2,2,2,1,1,1,1,1,1,1,1
1,1,4,4,4,4,4,4,4,1,1,1,1,1,1,1,1,1,1,1,1,1,1,1,1,1,1,1,1,1,1,1,1,1,1,1,1,1,2,2,1,1,1,1,1,1,1,1,1
1,1,1,4,4,4,4,4,4,4,1,1,1,1,1,1,1,1,1,1,1,1,1,1,1,1,1,1,1,1,1,1,1,1,1,1,1,1,2,2,1,1,1,1,1,1,1,1,1
1,1,1,1,4,4,4,4,4,4,1,1,1,1,1,1,1,1,1,1,1,1,1,1,1,1,1,1,1,1,1,1,1,1,1,1,1,1,2,1,1,1,1,1,1,1,1,1,1
1,1,1,1,1,1,4,4,4,4,1,1,1,1,1,1,1,1,1,1,1,1,1,1,1,1,1,1,1,1,1,1,1,1,1,1,1,1,1,1,1,1,1,1,1,1,1,1,1
1,1,1,1,1,1,1,1,1,1,1,1,1,1,1,1,1,2,2,1,1,1,1,1,1,1,1,1,1,1,1,1,1,1,1,1,1,1,1,1,1,1,1,1,1,1,1,1,1
1,1,1,1,1,1,1,1,1,1,1,1,1,1,1,1,2,2,2,1,1,1,1,1,1,1,1,1,1,1,1,1,1,1,1,1,1,1,1,1,1,1,1,1,1,1,1,1,1
1,1,1,1,1,1,1,1,1,1,1,1,1,1,1,1,2,2,1,1,1,1,1,1,1,1,1,1,1,1,1,1,1,1,1,1,1,1,1,1,1,1,1,1,1,1,1,1,2
1,1,1,1,1,1,4,1,1,1,1,1,1,1,1,1,1,1,1,1,1,1,1,1,1,1,1,1,1,1,1,1,1,1,1,1,1,1,1,1,1,1,1,1,1,1,1,1,2
1,1,1,1,1,4,4,4,1,1,1,1,1,1,1,1,1,1,1,1,1,1,1,1,1,1,1,1,1,1,1,1,1,1,1,1,1,1,1,1,1,1,1,1,1,1,1,1,1
1,1,1,1,1,4,4,4,1,1,1,1,1,1,1,1,1,1,1,1,1,1,1,1,1,1,1,1,1,1,1,1,1,1,1,1,1,1,1,1,1,1,1,1,1,1,1,1,1
1,1,1,1,1,4,4,4,4,1,1,1,1,1,1,1,1,1,1,1,5,5,1,1,1,1,1,1,1,1,1,3,3,1,1,1,1,1,3,3,3,3,1,1,1,1,1,1,3
1,1,1,1,1,4,4,4,4,1,1,1,1,1,1,1,1,1,1,1,5,5,1,1,1,1,1,1,1,1,1,3,3,1,1,1,1,3,3,3,3,3,3,3,1,1,1,1,3
1,1,1,1,1,4,4,4,4,1,1,1,1,1,1,1,1,1,1,1,6,6,6,1,1,1,1,1,1,1,3,3,3,1,1,1,1,1,3,3,3,3,3,3,3,1,1,1,1
1,1,1,1,1,3,3,4,4,1,1,1,1,1,1,1,1,1,6,6,6,6,6,6,1,1,1,1,1,3,3,3,3,1,1,1,1,1,1,3,3,3,3,3,3,3,1,1,1
1,1,1,1,1,3,3,3,3,1,1,1,1,1,1,1,1,1,6,6,6,6,6,6,6,6,1,1,1,3,3,3,3,1,1,1,1,1,1,1,3,3,3,3,3,3,1,1,1
1,1,1,1,1,1,3,3,3,3,1,1,1,1,1,1,1,1,1,6,6,6,6,6,6,6,1,1,3,3,3,3,1,1,1,1,1,1,1,1,1,1,3,3,3,3,1,1,1
1,1,1,1,1,1,3,3,3,3,3,1,1,1,1,1,1,1,1,6,6,6,6,6,6,6,1,1,3,3,3,3,1,1,1,1,1,1,1,1,1,1,1,1,1,1,1,1,1
1,1,1,1,1,1,1,3,3,3,3,1,1,1,1,1,1,1,1,6,6,6,6,6,6,6,1,1,3,3,3,1,1,1,1,1,1,1,1,1,1,1,1,1,1,1,1,1,1
1,1,1,1,1,1,1,1,3,3,3,1,1,4,4,1,1,1,6,6,6,6,6,6,6,6,1,1,1,3,1,1,1,1,1,1,1,1,1,1,1,1,1,1,1,1,1,1,1
1,1,1,1,1,1,1,5,5,1,1,1,4,4,4,1,4,4,1,6,6,6,6,6,6,1,1,1,1,1,1,1,1,1,1,1,1,1,1,1,1,1,1,1,1,1,1,1,1
1,1,1,1,1,1,1,5,5,1,1,1,5,1,4,4,4,4,4,6,6,6,6,6,6,1,1,1,1,1,1,1,1,1,1,1,1,1,1,1,1,1,1,1,1,1,1,1,1
1,1,1,1,1,1,1,1,1,1,1,1,5,4,4,4,4,4,1,6,6,6,6,6,6,1,1,1,1,1,1,1,1,1,1,1,1,1,1,1,1,1,1,1,1,1,1,2,2
3,3,3,1,1,1,1,1,1,1,1,1,1,4,4,4,4,4,1,1,1,6,6,1,1,1,1,1,1,1,1,1,1,1,1,1,1,1,1,1,1,1,1,1,1,1,1,2,2
3,3,3,1,1,1,1,1,1,1,1,1,4,4,4,4,4,4,1,1,1,1,1,3,3,3,3,3,3,1,1,1,1,1,1,1,1,1,1,1,1,1,1,1,1,1,1,1,2
3,3,3,1,1,1,1,1,1,1,1,1,4,4,4,4,4,1,1,1,1,1,1,3,3,3,3,3,3,1,1,1,1,1,1,1,1,1,1,1,1,1,1,1,1,1,1,1,1
3,3,3,1,1,1,1,1,1,1,1,1,4,4,4,4,1,1,1,1,1,1,1,3,3,3,3,3,3,1,1,1,1,1,1,1,1,2,2,1,1,1,1,1,1,1,1,1,1
3,3,1,1,1,1,1,1,1,1,1,1,4,4,1,1,1,1,1,1,4,4,1,3,3,3,1,1,1,1,1,1,1,1,1,1,2,2,1,1,1,1,1,1,1,1,1,1,1
3,1,1,1,1,1,1,1,1,1,1,1,1,1,1,1,1,1,1,4,4,4,4,1,1,1,1,1,1,1,1,1,1,1,1,1,2,2,1,5,5,1,1,1,3,1,1,1,1
3,1,1,1,1,1,1,1,1,1,1,1,1,1,1,1,1,1,1,4,4,4,4,1,1,1,1,1,1,1,1,1,1,1,1,1,1,1,1,1,5,3,3,3,3,3,1,1,1
3,1,1,1,1,1,1,1,1,1,1,1,1,1,1,1,1,1,1,4,4,4,4,1,1,1,1,1,1,1,1,1,1,1,1,1,1,1,1,3,3,3,3,3,3,1,1,1,1
1,1,1,1,1,1,1,1,1,1,1,1,1,1,1,1,1,1,1,4,4,4,4,1,1,1,1,1,1,1,1,1,1,1,1,1,1,1,3,3,3,3,3,3,3,1,1,1,1
1,1,1,1,1,1,1,1,1,1,1,1,1,1,1,1,1,1,1,4,4,4,4,1,1,1,1,1,1,1,1,1,1,1,1,1,1,1,3,3,3,3,3,1,2,1,1,1,1
1,1,1,1,1,1,1,1,1,1,1,1,1,1,1,1,1,1,1,4,4,4,4,1,1,1,1,1,1,1,1,1,1,1,1,1,1,1,3,3,3,3,1,2,4,2,1,1,1
1,1,1,1,1,1,1,1,1,1,1,1,1,1,1,1,1,1,1,1,4,4,1,1,1,1,1,1,1,1,1,1,1,1,1,1,1,1,1,1,1,1,2,2,4,1,1,1,1
1,1,1,1,1,1,1,1,1,1,1,1,1,1,1,1,1,1,1,1,4,4,1,1,1,1,1,1,1,1,1,1,1,1,1,1,1,1,1,1,1,1,2,2,1,1,1,1,1
1,1,1,1,1,1,1,1,1,1,1,1,1,1,1,1,1,1,1,1,1,1,1,1,1,1,1,1,1,1,1,1,1,1,1,1,1,1,1,1,1,1,1,1,2,1,1,1,1
1,1,1,1,1,1,1,1,1,1,1,1,1,1,1,1,1,1,1,1,1,1,1,1,1,1,1,1,1,1,1,1,1,1,1,1,1,1,1,1,1,1,1,1,2,1,1,1,1
1,1,1,1,1,1,1,1,1,1,1,1,1,1,1,1,1,1,1,1,1,1,1,1,1,1,1,1,1,1,1,1,1,1,1,1,1,1,1,1,1,1,4,4,4,1,1,1,1
1,1,1,1,1,1,1,1,4,1,1,1,1,1,1,1,1,1,1,1,1,1,1,1,1,1,1,1,1,0,0,1,1,1,1,1,1,1,1,1,1,1,4,4,4,4,1,1,1
1,1,1,1,1,1,1,4,4,4,1,1,1,1,1,1,1,1,1,1,1,1,1,1,1,1,1,1,0,0,0,0,1,1,1,1,1,1,1,1,1,1,1,4,4,4,4,1,1
1,1,1,1,1,1,1,4,4,4,1,1,1,1,1,1,1,1,1,1,1,1,1,1,1,1,1,1,0,0,0,1,1,1,1,1,1,1,1,1,1,1,1,1,4,4,4,4,1
1,1,1,1,1,1,4,4,4,4,1,1,1,1,1,1,1,1,1,1,1,1,1,1,1,1,1,0,0,0,0,1,1,1,1,1,1,1,1,1,1,1,1,1,1,1,1,1,1
1,1,1,1,1,1,4,4,4,4,1,1,1,1,1,1,1,1,1,1,1,1,1,1,1,1,0,0,0,0,0,1,1,1,1,1,1,1,1,1,1,1,1,1,1,1,1,1,1
1,1,1,1,1,1,4,4,4,4,1,1,1,1,1,1,1,1,1,1,1,1,1,1,1,1,0,0,0,0,0,1,1,2,2,2,1,1,1,1,1,1,1,1,1,1,1,1,1
1,1,1,1,5,4,4,4,4,4,1,1,1,1,1,1,1,1,1,1,1,1,1,1,1,1,0,0,0,0,1,1,1,1,1,1,1,1,1,1,1,1,1,1,1,1,1,1,1
1,1,1,1,5,5,4,4,4,4,1,1,1,1,1,1,1,1,1,1,1,1,1,1,1,1,0,0,0,1,1,1,1,1,1,1,1,1,1,1,1,1,1,1,1,1,1,1,1
1,1,1,1,1,1,4,4,4,1,1,1,1,1,1,1,1,1,1,1,1,1,1,1,1,1,0,0,1,1,1,1,5,1,1,1,1,1,1,1,1,1,1,1,1,1,1,1,1
1,1,1,1,1,1,4,4,1,1,1,1,2,1,1,1,1,1,1,1,1,1,1,1,1,3,1,1,1,1,1,5,1,1,1,1,1,1,1,1,1,1,1,1,1,1,1,1,1
1,1,1,1,1,1,1,1,1,1,1,1,1,1,1,1,1,1,1,1,1,1,1,1,3,3,3,1,1,1,1,1,1,1,1,1,1,1,1,1,1,2,2,1,1,1,1,1,3
1,1,1,1,3,3,3,3,3,1,1,1,1,1,1,1,1,1,1,1,1,1,1,3,3,3,1,1,1,1,1,1,1,1,1,1,1,1,1,1,2,2,1,1,1,1,1,3,3
:endlayer
layer: 1
1,1,1,2,1,1,1,1,1,1,1,1,1,1,1,1,1,1,1,1,1,1,1,1,1,1,1,1,1,1,1,1,1,1,1,1,1,1,1,1,1,4,4,4,4,4,1,1,1
1,2,2,2,1,1,1,1,1,1,1,1,1,1,1,1,1,1,1,1,1,1,1,1,1,1,1,1,1,1,1,1,1,1,1,1,1,1,1,1,1,1,1,1,1,1,1,1,1
2,2,2,1,1,1,1,1,1,1,1,1,1,1,1,1,1,1,1,1,1,1,1,1,1,1,1,1,1,1,1,1,1,1,1,1,1,1,1,1,1,1,1,1,1,1,1,1,1
2,2,2,2,1,1,1,1,1,1,1,1,1,1,1,1,1,1,1,1,1,1,1,1,1,1,1,1,1,1,1,1,1,1,1,1,1,1,1,1,1,1,1,1,1,1,1,1,1
2,2,2,4,4,4,1,1,1,1,1,1,1,1,1,1,1,1,1,1,1,1,1,1,1,1,1,1,1,1,1,1,1,1,1,1,1,1,1,1,1,1,1,1,1,1,1,1,1
1,1,4,4,4,4,4,4,1,1,1,1,1,1,1,1,1,1,1,1,1,1,1,1,1,1,1,1,1,1,1,1,1,1,1,1,1,1,2,2,1,1,1,1,1,1,1,1,1
5,1,4,4,4,4,4,4,4,1,1,1,1,1,1,1,1,1,1,1,1,1,1,1,1,1,1,1,1,1,1,1,1,1,1,1,1,1,2,2,1,1,1,1,1,1,1,1,1
5,1,1,4,4,4,4,4,4,4,1,1,1,1,1,1,1,1,1,1,1,1,1,1,1,1,1,1,1,1,1,1,1,1,1,1,1,1,2,1,1,1,1,1,1,1,1,1,1
1,1,1,1,4,4,4,4,4,4,1,1,1,1,1,1,1,1,1,1,1,1,1,1,1,1,1,1,1,4,1,1,1,1,1,1,1,1,2,1,1,1,1,1,1,1,1,1,1
1,1,1,1,1,1,4,4,4,4,1,1,1,1,1,1,1,1,1,1,1,1,1,1,1,1,1,1,1,4,4,1,1,1,1,1,1,1,1,1,1,1,1,1,1,1,1,1,1
1,1,1,1,1,1,1,1,1,1,1,1,1,1,1,1,1,1,1,1,1,1,1,1,1,1,1,1,1,4,4,4,1,1,1,1,1,1,1,1,1,1,1,1,1,1,1,1,1
1,1,1,1,1,1,1,1,1,1,1,1,1,1,1,1,2,2,1,1,1,1,1,1,1,1,1,1,1,4,4,4,1,1,1,1,1,1,1,1,1,1,1,1,1,1,1,1,1
1,1,1,1,1,1,1,1,1,1,1,1,1,1,1,1,2,2,1,1,1,1,1,1,1,1,1,1,1,1,4,4,1,1,1,1,1,1,1,1,1,1,1,1,1,1,1,1,1
1,1,1,1,1,1,1,1,1,1,1,1,1,1,2,2,2,1,1,1,1,1,1,1,1,1,1,1,1,1,1,4,1,1,1,1,1,1,1,1,1,1,1,1,1,1,1,1,1
1,1,1,1,1,1,1,1,1,1,1,1,1,1,2,2,2,1,1,1,1,1,1,1,1,1,1,1,1,1,1,1,1,1,1,1,1,1,1,1,1,1,1,1,1,1,1,1,1
1,1,1,1,1,1,1,1,1,1,1,1,1,1,1,1,1,1,1,1,1,1,1,1,1,1,1,1,1,1,1,1,3,3,1,1,1,1,1,1,1,1,1,1,2,2,1,1,1
1,1,1,1,1,3,3,3,1,1,1,1,1,1,1,1,1,1,1,1,1,1,1,1,1,1,1,1,1,1,1,3,3,3,1,1,1,1,3,3,3,3,1,1,2,2,1,1,1
1,1,1,3,3,3,3,3,1,1,1,1,1,1,1,1,1,1,1,1,1,1,1,1,1,1,1,1,1,1,3,3,3,3,1,1,1,3,3,3,3,3,3,3,1,1,2,1,1
1,1,3,3,3,3,1,1,1,1,1,1,1,1,1,1,1,1,1,1,1,1,1,1,1,1,1,1,1,3,3,3,3,3,1,1,1,1,3,3,3,3,3,3,3,1,1,1,1
1,1,3,3,3,1,1,1,1,1,1,1,1,1,1,0,0,0,0,1,1,1,1,1,1,1,1,1,1,3,3,3,3,3,1,1,1,1,1,3,3,3,3,3,3,3,1,1,1
1,1,1,1,1,1,1,1,1,1,1,1,1,1,1,0,0,0,0,1,1,1,1,1,1,1,1,1,1,3,3,3,3,1,1,1,1,1,1,1,3,3,3,3,3,3,1,1,1
1,1,1,1,1,1,1,3,3,1,1,1,1,1,1,1,0,0,1,0,0,0,0,0,0,0,0,1,3,3,3,3,3,1,1,1,1,1,1,1,1,1,3,3,3,3,1,1,1
1,1,1,1,1,1,1,3,3,1,1,1,1,1,1,1,1,1,1,0,0,0,0,0,0,0,0,1,3,3,3,3,1,1,1,1,1,1,1,1,1,1,1,1,1,1,1,1,1
1,1,1,1,1,1,1,1,1,1,1,1,1,1,1,1,1,1,1,0,0,0,0,0,0,0,0,1,3,3,3,1,1,1,1,1,1,1,1,1,1,1,1,1,1,1,1,1,1
1,1,1,1,1,1,1,1,1,1,1,1,1,1,1,1,1,1,0,0,0,0,0,0,0,0,1,1,1,3,1,1,1,1,1,1,1,1,1,1,1,1,1,1,1,1,1,1,1
1,1,1,1,1,1,1,5,5,1,1,1,1,1,1,1,4,1,1,0,0,0,0,0,0,0,1,1,1,1,1,1,1,1,1,1,1,1,1,1,1,1,1,1,1,1,1,1,1
1,1,1,1,1,1,1,5,5,1,1,1,1,1,4,4,4,4,1,0,0,0,0,0,0,0,1,1,1,1,1,1,1,1,1,1,1,1,1,1,1,1,1,1,1,1,1,1,1
1,1,1,1,1,1,1,1,1,1,1,2,2,4,4,4,4,4,1,0,0,0,0,0,0,1,1,1,1,1,1,1,1,1,1,1,1,1,1,1,1,1,1,1,1,1,1,1,1
1,1,1,1,1,1,1,1,1,1,1,2,2,4,4,4,4,4,1,1,0,0,0,0,1,1,1,1,1,1,1,1,1,1,1,1,1,1,1,1,1,1,3,3,3,3,1,1,1
1,3,1,1,1,1,1,1,1,1,1,2,4,4,4,4,4,1,1,1,1,1,1,1,1,1,1,1,1,1,1,1,1,1,1,1,1,1,1,1,1,1,3,3,3,3,3,1,1
3,3,1,1,1,1,1,1,1,1,1,4,4,4,4,4,4,1,1,1,1,1,1,1,1,3,3,1,1,1,1,1,1,1,1,1,1,1,1,1,1,1,3,3,3,3,3,3,1
3,3,1,1,1,1,1,1,1,1,1,4,4,4,4,4,1,1,1,1,1,1,1,1,1,1,1,1,1,1,1,1,1,1,1,1,1,1,1,1,1,1,1,1,3,3,3,3,1
3,3,1,1,1,1,1,1,1,1,1,4,4,4,4,1,1,1,1,1,1,1,1,1,1,1,1,1,1,1,1,1,1,1,1,1,1,1,1,1,1,1,1,1,1,1,1,4,4
3,3,1,1,1,1,1,1,1,1,1,1,1,1,1,1,1,1,1,1,4,4,1,1,1,1,1,1,1,1,1,1,1,1,1,1,1,1,1,1,1,1,1,1,1,1,1,4,4
3,1,1,1,1,1,1,1,1,1,1,1,1,1,1,1,1,1,1,1,4,4,1,1,1,1,1,1,1,1,1,1,1,1,1,1,1,1,1,1,1,1,1,1,1,1,1,4,4
3,1,1,1,1,1,1,1,1,1,1,1,1,1,1,1,1,1,1,1,4,4,1,1,1,1,1,1,1,1,1,1,1,1,1,1,1,1,1,1,1,3,3,1,1,1,1,1,4
1,1,1,1,1,1,1,1,1,1,1,1,1,1,1,1,1,1,1,1,4,4,1,1,1,1,1,3,1,1,1,1,1,1,1,1,1,1,1,3,3,3,3,1,1,1,1,1,4
1,1,1,1,1,1,1,1,1,1,1,1,1,1,1,1,1,1,1,1,4,4,1,1,1,1,3,3,1,1,1,1,1,1,1,1,1,1,1,3,3,1,1,1,2,1,1,1,1
1,1,1,1,1,1,1,1,1,1,1,1,1,1,1,1,1,1,1,1,4,4,1,1,1,1,1,1,1,1,1,1,1,1,1,2,2,1,1,1,1,1,1,2,2,2,1,1,1
1,1,1,1,1,1,1,1,1,1,1,1,1,1,1,1,1,1,1,1,1,1,1,1,1,1,1,1,1,1,1,1,1,1,1,2,2,1,1,1,1,1,2,2,2,1,1,1,1
1,1,1,1,1,1,1,1,1,1,1,1,1,1,1,1,1,1,1,1,1,1,1,1,1,1,1,1,1,1,1,1,1,1,1,2,2,1,1,1,1,1,2,2,1,1,1,1,1
1,1,1,1,1,1,1,1,1,1,1,1,1,1,1,1,1,1,1,1,1,1,1,1,1,1,1,1,1,1,1,1,1,1,1,2,1,1,1,1,1,1,1,1,1,1,1,1,1
1,1,1,1,1,1,1,1,1,1,1,1,1,1,1,1,1,1,1,1,1,1,1,1,1,1,1,1,1,1,1,1,1,1,1,1,1,1,1,1,1,1,1,1,1,1,1,1,1
1,1,1,1,1,1,1,1,1,1,1,1,1,1,1,1,1,1,1,1,1,1,1,1,1,1,1,7,7,1,1,1,1,1,1,1,1,1,1,1,1,1,1,1,1,1,1,1,1
1,1,1,1,1,1,1,1,1,1,1,1,1,1,1,1,1,1,1,1,1,1,1,1,1,1,1,8,3,0,0,4,1,1,1,1,1,1,1,1,1,1,1,1,1,1,1,1,1
1,1,1,1,1,1,1,1,4,1,1,1,1,1,1,1,1,1,1,1,1,1,1,1,1,1,1,7,0,0,0,0,1,1,1,1,1,1,1,1,1,1,1,1,1,1,1,1,1
1,1,1,1,1,1,1,4,4,4,1,1,1,1,1,1,1,1,1,1,1,1,1,1,1,1,1,7,0,0,0,4,1,1,1,1,1,1,1,1,1,1,1,1,1,1,1,1,1
1,1,1,1,1,1,1,4,4,4,1,1,1,1,1,1,1,1,1,1,1,1,1,1,1,1,1,0,0,0,0,4,1,1,1,1,1,1,1,1,1,1,1,1,1,1,1,1,1
1,1,1,1,1,1,1,4,4,4,1,1,1,1,1,1,1,1,1,1,1,1,1,1,1,1,0,0,0,0,0,1,1,1,1,1,1,1,1,1,1,1,1,1,1,1,1,1,1
1,1,1,1,1,1,4,4,4,1,1,1,1,1,1,1,1,1,1,1,1,1,1,1,1,1,0,0,0,0,0,1,1,2,2,2,2,1,1,1,1,1,1,1,1,1,1,1,1
1,1,1,1,1,1,4,4,4,1,1,1,1,1,1,1,1,1,1,1,1,1,1,1,1,1,0,0,0,0,1,1,1,1,2,2,2,2,1,1,1,1,1,1,1,1,1,1,1
1,1,1,1,1,1,4,4,4,1,1,1,2,2,1,1,1,1,1,1,1,1,1,1,1,1,0,9,0,1,1,1,1,1,1,1,1,1,1,1,1,1,1,1,1,1,1,1,1
1,1,1,1,1,1,1,4,1,1,1,1,2,2,1,1,1,1,1,1,1,1,1,1,1,3,3,3,2,1,1,1,1,1,1,1,1,1,1,1,1,1,1,1,1,1,1,1,1
1,1,1,1,1,1,1,1,1,1,1,1,2,1,1,1,1,1,1,1,1,1,1,3,3,3,3,10,1,1,1,1,1,1,1,1,1,1,1,1,1,1,1,1,1,1,1,1,1
1,1,1,1,1,1,1,1,1,1,1,1,1,1,1,1,1,1,1,1,1,1,1,3,3,3,3,3,1,1,1,1,1,1,1,1,1,1,1,1,1,1,1,1,1,1,1,1,3
1,1,1,1,3,3,3,3,3,1,1,1,1,1,1,1,1,1,1,1,1,1,3,3,3,3,3,1,1,1,1,1,1,1,1,1,1,1,1,1,1,1,1,1,1,1,1,3,3
:endlayer
layer: 2
3,3,3,3,3,3,3,3,3,3,3,3,3,3,3,3,3,3,3,3,3,3,3,3,3,3,3,3,3,3,3,3,3,3,3,3,3,3,3,3,3,3,3,3,3,3,3,3,3
3,3,3,3,3,3,3,3,3,3,3,3,3,3,3,3,3,3,3,3,3,3,3,3,3,3,3,3,3,3,3,3,3,3,3,3,3,3,3,3,3,3,3,3,3,3,3,3,3
3,3,3,3,3,3,3,3,3,3,3,3,3,3,3,3,3,3,3,3,3,3,3,3,3,3,3,3,3,3,3,3,3,3,3,3,3,3,3,3,3,3,3,3,3,3,3,3,3
3,3,3,3,3,3,3,3,3,3,3,3,3,3,3,3,3,3,3,3,3,3,3,3,3,3,3,3,3,3,3,3,3,3,3,3,3,3,3,3,3,3,3,3,3,3,3,3,3
3,3,3,3,3,3,3,3,3,3,3,3,3,3,3,3,3,3,3,3,3,3,3,3,3,3,3,3,3,3,3,3,3,3,3,3,3,3,3,3,3,3,3,3,3,3,3,3,3
3,3,3,3,3,3,3,3,3,3,3,3,3,3,3,3,3,3,3,3,3,3,3,3,3,3,3,3,3,3,3,3,3,3,3,3,3,3,3,3,3,3,3,3,3,3,3,3,3
3,3,3,3,3,3,3,3,3,3,3,3,3,3,3,3,3,3,3,3,3,3,3,3,3,3,3,3,3,3,3,3,3,3,3,3,3,3,3,3,3,3,3,3,3,3,3,3,3
3,3,3,3,3,3,3,3,3,3,3,3,3,3,3,3,3,3,20,20,20,20,20,20,23,20,20,3,3,3,3,3,3,3,3,3,3,3,3,3,3,3,3,3,3,3,3,3,3
3,3,3,3,3,3,3,3,3,3,3,3,3,3,3,3,3,3,20,0,0,0,0,0,0,23,20,3,3,3,3,3,3,3,3,3,3,3,3,3,3,3,3,3,3,3,3,3,3
3,3,3,3,3,3,3,3,3,3,3,3,3,3,3,3,3,3,20,0,0,0,0,0,0,24,3,3,3,3,3,3,3,3,3,3,3,3,3,3,3,3,3,3,3,3,3,3,3
3,3,3,3,3,3,3,3,3,3,3,3,3,3,3,3,3,3,23,0,30,0,0,0,0,13,12,3,3,3,3,3,3,3,3,3,3,3,3,3,3,3,3,3,3,3,3,3,3
3,3,3,3,3,3,3,3,3,3,3,3,3,3,3,3,3,3,20,13,12,0,0,0,13,13,13,14,12,3,3,3,3,3,3,3,3,3,3,3,3,3,3,3,3,3,3,3,3
3,3,3,3,3,3,3,3,3,3,3,3,3,3,3,3,3,3,20,12,31,0,0,0,0,25,21,0,13,3,3,3,3,3,3,3,3,3,3,3,3,3,3,3,3,3,3,3,3
3,3,3,3,3,3,3,3,3,3,3,3,3,3,3,3,3,3,20,13,0,0,0,0,0,0,0,15,13,3,3,3,3,3,3,3,3,3,3,3,3,3,3,3,3,3,3,3,3
3,3,3,3,3,3,3,3,3,3,3,3,3,3,3,3,3,3,3,13,32,0,26,0,0,26,0,16,13,3,3,3,3,3,3,3,3,3,3,3,3,3,3,3,3,3,3,3,3
3,3,3,3,3,3,3,3,3,3,3,3,3,3,3,3,3,3,3,13,33,0,0,0,0,0,0,0,13,3,3,3,3,3,3,3,3,3,3,3,3,3,3,3,3,3,3,3,3
3,3,3,3,3,3,3,3,3,3,3,3,3,3,3,3,3,3,3,13,0,0,0,0,0,0,0,0,13,3,3,3,3,3,3,3,3,3,3,3,3,3,3,3,3,3,3,3,3
3,3,3,3,3,3,3,3,3,3,3,3,3,3,3,3,3,3,3,13,34,0,26,0,0,26,0,17,13,3,3,3,3,3,3,3,3,3,3,3,3,3,3,3,3,3,3,3,3
3,3,3,3,3,3,3,3,3,3,3,3,3,3,3,3,3,3,3,13,35,0,0,0,0,0,0,18,13,3,3,3,3,3,3,3,3,3,3,3,3,3,3,3,3,3,3,3,3
3,3,3,3,3,3,3,3,3,3,3,3,3,3,3,0,0,0,0,13,0,29,28,0,0,27,22,0,13,3,3,3,3,3,3,3,3,3,3,3,3,3,3,3,3,3,3,3,3
3,3,3,3,3,3,3,3,3,3,3,3,3,3,3,0,0,0,0,13,13,13,13,13,13,13,13,13,13,3,3,3,3,3,3,3,3,3,3,3,3,3,3,3,3,3,3,3,3
3,3,3,3,3,3,3,3,3,3,3,3,3,3,3,3,0,0,3,0,0,0,0,0,0,0,0,3,3,3,3,3,3,3,3,3,3,3,3,3,3,3,3,3,3,3,3,3,3
3,3,3,3,3,3,3,3,3,3,3,3,3,3,3,3,3,3,3,0,0,0,0,0,0,0,0,3,3,3,3,3,3,3,3,3,3,3,3,3,3,3,3,3,3,3,3,3,3
3,3,3,3,3,3,3,3,3,3,3,3,3,3,3,3,3,3,3,0,0,0,0,0,0,0,0,3,3,3,3,3,3,3,3,3,3,3,3,3,3,3,3,3,3,3,3,3,3
3,3,3,3,3,3,3,3,3,3,3,3,3,3,3,3,3,3,3,0,0,0,0,0,0,0,3,3,3,3,3,3,3,3,3,3,3,3,3,3,3,3,3,3,3,3,3,3,3
3,3,3,3,3,3,3,3,3,3,3,3,3,3,3,3,3,3,3,0,0,0,0,0,0,3,3,3,3,3,3,3,3,3,3,3,3,3,3,3,3,3,3,3,3,3,3,3,3
3,3,3,3,3,3,3,3,3,3,3,3,3,3,3,3,3,3,3,0,0,0,0,0,0,3,3,3,3,3,3,3,3,3,3,3,3,3,3,3,3,3,3,3,3,3,3,3,3
3,3,3,3,3,3,3,3,3,3,3,3,3,3,3,3,3,3,3,0,0,0,0,0,0,3,3,3,3,3,3,3,3,3,3,3,3,3,3,3,3,3,3,3,3,3,3,3,3
3,3,3,3,3,3,3,3,3,3,3,3,3,3,3,3,3,3,3,3,3,0,0,3,3,3,3,3,3,3,3,3,3,3,3,3,3,3,3,3,3,3,3,3,3,3,3,3,3
3,3,3,3,3,3,3,3,3,3,3,3,3,3,3,3,3,3,3,3,3,3,3,3,3,3,3,3,3,3,3,3,3,3,3,3,3,3,3,3,3,3,3,3,3,3,3,3,3
3,3,3,3,3,3,3,3,3,3,3,3,3,3,3,3,3,3,3,3,3,3,3,3,3,3,3,3,3,3,3,3,3,3,3,3,3,3,3,3,3,3,3,3,3,3,3,3,3
3,3,3,3,3,3,3,3,3,3,3,3,3,3,3,3,3,3,3,3,3,3,3,3,3,3,3,3,3,3,3,3,3,3,3,3,3,3,3,3,3,3,3,3,3,3,3,3,3
3,3,3,3,3,3,3,3,3,3,3,3,3,3,3,3,3,3,3,3,3,3,3,3,3,3,3,3,3,3,3,3,3,3,3,3,3,3,3,3,3,3,3,3,3,3,3,3,3
3,3,3,3,3,3,3,3,3,3,3,3,3,3,3,3,3,3,3,3,3,3,3,3,3,3,3,3,3,3,3,3,3,3,3,3,3,3,3,3,3,3,3,3,3,3,3,3,3
3,3,3,3,3,3,3,3,3,3,3,3,3,3,3,3,3,3,3,3,3,3,3,3,3,3,3,3,3,3,3,3,3,3,3,3,3,3,3,3,3,3,3,3,3,3,3,3,3
3,3,3,3,3,3,3,3,3,3,3,3,3,3,3,3,3,3,3,3,3,3,3,3,3,3,3,3,3,3,3,3,3,3,3,3,3,3,3,3,3,3,3,3,3,3,3,3,3
3,3,3,3,3,3,3,3,3,3,3,3,3,3,3,3,3,3,3,3,3,3,3,3,3,3,3,3,3,3,3,3,3,3,3,3,3,3,3,3,3,3,3,3,3,3,3,3,3
3,3,3,3,3,3,3,3,3,3,3,3,3,3,3,3,3,3,3,3,3,3,3,3,3,3,3,3,3,3,3,3,3,3,3,3,3,3,3,3,3,3,3,3,3,3,3,3,3
3,3,3,3,3,3,3,3,3,3,3,3,3,3,3,3,3,3,3,3,3,3,3,3,3,3,3,3,3,3,3,3,3,3,3,3,3,3,3,3,3,3,3,3,3,3,3,3,3
3,3,3,3,3,3,3,3,3,3,3,3,3,3,3,3,3,3,3,3,3,3,3,3,3,3,3,3,3,3,3,3,3,3,3,3,3,3,3,3,3,3,3,3,3,3,3,3,3
3,3,3,3,3,3,3,3,3,3,3,3,3,3,3,3,3,3,3,3,3,3,3,3,3,3,3,3,3,3,3,3,3,3,3,3,3,3,3,3,3,3,3,3,3,3,3,3,3
3,3,3,3,3,3,3,3,3,3,3,3,3,3,3,3,3,3,3,3,3,3,3,3,3,3,3,3,3,3,3,3,3,3,3,3,3,3,3,3,3,3,3,3,3,3,3,3,3
3,3,3,3,3,3,3,3,3,3,3,3,3,3,3,3,3,3,3,3,3,3,3,3,3,3,3,3,3,3,3,3,3,3,3,3,3,3,3,3,3,3,3,3,3,3,3,3,3
3,3,3,3,3,3,3,3,3,3,3,3,3,3,3,3,3,3,3,3,3,3,3,3,3,3,3,3,0,7,3,3,3,3,3,3,3,3,3,3,3,3,3,3,3,3,3,3,3
3,3,3,3,3,3,3,3,3,3,3,3,3,3,3,3,3,3,3,3,3,3,3,3,3,3,3,3,3,3,3,3,3,3,3,3,3,3,3,3,3,3,3,3,3,3,3,3,3
3,3,3,3,3,3,3,3,3,3,3,3,3,3,3,3,3,3,3,3,3,3,3,3,3,3,3,3,3,3,3,3,3,3,3,3,3,3,3,3,3,3,3,3,3,3,3,3,3
3,3,3,3,3,3,3,3,3,3,3,3,3,3,3,3,3,3,3,3,3,3,3,3,3,3,3,3,3,3,3,3,3,3,3,3,3,3,3,3,3,3,3,3,3,3,3,3,3
3,3,3,3,3,3,3,3,3,3,3,3,3,3,3,3,3,3,3,3,3,3,3,3,3,3,3,3,3,3,3,3,3,3,3,3,3,3,3,3,3,3,3,3,3,3,3,3,3
3,3,3,3,3,3,3,3,3,3,3,3,3,3,3,3,3,3,3,3,3,3,3,3,3,3,3,3,3,3,3,3,3,3,3,3,3,3,3,3,3,3,3,3,3,3,3,3,3
3,3,3,3,3,3,3,3,3,3,3,3,3,3,3,3,3,3,3,3,3,3,3,3,3,3,3,3,3,3,3,3,3,3,3,3,3,3,3,3,3,3,3,3,3,3,3,3,3
3,3,3,3,3,3,3,3,3,3,3,3,3,3,3,3,3,3,3,3,3,3,3,3,3,3,3,3,3,3,3,3,3,3,3,3,3,3,3,3,3,3,3,3,3,3,3,3,3
3,3,3,3,3,3,3,3,3,3,3,3,3,3,3,3,3,3,3,3,3,3,3,3,3,3,3,3,3,3,3,3,3,3,3,3,3,3,3,3,3,3,3,3,3,3,3,3,3
3,3,3,3,3,3,3,3,3,3,3,3,3,3,3,3,3,3,3,3,3,3,3,3,3,3,3,3,3,3,3,3,3,3,3,3,3,3,3,3,3,3,3,3,3,3,3,3,3
3,3,3,3,3,3,3,3,3,3,3,3,3,3,3,3,3,3,3,3,3,3,3,3,3,3,3,0,3,3,3,3,3,3,3,3,3,3,3,3,3,3,3,3,3,3,3,3,3
3,3,3,3,3,3,3,3,3,3,3,3,3,3,3,3,3,3,3,3,3,3,3,3,3,3,3,19,3,11,3,3,3,3,3,3,3,3,3,3,3,3,3,3,3,3,3,3,3
3,3,3,3,3,3,3,3,3,3,3,3,3,3,3,3,3,3,3,3,3,3,3,3,3,3,3,3,3,3,3,3,3,3,3,3,3,3,3,3,3,3,3,3,3,3,3,3,3
:endlayer
layer: 3
3,3,3,3,3,3,3,3,3,3,3,3,3,3,3,3,3,3,3,3,3,3,3,3,3,3,3,3,3,3,3,3,3,3,3,3,3,3,3,3,3,3,3,3,3,3,3,3,3
3,3,3,3,3,3,3,3,3,3,3,3,3,3,3,3,3,3,3,3,3,3,3,3,3,3,3,3,3,3,3,3,3,3,3,3,3,3,3,3,3,3,3,3,3,3,3,3,3
3,3,3,3,3,3,3,3,3,3,3,3,3,3,3,3,3,3,3,3,3,3,3,3,3,3,3,3,3,3,3,3,3,3,3,3,3,3,3,3,3,3,3,3,3,3,3,3,3
3,3,3,3,3,3,3,3,3,3,3,3,3,3,3,3,3,3,3,3,3,3,3,3,3,3,3,3,3,3,3,3,3,3,3,3,3,3,3,3,3,3,3,3,3,3,3,3,3
3,3,3,3,3,3,3,3,3,3,3,3,3,3,3,3,3,3,3,3,3,3,3,3,3,3,3,3,3,3,3,3,3,3,3,3,3,3,3,3,3,3,3,3,3,3,3,3,3
3,3,3,3,3,3,3,3,3,3,3,3,3,3,3,3,3,3,3,3,3,3,3,3,3,3,3,3,3,3,3,3,3,3,3,3,3,3,3,3,3,3,3,3,3,3,3,3,3
3,3,3,3,3,3,3,3,3,3,3,3,3,3,3,3,3,3,3,3,3,3,3,3,3,3,3,3,3,3,3,3,3,3,3,3,3,3,3,3,3,3,3,3,3,3,3,3,3
3,3,3,3,3,3,3,3,3,3,3,3,3,3,3,3,3,3,20,20,20,23,20,20,20,20,3,3,3,3,3,3,3,3,3,3,3,3,3,3,3,3,3,3,3,3,3,3,3
3,3,3,3,3,3,3,3,3,3,3,3,3,3,3,3,3,3,23,0,0,0,0,0,0,20,20,3,3,3,3,3,3,3,3,3,3,3,3,3,3,3,3,3,3,3,3,3,3
3,3,3,3,3,3,3,3,3,3,3,3,3,3,3,3,3,3,20,0,0,0,0,0,0,0,24,13,3,3,3,3,3,3,3,3,3,3,3,3,3,3,3,3,3,3,3,3,3
3,3,3,3,3,3,3,3,3,3,3,3,3,3,3,3,3,3,20,0,0,0,0,0,0,13,13,3,3,3,3,3,3,3,3,3,3,3,3,3,3,3,3,3,3,3,3,3,3
3,3,3,3,3,3,3,3,3,3,3,3,3,3,3,3,3,3,20,13,13,0,0,0,13,13,13,13,13,3,3,3,3,3,3,3,3,3,3,3,3,3,3,3,3,3,3,3,3
3,3,3,3,3,3,3,3,3,3,3,3,3,3,3,3,3,3,20,13,0,0,0,0,0,0,0,0,13,3,3,3,3,3,3,3,3,3,3,3,3,3,3,3,3,3,3,3,3
3,3,3,3,3,3,3,3,3,3,3,3,3,3,3,3,3,3,20,13,0,0,0,0,0,0,0,0,13,3,3,3,3,3,3,3,3,3,3,3,3,3,3,3,3,3,3,3,3
3,3,3,3,3,3,3,3,3,3,3,3,3,3,3,3,3,3,3,13,0,0,0,0,0,0,0,0,13,3,3,3,3,3,3,3,3,3,3,3,3,3,3,3,3,3,3,3,3
3,3,3,3,3,3,3,3,3,3,3,3,3,3,3,3,3,3,3,13,0,0,0,0,0,0,0,0,13,3,3,3,3,3,3,3,3,3,3,3,3,3,3,3,3,3,3,3,3
3,3,3,3,3,3,3,3,3,3,3,3,3,3,3,3,3,3,3,13,0,0,0,0,0,0,0,0,13,3,3,3,3,3,3,3,3,3,3,3,3,3,3,3,3,3,3,3,3
3,3,3,3,3,3,3,3,3,3,3,3,3,3,3,3,3,3,3,13,0,0,0,0,0,0,0,0,13,3,3,3,3,3,3,3,3,3,3,3,3,3,3,3,3,3,3,3,3
3,3,3,3,3,3,3,3,3,3,3,3,3,3,3,3,3,3,3,13,0,0,0,0,0,0,0,0,13,3,3,3,3,3,3,3,3,3,3,3,3,3,3,3,3,3,3,3,3
3,3,3,3,3,3,3,3,3,3,3,3,3,3,3,3,3,3,3,13,0,0,0,0,0,0,0,0,13,3,3,3,3,3,3,3,3,3,3,3,3,3,3,3,3,3,3,3,3
3,3,3,3,3,3,3,3,3,3,3,3,3,3,3,3,3,3,3,13,13,13,13,13,13,13,13,13,13,3,3,3,3,3,3,3,3,3,3,3,3,3,3,3,3,3,3,3,3
3,3,3,3,3,3,3,3,3,3,3,3,3,3,3,3,3,3,3,3,0,0,0,0,0,0,3,3,3,3,3,3,3,3,3,3,3,3,3,3,3,3,3,3,3,3,3,3,3
3,3,3,3,3,3,3,3,3,3,3,3,3,3,3,3,3,3,3,0,0,0,0,0,0,0,3,3,3,3,3,3,3,3,3,3,3,3,3,3,3,3,3,3,3,3,3,3,3
3,3,3,3,3,3,3,3,3,3,3,3,3,3,3,3,3,3,3,3,0,0,0,0,0,0,3,3,3,3,3,3,3,3,3,3,3,3,3,3,3,3,3,3,3,3,3,3,3
3,3,3,3,3,3,3,3,3,3,3,3,3,3,3,3,3,3,3,0,0,0,0,0,0,3,3,3,3,3,3,3,3,3,3,3,3,3,3,3,3,3,3,3,3,3,3,3,3
3,3,3,3,3,3,3,3,3,3,3,3,3,3,3,3,3,3,3,3,0,3,0,3,3,3,3,3,3,3,3,3,3,3,3,3,3,3,3,3,3,3,3,3,3,3,3,3,3
3,3,3,3,3,3,3,3,3,3,3,3,3,3,3,3,3,3,3,3,3,3,3,3,3,3,3,3,3,3,3,3,3,3,3,3,3,3,3,3,3,3,3,3,3,3,3,3,3
3,3,3,3,3,3,3,3,3,3,3,3,3,3,3,3,3,3,3,3,3,3,3,3,3,3,3,3,3,3,3,3,3,3,3,3,3,3,3,3,3,3,3,3,3,3,3,3,3
3,3,3,3,3,3,3,3,3,3,3,3,3,3,3,3,3,3,3,3,3,3,3,3,3,3,3,3,3,3,3,3,3,3,3,3,3,3,3,3,3,3,3,3,3,3,3,3,3
3,3,3,3,3,3,3,3,3,3,3,3,3,3,3,3,3,3,3,3,3,3,3,3,3,3,3,3,3,3,3,3,3,3,3,3,3,3,3,3,3,3,3,3,3,3,3,3,3
3,3,3,3,3,3,3,3,3,3,3,3,3,3,3,3,3,3,3,3,3,3,3,3,3,3,3,3,3,3,3,3,3,3,3,3,3,3,3,3,3,3,3,3,3,3,3,3,3
3,3,3,3,3,3,3,3,3,3,3,3,3,3,3,3,3,3,3,3,3,3,3,3,3,3,3,3,3,3,3,3,3,3,3,3,3,3,3,3,3,3,3,3,3,3,3,3,3
3,3,3,3,3,3,3,3,3,3,3,3,3,3,3,3,3,3,3,3,3,3,3,3,3,3,3,3,3,3,3,3,3,3,3,3,3,3,3,3,3,3,3,3,3,3,3,3,3
3,3,3,3,3,3,3,3,3,3,3,3,3,3,3,3,3,3,3,3,3,3,3,3,3,3,3,3,3,3,3,3,3,3,3,3,3,3,3,3,3,3,3,3,3,3,3,3,3
3,3,3,3,3,3,3,3,3,3,3,3,3,3,3,3,3,3,3,3,3,3,3,3,3,3,3,3,3,3,3,3,3,3,3,3,3,3,3,3,3,3,3,3,3,3,3,3,3
3,3,3,3,3,3,3,3,3,3,3,3,3,3,3,3,3,3,3,3,3,3,3,3,3,3,3,3,3,3,3,3,3,3,3,3,3,3,3,3,3,3,3,3,3,3,3,3,3
3,3,3,3,3,3,3,3,3,3,3,3,3,3,3,3,3,3,3,3,3,3,3,3,3,3,3,3,3,3,3,3,3,3,3,3,3,3,3,3,3,3,3,3,3,3,3,3,3
3,3,3,3,3,3,3,3,3,3,3,3,3,3,3,3,3,3,3,3,3,3,3,3,3,3,3,3,3,3,3,3,3,3,3,3,3,3,3,3,3,3,3,3,3,3,3,3,3
3,3,3,3,3,3,3,3,3,3,3,3,3,3,3,3,3,3,3,3,3,3,3,3,3,3,3,3,3,3,3,3,3,3,3,3,3,3,3,3,3,3,3,3,3,3,3,3,3
3,3,3,3,3,3,3,3,3,3,3,3,3,3,3,3,3,3,3,3,3,3,3,3,3,3,3,3,3,3,3,3,3,3,3,3,3,3,3,3,3,3,3,3,3,3,3,3,3
3,3,3,3,3,3,3,3,3,3,3,3,3,3,3,3,3,3,3,3,3,3,3,3,3,3,3,3,3,3,3,3,3,3,3,3,3,3,3,3,3,3,3,3,3,3,3,3,3
3,3,3,3,3,3,3,3,3,3,3,3,3,3,3,3,3,3,3,3,3,3,3,3,3,3,3,3,3,3,3,3,3,3,3,3,3,3,3,3,3,3,3,3,3,3,3,3,3
3,3,3,3,3,3,3,3,3,3,3,3,3,3,3,3,3,3,3,3,3,3,3,3,3,3,3,3,3,3,3,3,3,3,3,3,3,3,3,3,3,3,3,3,3,3,3,3,3
3,3,3,3,3,3,3,3,3,3,3,3,6,6,6,6,6,6,3,3,3,3,3,3,3,3,3,3,0,0,3,6,6,6,6,6,6,3,3,3,3,3,3,3,3,3,3,3,3
3,3,3,3,3,3,3,3,3,3,3,3,6,6,6,6,6,6,3,3,3,3,3,3,3,3,3,3,3,7,3,6,6,6,6,6,6,3,3,3,3,3,3,3,3,3,3,3,3
3,3,3,3,3,3,3,3,3,3,3,6,6,6,6,6,6,6,6,3,3,3,3,3,3,3,3,3,3,3,6,6,6,6,6,6,6,6,3,3,3,3,3,3,3,3,3,3,3
3,3,3,3,3,3,3,3,3,3,6,6,6,6,6,6,6,6,6,6,6,3,3,3,3,3,3,3,6,6,6,6,6,6,6,6,6,6,6,3,3,3,3,3,3,3,3,3,3
3,3,3,3,3,3,3,3,3,6,6,6,6,6,6,6,6,6,6,6,6,6,6,6,6,6,6,6,6,6,6,6,6,6,6,6,6,6,6,6,3,3,3,3,3,3,3,3,3
3,3,3,3,3,3,3,3,3,3,6,6,6,6,6,6,6,6,6,6,6,6,6,6,6,6,6,6,6,6,6,6,6,6,6,6,6,6,6,3,3,3,3,3,3,3,3,3,3
3,3,3,3,3,3,3,3,3,3,3,6,6,6,6,6,6,6,6,6,6,6,6,6,6,6,6,6,6,6,6,6,6,6,6,6,6,6,3,3,3,3,3,3,3,3,3,3,3
3,3,3,3,3,3,3,3,3,3,3,3,6,6,6,6,6,6,6,6,6,6,6,6,6,6,6,6,6,6,6,6,6,6,6,6,6,3,3,3,3,3,3,3,3,3,3,3,3
3,3,3,3,3,3,3,3,3,3,3,3,3,6,6,6,6,6,6,6,6,6,6,6,6,6,6,6,6,6,6,6,6,6,6,6,3,3,3,3,3,3,3,3,3,3,3,3,3
3,3,3,3,3,3,3,3,3,3,3,3,3,3,6,6,6,6,6,6,6,6,6,6,6,6,6,6,6,6,6,6,6,6,6,3,3,3,3,3,3,3,3,3,3,3,3,3,3
3,3,3,3,3,3,3,3,3,3,3,3,3,3,3,3,3,3,3,3,3,3,3,3,3,3,3,3,3,3,3,3,3,3,3,3,3,3,3,3,3,3,3,3,3,3,3,3,3
3,3,3,3,3,3,3,3,3,3,3,3,3,3,3,3,3,3,3,3,3,3,3,3,3,3,3,36,11,0,3,3,3,3,3,3,3,3,3,3,3,3,3,3,3,3,3,3,3
3,3,3,3,3,3,3,3,3,3,3,3,3,3,3,3,3,3,3,3,3,3,3,3,3,3,3,3,3,3,3,3,3,3,3,3,3,3,3,3,3,3,3,3,3,3,3,3,3
:endlayer
layer: 4
3,3,3,3,3,3,3,3,3,3,3,3,3,3,3,3,3,3,3,3,3,3,3,3,3,3,3,3,3,3,3,3,3,3,3,3,3,3,3,3,3,3,3,3,3,3,3,3,3
3,3,3,3,3,3,3,3,3,3,3,3,3,3,3,3,3,3,3,3,3,3,3,3,3,3,3,3,3,3,3,3,3,3,3,3,3,3,3,3,3,3,3,3,3,3,3,3,3
3,3,3,3,3,3,3,3,3,3,3,3,3,3,3,3,3,3,3,3,3,3,3,3,3,3,3,3,3,3,3,3,3,3,3,3,3,3,3,3,3,3,3,3,3,3,3,3,3
3,3,3,3,3,3,3,3,3,3,3,3,3,3,3,3,3,3,3,3,3,3,3,3,3,3,3,3,3,3,3,3,3,3,3,3,3,3,3,3,3,3,3,3,3,3,3,3,3
3,3,3,3,3,3,3,3,3,3,3,3,3,3,3,3,3,3,3,3,3,3,3,3,3,3,3,3,3,3,3,3,3,3,3,3,3,3,3,3,3,3,3,3,3,3,3,3,3
3,3,3,3,3,3,3,3,3,3,3,3,3,3,3,3,3,3,3,3,3,3,3,3,3,3,3,3,3,3,3,3,3,3,3,3,3,3,3,3,3,3,3,3,3,3,3,3,3
3,3,3,3,3,3,3,3,3,3,3,3,3,3,3,3,3,3,3,3,3,3,3,3,3,3,3,3,3,3,3,3,3,3,3,3,3,3,3,3,3,3,3,3,3,3,3,3,3
3,3,3,3,3,3,3,3,3,3,3,3,3,3,3,3,3,3,3,20,20,20,23,20,20,20,3,3,3,3,3,3,3,3,3,3,3,3,3,3,3,3,3,3,3,3,3,3,3
3,3,3,3,3,3,3,3,3,3,3,3,3,3,3,3,3,3,20,0,38,0,0,0,38,20,20,20,3,3,3,3,3,3,3,3,3,3,3,3,3,3,3,3,3,3,3,3,3
3,3,3,3,3,3,3,3,3,3,3,3,3,3,3,3,3,3,23,0,0,0,0,0,0,0,0,24,13,3,3,3,3,3,3,3,3,3,3,3,3,3,3,3,3,3,3,3,3
3,3,3,3,3,3,3,3,3,3,3,3,3,3,3,3,3,3,20,0,39,0,0,0,39,13,14,13,3,3,3,3,3,3,3,3,3,3,3,3,3,3,3,3,3,3,3,3,3
3,3,3,3,3,3,3,3,3,3,3,3,3,3,3,3,3,3,20,12,13,0,0,0,13,13,12,13,14,3,3,3,3,3,3,3,3,3,3,3,3,3,3,3,3,3,3,3,3
3,3,3,3,3,3,3,3,3,3,3,3,3,3,3,3,3,3,20,13,0,0,0,0,0,0,38,0,13,3,3,3,3,3,3,3,3,3,3,3,3,3,3,3,3,3,3,3,3
3,3,3,3,3,3,3,3,3,3,3,3,3,3,3,3,3,3,20,13,40,0,0,0,0,0,0,37,13,3,3,3,3,3,3,3,3,3,3,3,3,3,3,3,3,3,3,3,3
3,3,3,3,3,3,3,3,3,3,3,3,3,3,3,3,3,3,3,13,0,0,0,0,0,0,0,0,13,3,3,3,3,3,3,3,3,3,3,3,3,3,3,3,3,3,3,3,3
3,3,3,3,3,3,3,3,3,3,3,3,3,3,3,3,3,3,3,13,0,0,0,0,0,0,0,0,13,3,3,3,3,3,3,3,3,3,3,3,3,3,3,3,3,3,3,3,3
3,3,3,3,3,3,3,3,3,3,3,3,3,3,3,3,3,3,3,13,0,0,0,0,0,0,0,0,13,3,3,3,3,3,3,3,3,3,3,3,3,3,3,3,3,3,3,3,3
3,3,3,3,3,3,3,3,3,3,3,3,3,3,3,3,3,3,3,13,0,0,0,0,0,0,0,0,13,3,3,3,3,3,3,3,3,3,3,3,3,3,3,3,3,3,3,3,3
3,3,3,3,3,3,3,3,3,11,3,3,11,3,3,3,3,3,3,13,40,0,0,0,0,0,0,37,13,3,3,3,3,3,3,3,11,3,3,11,3,3,3,3,3,3,3,3,3
3,3,3,3,3,3,3,3,3,3,3,3,3,3,3,3,3,3,3,13,0,39,0,0,0,0,39,0,13,3,3,3,3,3,3,3,3,3,3,3,3,3,3,3,3,3,3,3,3
3,3,3,3,3,3,3,3,3,3,3,3,3,3,3,3,3,3,3,13,13,13,13,13,13,13,13,13,13,3,3,3,3,3,3,3,3,3,3,3,3,3,3,3,3,3,3,3,3
3,3,3,3,3,3,3,3,3,3,3,3,3,3,3,3,3,3,3,3,3,3,3,3,3,3,3,3,3,3,3,3,3,3,3,3,3,3,3,3,3,3,3,3,3,3,3,3,3
3,3,3,3,3,3,3,3,3,3,3,3,3,3,3,3,3,3,3,3,3,3,3,3,3,3,3,3,3,3,3,3,3,3,3,3,3,3,3,3,3,3,3,3,3,3,3,3,3
3,3,3,3,3,3,3,3,3,11,3,3,11,3,3,3,3,3,3,3,3,3,3,3,3,3,3,3,3,3,3,3,3,3,3,3,3,3,3,3,3,3,3,3,3,3,3,3,3
3,3,3,3,3,3,3,3,3,3,3,3,3,3,3,3,3,3,3,3,3,3,3,3,3,3,3,3,3,3,3,3,3,3,3,3,3,3,3,3,3,3,3,3,3,3,3,3,3
3,3,3,3,3,3,3,3,3,3,3,3,3,3,3,3,3,3,3,3,3,3,3,3,3,3,3,3,3,3,3,3,3,3,3,3,3,3,3,3,3,3,3,3,3,3,3,3,3
3,3,3,3,3,3,3,3,3,3,3,3,3,3,3,3,3,3,3,3,3,3,3,3,3,3,3,3,3,3,3,3,3,3,3,3,3,3,3,3,3,3,3,3,3,3,3,3,3
3,3,3,3,3,3,3,3,3,3,3,3,3,3,3,3,3,3,3,3,3,3,3,3,3,3,3,3,3,3,3,3,3,3,3,3,3,3,3,3,3,3,3,3,3,3,3,3,3
3,3,3,3,3,3,3,3,3,11,3,3,11,3,3,3,3,3,3,3,3,3,3,3,3,3,3,3,3,3,3,3,3,3,3,3,3,3,3,3,3,3,3,3,3,3,3,3,3
3,3,3,3,3,3,3,3,3,3,3,3,3,3,3,3,3,3,3,3,3,3,3,3,3,3,3,3,3,3,3,3,3,3,3,3,3,3,3,3,3,3,3,3,3,3,3,3,3
3,3,3,3,3,3,3,3,3,3,3,3,3,3,3,3,3,3,3,3,3,3,3,3,3,3,3,3,3,3,3,3,3,3,3,3,3,3,3,3,3,3,3,3,3,3,3,3,3
3,3,3,3,3,3,3,3,3,3,3,3,3,3,3,3,3,3,3,3,3,3,3,3,3,3,3,3,3,3,3,3,3,3,3,3,3,3,3,3,3,3,3,3,3,3,3,3,3
3,3,3,3,3,3,3,3,3,3,3,3,3,3,3,3,3,3,3,3,3,3,3,3,3,3,3,3,3,3,3,3,3,3,3,3,3,3,3,3,3,3,3,3,3,3,3,3,3
3,3,3,3,3,3,3,3,3,11,3,3,11,3,3,3,3,3,3,3,3,3,3,3,3,3,3,3,3,3,3,3,3,3,3,3,3,3,3,3,3,3,3,3,3,3,3,3,3
3,3,3,3,3,3,3,3,3,3,3,3,3,3,3,3,3,3,3,3,3,3,3,3,3,3,3,3,3,3,3,3,3,3,3,3,3,3,3,3,3,3,3,3,3,3,3,3,3
3,3,3,3,3,3,3,3,3,3,3,3,3,3,3,3,3,3,3,3,3,3,3,3,3,3,3,3,3,3,3,3,3,3,3,3,3,3,3,3,3,3,3,3,3,3,3,3,3
3,3,3,3,3,3,3,3,3,3,3,3,3,3,3,3,3,3,3,3,3,3,3,3,3,3,3,3,3,3,3,3,3,3,3,3,3,3,3,3,3,3,3,3,3,3,3,3,3
3,3,3,3,3,3,3,3,3,3,3,3,3,3,3,3,3,3,3,3,3,3,3,3,3,3,3,3,3,3,3,3,3,3,3,3,3,3,3,3,3,3,3,3,3,3,3,3,3
3,3,3,3,3,3,3,3,3,3,3,3,3,3,3,3,3,3,3,3,3,3,3,3,3,3,3,3,3,3,3,3,3,3,3,3,3,3,3,3,3,3,3,3,3,3,3,3,3
3,3,3,3,3,3,3,3,3,3,3,3,3,3,3,3,3,3,3,3,3,3,3,3,3,3,3,3,3,3,3,3,3,3,3,3,3,3,3,3,3,3,3,3,3,3,3,3,3
3,3,3,3,3,3,3,3,3,3,3,3,3,3,3,3,3,3,3,3,3,3,3,3,3,3,3,3,3,3,3,3,3,3,3,3,3,3,3,3,3,3,3,3,3,3,3,3,3
3,3,3,3,3,3,3,3,3,3,3,3,3,3,3,3,3,3,3,3,3,3,3,3,3,3,3,3,3,3,3,3,3,3,3,3,3,3,3,3,3,3,3,3,3,3,3,3,3
3,3,3,3,3,3,3,3,3,3,3,3,3,3,3,3,3,3,3,3,3,3,3,3,3,3,3,3,3,3,3,3,3,3,3,3,3,3,3,3,3,3,3,3,3,3,3,3,3
3,3,3,3,3,3,3,3,3,3,3,3,6,6,6,6,6,6,3,3,3,3,3,3,0,0,0,3,0,0,3,6,6,6,6,6,6,3,3,3,3,3,3,3,3,3,3,3,3
3,3,3,3,3,3,3,3,3,3,3,3,6,6,6,6,6,6,3,3,3,3,3,3,3,3,3,3,7,0,3,6,6,6,6,6,6,3,3,3,3,3,3,3,3,3,3,3,3
3,3,3,3,3,3,3,3,3,3,3,6,6,6,6,6,6,6,6,3,3,3,3,3,3,3,3,3,3,3,6,6,6,6,6,6,6,6,3,3,3,3,3,3,3,3,3,3,3
3,3,3,3,3,3,3,3,3,3,6,6,6,6,6,6,6,6,6,6,6,3,3,3,3,3,3,3,6,6,6,6,6,6,6,6,6,6,6,3,3,3,3,3,3,3,3,3,3
3,3,3,3,3,3,3,3,3,6,6,6,6,6,6,6,6,6,6,6,6,6,6,6,6,6,6,6,6,6,6,6,6,6,6,6,6,6,6,6,3,3,3,3,3,3,3,3,3
3,3,3,3,3,3,3,3,3,3,6,6,6,6,6,6,6,6,6,6,6,6,6,6,6,6,6,6,6,6,6,6,6,6,6,6,6,6,6,3,3,3,3,3,3,3,3,3,3
3,3,3,3,3,3,3,3,3,3,3,6,6,6,6,6,6,6,6,6,6,6,6,6,6,6,6,6,6,6,6,6,6,6,6,6,6,6,3,3,3,3,3,3,3,3,3,3,3
3,3,3,3,3,3,3,3,3,3,3,3,6,6,6,6,6,6,6,6,6,6,6,6,6,6,6,6,6,6,6,6,6,6,6,6,6,3,3,3,3,3,3,3,3,3,3,3,3
3,3,3,3,3,3,3,3,3,3,3,3,3,6,6,6,6,6,6,6,6,6,6,6,6,6,6,6,6,6,6,6,6,6,6,6,3,3,3,3,3,3,3,3,3,3,3,3,3
3,3,3,3,3,3,3,3,3,3,3,3,3,3,6,6,6,6,6,6,6,6,6,6,6,6,6,6,6,6,6,6,6,6,6,3,3,3,3,3,3,3,3,3,3,3,3,3,3
3,3,3,3,3,3,3,3,3,3,3,3,3,3,3,3,3,3,3,3,3,3,3,3,3,3,3,3,3,3,3,3,3,3,3,3,3,3,3,3,3,3,3,3,3,3,3,3,3
3,3,3,3,3,3,3,3,3,3,3,3,3,3,3,3,3,3,3,3,3,3,3,3,3,3,3,0,7,11,3,3,3,3,3,3,3,3,3,3,3,3,3,3,3,3,3,3,3
3,3,3,3,3,3,3,3,3,3,3,3,3,3,3,3,3,3,3,3,3,3,3,3,3,3,3,3,3,3,3,3,3,3,3,3,3,3,3,3,3,3,3,3,3,3,3,3,3
:endlayer
layer: 5
11,11,11,11,11,11,11,11,11,11,11,11,11,11,11,11,11,11,11,11,11,11,11,11,11,11,11,11,11,11,11,11,11,11,11,11,11,11,11,11,11,11,11,11,11,11,11,11,11
11,11,11,11,3,3,3,3,3,11,11,11,11,11,11,11,11,11,11,11,11,11,11,11,11,11,11,11,11,11,11,11,11,11,11,11,11,11,11,11,3,3,3,3,3,11,11,11,11
11,11,11,3,3,3,3,3,3,3,11,11,11,11,11,11,11,11,11,11,11,11,11,11,11,11,11,11,11,11,11,11,11,11,11,11,11,11,11,3,3,3,3,3,3,3,11,11,11
11,11,3,3,3,3,3,3,3,3,3,11,11,11,11,11,11,11,11,11,11,11,11,11,11,11,11,11,11,11,11,11,11,11,11,11,11,11,3,3,3,3,3,3,3,3,3,11,11
11,3,3,3,3,3,3,3,3,3,3,3,11,11,11,11,11,11,11,11,11,11,11,11,11,11,11,11,11,11,11,11,11,11,11,11,11,3,3,3,3,3,3,3,3,3,3,3,11
11,3,3,3,3,3,3,3,3,3,3,3,11,11,11,11,11,11,11,11,11,11,11,11,11,11,11,11,11,11,11,11,11,11,11,11,11,3,3,3,3,3,3,3,3,3,3,3,11
11,3,3,3,3,3,3,3,3,3,3,3,3,3,3,3,3,3,3,3,3,3,3,3,3,3,3,3,3,3,3,3,3,3,3,3,3,3,3,3,3,3,3,3,3,3,3,3,11
11,3,3,3,3,3,3,3,3,3,3,3,3,3,3,3,3,3,3,23,20,20,20,20,23,20,3,3,3,3,3,3,3,3,3,3,3,3,3,3,3,3,3,3,3,3,3,3,11
11,3,3,3,3,3,3,3,3,3,3,3,3,3,3,3,41,3,20,0,0,0,0,0,0,20,20,20,20,3,3,3,3,3,3,3,3,3,3,3,3,3,3,3,3,3,3,3,11
11,11,3,3,3,3,3,3,3,3,3,3,3,3,3,3,3,3,23,0,0,0,0,0,0,0,0,0,24,13,3,3,3,3,3,3,3,3,3,3,3,3,3,3,3,3,3,11,11
11,11,11,3,3,3,3,3,3,3,3,3,3,3,3,3,3,3,20,0,0,0,0,0,0,13,13,12,13,3,3,3,3,3,3,3,3,3,3,3,3,3,3,3,3,3,11,11,11
11,11,11,11,3,3,3,3,3,3,3,3,3,3,3,3,3,3,20,13,13,13,14,13,13,13,13,12,13,3,3,3,3,3,3,3,3,3,3,3,3,3,3,3,3,11,11,11,11
11,11,11,11,11,11,3,3,3,3,3,3,3,3,3,3,3,3,20,13,13,13,13,13,13,13,13,13,13,3,3,3,3,3,3,3,3,3,3,3,3,3,3,11,11,11,11,11,11
11,11,11,11,11,11,3,3,3,41,3,3,41,3,3,3,41,3,20,14,13,13,13,13,13,13,13,13,13,3,3,3,41,3,3,3,41,3,3,41,3,3,3,11,11,11,11,11,11
11,11,11,11,11,11,3,3,3,3,3,3,3,3,3,3,3,3,3,13,13,13,13,13,13,13,13,13,13,3,3,3,3,3,3,3,3,3,3,3,3,3,3,11,11,11,11,11,11
11,11,11,11,11,11,3,3,3,3,3,3,3,3,3,3,3,3,3,13,13,13,13,13,13,13,13,13,13,3,3,3,3,3,3,3,3,3,3,3,3,3,3,11,11,11,11,11,11
11,11,11,11,11,11,3,3,3,3,3,3,3,3,3,3,3,3,3,13,13,13,13,13,13,13,13,13,13,3,3,3,3,3,3,3,3,3,3,3,3,3,3,11,11,11,11,11,11
11,11,11,11,11,11,3,3,3,3,3,3,3,3,3,3,3,3,3,13,13,13,13,13,13,13,13,13,13,3,3,3,3,3,3,3,3,3,3,3,3,3,3,11,11,11,11,11,11
11,11,11,11,11,11,3,3,3,41,3,3,41,3,3,3,41,3,3,13,13,13,13,13,13,13,13,13,13,3,3,3,41,3,3,3,41,3,3,41,3,3,3,11,11,11,11,11,11
11,11,11,11,11,11,3,3,3,3,3,3,3,3,3,3,3,3,3,13,13,13,13,13,13,13,13,13,13,3,3,3,3,3,3,3,3,3,3,3,3,3,3,11,11,11,11,11,11
11,11,11,11,11,11,3,3,3,3,3,3,3,3,3,3,3,3,3,13,13,13,13,13,13,13,13,13,13,3,3,3,3,3,3,3,3,3,3,3,3,3,3,11,11,11,11,11,11
11,11,11,11,11,11,3,3,3,3,3,3,3,3,3,3,3,3,3,3,3,3,3,3,3,3,3,3,3,3,3,3,3,3,3,3,3,3,3,3,3,3,3,11,11,11,11,11,11
11,11,11,11,11,11,3,3,3,3,3,3,3,3,3,3,3,3,3,3,3,3,3,3,3,3,3,3,3,3,3,3,3,3,3,3,3,3,3,3,3,3,3,11,11,11,11,11,11
11,11,11,11,11,11,3,3,3,41,3,3,41,3,3,3,41,3,3,3,3,41,3,3,3,3,3,41,3,3,3,3,41,3,3,3,3,3,3,3,3,3,3,11,11,11,11,11,11
11,11,11,11,11,11,3,3,3,3,3,3,3,3,3,3,3,3,3,3,3,3,3,3,3,3,3,3,3,3,3,3,3,3,3,3,3,3,3,3,3,3,3,11,11,11,11,11,11
11,11,11,11,11,11,3,3,3,3,3,3,3,3,3,3,3,3,3,3,3,3,3,3,3,3,3,3,3,3,3,3,3,3,3,3,3,3,3,3,3,3,3,11,11,11,11,11,11
11,11,11,11,11,11,3,3,3,3,3,3,3,3,3,3,3,3,3,3,3,3,3,3,3,3,3,3,3,3,3,3,3,3,3,3,3,3,3,3,3,3,3,11,11,11,11,11,11
11,11,11,11,11,11,3,3,3,3,3,3,3,3,3,3,3,3,3,3,3,3,3,3,3,3,3,3,3,3,3,3,3,3,3,3,3,3,3,3,3,3,3,11,11,11,11,11,11
11,11,11,11,11,11,3,3,3,41,3,3,41,3,3,3,41,3,3,3,3,3,3,3,3,3,3,3,3,3,3,3,41,3,3,3,41,3,3,41,3,3,3,11,11,11,11,11,11
11,11,11,11,11,11,3,3,3,3,3,3,3,3,3,3,3,3,3,3,3,3,3,3,3,3,3,3,3,3,3,3,3,3,3,3,3,3,3,3,3,3,3,11,11,11,11,11,11
11,11,11,11,11,11,3,3,3,3,3,3,3,3,3,3,3,3,3,3,3,3,3,3,3,3,3,3,3,3,3,3,3,3,3,3,3,3,3,3,3,3,3,11,11,11,11,11,11
11,11,11,11,11,11,3,3,3,3,3,3,3,3,3,3,3,3,3,3,3,3,3,3,3,3,3,3,3,3,3,3,3,3,3,3,3,3,3,3,3,3,3,11,11,11,11,11,11
11,11,11,11,11,11,3,3,3,3,3,3,3,3,3,3,3,3,3,3,3,3,3,3,3,3,3,3,3,3,3,3,3,3,3,3,3,3,3,3,3,3,3,11,11,11,11,11,11
11,11,11,11,11,11,3,3,3,41,3,3,41,3,3,3,41,3,3,3,3,3,3,3,3,3,3,3,3,3,3,3,41,3,3,3,3,3,3,3,3,3,3,11,11,11,11,11,11
11,11,11,11,11,11,3,3,3,3,3,3,3,3,3,3,3,3,3,3,3,3,3,3,3,3,3,3,3,3,3,3,3,3,3,3,3,3,3,3,3,3,3,11,11,11,11,11,11
11,11,11,11,11,11,3,3,3,3,3,3,3,3,3,3,3,3,3,3,3,3,3,3,3,3,3,3,3,3,3,3,3,3,3,3,3,3,3,3,3,3,3,11,11,11,11,11,11
11,11,11,11,11,11,3,3,3,3,3,3,3,3,3,3,3,3,3,3,3,3,3,3,3,3,3,3,3,3,3,3,3,3,3,3,3,3,3,3,3,3,3,11,11,11,11,11,11
11,11,11,11,3,3,3,3,3,3,3,3,41,3,3,3,41,3,3,3,3,41,3,3,3,3,3,41,3,3,3,3,41,3,3,3,42,3,3,3,3,3,3,3,3,11,11,11,11
11,11,11,3,3,3,3,3,3,3,3,3,3,3,3,3,3,3,3,3,3,3,3,3,3,3,3,3,3,3,3,3,3,3,3,3,3,3,3,3,3,3,3,3,3,3,11,11,11
11,11,3,3,3,3,3,3,3,3,3,3,3,3,3,3,3,3,3,3,3,3,3,3,3,3,3,3,3,3,3,3,3,3,3,3,3,3,3,3,3,3,3,3,3,3,3,11,11
11,3,3,3,3,3,3,3,3,3,3,3,3,3,3,3,3,3,3,3,3,3,3,3,3,3,3,3,3,3,3,3,3,3,3,3,3,3,3,3,3,3,3,3,3,3,3,3,11
11,3,3,3,3,3,3,3,3,3,3,3,3,3,3,3,3,3,3,3,3,3,3,3,3,3,3,3,3,3,3,3,3,3,3,3,3,3,3,3,3,3,3,3,3,3,3,3,11
11,3,3,3,3,3,3,3,3,3,3,3,3,3,3,3,3,3,3,3,3,3,3,3,3,3,3,3,3,3,3,3,3,3,3,3,3,3,3,3,3,3,3,3,3,3,3,3,11
11,3,3,3,3,3,3,3,3,3,3,3,6,6,6,6,6,6,3,3,3,3,3,3,0,0,0,3,0,0,3,6,6,6,6,6,6,3,3,3,3,3,3,3,3,3,3,3,11
11,3,3,3,3,3,3,3,3,3,3,3,6,6,6,6,6,6,3,3,3,3,3,3,0,0,0,7,0,0,3,6,6,6,6,6,6,3,3,3,3,3,3,3,3,3,3,3,11
11,11,3,3,3,3,3,3,3,3,3,6,6,6,6,6,6,6,6,3,3,3,3,3,0,0,0,43,3,3,6,6,6,6,6,6,6,6,3,3,3,3,3,3,3,3,3,11,11
11,11,11,3,3,3,3,3,3,3,6,6,6,6,6,6,6,6,6,6,6,11,11,11,11,11,11,11,6,6,6,6,6,6,6,6,6,6,6,3,3,3,3,3,3,3,11,11,11
11,11,11,11,3,3,3,3,3,6,6,6,6,6,6,6,6,6,6,6,6,6,6,6,6,6,6,6,6,6,6,6,6,6,6,6,6,6,6,6,3,3,3,3,3,11,11,11,11
11,11,11,11,11,11,11,11,11,11,6,6,6,6,6,6,6,6,6,6,6,6,6,6,6,6,6,6,6,6,6,6,6,6,6,6,6,6,6,11,11,11,11,11,11,11,11,11,11
11,11,11,11,11,11,11,11,11,11,11,6,6,6,6,6,6,6,6,6,6,6,6,6,6,6,6,6,6,6,6,6,6,6,6,6,6,6,11,11,11,11,11,11,11,11,11,11,11
11,11,11,11,11,11,11,11,11,11,11,11,6,6,6,6,6,6,6,6,6,6,6,6,6,6,6,6,6,6,6,6,6,6,6,6,6,11,11,11,11,11,11,11,11,11,11,11,11
11,11,11,11,11,11,11,11,11,11,11,11,11,6,6,6,6,6,6,6,6,6,6,6,6,6,6,6,6,6,6,6,6,6,6,6,11,11,11,11,11,11,11,11,11,11,11,11,11
11,11,11,11,11,11,11,11,11,11,11,11,11,11,6,6,6,6,6,6,6,6,6,6,6,6,6,6,6,6,6,6,6,6,6,11,11,11,11,11,11,11,11,11,11,11,11,11,11
11,11,11,11,11,11,11,11,11,11,11,11,11,11,11,11,11,11,11,11,11,11,11,11,11,11,11,3,11,11,11,11,11,11,11,11,11,11,11,11,11,11,11,11,11,11,11,11,11
11,11,11,11,11,11,11,11,11,11,11,11,11,11,11,11,11,11,11,11,11,11,11,11,11,11,11,11,0,7,3,11,11,11,11,11,11,11,11,11,11,11,11,11,11,11,11,11,11
11,11,11,11,11,11,11,11,11,11,11,11,11,11,11,11,11,11,11,11,11,11,11,11,11,11,11,11,11,11,11,11,11,11,11,11,11,11,11,11,11,11,11,11,11,11,11,11,11
:endlayer
layer: 6
44,44,0,0,44,0,0,0,0,0,0,0,0,0,0,44,0,0,0,44,0,0,0,0,0,0,0,0,0,44,0,44,44,44,44,0,44,0,0,0,0,44,0,0,0,0,0,0,0
0,0,0,0,13,13,13,13,13,0,0,0,0,0,0,44,44,44,44,0,0,0,0,0,0,0,0,44,0,44,44,0,44,0,0,0,0,0,0,0,13,13,13,13,13,0,0,0,0
0,0,0,13,13,13,13,13,13,13,0,0,0,0,0,44,0,0,44,44,0,0,0,0,0,44,0,0,44,0,44,44,0,0,0,0,0,0,0,13,13,13,13,13,13,13,0,0,0
0,0,13,13,13,13,13,13,13,13,13,0,0,0,0,44,44,0,44,0,44,44,44,44,0,44,0,0,44,44,44,44,0,44,0,0,0,0,13,13,13,13,13,13,13,13,13,0,0
0,13,13,13,13,13,13,13,13,13,13,13,0,0,0,44,44,44,44,44,44,0,0,0,44,0,44,44,0,44,44,44,0,44,0,0,0,13,13,13,13,13,13,13,13,13,13,13,44
0,13,13,13,13,13,13,13,13,13,13,13,0,0,0,0,0,0,0,0,0,0,0,0,0,0,0,0,0,0,0,0,0,0,0,0,0,13,13,13,13,13,13,13,13,13,13,13,0
0,13,13,13,13,13,13,13,13,13,13,13,13,13,13,13,13,13,13,13,13,13,13,13,13,13,13,13,13,13,13,13,13,13,13,13,13,13,13,13,13,13,13,13,13,13,13,13,0
44,13,13,13,13,13,13,13,13,13,13,13,13,13,13,13,13,13,13,13,13,13,13,13,13,13,13,13,13,13,13,11,11,11,11,11,11,13,13,13,13,13,13,13,13,13,13,13,0
0,13,13,13,13,13,13,13,13,13,13,13,13,13,13,13,45,13,13,13,13,13,13,13,13,13,13,13,13,13,13,11,11,11,11,11,11,13,13,13,13,13,13,13,13,13,13,13,0
0,0,13,13,13,13,13,13,13,13,13,13,13,13,13,13,13,13,13,13,13,13,13,13,13,13,47,0,0,24,13,11,11,11,11,11,13,13,13,13,13,13,13,13,13,13,13,0,0
0,0,0,13,13,13,13,13,13,13,13,13,13,13,13,13,13,13,13,13,13,13,13,13,13,13,13,13,13,13,13,11,11,11,11,13,13,13,13,13,13,13,13,13,13,13,0,0,0
0,0,0,0,13,13,13,13,13,13,13,13,13,13,13,13,13,13,13,13,13,13,13,13,13,13,13,13,13,13,13,11,11,11,13,13,13,13,13,13,13,13,13,13,13,0,0,0,0
44,0,0,0,0,0,13,13,13,13,13,13,13,13,13,13,13,13,13,13,13,13,13,13,48,13,13,13,13,13,13,13,13,13,13,13,13,13,13,13,13,13,13,0,0,0,0,0,0
0,44,0,0,0,0,13,13,13,45,13,13,45,13,13,13,45,13,13,13,13,13,13,13,13,13,13,13,13,13,13,13,45,13,13,13,45,13,13,45,13,13,13,0,0,0,0,0,0
44,0,0,0,0,0,13,13,13,13,13,13,13,13,13,13,13,13,13,13,13,13,13,13,13,13,13,13,13,13,13,13,13,13,13,13,13,13,13,13,13,13,13,0,0,0,0,0,44
0,0,0,44,44,0,13,11,11,11,11,11,11,11,11,13,13,13,13,13,13,48,13,13,13,13,48,13,13,13,13,13,13,13,13,11,11,11,11,11,11,11,13,0,0,0,0,0,44
0,0,44,0,0,0,13,11,11,11,11,11,11,11,11,13,13,13,13,13,13,13,13,13,13,13,13,13,13,13,13,13,13,13,13,11,11,11,11,11,11,11,13,0,0,0,0,0,44
0,0,0,44,0,0,13,11,11,11,11,11,11,11,11,13,13,13,13,13,13,13,13,13,13,13,13,13,13,13,13,13,13,13,13,11,11,11,11,11,11,11,13,0,0,0,44,0,44
0,0,0,0,0,0,13,11,11,45,11,11,45,11,11,13,45,13,13,13,13,13,13,13,13,13,13,13,13,13,13,13,45,13,13,11,45,11,11,45,11,11,13,0,0,0,0,44,44
0,0,0,0,44,0,13,11,11,11,11,11,11,11,11,13,13,13,13,13,13,13,13,13,13,13,13,13,13,13,13,13,13,13,13,11,11,11,11,11,11,11,13,0,0,0,0,0,0
0,0,0,44,0,0,13,11,11,11,11,11,11,11,11,13,13,13,13,13,13,13,13,13,13,13,13,13,13,13,13,13,13,13,13,11,11,11,11,11,11,11,13,0,0,0,0,44,44
44,44,0,0,44,0,13,11,11,11,11,11,11,11,11,13,13,13,13,13,13,13,13,13,13,13,13,13,13,13,13,13,13,13,13,11,11,11,11,11,11,11,13,0,0,0,0,0,0
0,0,0,0,0,0,13,11,11,11,11,11,11,11,11,13,13,13,13,13,13,13,13,13,13,13,13,13,13,13,13,13,13,13,13,11,11,11,11,11,11,11,13,0,0,0,0,0,44
44,44,0,0,0,0,13,11,11,45,11,11,45,11,11,13,45,13,13,13,13,45,13,49,49,49,13,45,13,13,13,13,45,13,13,13,13,13,13,13,13,13,13,0,0,0,0,44,44
0,0,0,0,0,0,13,11,11,11,11,11,11,11,11,13,13,13,13,13,13,13,13,49,49,49,13,13,13,13,13,13,13,13,13,13,13,13,13,13,13,13,13,0,0,0,0,0,0
44,0,0,0,0,0,13,11,11,11,11,11,11,11,11,13,13,13,13,13,13,13,13,49,49,49,13,13,13,13,13,13,13,13,13,13,13,13,13,13,13,13,13,0,0,0,0,0,44
44,44,0,0,44,0,13,11,11,11,11,11,11,11,11,13,13,13,13,13,13,13,13,49,49,49,13,13,13,13,13,13,13,13,13,13,13,13,13,13,13,13,13,0,44,0,0,44,44
44,44,0,0,0,0,13,11,11,11,11,11,11,11,11,13,13,13,13,13,13,13,13,49,49,49,13,13,13,13,13,13,13,13,13,13,13,13,13,13,13,13,13,0,0,0,44,0,44
44,44,0,0,0,0,13,11,11,45,11,11,45,11,11,13,45,13,13,13,13,13,13,49,49,49,13,13,13,13,13,13,45,13,13,13,45,13,13,45,13,13,13,0,0,44,44,0,44
0,44,0,0,0,0,13,11,11,11,11,11,11,11,11,13,13,13,13,13,13,13,13,49,49,49,13,13,13,13,13,13,13,13,13,13,13,13,13,13,13,13,13,0,44,0,44,44,44
44,0,44,0,0,0,13,11,11,11,11,11,11,11,11,13,13,13,13,13,13,13,13,49,49,49,13,13,13,13,13,13,13,13,13,13,13,13,13,13,13,13,13,0,44,0,44,44,44
44,44,0,44,0,0,13,11,11,11,11,11,11,11,11,13,13,13,13,13,13,13,13,49,49,49,13,13,13,13,13,13,13,13,13,13,13,13,13,13,13,13,13,0,0,0,44,0,44
44,44,44,0,0,0,13,11,11,11,11,11,11,11,11,13,13,13,13,13,13,13,13,49,49,49,13,13,13,13,13,13,13,13,13,13,13,13,13,13,13,13,13,0,0,44,0,0,44
44,44,0,44,0,0,13,11,11,45,11,11,45,11,11,13,45,13,13,13,13,13,13,49,49,49,13,13,13,13,13,13,45,13,13,13,13,13,13,13,13,13,13,0,0,0,44,0,0
44,44,44,0,0,0,13,13,13,13,13,13,13,13,13,13,13,13,13,13,13,13,13,49,49,49,13,13,13,13,13,13,13,13,13,13,13,13,13,13,13,13,13,0,0,0,0,0,0
0,0,44,44,0,0,13,13,13,13,13,13,13,13,13,13,13,13,13,13,13,13,13,49,49,49,13,13,13,13,13,13,13,13,13,13,13,13,13,13,13,13,13,0,0,0,0,0,0
0,0,0,0,0,0,13,13,13,13,13,13,13,13,13,13,13,13,13,13,13,13,13,49,49,49,13,13,13,13,13,13,13,13,13,13,13,13,13,13,13,13,13,0,0,44,0,44,44
0,0,0,0,13,13,13,13,13,13,13,13,45,13,13,13,45,13,13,13,13,45,13,49,49,49,13,45,13,13,13,13,45,13,13,13,45,13,13,13,13,13,13,13,13,0,0,0,0
0,0,0,13,13,13,13,13,13,13,13,13,13,13,13,13,13,13,13,13,13,13,13,49,49,49,13,13,13,13,13,13,13,13,13,13,13,13,13,13,13,13,13,13,13,13,0,0,0
0,0,13,13,13,13,13,13,13,13,13,13,13,13,13,13,13,13,13,13,13,13,13,49,49,49,13,13,13,13,13,13,13,13,13,13,13,13,13,13,13,13,13,13,13,13,13,0,0
0,13,13,13,13,13,13,13,13,13,13,13,13,13,13,13,13,13,13,13,13,13,13,13,13,13,13,13,13,13,13,13,13,13,13,13,13,13,13,13,13,13,13,13,13,13,13,13,0
0,13,13,13,13,13,13,13,13,13,13,13,13,13,13,13,13,13,13,13,13,13,13,13,13,13,13,13,13,13,13,13,13,13,13,13,13,13,13,13,13,13,13,13,13,13,13,13,0
0,13,13,13,13,13,13,13,13,13,13,13,13,13,13,13,13,13,13,13,13,13,13,13,13,13,13,13,13,13,13,13,13,13,13,13,13,13,13,13,13,13,13,13,13,13,13,13,0
0,13,13,13,13,13,13,13,13,13,13,13,0,0,0,0,0,0,13,13,13,13,13,13,13,13,13,7,13,13,13,0,0,0,0,0,0,13,13,13,13,13,13,13,13,13,13,13,0
44,13,13,13,13,13,13,13,13,13,13,13,0,0,0,0,0,0,13,13,13,13,13,13,13,13,13,0,13,13,13,0,0,0,0,0,0,13,13,13,13,13,13,13,13,13,13,13,0
0,0,13,13,13,13,13,13,13,13,13,0,0,0,0,0,0,0,0,13,13,13,13,13,13,13,13,13,13,13,0,0,0,0,0,0,0,0,13,13,13,13,13,13,13,13,13,0,0
0,0,0,13,13,13,13,13,13,13,0,0,0,0,0,0,0,0,0,0,0,0,0,0,0,0,0,0,0,0,0,0,0,0,0,0,0,0,0,13,13,13,13,13,13,13,0,0,0
44,0,0,0,13,13,13,13,13,0,0,0,0,0,0,0,0,0,0,0,0,0,0,0,0,0,0,0,0,0,0,0,0,0,0,0,0,0,0,0,13,13,13,13,13,0,0,0,0
44,0,0,0,0,0,0,44,0,0,0,0,0,0,0,0,0,0,0,0,0,0,0,0,0,0,0,0,0,0,0,0,0,0,0,0,0,0,0,0,0,0,0,44,0,0,0,0,44
0,0,44,44,0,0,44,0,0,0,0,0,0,0,0,0,0,0,0,0,0,0,0,0,0,0,0,0,0,0,0,0,0,0,0,0,0,0,44,0,0,0,44,44,44,0,44,44,44
0,0,44,0,44,0,44,44,0,0,44,0,0,0,0,0,0,0,0,0,0,0,0,0,0,0,0,0,0,0,0,0,0,0,0,0,0,0,44,0,0,0,44,44,44,44,44,44,44
0,44,44,0,44,0,0,0,0,0,0,44,0,0,0,0,0,0,0,0,0,0,0,0,0,0,0,0,0,0,0,0,0,0,0,0,0,0,0,0,0,44,44,0,44,44,44,44,0
0,44,0,0,0,0,0,44,0,44,0,0,0,44,0,0,0,0,0,0,0,0,0,0,0,0,0,0,0,0,0,0,0,0,0,0,0,0,0,44,0,0,0,44,0,44,44,0,0
44,44,0,0,44,0,0,44,0,0,0,0,44,50,0,0,0,0,0,0,0,46,46,46,46,46,46,46,0,0,0,0,0,0,0,0,0,0,0,0,0,0,44,44,44,44,0,0,0
0,44,0,0,44,44,44,0,0,0,0,44,0,44,0,0,0,0,50,0,0,46,46,46,46,46,46,46,13,13,13,0,0,0,0,0,0,0,0,0,0,0,0,0,44,0,44,44,44
0,0,44,0,0,0,44,44,44,0,0,0,0,0,0,0,0,0,0,0,0,0,0,0,0,0,0,0,0,31,0,0,0,0,0,0,0,0,0,44,44,0,0,44,0,44,44,0,0
:endlayer
layer: 7
0,0,0,0,0,0,0,0,0,0,0,0,0,0,0,0,0,0,0,0,0,0,0,0,0,0,0,0,0,0,0,0,0,0,0,0,0,0,0,0,0,0,0,0,0,0,0,0,0
0,0,0,0,13,13,13,13,13,0,0,0,0,0,0,0,0,0,0,0,0,0,0,0,0,0,0,0,0,0,0,0,0,0,0,0,0,0,0,0,13,13,13,13,13,0,0,0,0
0,0,0,13,78,81,78,80,78,13,0,0,0,0,0,0,0,0,0,0,0,0,0,0,0,0,0,0,0,0,0,0,0,0,0,0,0,0,0,13,0,0,0,0,0,13,0,0,0
0,0,13,71,79,0,79,0,79,77,13,0,0,0,0,0,0,0,0,0,0,0,0,0,0,0,0,0,0,0,0,0,0,0,0,0,0,0,13,0,0,0,0,0,0,0,13,0,0
0,13,84,82,0,0,0,0,0,0,0,13,0,0,0,0,0,0,0,0,0,0,0,0,0,0,0,0,0,0,0,0,0,0,0,0,0,13,0,0,0,0,0,0,0,0,0,13,0
0,13,85,0,0,0,0,0,0,0,0,13,0,0,0,0,0,0,0,0,0,0,0,0,0,0,0,0,0,0,0,0,0,0,0,0,0,13,0,0,0,0,0,0,0,0,0,13,0
0,13,84,82,0,0,13,13,0,13,13,13,13,13,13,13,13,13,13,13,13,13,13,13,13,13,13,13,13,13,13,13,13,13,13,13,13,13,0,0,0,0,0,0,0,0,0,13,0
0,13,86,0,0,0,13,0,0,0,0,0,0,0,0,0,0,0,13,0,0,24,19,10,13,42,13,65,65,65,13,50,0,50,0,0,58,13,0,0,0,0,0,0,0,0,0,13,0
0,13,84,82,0,0,13,0,0,13,13,13,0,0,0,0,0,0,13,0,0,24,42,0,0,13,0,66,66,66,13,0,58,0,58,50,0,13,0,0,0,0,0,0,0,0,0,13,0
0,0,13,83,0,0,0,0,0,72,13,0,0,0,0,0,0,0,13,0,0,13,13,13,13,7,13,13,13,13,13,0,50,50,0,0,0,0,13,0,0,0,0,0,0,0,13,0,0
0,0,0,13,0,0,13,0,0,13,0,0,0,0,0,0,0,0,13,0,0,0,74,71,71,71,74,71,71,0,13,58,58,0,58,0,0,0,0,13,0,0,0,0,51,13,0,0,0
0,0,0,0,13,13,13,0,13,0,0,0,0,0,0,0,0,0,13,0,0,0,0,73,46,68,71,46,71,0,13,50,50,58,0,0,0,0,0,0,13,0,13,13,13,0,0,0,0
0,0,0,0,0,0,13,0,0,0,0,0,0,0,0,0,0,0,13,0,0,0,0,0,0,0,0,0,0,0,13,0,0,0,0,0,0,0,0,0,0,0,13,0,0,0,0,0,0
0,0,0,0,0,0,13,0,0,0,0,0,0,0,0,0,0,0,13,0,0,0,0,0,0,0,0,0,0,0,13,0,0,0,0,0,0,0,0,0,0,0,13,0,0,0,0,0,0
0,0,0,0,0,0,13,53,53,53,53,53,53,53,53,53,0,0,13,0,0,0,0,0,0,0,0,0,0,0,13,0,0,0,53,53,53,53,53,53,53,53,13,0,0,0,0,0,0
0,0,0,0,0,0,13,0,0,0,0,0,0,0,0,53,0,0,13,0,0,0,0,0,0,0,0,0,0,0,13,0,0,0,53,0,0,0,0,0,0,0,13,0,0,0,0,0,0
0,0,0,0,0,0,13,0,0,0,0,0,0,0,0,53,0,0,13,0,0,0,0,0,0,0,0,0,0,0,13,0,0,0,53,0,0,0,0,0,0,0,13,0,0,0,0,0,0
0,0,0,0,0,0,13,0,0,0,0,0,0,0,0,53,0,0,13,67,0,0,0,0,0,0,0,0,0,67,13,0,0,0,53,0,0,0,0,0,0,0,13,0,0,0,0,0,0
0,0,0,0,0,0,13,0,0,0,0,0,0,0,0,53,0,0,13,73,0,0,0,0,0,0,0,0,0,68,13,0,0,0,53,0,0,0,0,0,0,0,13,0,0,0,0,0,0
0,0,0,0,0,0,13,0,0,0,0,0,0,0,0,53,0,0,13,73,0,0,0,0,0,0,0,0,0,68,13,0,0,0,59,0,0,0,0,0,0,0,13,0,0,0,0,0,0
0,0,0,0,0,0,13,0,0,0,0,0,0,0,0,53,0,0,13,73,0,0,0,0,0,0,0,0,0,68,13,0,0,0,53,0,0,0,0,0,0,0,13,0,0,0,0,0,0
0,0,0,0,0,0,13,0,0,0,0,0,0,0,0,53,0,0,13,69,69,68,0,0,0,0,30,73,69,69,13,0,0,0,53,0,0,0,0,0,0,0,13,0,0,0,0,0,0
0,0,0,0,0,0,13,0,0,0,0,0,0,0,0,53,0,0,13,13,13,13,13,0,0,0,13,13,13,13,13,0,0,0,53,0,0,0,0,0,0,0,13,0,0,0,0,0,0
0,0,0,0,0,0,13,0,0,0,0,0,0,0,0,53,0,0,0,0,0,0,0,0,0,0,31,0,0,0,0,0,0,0,53,0,0,0,0,0,0,0,13,0,0,0,0,0,0
0,0,0,0,0,0,13,0,0,0,0,0,0,0,0,53,0,0,0,0,0,0,0,0,0,0,0,0,0,0,0,0,0,0,13,13,13,13,13,13,13,13,13,0,0,0,0,0,0
0,0,0,0,0,0,13,0,0,0,0,0,0,0,0,53,0,0,0,0,0,0,0,0,0,0,0,0,0,0,0,0,0,0,0,0,0,0,0,0,0,0,13,0,0,0,0,0,0
0,0,0,0,0,0,13,0,0,0,0,0,0,0,0,53,0,0,0,0,0,0,0,0,0,0,0,0,0,0,0,0,0,0,0,0,0,0,0,0,0,0,13,0,0,0,0,0,0
0,0,0,0,0,0,13,0,0,0,0,0,0,0,0,53,0,0,0,0,0,0,0,0,0,0,0,0,0,0,0,0,0,0,0,0,0,0,0,0,0,0,13,0,0,0,0,0,0
0,0,0,0,0,0,13,0,0,0,0,0,0,0,0,53,0,0,0,0,0,0,53,0,0,0,53,0,0,0,0,0,0,0,0,0,0,0,0,0,0,0,13,0,0,0,0,0,0
0,0,0,0,0,0,13,0,0,0,0,0,0,0,0,53,0,62,62,62,62,60,0,0,0,0,0,62,62,62,62,60,0,0,0,0,0,0,0,0,0,0,13,0,0,0,0,0,0
0,0,0,0,0,0,13,0,0,0,0,0,0,0,0,76,0,24,63,64,63,60,0,0,0,0,0,24,63,64,63,60,0,0,0,0,0,0,0,0,0,0,13,0,0,0,0,0,0
0,0,0,0,0,0,13,0,0,0,0,0,0,0,0,53,0,24,64,70,64,60,0,0,0,0,0,24,64,70,64,60,0,0,13,13,13,13,13,13,13,13,13,0,0,0,0,0,0
0,0,0,0,0,0,13,0,0,0,0,0,0,0,0,53,0,24,63,64,63,60,0,0,0,0,0,24,63,64,63,60,0,0,13,13,13,13,13,13,13,13,13,0,0,0,0,0,0
0,0,0,0,0,0,13,0,0,0,0,0,0,0,0,53,0,24,61,61,61,61,53,0,0,0,53,61,61,61,61,61,0,0,0,0,0,0,0,0,0,54,13,0,0,0,0,0,0
0,0,0,0,0,0,13,53,53,53,53,53,53,53,53,53,0,0,0,0,0,0,0,0,0,0,0,0,0,0,0,0,0,0,0,0,0,0,0,0,0,55,13,0,0,0,0,0,0
0,0,0,0,0,0,13,0,0,0,0,0,0,0,0,0,0,0,0,0,0,0,0,0,0,0,0,0,0,0,0,0,0,0,0,0,0,0,0,0,0,56,13,0,0,0,0,0,0
0,0,0,0,0,0,13,0,0,0,0,0,0,0,0,0,0,0,0,0,0,0,0,0,0,0,0,0,0,0,0,0,0,0,0,0,0,0,0,0,0,57,13,0,0,0,0,0,0
0,0,0,0,13,13,13,0,13,0,0,0,0,0,0,0,0,0,0,0,0,0,0,0,0,0,0,0,0,0,0,0,0,0,0,0,0,13,13,13,13,14,13,13,13,0,0,0,0
0,0,0,13,52,13,0,0,0,13,0,0,0,0,0,0,0,0,0,0,0,0,0,0,0,0,0,0,0,0,0,0,0,0,13,13,13,13,13,13,0,0,0,13,52,13,0,0,0
0,0,13,0,0,0,0,0,0,0,13,0,0,0,0,0,0,0,0,0,0,0,30,0,0,0,0,0,0,0,0,0,0,0,0,0,0,0,13,0,0,0,0,0,0,0,13,0,0
0,13,0,0,0,0,0,0,0,0,0,13,0,0,0,0,0,0,13,13,13,13,13,0,0,0,13,13,13,13,13,0,0,0,0,0,0,13,0,0,0,0,0,0,0,0,0,13,0
0,13,0,0,0,0,0,0,0,0,0,0,0,0,0,0,0,0,0,0,0,13,0,0,0,0,0,13,0,0,0,0,0,0,0,0,0,0,0,0,0,0,0,0,0,0,0,13,0
0,13,0,0,0,0,0,0,0,0,0,13,13,13,13,13,13,13,13,0,0,13,0,0,0,0,0,13,0,0,13,13,13,13,13,13,13,13,0,0,0,0,0,0,0,0,0,13,0
0,13,0,0,0,0,0,0,0,0,0,13,0,0,0,0,0,0,13,0,0,13,0,0,0,0,0,13,47,0,13,0,0,0,0,0,0,13,0,0,0,0,26,0,0,0,0,13,0
0,13,0,0,0,0,0,0,0,0,0,13,0,0,0,0,0,0,13,13,75,13,0,0,0,0,0,13,72,13,13,0,0,0,0,0,0,13,0,0,0,0,0,0,0,0,0,13,0
0,0,13,0,0,0,0,0,0,0,13,0,0,0,0,0,0,0,0,13,13,13,0,0,0,0,0,13,13,13,0,0,0,0,0,0,0,0,13,0,0,0,0,0,0,0,13,0,0
0,0,0,13,0,0,0,0,0,13,0,0,0,0,0,0,0,0,0,0,0,0,0,0,0,0,0,0,0,0,0,0,0,0,0,0,0,0,0,13,0,0,0,0,0,13,0,0,0
0,0,0,0,13,13,13,13,13,0,0,0,0,0,0,0,0,0,0,0,0,0,0,0,0,0,0,0,0,0,0,0,0,0,0,0,0,0,0,0,13,13,13,13,13,0,0,0,0
0,0,0,0,0,0,0,0,0,0,0,0,0,0,0,0,0,0,0,0,0,0,0,0,0,0,0,0,0,0,0,0,0,0,0,0,0,0,0,0,0,0,0,0,0,0,0,0,0
0,0,0,0,0,0,0,0,0,0,0,0,0,0,0,0,0,0,0,0,0,0,0,0,0,0,0,0,0,0,0,0,0,0,0,0,0,0,0,0,0,0,0,0,0,0,0,0,0
0,0,0,0,0,0,0,0,0,0,0,0,0,0,0,0,0,0,0,0,0,0,0,0,0,0,0,0,0,0,0,0,0,0,0,0,0,0,0,0,0,0,0,0,0,0,0,0,0
0,0,0,0,0,0,0,0,0,0,0,0,0,0,0,0,0,0,0,0,0,0,0,0,0,0,0,0,0,0,0,0,0,0,0,0,0,0,0,0,0,0,0,0,0,0,0,0,0
0,0,0,0,0,0,0,0,0,0,0,0,0,0,0,0,0,0,0,0,0,0,0,0,0,0,0,0,0,0,0,0,0,0,0,0,0,0,0,0,0,0,0,0,0,0,0,0,0
0,0,0,0,0,0,0,0,0,0,0,0,0,0,0,0,0,0,0,0,0,0,0,0,0,0,0,0,0,0,0,0,0,0,0,0,0,0,0,0,0,0,0,0,0,0,0,0,0
0,0,0,0,0,0,0,0,0,0,0,0,0,0,0,0,0,0,0,0,0,0,0,0,0,0,0,0,24,13,60,0,0,0,0,0,0,0,0,0,0,0,0,0,0,0,0,0,0
0,0,0,0,0,0,0,0,0,0,0,0,0,0,0,0,0,0,0,0,0,0,0,0,0,0,0,0,0,0,0,0,0,0,0,0,0,0,0,0,0,0,0,0,0,0,0,0,0
:endlayer
layer: 8
0,0,0,0,0,0,0,0,0,0,0,0,0,0,0,0,0,0,0,0,0,0,0,0,0,0,0,0,0,0,0,0,0,0,0,0,0,0,0,0,0,0,0,0,0,0,0,0,0
0,0,0,0,13,13,13,13,13,0,0,0,0,0,0,0,0,0,0,0,0,0,0,0,0,0,0,0,0,0,0,0,0,0,0,0,0,0,0,0,13,13,13,13,13,0,0,0,0
0,0,0,13,0,0,0,0,0,13,0,0,0,0,0,0,0,0,0,0,0,0,0,0,0,0,0,0,0,0,0,0,0,0,0,0,0,0,0,13,0,0,0,0,0,13,0,0,0
0,0,13,26,0,0,0,0,0,0,13,0,0,0,0,0,0,0,0,0,0,0,0,0,0,0,0,0,0,0,0,0,0,0,0,0,0,0,13,0,0,0,0,0,0,0,13,0,0
0,13,0,0,0,0,0,0,0,0,0,13,0,0,0,0,0,0,0,0,0,0,0,0,0,0,0,0,0,0,0,0,0,0,0,0,0,13,0,0,0,0,0,0,0,0,0,13,0
0,13,0,0,0,0,0,0,0,0,0,13,0,0,0,0,0,0,0,0,0,0,0,0,0,0,0,0,0,0,0,0,0,0,0,0,0,13,0,0,0,0,0,0,0,0,0,13,0
0,13,0,0,0,0,13,13,0,13,13,13,13,13,13,13,13,13,13,13,13,13,13,13,13,13,13,13,13,13,13,13,13,13,13,13,13,13,0,0,0,0,0,0,0,0,0,13,0
0,13,0,0,0,0,13,0,0,0,0,0,0,0,0,0,0,0,13,0,0,0,24,0,19,13,13,65,65,65,13,0,0,0,0,0,0,13,0,0,0,0,0,0,0,0,0,13,0
0,13,0,0,0,0,13,0,0,13,13,13,0,0,0,0,0,0,13,0,0,0,24,39,0,0,0,66,66,66,13,0,0,0,0,0,0,13,0,0,0,0,0,0,0,0,0,13,0
0,0,13,0,0,0,0,0,0,72,13,0,0,0,0,0,0,0,13,0,0,13,13,13,13,13,13,13,13,13,13,0,0,0,0,0,0,0,13,0,0,0,0,0,0,0,13,0,0
0,0,0,13,0,0,13,0,0,13,0,0,0,0,0,0,0,0,13,0,0,0,0,91,92,90,91,67,90,0,13,0,0,0,0,0,0,0,0,13,0,0,0,0,51,13,0,0,0
0,0,0,0,13,13,13,0,13,0,0,0,0,0,0,0,0,0,13,0,0,0,0,0,0,0,0,0,0,0,13,0,0,0,0,0,0,0,0,0,13,0,13,13,13,0,0,0,0
0,0,0,0,0,0,13,0,0,0,0,0,0,0,0,0,0,0,13,0,0,0,0,0,0,0,0,0,0,0,13,0,0,0,0,0,0,0,0,0,0,0,13,0,0,0,0,0,0
0,0,0,0,0,0,13,0,0,0,0,0,0,0,0,0,0,0,13,0,0,0,0,0,0,0,0,0,0,0,13,0,0,0,0,0,0,0,0,0,0,0,13,0,0,0,0,0,0
0,0,0,0,0,0,13,53,53,53,53,53,53,53,53,53,0,0,13,0,0,0,0,0,0,0,0,0,0,0,13,0,0,0,53,53,53,53,53,53,53,53,13,0,0,0,0,0,0
0,0,0,0,0,0,13,0,0,0,0,0,0,0,0,53,0,0,13,0,0,0,0,0,0,0,0,0,0,0,13,0,0,0,53,0,0,0,0,0,0,0,13,0,0,0,0,0,0
0,0,0,0,0,0,13,0,0,0,0,0,0,0,0,53,0,0,89,0,0,0,0,0,0,0,0,0,0,0,89,0,0,0,53,0,0,0,0,0,0,0,13,0,0,0,0,0,0
0,0,0,0,0,0,13,0,0,0,0,0,0,0,0,53,0,0,89,0,0,0,0,0,0,0,0,0,0,0,89,0,0,0,53,0,0,0,0,0,0,0,13,0,0,0,0,0,0
0,0,0,0,0,0,13,0,0,0,0,0,0,0,0,53,0,0,89,0,0,0,0,0,0,0,0,0,0,0,89,0,0,0,53,0,0,0,0,0,0,0,13,0,0,0,0,0,0
0,0,0,0,0,0,13,0,0,0,0,0,0,0,0,53,0,0,89,0,0,0,0,0,0,0,0,0,0,0,89,0,0,0,0,0,0,0,0,0,0,0,13,0,0,0,0,0,0
0,0,0,0,0,0,13,0,0,0,0,0,0,0,0,53,0,0,13,0,0,0,0,0,0,0,0,0,0,0,13,0,0,0,53,0,0,0,0,0,0,0,13,0,0,0,0,0,0
0,0,0,0,0,0,13,0,0,0,0,0,0,0,0,53,0,0,13,0,0,0,0,0,0,0,0,0,0,0,13,0,0,0,53,0,0,0,0,0,0,0,13,0,0,0,0,0,0
0,0,0,0,0,0,13,0,0,0,0,0,0,0,0,53,0,0,13,13,89,89,13,0,0,0,13,89,89,13,13,0,0,0,53,0,0,0,0,0,0,0,13,0,0,0,0,0,0
0,0,0,0,0,0,13,0,0,0,0,0,0,0,0,53,0,0,0,0,0,0,0,0,0,0,0,0,0,0,0,0,0,0,53,0,0,0,0,0,0,0,13,0,0,0,0,0,0
0,0,0,0,0,0,13,0,0,0,0,0,0,0,0,53,0,0,0,0,0,0,0,0,0,0,0,0,0,0,0,0,0,0,13,13,13,13,13,13,13,13,13,0,0,0,0,0,0
0,0,0,0,0,0,13,0,0,0,0,0,0,0,0,53,0,0,0,0,0,0,0,0,0,0,0,0,0,0,0,0,0,0,0,0,0,0,0,0,0,0,13,0,0,0,0,0,0
0,0,0,0,0,0,13,0,0,0,0,0,0,0,0,53,0,0,0,0,0,0,0,0,0,0,0,0,0,0,0,0,0,0,0,0,0,0,0,0,0,0,13,0,0,0,0,0,0
0,0,0,0,0,0,13,0,0,0,0,0,0,0,0,53,0,0,0,0,0,0,0,0,0,0,0,0,0,0,0,0,0,0,0,0,0,0,0,0,0,0,13,0,0,0,0,0,0
0,0,0,0,0,0,13,0,0,0,0,0,0,0,0,53,0,0,0,0,0,0,53,0,0,0,53,0,0,0,0,0,0,0,0,0,0,0,0,0,0,0,13,0,0,0,0,0,0
0,0,0,0,0,0,13,0,0,0,0,0,0,0,0,53,0,0,0,0,0,0,0,0,0,0,0,0,0,0,0,0,0,0,0,0,0,0,0,0,0,0,13,0,0,0,0,0,0
0,0,0,0,0,0,13,0,0,0,0,0,0,0,0,0,0,0,0,64,0,0,0,0,0,0,0,0,0,64,0,0,0,0,0,0,0,0,0,0,0,0,13,0,0,0,0,0,0
0,0,0,0,0,0,13,0,0,0,0,0,0,0,0,53,0,0,64,70,64,0,0,0,0,0,0,0,64,70,64,0,0,0,13,13,13,13,13,13,13,13,13,0,0,0,0,0,0
0,0,0,0,0,0,13,0,0,0,0,0,0,0,0,53,0,0,0,64,0,0,0,0,0,0,0,0,0,64,0,0,0,0,13,13,13,13,13,13,13,13,13,0,0,0,0,0,0
0,0,0,0,0,0,13,0,0,0,0,0,0,0,0,53,0,0,0,0,0,0,53,0,0,0,53,0,0,0,0,0,0,0,0,0,0,0,0,0,0,0,13,0,0,0,0,0,0
0,0,0,0,0,0,13,53,53,53,53,53,53,53,53,53,0,0,0,0,0,0,0,0,0,0,0,0,0,0,0,0,0,0,0,0,0,0,0,0,0,0,13,0,0,0,0,0,0
0,0,0,0,0,0,13,0,0,0,0,0,0,0,0,0,0,0,0,0,0,0,0,0,0,0,0,0,0,0,0,0,0,0,0,0,0,0,0,0,0,0,13,0,0,0,0,0,0
0,0,0,0,0,0,13,0,0,0,0,0,0,0,0,0,0,0,0,0,0,0,0,0,0,0,0,0,0,0,0,0,0,0,0,0,0,0,0,0,0,0,13,0,0,0,0,0,0
0,0,0,0,13,13,13,0,13,0,0,0,0,0,0,0,0,0,0,0,0,0,0,0,0,0,0,0,0,0,0,0,0,0,0,0,0,88,0,87,13,13,13,13,13,0,0,0,0
0,0,0,13,52,13,0,0,0,13,0,0,0,0,0,0,0,0,0,0,0,0,0,0,0,0,0,0,0,0,0,0,0,0,13,13,13,13,13,13,0,0,0,13,52,13,0,0,0
0,0,13,0,0,0,0,0,0,0,13,0,0,0,0,0,0,0,0,0,0,0,0,0,0,0,0,0,0,0,0,0,0,0,0,0,0,0,13,0,0,0,0,0,0,0,13,0,0
0,13,0,0,0,0,0,0,0,0,0,13,0,0,0,0,0,0,13,13,13,13,13,0,0,0,13,13,13,13,13,0,0,0,0,0,0,13,0,0,0,0,0,0,0,0,0,13,0
0,13,0,0,0,0,0,0,0,0,0,0,0,0,0,0,0,0,0,0,0,13,0,0,0,0,0,13,0,0,0,0,0,0,0,0,0,0,0,0,0,0,0,0,0,0,0,13,0
0,13,0,0,0,0,0,0,0,0,0,13,13,13,13,13,13,13,13,0,0,0,0,0,0,0,0,0,0,0,13,13,13,13,13,13,13,13,0,0,0,0,0,0,0,0,0,13,0
0,13,0,0,0,0,0,0,0,0,0,13,0,0,0,0,0,0,13,0,0,0,0,0,0,0,0,0,0,0,13,0,0,0,0,0,0,13,0,0,0,0,0,0,0,0,0,13,0
0,13,0,0,0,0,0,0,0,0,0,13,0,0,0,0,0,0,13,13,75,13,0,0,0,0,0,13,72,13,13,0,0,0,0,0,0,13,0,0,0,0,0,0,0,0,0,13,0
0,0,13,0,0,0,0,0,0,0,13,0,0,0,0,0,0,0,0,13,13,13,0,0,0,0,0,13,13,13,0,0,0,0,0,0,0,0,13,0,0,0,0,0,0,0,13,0,0
0,0,0,13,0,0,0,0,0,13,0,0,0,0,0,0,0,0,0,0,0,0,0,0,0,0,0,0,0,0,0,0,0,0,0,0,0,0,0,13,0,0,0,0,0,13,0,0,0
0,0,0,0,13,13,13,13,13,0,0,0,0,0,0,0,0,0,0,0,0,0,0,0,0,0,0,0,0,0,0,0,0,0,0,0,0,0,0,0,13,13,13,13,13,0,0,0,0
0,0,0,0,0,0,0,0,0,0,0,0,0,0,0,0,0,0,0,0,0,0,0,0,0,0,0,0,0,0,0,0,0,0,0,0,0,0,0,0,0,0,0,0,0,0,0,0,0
0,0,0,0,0,0,0,0,0,0,0,0,0,0,0,0,0,0,0,0,0,0,0,0,0,0,0,0,0,0,0,0,0,0,0,0,0,0,0,0,0,0,0,0,0,0,0,0,0
0,0,0,0,0,0,0,0,0,0,0,0,0,0,0,0,0,0,0,0,0,0,0,0,0,0,0,0,0,0,0,0,0,0,0,0,0,0,0,0,0,0,0,0,0,0,0,0,0
0,0,0,0,0,0,0,0,0,0,0,0,0,0,0,0,0,0,0,0,0,0,0,0,0,0,0,0,0,0,0,0,0,0,0,0,0,0,0,0,0,0,0,0,0,0,0,0,0
0,0,0,0,0,0,0,0,0,0,0,0,0,0,0,0,0,0,0,0,0,0,0,0,0,0,0,0,0,0,0,0,0,0,0,0,0,0,0,0,0,0,0,0,0,0,0,0,0
0,0,0,0,0,0,0,0,0,0,0,0,0,0,0,0,0,0,0,0,0,0,0,0,0,0,0,0,0,0,0,0,0,0,0,0,0,0,0,0,0,0,0,0,0,0,0,0,0
0,0,0,0,0,0,0,0,0,0,0,0,0,0,0,0,0,0,0,0,0,0,0,0,0,0,0,0,0,0,0,0,0,0,0,0,0,0,0,0,0,0,0,0,0,0,0,0,0
0,0,0,0,0,0,0,0,0,0,0,0,0,0,0,0,0,0,0,0,0,0,0,0,0,0,0,0,0,0,0,0,0,0,0,0,0,0,0,0,0,0,0,0,0,0,0,0,0
:endlayer
layer: 9
0,0,0,0,0,0,0,0,0,0,0,0,0,0,0,0,0,0,0,0,0,0,0,0,0,0,0,0,0,0,0,0,0,0,0,0,0,0,0,0,0,0,0,0,0,0,0,0,0
0,0,0,0,13,13,13,13,13,0,0,0,0,0,0,0,0,0,0,0,0,0,0,0,0,0,0,0,0,0,0,0,0,0,0,0,0,0,0,0,13,13,13,13,13,0,0,0,0
0,0,0,13,0,0,0,0,0,13,0,0,0,0,0,0,0,0,0,0,0,0,0,0,0,0,0,0,0,0,0,0,0,0,0,0,0,0,0,13,0,0,38,0,0,13,0,0,0
0,0,13,0,0,0,0,0,0,0,13,0,0,0,0,0,0,0,0,0,0,0,0,0,0,0,0,0,0,0,0,0,0,0,0,0,0,0,13,0,0,0,0,0,0,0,13,0,0
0,13,0,0,0,0,0,0,0,0,0,13,0,0,0,0,0,0,0,0,0,0,0,0,0,0,0,0,0,0,0,0,0,0,0,0,0,13,0,0,0,0,0,0,0,0,0,13,0
0,13,0,0,0,0,0,0,39,0,0,13,0,0,0,0,0,0,0,0,0,0,0,0,0,0,0,0,0,0,0,0,0,0,0,0,0,13,0,0,0,0,0,0,0,0,0,13,0
0,13,0,0,0,0,13,13,13,13,13,13,13,13,13,13,13,13,13,13,13,13,13,13,13,13,13,13,13,13,13,13,13,13,13,13,13,13,40,0,0,0,0,0,0,0,37,13,0
0,13,0,0,0,0,13,0,0,0,0,13,0,0,0,0,38,0,13,38,0,0,0,24,0,19,10,13,13,13,13,0,0,0,38,0,0,13,0,0,0,0,0,0,0,0,0,13,0
0,13,0,0,0,37,13,40,0,13,13,13,40,0,0,0,0,0,13,0,0,0,0,24,0,0,0,0,0,0,13,0,0,0,0,0,37,13,0,0,0,0,0,0,0,0,0,13,0
0,0,13,0,0,0,13,0,0,72,13,0,0,0,0,0,0,0,13,95,94,13,13,13,13,13,13,13,13,13,13,0,0,0,0,0,0,0,13,0,0,0,0,0,0,0,13,0,0
0,0,0,13,0,0,13,0,0,13,0,0,0,0,0,0,0,0,13,0,0,0,0,68,93,73,68,93,73,0,13,0,0,0,0,0,0,0,0,13,0,0,39,0,51,13,0,0,0
0,0,0,0,13,13,13,13,13,38,0,0,0,0,0,0,0,0,13,0,0,0,0,0,0,0,0,0,0,0,13,0,0,0,0,0,0,0,0,38,13,13,13,13,13,0,0,0,0
0,0,0,0,0,0,13,0,0,0,0,0,0,0,0,0,0,0,13,0,0,0,0,0,0,0,0,0,0,0,13,0,0,0,0,0,0,0,0,0,0,0,13,0,0,0,0,0,0
0,0,0,0,0,0,13,40,0,0,0,0,0,0,0,0,0,0,13,0,0,0,0,0,0,0,0,0,0,0,13,0,0,0,0,0,0,0,0,0,0,37,13,0,0,0,0,0,0
0,0,0,0,0,0,13,0,0,0,0,0,0,0,0,0,0,0,13,0,0,0,0,0,0,0,0,0,0,0,13,0,0,0,0,0,0,0,0,0,0,0,13,0,0,0,0,0,0
0,0,0,0,0,0,13,0,0,0,0,0,0,0,0,0,0,0,13,0,0,0,0,0,0,0,0,0,0,0,13,0,0,0,0,0,0,0,0,0,0,0,13,0,0,0,0,0,0
0,0,0,0,0,0,13,0,0,0,0,0,0,0,0,0,0,0,89,0,0,0,0,0,0,0,0,0,0,0,89,0,0,0,0,0,0,0,0,0,0,0,13,0,0,0,0,0,0
0,0,0,0,0,0,13,0,0,0,0,0,0,0,0,0,0,0,89,0,0,0,0,0,0,0,0,0,0,0,89,0,0,0,0,0,0,0,0,0,0,0,13,0,0,0,0,0,0
0,0,0,0,0,0,13,40,0,0,0,0,0,0,0,0,0,0,89,0,0,0,0,0,0,0,0,0,0,0,89,0,0,0,0,0,0,0,0,0,0,37,13,0,0,0,0,0,0
0,0,0,0,0,0,13,0,0,0,0,0,0,0,0,0,0,0,89,0,0,0,0,0,0,0,0,0,0,0,89,0,0,0,0,0,0,0,0,0,0,0,13,0,0,0,0,0,0
0,0,0,0,0,0,13,0,0,0,0,0,0,0,0,0,0,0,13,0,0,0,0,0,0,0,0,0,0,0,13,0,0,0,0,0,0,0,0,0,0,0,13,0,0,0,0,0,0
0,0,0,0,0,0,13,0,0,0,0,0,0,0,0,0,0,0,13,0,0,0,0,0,0,0,0,0,0,0,13,0,0,0,0,0,0,0,0,0,0,0,13,0,0,0,0,0,0
0,0,0,0,0,0,13,0,0,0,0,0,0,0,0,0,0,0,13,13,89,89,13,0,0,0,13,89,89,13,13,0,0,0,0,0,0,0,0,0,0,0,13,0,0,0,0,0,0
0,0,0,0,0,0,13,40,0,0,0,0,0,0,0,0,0,0,0,0,0,0,0,0,0,0,0,0,0,0,0,0,0,0,0,0,0,0,0,0,0,37,13,0,0,0,0,0,0
0,0,0,0,0,0,13,0,0,0,0,0,0,0,0,0,0,0,0,0,0,0,0,0,0,0,0,0,0,0,0,0,0,0,13,13,13,13,13,13,13,13,13,0,0,0,0,0,0
0,0,0,0,0,0,13,0,0,0,0,0,0,0,0,0,0,0,0,0,0,0,0,0,0,0,0,0,0,0,0,0,0,0,0,0,0,0,0,0,0,0,13,0,0,0,0,0,0
0,0,0,0,0,0,13,0,0,0,0,0,0,0,0,0,0,0,0,0,0,0,0,0,0,0,0,0,0,0,0,0,0,0,0,0,0,0,0,0,0,0,13,0,0,0,0,0,0
0,0,0,0,0,0,13,0,0,0,0,0,0,0,0,0,0,0,0,0,0,0,0,0,0,0,0,0,0,0,0,0,0,0,0,0,0,0,0,0,0,0,13,0,0,0,0,0,0
0,0,0,0,0,0,13,40,0,0,0,0,0,0,0,0,0,0,0,0,0,0,53,0,0,0,53,0,0,0,0,0,0,0,0,0,0,0,0,0,0,37,13,0,0,0,0,0,0
0,0,0,0,0,0,13,0,0,0,0,0,0,0,0,0,0,0,0,0,0,0,0,0,0,0,0,0,0,0,0,0,0,0,0,0,0,0,0,0,0,0,13,0,0,0,0,0,0
0,0,0,0,0,0,13,0,0,0,0,0,0,0,0,0,0,0,0,64,0,0,0,0,0,0,0,0,0,64,0,0,0,0,0,0,0,0,0,0,0,0,13,0,0,0,0,0,0
0,0,0,0,0,0,13,0,0,0,0,0,0,0,0,0,0,0,64,70,64,0,0,0,0,0,0,0,64,70,64,0,0,0,13,13,13,13,13,13,13,13,13,0,0,0,0,0,0
0,0,0,0,0,0,13,0,0,0,0,0,0,0,0,0,0,0,0,64,0,0,0,0,0,0,0,0,0,64,0,0,0,0,13,13,13,13,13,13,13,13,13,0,0,0,0,0,0
0,0,0,0,0,0,13,40,0,0,0,0,0,0,0,0,0,0,0,0,0,0,53,0,0,0,53,0,0,0,0,0,0,0,0,0,0,0,0,0,0,37,13,0,0,0,0,0,0
0,0,0,0,0,0,13,0,0,0,0,0,0,0,0,0,0,0,0,0,0,0,0,0,0,0,0,0,0,0,0,0,0,0,0,0,0,0,0,0,0,0,13,0,0,0,0,0,0
0,0,0,0,0,0,13,0,0,0,0,0,0,0,0,0,0,0,0,0,0,0,0,0,0,0,0,0,0,0,0,0,0,0,0,0,0,0,0,0,0,0,13,0,0,0,0,0,0
0,0,0,0,0,0,13,0,0,0,0,0,0,0,0,0,0,0,0,0,0,0,0,0,0,0,0,0,0,0,0,0,0,0,0,0,0,0,0,39,0,0,13,0,0,0,0,0,0
0,0,0,0,13,13,13,13,13,39,0,0,0,0,0,0,0,0,0,0,0,0,0,0,0,0,0,0,0,0,0,0,0,0,0,0,0,0,0,13,13,13,13,13,13,0,0,0,0
0,0,0,13,52,13,38,0,0,13,0,0,0,0,0,0,0,0,0,0,0,0,0,0,0,0,0,0,0,0,0,0,0,0,13,13,13,13,13,13,0,0,38,13,52,13,0,0,0
0,0,13,0,0,0,0,0,0,0,13,0,0,0,0,0,0,0,0,0,0,39,0,0,0,0,0,39,0,0,0,0,0,0,0,0,0,0,13,0,0,0,0,0,0,0,13,0,0
0,13,0,0,0,0,0,0,0,0,0,13,40,0,0,0,0,0,13,13,13,13,13,0,0,0,13,13,13,13,13,0,0,0,0,0,37,13,0,0,0,0,0,0,0,0,0,13,0
0,13,0,0,0,0,0,0,0,0,0,13,0,0,0,0,39,0,13,0,0,13,38,0,0,0,38,13,0,0,13,0,39,0,0,0,0,13,0,0,0,0,0,0,0,0,0,13,0
0,13,40,0,0,0,0,0,0,0,37,13,13,13,13,13,13,13,13,40,0,13,0,0,0,0,0,13,0,37,13,13,13,13,13,13,13,13,40,0,0,0,0,0,0,0,37,13,0
0,13,0,0,0,0,0,0,0,0,0,13,0,0,0,0,0,0,13,0,0,13,0,0,0,0,0,13,0,0,13,0,0,0,0,0,0,13,0,0,0,0,0,0,0,0,0,13,0
0,13,0,0,0,0,0,0,0,0,0,13,0,0,0,0,0,0,13,13,75,13,0,0,0,0,0,13,72,13,13,0,0,0,0,0,0,13,0,0,0,0,0,0,0,0,0,13,0
0,0,13,0,0,0,0,0,0,0,13,0,0,0,0,0,0,0,0,13,13,13,0,0,0,0,0,13,13,13,0,0,0,0,0,0,0,0,13,0,0,0,0,0,0,0,13,0,0
0,0,0,13,0,0,39,0,0,13,0,0,0,0,0,0,0,0,0,0,0,0,0,0,0,0,0,0,0,0,0,0,0,0,0,0,0,0,0,13,0,0,39,0,0,13,0,0,0
0,0,0,0,13,13,13,13,13,0,0,0,0,0,0,0,0,0,0,0,0,0,0,0,0,0,0,0,0,0,0,0,0,0,0,0,0,0,0,0,13,13,13,13,13,0,0,0,0
0,0,0,0,0,0,0,0,0,0,0,0,0,0,0,0,0,0,0,0,0,0,0,0,0,0,0,0,0,0,0,0,0,0,0,0,0,0,0,0,0,0,0,0,0,0,0,0,0
0,0,0,0,0,0,0,0,0,0,0,0,0,0,0,0,0,0,0,0,0,0,0,0,0,0,0,0,0,0,0,0,0,0,0,0,0,0,0,0,0,0,0,0,0,0,0,0,0
0,0,0,0,0,0,0,0,0,0,0,0,0,0,0,0,0,0,0,0,0,0,0,0,0,0,0,0,0,0,0,0,0,0,0,0,0,0,0,0,0,0,0,0,0,0,0,0,0
0,0,0,0,0,0,0,0,0,0,0,0,0,0,0,0,0,0,0,0,0,0,0,0,0,0,0,0,0,0,0,0,0,0,0,0,0,0,0,0,0,0,0,0,0,0,0,0,0
0,0,0,0,0,0,0,0,0,0,0,0,0,0,0,0,0,0,0,0,0,0,0,0,0,0,0,0,0,0,0,0,0,0,0,0,0,0,0,0,0,0,0,0,0,0,0,0,0
0,0,0,0,0,0,0,0,0,0,0,0,0,0,0,0,0,0,0,0,0,0,0,0,0,0,0,0,0,0,0,0,0,0,0,0,0,0,0,0,0,0,0,0,0,0,0,0,0
0,0,0,0,0,0,0,0,0,0,0,0,0,0,0,0,0,0,0,0,0,0,0,0,0,0,0,0,0,0,0,0,0,0,0,0,0,0,0,0,0,0,0,0,0,0,0,0,0
0,0,0,0,0,0,0,0,0,0,0,0,0,0,0,0,0,0,0,0,0,0,0,0,0,0,0,0,0,0,0,0,0,0,0,0,0,0,0,0,0,0,0,0,0,0,0,0,0
:endlayer
layer: 10
0,0,0,0,0,0,0,0,0,0,0,0,0,0,0,0,0,0,0,0,0,0,0,0,0,0,0,0,0,0,0,0,0,0,0,0,0,0,0,0,0,0,0,0,0,0,0,0,0
0,0,0,0,13,13,13,13,13,0,0,0,0,0,0,0,0,0,0,0,0,0,0,0,0,0,0,0,0,0,0,0,0,0,0,0,0,0,0,0,13,13,13,13,13,0,0,0,0
0,0,0,13,0,0,0,0,0,13,0,0,0,0,0,0,0,0,0,0,0,0,0,0,0,0,0,0,0,0,0,0,0,0,0,0,0,0,0,13,0,0,0,0,0,13,0,0,0
0,0,13,0,0,0,0,0,0,0,13,0,0,0,0,0,0,0,0,0,0,0,0,0,0,0,0,0,0,0,0,0,0,0,0,0,0,0,13,0,0,0,0,0,0,0,13,0,0
0,13,0,0,0,0,0,0,0,0,0,13,0,0,0,0,0,0,0,0,0,0,0,0,0,0,0,0,0,0,0,0,0,0,0,0,0,13,0,0,0,0,0,0,0,0,0,13,0
0,13,0,0,0,0,0,0,0,0,0,13,0,0,0,0,0,0,0,0,0,0,0,0,0,0,0,0,0,0,0,0,0,0,0,0,0,13,0,0,0,0,0,0,0,0,0,13,0
0,13,0,0,0,0,13,13,13,13,13,13,13,13,13,13,13,13,13,13,13,13,13,13,13,13,13,13,13,13,13,13,13,13,13,13,13,13,0,0,0,0,0,0,0,0,0,13,0
0,13,0,0,0,0,13,0,0,0,0,13,0,0,0,0,0,0,13,0,0,0,0,0,24,0,0,100,99,98,13,0,0,0,0,0,0,13,0,0,0,0,0,0,0,0,0,13,0
0,13,0,0,0,0,13,0,0,13,13,13,0,0,0,0,0,0,13,0,0,39,0,0,24,39,0,0,0,37,13,0,0,0,0,0,0,13,0,0,0,0,0,0,0,0,0,13,0
0,0,13,0,0,0,13,0,0,72,13,0,0,0,0,0,0,0,13,13,13,13,13,13,13,13,13,13,13,13,13,0,0,0,0,0,0,0,13,0,0,0,0,0,0,0,13,0,0
0,0,0,13,0,0,13,0,0,13,0,0,0,0,0,0,0,0,13,0,0,38,0,0,0,0,0,38,0,0,13,0,0,0,0,0,0,0,0,13,0,0,0,0,51,13,0,0,0
0,0,0,0,13,13,13,13,13,0,0,0,0,0,0,0,0,0,13,0,0,0,0,0,0,0,0,0,0,0,13,0,0,0,0,0,0,0,0,0,13,13,13,13,13,0,0,0,0
0,0,0,0,0,0,13,0,0,0,0,0,0,0,0,0,0,0,13,40,0,0,0,0,0,0,0,0,0,37,13,0,0,0,0,0,0,0,0,0,0,0,13,0,0,0,0,0,0
0,0,0,0,0,0,13,0,0,0,0,0,0,0,0,0,0,0,13,0,0,0,0,0,0,0,0,0,0,0,13,0,0,0,0,0,0,0,0,0,0,0,13,0,0,0,0,0,0
0,0,0,0,0,0,13,0,0,0,0,0,0,0,0,0,0,0,13,0,0,0,0,0,0,0,0,0,0,0,13,0,0,0,0,0,0,0,0,0,0,0,13,0,0,0,0,0,0
0,0,0,0,0,0,13,0,0,0,0,0,0,0,0,0,0,0,13,0,0,0,0,0,0,0,0,0,0,0,13,0,0,0,0,0,0,0,0,0,0,0,13,0,0,0,0,0,0
0,0,0,0,0,0,13,0,0,0,0,0,0,0,0,0,0,0,13,0,0,0,0,0,0,0,0,0,0,0,13,0,0,0,0,0,0,0,0,0,0,0,13,0,0,0,0,0,0
0,0,0,0,0,0,13,0,0,0,0,0,0,0,0,0,0,0,13,0,0,0,0,0,0,0,0,0,0,0,13,0,0,0,0,0,0,0,0,0,0,0,13,0,0,0,0,0,0
0,0,0,0,0,0,13,0,0,0,0,0,0,0,0,0,0,0,13,0,0,0,0,0,0,0,0,0,0,0,13,0,0,0,0,0,0,0,0,0,0,0,13,0,0,0,0,0,0
0,0,0,0,0,0,13,0,0,0,0,0,0,0,0,0,0,0,13,40,0,0,0,0,0,0,0,0,0,37,13,0,0,0,0,0,0,0,0,0,0,0,13,0,0,0,0,0,0
0,0,0,0,0,0,13,0,0,0,0,0,0,0,0,0,0,0,13,0,0,0,0,0,0,0,0,0,0,0,13,0,0,0,0,0,0,0,0,0,0,0,13,0,0,0,0,0,0
0,0,0,0,0,0,13,0,0,0,0,0,0,0,0,0,0,0,13,0,0,39,0,0,0,0,0,39,0,0,13,0,0,0,0,0,0,0,0,0,0,0,13,0,0,0,0,0,0
0,0,0,0,0,0,13,0,0,0,0,0,0,0,0,0,0,0,13,13,13,13,13,13,13,13,13,13,13,13,13,0,0,0,0,0,0,0,0,0,0,0,13,0,0,0,0,0,0
0,0,0,0,0,0,13,0,0,0,0,0,0,0,0,0,0,0,0,0,0,0,0,0,0,0,0,0,0,0,0,0,0,0,0,0,0,0,0,0,0,0,13,0,0,0,0,0,0
0,0,0,0,0,0,13,0,0,0,0,0,0,0,0,0,0,0,0,0,0,0,0,0,0,0,0,0,0,0,0,0,0,0,13,13,13,13,13,13,13,13,13,0,0,0,0,0,0
0,0,0,0,0,0,13,0,0,0,0,0,0,0,0,0,0,0,0,0,0,0,0,0,0,0,0,0,0,0,0,0,0,0,96,0,0,0,0,0,0,0,13,0,0,0,0,0,0
0,0,0,0,0,0,13,0,0,0,0,0,0,0,0,0,0,0,0,0,0,0,0,0,0,0,0,0,0,0,0,0,0,0,0,0,0,0,0,0,0,0,13,0,0,0,0,0,0
0,0,0,0,0,0,13,0,0,0,0,0,0,0,0,0,0,0,0,0,0,0,39,0,0,0,39,0,0,0,0,0,0,0,0,0,0,0,0,0,0,0,13,0,0,0,0,0,0
0,0,0,0,0,0,13,0,0,0,0,0,0,0,0,0,0,0,0,0,0,37,101,40,0,0,101,40,0,0,0,0,0,0,0,0,0,0,0,0,0,0,13,0,0,0,0,0,0
0,0,0,0,0,0,13,0,0,0,0,0,0,0,0,0,0,0,0,0,0,0,38,0,0,0,38,0,0,0,0,0,0,0,0,0,0,0,0,0,0,0,13,0,0,0,0,0,0
0,0,0,0,0,0,13,0,0,0,0,0,0,0,0,0,0,0,0,64,0,0,0,0,0,0,0,0,0,64,0,0,0,0,97,0,0,0,0,0,0,0,13,0,0,0,0,0,0
0,0,0,0,0,0,13,0,0,0,0,0,0,0,0,0,0,0,64,70,64,0,0,0,0,0,0,0,64,70,64,0,0,0,13,13,13,13,13,13,13,13,13,0,0,0,0,0,0
0,0,0,0,0,0,13,0,0,0,0,0,0,0,0,0,0,0,0,64,0,0,39,0,0,0,39,0,0,64,0,0,0,0,13,13,13,13,13,13,13,13,13,0,0,0,0,0,0
0,0,0,0,0,0,13,0,0,0,0,0,0,0,0,0,0,0,0,0,0,37,101,40,0,37,101,40,0,0,0,0,0,0,96,0,38,0,0,0,0,0,13,0,0,0,0,0,0
0,0,0,0,0,0,13,0,0,0,0,0,0,0,0,0,0,0,0,0,0,0,38,0,0,0,38,0,0,0,0,0,0,0,0,0,0,0,0,0,0,0,13,0,0,0,0,0,0
0,0,0,0,0,0,13,0,0,0,0,0,0,0,0,0,0,0,0,0,0,0,0,0,0,0,0,0,0,0,0,0,0,0,0,0,0,0,0,0,0,0,13,0,0,0,0,0,0
0,0,0,0,0,0,13,0,0,0,0,0,0,0,0,0,0,0,0,0,0,0,0,0,0,0,0,0,0,0,0,0,0,0,0,0,0,0,0,0,0,0,13,0,0,0,0,0,0
0,0,0,0,13,13,13,13,13,0,0,0,0,0,0,0,0,0,0,0,0,0,0,0,0,0,0,0,0,0,0,0,0,0,97,0,0,0,0,13,13,13,13,13,13,0,0,0,0
0,0,0,13,52,13,0,0,0,13,0,0,0,0,0,0,0,0,0,0,0,0,0,0,0,0,0,0,0,0,0,0,0,0,13,13,13,13,13,13,0,0,0,13,52,13,0,0,0
0,0,13,0,0,0,0,0,0,0,13,0,0,0,0,0,0,0,0,0,0,0,0,0,0,0,0,0,0,0,0,0,0,0,0,0,0,0,13,0,0,0,0,0,0,0,13,0,0
0,13,0,0,0,0,0,0,0,0,0,13,0,0,0,0,0,0,13,13,13,13,13,0,0,0,13,13,13,13,13,0,0,0,0,0,0,13,0,0,0,0,0,0,0,0,0,13,0
0,13,0,0,0,0,0,0,0,0,0,13,0,0,0,0,0,0,13,0,0,13,0,0,0,0,0,13,0,0,13,0,0,0,0,0,0,13,0,0,0,0,0,0,0,0,0,13,0
0,13,0,0,0,0,0,0,0,0,0,13,13,13,13,13,13,13,13,0,0,13,0,0,0,0,0,13,0,0,13,13,13,13,13,13,13,13,0,0,0,0,0,0,0,0,0,13,0
0,13,0,0,0,0,0,0,0,0,0,13,0,0,0,0,0,0,13,0,0,13,0,0,0,0,0,13,0,0,13,0,0,0,0,0,0,13,0,0,0,0,0,0,0,0,0,13,0
0,13,0,0,0,0,0,0,0,0,0,13,0,0,0,0,0,0,13,13,75,13,40,0,0,0,37,13,72,13,13,0,0,0,0,0,0,13,0,0,0,0,0,0,0,0,0,13,0
0,0,13,0,0,0,0,0,0,0,13,0,0,0,0,0,0,0,0,13,13,13,0,0,0,0,0,13,13,13,0,0,0,0,0,0,0,0,13,0,0,0,0,0,0,0,13,0,0
0,0,0,13,0,0,0,0,0,13,0,0,0,0,0,0,0,0,0,0,0,0,0,0,0,0,0,0,0,0,0,0,0,0,0,0,0,0,0,13,0,0,0,0,0,13,0,0,0
0,0,0,0,13,13,13,13,13,0,0,0,0,0,0,0,0,0,0,0,0,0,0,0,0,0,0,0,0,0,0,0,0,0,0,0,0,0,0,0,13,13,13,13,13,0,0,0,0
0,0,0,0,0,0,0,0,0,0,0,0,0,0,0,0,0,0,0,0,0,0,0,0,0,0,0,0,0,0,0,0,0,0,0,0,0,0,0,0,0,0,0,0,0,0,0,0,0
0,0,0,0,0,0,0,0,0,0,0,0,0,0,0,0,0,0,0,0,0,0,0,0,0,0,0,0,0,0,0,0,0,0,0,0,0,0,0,0,0,0,0,0,0,0,0,0,0
0,0,0,0,0,0,0,0,0,0,0,0,0,0,0,0,0,0,0,0,0,0,0,0,0,0,0,0,0,0,0,0,0,0,0,0,0,0,0,0,0,0,0,0,0,0,0,0,0
0,0,0,0,0,0,0,0,0,0,0,0,0,0,0,0,0,0,0,0,0,0,0,0,0,0,0,0,0,0,0,0,0,0,0,0,0,0,0,0,0,0,0,0,0,0,0,0,0
0,0,0,0,0,0,0,0,0,0,0,0,0,0,0,0,0,0,0,0,0,0,0,0,0,0,0,0,0,0,0,0,0,0,0,0,0,0,0,0,0,0,0,0,0,0,0,0,0
0,0,0,0,0,0,0,0,0,0,0,0,0,0,0,0,0,0,0,0,0,0,0,0,0,0,0,0,0,0,0,0,0,0,0,0,0,0,0,0,0,0,0,0,0,0,0,0,0
0,0,0,0,0,0,0,0,0,0,0,0,0,0,0,0,0,0,0,0,0,0,0,0,0,0,0,0,0,0,0,0,0,0,0,0,0,0,0,0,0,0,0,0,0,0,0,0,0
0,0,0,0,0,0,0,0,0,0,0,0,0,0,0,0,0,0,0,0,0,0,0,0,0,0,0,0,0,0,0,0,0,0,0,0,0,0,0,0,0,0,0,0,0,0,0,0,0
:endlayer
layer: 11
0,0,0,0,0,0,0,0,0,0,0,0,0,0,0,0,0,0,0,0,0,0,0,0,0,0,0,0,0,0,0,0,0,0,0,0,0,0,0,0,0,0,0,0,0,0,0,0,0
0,0,0,0,13,13,13,13,13,0,0,0,0,0,0,0,0,0,0,0,0,0,0,0,0,0,0,0,0,0,0,0,0,0,0,0,0,0,0,0,13,13,13,13,13,0,0,0,0
0,0,0,13,13,13,13,13,13,13,0,0,0,0,0,0,0,0,0,0,0,0,0,0,0,0,0,0,0,0,0,0,0,0,0,0,0,0,0,13,13,13,13,13,13,13,0,0,0
0,0,13,13,13,13,13,13,13,13,13,0,0,0,0,0,0,0,0,0,0,0,0,0,0,0,0,0,0,0,0,0,0,0,0,0,0,0,13,13,13,13,13,13,13,13,13,0,0
0,13,13,13,13,13,13,13,13,13,13,13,0,0,0,0,0,0,0,0,0,0,0,0,0,0,0,0,0,0,0,0,0,0,0,0,0,13,13,13,13,13,13,13,13,13,13,13,0
0,13,13,13,13,13,13,13,13,13,13,13,0,0,0,0,0,0,0,0,0,0,0,0,0,0,0,0,0,0,0,0,0,0,0,0,0,13,13,13,13,13,13,13,13,13,13,13,0
0,13,13,13,13,13,13,13,13,13,13,13,13,13,13,13,13,13,13,13,13,13,13,13,13,13,13,13,13,13,13,13,13,13,13,13,13,13,13,13,13,13,13,13,13,13,13,13,0
0,13,13,13,13,13,13,13,13,13,13,13,0,0,0,0,0,0,13,0,0,0,0,0,0,24,13,13,13,13,13,0,0,0,0,0,0,13,13,13,13,13,13,13,13,13,13,13,0
0,13,13,13,13,13,13,13,13,13,13,13,0,0,0,0,0,37,13,0,0,0,0,0,0,24,13,13,13,13,13,40,0,0,0,0,0,13,13,13,13,13,13,13,13,13,13,13,0
0,0,13,13,13,13,13,13,13,72,13,0,0,0,0,0,0,0,13,13,13,13,13,13,13,13,13,13,13,13,13,0,0,0,0,0,0,0,13,13,13,13,13,13,13,13,13,0,0
0,0,0,13,13,13,13,13,13,13,0,0,0,0,0,0,0,0,13,13,13,13,13,13,13,13,13,13,13,13,13,0,0,0,0,0,0,0,0,13,13,13,13,13,51,13,0,0,0
0,0,0,0,13,13,13,13,13,13,0,0,0,0,0,0,0,0,13,13,13,13,13,13,13,13,13,13,13,13,13,0,0,0,0,0,0,0,0,13,13,13,13,13,13,0,0,0,0
0,0,0,0,0,0,13,13,13,13,0,0,0,0,0,0,0,0,13,13,13,13,13,13,48,13,13,13,13,13,13,0,0,0,0,0,0,0,0,13,13,13,13,0,0,0,0,0,0
0,0,0,0,0,0,13,13,13,13,0,0,0,0,0,0,0,37,13,13,13,13,13,13,13,13,13,13,13,13,13,40,0,0,0,0,0,0,0,13,13,13,13,0,0,0,0,0,0
0,0,0,0,0,0,13,13,13,13,0,0,0,0,0,0,0,0,13,13,13,13,13,13,13,13,13,13,13,13,13,0,0,0,0,0,0,0,0,13,13,13,13,0,0,0,0,0,0
0,0,0,0,0,0,13,13,13,13,0,0,0,0,0,0,0,0,13,13,13,48,13,13,13,13,48,13,13,13,13,0,0,0,0,0,0,0,0,13,13,13,13,0,0,0,0,0,0
0,0,0,0,0,0,13,13,13,13,0,0,0,0,0,0,0,0,13,13,13,13,13,13,13,13,13,13,13,13,13,0,0,0,0,0,0,0,0,13,13,13,13,0,0,0,0,0,0
0,0,0,0,0,0,13,13,13,13,0,0,0,0,0,0,0,0,13,13,13,13,13,13,13,13,13,13,13,13,13,0,0,0,0,0,0,0,0,13,13,13,13,0,0,0,0,0,0
0,0,0,0,0,0,13,13,13,13,0,0,0,0,0,0,0,37,13,13,13,13,13,13,13,13,13,13,13,13,13,40,0,0,0,0,0,0,0,13,13,13,13,0,0,0,0,0,0
0,0,0,0,0,0,13,13,13,13,0,0,0,0,0,0,0,0,13,13,13,13,13,13,13,13,13,13,13,13,13,0,0,0,0,0,0,0,0,13,13,13,13,0,0,0,0,0,0
0,0,0,0,0,0,13,13,13,13,0,0,0,0,0,0,0,0,13,13,13,13,13,13,13,13,13,13,13,13,13,0,0,0,0,0,0,0,0,13,13,13,13,0,0,0,0,0,0
0,0,0,0,0,0,13,13,13,13,0,0,0,0,0,0,0,0,13,13,13,13,13,13,13,13,13,13,13,13,13,0,0,0,0,0,0,0,0,13,13,13,13,0,0,0,0,0,0
0,0,0,0,0,0,13,13,13,13,0,0,0,0,0,0,0,0,13,13,13,13,13,13,13,13,13,13,13,13,13,0,0,0,0,0,0,0,0,13,13,13,13,0,0,0,0,0,0
0,0,0,0,0,0,13,13,13,13,0,0,0,0,0,0,0,0,0,0,0,38,0,0,0,0,0,38,0,0,0,0,0,0,0,0,0,0,0,13,13,13,13,0,0,0,0,0,0
0,0,0,0,0,0,13,13,13,13,0,0,0,0,0,0,0,0,0,0,0,0,0,0,0,0,0,0,0,0,0,0,0,0,13,13,13,13,13,13,13,13,13,0,0,0,0,0,0
0,0,0,0,0,0,13,13,13,13,0,0,0,0,0,0,0,0,0,0,0,0,0,0,0,0,0,0,0,0,0,0,0,37,13,13,13,13,13,13,13,13,13,0,0,0,0,0,0
0,0,0,0,0,0,13,13,13,13,0,0,0,0,0,0,0,0,0,0,0,0,0,0,0,0,0,0,0,0,0,0,0,0,13,13,13,13,13,13,13,13,13,0,0,0,0,0,0
0,0,0,0,0,0,13,13,13,13,0,0,0,0,0,0,0,0,0,0,0,0,0,0,0,0,0,0,0,0,0,0,0,0,13,13,13,13,13,13,13,13,13,0,0,0,0,0,0
0,0,0,0,0,0,13,13,13,13,0,0,0,0,0,0,0,0,0,0,0,0,0,0,0,0,0,0,0,0,0,0,0,0,13,13,13,13,13,13,13,13,13,0,0,0,0,0,0
0,0,0,0,0,0,13,13,13,13,0,0,0,0,0,0,0,0,0,0,0,0,0,0,0,0,0,0,0,0,0,0,0,0,13,13,13,13,13,13,13,13,13,0,0,0,0,0,0
0,0,0,0,0,0,13,13,13,13,0,0,0,0,0,0,0,0,0,63,0,0,0,0,0,0,0,0,0,63,0,0,0,37,13,13,13,13,13,13,13,13,13,0,0,0,0,0,0
0,0,0,0,0,0,13,13,13,13,0,0,0,0,0,0,0,0,63,6,63,0,0,0,0,0,0,0,63,6,63,0,0,0,13,13,13,13,13,13,13,13,13,0,0,0,0,0,0
0,0,0,0,0,0,13,13,13,13,0,0,0,0,0,0,0,0,0,63,0,0,0,0,0,0,0,0,0,63,0,0,0,0,13,13,13,13,13,13,13,13,13,0,0,0,0,0,0
0,0,0,0,0,0,13,13,13,13,0,0,0,0,0,0,0,0,0,0,0,0,0,0,0,0,0,0,0,0,0,0,0,37,13,0,0,0,13,13,13,13,13,0,0,0,0,0,0
0,0,0,0,0,0,13,13,13,13,0,0,0,0,0,0,0,0,0,0,0,0,0,0,0,0,0,0,0,0,0,0,0,0,13,0,0,0,13,13,13,13,13,0,0,0,0,0,0
0,0,0,0,0,0,13,13,13,13,0,0,0,0,0,0,0,0,0,0,0,0,0,0,0,0,0,0,0,0,0,0,0,0,13,0,0,0,13,13,13,13,13,0,0,0,0,0,0
0,0,0,0,0,0,13,13,13,13,0,0,0,0,0,0,0,0,0,0,0,0,0,0,0,0,0,0,0,0,0,0,0,0,13,0,0,0,13,13,13,13,13,0,0,0,0,0,0
0,0,0,0,13,13,13,13,13,13,0,0,0,0,0,0,0,0,0,0,0,0,0,0,0,0,0,0,0,0,0,0,0,37,13,0,0,0,13,13,13,13,13,13,13,0,0,0,0
0,0,0,13,52,13,13,13,13,13,0,0,0,0,0,0,0,0,0,0,0,0,0,0,0,0,0,0,0,0,0,0,0,0,13,13,13,13,13,13,13,13,13,13,52,13,0,0,0
0,0,13,13,13,13,13,13,13,13,13,13,13,13,13,13,13,13,13,13,13,13,13,13,13,13,13,13,13,13,13,13,13,13,13,13,13,13,13,13,13,13,13,13,13,13,13,0,0
0,13,13,13,13,13,13,13,13,13,13,13,13,13,13,13,13,13,13,13,13,13,13,13,13,13,13,13,13,13,13,13,13,13,13,13,13,13,13,13,13,13,13,13,13,13,13,13,0
0,13,13,13,13,13,13,13,13,13,13,13,13,13,13,13,13,13,13,13,13,13,13,0,13,0,13,13,13,13,13,13,13,13,13,13,13,13,13,13,13,13,13,13,13,13,13,13,0
0,13,13,13,13,13,13,13,13,13,13,13,13,13,13,13,13,13,13,13,13,13,13,13,13,13,13,13,13,13,13,13,13,13,13,13,13,13,13,13,13,13,13,13,13,13,13,13,0
0,13,13,13,13,13,13,13,13,13,13,13,0,0,0,0,0,0,13,0,0,13,0,0,0,0,0,13,0,0,13,0,0,0,0,0,0,13,13,13,13,13,13,13,13,13,13,13,0
0,13,13,13,13,13,13,13,13,13,13,13,0,0,0,0,0,0,13,13,75,13,0,0,0,0,0,13,72,13,13,0,0,0,0,0,0,13,13,13,13,13,13,13,13,13,13,13,0
0,0,13,13,13,13,13,13,13,13,13,0,0,0,0,0,0,0,0,13,13,13,0,0,0,0,0,13,13,13,0,0,0,0,0,0,0,0,13,13,13,13,13,13,13,13,13,0,0
0,0,0,13,13,13,13,13,13,13,0,0,0,0,0,0,0,0,0,0,38,0,0,0,0,0,0,0,38,0,0,0,0,0,0,0,0,0,0,13,13,13,13,13,13,13,0,0,0
0,0,0,0,13,13,13,13,13,0,0,0,0,0,0,0,0,0,0,0,0,0,0,0,0,0,0,0,0,0,0,0,0,0,0,0,0,0,0,0,13,13,13,13,13,0,0,0,0
0,0,0,0,0,0,0,0,0,0,0,0,0,0,0,0,0,0,0,0,0,0,0,0,0,0,0,0,0,0,0,0,0,0,0,0,0,0,0,0,0,0,0,0,0,0,0,0,0
0,0,0,0,0,0,0,0,0,0,0,0,0,0,0,0,0,0,0,0,0,0,0,0,0,0,0,0,0,0,0,0,0,0,0,0,0,0,0,0,0,0,0,0,0,0,0,0,0
0,0,0,0,0,0,0,0,0,0,0,0,0,0,0,0,0,0,0,0,0,0,0,0,0,0,0,0,0,0,0,0,0,0,0,0,0,0,0,0,0,0,0,0,0,0,0,0,0
0,0,0,0,0,0,0,0,0,0,0,0,0,0,0,0,0,0,0,0,0,0,0,0,0,0,0,0,0,0,0,0,0,0,0,0,0,0,0,0,0,0,0,0,0,0,0,0,0
0,0,0,0,0,0,0,0,0,0,0,0,0,0,0,0,0,0,0,0,0,0,0,0,0,0,0,0,0,0,0,0,0,0,0,0,0,0,0,0,0,0,0,0,0,0,0,0,0
0,0,0,0,0,0,0,0,0,0,0,0,0,0,0,0,0,0,0,0,0,0,0,0,0,0,0,0,0,0,0,0,0,0,0,0,0,0,0,0,0,0,0,0,0,0,0,0,0
0,0,0,0,0,0,0,0,0,0,0,0,0,0,0,0,0,0,0,0,0,0,0,0,0,0,0,0,0,0,0,0,0,0,0,0,0,0,0,0,0,0,0,0,0,0,0,0,0
0,0,0,0,0,0,0,0,0,0,0,0,0,0,0,0,0,0,0,0,0,0,0,0,0,0,0,0,0,0,0,0,0,0,0,0,0,0,0,0,0,0,0,0,0,0,0,0,0
:endlayer
layer: 12
0,0,0,0,0,0,0,0,0,0,0,0,0,0,0,0,0,0,0,0,0,0,0,0,0,0,0,0,0,0,0,0,0,0,0,0,0,0,0,0,0,0,0,0,0,0,0,0,0
0,0,0,0,13,13,13,13,13,0,0,0,0,0,0,0,0,0,0,0,0,0,0,0,0,0,0,0,0,0,0,0,0,0,0,0,0,0,0,0,13,13,13,13,13,0,0,0,0
0,0,0,13,78,110,78,109,78,13,0,0,0,0,0,0,0,0,0,0,0,0,0,0,0,0,0,0,0,0,0,0,0,0,0,0,0,0,0,13,0,0,0,0,0,13,0,0,0
0,0,13,71,79,0,79,0,79,108,13,0,0,0,0,0,0,0,0,0,0,0,0,0,0,0,0,0,0,0,0,0,0,0,0,0,0,0,13,0,0,0,0,0,0,0,13,0,0
0,13,84,82,0,0,0,0,0,0,0,13,0,0,0,0,0,0,0,0,0,0,0,0,0,0,0,0,0,0,0,0,0,0,0,0,0,13,0,0,0,0,0,0,0,0,0,13,0
0,13,112,0,0,0,0,0,0,0,0,13,0,0,0,0,0,0,0,0,0,0,0,0,0,0,0,0,0,0,0,0,0,0,0,0,0,13,0,0,0,0,0,0,0,0,0,13,0
0,13,84,82,0,0,13,13,0,13,13,13,13,13,13,13,13,13,13,13,13,13,13,13,13,13,13,13,13,13,13,13,13,13,13,13,13,13,0,0,0,0,0,0,0,0,0,13,0
0,13,113,0,0,0,13,0,0,0,0,13,0,0,0,0,0,0,13,0,0,0,0,0,0,0,0,0,0,0,13,0,0,0,0,0,0,13,0,0,0,0,0,0,0,0,0,13,0
0,13,84,82,0,0,13,0,0,13,13,13,0,0,0,0,0,0,13,0,0,0,0,0,0,0,0,0,0,0,13,0,0,0,0,0,0,13,0,0,0,0,0,0,0,0,0,13,0
0,0,13,111,0,0,0,0,0,72,13,0,0,0,0,0,0,0,13,53,53,53,53,53,53,53,0,0,0,0,13,0,0,0,0,0,0,0,13,0,0,0,0,0,0,0,13,0,0
0,0,0,13,0,0,13,0,0,13,0,0,0,0,0,0,0,0,13,0,0,0,0,0,0,0,0,0,0,0,13,0,0,0,0,0,0,0,0,13,0,0,0,13,51,13,0,0,0
0,0,0,0,13,13,13,0,13,13,0,0,0,0,0,0,0,0,13,0,0,0,0,0,0,0,0,0,0,0,13,0,0,0,0,0,0,0,0,13,13,0,13,13,13,0,0,0,0
0,0,0,0,0,0,13,0,0,13,0,0,0,0,0,0,0,0,13,0,0,0,0,0,0,0,0,0,0,0,13,0,0,0,0,0,0,0,0,13,0,0,13,0,0,0,0,0,0
0,0,0,0,0,0,13,0,0,13,0,0,0,0,0,0,0,0,13,67,0,0,0,0,0,0,0,0,0,67,13,0,0,0,0,0,0,0,0,13,0,0,13,0,0,0,0,0,0
0,0,0,0,0,0,13,0,0,13,0,0,0,0,0,0,0,0,13,73,0,0,0,0,0,0,0,0,0,68,13,0,0,0,0,0,0,0,0,13,0,0,13,0,0,0,0,0,0
0,0,0,0,0,0,13,0,0,13,0,0,0,0,0,0,0,0,13,69,0,0,0,0,0,0,0,0,0,69,13,0,0,0,0,0,0,0,0,13,0,0,13,0,0,0,0,0,0
0,0,0,0,0,0,13,0,0,13,0,0,0,0,0,0,0,0,13,0,0,0,0,0,0,0,0,0,0,0,13,0,0,0,0,0,0,0,0,13,0,0,13,0,0,0,0,0,0
0,0,0,0,0,0,13,0,0,13,0,0,0,0,0,0,0,0,13,0,0,0,0,0,0,0,0,0,0,0,13,0,0,0,0,0,0,0,0,13,0,0,13,0,0,0,0,0,0
0,0,0,0,0,0,13,0,0,13,0,0,0,0,0,0,0,0,13,0,0,0,71,46,46,46,71,0,0,0,13,0,0,0,0,0,0,0,0,13,0,0,13,0,0,0,0,0,0
0,0,0,0,0,0,13,0,0,13,0,0,0,0,0,0,0,0,13,0,0,0,68,104,104,104,73,0,0,0,13,0,0,0,0,0,0,0,0,13,0,0,13,0,0,0,0,0,0
0,0,0,0,0,0,13,0,0,13,0,0,0,0,0,0,0,0,13,0,0,0,68,105,105,105,73,0,0,0,13,0,0,0,0,0,0,0,0,13,0,0,13,0,0,0,0,0,0
0,0,0,0,0,0,13,0,0,13,0,0,0,0,0,0,0,0,13,107,26,106,71,71,71,71,71,103,26,102,13,0,0,0,0,0,0,0,0,13,0,0,13,0,0,0,0,0,0
0,0,0,0,0,0,13,0,0,13,0,0,0,0,0,0,0,0,13,13,13,13,13,13,13,13,13,13,13,13,13,0,0,0,0,0,0,0,0,13,0,0,13,0,0,0,0,0,0
0,0,0,0,0,0,13,0,0,13,0,0,0,0,0,0,0,0,0,0,0,0,0,0,0,0,0,0,0,0,0,0,0,0,0,0,0,0,0,13,0,0,13,0,0,0,0,0,0
0,0,0,0,0,0,13,0,0,13,0,0,0,0,0,0,0,0,0,0,0,0,0,0,0,0,0,0,0,0,0,0,0,0,69,69,69,69,69,13,0,0,13,0,0,0,0,0,0
0,0,0,0,0,0,13,0,0,13,0,0,0,0,0,0,0,0,0,0,0,0,0,0,0,0,0,0,0,0,0,0,0,0,68,71,0,0,73,13,0,0,13,0,0,0,0,0,0
0,0,0,0,0,0,13,0,0,13,0,0,0,0,0,0,0,0,0,0,0,0,0,0,0,0,0,0,0,0,0,0,0,0,68,71,0,0,73,13,0,0,13,0,0,0,0,0,0
0,0,0,0,0,0,13,0,0,13,0,0,0,0,0,0,0,0,0,0,0,0,0,0,0,0,0,0,0,0,0,0,0,0,68,71,0,0,73,13,0,0,13,0,0,0,0,0,0
0,0,0,0,0,0,13,0,0,13,0,0,0,0,0,0,0,0,0,0,0,0,0,0,0,0,0,0,0,0,0,0,0,0,68,71,0,0,73,13,0,0,13,0,0,0,0,0,0
0,0,0,0,0,0,13,0,0,13,0,0,0,0,0,0,0,0,0,0,0,0,0,0,0,0,0,0,0,0,0,0,0,0,68,71,0,0,73,13,0,0,13,0,0,0,0,0,0
0,0,0,0,0,0,13,0,0,13,0,0,0,0,0,0,0,0,0,0,0,0,0,0,0,0,0,0,0,0,0,0,0,0,68,71,0,0,73,13,0,0,13,0,0,0,0,0,0
0,0,0,0,0,0,13,0,0,13,0,0,0,0,0,0,0,0,0,0,0,0,0,0,0,0,0,0,0,0,0,0,0,0,67,67,67,67,67,13,0,0,13,0,0,0,0,0,0
0,0,0,0,0,0,13,0,0,13,0,0,0,0,0,0,0,0,0,0,0,0,0,0,0,0,0,0,0,0,0,0,0,0,69,69,69,69,69,13,0,0,13,0,0,0,0,0,0
0,0,0,0,0,0,13,0,0,13,0,0,0,0,0,0,0,0,0,0,0,0,0,0,0,0,0,0,0,0,0,0,0,0,71,0,0,0,71,13,0,0,13,0,0,0,0,0,0
0,0,0,0,0,0,13,0,0,13,0,0,0,0,0,0,0,0,0,0,0,0,0,0,0,0,0,0,0,0,0,0,0,0,13,0,0,0,71,13,0,0,13,0,0,0,0,0,0
0,0,0,0,0,0,13,0,0,13,0,0,0,0,0,0,0,0,0,0,0,0,0,0,0,0,0,0,0,0,0,0,0,0,13,0,0,0,71,13,0,0,13,0,0,0,0,0,0
0,0,0,0,0,0,13,0,0,13,0,0,0,0,0,0,0,0,0,0,0,0,0,0,0,0,0,0,0,0,0,0,0,0,13,0,0,0,71,13,0,0,13,0,0,0,0,0,0
0,0,0,0,13,13,13,0,13,13,0,0,0,0,0,0,0,0,0,0,0,0,0,0,0,0,0,0,0,0,0,0,0,0,71,0,0,0,71,13,13,0,13,13,13,0,0,0,0
0,0,0,13,52,13,0,0,0,13,0,0,0,0,0,0,0,0,0,0,0,0,0,0,0,0,0,0,0,0,0,0,0,0,67,67,67,67,67,13,0,0,0,13,52,13,0,0,0
0,0,13,0,0,0,0,0,0,0,13,13,13,13,13,13,13,13,13,13,13,13,13,13,13,13,13,13,13,13,13,13,13,13,13,13,13,13,13,0,0,0,0,0,0,0,13,0,0
0,13,0,0,0,0,0,0,0,0,0,13,0,0,0,0,0,0,0,0,0,0,0,0,0,0,0,0,0,0,0,0,0,0,0,0,0,13,0,0,0,0,0,0,0,0,0,13,0
0,13,0,0,0,0,0,0,0,0,0,0,0,0,0,0,0,0,13,13,13,13,0,0,0,0,0,13,13,13,0,0,0,0,0,0,0,0,0,0,0,0,0,0,0,0,0,13,0
0,13,0,0,0,0,0,0,0,0,0,13,13,13,13,13,13,13,13,13,13,13,13,13,13,13,13,13,13,13,13,13,13,13,13,13,13,13,0,0,0,0,0,0,0,0,0,13,0
0,13,0,0,0,0,0,0,0,0,0,13,0,0,0,0,0,0,13,0,0,13,13,13,13,13,13,13,0,0,13,0,0,0,0,0,0,13,0,0,0,0,0,0,0,0,0,13,0
0,13,0,0,0,0,0,0,0,0,0,13,0,0,0,0,0,0,13,13,75,13,0,0,0,0,0,13,72,13,13,0,0,0,0,0,0,13,0,0,0,0,0,0,0,0,0,13,0
0,0,13,0,0,0,0,0,0,0,13,0,0,0,0,0,0,0,0,13,13,13,0,0,0,0,0,13,13,13,0,0,0,0,0,0,0,0,13,0,0,0,0,0,0,0,13,0,0
0,0,0,13,0,0,0,0,0,13,0,0,0,0,0,0,0,0,0,0,0,0,0,0,0,0,0,0,0,0,0,0,0,0,0,0,0,0,0,13,0,0,0,0,0,13,0,0,0
0,0,0,0,13,13,13,13,13,0,0,0,0,0,0,0,0,0,0,0,0,0,0,0,0,0,0,0,0,0,0,0,0,0,0,0,0,0,0,0,13,13,13,13,13,0,0,0,0
0,0,0,0,0,0,0,0,0,0,0,0,0,0,0,0,0,0,0,0,0,0,0,0,0,0,0,0,0,0,0,0,0,0,0,0,0,0,0,0,0,0,0,0,0,0,0,0,0
0,0,0,0,0,0,0,0,0,0,0,0,0,0,0,0,0,0,0,0,0,0,0,0,0,0,0,0,0,0,0,0,0,0,0,0,0,0,0,0,0,0,0,0,0,0,0,0,0
0,0,0,0,0,0,0,0,0,0,0,0,0,0,0,0,0,0,0,0,0,0,0,0,0,0,0,0,0,0,0,0,0,0,0,0,0,0,0,0,0,0,0,0,0,0,0,0,0
0,0,0,0,0,0,0,0,0,0,0,0,0,0,0,0,0,0,0,0,0,0,0,0,0,0,0,0,0,0,0,0,0,0,0,0,0,0,0,0,0,0,0,0,0,0,0,0,0
0,0,0,0,0,0,0,0,0,0,0,0,0,0,0,0,0,0,0,0,0,0,0,0,0,0,0,0,0,0,0,0,0,0,0,0,0,0,0,0,0,0,0,0,0,0,0,0,0
0,0,0,0,0,0,0,0,0,0,0,0,0,0,0,0,0,0,0,0,0,0,0,0,0,0,0,0,0,0,0,0,0,0,0,0,0,0,0,0,0,0,0,0,0,0,0,0,0
0,0,0,0,0,0,0,0,0,0,0,0,0,0,0,0,0,0,0,0,0,0,0,0,0,0,0,0,0,0,0,0,0,0,0,0,0,0,0,0,0,0,0,0,0,0,0,0,0
0,0,0,0,0,0,0,0,0,0,0,0,0,0,0,0,0,0,0,0,0,0,0,0,0,0,0,0,0,0,0,0,0,0,0,0,0,0,0,0,0,0,0,0,0,0,0,0,0
:endlayer
layer: 13
0,0,0,0,0,0,0,0,0,0,0,0,0,0,0,0,0,0,0,0,0,0,0,0,0,0,0,0,0,0,0,0,0,0,0,0,0,0,0,0,0,0,0,0,0,0,0,0,0
0,0,0,0,13,13,13,13,13,0,0,0,0,0,0,0,0,0,0,0,0,0,0,0,0,0,0,0,0,0,0,0,0,0,0,0,0,0,0,0,13,13,13,13,13,0,0,0,0
0,0,0,13,0,0,0,0,0,13,0,0,0,0,0,0,0,0,0,0,0,0,0,0,0,0,0,0,0,0,0,0,0,0,0,0,0,0,0,13,0,0,0,0,0,13,0,0,0
0,0,13,26,0,0,0,0,0,0,13,0,0,0,0,0,0,0,0,0,0,0,0,0,0,0,0,0,0,0,0,0,0,0,0,0,0,0,13,0,0,0,0,0,0,0,13,0,0
0,13,0,0,0,0,0,0,0,0,0,13,0,0,0,0,0,0,0,0,0,0,0,0,0,0,0,0,0,0,0,0,0,0,0,0,0,13,0,0,0,0,0,0,0,0,0,13,0
0,13,0,0,0,0,0,0,0,0,0,13,0,0,0,0,0,0,0,0,0,0,0,0,0,0,0,0,0,0,0,0,0,0,0,0,0,13,0,0,0,0,0,0,0,0,0,13,0
0,13,0,0,0,0,13,13,0,13,13,13,13,13,13,13,13,13,13,13,13,13,13,13,13,13,13,13,13,13,13,13,13,13,13,13,13,13,0,0,0,0,0,0,0,0,0,13,0
0,13,0,0,0,0,13,0,0,0,0,13,0,0,0,0,0,0,13,0,0,0,0,0,0,0,0,0,0,0,13,0,0,0,0,0,0,13,0,0,0,0,0,0,0,0,0,13,0
0,13,0,0,0,0,13,0,0,13,13,13,0,0,0,0,0,0,13,0,0,0,0,0,0,0,0,0,0,0,13,0,0,0,0,0,0,13,0,0,0,0,0,0,0,0,0,13,0
0,0,13,0,0,0,0,0,0,72,13,0,0,0,0,0,0,0,13,0,0,0,0,0,0,0,0,0,0,0,13,0,0,0,0,0,0,0,13,0,0,0,0,0,0,0,13,0,0
0,0,0,13,0,0,13,0,0,13,0,0,0,0,0,0,0,0,13,0,0,0,0,0,0,0,0,0,0,0,13,0,0,0,0,0,0,0,0,13,0,0,0,13,51,13,0,0,0
0,0,0,0,13,13,13,0,13,0,0,0,0,0,0,0,0,0,89,0,0,0,0,0,0,0,0,0,0,0,89,0,0,0,0,0,0,0,0,0,13,0,13,13,13,0,0,0,0
0,0,0,0,0,0,13,0,0,0,0,0,0,0,0,0,0,0,89,0,0,0,0,0,0,0,0,0,0,0,89,0,0,0,0,0,0,0,0,0,0,0,13,0,0,0,0,0,0
0,0,0,0,0,0,13,0,0,0,0,0,0,0,0,0,0,0,89,0,0,0,0,0,0,0,0,0,0,0,89,0,0,0,0,0,0,0,0,0,0,0,13,0,0,0,0,0,0
0,0,0,0,0,0,13,0,0,0,0,0,0,0,0,0,0,0,13,0,0,0,0,0,0,0,0,0,0,0,13,0,0,0,0,0,0,0,0,0,0,0,13,0,0,0,0,0,0
0,0,0,0,0,0,13,0,0,0,0,0,0,0,0,0,0,0,13,0,0,0,0,0,0,0,0,0,0,0,13,0,0,0,0,0,0,0,0,0,0,0,13,0,0,0,0,0,0
0,0,0,0,0,0,13,0,0,0,0,0,0,0,0,0,0,0,13,0,0,0,0,0,0,0,0,0,0,0,13,0,0,0,0,0,0,0,0,0,0,0,13,0,0,0,0,0,0
0,0,0,0,0,0,13,0,0,0,0,0,0,0,0,0,0,0,13,0,0,0,0,0,0,0,0,0,0,0,13,0,0,0,0,0,0,0,0,0,0,0,13,0,0,0,0,0,0
0,0,0,0,0,0,13,0,0,0,0,0,0,0,0,0,0,0,89,0,0,0,53,0,0,0,53,0,0,0,89,0,0,0,0,0,0,0,0,0,0,0,13,0,0,0,0,0,0
0,0,0,0,0,0,13,0,0,0,0,0,0,0,0,0,0,0,89,0,0,0,0,0,0,0,0,0,0,0,89,0,0,0,0,0,0,0,0,0,0,0,13,0,0,0,0,0,0
0,0,0,0,0,0,13,0,0,0,0,0,0,0,0,0,0,0,89,0,0,0,0,0,0,0,0,0,0,0,89,0,0,0,0,0,0,0,0,0,0,0,13,0,0,0,0,0,0
0,0,0,0,0,0,13,0,0,0,0,0,0,0,0,0,0,0,13,0,0,0,53,69,69,69,53,0,0,0,13,0,0,0,0,0,0,0,0,0,0,0,13,0,0,0,0,0,0
0,0,0,0,0,0,13,0,0,0,0,0,0,0,0,0,0,0,13,13,89,89,13,13,13,13,13,89,89,13,13,0,0,0,0,0,0,0,0,0,0,0,13,0,0,0,0,0,0
0,0,0,0,0,0,13,0,0,0,0,0,0,0,0,0,0,0,0,0,0,0,0,0,0,0,0,0,0,0,0,0,0,0,0,0,0,0,0,0,0,0,13,0,0,0,0,0,0
0,0,0,0,0,0,13,0,0,0,0,0,0,0,0,0,0,0,0,0,0,0,0,0,0,0,0,0,0,0,0,0,0,0,0,0,0,0,0,0,0,0,13,0,0,0,0,0,0
0,0,0,0,0,0,13,0,0,0,0,0,0,0,0,0,0,0,0,0,0,0,0,0,0,0,0,0,0,0,0,0,0,0,0,68,69,73,0,0,0,0,13,0,0,0,0,0,0
0,0,0,0,0,0,13,0,0,0,0,0,0,0,0,0,0,0,0,0,0,0,0,0,0,0,0,0,0,0,0,0,0,0,0,68,71,73,0,0,0,0,13,0,0,0,0,0,0
0,0,0,0,0,0,13,0,0,0,0,0,0,0,0,0,0,0,0,0,0,0,0,0,0,0,0,0,0,0,0,0,0,0,0,68,71,73,0,0,0,0,13,0,0,0,0,0,0
0,0,0,0,0,0,13,0,0,0,0,0,0,0,0,0,0,0,0,0,0,0,0,0,0,0,0,0,0,0,0,0,0,0,0,68,71,73,0,0,0,0,13,0,0,0,0,0,0
0,0,0,0,0,0,13,0,0,0,0,0,0,0,0,0,0,0,0,0,0,0,0,0,0,0,0,0,0,0,0,0,0,0,0,68,71,73,0,0,0,0,13,0,0,0,0,0,0
0,0,0,0,0,0,13,0,0,0,0,0,0,0,0,0,0,0,0,0,0,0,0,0,0,0,0,0,0,0,0,0,0,0,0,68,67,73,0,0,0,0,13,0,0,0,0,0,0
0,0,0,0,0,0,13,0,0,0,0,0,0,0,0,0,0,0,0,0,0,0,0,0,0,0,0,0,0,0,0,0,0,0,0,0,0,0,0,0,0,0,13,0,0,0,0,0,0
0,0,0,0,0,0,13,0,0,0,0,0,0,0,0,0,0,0,0,0,0,0,0,0,0,0,0,0,0,0,0,0,0,0,0,0,0,0,0,0,0,0,13,0,0,0,0,0,0
0,0,0,0,0,0,13,0,0,0,0,0,0,0,0,0,0,0,0,0,0,0,0,0,0,0,0,0,0,0,0,0,0,0,69,69,69,69,69,0,0,0,13,0,0,0,0,0,0
0,0,0,0,0,0,13,0,0,0,0,0,0,0,0,0,0,0,0,0,0,0,0,0,0,0,0,0,0,0,0,0,0,0,71,0,0,0,71,0,0,0,13,0,0,0,0,0,0
0,0,0,0,0,0,13,0,0,0,0,0,0,0,0,0,0,0,0,0,0,0,0,0,0,0,0,0,0,0,0,0,0,0,71,0,0,0,71,0,0,0,13,0,0,0,0,0,0
0,0,0,0,0,0,13,0,0,0,0,0,0,0,0,0,0,0,0,0,0,0,0,0,0,0,0,0,0,0,0,0,0,0,71,0,0,0,71,0,0,0,13,0,0,0,0,0,0
0,0,0,0,13,13,13,0,13,0,0,0,0,0,0,0,0,0,0,0,0,0,0,0,0,0,0,0,0,0,0,0,0,0,67,67,67,67,67,0,13,0,13,13,13,0,0,0,0
0,0,0,13,52,13,0,0,0,13,0,0,0,0,0,0,0,0,0,0,0,0,0,0,0,0,0,0,0,0,0,0,0,0,0,0,0,0,0,13,0,0,0,13,52,13,0,0,0
0,0,13,0,0,0,0,0,0,0,13,0,0,0,0,0,0,0,0,0,0,0,0,0,0,0,0,0,0,0,0,0,0,0,0,0,0,0,13,0,0,0,0,0,0,0,13,0,0
0,13,0,0,0,0,0,0,0,0,0,13,0,0,0,0,0,0,0,0,0,0,0,0,0,0,0,0,0,0,0,0,0,0,0,0,0,13,0,0,0,0,0,0,0,0,0,13,0
0,13,0,0,0,0,0,0,0,0,0,0,0,0,0,0,0,0,13,13,13,13,0,0,0,0,0,13,13,13,0,0,0,0,0,0,0,0,0,0,0,0,0,0,0,0,0,13,0
0,13,0,0,0,0,0,0,0,0,0,13,13,13,13,13,13,13,13,13,13,13,13,13,13,13,13,13,13,13,13,13,13,13,13,13,13,13,0,0,0,0,0,0,0,0,0,13,0
0,13,0,0,0,0,0,0,0,0,0,13,0,0,0,0,0,13,13,13,13,13,13,13,13,13,13,13,13,13,13,13,0,0,0,0,0,13,0,0,0,0,0,0,0,0,0,13,0
0,13,0,0,0,0,0,0,0,0,0,13,0,0,0,0,0,13,13,13,75,13,13,0,13,0,13,13,72,13,13,13,0,0,0,0,0,13,0,0,0,0,0,0,0,0,0,13,0
0,0,13,0,0,0,0,0,0,0,13,0,0,0,0,0,0,13,13,13,13,13,13,13,13,13,13,13,13,13,13,13,0,0,0,0,0,0,13,0,0,0,0,0,0,0,13,0,0
0,0,0,13,0,0,0,0,0,13,0,0,0,0,0,0,0,0,13,13,13,13,13,13,13,13,13,13,13,13,13,0,0,0,0,0,0,0,0,13,0,0,0,0,0,13,0,0,0
0,0,0,0,13,13,13,13,13,0,0,0,0,0,0,0,0,0,0,0,0,0,0,0,0,0,0,0,0,0,0,0,0,0,0,0,0,0,0,0,13,13,13,13,13,0,0,0,0
0,0,0,0,0,0,0,0,0,0,0,0,0,0,0,0,0,0,0,0,0,0,0,0,0,0,0,0,0,0,0,0,0,0,0,0,0,0,0,0,0,0,0,0,0,0,0,0,0
0,0,0,0,0,0,0,0,0,0,0,0,0,0,0,0,0,0,0,0,0,0,0,0,0,0,0,0,0,0,0,0,0,0,0,0,0,0,0,0,0,0,0,0,0,0,0,0,0
0,0,0,0,0,0,0,0,0,0,0,0,0,0,0,0,0,0,0,0,0,0,0,0,0,0,0,0,0,0,0,0,0,0,0,0,0,0,0,0,0,0,0,0,0,0,0,0,0
0,0,0,0,0,0,0,0,0,0,0,0,0,0,0,0,0,0,0,0,0,0,0,0,0,0,0,0,0,0,0,0,0,0,0,0,0,0,0,0,0,0,0,0,0,0,0,0,0
0,0,0,0,0,0,0,0,0,0,0,0,0,0,0,0,0,0,0,0,0,0,0,0,0,0,0,0,0,0,0,0,0,0,0,0,0,0,0,0,0,0,0,0,0,0,0,0,0
0,0,0,0,0,0,0,0,0,0,0,0,0,0,0,0,0,0,0,0,0,0,0,0,0,0,0,0,0,0,0,0,0,0,0,0,0,0,0,0,0,0,0,0,0,0,0,0,0
0,0,0,0,0,0,0,0,0,0,0,0,0,0,0,0,0,0,0,0,0,0,0,0,0,0,0,0,0,0,0,0,0,0,0,0,0,0,0,0,0,0,0,0,0,0,0,0,0
0,0,0,0,0,0,0,0,0,0,0,0,0,0,0,0,0,0,0,0,0,0,0,0,0,0,0,0,0,0,0,0,0,0,0,0,0,0,0,0,0,0,0,0,0,0,0,0,0
:endlayer
layer: 14
0,0,0,0,0,0,0,0,0,0,0,0,0,0,0,0,0,0,0,0,0,0,0,0,0,0,0,0,0,0,0,0,0,0,0,0,0,0,0,0,0,0,0,0,0,0,0,0,0
0,0,0,0,13,13,13,13,13,0,0,0,0,0,0,0,0,0,0,0,0,0,0,0,0,0,0,0,0,0,0,0,0,0,0,0,0,0,0,0,13,13,13,13,13,0,0,0,0
0,0,0,13,0,0,0,0,0,13,0,0,0,0,0,0,0,0,0,0,0,0,0,0,0,0,0,0,0,0,0,0,0,0,0,0,0,0,0,13,0,0,38,0,0,13,0,0,0
0,0,13,0,0,0,0,0,0,0,13,0,0,0,0,0,0,0,0,0,0,0,0,0,0,0,0,0,0,0,0,0,0,0,0,0,0,0,13,0,0,0,0,0,0,0,13,0,0
0,13,0,0,0,0,0,0,0,0,0,13,0,0,0,0,0,0,0,0,0,0,0,0,0,0,0,0,0,0,0,0,0,0,0,0,0,13,0,0,0,0,0,0,0,0,0,13,0
0,13,0,0,0,0,0,0,39,0,0,13,0,0,0,0,0,0,0,0,0,0,0,0,0,0,0,0,0,0,0,0,0,0,0,0,0,13,0,0,0,0,0,0,0,0,0,13,0
0,13,0,0,0,0,13,13,13,13,13,13,13,13,13,13,13,13,13,13,13,13,13,13,13,13,13,13,13,13,13,13,13,13,13,13,13,13,40,0,0,0,0,0,0,0,37,13,0
0,13,0,0,0,0,13,0,38,0,0,13,0,0,0,0,0,0,13,0,38,0,0,0,38,0,0,0,38,0,13,0,0,0,0,0,0,13,0,0,0,0,0,0,0,0,0,13,0
0,13,0,0,0,37,13,40,0,13,13,13,0,0,0,0,0,0,13,0,0,0,0,0,0,0,0,0,0,0,13,0,0,0,0,0,0,13,0,0,0,0,0,0,0,0,0,13,0
0,0,13,0,0,0,13,0,0,72,13,0,0,0,0,0,0,0,13,0,0,0,0,0,0,0,0,0,0,0,13,0,0,0,0,0,0,0,13,0,0,0,0,0,0,0,13,0,0
0,0,0,13,0,0,13,0,0,13,0,0,0,0,0,0,0,0,13,40,0,0,0,0,0,0,0,0,0,37,13,0,0,0,0,0,0,0,0,13,0,0,39,13,51,13,0,0,0
0,0,0,0,13,13,13,13,13,0,0,0,0,0,0,0,0,0,89,0,0,0,0,0,0,0,0,0,0,0,89,0,0,0,0,0,0,0,0,0,13,13,13,13,13,0,0,0,0
0,0,0,0,0,0,13,0,0,0,0,0,0,0,0,0,0,0,89,0,0,0,0,0,0,0,0,0,0,0,89,0,0,0,0,0,0,0,0,0,0,0,13,0,0,0,0,0,0
0,0,0,0,0,0,13,40,0,0,0,0,0,0,0,0,0,0,89,0,0,0,0,0,0,0,0,0,0,0,89,0,0,0,0,0,0,0,0,0,0,37,13,0,0,0,0,0,0
0,0,0,0,0,0,13,0,0,0,0,0,0,0,0,0,0,0,13,0,0,0,0,0,0,0,0,0,0,0,13,0,0,0,0,0,0,0,0,0,0,0,13,0,0,0,0,0,0
0,0,0,0,0,0,13,0,0,0,0,0,0,0,0,0,0,0,13,0,0,0,0,0,0,0,0,0,0,0,13,0,0,0,0,0,0,0,0,0,0,0,13,0,0,0,0,0,0
0,0,0,0,0,0,13,0,0,0,0,0,0,0,0,0,0,0,13,0,0,0,0,0,0,0,0,0,0,0,13,0,0,0,0,0,0,0,0,0,0,0,13,0,0,0,0,0,0
0,0,0,0,0,0,13,0,0,0,0,0,0,0,0,0,0,0,13,0,0,0,0,0,0,0,0,0,0,0,13,0,0,0,0,0,0,0,0,0,0,0,13,0,0,0,0,0,0
0,0,0,0,0,0,13,40,0,0,0,0,0,0,0,0,0,0,89,0,0,0,53,0,0,0,53,0,0,0,89,0,0,0,0,0,0,0,0,0,0,37,13,0,0,0,0,0,0
0,0,0,0,0,0,13,0,0,0,0,0,0,0,0,0,0,0,89,0,0,0,0,0,0,0,0,0,0,0,89,0,0,0,0,0,0,0,0,0,0,0,13,0,0,0,0,0,0
0,0,0,0,0,0,13,0,0,0,0,0,0,0,0,0,0,0,89,0,0,0,0,0,0,0,0,0,0,0,89,0,0,0,0,0,0,0,0,0,0,0,13,0,0,0,0,0,0
0,0,0,0,0,0,13,0,0,0,0,0,0,0,0,0,0,0,13,0,0,0,53,114,114,114,53,0,0,0,13,0,0,0,0,0,0,0,0,0,0,0,13,0,0,0,0,0,0
0,0,0,0,0,0,13,0,0,0,0,0,0,0,0,0,0,0,13,13,89,89,13,13,13,13,13,89,89,13,13,0,0,0,0,0,0,0,0,0,0,0,13,0,0,0,0,0,0
0,0,0,0,0,0,13,40,0,0,0,0,0,0,0,0,0,0,0,0,0,0,0,0,0,0,0,0,0,0,0,0,0,0,0,0,0,0,0,0,0,37,13,0,0,0,0,0,0
0,0,0,0,0,0,13,0,0,0,0,0,0,0,0,0,0,0,0,0,0,0,0,0,0,0,0,0,0,0,0,0,0,0,0,0,0,0,0,0,0,0,13,0,0,0,0,0,0
0,0,0,0,0,0,13,0,0,0,0,0,0,0,0,0,0,0,0,0,0,0,0,0,0,0,0,0,0,0,0,0,0,0,0,0,0,0,0,0,0,0,13,0,0,0,0,0,0
0,0,0,0,0,0,13,0,0,0,0,0,0,0,0,0,0,0,0,0,0,0,0,0,0,0,0,0,0,0,0,0,0,0,0,0,26,0,0,0,0,0,13,0,0,0,0,0,0
0,0,0,0,0,0,13,0,0,0,0,0,0,0,0,0,0,0,0,0,0,0,0,0,0,0,0,0,0,0,0,0,0,0,0,0,0,0,0,0,0,0,13,0,0,0,0,0,0
0,0,0,0,0,0,13,40,0,0,0,0,0,0,0,0,0,0,0,0,0,0,0,0,0,0,0,0,0,0,0,0,0,0,0,0,0,0,0,0,0,37,13,0,0,0,0,0,0
0,0,0,0,0,0,13,0,0,0,0,0,0,0,0,0,0,0,0,0,0,0,0,0,0,0,0,0,0,0,0,0,0,0,0,0,26,0,0,0,0,0,13,0,0,0,0,0,0
0,0,0,0,0,0,13,0,0,0,0,0,0,0,0,0,0,0,0,0,0,0,0,0,0,0,0,0,0,0,0,0,0,0,0,0,0,0,0,0,0,0,13,0,0,0,0,0,0
0,0,0,0,0,0,13,0,0,0,0,0,0,0,0,0,0,0,0,0,0,0,0,0,0,0,0,0,0,0,0,0,0,0,0,0,0,0,0,0,0,0,13,0,0,0,0,0,0
0,0,0,0,0,0,13,0,0,0,0,0,0,0,0,0,0,0,0,0,0,0,0,0,0,0,0,0,0,0,0,0,0,0,0,0,0,0,0,0,0,0,13,0,0,0,0,0,0
0,0,0,0,0,0,13,40,0,0,0,0,0,0,0,0,0,0,0,0,0,0,0,0,0,0,0,0,0,0,0,0,0,0,0,0,0,0,0,0,0,37,13,0,0,0,0,0,0
0,0,0,0,0,0,13,0,0,0,0,0,0,0,0,0,0,0,0,0,0,0,0,0,0,0,0,0,0,0,0,0,0,0,69,69,69,69,69,0,0,0,13,0,0,0,0,0,0
0,0,0,0,0,0,13,0,0,0,0,0,0,0,0,0,0,0,0,0,0,0,0,0,0,0,0,0,0,0,0,0,0,0,71,71,71,71,71,0,0,0,13,0,0,0,0,0,0
0,0,0,0,0,0,13,0,0,0,0,0,0,0,0,0,0,0,0,0,0,0,0,0,0,0,0,0,0,0,0,0,0,0,67,67,67,67,67,0,0,0,13,0,0,0,0,0,0
0,0,0,0,13,13,13,13,13,39,0,0,0,0,0,0,0,0,0,0,0,0,0,0,0,0,0,0,0,0,0,0,0,0,0,0,0,0,0,39,13,13,13,13,13,0,0,0,0
0,0,0,13,52,13,38,0,0,13,0,0,0,0,0,0,0,0,0,0,0,0,0,0,0,0,0,0,0,0,0,0,0,0,0,0,0,0,0,13,0,0,38,13,52,13,0,0,0
0,0,13,0,0,0,0,0,0,0,13,0,0,0,0,0,0,0,0,0,0,0,0,0,0,0,0,0,0,0,0,0,0,0,0,0,0,0,13,0,0,0,0,0,0,0,13,0,0
0,13,0,0,0,0,0,0,0,0,0,13,0,0,0,0,0,0,0,0,0,0,0,0,0,0,0,0,0,0,0,0,0,0,0,0,0,13,0,0,0,0,0,0,0,0,0,13,0
0,13,0,0,0,0,0,0,0,0,0,13,39,0,0,0,39,0,13,13,13,13,39,0,0,0,39,13,13,13,0,0,39,0,0,0,39,13,0,0,0,0,0,0,0,0,0,13,0
0,13,40,0,0,0,0,0,0,0,37,13,13,13,13,13,13,13,13,13,60,0,13,13,13,13,13,0,24,13,13,13,13,13,13,13,13,13,40,0,0,0,0,0,0,0,37,13,0
0,13,0,0,0,0,0,0,0,0,0,13,0,0,0,0,0,13,0,0,0,0,0,0,26,0,0,0,0,0,0,13,0,0,0,0,0,13,0,0,0,0,0,0,0,0,0,13,0
0,13,0,0,0,0,0,0,0,0,0,13,0,0,0,0,0,0,0,0,0,0,0,0,0,0,0,0,0,0,0,0,0,0,0,0,0,13,0,0,0,0,0,0,0,0,0,13,0
0,0,13,0,0,0,0,0,0,0,13,0,0,0,0,0,0,13,13,26,0,0,0,0,0,0,0,0,0,26,13,13,0,0,0,0,0,0,13,0,0,0,0,0,0,0,13,0,0
0,0,0,13,0,0,39,0,0,13,0,0,0,0,0,0,0,0,13,60,0,24,13,13,0,13,13,60,0,24,13,0,0,0,0,0,0,0,0,13,0,0,39,0,0,13,0,0,0
0,0,0,0,13,13,13,13,13,0,0,0,0,0,0,0,0,0,0,0,0,0,0,0,0,0,0,0,0,0,0,0,0,0,0,0,0,0,0,0,13,13,13,13,13,0,0,0,0
0,0,0,0,0,0,0,0,0,0,0,0,0,0,0,0,0,0,0,0,0,0,0,0,0,0,0,0,0,0,0,0,0,0,0,0,0,0,0,0,0,0,0,0,0,0,0,0,0
0,0,0,0,0,0,0,0,0,0,0,0,0,0,0,0,0,0,0,0,0,0,0,0,0,0,0,0,0,0,0,0,0,0,0,0,0,0,0,0,0,0,0,0,0,0,0,0,0
0,0,0,0,0,0,0,0,0,0,0,0,0,0,0,0,0,0,0,0,0,0,0,0,0,0,0,0,0,0,0,0,0,0,0,0,0,0,0,0,0,0,0,0,0,0,0,0,0
0,0,0,0,0,0,0,0,0,0,0,0,0,0,0,0,0,0,0,0,0,0,0,0,0,0,0,0,0,0,0,0,0,0,0,0,0,0,0,0,0,0,0,0,0,0,0,0,0
0,0,0,0,0,0,0,0,0,0,0,0,0,0,0,0,0,0,0,0,0,0,0,0,0,0,0,0,0,0,0,0,0,0,0,0,0,0,0,0,0,0,0,0,0,0,0,0,0
0,0,0,0,0,0,0,0,0,0,0,0,0,0,0,0,0,0,0,0,0,0,0,0,0,0,0,0,0,0,0,0,0,0,0,0,0,0,0,0,0,0,0,0,0,0,0,0,0
0,0,0,0,0,0,0,0,0,0,0,0,0,0,0,0,0,0,0,0,0,0,0,0,0,0,0,0,0,0,0,0,0,0,0,0,0,0,0,0,0,0,0,0,0,0,0,0,0
0,0,0,0,0,0,0,0,0,0,0,0,0,0,0,0,0,0,0,0,0,0,0,0,0,0,0,0,0,0,0,0,0,0,0,0,0,0,0,0,0,0,0,0,0,0,0,0,0
:endlayer
layer: 15
0,0,0,0,0,0,0,0,0,0,0,0,0,0,0,0,0,0,0,0,0,0,0,0,0,0,0,0,0,0,0,0,0,0,0,0,0,0,0,0,0,0,0,0,0,0,0,0,0
0,0,0,0,13,13,13,13,13,0,0,0,0,0,0,0,0,0,0,0,0,0,0,0,0,0,0,0,0,0,0,0,0,0,0,0,0,0,0,0,13,13,13,13,13,0,0,0,0
0,0,0,13,0,0,0,0,0,13,0,0,0,0,0,0,0,0,0,0,0,0,0,0,0,0,0,0,0,0,0,0,0,0,0,0,0,0,0,13,0,0,0,0,0,13,0,0,0
0,0,13,0,0,0,0,0,0,0,13,0,0,0,0,0,0,0,0,0,0,0,0,0,0,0,0,0,0,0,0,0,0,0,0,0,0,0,13,0,0,0,0,0,0,0,13,0,0
0,13,0,0,0,0,0,0,0,0,0,13,0,0,0,0,0,0,0,0,0,0,0,0,0,0,0,0,0,0,0,0,0,0,0,0,0,13,0,0,0,0,0,0,0,0,0,13,0
0,13,0,0,0,0,0,0,0,0,0,13,0,0,0,0,0,0,0,0,0,0,0,0,0,0,0,0,0,0,0,0,0,0,0,0,0,13,0,0,0,0,0,0,0,0,0,13,0
0,13,0,0,0,0,13,13,13,13,13,13,13,13,13,13,13,13,13,13,13,13,13,13,13,13,13,13,13,13,13,13,13,13,13,13,13,13,0,0,0,0,0,0,0,0,0,13,0
0,13,0,0,0,0,13,0,0,0,0,13,0,0,0,0,0,0,13,0,0,0,0,0,0,0,0,0,0,0,13,0,0,0,0,0,0,13,0,0,0,0,0,0,0,0,0,13,0
0,13,0,0,0,0,13,0,0,13,13,13,0,0,0,0,0,0,13,0,0,0,0,0,0,0,0,0,0,0,13,0,0,0,0,0,0,13,0,0,0,0,0,0,0,0,0,13,0
0,0,13,0,0,0,13,0,0,72,13,0,0,0,0,0,0,0,13,0,0,0,0,0,0,0,0,0,0,0,13,0,0,0,0,0,0,0,13,0,0,0,0,0,0,0,13,0,0
0,0,0,13,0,0,13,0,0,13,0,0,0,0,0,0,0,0,13,0,0,0,0,0,0,0,0,0,0,0,13,0,0,0,0,0,0,0,0,13,0,0,0,13,51,13,0,0,0
0,0,0,0,13,13,13,13,13,0,0,0,0,0,0,0,0,0,13,0,0,0,0,0,0,0,0,0,0,0,13,0,0,0,0,0,0,0,0,0,13,13,13,13,13,0,0,0,0
0,0,0,0,0,0,13,0,0,0,0,0,0,0,0,0,0,0,13,0,0,0,0,0,0,0,0,0,0,0,13,0,0,0,0,0,0,0,0,0,0,0,13,0,0,0,0,0,0
0,0,0,0,0,0,13,0,0,0,0,0,0,0,0,0,0,0,13,0,0,0,0,0,0,0,0,0,0,0,13,0,0,0,0,0,0,0,0,0,0,0,13,0,0,0,0,0,0
0,0,0,0,0,0,13,0,0,0,0,0,0,0,0,0,0,0,13,0,0,0,0,0,0,0,0,0,0,0,13,0,0,0,0,0,0,0,0,0,0,0,13,0,0,0,0,0,0
0,0,0,0,0,0,13,0,0,0,0,0,0,0,0,0,0,0,13,0,0,0,0,0,0,0,0,0,0,0,13,0,0,0,0,0,0,0,0,0,0,0,13,0,0,0,0,0,0
0,0,0,0,0,0,13,0,0,0,0,0,0,0,0,0,0,0,13,0,0,0,0,0,0,0,0,0,0,0,13,0,0,0,0,0,0,0,0,0,0,0,13,0,0,0,0,0,0
0,0,0,0,0,0,13,0,0,0,0,0,0,0,0,0,0,0,13,0,0,0,0,0,0,0,0,0,0,0,13,0,0,0,0,0,0,0,0,0,0,0,13,0,0,0,0,0,0
0,0,0,0,0,0,13,0,0,0,0,0,0,0,0,0,0,0,13,0,0,0,68,101,101,101,73,0,0,0,13,0,0,0,0,0,0,0,0,0,0,0,13,0,0,0,0,0,0
0,0,0,0,0,0,13,0,0,0,0,0,0,0,0,0,0,0,13,0,0,0,68,101,101,101,73,0,0,0,13,0,0,0,0,0,0,0,0,0,0,0,13,0,0,0,0,0,0
0,0,0,0,0,0,13,0,0,0,0,0,0,0,0,0,0,0,13,0,0,0,68,101,101,101,73,0,0,0,13,0,0,0,0,0,0,0,0,0,0,0,13,0,0,0,0,0,0
0,0,0,0,0,0,13,0,0,0,0,0,0,0,0,0,0,0,13,0,0,39,68,101,101,101,73,39,0,0,13,0,0,0,0,0,0,0,0,0,0,0,13,0,0,0,0,0,0
0,0,0,0,0,0,13,0,0,0,0,0,0,0,0,0,0,0,13,13,13,13,13,13,13,13,13,13,13,13,13,0,0,0,0,0,0,0,0,0,0,0,13,0,0,0,0,0,0
0,0,0,0,0,0,13,0,0,0,0,0,0,0,0,0,0,0,0,0,0,0,0,0,0,0,0,0,0,0,0,0,0,0,0,0,0,0,0,0,0,0,13,0,0,0,0,0,0
0,0,0,0,0,0,13,0,0,0,0,0,0,0,0,0,0,0,0,0,0,0,0,0,0,0,0,0,0,0,0,0,0,0,0,0,0,0,0,0,0,0,13,0,0,0,0,0,0
0,0,0,0,0,0,13,0,0,0,0,0,0,0,0,0,0,0,0,0,0,0,0,0,0,0,0,0,0,0,0,0,0,0,0,0,0,0,0,0,0,0,13,0,0,0,0,0,0
0,0,0,0,0,0,13,0,0,0,0,0,0,0,0,0,0,0,0,0,0,0,0,0,0,0,0,0,0,0,0,0,0,0,0,0,0,0,0,0,0,0,13,0,0,0,0,0,0
0,0,0,0,0,0,13,0,0,0,0,0,0,0,0,0,0,0,0,0,0,0,0,0,0,0,0,0,0,0,0,0,0,0,0,0,0,0,0,0,0,0,13,0,0,0,0,0,0
0,0,0,0,0,0,13,0,0,0,0,0,0,0,0,0,0,0,0,0,0,0,0,0,0,0,0,0,0,0,0,0,0,0,0,0,0,0,0,0,0,0,13,0,0,0,0,0,0
0,0,0,0,0,0,13,0,0,0,0,0,0,0,0,0,0,0,0,0,0,0,0,0,0,0,0,0,0,0,0,0,0,0,0,0,0,0,0,0,0,0,13,0,0,0,0,0,0
0,0,0,0,0,0,13,0,0,0,0,0,0,0,0,0,0,0,0,0,0,0,0,0,0,0,0,0,0,0,0,0,0,0,0,0,0,0,0,0,0,0,13,0,0,0,0,0,0
0,0,0,0,0,0,13,0,0,0,0,0,0,0,0,0,0,0,0,0,0,0,0,0,0,0,0,0,0,0,0,0,0,0,0,0,0,0,0,0,0,0,13,0,0,0,0,0,0
0,0,0,0,0,0,13,0,0,0,0,0,0,0,0,0,0,0,0,0,0,0,0,0,0,0,0,0,0,0,0,0,0,0,0,0,0,0,0,0,0,0,13,0,0,0,0,0,0
0,0,0,0,0,0,13,0,0,0,0,0,0,0,0,0,0,0,0,0,0,0,0,0,0,0,0,0,0,0,0,0,0,0,0,0,0,0,0,0,0,0,13,0,0,0,0,0,0
0,0,0,0,0,0,13,0,0,0,0,0,0,0,0,0,0,0,0,0,0,0,0,0,0,0,0,0,0,0,0,0,0,0,0,0,0,0,0,0,0,0,13,0,0,0,0,0,0
0,0,0,0,0,0,13,0,0,0,0,0,0,0,0,0,0,0,0,0,0,0,0,0,0,0,0,0,0,0,0,0,0,0,0,0,26,0,0,0,0,0,13,0,0,0,0,0,0
0,0,0,0,0,0,13,0,0,0,0,0,0,0,0,0,0,0,0,0,0,0,0,0,0,0,0,0,0,0,0,0,0,0,0,0,0,0,0,0,0,0,13,0,0,0,0,0,0
0,0,0,0,13,13,13,13,13,0,0,0,0,0,0,0,0,0,0,0,0,0,0,0,0,0,0,0,0,0,0,0,0,0,0,0,0,0,0,0,13,13,13,13,13,0,0,0,0
0,0,0,13,52,13,0,0,0,13,0,0,0,0,0,0,0,0,0,0,0,0,0,0,0,0,0,0,0,0,0,0,0,0,0,0,0,0,0,13,0,0,0,13,52,13,0,0,0
0,0,13,0,0,0,0,0,0,0,13,0,0,0,0,0,0,0,0,0,0,0,0,0,0,0,0,0,0,0,0,0,0,0,0,0,0,0,13,0,0,0,0,0,0,0,13,0,0
0,13,0,0,0,0,0,0,0,0,0,13,0,0,0,0,0,0,0,0,0,0,0,0,0,0,0,0,0,0,0,0,0,0,0,0,0,13,0,0,0,0,0,0,0,0,0,13,0
0,13,0,0,0,0,0,0,0,0,0,13,0,0,0,0,0,0,13,13,13,13,0,0,0,0,0,13,13,13,0,0,0,0,0,0,0,13,0,0,0,0,0,0,0,0,0,13,0
0,13,0,0,0,0,0,0,0,0,0,13,13,13,13,13,13,13,13,60,0,0,13,13,13,13,13,0,0,24,13,13,13,13,13,13,13,13,0,0,0,0,0,0,0,0,0,13,0
0,13,0,0,0,0,0,0,0,0,0,13,0,0,0,0,0,13,0,0,0,0,0,0,0,0,0,0,0,0,0,13,0,0,0,0,0,13,0,0,0,0,0,0,0,0,0,13,0
0,13,0,0,0,0,0,0,0,0,0,13,0,0,0,0,0,0,0,0,0,0,0,0,0,0,0,0,0,0,0,0,0,0,0,0,0,13,0,0,0,0,0,0,0,0,0,13,0
0,0,13,0,0,0,0,0,0,0,13,0,0,0,0,0,0,13,13,0,0,0,0,0,0,0,0,0,0,0,13,13,0,0,0,0,0,0,13,0,0,0,0,0,0,0,13,0,0
0,0,0,13,0,0,0,0,0,13,0,0,0,0,0,0,0,0,13,0,0,0,13,0,0,0,13,0,0,0,13,0,0,0,0,0,0,0,0,13,0,0,0,0,0,13,0,0,0
0,0,0,0,13,13,13,13,13,0,0,0,0,0,0,0,0,0,0,0,0,0,0,0,0,0,0,0,0,0,0,0,0,0,0,0,0,0,0,0,13,13,13,13,13,0,0,0,0
0,0,0,0,0,0,0,0,0,0,0,0,0,0,0,0,0,0,0,0,0,0,0,0,0,0,0,0,0,0,0,0,0,0,0,0,0,0,0,0,0,0,0,0,0,0,0,0,0
0,0,0,0,0,0,0,0,0,0,0,0,0,0,0,0,0,0,0,0,0,0,0,0,0,0,0,0,0,0,0,0,0,0,0,0,0,0,0,0,0,0,0,0,0,0,0,0,0
0,0,0,0,0,0,0,0,0,0,0,0,0,0,0,0,0,0,0,0,0,0,0,0,0,0,0,0,0,0,0,0,0,0,0,0,0,0,0,0,0,0,0,0,0,0,0,0,0
0,0,0,0,0,0,0,0,0,0,0,0,0,0,0,0,0,0,0,0,0,0,0,0,0,0,0,0,0,0,0,0,0,0,0,0,0,0,0,0,0,0,0,0,0,0,0,0,0
0,0,0,0,0,0,0,0,0,0,0,0,0,0,0,0,0,0,0,0,0,0,0,0,0,0,0,0,0,0,0,0,0,0,0,0,0,0,0,0,0,0,0,0,0,0,0,0,0
0,0,0,0,0,0,0,0,0,0,0,0,0,0,0,0,0,0,0,0,0,0,0,0,0,0,0,0,0,0,0,0,0,0,0,0,0,0,0,0,0,0,0,0,0,0,0,0,0
0,0,0,0,0,0,0,0,0,0,0,0,0,0,0,0,0,0,0,0,0,0,0,0,0,0,0,0,0,0,0,0,0,0,0,0,0,0,0,0,0,0,0,0,0,0,0,0,0
0,0,0,0,0,0,0,0,0,0,0,0,0,0,0,0,0,0,0,0,0,0,0,0,0,0,0,0,0,0,0,0,0,0,0,0,0,0,0,0,0,0,0,0,0,0,0,0,0
:endlayer
layer: 16
0,0,0,0,0,0,0,0,0,0,0,0,0,0,0,0,0,0,0,0,0,0,0,0,0,0,0,0,0,0,0,0,0,0,0,0,0,0,0,0,0,0,0,0,0,0,0,0,0
0,0,0,0,13,13,13,13,13,0,0,0,0,0,0,0,0,0,0,0,0,0,0,0,0,0,0,0,0,0,0,0,0,0,0,0,0,0,0,0,13,13,13,13,13,0,0,0,0
0,0,0,13,13,13,13,13,13,13,0,0,0,0,0,0,0,0,0,0,0,0,0,0,0,0,0,0,0,0,0,0,0,0,0,0,0,0,0,13,13,13,13,13,13,13,0,0,0
0,0,13,13,13,13,13,13,13,13,13,0,0,0,0,0,0,0,0,0,0,0,0,0,0,0,0,0,0,0,0,0,0,0,0,0,0,0,13,13,13,13,13,13,13,13,13,0,0
0,13,13,13,13,13,13,13,13,13,13,13,0,0,0,0,0,0,0,0,0,0,0,0,0,0,0,0,0,0,0,0,0,0,0,0,0,13,13,13,13,13,13,13,13,13,13,13,0
0,13,13,13,13,13,13,13,13,13,13,13,13,13,13,13,13,13,13,13,13,13,13,13,13,13,13,13,13,13,13,13,13,13,13,13,13,13,13,13,13,13,13,13,13,13,13,13,0
0,13,13,13,13,13,13,13,13,13,13,13,13,13,13,13,13,13,13,13,13,13,13,13,13,13,13,13,13,13,13,13,13,13,13,13,13,13,13,13,13,13,13,13,13,13,13,13,0
0,13,13,13,13,13,13,13,13,13,13,13,13,13,13,13,13,13,13,13,13,13,13,13,13,13,13,13,13,13,13,13,13,13,13,13,13,13,13,13,13,13,13,13,13,13,13,13,0
0,13,13,13,13,13,13,13,13,13,13,13,13,13,13,13,13,13,13,13,13,13,13,13,13,13,13,13,13,13,13,13,13,13,13,13,13,13,13,13,13,13,13,13,13,13,13,13,0
0,0,13,13,13,13,13,13,13,72,13,13,13,13,13,13,13,13,13,13,13,13,13,13,13,13,13,13,13,13,13,13,13,13,13,13,13,13,13,13,13,13,13,13,13,13,13,0,0
0,0,0,13,13,13,13,13,13,13,0,0,0,0,0,0,0,0,13,13,13,13,13,13,13,13,13,13,13,13,13,0,0,0,0,0,0,0,0,13,13,13,13,13,51,13,0,0,0
0,0,0,0,13,13,13,13,13,13,0,0,0,0,0,0,0,0,13,13,13,13,13,13,13,13,13,13,13,13,13,0,0,0,0,0,0,0,0,13,13,13,13,13,13,0,0,0,0
0,0,0,0,0,13,13,13,13,13,0,0,0,0,0,0,0,0,13,13,13,13,13,13,13,13,13,13,13,13,13,0,0,0,0,0,0,0,0,13,13,13,13,13,0,0,0,0,0
0,0,0,0,0,13,13,13,13,13,0,0,0,0,0,0,0,0,13,13,13,13,13,13,13,13,13,13,13,13,13,0,0,0,0,0,0,0,0,13,13,13,13,13,0,0,0,0,0
0,0,0,0,0,13,13,13,13,13,0,0,0,0,0,0,0,0,13,13,13,13,13,13,13,13,13,13,13,13,13,0,0,0,0,0,0,0,0,13,13,13,13,13,0,0,0,0,0
0,0,0,0,0,13,13,13,13,13,0,0,0,0,0,0,0,0,13,13,13,13,13,13,13,13,13,13,13,13,13,0,0,0,0,0,0,0,0,13,13,13,13,13,0,0,0,0,0
0,0,0,0,0,13,13,13,13,13,0,0,0,0,0,0,0,0,13,13,13,13,13,13,13,13,13,13,13,13,13,0,0,0,0,0,0,0,0,13,13,13,13,13,0,0,0,0,0
0,0,0,0,0,13,13,13,13,13,0,0,0,0,0,0,0,0,13,13,13,13,13,13,13,13,13,13,13,13,13,0,0,0,0,0,0,0,0,13,13,13,13,13,0,0,0,0,0
0,0,0,0,0,13,13,13,13,13,0,0,0,0,0,0,0,0,13,13,13,13,13,13,13,13,13,13,13,13,13,0,0,0,0,0,0,0,0,13,13,13,13,13,0,0,0,0,0
0,0,0,0,0,13,13,13,13,13,0,0,0,0,0,0,0,0,13,13,13,13,13,13,13,13,13,13,13,13,13,0,0,0,0,0,0,0,0,13,13,13,13,13,0,0,0,0,0
0,0,0,0,0,13,13,13,13,13,0,0,0,0,0,0,0,0,13,13,13,13,13,13,13,13,13,13,13,13,13,0,0,0,0,0,0,0,0,13,13,13,13,13,0,0,0,0,0
0,0,0,0,0,13,13,13,13,13,0,0,0,0,0,0,0,0,13,13,13,13,13,13,13,13,13,13,13,13,13,0,0,0,0,0,0,0,0,13,13,13,13,13,0,0,0,0,0
0,0,0,0,0,13,13,13,13,13,0,0,0,0,0,0,0,0,13,13,13,13,13,13,13,13,13,13,13,13,13,0,0,0,0,0,0,0,0,13,13,13,13,13,0,0,0,0,0
0,0,0,0,0,13,13,13,13,13,0,0,0,0,0,0,0,0,0,0,0,0,0,0,0,0,0,0,0,0,0,0,0,0,0,0,0,0,0,13,13,13,13,13,0,0,0,0,0
0,0,0,0,0,13,13,13,13,13,0,0,0,0,0,0,0,0,0,0,0,0,0,0,0,0,0,0,0,0,0,0,0,0,0,0,0,0,0,13,13,13,13,13,0,0,0,0,0
0,0,0,0,0,13,13,13,13,13,0,0,0,0,0,0,0,0,0,0,0,0,0,0,0,0,0,0,0,0,0,0,0,0,0,0,0,0,0,13,13,13,13,13,0,0,0,0,0
0,0,0,0,0,13,13,13,13,13,0,0,0,0,0,0,0,0,0,0,0,0,0,0,0,0,0,0,0,0,0,0,0,0,0,0,0,0,0,13,13,13,13,13,0,0,0,0,0
0,0,0,0,0,13,13,13,13,13,0,0,0,0,0,0,0,0,0,0,0,0,0,0,0,0,0,0,0,0,0,0,0,0,0,0,0,0,0,13,13,13,13,13,0,0,0,0,0
0,0,0,0,0,13,13,13,13,13,0,0,0,0,0,0,0,0,0,0,0,0,0,0,0,0,0,0,0,0,0,0,0,0,0,0,0,0,0,13,13,13,13,13,0,0,0,0,0
