# Ancient Warfare Structure Template File
# auto-generated structure file. created on: 4/21/2014 at: 16:59:21
# Lines beginning with # denote comments

header:
version=2.0
name=fortress2
size=27,16,27
offset=13,1,26
:endheader

#### VALIDATION ####
validation:
type=ground
survival=false
worldGenEnabled=true
unique=false
preserveBlocks=false
selectionWeight=10
clusterValue=100
minDuplicateDistance=40
dimensionWhiteList=false
dimensionList=
biomeWhiteList=false
biomeList=
leveling=15
fill=5
border=5
validTargetBlocks=clay,lapis_ore,lit_redstone_ore,stone,tile.bop.mud,carpet,gravel,coal_block,diamond_ore,ice,snow,netherrack,tile.bop.longGrass,tile.bop.generic.hard_dirt,tile.bop.redRocks,dirt,redstone_ore,mycelium,tile.bop.holyStone,sand,grass,tile.bop.ash,iron_ore,soul_sand,snow_layer,stained_hardened_clay,coal_ore,gold_ore,tile.bop.generic.hard_sand
data:
:enddata
:endvalidation

#### LAYERS ####
layer: 0
1,1,1,1,1,1,1,1,1,1,1,1,1,1,1,1,1,1,1,1,1,1,1,1,1,1,1
1,2,2,2,2,2,1,1,1,1,1,1,1,1,1,1,1,1,1,1,1,2,2,2,2,2,1
1,2,2,2,2,2,1,1,1,1,1,1,1,1,1,1,1,1,1,1,1,2,2,2,2,2,1
1,2,2,2,2,2,2,2,2,2,2,2,2,2,2,2,2,2,2,2,2,2,2,2,2,2,1
1,2,2,2,2,2,3,3,3,3,3,3,3,3,3,3,3,3,3,3,3,2,2,2,2,2,1
1,2,2,2,2,2,4,4,4,3,3,4,4,4,4,4,3,3,4,4,4,2,2,2,2,2,1
1,1,1,2,3,4,4,4,4,3,3,4,4,4,4,4,3,3,4,4,4,4,3,2,1,1,1
1,1,1,2,3,4,4,4,4,3,3,4,4,4,4,4,3,3,4,4,4,4,3,2,1,1,1
1,1,1,2,3,4,4,4,4,3,3,4,4,4,4,4,3,3,4,4,4,4,3,2,1,1,1
1,1,1,2,3,3,3,3,3,2,2,3,3,3,3,3,2,2,3,3,3,3,3,2,1,1,1
1,1,1,2,3,3,3,3,3,2,2,3,3,3,3,3,2,2,3,3,3,3,3,2,1,1,1
1,1,1,2,3,4,4,4,4,3,3,4,4,4,4,4,3,3,4,4,4,4,3,2,1,1,1
1,1,1,2,3,4,4,4,4,3,3,4,4,4,4,4,3,3,4,4,4,4,3,2,1,1,1
1,1,1,2,3,4,4,4,4,3,3,4,4,4,4,4,3,3,4,4,4,4,3,2,1,1,1
1,1,1,2,3,4,4,4,4,3,3,4,4,4,4,4,3,3,4,4,4,4,3,2,1,1,1
1,1,1,2,3,4,4,4,4,3,3,4,4,4,4,4,3,3,4,4,4,4,3,2,1,1,1
1,1,1,2,3,3,3,3,3,2,2,3,3,3,3,3,2,2,3,3,3,3,3,2,1,1,1
1,1,1,2,3,3,3,3,3,2,2,3,3,3,3,3,2,2,3,3,3,3,3,2,1,1,1
1,1,1,2,3,4,4,4,4,3,3,4,4,4,4,4,3,3,4,4,4,4,3,2,1,1,1
1,1,1,2,3,4,4,4,4,3,3,4,4,4,4,4,3,3,4,4,4,4,3,2,1,1,1
1,1,1,2,3,4,4,4,4,3,3,4,4,4,4,4,3,3,4,4,4,4,3,2,1,1,1
1,2,2,2,2,2,4,4,4,2,2,3,3,3,3,3,2,2,4,4,4,2,2,2,2,2,1
1,2,2,2,2,2,3,3,3,2,2,3,3,3,3,3,2,2,3,3,3,2,2,2,2,2,1
1,2,2,2,2,2,2,2,2,2,2,3,3,3,3,3,2,2,2,2,2,2,2,2,2,2,1
1,2,2,2,2,2,1,1,1,1,1,1,1,1,1,1,1,1,1,1,1,2,2,2,2,2,1
1,2,2,2,2,2,1,1,1,1,1,1,1,1,1,1,1,1,1,1,1,2,2,2,2,2,1
1,1,1,1,1,1,1,1,1,1,1,1,1,1,1,1,1,1,1,1,1,1,1,1,1,1,1
:endlayer
layer: 1
0,0,0,0,0,0,0,0,0,0,0,0,0,0,0,0,0,0,0,0,0,0,0,0,0,0,0
0,2,2,2,2,2,0,0,0,0,0,0,0,0,0,0,0,0,0,0,0,2,2,2,2,2,0
0,2,0,0,0,2,0,0,0,0,0,0,0,0,0,0,0,0,0,0,0,2,0,0,0,2,0
0,2,0,0,6,2,2,2,2,2,2,2,2,12,2,2,2,2,2,2,2,2,6,0,0,2,0
0,2,0,5,7,5,0,0,0,0,0,0,0,0,0,0,0,0,0,0,0,5,7,5,0,2,0
0,2,2,2,5,2,0,0,0,0,0,0,0,0,0,0,0,0,0,0,0,2,5,2,2,2,0
0,0,0,2,0,0,0,0,0,0,0,0,0,0,0,0,0,0,0,0,0,0,0,2,0,0,0
0,0,0,2,0,0,0,0,0,0,0,0,0,0,0,0,0,0,0,0,0,0,0,2,0,0,0
0,0,0,2,0,0,0,0,0,0,0,0,10,10,10,0,0,0,0,0,0,0,0,2,0,0,0
0,0,0,2,5,0,0,0,0,2,2,0,11,11,11,0,2,2,0,0,0,0,0,2,0,0,0
0,0,0,2,0,0,0,0,0,2,2,0,0,0,0,0,2,2,0,0,0,0,0,2,0,0,0
0,0,0,2,0,0,0,0,0,0,0,0,0,0,0,0,0,0,0,0,0,0,0,2,0,0,0
0,0,0,2,0,0,0,0,0,0,0,0,0,0,0,0,0,0,0,0,0,0,0,2,0,0,0
0,0,0,2,0,0,0,0,0,0,0,0,0,0,0,0,0,0,0,0,0,0,0,2,0,0,0
0,0,0,2,0,0,0,0,0,0,0,0,0,0,0,0,0,0,0,0,0,0,0,2,0,0,0
0,0,0,2,0,0,0,0,0,0,0,0,0,0,0,0,0,0,0,0,0,0,0,2,0,0,0
0,0,0,2,0,0,0,0,0,2,2,0,0,0,0,0,2,2,0,0,0,0,0,2,0,0,0
0,0,0,2,5,0,0,0,0,2,2,0,0,0,0,0,2,2,0,0,0,0,5,2,0,0,0
0,0,0,2,0,0,0,0,0,0,0,0,0,0,0,0,0,0,0,0,0,0,0,2,0,0,0
0,0,0,2,0,0,0,0,0,0,0,0,0,0,0,0,0,0,0,0,0,0,0,2,0,0,0
0,0,0,2,0,0,0,0,0,0,0,0,0,0,0,0,0,0,0,0,0,0,0,2,0,0,0
0,2,2,2,5,2,0,0,0,2,2,0,0,0,0,8,2,2,0,0,0,2,5,2,2,2,0
0,2,0,5,7,5,0,5,0,2,2,0,0,0,0,0,2,2,0,5,0,5,7,5,0,2,0
0,2,0,0,6,2,2,2,2,2,2,0,0,0,0,9,2,2,2,2,2,2,6,0,0,2,0
0,2,0,0,0,2,0,0,0,0,0,0,0,0,0,0,0,0,0,0,0,2,0,0,0,2,0
0,2,2,2,2,2,0,0,0,0,0,0,0,0,0,0,0,0,0,0,0,2,2,2,2,2,0
0,0,0,0,0,0,0,0,0,0,0,0,0,0,0,0,0,0,0,0,0,0,0,0,0,0,0
:endlayer
layer: 2
0,0,0,0,0,0,0,0,0,0,0,0,0,0,0,0,0,0,0,0,0,0,0,0,0,0,0
0,2,2,2,2,2,0,0,0,0,0,0,0,0,0,0,0,0,0,0,0,2,2,2,2,2,0
0,2,0,6,7,2,0,0,0,0,0,0,17,0,0,0,0,0,0,0,0,2,7,6,0,2,0
0,2,0,0,5,2,2,2,2,2,2,2,2,16,2,2,2,2,2,2,2,2,5,0,0,2,0
0,2,0,0,0,0,0,0,0,0,0,0,0,0,15,0,0,0,0,0,0,0,0,0,0,2,0
0,2,2,2,0,2,0,0,0,0,0,0,0,0,0,0,0,0,0,0,0,2,0,2,2,2,0
0,0,0,2,0,0,0,0,0,0,0,0,0,0,0,0,0,0,0,0,0,0,0,2,0,0,0
0,0,0,2,0,0,0,0,0,0,0,0,10,10,10,0,0,0,0,0,0,0,0,2,0,0,0
0,0,0,2,0,0,0,0,0,0,0,0,11,11,11,0,0,0,0,0,0,0,0,2,0,0,0
0,0,0,18,0,0,0,0,0,2,2,0,0,0,0,0,2,2,0,0,0,0,0,13,0,0,0
0,0,0,2,0,0,0,0,0,2,2,0,0,0,0,0,2,2,0,0,0,0,0,2,0,0,0
0,0,0,2,0,0,0,0,0,0,0,0,0,0,0,0,0,0,0,0,0,0,0,2,0,0,0
0,0,0,2,0,0,0,0,0,0,0,0,0,0,0,0,0,0,0,0,0,0,0,2,0,0,0
0,0,0,2,0,0,0,0,0,0,0,0,0,0,0,0,0,0,0,0,0,0,0,2,0,0,0
0,0,0,2,0,0,0,0,0,0,0,0,0,0,0,0,0,0,0,0,0,0,0,2,0,0,0
0,0,0,2,0,0,0,0,0,0,0,0,0,0,0,0,0,0,0,0,0,0,0,2,0,0,0
0,0,0,2,0,0,0,0,0,2,2,0,0,0,0,0,2,2,0,0,0,0,0,2,0,0,0
0,0,0,18,0,0,0,0,0,2,2,0,0,0,0,0,2,2,0,0,0,0,0,13,0,0,0
0,0,0,2,0,0,0,0,0,0,0,0,0,0,0,0,0,0,0,0,0,0,0,2,0,0,0
0,0,0,2,0,0,0,0,0,0,0,0,0,0,0,0,0,0,0,0,0,0,0,2,0,0,0
0,0,0,2,0,0,0,0,0,0,0,0,0,0,0,0,0,0,0,0,0,0,0,2,0,0,0
0,2,2,2,0,2,0,0,0,2,2,0,0,0,0,0,2,2,0,0,0,2,0,2,2,2,0
0,2,0,0,0,0,0,0,0,2,2,0,0,0,0,0,2,2,0,0,0,0,0,0,0,2,0
0,2,0,0,5,2,2,14,2,2,2,0,0,0,0,0,2,2,2,14,2,2,5,0,0,2,0
0,2,0,6,7,2,0,0,0,0,0,0,0,0,0,0,0,0,0,0,0,2,7,6,0,2,0
0,2,2,2,2,2,0,0,0,0,0,0,0,0,0,0,0,0,0,0,0,2,2,2,2,2,0
0,0,0,0,0,0,0,0,0,0,0,0,0,0,0,0,0,0,0,0,0,0,0,0,0,0,0
:endlayer
layer: 3
0,0,0,0,0,0,0,0,0,0,0,0,0,0,0,0,0,0,0,0,0,0,0,0,0,0,0
0,2,2,2,2,2,0,0,0,0,0,0,0,0,0,0,0,0,0,0,0,2,2,2,2,2,0
0,2,7,5,0,2,0,0,0,0,0,0,0,0,0,0,0,0,0,0,0,2,0,5,7,2,0
0,2,6,0,0,2,2,2,2,2,2,2,2,2,2,2,2,2,2,2,2,2,0,0,6,2,0
0,2,0,19,0,0,0,0,0,20,0,23,0,20,0,23,0,20,0,0,0,0,0,19,0,2,0
0,2,2,2,0,2,22,0,0,0,0,6,0,0,0,6,0,0,0,0,21,2,0,2,2,2,0
0,0,0,2,0,20,0,0,0,0,0,6,10,10,10,6,0,0,0,0,0,20,0,2,0,0,0
0,0,0,2,0,0,0,0,0,0,0,0,11,11,11,0,0,0,0,0,0,0,0,2,0,0,0
0,0,0,2,0,0,0,0,0,19,19,0,0,0,0,0,0,19,0,0,0,0,0,2,0,0,0
0,0,0,0,0,0,0,0,21,2,2,0,0,0,0,0,2,2,0,0,0,0,0,0,0,0,0
0,0,0,2,22,0,0,0,21,2,2,0,0,0,0,0,2,2,22,0,0,0,21,2,0,0,0
0,0,0,2,0,0,0,0,0,0,0,0,0,0,0,0,0,20,0,0,0,0,0,2,0,0,0
0,0,0,2,0,0,0,0,0,0,0,0,0,0,0,0,0,0,0,0,0,0,0,2,0,0,0
0,0,0,2,0,0,0,0,0,0,0,0,0,0,0,0,0,0,0,0,0,0,0,2,0,0,0
0,0,0,2,0,0,0,0,0,0,0,0,0,0,0,0,0,0,0,0,0,0,0,2,0,0,0
0,0,0,2,0,0,0,0,0,19,0,0,0,0,0,0,0,19,0,0,0,0,0,2,0,0,0
0,0,0,2,22,0,0,0,21,2,2,0,0,0,0,0,2,2,22,0,0,0,21,2,0,0,0
0,0,0,0,0,0,0,0,0,2,2,0,0,0,0,0,2,2,0,0,0,0,0,0,0,0,0
0,0,0,2,0,0,0,0,0,20,0,0,0,0,0,0,0,20,0,0,0,0,0,2,0,0,0
0,0,0,2,0,0,0,0,0,0,0,0,0,0,0,0,0,0,0,0,0,0,0,2,0,0,0
0,0,0,2,0,19,0,0,0,19,0,0,0,0,0,0,0,19,0,0,0,19,0,2,0,0,0
0,2,2,2,0,2,22,0,21,2,2,22,0,0,0,21,2,2,22,0,21,2,0,2,2,2,0
0,2,0,20,0,0,0,0,0,2,2,0,0,0,0,0,2,2,19,0,0,0,0,20,0,2,0
0,2,6,0,0,2,2,0,2,2,2,22,0,0,0,21,2,2,2,0,2,2,0,0,6,2,0
0,2,7,5,0,2,0,0,0,0,0,0,0,0,0,0,0,0,0,0,0,2,0,5,7,2,0
0,2,2,2,2,2,0,0,0,0,0,0,0,0,0,0,0,0,0,0,0,2,2,2,2,2,0
0,0,0,0,0,0,0,0,0,0,0,0,0,0,0,0,0,0,0,0,0,0,0,0,0,0,0
:endlayer
layer: 4
0,0,0,0,0,0,0,0,0,0,0,0,0,0,0,0,0,0,0,0,0,0,0,0,0,0,0
0,2,2,24,2,2,0,0,0,0,0,0,0,0,0,0,0,0,0,0,0,2,2,24,2,2,0
0,2,0,0,0,2,0,0,0,0,0,0,0,0,0,0,0,0,0,0,0,2,0,0,0,2,0
0,24,5,0,0,2,2,2,2,2,2,2,2,2,2,2,2,2,2,2,2,2,0,0,5,24,0
0,2,7,6,0,2,0,0,0,28,7,32,5,5,5,31,7,28,0,0,0,2,0,6,7,2,0
0,2,2,2,2,2,0,0,0,0,33,32,5,5,5,31,30,0,0,0,0,2,2,2,2,2,0
0,0,0,2,0,0,0,0,0,0,33,32,5,5,5,31,30,0,0,0,0,0,0,2,0,0,0
0,0,0,2,0,0,0,0,0,0,0,0,0,0,0,0,0,0,0,0,0,0,0,2,0,0,0
0,0,0,2,0,0,0,0,0,29,0,0,0,0,0,0,0,29,0,0,0,0,0,2,0,0,0
0,0,0,25,0,0,0,0,0,2,2,0,0,0,0,0,2,2,0,0,0,0,0,25,0,0,0
0,0,0,2,27,0,0,0,26,2,2,0,0,0,0,0,2,2,27,0,0,0,26,2,0,0,0
0,0,0,2,0,0,0,0,0,28,0,0,0,0,0,0,0,28,0,0,0,0,0,2,0,0,0
0,0,0,2,0,0,0,0,0,0,0,0,0,0,0,0,0,0,0,0,0,0,0,2,0,0,0
0,0,0,2,0,0,0,0,0,0,0,0,0,0,0,0,0,0,0,0,0,0,0,2,0,0,0
0,0,0,2,0,0,0,0,0,0,0,0,0,0,0,0,0,0,0,0,0,0,0,2,0,0,0
0,0,0,2,0,0,0,0,0,29,0,0,0,0,0,0,0,29,0,0,0,0,0,2,0,0,0
0,0,0,2,27,0,0,0,26,2,2,0,0,0,0,0,2,2,27,0,0,0,26,2,0,0,0
0,0,0,25,0,0,0,0,0,2,2,0,0,0,0,0,2,2,0,0,0,0,0,25,0,0,0
0,0,0,2,0,0,0,0,0,28,0,0,0,0,0,0,0,28,0,0,0,0,0,2,0,0,0
0,0,0,2,0,0,0,0,0,0,0,0,0,0,0,0,0,0,0,0,0,0,0,2,0,0,0
0,0,0,2,0,0,0,0,0,29,0,0,0,0,0,0,0,29,0,0,0,0,0,2,0,0,0
0,2,2,2,2,2,0,0,26,2,2,0,0,0,0,0,2,2,27,0,0,2,2,2,2,2,0
0,2,7,6,0,2,0,0,26,2,2,0,0,0,0,0,2,2,27,0,0,2,0,6,7,2,0
0,24,5,0,0,2,2,25,2,2,2,0,0,0,0,0,2,2,2,25,2,2,0,0,5,24,0
0,2,0,0,0,2,0,0,0,0,0,0,0,0,0,0,0,0,0,0,0,2,0,0,0,2,0
0,2,2,24,2,2,0,0,0,0,0,0,0,0,0,0,0,0,0,0,0,2,2,24,2,2,0
0,0,0,0,0,0,0,0,0,0,0,0,0,0,0,0,0,0,0,0,0,0,0,0,0,0,0
:endlayer
layer: 5
0,0,0,0,0,0,0,0,0,0,0,0,0,0,0,0,0,0,0,0,0,0,0,0,0,0,0
0,2,2,0,2,2,0,0,0,0,0,0,0,0,0,0,0,0,0,0,0,2,2,0,2,2,0
0,2,0,0,0,2,0,0,0,0,0,0,0,0,0,0,0,0,0,0,0,2,0,0,0,2,0
0,0,0,0,6,2,2,2,2,2,2,2,2,2,2,2,2,2,2,2,2,2,6,0,0,0,0
0,2,0,5,7,2,6,6,6,36,32,0,0,0,0,0,31,36,6,6,6,2,7,5,0,2,0
0,2,2,2,2,2,6,6,6,36,32,0,0,0,0,0,31,36,6,6,6,2,2,2,2,2,0
0,0,0,2,6,6,6,6,6,36,32,0,0,0,0,0,31,36,6,6,6,6,6,2,0,0,0
0,0,0,2,6,6,6,6,6,36,30,0,0,0,0,0,33,36,6,6,6,6,6,2,0,0,0
0,0,0,2,6,6,6,6,6,36,30,0,0,0,0,0,33,36,6,6,6,6,6,2,0,0,0
0,0,0,2,6,6,6,6,6,2,2,0,0,0,0,0,2,2,6,6,6,6,6,2,0,0,0
0,0,0,2,34,34,34,34,34,2,2,34,34,34,34,34,2,2,34,34,34,34,34,2,0,0,0
0,0,0,2,6,6,6,6,6,36,6,6,6,6,6,6,6,36,6,6,6,6,6,2,0,0,0
0,0,0,2,6,6,6,6,6,36,34,34,34,34,34,34,34,36,6,6,6,6,6,2,0,0,0
0,0,0,2,6,6,6,6,6,36,0,0,0,0,0,0,0,36,6,6,6,6,6,2,0,0,0
0,0,0,2,6,6,6,6,6,36,0,0,0,0,0,0,0,36,6,6,6,6,6,2,0,0,0
0,0,0,2,6,6,6,6,6,36,0,0,0,0,0,0,0,36,6,6,6,6,6,2,0,0,0
0,0,0,2,34,34,34,34,34,2,2,0,0,0,0,0,2,2,34,34,34,34,34,2,0,0,0
0,0,0,2,6,6,6,6,6,2,2,0,0,0,0,0,2,2,6,6,6,6,6,2,0,0,0
0,0,0,2,6,6,6,6,6,36,0,0,0,0,0,0,0,36,6,6,6,6,6,2,0,0,0
0,0,0,2,6,6,6,6,6,36,0,0,0,0,0,0,0,36,6,6,6,6,6,2,0,0,0
0,0,0,2,6,6,6,6,6,36,0,0,0,0,0,0,0,36,6,6,6,6,6,2,0,0,0
0,2,2,2,2,2,6,6,7,2,2,2,2,2,2,2,2,2,7,6,6,2,2,2,2,2,0
0,2,0,5,7,2,6,6,7,2,2,2,2,2,2,2,2,2,7,6,6,2,7,5,0,2,0
0,0,0,0,6,2,2,2,2,2,2,2,2,2,2,2,2,2,2,35,2,2,6,0,0,0,0
0,2,0,0,0,2,0,0,0,0,0,0,0,0,0,0,0,0,0,0,0,2,0,0,0,2,0
0,2,2,0,2,2,0,0,0,0,0,0,0,0,0,0,0,0,0,0,0,2,2,0,2,2,0
0,0,0,0,0,0,0,0,0,0,0,0,0,0,0,0,0,0,0,0,0,0,0,0,0,0,0
:endlayer
layer: 6
0,0,0,0,0,0,0,0,0,0,0,0,0,0,0,0,0,0,0,0,0,0,0,0,0,0,0
0,2,2,28,2,2,0,0,0,0,0,0,0,0,0,0,0,0,0,0,0,2,2,28,2,2,0
0,2,0,6,7,2,0,0,0,0,0,0,0,0,0,0,0,0,0,0,0,2,7,6,0,2,0
0,27,0,0,5,2,2,24,2,2,2,24,2,2,2,24,2,2,2,24,2,2,5,0,0,26,0
0,2,0,0,0,0,0,0,0,0,0,0,0,0,0,0,0,0,0,0,0,0,0,0,0,2,0
0,2,2,2,0,2,0,0,0,0,0,0,0,0,0,0,0,0,0,0,0,2,0,2,2,2,0
0,0,0,2,0,0,0,0,0,0,0,0,0,0,0,0,0,0,0,0,0,0,0,2,0,0,0
0,0,0,24,0,0,0,0,0,0,31,30,0,0,0,33,32,0,0,0,0,0,0,24,0,0,0
0,0,0,2,0,0,0,0,0,0,31,30,0,0,0,33,32,0,0,0,0,0,0,2,0,0,0
0,0,0,2,0,0,0,0,0,2,2,0,0,0,0,0,2,2,0,0,0,0,0,2,0,0,0
0,0,0,2,0,0,0,0,0,2,2,38,38,38,38,38,2,2,0,0,0,0,0,2,0,0,0
0,0,0,24,0,0,0,0,0,0,0,0,0,0,0,0,0,0,0,0,0,0,0,24,0,0,0
0,0,0,2,0,0,0,0,0,38,38,38,38,38,38,38,38,38,0,0,0,0,0,2,0,0,0
0,0,0,35,39,0,0,0,0,38,0,0,0,0,0,0,0,38,0,0,0,0,37,2,0,0,0
0,0,0,2,0,0,0,0,0,38,0,0,0,0,0,0,0,38,0,0,0,0,0,2,0,0,0
0,0,0,24,0,0,0,0,0,38,0,0,0,0,0,0,0,38,0,0,0,0,0,24,0,0,0
0,0,0,2,0,0,0,0,0,2,2,0,0,0,0,0,2,2,0,0,0,0,0,2,0,0,0
0,0,0,2,0,0,0,0,0,2,2,0,0,0,0,0,2,2,0,0,0,0,0,2,0,0,0
0,0,0,2,0,0,0,0,0,38,0,0,0,0,0,0,0,38,0,0,0,0,0,2,0,0,0
0,0,0,24,0,0,0,0,0,38,0,0,0,0,0,0,0,38,0,0,0,0,0,24,0,0,0
0,0,0,2,0,0,0,0,0,38,0,0,0,0,0,0,0,38,0,0,0,0,0,2,0,0,0
0,2,2,2,0,2,0,0,0,2,2,35,24,35,24,35,2,2,0,0,0,2,0,2,2,2,0
0,2,0,0,0,0,0,0,0,24,0,0,0,0,0,0,0,24,0,0,0,0,0,0,0,2,0
0,27,0,0,5,2,2,24,2,2,2,24,2,2,2,24,2,2,2,24,2,2,5,0,0,26,0
0,2,0,6,7,2,0,0,0,0,0,0,0,0,0,0,0,0,0,0,0,2,7,6,0,2,0
0,2,2,29,2,2,0,0,0,0,0,0,0,0,0,0,0,0,0,0,0,2,2,29,2,2,0
0,0,0,0,0,0,0,0,0,0,0,0,0,0,0,0,0,0,0,0,0,0,0,0,0,0,0
:endlayer
layer: 7
0,0,0,0,0,0,0,0,0,0,0,0,0,0,0,0,0,0,0,0,0,0,0,0,0,0,0
0,2,2,2,2,2,0,0,0,0,0,0,0,0,0,0,0,0,0,0,0,2,2,2,2,2,0
0,2,7,5,0,2,0,0,0,0,0,0,0,0,0,0,0,0,0,0,0,2,0,5,7,2,0
0,2,6,0,0,2,2,25,2,2,2,25,2,2,2,25,2,2,2,25,2,2,0,0,6,2,0
0,2,0,19,0,0,0,0,0,20,20,0,0,0,0,0,20,20,0,0,0,0,0,19,0,2,0
0,2,2,2,0,2,22,0,0,0,0,0,0,0,0,0,0,0,0,0,21,2,0,2,2,2,0
0,0,0,2,0,20,0,0,0,0,0,0,0,0,0,0,0,0,0,0,0,20,0,2,0,0,0
0,0,0,25,0,0,0,0,0,0,0,31,30,0,33,32,0,0,0,0,0,0,0,25,0,0,0
0,0,0,2,0,0,0,0,0,19,19,31,30,0,33,32,19,19,0,0,0,0,0,2,0,0,0
0,0,0,2,22,0,0,0,21,2,2,22,0,0,0,21,2,2,22,0,0,0,21,2,0,0,0
0,0,0,2,22,0,0,0,21,2,2,22,0,0,0,21,2,2,22,0,0,0,21,2,0,0,0
0,0,0,25,0,0,0,0,0,20,20,0,0,0,0,0,20,20,0,0,0,0,0,25,0,0,0
0,0,0,2,0,0,0,0,0,0,0,0,0,0,0,0,0,0,0,0,0,0,0,2,0,0,0
0,0,0,2,0,0,0,0,0,0,0,0,0,0,0,0,0,0,0,0,0,0,0,2,0,0,0
0,0,0,2,0,0,0,0,0,0,0,0,0,0,0,0,0,0,0,0,0,0,0,2,0,0,0
0,0,0,25,0,0,0,0,0,19,19,0,0,0,0,0,19,19,0,0,0,0,0,25,0,0,0
0,0,0,2,22,0,0,0,21,2,2,22,0,0,0,21,2,2,22,0,0,0,21,2,0,0,0
0,0,0,2,22,0,0,0,21,2,2,22,0,0,0,21,2,2,22,0,0,0,21,2,0,0,0
0,0,0,2,0,0,0,0,0,20,20,0,0,0,0,0,20,20,0,0,0,0,0,2,0,0,0
0,0,0,25,0,0,0,0,0,0,0,0,0,0,0,0,0,0,0,0,0,0,0,25,0,0,0
0,0,0,2,0,19,0,0,0,19,19,0,0,0,0,0,19,19,0,0,0,0,0,2,0,0,0
0,2,2,2,0,2,22,0,21,2,2,35,0,35,0,35,2,2,22,0,0,2,0,2,2,2,0
0,2,0,20,0,0,0,0,0,0,0,0,0,0,0,0,0,0,0,0,0,0,0,20,0,2,0
0,2,6,0,0,2,2,25,2,2,2,25,2,2,2,25,2,2,2,25,2,2,0,0,6,2,0
0,2,7,5,0,2,0,0,0,0,0,0,0,0,0,0,0,0,0,0,0,2,0,5,7,2,0
0,2,2,2,2,2,0,0,0,0,0,0,0,0,0,0,0,0,0,0,0,2,2,2,2,2,0
0,0,0,0,0,0,0,0,0,0,0,0,0,0,0,0,0,0,0,0,0,0,0,0,0,0,0
:endlayer
layer: 8
0,0,0,0,0,0,0,0,0,0,0,0,0,0,0,0,0,0,0,0,0,0,0,0,0,0,0
0,2,2,2,2,2,0,0,0,0,0,0,0,0,0,0,0,0,0,0,0,2,2,2,2,2,0
0,2,0,0,0,2,29,0,29,0,29,0,29,0,29,0,29,0,29,0,29,2,0,0,0,2,0
0,2,5,0,0,2,4,4,4,4,4,4,4,4,4,4,4,4,4,4,4,2,0,0,5,2,0
0,2,7,6,0,2,0,0,0,28,28,0,0,0,0,0,28,28,0,0,0,2,0,6,7,2,0
0,2,2,2,2,2,27,25,25,25,25,25,25,25,25,25,25,25,25,25,26,2,2,2,2,2,0
0,0,26,4,0,28,0,0,0,0,0,0,7,7,7,0,0,0,0,0,0,28,0,4,27,0,0
0,0,0,4,0,25,0,0,0,0,0,0,5,5,5,0,0,0,0,0,0,25,0,4,0,0,0
0,0,26,4,0,25,0,0,0,0,0,0,5,5,5,0,0,0,0,0,0,25,0,4,27,0,0
0,0,0,4,27,25,0,0,26,2,2,27,0,0,0,26,2,2,27,0,0,25,26,4,0,0,0
0,0,26,4,27,25,0,0,26,2,2,27,0,0,0,26,2,2,27,0,0,25,26,4,27,0,0
0,0,0,4,0,25,0,0,0,28,28,0,0,0,0,0,28,28,0,0,0,25,0,4,0,0,0
0,0,26,4,0,25,0,0,0,0,0,0,0,0,0,0,0,0,0,0,0,25,0,4,27,0,0
0,0,0,4,0,25,0,0,0,0,0,0,0,0,0,0,0,0,0,0,0,25,0,4,0,0,0
0,0,26,4,0,25,0,0,0,0,0,0,0,0,0,0,0,0,0,0,0,25,0,4,27,0,0
0,0,0,4,0,25,0,0,0,29,29,0,0,0,0,0,29,29,0,0,0,25,0,4,0,0,0
0,0,26,4,27,25,0,0,26,2,2,27,0,0,0,26,2,2,27,0,0,25,26,4,27,0,0
0,0,0,4,27,25,0,0,26,2,2,27,0,0,0,26,2,2,27,0,0,25,26,4,0,0,0
0,0,26,4,0,25,0,0,0,28,28,0,0,0,0,0,28,28,0,0,0,25,0,4,27,0,0
0,0,0,4,0,25,0,0,0,0,0,0,0,0,0,0,0,0,0,0,0,25,0,4,0,0,0
0,0,26,4,0,29,0,0,0,29,29,0,0,0,0,0,29,29,0,0,0,29,0,4,27,0,0
0,2,2,2,2,2,27,25,26,2,2,2,2,2,2,2,2,2,27,25,26,2,2,2,2,2,0
0,2,7,6,0,2,0,0,0,25,0,0,0,0,0,0,0,25,0,0,0,2,0,6,7,2,0
0,2,5,0,0,2,4,4,4,4,4,4,4,4,4,4,4,4,4,4,4,2,0,0,5,2,0
0,2,0,0,0,2,28,0,28,0,28,0,28,0,28,0,28,0,28,0,28,2,0,0,0,2,0
0,2,2,2,2,2,0,0,0,0,0,0,0,0,0,0,0,0,0,0,0,2,2,2,2,2,0
0,0,0,0,0,0,0,0,0,0,0,0,0,0,0,0,0,0,0,0,0,0,0,0,0,0,0
:endlayer
layer: 9
0,0,0,0,0,0,0,0,0,0,0,0,0,0,0,0,0,0,0,0,0,0,0,0,0,0,0
0,2,2,2,2,2,0,0,0,0,0,0,0,0,0,0,0,0,0,0,0,2,2,2,2,2,0
0,2,0,0,0,2,2,2,2,2,2,2,2,2,2,2,2,2,2,2,2,2,0,0,0,2,0
0,2,0,0,6,2,4,4,4,2,4,4,4,4,4,4,4,2,4,4,4,2,6,0,0,2,0
0,2,0,5,7,2,4,4,4,2,2,2,2,2,2,2,2,2,4,4,4,2,7,5,0,2,0
0,2,2,2,2,2,4,4,4,2,2,2,5,5,5,2,2,2,4,4,4,2,2,2,2,2,0
0,0,2,4,4,4,40,40,4,2,28,2,0,0,0,2,28,2,4,40,40,4,4,4,2,0,0
0,0,2,4,4,4,40,40,4,27,0,0,0,0,0,0,0,26,4,40,40,4,4,4,2,0,0
0,0,2,4,4,4,40,40,4,27,0,0,0,0,0,0,0,26,4,40,40,4,4,4,2,0,0
0,0,2,2,2,2,2,2,2,2,2,2,2,2,2,2,2,2,2,2,2,2,2,2,2,0,0
0,0,2,2,2,2,2,2,2,2,2,2,2,2,2,2,2,2,2,2,2,2,2,2,2,0,0
0,0,2,4,4,4,40,40,40,2,2,0,0,0,0,0,2,2,40,40,40,4,4,4,2,0,0
0,0,2,4,4,4,40,40,40,2,2,0,0,0,0,0,2,2,40,40,40,4,4,4,2,0,0
0,0,2,4,4,4,40,40,40,2,2,0,0,0,0,0,2,2,40,40,40,4,4,4,2,0,0
0,0,2,4,4,4,40,40,40,2,2,0,0,0,0,0,2,2,40,40,40,4,4,4,2,0,0
0,0,2,4,4,4,40,40,40,2,2,0,0,0,0,0,2,2,40,40,40,4,4,4,2,0,0
0,0,2,2,2,2,2,2,2,2,2,2,2,2,2,2,2,2,2,2,2,2,2,2,2,0,0
0,0,2,2,2,2,2,2,2,2,2,2,2,2,2,2,2,2,2,2,2,2,2,2,2,0,0
0,0,2,4,4,4,40,40,40,2,2,40,40,40,40,40,2,2,40,40,40,4,4,4,2,0,0
0,0,2,4,4,4,40,40,40,2,2,40,40,40,40,40,2,2,40,40,40,4,4,4,2,0,0
0,0,2,4,4,4,40,40,40,2,2,40,40,40,40,40,2,2,40,40,40,4,4,4,2,0,0
0,2,2,2,2,4,4,4,4,2,2,4,4,4,4,4,2,2,4,4,4,4,2,2,2,2,0
0,2,0,5,7,2,4,4,4,2,2,4,4,4,4,4,2,2,4,4,4,2,7,5,0,2,0
0,2,0,0,6,2,4,4,4,2,2,4,4,4,4,4,2,2,4,4,4,2,6,0,0,2,0
0,2,0,0,0,2,2,2,2,2,2,2,2,2,2,2,2,2,2,2,2,2,0,0,0,2,0
0,2,2,2,2,2,0,0,0,0,0,0,0,0,0,0,0,0,0,0,0,2,2,2,2,2,0
0,0,0,0,0,0,0,0,0,0,0,0,0,0,0,0,0,0,0,0,0,0,0,0,0,0,0
:endlayer
layer: 10
0,0,0,0,0,0,0,0,0,0,0,0,0,0,0,0,0,0,0,0,0,0,0,0,0,0,0
0,2,2,2,2,2,0,0,0,0,0,0,0,0,0,0,0,0,0,0,0,2,2,2,2,2,0
0,2,0,6,7,2,2,2,2,2,2,2,2,2,2,2,2,2,2,2,2,2,7,6,0,2,0
0,2,0,0,5,2,2,2,2,2,2,2,2,2,2,2,2,2,2,2,2,2,5,0,0,2,0
0,2,0,0,0,0,0,24,24,24,24,24,0,0,0,24,24,24,24,24,0,0,0,0,0,2,0
0,2,2,2,0,2,0,0,0,0,0,0,0,0,0,0,0,0,0,0,0,2,0,2,2,2,0
0,0,2,2,0,0,0,0,0,0,0,0,0,0,0,0,0,0,0,0,0,0,0,2,2,0,0
0,0,2,2,24,0,0,0,0,0,0,0,0,0,0,0,0,0,0,0,0,0,24,2,2,0,0
0,0,2,2,24,0,0,0,0,0,0,0,0,0,0,0,0,0,0,0,0,0,24,2,2,0,0
0,0,2,2,24,0,0,0,0,24,24,24,24,24,24,24,24,24,0,0,0,0,24,2,2,0,0
0,0,2,2,24,0,0,0,0,24,2,2,2,2,2,2,2,24,0,0,0,0,24,2,2,0,0
0,0,2,2,24,0,0,0,0,24,2,0,0,0,0,0,2,24,0,0,0,0,24,2,2,0,0
0,0,2,2,24,0,0,0,0,24,2,0,0,0,0,0,2,24,0,0,0,0,24,2,2,0,0
0,0,2,2,24,0,0,0,0,24,2,0,0,0,0,0,2,24,0,0,0,0,24,2,2,0,0
0,0,2,2,24,0,0,0,0,24,2,0,0,0,0,0,2,24,0,0,0,0,24,2,2,0,0
0,0,2,2,24,0,0,0,0,24,2,0,0,0,0,0,2,24,0,0,0,0,24,2,2,0,0
0,0,2,2,24,0,0,0,0,24,2,2,2,2,2,2,2,24,0,0,0,0,24,2,2,0,0
0,0,35,2,24,0,0,0,0,24,24,24,24,24,24,24,24,24,0,0,0,0,24,2,2,0,0
0,0,2,2,24,0,0,0,0,0,0,0,0,0,0,0,0,0,0,0,0,0,24,2,2,0,0
0,0,2,2,24,0,0,0,0,0,0,0,0,0,0,0,0,0,0,0,0,0,24,2,2,0,0
0,0,2,2,0,0,0,0,0,0,0,0,0,0,0,0,0,0,0,0,0,0,0,2,2,0,0
0,2,2,2,0,2,0,0,0,0,0,0,0,0,0,0,0,0,0,0,0,2,0,2,2,2,0
0,2,0,0,0,0,0,24,24,24,24,24,24,24,24,24,24,24,24,24,0,0,0,0,0,2,0
0,2,0,0,5,2,2,2,2,2,2,2,2,2,2,2,2,2,2,2,2,2,5,0,0,2,0
0,2,0,6,7,2,2,2,2,2,2,2,2,2,2,2,2,2,2,2,2,2,7,6,0,2,0
0,2,2,2,2,2,0,0,0,0,0,0,0,0,0,0,0,0,0,0,0,2,2,2,2,2,0
0,0,0,0,0,0,0,0,0,0,0,0,0,0,0,0,0,0,0,0,0,0,0,0,0,0,0
:endlayer
layer: 11
0,0,0,0,0,0,0,0,0,0,0,0,0,0,0,0,0,0,0,0,0,0,0,0,0,0,0
0,2,2,2,2,2,0,0,0,0,0,0,0,0,0,0,0,0,0,0,0,2,2,2,2,2,0
0,2,7,5,0,2,35,24,35,24,2,24,35,24,35,24,2,24,35,24,35,2,0,5,7,2,0
0,2,6,0,0,2,0,0,20,0,0,0,20,0,20,0,0,0,20,0,0,2,0,0,6,2,0
0,2,0,19,0,0,0,0,0,0,0,0,0,0,0,0,0,0,0,0,0,0,0,19,0,2,0
0,2,2,2,0,2,22,0,0,0,0,0,0,0,0,0,0,0,0,0,21,2,0,2,2,2,0
0,0,35,0,0,20,0,0,0,0,0,0,0,0,0,0,0,0,0,0,0,20,0,0,2,0,0
0,0,24,0,0,0,0,0,0,0,0,0,0,0,0,0,0,0,0,0,0,0,0,0,24,0,0
0,0,35,22,0,0,0,0,0,0,0,0,0,0,0,0,0,0,0,0,0,0,0,21,2,0,0
0,0,24,0,0,0,0,0,0,0,19,0,0,0,0,0,19,0,0,0,0,0,0,0,24,0,0
0,0,2,0,0,0,0,0,0,21,2,2,2,2,2,2,2,22,0,0,0,0,0,0,2,0,0
0,0,24,0,0,0,0,0,0,0,2,0,0,0,0,0,2,0,0,0,0,0,0,0,24,0,0
0,0,35,22,0,0,0,0,0,0,2,0,0,0,0,0,2,0,0,0,0,0,0,21,35,0,0
0,0,24,0,0,0,0,0,0,0,2,0,0,0,0,0,2,0,0,0,0,0,0,0,24,0,0
0,0,35,22,0,0,0,0,0,0,2,0,0,0,0,0,2,0,0,0,0,0,0,21,35,0,0
0,0,24,0,0,0,0,0,0,0,2,0,0,0,0,0,2,0,0,0,0,0,0,0,24,0,0
0,0,2,0,0,0,0,0,0,21,2,2,2,2,2,2,2,22,0,0,0,0,0,0,2,0,0
0,0,24,0,0,0,0,0,0,0,20,0,0,0,0,0,20,0,0,0,0,0,0,0,24,0,0
0,0,35,22,0,0,0,0,0,0,0,0,0,0,0,0,0,0,0,0,0,0,0,21,35,0,0
0,0,24,0,0,0,0,0,0,0,0,0,0,0,0,0,0,0,0,0,0,0,0,0,24,0,0
0,0,35,0,0,19,0,0,0,0,0,0,0,0,0,0,0,0,0,0,0,19,0,0,35,0,0
0,2,2,2,0,2,22,0,0,0,0,0,0,0,0,0,0,0,0,0,21,2,0,2,2,2,0
0,2,0,20,0,0,0,0,0,0,0,0,0,0,0,0,0,0,0,0,0,0,0,20,0,2,0
0,2,6,0,0,2,0,0,19,0,0,0,19,0,19,0,0,0,19,0,0,2,0,0,6,2,0
0,2,7,5,0,2,35,24,35,24,2,24,35,24,35,24,2,24,35,24,35,2,0,5,7,2,0
0,2,2,2,2,2,0,0,0,0,0,0,0,0,0,0,0,0,0,0,0,2,2,2,2,2,0
0,0,0,0,0,0,0,0,0,0,0,0,0,0,0,0,0,0,0,0,0,0,0,0,0,0,0
:endlayer
layer: 12
0,29,25,29,25,29,0,0,0,0,0,0,0,0,0,0,0,0,0,0,0,29,25,29,25,29,0
26,4,4,4,4,4,27,0,0,0,0,0,0,0,0,0,0,0,0,0,26,4,4,4,4,4,27
25,4,0,0,0,4,25,0,0,0,0,0,0,0,0,0,0,0,0,0,25,4,0,0,0,4,25
26,4,5,0,0,4,27,0,0,0,0,0,0,0,0,0,0,0,0,0,26,4,0,0,5,4,27
25,4,7,6,0,4,25,0,0,0,0,0,0,0,0,0,0,0,0,0,25,4,0,6,7,4,25
26,4,4,4,4,4,27,0,0,0,0,0,0,0,0,0,0,0,0,0,26,4,4,4,4,4,27
0,28,25,28,25,28,0,0,0,0,0,0,0,0,0,0,0,0,0,0,0,28,25,28,25,28,0
0,0,0,0,0,0,0,0,0,0,0,0,0,0,0,0,0,0,0,0,0,0,0,0,0,0,0
0,0,0,0,0,0,0,0,0,0,0,0,0,0,0,0,0,0,0,0,0,0,0,0,0,0,0
0,0,0,0,0,0,0,0,0,0,0,0,0,0,0,0,0,0,0,0,0,0,0,0,0,0,0
0,0,0,0,0,0,0,0,0,0,0,0,0,0,0,0,0,0,0,0,0,0,0,0,0,0,0
0,0,0,0,0,0,0,0,0,0,0,0,0,0,0,0,0,0,0,0,0,0,0,0,0,0,0
0,0,0,0,0,0,0,0,0,0,0,0,0,0,0,0,0,0,0,0,0,0,0,0,0,0,0
0,0,0,0,0,0,0,0,0,0,0,0,0,0,0,0,0,0,0,0,0,0,0,0,0,0,0
0,0,0,0,0,0,0,0,0,0,0,0,0,0,0,0,0,0,0,0,0,0,0,0,0,0,0
0,0,0,0,0,0,0,0,0,0,0,0,0,0,0,0,0,0,0,0,0,0,0,0,0,0,0
0,0,0,0,0,0,0,0,0,0,0,0,0,0,0,0,0,0,0,0,0,0,0,0,0,0,0
0,0,0,0,0,0,0,0,0,0,0,0,0,0,0,0,0,0,0,0,0,0,0,0,0,0,0
0,0,0,0,0,0,0,0,0,0,0,0,0,0,0,0,0,0,0,0,0,0,0,0,0,0,0
0,0,0,0,0,0,0,0,0,0,0,0,0,0,0,0,0,0,0,0,0,0,0,0,0,0,0
0,29,25,29,25,29,0,0,0,0,0,0,0,0,0,0,0,0,0,0,0,29,25,29,25,29,0
26,4,4,4,4,4,27,0,0,0,0,0,0,0,0,0,0,0,0,0,26,4,4,4,4,4,27
25,4,7,6,0,4,25,0,0,0,0,0,0,0,0,0,0,0,0,0,25,4,0,6,7,4,25
26,4,5,0,0,4,27,0,0,0,0,0,0,0,0,0,0,0,0,0,26,4,0,0,5,4,27
25,4,0,0,0,4,25,0,0,0,0,0,0,0,0,0,0,0,0,0,25,4,0,0,0,4,25
26,4,4,4,4,4,27,0,0,0,0,0,0,0,0,0,0,0,0,0,26,4,4,4,4,4,27
0,28,25,28,25,28,0,0,0,0,0,0,0,0,0,0,0,0,0,0,0,28,25,28,25,28,0
:endlayer
layer: 13
2,2,2,2,2,2,2,0,0,0,0,0,0,0,0,0,0,0,0,0,2,2,2,2,2,2,2
2,2,2,2,2,2,2,0,0,0,0,0,0,0,0,0,0,0,0,0,2,2,2,2,2,2,2
2,2,0,0,6,2,2,0,0,0,0,0,0,0,0,0,0,0,0,0,2,2,6,0,0,2,2
2,2,0,6,6,2,2,0,0,0,0,0,0,0,0,0,0,0,0,0,2,2,6,6,0,2,2
2,2,0,5,7,2,2,0,0,0,0,0,0,0,0,0,0,0,0,0,2,2,7,5,0,2,2
2,2,2,2,2,2,2,0,0,0,0,0,0,0,0,0,0,0,0,0,2,2,2,2,2,2,2
2,2,2,2,2,2,2,0,0,0,0,0,0,0,0,0,0,0,0,0,2,2,2,2,2,2,2
0,0,0,0,0,0,0,0,0,0,0,0,0,0,0,0,0,0,0,0,0,0,0,0,0,0,0
0,0,0,0,0,0,0,0,0,0,0,0,0,0,0,0,0,0,0,0,0,0,0,0,0,0,0
0,0,0,0,0,0,0,0,0,0,0,0,0,0,0,0,0,0,0,0,0,0,0,0,0,0,0
0,0,0,0,0,0,0,0,0,0,0,0,0,0,0,0,0,0,0,0,0,0,0,0,0,0,0
0,0,0,0,0,0,0,0,0,0,0,0,0,0,0,0,0,0,0,0,0,0,0,0,0,0,0
0,0,0,0,0,0,0,0,0,0,0,0,0,0,0,0,0,0,0,0,0,0,0,0,0,0,0
0,0,0,0,0,0,0,0,0,0,0,0,0,0,0,0,0,0,0,0,0,0,0,0,0,0,0
0,0,0,0,0,0,0,0,0,0,0,0,0,0,0,0,0,0,0,0,0,0,0,0,0,0,0
0,0,0,0,0,0,0,0,0,0,0,0,0,0,0,0,0,0,0,0,0,0,0,0,0,0,0
0,0,0,0,0,0,0,0,0,0,0,0,0,0,0,0,0,0,0,0,0,0,0,0,0,0,0
0,0,0,0,0,0,0,0,0,0,0,0,0,0,0,0,0,0,0,0,0,0,0,0,0,0,0
0,0,0,0,0,0,0,0,0,0,0,0,0,0,0,0,0,0,0,0,0,0,0,0,0,0,0
0,0,0,0,0,0,0,0,0,0,0,0,0,0,0,0,0,0,0,0,0,0,0,0,0,0,0
2,2,2,2,2,2,2,0,0,0,0,0,0,0,0,0,0,0,0,0,2,2,2,2,2,2,2
2,2,2,2,2,2,2,0,0,0,0,0,0,0,0,0,0,0,0,0,2,2,2,2,2,2,2
2,2,0,5,7,2,2,0,0,0,0,0,0,0,0,0,0,0,0,0,2,2,7,5,0,2,2
2,2,0,6,6,2,2,0,0,0,0,0,0,0,0,0,0,0,0,0,2,2,6,6,0,2,2
2,2,0,0,6,2,2,0,0,0,0,0,0,0,0,0,0,0,0,0,2,2,6,0,0,2,2
2,2,2,2,2,2,2,0,0,0,0,0,0,0,0,0,0,0,0,0,2,2,2,2,2,2,2
2,2,2,2,2,2,2,0,0,0,0,0,0,0,0,0,0,0,0,0,2,2,2,2,2,2,2
:endlayer
layer: 14
2,2,2,2,2,2,2,0,0,0,0,0,0,0,0,0,0,0,0,0,2,2,2,2,2,2,2
2,0,0,0,0,0,2,0,0,0,0,0,0,0,0,0,0,0,0,0,2,0,0,0,0,0,2
2,0,0,0,0,0,2,0,0,0,0,0,0,0,0,0,0,0,0,0,2,0,0,0,0,0,2
2,0,0,41,0,0,2,0,0,0,0,0,0,0,0,0,0,0,0,0,2,0,0,41,0,0,2
2,0,0,0,0,0,2,0,0,0,0,0,0,0,0,0,0,0,0,0,2,0,0,0,0,0,2
2,0,0,0,0,0,2,0,0,0,0,0,0,0,0,0,0,0,0,0,2,0,0,0,0,0,2
2,2,2,2,2,2,2,0,0,0,0,0,0,0,0,0,0,0,0,0,2,2,2,2,2,2,2
0,0,0,0,0,0,0,0,0,0,0,0,0,0,0,0,0,0,0,0,0,0,0,0,0,0,0
0,0,0,0,0,0,0,0,0,0,0,0,0,0,0,0,0,0,0,0,0,0,0,0,0,0,0
0,0,0,0,0,0,0,0,0,0,0,0,0,0,0,0,0,0,0,0,0,0,0,0,0,0,0
0,0,0,0,0,0,0,0,0,0,0,0,0,0,0,0,0,0,0,0,0,0,0,0,0,0,0
0,0,0,0,0,0,0,0,0,0,0,0,0,0,0,0,0,0,0,0,0,0,0,0,0,0,0
0,0,0,0,0,0,0,0,0,0,0,0,0,0,0,0,0,0,0,0,0,0,0,0,0,0,0
0,0,0,0,0,0,0,0,0,0,0,0,0,0,0,0,0,0,0,0,0,0,0,0,0,0,0
0,0,0,0,0,0,0,0,0,0,0,0,0,0,0,0,0,0,0,0,0,0,0,0,0,0,0
0,0,0,0,0,0,0,0,0,0,0,0,0,0,0,0,0,0,0,0,0,0,0,0,0,0,0
0,0,0,0,0,0,0,0,0,0,0,0,0,0,0,0,0,0,0,0,0,0,0,0,0,0,0
0,0,0,0,0,0,0,0,0,0,0,0,0,0,0,0,0,0,0,0,0,0,0,0,0,0,0
0,0,0,0,0,0,0,0,0,0,0,0,0,0,0,0,0,0,0,0,0,0,0,0,0,0,0
0,0,0,0,0,0,0,0,0,0,0,0,0,0,0,0,0,0,0,0,0,0,0,0,0,0,0
2,2,2,2,2,2,2,0,0,0,0,0,0,0,0,0,0,0,0,0,2,2,2,2,2,2,2
2,0,0,0,0,0,2,0,0,0,0,0,0,0,0,0,0,0,0,0,2,0,0,0,0,0,2
2,0,0,0,0,0,2,0,0,0,0,0,0,0,0,0,0,0,0,0,2,0,0,0,0,0,2
2,0,0,41,0,0,2,0,0,0,0,0,0,0,0,0,0,0,0,0,2,0,0,41,0,0,2
2,0,0,0,0,0,2,0,0,0,0,0,0,0,0,0,0,0,0,0,2,0,0,0,0,0,2
2,0,0,0,0,0,2,0,0,0,0,0,0,0,0,0,0,0,0,0,2,0,0,0,0,0,2
2,2,2,2,2,2,2,0,0,0,0,0,0,0,0,0,0,0,0,0,2,2,2,2,2,2,2
:endlayer
layer: 15
2,24,2,24,2,24,2,0,0,0,0,0,0,0,0,0,0,0,0,0,2,24,2,24,2,24,2
24,0,0,0,0,0,24,0,0,0,0,0,0,0,0,0,0,0,0,0,24,0,0,0,0,0,24
2,0,0,0,0,0,2,0,0,0,0,0,0,0,0,0,0,0,0,0,2,0,0,0,0,0,2
24,0,0,0,0,0,24,0,0,0,0,0,0,0,0,0,0,0,0,0,24,0,0,0,0,0,24
2,0,0,0,0,0,2,0,0,0,0,0,0,0,0,0,0,0,0,0,2,0,0,0,0,0,2
24,0,0,0,0,0,24,0,0,0,0,0,0,0,0,0,0,0,0,0,24,0,0,0,0,0,24
2,24,2,24,2,24,2,0,0,0,0,0,0,0,0,0,0,0,0,0,2,24,2,24,2,24,2
0,0,0,0,0,0,0,0,0,0,0,0,0,0,0,0,0,0,0,0,0,0,0,0,0,0,0
0,0,0,0,0,0,0,0,0,0,0,0,0,0,0,0,0,0,0,0,0,0,0,0,0,0,0
0,0,0,0,0,0,0,0,0,0,0,0,0,0,0,0,0,0,0,0,0,0,0,0,0,0,0
0,0,0,0,0,0,0,0,0,0,0,0,0,0,0,0,0,0,0,0,0,0,0,0,0,0,0
0,0,0,0,0,0,0,0,0,0,0,0,0,0,0,0,0,0,0,0,0,0,0,0,0,0,0
0,0,0,0,0,0,0,0,0,0,0,0,0,0,0,0,0,0,0,0,0,0,0,0,0,0,0
0,0,0,0,0,0,0,0,0,0,0,0,0,0,0,0,0,0,0,0,0,0,0,0,0,0,0
0,0,0,0,0,0,0,0,0,0,0,0,0,0,0,0,0,0,0,0,0,0,0,0,0,0,0
0,0,0,0,0,0,0,0,0,0,0,0,0,0,0,0,0,0,0,0,0,0,0,0,0,0,0
0,0,0,0,0,0,0,0,0,0,0,0,0,0,0,0,0,0,0,0,0,0,0,0,0,0,0
0,0,0,0,0,0,0,0,0,0,0,0,0,0,0,0,0,0,0,0,0,0,0,0,0,0,0
0,0,0,0,0,0,0,0,0,0,0,0,0,0,0,0,0,0,0,0,0,0,0,0,0,0,0
0,0,0,0,0,0,0,0,0,0,0,0,0,0,0,0,0,0,0,0,0,0,0,0,0,0,0
2,24,2,24,2,24,2,0,0,0,0,0,0,0,0,0,0,0,0,0,2,24,2,24,2,24,2
24,0,0,0,0,0,24,0,0,0,0,0,0,0,0,0,0,0,0,0,24,0,0,0,0,0,24
2,0,0,0,0,0,2,0,0,0,0,0,0,0,0,0,0,0,0,0,2,0,0,0,0,0,2
24,0,0,0,0,0,24,0,0,0,0,0,0,0,0,0,0,0,0,0,24,0,0,0,0,0,24
2,0,0,0,0,0,2,0,0,0,0,0,0,0,0,0,0,0,0,0,2,0,0,0,0,0,2
24,0,0,0,0,0,24,0,0,0,0,0,0,0,0,0,0,0,0,0,24,0,0,0,0,0,24
2,24,2,24,2,24,2,0,0,0,0,0,0,0,0,0,0,0,0,0,2,24,2,24,2,24,2
:endlayer

#### RULES ####
rule:
plugin=vanillaBlocks
number=1
data:
tag:
TAG=10={
TAG=8=blockName{grass}
TAG=3=meta{0}
TAG=3=buildPass{0}
}
:endtag
:enddata
:endrule

rule:
plugin=vanillaBlocks
number=2
data:
tag:
TAG=10={
TAG=8=blockName{stonebrick}
TAG=3=meta{0}
TAG=3=buildPass{0}
}
:endtag
:enddata
:endrule

rule:
plugin=vanillaBlocks
number=3
data:
tag:
TAG=10={
TAG=8=blockName{stone}
TAG=3=meta{0}
TAG=3=buildPass{0}
}
:endtag
:enddata
:endrule

rule:
plugin=vanillaBlocks
number=4
data:
tag:
TAG=10={
TAG=8=blockName{double_stone_slab}
TAG=3=meta{0}
TAG=3=buildPass{0}
}
:endtag
:enddata
:endrule

rule:
plugin=vanillaBlocks
number=5
data:
tag:
TAG=10={
TAG=8=blockName{wooden_slab}
TAG=3=meta{0}
TAG=3=buildPass{0}
}
:endtag
:enddata
:endrule

rule:
plugin=vanillaBlocks
number=6
data:
tag:
TAG=10={
TAG=8=blockName{wooden_slab}
TAG=3=meta{8}
TAG=3=buildPass{0}
}
:endtag
:enddata
:endrule

rule:
plugin=vanillaBlocks
number=7
data:
tag:
TAG=10={
TAG=8=blockName{double_wooden_slab}
TAG=3=meta{0}
TAG=3=buildPass{0}
}
:endtag
:enddata
:endrule

rule:
plugin=vanillaBlocks
number=8
data:
tag:
TAG=10={
TAG=8=blockName{lever}
TAG=3=meta{2}
TAG=3=buildPass{3}
}
:endtag
:enddata
:endrule

rule:
plugin=vanillaBlocks
number=9
data:
tag:
TAG=10={
TAG=8=blockName{stone_button}
TAG=3=meta{2}
TAG=3=buildPass{3}
}
:endtag
:enddata
:endrule

rule:
plugin=vanillaBlocks
number=10
data:
tag:
TAG=10={
TAG=8=blockName{oak_stairs}
TAG=3=meta{6}
TAG=3=buildPass{0}
}
:endtag
:enddata
:endrule

rule:
plugin=vanillaBlocks
number=11
data:
tag:
TAG=10={
TAG=8=blockName{oak_stairs}
TAG=3=meta{3}
TAG=3=buildPass{0}
}
:endtag
:enddata
:endrule

rule:
plugin=vanillaDoors
number=12
data:
tag:
TAG=10={
TAG=1=sideFlag{8}
TAG=8=blockName{iron_door}
TAG=3=meta{1}
TAG=3=buildPass{1}
}
:endtag
:enddata
:endrule

rule:
plugin=vanillaBlocks
number=13
data:
tag:
TAG=10={
TAG=8=blockName{stone_brick_stairs}
TAG=3=meta{0}
TAG=3=buildPass{0}
}
:endtag
:enddata
:endrule

rule:
plugin=vanillaBlocks
number=14
data:
tag:
TAG=10={
TAG=8=blockName{stone_brick_stairs}
TAG=3=meta{2}
TAG=3=buildPass{0}
}
:endtag
:enddata
:endrule

rule:
plugin=vanillaBlocks
number=15
data:
tag:
TAG=10={
TAG=8=blockName{stone_button}
TAG=3=meta{3}
TAG=3=buildPass{3}
}
:endtag
:enddata
:endrule

rule:
plugin=vanillaDoors
number=16
data:
tag:
TAG=10={
TAG=1=sideFlag{0}
TAG=8=blockName{iron_door}
TAG=3=meta{8}
TAG=3=buildPass{1}
}
:endtag
:enddata
:endrule

rule:
plugin=vanillaBlocks
number=17
data:
tag:
TAG=10={
TAG=8=blockName{stone_button}
TAG=3=meta{4}
TAG=3=buildPass{3}
}
:endtag
:enddata
:endrule

rule:
plugin=vanillaBlocks
number=18
data:
tag:
TAG=10={
TAG=8=blockName{stone_brick_stairs}
TAG=3=meta{1}
TAG=3=buildPass{0}
}
:endtag
:enddata
:endrule

rule:
plugin=vanillaBlocks
number=19
data:
tag:
TAG=10={
TAG=8=blockName{torch}
TAG=3=meta{4}
TAG=3=buildPass{1}
}
:endtag
:enddata
:endrule

rule:
plugin=vanillaBlocks
number=20
data:
tag:
TAG=10={
TAG=8=blockName{torch}
TAG=3=meta{3}
TAG=3=buildPass{1}
}
:endtag
:enddata
:endrule

rule:
plugin=vanillaBlocks
number=21
data:
tag:
TAG=10={
TAG=8=blockName{torch}
TAG=3=meta{2}
TAG=3=buildPass{1}
}
:endtag
:enddata
:endrule

rule:
plugin=vanillaBlocks
number=22
data:
tag:
TAG=10={
TAG=8=blockName{torch}
TAG=3=meta{1}
TAG=3=buildPass{1}
}
:endtag
:enddata
:endrule

rule:
plugin=vanillaBlocks
number=23
data:
tag:
TAG=10={
TAG=8=blockName{oak_stairs}
TAG=3=meta{7}
TAG=3=buildPass{0}
}
:endtag
:enddata
:endrule

rule:
plugin=vanillaBlocks
number=24
data:
tag:
TAG=10={
TAG=8=blockName{stone_slab}
TAG=3=meta{5}
TAG=3=buildPass{0}
}
:endtag
:enddata
:endrule

rule:
plugin=vanillaBlocks
number=25
data:
tag:
TAG=10={
TAG=8=blockName{stone_slab}
TAG=3=meta{13}
TAG=3=buildPass{0}
}
:endtag
:enddata
:endrule

rule:
plugin=vanillaBlocks
number=26
data:
tag:
TAG=10={
TAG=8=blockName{stone_brick_stairs}
TAG=3=meta{4}
TAG=3=buildPass{0}
}
:endtag
:enddata
:endrule

rule:
plugin=vanillaBlocks
number=27
data:
tag:
TAG=10={
TAG=8=blockName{stone_brick_stairs}
TAG=3=meta{5}
TAG=3=buildPass{0}
}
:endtag
:enddata
:endrule

rule:
plugin=vanillaBlocks
number=28
data:
tag:
TAG=10={
TAG=8=blockName{stone_brick_stairs}
TAG=3=meta{7}
TAG=3=buildPass{0}
}
:endtag
:enddata
:endrule

rule:
plugin=vanillaBlocks
number=29
data:
tag:
TAG=10={
TAG=8=blockName{stone_brick_stairs}
TAG=3=meta{6}
TAG=3=buildPass{0}
}
:endtag
:enddata
:endrule

rule:
plugin=vanillaBlocks
number=30
data:
tag:
TAG=10={
TAG=8=blockName{oak_stairs}
TAG=3=meta{5}
TAG=3=buildPass{0}
}
:endtag
:enddata
:endrule

rule:
plugin=vanillaBlocks
number=31
data:
tag:
TAG=10={
TAG=8=blockName{oak_stairs}
TAG=3=meta{0}
TAG=3=buildPass{0}
}
:endtag
:enddata
:endrule

rule:
plugin=vanillaBlocks
number=32
data:
tag:
TAG=10={
TAG=8=blockName{oak_stairs}
TAG=3=meta{1}
TAG=3=buildPass{0}
}
:endtag
:enddata
:endrule

rule:
plugin=vanillaBlocks
number=33
data:
tag:
TAG=10={
TAG=8=blockName{oak_stairs}
TAG=3=meta{4}
TAG=3=buildPass{0}
}
:endtag
:enddata
:endrule

rule:
plugin=vanillaBlocks
number=34
data:
tag:
TAG=10={
TAG=8=blockName{log}
TAG=3=meta{4}
TAG=3=buildPass{0}
}
:endtag
:enddata
:endrule

rule:
plugin=vanillaBlocks
number=35
data:
tag:
TAG=10={
TAG=8=blockName{double_stone_slab}
TAG=3=meta{5}
TAG=3=buildPass{0}
}
:endtag
:enddata
:endrule

rule:
plugin=vanillaBlocks
number=36
data:
tag:
TAG=10={
TAG=8=blockName{log}
TAG=3=meta{8}
TAG=3=buildPass{0}
}
:endtag
:enddata
:endrule

rule:
plugin=vanillaInventory
number=37
data:
tag:
TAG=10={
TAG=3=lootLevel{2}
TAG=8=blockName{chest}
TAG=3=meta{4}
TAG=3=buildPass{0}
}
:endtag
:enddata
:endrule

rule:
plugin=vanillaBlocks
number=38
data:
tag:
TAG=10={
TAG=8=blockName{fence}
TAG=3=meta{0}
TAG=3=buildPass{0}
}
:endtag
:enddata
:endrule

rule:
plugin=vanillaInventory
number=39
data:
tag:
TAG=10={
TAG=3=lootLevel{1}
TAG=8=blockName{chest}
TAG=3=meta{5}
TAG=3=buildPass{0}
}
:endtag
:enddata
:endrule

rule:
plugin=vanillaBlocks
number=40
data:
tag:
TAG=10={
TAG=8=blockName{stone_slab}
TAG=3=meta{8}
TAG=3=buildPass{0}
}
:endtag
:enddata
:endrule

rule:
plugin=vanillaBlocks
number=41
data:
tag:
TAG=10={
TAG=8=blockName{torch}
TAG=3=meta{5}
TAG=3=buildPass{1}
}
:endtag
:enddata
:endrule

#### ENTITIES ####
entity:
plugin=awNpcOld
number=0
data:
position=14,4,5
tag:
TAG=10={
TAG=5=yOffset{0.5}
TAG=5=xOffset{0.48411536}
TAG=5=zOffset{0.45027336}
TAG=5=rotation{-75.65674}
TAG=3=npcLevel{2}
TAG=3=npcType{16}
TAG=3=npcTeam{17}
}
:endtag
:enddata
:endentity

entity:
plugin=awNpcOld
number=1
data:
position=12,4,5
tag:
TAG=10={
TAG=5=yOffset{0.5}
TAG=5=xOffset{0.20736444}
TAG=5=zOffset{0.66806173}
TAG=5=rotation{-17.456848}
TAG=3=npcLevel{0}
TAG=3=npcType{16}
TAG=3=npcTeam{17}
}
:endtag
:enddata
:endentity

entity:
plugin=awNpcOld
number=2
data:
position=17,6,4
tag:
TAG=10={
TAG=5=yOffset{0.0}
TAG=5=xOffset{0.60707736}
TAG=5=zOffset{0.76524794}
TAG=5=rotation{-78.50708}
TAG=3=npcLevel{0}
TAG=3=npcType{17}
TAG=3=npcTeam{17}
}
:endtag
:enddata
:endentity

entity:
plugin=awNpcOld
number=3
data:
position=19,10,7
tag:
TAG=10={
TAG=5=yOffset{0.0}
TAG=5=xOffset{0.6840519}
TAG=5=zOffset{0.35911432}
TAG=5=rotation{-93.9577}
TAG=3=npcLevel{0}
TAG=3=npcType{17}
TAG=3=npcTeam{17}
}
:endtag
:enddata
:endentity

entity:
plugin=awNpcOld
number=4
data:
position=9,6,5
tag:
TAG=10={
TAG=5=yOffset{0.0}
TAG=5=xOffset{0.26584458}
TAG=5=zOffset{0.2878212}
TAG=5=rotation{83.342804}
TAG=3=npcLevel{0}
TAG=3=npcType{17}
TAG=3=npcTeam{17}
}
:endtag
:enddata
:endentity

entity:
plugin=awNpcOld
number=5
data:
position=6,10,7
tag:
TAG=10={
TAG=5=yOffset{0.0}
TAG=5=xOffset{0.19937843}
TAG=5=zOffset{0.17532028}
TAG=5=rotation{-174.35788}
TAG=3=npcLevel{0}
TAG=3=npcType{17}
TAG=3=npcTeam{17}
}
:endtag
:enddata
:endentity

entity:
plugin=awGates
number=6
data:
position=13,1,22
tag:
TAG=10={
TAG=10=pos1{
TAG=3=z{0}
TAG=3=y{0}
TAG=3=x{2}
}
TAG=1=orientation{2}
TAG=10=pos2{
TAG=3=z{0}
TAG=3=y{3}
TAG=3=x{-2}
}
TAG=8=gateType{gate.verticalIron}
}
:endtag
:enddata
:endentity

entity:
plugin=awNpcOld
number=7
data:
position=20,1,13
tag:
TAG=10={
TAG=5=yOffset{0.0}
TAG=5=xOffset{0.5}
TAG=5=zOffset{0.5}
TAG=5=rotation{-92.906555}
TAG=3=npcLevel{0}
TAG=3=npcType{16}
TAG=3=npcTeam{17}
}
:endtag
:enddata
:endentity

entity:
plugin=awNpcOld
number=8
data:
position=19,1,19
tag:
TAG=10={
TAG=5=yOffset{0.0}
TAG=5=xOffset{0.7715132}
TAG=5=zOffset{0.8551553}
TAG=5=rotation{-7.1065674}
TAG=3=npcLevel{0}
TAG=3=npcType{16}
TAG=3=npcTeam{17}
}
:endtag
:enddata
:endentity

entity:
plugin=awNpcOld
number=9
data:
position=20,6,19
tag:
TAG=10={
TAG=5=yOffset{0.0}
TAG=5=xOffset{0.5}
TAG=5=zOffset{0.5}
TAG=5=rotation{-6.207123}
TAG=3=npcLevel{0}
TAG=3=npcType{17}
TAG=3=npcTeam{17}
}
:endtag
:enddata
:endentity

entity:
plugin=awNpcOld
number=10
data:
position=20,10,18
tag:
TAG=10={
TAG=5=yOffset{0.0}
TAG=5=xOffset{0.8339986}
TAG=5=zOffset{0.8693564}
TAG=5=rotation{2.4922485}
TAG=3=npcLevel{0}
TAG=3=npcType{17}
TAG=3=npcTeam{17}
}
:endtag
:enddata
:endentity

entity:
plugin=awNpcOld
number=11
data:
position=6,1,13
tag:
TAG=10={
TAG=5=yOffset{0.0}
TAG=5=xOffset{0.5}
TAG=5=zOffset{0.5}
TAG=5=rotation{84.99396}
TAG=3=npcLevel{0}
TAG=3=npcType{16}
TAG=3=npcTeam{17}
}
:endtag
:enddata
:endentity

entity:
plugin=awNpcOld
number=12
data:
position=6,1,19
tag:
TAG=10={
TAG=5=yOffset{0.0}
TAG=5=xOffset{0.5}
TAG=5=zOffset{0.5}
TAG=5=rotation{-269.0066}
TAG=3=npcLevel{0}
TAG=3=npcType{16}
TAG=3=npcTeam{17}
}
:endtag
:enddata
:endentity

entity:
plugin=awNpcOld
number=13
data:
position=6,6,19
tag:
TAG=10={
TAG=5=yOffset{0.0}
TAG=5=xOffset{0.5}
TAG=5=zOffset{0.5}
TAG=5=rotation{-7.5569153}
TAG=3=npcLevel{0}
TAG=3=npcType{17}
TAG=3=npcTeam{17}
}
:endtag
:enddata
:endentity

entity:
plugin=awNpcOld
number=14
data:
position=7,10,20
tag:
TAG=10={
TAG=5=yOffset{0.0}
TAG=5=xOffset{0.31148052}
TAG=5=zOffset{0.86191595}
TAG=5=rotation{-265.10782}
TAG=3=npcLevel{0}
TAG=3=npcType{17}
TAG=3=npcTeam{17}
}
:endtag
:enddata
:endentity

