# Ancient Warfare Structure Template File
# auto-generated structure file. created on: 4/21/2014 at: 17:18:47
# Lines beginning with # denote comments

header:
version=2.0
name=frostmoore_church
size=28,33,25
offset=18,12,24
:endheader

#### VALIDATION ####
validation:
type=ground
survival=false
worldGenEnabled=true
unique=false
preserveBlocks=false
selectionWeight=1
clusterValue=125
minDuplicateDistance=40
dimensionWhiteList=false
dimensionList=
biomeWhiteList=false
biomeList=
leveling=12
fill=8
border=8
validTargetBlocks=clay,lapis_ore,lit_redstone_ore,stone,tile.bop.mud,carpet,gravel,coal_block,diamond_ore,ice,snow,netherrack,tile.bop.longGrass,tile.bop.generic.hard_dirt,tile.bop.redRocks,dirt,redstone_ore,mycelium,tile.bop.holyStone,sand,grass,tile.bop.ash,iron_ore,soul_sand,snow_layer,stained_hardened_clay,coal_ore,gold_ore,tile.bop.generic.hard_sand
data:
:enddata
:endvalidation

#### LAYERS ####
layer: 0
1,1,1,1,1,1,2,2,2,2,2,1,1,1,1,1,1,1,1,1,1,1,1,1,1,1,1,1
1,1,1,1,1,1,1,2,2,2,2,2,2,2,2,2,2,2,1,1,1,1,1,1,1,1,1,1
1,1,1,1,1,1,1,1,2,2,2,2,2,2,2,2,2,2,2,1,1,1,1,1,1,1,1,1
1,1,1,1,1,1,1,1,1,2,2,2,2,2,2,2,2,2,2,1,1,1,1,1,1,1,1,1
1,1,1,1,1,1,1,1,1,1,1,2,2,2,2,2,2,2,1,1,1,1,1,1,1,1,1,1
2,2,2,2,2,2,1,1,1,1,1,1,1,1,1,1,1,1,1,1,1,1,1,1,1,1,1,1
2,2,2,2,2,2,1,1,1,1,1,1,1,1,1,1,1,1,1,1,1,1,1,1,1,1,1,2
2,2,2,2,2,2,2,1,1,1,1,1,1,1,1,1,1,1,1,1,1,1,1,1,1,1,1,2
1,1,2,2,2,2,3,1,1,1,1,1,1,1,1,1,1,1,1,1,1,1,1,1,1,1,2,2
1,1,1,1,1,1,1,1,1,1,1,1,1,1,1,1,1,1,1,1,1,1,1,1,1,1,1,2
1,1,1,1,1,1,1,1,1,1,1,1,1,1,1,1,1,1,1,1,1,1,1,1,1,1,1,2
1,1,1,1,1,1,1,1,1,1,1,1,1,1,1,1,1,1,1,1,1,1,1,1,1,1,1,2
1,1,1,1,1,1,1,1,1,1,1,1,1,1,1,1,1,1,1,1,1,1,1,1,1,1,1,1
1,1,1,1,1,1,1,1,1,1,1,1,1,1,1,1,1,1,1,1,1,1,1,1,1,1,1,1
1,1,1,1,1,1,1,1,1,1,1,1,1,1,1,1,1,1,1,2,2,2,1,1,1,1,1,1
1,1,1,1,1,1,1,1,1,1,1,1,3,1,1,1,1,1,1,2,2,2,2,1,1,1,1,1
1,1,1,1,1,1,1,1,1,1,1,1,3,3,1,1,1,1,1,2,2,2,2,1,1,1,1,1
1,1,1,1,1,1,1,1,1,1,1,1,1,1,1,1,1,1,1,2,2,2,2,2,1,1,1,1
1,1,1,1,1,1,1,1,1,1,1,1,1,1,1,1,1,1,1,1,1,2,2,2,1,1,1,1
1,1,1,1,1,1,1,1,1,1,1,1,1,1,1,1,1,1,1,1,1,2,2,2,1,1,1,1
1,1,1,1,1,1,1,1,1,1,1,1,1,1,1,1,1,1,1,1,1,1,1,1,1,1,1,1
1,1,1,1,1,1,1,1,1,1,1,1,1,1,1,1,1,1,1,1,1,1,1,1,1,1,1,1
1,1,1,1,1,1,1,1,1,1,1,1,1,1,1,1,1,1,1,1,1,1,1,1,1,1,1,1
1,1,1,1,1,1,1,1,1,1,1,1,1,1,1,1,1,1,1,1,1,1,1,1,1,1,1,1
1,1,1,1,1,1,1,1,1,1,1,1,1,1,1,1,1,1,1,1,1,1,1,1,1,1,1,1
:endlayer
layer: 1
1,1,1,1,1,1,2,2,2,2,2,1,1,2,2,1,1,1,1,1,1,1,1,1,1,1,1,1
1,1,1,1,1,1,1,2,2,2,2,2,2,2,2,2,2,2,1,1,1,1,1,1,1,1,1,1
1,1,1,1,1,1,1,1,2,2,2,2,2,2,2,2,2,2,2,1,1,1,1,1,1,1,1,1
1,1,1,1,1,1,1,1,1,2,2,2,2,2,2,2,2,2,2,1,1,1,1,1,1,1,1,1
1,1,1,1,1,1,1,1,1,1,2,2,2,2,2,2,2,2,1,1,1,1,1,1,1,1,1,1
1,2,2,1,1,1,1,1,1,1,2,2,2,1,1,1,1,1,1,1,1,1,1,1,1,1,1,1
1,2,2,2,2,1,1,1,1,1,2,2,1,1,1,1,1,1,1,1,1,1,1,1,1,1,1,1
1,1,2,2,2,2,1,1,1,1,1,1,1,1,1,1,1,1,1,1,1,1,1,1,1,1,1,1
1,1,1,1,1,1,1,1,1,1,1,1,1,1,1,1,1,1,1,1,1,1,1,1,1,1,1,2
1,1,1,1,1,1,1,1,1,1,5,5,1,1,1,1,1,1,1,1,1,1,1,1,1,1,1,2
1,1,1,1,1,1,1,1,5,5,5,5,1,1,1,1,1,1,1,1,1,1,1,1,1,1,4,4
1,1,1,1,1,1,1,1,5,5,5,5,1,1,1,1,1,1,1,1,1,1,1,1,1,1,4,4
1,1,1,1,1,1,1,1,1,5,1,1,1,1,1,1,1,1,1,1,1,1,1,1,1,1,1,1
1,1,1,1,1,1,1,1,1,1,1,1,1,1,1,1,1,1,1,1,1,1,1,1,1,1,1,1
1,1,1,1,1,1,1,1,1,1,1,1,1,1,1,1,1,1,1,2,2,2,1,1,1,1,1,1
1,1,1,1,1,1,1,1,1,1,1,1,1,3,1,1,1,1,1,2,2,2,2,1,1,1,1,1
1,1,1,1,1,1,1,1,1,1,1,1,3,1,1,1,1,1,1,2,2,2,2,1,1,1,1,1
1,1,1,1,1,1,1,1,1,1,1,1,1,1,1,1,1,1,1,2,2,2,2,2,1,1,1,1
1,1,1,1,1,1,1,1,1,1,1,1,1,1,1,1,1,1,1,1,2,2,2,2,2,1,1,1
1,1,1,1,1,1,1,1,1,1,1,1,1,1,1,1,1,1,1,1,2,2,2,2,2,1,1,1
1,1,1,1,1,1,1,1,1,1,1,1,1,1,1,1,1,1,1,1,1,2,2,2,2,1,1,1
1,1,1,1,1,1,1,1,1,1,1,1,1,1,1,1,1,1,1,1,1,1,1,2,1,1,1,1
1,1,1,1,1,1,1,1,1,1,1,1,1,1,1,1,1,1,1,1,1,1,1,1,1,1,1,1
1,1,1,1,1,1,1,5,5,1,1,1,1,1,1,1,1,1,1,1,1,1,1,1,1,1,1,1
1,1,1,1,1,1,1,5,5,1,1,1,1,1,1,1,1,1,1,1,1,1,1,1,1,1,1,1
:endlayer
layer: 2
1,1,1,1,1,1,2,2,2,2,1,1,2,2,2,1,1,1,1,1,1,1,1,1,1,1,1,1
1,1,1,1,1,1,1,2,2,2,1,2,2,2,2,2,1,1,1,1,1,1,1,1,1,1,1,1
1,1,1,1,1,1,1,1,1,2,2,2,2,2,2,2,2,2,1,1,1,1,1,1,1,1,1,1
1,1,1,1,1,1,1,1,1,2,2,2,2,2,2,2,2,2,1,1,1,1,1,1,1,1,1,1
1,1,1,1,1,1,1,1,1,2,2,2,2,2,2,2,1,1,1,1,1,1,1,1,1,1,1,1
1,1,1,1,1,1,1,1,1,2,2,2,2,2,1,1,1,1,1,1,1,1,1,1,1,1,1,1
1,1,1,1,1,1,1,1,1,2,2,2,2,1,1,1,1,1,1,1,1,1,1,1,1,1,1,1
1,5,1,1,1,1,1,1,1,2,2,1,1,1,1,1,1,1,1,1,1,1,1,1,1,1,1,1
5,5,5,1,1,1,1,1,1,1,1,1,1,1,1,1,1,1,1,1,1,1,1,1,1,1,1,1
5,1,1,1,1,1,1,1,1,1,5,5,1,1,1,1,1,1,1,1,1,1,1,1,1,4,4,4
1,1,1,1,1,1,1,1,5,5,5,5,1,1,1,1,1,1,1,1,1,1,1,1,4,4,4,4
1,1,1,1,1,1,1,1,5,5,5,5,1,1,1,1,1,1,1,1,1,1,1,4,4,4,4,4
1,1,1,1,1,1,1,1,1,5,1,1,1,1,1,1,1,1,1,1,1,1,1,4,4,4,4,4
1,1,1,1,1,1,1,1,1,1,1,1,1,1,1,1,1,1,1,1,1,1,1,1,1,1,1,1
1,1,1,1,1,1,1,1,1,1,1,1,1,1,1,1,1,1,1,1,2,2,1,1,1,1,1,1
1,1,1,1,1,1,1,1,1,1,1,1,1,1,1,1,1,1,1,2,2,2,1,1,1,1,1,4
1,1,1,1,1,1,1,1,1,1,1,1,1,1,1,1,1,1,1,2,2,2,2,1,1,1,1,1
1,1,1,1,1,1,1,1,1,1,1,1,1,1,1,1,1,1,1,1,2,2,2,2,1,1,1,1
1,1,1,1,1,1,1,1,1,1,1,1,1,1,1,1,1,1,1,1,2,2,2,2,2,1,1,1
1,1,1,1,1,1,1,1,1,1,1,1,1,1,1,1,1,1,1,1,2,2,2,2,2,1,1,1
1,1,1,1,1,1,1,1,1,1,1,1,1,1,1,1,1,1,1,1,1,2,2,2,2,1,1,1
1,1,1,1,1,1,1,1,1,1,1,1,1,1,1,1,1,1,1,1,1,1,2,2,2,1,1,1
1,1,1,1,1,1,1,1,1,1,1,1,1,1,1,1,1,1,1,1,1,1,1,1,1,1,1,1
1,1,1,1,1,1,1,5,5,1,1,1,1,1,1,1,1,1,1,1,1,1,1,1,1,1,1,1
1,1,1,1,1,1,1,5,5,1,1,1,1,1,1,1,1,1,1,1,1,1,1,1,1,1,1,1
:endlayer
layer: 3
1,1,1,1,1,1,1,1,1,1,1,1,1,1,1,1,1,1,1,1,1,1,1,1,1,1,1,1
1,1,1,1,1,1,1,1,1,1,1,2,2,2,2,1,1,7,1,1,1,1,1,1,1,1,1,1
1,1,1,1,1,1,1,1,1,1,1,2,2,2,2,1,1,1,1,1,1,1,1,1,1,1,1,1
1,1,1,1,1,1,1,1,1,1,2,2,2,2,2,1,1,1,1,1,1,1,1,1,1,1,1,1
1,1,1,1,1,1,1,1,1,1,2,2,2,2,1,1,1,1,1,1,1,1,1,1,1,1,1,1
1,1,1,1,1,1,1,1,1,2,2,2,2,1,1,1,1,1,1,1,1,1,1,1,1,1,1,1
1,1,1,1,1,1,1,1,1,2,2,2,1,1,1,1,1,1,1,1,1,1,1,1,1,1,1,1
1,5,1,1,1,1,1,1,1,2,2,1,1,1,1,1,1,1,1,1,1,1,1,1,1,1,1,1
5,5,5,1,1,1,1,1,1,1,1,1,1,1,1,1,1,1,1,1,1,1,1,1,1,1,1,4
5,5,1,1,1,1,1,1,1,1,1,1,1,1,1,1,1,1,1,1,1,1,1,1,6,4,4,4
1,1,1,1,1,1,1,1,1,1,1,1,1,1,1,1,1,1,1,1,1,1,1,4,4,4,4,4
8,1,1,1,1,1,1,1,1,1,1,1,1,1,1,1,1,1,1,1,1,1,1,4,4,4,4,4
1,1,1,1,1,1,1,1,1,1,1,1,1,1,1,1,1,1,1,1,1,1,4,4,4,4,4,4
1,1,1,1,1,1,1,1,1,1,1,1,1,1,1,1,1,1,1,1,1,1,1,4,4,4,1,1
8,1,1,1,1,1,1,1,1,1,1,1,1,1,1,1,1,1,1,1,1,1,1,1,1,1,1,1
1,1,1,1,1,1,1,1,1,1,1,1,1,1,1,1,1,1,1,1,1,1,1,1,1,1,1,4
1,1,1,1,1,1,1,1,1,1,1,1,1,1,1,1,1,1,1,1,1,2,1,1,1,1,1,1
1,1,1,1,1,1,1,1,1,1,1,1,1,1,1,1,1,1,1,1,1,2,2,2,1,1,1,1
1,1,1,1,1,1,1,1,1,1,1,1,1,1,1,1,1,1,1,1,1,2,2,2,2,1,1,1
1,1,1,1,1,1,1,1,1,1,1,1,1,1,1,1,1,1,1,1,1,2,2,2,2,1,1,1
1,1,1,3,1,1,1,1,1,1,1,1,1,1,1,1,1,1,1,1,1,2,2,2,2,1,1,1
1,1,1,1,1,1,1,1,1,1,1,1,1,1,1,1,1,1,1,1,1,1,1,2,2,1,1,1
1,1,1,1,1,1,1,1,1,1,1,1,1,1,1,1,1,1,1,1,1,1,1,1,1,1,1,1
1,1,1,1,1,1,1,1,1,1,1,1,1,1,1,1,1,1,1,1,1,1,1,1,1,1,1,1
1,1,1,1,1,1,1,3,1,1,1,1,1,1,1,1,1,1,1,1,1,1,2,2,2,1,1,1
:endlayer
layer: 4
1,1,1,1,1,1,1,1,1,1,1,1,1,1,1,1,1,1,1,1,1,1,1,1,1,1,1,1
1,1,1,1,1,1,1,1,1,1,1,1,1,1,1,1,7,0,1,1,1,1,1,1,1,1,1,1
1,1,1,1,1,1,1,1,1,1,1,1,2,1,1,1,9,9,1,1,1,1,1,1,1,1,1,1
1,1,1,1,1,1,1,1,1,1,1,2,2,2,1,1,1,1,1,1,1,1,1,1,1,1,1,1
1,1,1,1,1,1,1,1,1,1,2,2,2,1,1,1,1,1,1,1,1,1,1,1,1,1,1,1
1,1,1,1,1,1,1,1,1,1,1,2,1,1,1,1,1,1,1,1,1,1,1,1,1,1,1,1
1,1,1,1,1,1,1,1,1,1,1,1,1,1,1,1,8,1,1,1,1,1,1,1,1,1,1,1
1,1,1,1,1,1,1,1,1,1,1,1,1,1,1,1,1,1,1,1,1,1,1,1,1,1,1,1
5,1,1,1,1,1,1,1,1,1,1,1,1,1,1,1,1,1,1,1,1,1,1,1,1,1,1,1
1,1,1,1,1,1,1,1,1,1,1,1,1,1,1,1,1,1,1,1,1,1,1,1,6,6,6,4
1,1,1,1,1,1,1,1,1,1,1,1,1,1,1,1,1,1,1,1,1,1,1,4,6,4,4,4
8,8,1,1,1,1,1,1,1,1,1,1,1,1,1,1,1,1,1,1,1,1,1,4,4,4,4,4
1,8,1,1,1,1,1,1,1,1,1,1,1,1,1,1,1,1,1,1,1,1,4,4,4,4,4,4
1,8,1,1,1,1,1,1,1,1,1,1,1,1,1,1,1,1,1,1,3,1,1,4,4,4,1,1
8,8,1,1,1,1,1,1,1,1,1,1,1,1,7,7,7,7,7,1,1,1,1,1,1,1,1,1
1,1,1,1,1,1,1,1,1,1,1,1,1,1,1,1,1,1,1,1,1,1,1,1,1,1,1,1
1,1,1,1,1,1,1,1,1,1,1,1,1,1,1,1,1,1,1,1,1,1,1,1,1,1,1,1
1,1,1,1,1,1,1,1,1,1,1,1,1,1,1,1,1,1,1,1,1,1,1,1,1,1,1,1
1,1,1,1,1,1,1,1,1,1,1,1,1,1,1,1,1,1,1,1,1,1,1,1,1,1,1,1
1,1,1,1,1,1,1,1,1,1,1,1,1,1,1,1,1,1,1,1,1,1,2,2,1,1,1,1
1,1,1,3,3,1,1,1,1,1,1,1,1,1,1,1,1,1,1,1,1,1,1,1,1,1,1,1
1,1,1,3,3,1,1,1,1,1,1,1,1,1,1,1,1,1,1,1,1,1,1,1,1,1,1,1
1,1,1,1,1,1,1,1,1,1,1,1,1,1,1,1,1,1,1,1,1,1,1,1,1,1,1,1
1,1,1,1,1,1,1,1,1,1,1,1,1,1,1,1,1,1,1,1,1,1,1,1,1,1,1,1
1,1,1,1,1,1,1,3,1,1,1,1,1,1,1,1,1,1,1,1,1,1,2,2,2,1,1,1
:endlayer
layer: 5
1,1,1,1,1,1,1,1,1,1,1,1,1,1,1,1,1,1,1,1,1,4,4,1,1,1,1,1
1,1,1,1,1,1,1,1,1,1,1,1,1,1,1,7,0,8,1,1,1,1,1,1,1,1,1,1
1,1,1,1,1,1,1,1,1,1,1,1,1,1,1,7,8,8,8,1,1,1,1,1,1,1,1,1
1,1,1,1,1,1,1,1,1,1,1,1,1,1,1,8,8,8,8,1,1,1,1,1,1,1,1,1
1,1,1,1,1,1,1,1,1,1,1,1,1,1,8,8,8,8,8,8,1,1,1,1,1,1,1,1
1,1,1,1,1,1,1,1,1,1,1,1,1,1,8,6,8,8,8,8,1,1,1,1,1,8,1,1
1,1,1,1,1,1,1,8,8,8,8,8,1,1,8,8,8,8,8,8,1,1,8,8,8,8,8,1
1,1,1,1,1,1,1,8,8,8,8,8,8,8,8,8,8,8,6,8,8,8,8,8,8,8,8,1
1,1,1,1,1,1,1,8,6,8,8,8,1,1,8,8,6,8,8,8,1,1,8,8,8,6,8,1
1,1,1,1,1,1,1,8,8,8,8,8,8,8,8,8,8,8,8,8,8,8,6,6,6,6,6,1
1,1,1,1,1,1,1,8,6,6,8,8,1,1,8,8,8,8,6,8,1,1,8,6,6,8,8,4
8,8,8,1,1,1,1,8,8,8,8,8,8,8,8,6,8,8,8,8,8,8,8,8,8,8,8,4
1,8,6,1,1,1,1,8,8,8,8,8,1,1,1,8,8,8,8,1,1,1,8,8,6,8,8,1
1,8,8,1,1,1,1,1,1,1,1,1,1,1,1,1,8,8,1,1,3,3,1,1,1,1,1,1
8,8,8,1,1,1,1,1,1,1,1,1,1,7,0,0,8,8,0,7,1,3,1,1,1,1,1,1
1,6,6,1,1,1,1,1,1,1,1,1,1,1,0,1,8,8,1,1,1,1,1,1,1,1,1,1
1,8,8,1,1,1,1,1,1,1,8,8,8,1,1,1,8,8,1,1,1,1,1,1,1,1,1,1
1,6,8,6,8,8,6,8,8,8,8,8,6,8,8,8,6,8,1,1,1,1,1,1,1,1,1,1
1,8,8,8,8,8,8,8,6,8,8,8,8,8,6,8,8,8,1,1,1,1,1,1,1,1,1,1
1,1,1,1,1,1,1,1,8,1,8,8,8,1,1,1,1,1,1,1,1,1,1,1,1,1,1,1
1,1,1,1,1,1,1,1,8,1,1,1,1,1,1,1,1,1,1,1,1,1,1,1,1,1,1,1
1,1,1,1,3,1,1,1,1,1,1,1,1,1,1,1,1,1,1,1,1,1,1,1,1,1,1,1
1,1,1,1,1,1,1,1,1,1,1,1,1,1,1,1,1,1,1,1,1,1,1,1,1,1,1,1
1,1,1,1,1,1,1,1,1,1,1,1,1,1,1,1,1,1,1,1,1,1,1,1,1,1,1,1
1,1,1,1,1,1,3,1,1,1,1,1,1,1,1,1,1,1,1,1,1,1,1,1,1,1,1,1
:endlayer
layer: 6
1,1,1,1,1,1,1,1,1,1,1,1,1,1,1,1,1,1,1,1,4,4,4,4,1,1,1,1
1,1,1,1,1,1,1,1,1,1,1,1,1,1,1,8,8,8,1,1,1,1,1,1,1,1,1,1
1,1,1,1,1,1,1,1,1,1,1,1,1,1,1,8,10,10,8,1,1,1,1,1,1,1,1,1
1,1,1,1,1,1,5,5,1,1,1,1,1,1,8,0,0,0,0,6,1,1,1,1,1,1,1,1
1,1,1,1,1,1,1,1,1,1,1,1,1,8,0,0,0,0,0,0,6,1,1,1,1,1,1,1
1,1,1,1,1,1,1,8,6,8,8,8,1,6,0,0,11,11,0,0,6,1,8,6,8,8,8,1
1,1,1,1,1,8,8,0,0,0,0,0,8,8,0,0,0,11,0,0,8,8,0,0,0,0,0,8
1,1,1,1,1,8,8,0,0,0,0,0,0,0,0,0,11,11,0,0,0,0,0,0,0,0,0,8
1,1,1,1,1,8,8,0,0,0,0,0,8,8,0,0,11,0,0,0,8,8,0,0,0,0,0,8
1,1,1,1,1,8,8,0,0,0,0,0,0,0,0,0,11,11,0,0,0,0,0,0,0,0,0,8
1,1,1,1,1,8,8,0,0,0,0,0,8,8,0,0,0,11,0,0,8,6,0,0,0,0,0,8
8,8,8,8,1,8,8,0,0,0,0,0,0,0,0,0,11,11,0,0,0,0,0,0,0,0,0,8
8,23,0,22,5,8,8,0,0,0,0,0,6,8,8,0,0,0,0,8,6,8,0,0,0,0,0,8
8,23,0,22,5,1,1,8,6,8,8,8,1,1,1,8,0,0,8,1,1,1,8,8,8,8,8,2
6,0,0,6,1,1,1,1,1,1,1,7,7,0,0,6,0,0,8,0,1,3,1,1,1,1,2,2
8,23,12,8,8,8,8,1,1,1,8,8,8,1,8,8,0,12,8,7,1,1,1,1,1,1,2,2
8,0,0,8,8,6,8,8,8,8,19,16,13,6,8,8,0,12,6,1,1,1,1,1,1,1,1,1
8,23,0,14,0,0,14,0,14,0,14,17,14,0,0,0,0,12,8,1,1,1,1,1,1,1,1,1
8,0,0,0,15,15,0,15,0,15,15,17,15,0,0,0,0,12,8,1,1,1,1,1,1,1,1,1
1,6,8,8,8,6,8,8,20,8,19,18,13,6,8,6,8,8,1,1,1,1,1,1,1,1,1,1
1,1,1,1,8,8,8,8,21,8,8,8,8,1,1,1,8,1,1,1,1,1,1,1,1,1,1,1
1,1,1,1,1,1,1,1,1,1,1,1,1,1,1,1,1,1,1,1,1,1,1,1,1,1,1,1
1,1,1,1,1,1,1,1,1,1,1,1,1,1,1,1,1,1,1,1,1,1,1,1,1,1,1,1
1,1,1,1,1,1,1,1,1,1,1,1,1,1,1,1,1,1,1,1,1,1,1,1,1,1,1,1
1,1,1,1,1,1,1,1,1,1,1,1,1,1,1,1,1,1,1,1,1,1,1,1,1,1,1,1
:endlayer
layer: 7
1,1,1,1,1,1,1,1,1,1,1,1,1,1,1,1,0,0,1,1,1,4,4,4,1,1,1,1
1,1,1,1,1,1,1,1,1,1,1,1,1,1,1,1,8,8,1,1,1,1,1,1,1,1,1,1
1,1,1,1,1,1,1,1,1,1,1,1,1,1,1,8,27,27,8,1,1,1,1,1,1,1,1,1
1,1,1,1,1,1,5,5,1,1,1,1,1,1,6,0,0,0,0,8,1,1,1,1,1,1,1,1
1,1,1,1,1,5,5,5,1,1,1,1,1,6,0,0,0,0,0,0,8,1,1,1,1,1,1,1
1,1,1,1,5,5,5,8,8,8,6,8,1,6,0,0,0,0,0,0,6,1,8,8,8,6,8,1
1,1,1,1,1,8,6,0,0,0,0,0,8,6,0,0,0,0,0,0,8,8,0,0,0,0,0,8
1,1,1,1,1,8,8,0,0,0,0,0,0,0,0,0,0,0,0,0,0,0,0,0,0,0,0,8
1,1,1,1,1,8,8,0,0,0,0,0,6,8,0,0,0,0,0,0,8,6,0,0,0,0,0,8
1,1,1,1,1,8,6,0,0,0,0,0,0,0,0,0,0,0,0,0,0,0,0,0,0,0,0,6
1,1,1,1,1,8,8,0,0,0,0,0,8,6,0,0,0,0,0,0,6,8,0,0,0,0,0,8
8,6,8,8,8,8,8,0,0,0,0,0,0,0,0,0,0,0,0,0,0,0,0,0,0,0,0,8
8,23,0,0,22,8,8,0,0,0,0,0,8,8,6,0,0,0,0,6,8,8,0,0,0,0,0,6
8,23,0,0,22,1,1,6,8,8,8,8,1,1,1,6,0,0,6,1,1,1,8,6,8,6,8,2
8,0,0,8,8,1,1,1,1,1,1,8,0,0,0,8,0,0,8,0,1,1,1,1,1,1,2,2
8,23,12,6,27,8,27,8,1,1,8,8,8,8,27,8,0,12,6,0,7,1,1,1,1,2,2,2
8,0,0,8,36,8,34,6,8,8,32,27,30,8,29,6,0,12,8,0,7,2,2,1,1,2,2,2
8,23,0,14,0,0,14,0,14,0,14,14,14,0,0,0,0,12,25,24,7,2,2,2,1,1,1,1
8,0,0,0,15,15,0,15,0,15,15,15,15,0,0,0,0,12,26,24,7,2,2,2,1,1,1,1
1,8,6,8,37,8,35,6,21,8,33,21,31,8,6,8,28,8,1,1,1,1,1,1,1,1,1,1
1,1,1,8,21,8,21,8,8,1,8,8,8,1,1,8,21,8,1,1,1,1,1,1,1,1,1,1
1,1,1,1,1,1,1,1,1,1,1,1,1,1,1,1,1,1,1,1,1,1,1,1,1,1,1,1
1,1,1,1,1,1,1,1,1,1,1,1,1,1,1,1,1,1,1,1,1,1,1,1,1,1,1,1
1,1,1,1,1,1,1,1,1,1,1,1,1,1,1,1,1,1,1,1,1,1,1,1,1,1,1,1
1,1,1,1,1,1,1,1,1,1,1,1,1,1,1,1,1,1,1,1,1,1,1,1,1,1,1,1
:endlayer
layer: 8
2,2,2,2,2,2,2,2,2,2,2,2,2,2,2,2,0,0,2,2,2,2,2,2,2,2,2,2
2,2,2,2,2,2,2,2,2,2,2,2,2,2,2,2,0,2,2,2,2,2,2,2,2,2,2,2
2,2,2,2,2,2,2,2,2,2,2,2,2,2,2,8,8,8,8,2,2,2,2,2,2,2,2,2
2,2,2,2,2,2,2,2,2,2,2,2,2,2,8,0,0,0,0,6,0,2,2,2,2,2,2,2
2,2,2,2,2,2,2,2,2,2,2,2,2,8,0,0,0,0,0,0,8,2,2,2,2,2,2,2
2,2,2,2,2,2,2,8,8,8,8,8,2,6,0,0,0,0,0,0,8,2,8,8,8,8,8,2
2,2,2,2,2,8,8,0,0,0,0,0,8,8,0,0,0,0,0,0,8,8,0,0,0,0,0,6
2,2,2,2,2,8,8,0,0,0,0,0,8,8,0,0,0,0,0,0,8,8,0,0,0,0,0,8
2,2,2,2,2,8,8,0,0,0,0,0,8,6,0,0,0,0,0,0,8,8,0,0,0,0,0,8
2,2,2,2,2,8,8,0,0,0,0,0,8,8,0,0,0,0,0,0,8,8,0,0,0,0,0,8
2,2,2,2,2,8,8,0,0,0,0,0,8,8,0,0,0,0,0,0,8,8,0,0,0,0,0,8
8,8,8,8,8,8,8,0,0,0,0,0,8,8,0,0,0,0,0,0,8,8,0,0,0,0,0,6
8,23,0,0,0,22,8,0,0,0,0,0,8,2,8,0,0,0,0,8,8,8,0,0,0,0,0,8
8,23,0,0,0,22,2,8,8,8,8,6,2,2,2,8,8,8,8,2,2,2,8,8,8,8,8,2
8,0,0,8,8,8,2,2,2,2,2,8,2,2,2,6,0,0,8,2,2,2,2,2,2,2,2,2
8,23,12,8,2,2,2,2,2,2,8,8,8,2,2,8,0,12,6,0,0,2,2,2,2,2,2,2
8,0,0,8,8,8,8,8,8,6,8,8,8,8,8,8,0,12,8,0,0,2,2,2,2,2,2,2
8,23,0,14,0,0,14,0,14,0,14,14,14,0,0,0,0,12,8,0,0,2,2,2,2,2,2,2
8,0,0,0,15,15,0,15,0,15,15,15,15,0,0,0,0,12,8,0,0,2,2,2,2,2,2,2
2,8,8,8,6,8,8,8,8,8,8,8,8,8,8,6,8,8,2,2,2,2,2,2,2,2,2,2
2,2,2,2,2,2,2,2,2,2,8,8,8,2,2,2,2,2,2,2,2,2,2,2,2,2,2,2
2,2,2,2,2,2,2,2,2,2,2,2,2,2,2,2,2,2,2,2,2,2,2,2,2,2,2,2
2,2,2,2,2,2,2,2,2,2,2,2,2,2,2,2,2,2,2,2,2,2,2,2,2,2,2,2
2,2,2,2,2,2,2,2,2,2,2,2,2,2,2,2,2,2,2,2,2,2,2,2,2,2,2,2
2,2,2,2,2,2,2,2,2,2,2,2,2,2,2,2,2,2,2,2,2,2,2,2,2,2,2,2
:endlayer
layer: 9
2,2,2,2,2,2,2,2,2,2,2,2,2,2,2,2,2,2,2,2,2,2,2,2,2,2,2,2
2,2,2,2,2,2,2,2,2,2,2,2,2,2,2,2,2,2,2,2,2,2,2,2,2,2,2,2
2,2,2,2,2,2,2,2,2,2,2,2,2,2,2,2,2,2,2,2,2,2,2,2,2,2,2,2
2,2,2,2,2,2,2,2,2,2,2,2,2,2,2,6,8,8,8,2,2,2,2,2,2,2,2,2
2,2,2,2,2,2,2,2,2,2,2,2,2,2,8,8,8,8,8,8,2,2,2,2,2,2,2,2
2,2,2,2,2,2,2,2,2,2,2,2,2,2,8,6,8,8,8,8,2,2,2,2,2,2,2,2
2,2,2,2,2,2,2,8,8,8,8,8,2,2,8,8,8,6,6,8,2,2,8,8,8,8,8,2
2,2,2,2,2,2,2,8,8,8,8,8,2,2,8,8,6,8,8,8,2,2,8,8,6,8,8,2
2,2,2,2,2,2,2,8,8,8,8,8,2,2,8,8,8,6,8,8,2,2,8,8,8,6,8,2
2,2,2,2,2,2,2,8,8,8,8,8,2,2,6,8,8,8,8,8,2,2,8,8,8,8,8,2
2,2,2,2,2,2,2,8,6,6,8,8,2,2,8,8,8,6,8,8,2,2,8,8,8,8,8,2
2,8,8,8,6,8,8,6,8,8,8,8,2,2,8,8,6,8,8,8,2,2,8,6,6,8,8,2
8,23,0,0,0,0,22,8,8,8,8,8,2,2,2,8,8,8,8,2,2,2,8,8,8,8,8,2
8,23,0,0,0,0,22,2,2,2,2,2,2,2,2,2,2,2,2,2,2,2,2,2,2,2,2,2
2,8,8,8,8,8,8,2,2,2,2,2,2,2,2,2,8,8,2,2,2,2,2,2,2,2,2,2
2,8,8,2,2,2,2,2,2,2,2,2,2,2,2,2,6,8,2,2,2,2,2,2,2,2,2,2
2,8,6,2,2,2,2,2,2,2,2,2,2,2,2,2,8,8,2,2,2,2,2,2,2,2,2,2
2,8,8,8,8,8,8,6,8,8,8,8,8,8,8,8,8,8,2,2,2,2,2,2,2,2,2,2
2,6,6,8,8,8,8,8,8,8,8,8,8,8,8,8,8,8,8,2,2,2,2,2,2,2,2,2
2,2,2,2,2,2,2,2,2,2,2,2,2,2,2,2,2,2,2,2,2,2,2,2,2,2,2,2
2,2,2,2,2,2,2,2,2,2,2,2,2,2,2,2,2,2,2,2,2,2,2,2,2,2,2,2
2,2,2,2,2,2,2,2,2,2,2,2,2,2,2,2,2,2,2,2,2,2,2,2,2,2,2,2
2,2,2,2,2,2,2,2,2,2,2,2,2,2,2,2,2,2,2,2,2,2,2,2,2,2,2,2
2,2,2,2,2,2,2,2,2,2,2,2,2,2,2,2,2,2,2,2,2,2,2,2,2,2,2,2
2,2,2,2,2,2,2,2,2,2,2,2,2,2,2,2,2,2,2,2,2,2,2,2,2,2,2,2
:endlayer
layer: 10
2,2,2,2,2,2,2,2,2,2,2,2,2,2,2,2,2,2,2,2,2,2,2,2,2,2,2,2
2,2,2,2,2,2,2,2,2,2,2,2,2,2,2,2,2,2,2,2,2,2,2,2,2,2,2,2
2,2,2,2,2,2,2,2,2,2,2,2,2,2,2,2,2,2,2,2,2,2,2,2,2,2,2,2
2,2,2,2,2,2,2,2,2,2,2,2,2,2,2,2,2,2,2,2,2,2,2,2,2,2,2,2
2,2,2,2,2,2,2,2,2,2,2,2,2,2,2,2,2,2,2,2,2,2,2,2,2,2,2,2
2,2,2,2,2,2,2,2,2,2,2,2,2,2,2,2,2,2,2,2,2,2,2,2,2,2,2,2
2,2,2,2,2,2,2,2,2,2,2,2,2,2,2,2,2,2,2,2,2,2,2,2,2,2,2,2
2,2,2,2,2,2,2,2,2,2,2,2,2,2,2,2,2,2,2,2,2,2,2,2,2,2,2,2
2,2,2,2,2,2,2,2,2,2,2,2,2,2,2,2,2,2,2,2,2,2,2,2,2,2,2,2
2,2,2,2,2,2,2,2,38,38,38,38,38,38,2,2,2,2,2,2,2,2,2,2,2,2,2,2
2,2,2,2,2,2,2,2,2,2,2,2,2,2,2,2,2,2,2,2,2,2,2,2,2,2,2,2
2,2,8,8,8,8,8,8,2,2,2,2,2,2,2,2,2,2,2,2,2,2,2,2,2,2,2,2
2,8,19,0,0,0,0,22,2,2,2,2,2,2,2,2,2,2,2,2,2,2,2,2,2,2,2,2
2,8,19,0,0,0,0,22,2,2,2,2,2,2,2,2,2,2,2,2,2,2,2,2,2,2,2,2
2,2,8,8,8,8,8,8,2,2,2,2,2,2,2,2,2,2,2,2,2,2,2,2,2,2,2,2
2,2,2,2,2,2,2,2,2,2,2,2,2,2,2,2,2,2,2,2,2,2,2,2,2,2,2,2
2,2,2,2,2,2,2,2,2,2,2,2,2,2,2,2,2,2,2,2,2,2,2,2,2,2,2,2
2,2,2,2,2,2,2,2,2,2,2,2,2,2,2,2,2,2,2,2,2,2,2,2,2,2,2,2
2,2,2,2,2,2,2,2,2,2,2,2,2,2,2,2,2,2,2,2,2,2,2,2,2,2,2,2
2,2,2,2,2,2,2,2,2,2,2,2,2,2,2,2,2,2,2,2,2,2,2,2,2,2,2,2
2,2,2,2,2,2,2,2,2,2,2,2,2,2,2,38,2,2,2,2,2,2,2,2,2,2,2,2
2,2,2,2,2,2,2,2,2,2,2,2,2,2,2,2,2,2,2,2,2,2,2,2,2,2,2,2
2,2,2,2,2,2,2,2,2,2,2,2,2,2,2,2,2,2,2,2,2,2,2,2,2,2,2,2
2,2,2,2,2,2,2,2,2,2,2,2,2,2,2,2,2,2,2,2,2,2,2,2,2,2,2,2
2,2,2,2,2,2,2,2,2,2,2,2,2,2,2,2,2,2,2,2,2,2,2,2,2,2,2,2
:endlayer
layer: 11
38,38,38,38,38,38,38,38,38,38,38,38,38,38,38,38,38,38,38,38,38,38,38,38,38,38,38,38
38,38,38,38,38,38,38,38,38,38,38,38,38,38,38,38,38,38,38,38,38,38,38,38,38,38,38,38
38,38,38,38,38,38,38,38,38,38,38,38,38,38,38,38,38,38,38,38,38,38,38,38,38,38,38,38
38,38,38,38,38,38,38,38,38,38,38,38,38,38,38,38,38,38,38,38,38,38,38,38,38,38,38,38
38,38,38,38,38,38,38,38,38,38,38,38,38,38,38,38,38,38,38,38,38,38,38,38,38,38,38,38
38,38,38,38,38,38,38,2,2,2,2,2,2,2,2,2,2,2,2,2,2,2,2,2,2,38,38,38
38,38,38,38,38,38,38,2,2,2,2,2,2,2,2,2,2,2,2,2,2,2,2,2,2,38,38,38
38,38,38,38,38,38,38,2,2,2,2,2,2,2,38,8,41,41,41,41,8,38,2,2,2,38,38,38
38,38,38,38,38,38,38,2,38,2,2,2,2,38,38,8,8,41,41,8,8,38,38,2,2,38,38,38
38,38,38,38,38,38,38,2,45,43,46,45,43,42,2,7,7,7,8,8,38,39,39,2,2,38,38,38
38,38,2,2,2,2,2,2,2,2,38,38,2,39,39,39,38,8,8,38,39,39,39,2,2,38,38,38
38,38,8,8,8,8,8,8,8,8,38,2,2,39,39,39,39,8,8,39,39,39,39,2,2,38,38,38
38,38,8,19,0,0,0,0,22,8,8,8,44,39,39,39,39,8,8,39,39,39,39,8,8,38,38,38
38,38,8,19,0,0,0,0,22,8,8,8,44,40,40,40,40,8,8,40,40,40,40,8,8,38,38,38
38,38,8,8,8,8,8,8,8,8,38,2,2,8,8,8,8,8,8,8,8,8,8,2,2,38,38,38
38,38,2,2,2,2,2,2,2,2,38,38,2,40,40,40,40,8,8,40,40,40,40,2,2,38,38,38
38,38,38,38,38,38,38,2,2,2,38,38,2,8,8,8,8,8,8,8,8,8,8,2,2,38,38,38
38,38,38,38,38,38,38,2,2,2,2,2,2,40,40,40,40,8,8,40,40,40,40,2,2,38,38,38
38,38,38,38,38,38,38,2,2,2,2,2,2,8,8,8,8,8,8,8,8,8,8,2,2,38,38,38
38,38,38,38,38,38,38,2,2,2,2,2,2,8,8,8,8,8,8,8,8,8,8,2,2,38,38,38
38,38,38,38,38,38,38,2,2,2,2,2,2,39,39,39,39,8,8,39,39,39,39,2,2,38,38,38
38,38,38,38,38,38,38,38,38,38,2,2,2,39,39,39,39,8,8,39,39,39,39,2,2,38,38,38
38,38,38,38,38,38,38,38,38,38,2,2,2,39,39,39,39,8,8,39,39,39,39,2,2,38,38,38
38,38,38,38,38,38,38,38,38,38,2,2,2,2,2,2,2,8,8,2,2,2,2,2,2,38,38,38
38,38,38,38,38,38,38,38,38,38,38,38,38,38,38,38,38,38,38,38,38,38,38,38,38,38,38,38
:endlayer
layer: 12
47,0,47,0,0,0,0,47,47,47,47,47,47,47,47,0,47,0,47,47,0,47,0,47,0,0,0,0
47,47,47,0,0,0,47,47,47,47,0,47,47,0,47,47,0,0,0,0,0,0,0,0,0,47,0,0
47,0,0,0,47,0,47,0,47,0,0,0,0,0,0,47,47,47,47,0,0,47,0,0,0,0,0,0
0,0,0,0,0,0,0,0,0,0,0,0,0,0,0,0,0,0,0,0,0,0,0,0,0,0,0,0
0,0,0,47,0,0,0,0,0,0,47,47,0,0,47,47,0,0,0,0,0,0,0,0,0,0,0,0
0,0,47,47,0,47,47,8,8,8,8,8,8,8,8,8,8,8,8,8,8,8,8,8,8,0,0,0
0,47,0,0,0,47,0,8,8,8,8,8,8,8,8,8,8,8,8,8,8,8,8,8,8,0,0,0
0,0,0,0,47,47,0,8,8,8,8,8,8,51,51,51,64,0,0,58,51,51,51,8,8,0,0,0
0,0,47,47,0,0,0,8,74,8,8,8,50,51,51,51,51,60,60,51,51,51,51,50,8,0,0,0
0,0,0,0,0,0,0,8,0,0,0,0,8,51,51,51,51,61,61,51,51,51,51,8,8,0,0,0
0,0,8,8,8,8,8,8,8,8,67,67,50,0,55,51,51,51,51,51,51,55,0,50,8,0,0,0
0,0,8,0,50,0,0,50,0,8,68,68,8,0,0,0,55,51,51,55,0,0,0,8,8,0,0,0
0,47,8,0,0,0,0,0,0,0,73,69,8,0,0,0,0,0,0,0,0,0,0,0,48,0,0,0
0,0,8,0,0,0,0,0,0,0,73,69,8,0,0,0,0,0,0,0,0,0,0,0,49,0,0,0
0,0,8,0,50,0,0,50,0,8,70,70,8,59,56,56,52,0,0,59,56,56,52,8,8,0,0,0
0,47,8,8,8,8,8,8,8,8,71,71,50,0,0,0,0,0,0,0,0,0,53,50,8,47,0,0
0,47,0,0,0,0,0,8,8,8,0,0,8,59,56,56,52,0,0,59,56,56,52,8,8,47,0,0
0,47,0,0,0,0,0,8,8,8,8,8,50,65,0,0,0,0,0,0,0,0,0,50,8,47,0,47
0,0,0,0,0,0,0,8,8,8,8,8,8,59,56,56,52,0,0,59,56,56,52,8,8,47,0,0
0,0,47,0,0,0,0,8,8,8,8,8,50,0,0,0,0,0,0,0,0,0,0,50,8,0,0,0
0,47,0,0,0,47,0,8,8,8,8,8,8,0,0,0,0,0,0,0,0,0,0,8,8,0,0,47
0,47,0,47,0,0,0,0,0,0,8,8,50,0,0,0,0,0,0,0,0,0,0,50,8,47,0,47
0,0,47,0,0,0,0,0,0,0,8,72,8,66,0,0,0,0,0,0,0,57,54,8,8,47,0,0
0,0,47,0,47,47,47,0,0,0,8,8,8,8,8,8,8,63,62,8,8,8,8,8,8,0,0,0
0,0,47,47,0,0,47,0,0,47,47,0,47,47,47,0,0,0,0,0,0,0,0,0,0,0,0,0
:endlayer
layer: 13
0,0,0,0,0,0,0,0,0,0,0,0,0,0,0,0,0,0,0,0,0,0,0,0,0,0,0,0
0,0,0,0,0,0,0,0,0,0,0,0,0,0,0,0,0,0,0,0,0,0,0,0,0,0,0,0
0,0,0,0,0,0,0,0,0,0,0,0,0,0,0,0,0,0,0,0,0,0,0,0,0,0,0,0
0,0,0,0,0,0,0,0,0,0,0,0,0,0,0,0,0,0,0,0,0,0,0,0,0,0,0,0
0,0,0,0,0,0,0,0,0,0,0,0,0,0,0,0,0,0,0,0,0,0,0,0,0,0,0,0
0,0,0,0,0,0,0,8,8,8,8,8,8,8,8,8,8,8,8,8,8,8,8,8,8,0,0,0
0,0,0,0,0,0,0,8,0,0,0,0,8,8,8,8,8,8,8,8,8,8,8,8,8,0,0,0
0,0,0,0,0,0,0,8,87,8,85,81,8,0,0,0,0,0,0,0,0,0,0,8,8,0,0,0
0,0,0,0,0,0,0,8,0,8,82,82,50,0,0,0,0,0,0,0,0,0,0,50,8,0,0,0
0,0,0,0,0,0,0,8,0,8,8,8,8,0,0,0,0,77,77,0,0,0,0,8,8,0,0,0
0,0,8,8,8,8,8,8,8,8,67,67,50,0,0,0,0,0,0,0,0,0,0,50,8,0,0,0
0,0,8,0,50,0,0,50,0,8,68,68,8,0,0,0,0,0,0,0,0,0,0,8,8,0,0,0
0,0,8,0,0,0,0,0,0,0,73,69,8,0,0,0,0,0,0,0,0,0,0,0,75,0,0,0
0,0,8,0,0,0,0,0,0,0,73,69,8,0,0,0,0,0,0,0,0,0,0,0,76,0,0,0
0,0,8,0,50,0,0,50,0,8,70,70,8,0,0,0,0,0,0,0,0,0,0,8,8,0,0,0
0,0,8,8,8,8,8,8,8,8,71,71,50,0,0,0,0,0,0,0,0,0,0,50,8,0,0,0
0,0,0,0,0,0,0,8,0,8,8,8,8,0,0,0,0,0,0,0,0,0,0,8,8,0,0,0
0,0,0,0,0,0,0,8,0,8,83,83,50,0,0,0,0,0,0,0,0,0,0,50,8,0,0,0
0,0,0,0,0,0,0,8,0,8,86,84,8,0,0,0,0,0,0,0,0,0,0,8,8,0,0,0
0,0,0,0,0,0,0,8,0,0,0,0,50,0,0,0,0,0,0,0,0,0,0,50,8,0,0,0
0,0,0,0,0,0,0,8,8,8,8,8,8,0,0,0,0,0,0,0,0,0,0,8,8,0,0,0
0,0,0,0,0,0,0,0,0,0,8,8,50,0,0,0,0,0,0,0,0,0,0,50,8,0,0,0
0,0,0,0,0,0,0,0,0,0,8,0,8,0,0,0,0,0,0,0,0,0,0,8,8,0,0,0
0,0,0,0,0,0,0,0,0,0,8,8,8,8,8,8,80,79,78,22,8,8,8,8,8,0,0,0
0,0,0,0,0,0,0,0,0,0,0,0,0,0,0,0,0,0,0,0,0,0,0,0,0,0,0,0
:endlayer
layer: 14
0,0,0,0,0,0,0,0,0,0,0,0,0,0,0,0,0,0,0,0,0,0,0,0,0,0,0,0
0,0,0,0,0,0,0,0,0,0,0,0,0,0,0,0,0,0,0,0,0,0,0,0,0,0,0,0
0,0,0,0,0,0,0,0,0,0,0,0,0,0,0,0,0,0,0,0,0,0,0,0,0,0,0,0
0,0,0,0,0,0,0,0,0,0,0,0,0,0,0,0,0,0,0,0,0,0,0,0,0,0,0,0
0,0,0,0,0,0,0,0,0,0,0,0,0,0,0,0,0,0,0,0,0,0,0,0,0,0,0,0
0,0,0,0,0,0,0,8,8,8,8,8,8,8,8,8,8,88,88,8,8,8,8,8,8,0,0,0
0,0,0,0,0,0,0,8,0,0,0,0,8,8,8,8,8,89,89,8,8,8,8,8,8,0,0,0
0,0,0,0,0,0,0,8,0,90,0,0,8,0,0,0,0,0,0,0,0,0,0,8,8,0,0,0
0,0,0,0,0,0,0,8,0,8,0,0,50,0,0,0,0,0,0,0,0,0,0,50,8,0,0,0
0,0,0,0,0,0,0,8,0,8,0,0,8,0,0,0,0,0,0,0,0,0,0,8,8,0,0,0
0,92,8,8,8,8,8,8,8,8,8,8,50,0,0,0,0,0,0,0,0,0,0,50,8,0,0,0
0,92,8,27,50,27,27,50,27,8,8,8,8,0,0,0,0,0,0,0,0,0,0,8,8,0,0,0
0,92,8,19,0,0,0,0,13,8,8,8,8,0,0,0,0,0,0,0,0,0,0,8,8,0,0,0
0,92,8,19,0,0,0,0,13,8,8,8,8,0,0,0,0,0,0,0,0,0,0,8,8,0,0,0
0,92,8,21,50,21,21,50,21,8,8,8,8,0,0,0,0,0,0,0,0,0,0,8,8,0,0,0
0,92,8,8,8,8,8,8,8,8,8,8,50,0,0,0,0,0,0,0,0,0,0,50,8,0,0,0
0,0,0,0,0,0,0,8,0,8,0,0,8,0,0,0,0,0,0,0,0,0,0,8,8,0,0,0
0,0,0,0,0,0,0,8,0,8,0,0,50,0,0,0,0,0,0,0,0,0,0,50,8,0,0,0
0,0,0,0,0,0,0,8,0,91,0,0,8,0,0,0,0,0,0,0,0,0,0,8,8,0,0,0
0,0,0,0,0,0,0,8,0,0,0,0,50,0,0,0,0,0,0,0,0,0,0,50,8,0,0,0
0,0,0,0,0,0,0,8,8,8,8,8,8,0,0,0,0,0,0,0,0,0,0,8,8,0,0,0
0,0,0,0,0,0,0,0,0,0,8,8,50,0,0,0,0,0,0,0,0,0,0,50,8,0,0,0
0,0,0,0,0,0,0,0,0,0,8,8,8,0,0,0,0,0,0,0,0,0,0,8,8,0,0,0
0,0,0,0,0,0,0,0,0,0,8,8,8,8,8,8,19,80,22,13,8,8,8,8,8,0,0,0
0,0,0,0,0,0,0,0,0,0,0,0,0,0,0,0,0,0,0,0,0,0,0,0,0,0,0,0
:endlayer
layer: 15
0,0,0,0,0,0,0,0,0,0,0,0,0,0,0,0,0,0,0,0,0,0,0,0,0,0,0,0
0,0,0,0,0,0,0,0,0,0,0,0,0,0,0,0,0,0,0,0,0,0,0,0,0,0,0,0
0,0,0,0,0,0,0,0,0,0,0,0,0,0,0,0,0,0,0,0,0,0,0,0,0,0,0,0
0,0,0,0,0,0,0,0,0,0,0,0,0,0,0,0,0,0,0,0,0,0,0,0,0,0,0,0
0,0,0,0,0,0,0,0,0,0,0,0,0,0,0,0,0,0,0,0,0,0,0,0,0,0,0,0
0,0,0,0,0,0,0,8,8,8,8,8,8,8,8,8,8,88,88,8,8,8,8,8,8,0,0,0
0,0,0,0,0,0,0,8,8,8,8,8,8,8,8,8,8,89,89,8,8,8,8,8,8,0,0,0
0,0,0,0,0,0,0,8,8,0,8,8,8,0,0,0,0,0,0,0,0,0,0,8,8,0,0,0
0,0,0,0,0,0,0,8,8,85,8,8,50,0,0,0,0,0,0,0,0,0,0,50,8,0,0,0
0,0,0,0,0,0,0,8,8,81,8,8,8,0,0,0,0,0,0,0,0,0,0,8,8,0,0,0
0,0,97,92,8,8,8,8,8,96,8,8,50,0,0,95,0,0,0,0,95,0,0,50,8,0,0,0
0,0,97,92,8,8,8,8,8,43,8,8,8,0,0,0,0,0,0,0,0,0,0,8,8,0,0,0
0,0,97,92,8,8,8,8,8,45,74,87,8,0,0,0,0,0,0,0,0,0,0,93,93,0,0,0
0,0,97,92,8,8,8,8,8,74,87,90,8,0,0,0,0,0,0,0,0,0,0,94,94,0,0,0
0,0,97,92,8,8,8,8,8,87,8,8,8,0,0,0,0,0,0,0,0,0,0,8,8,0,0,0
0,0,97,92,8,8,8,8,8,90,8,8,50,0,0,95,0,0,0,0,95,0,0,50,8,0,0,0
0,0,0,0,0,0,0,8,8,85,8,8,8,0,0,0,0,0,0,0,0,0,0,8,8,0,0,0
0,0,0,0,0,0,0,8,8,81,8,8,50,0,0,0,0,0,0,0,0,0,0,50,8,0,0,0
0,0,0,0,0,0,0,8,8,0,8,8,8,0,0,0,0,0,0,0,0,0,0,8,8,0,0,0
0,0,0,0,0,0,0,8,8,0,8,8,50,0,0,0,0,0,0,0,0,0,0,50,8,0,0,0
0,0,0,0,0,0,0,8,8,8,8,8,8,0,0,0,0,0,0,0,0,0,0,8,8,0,0,0
0,0,0,0,0,0,0,0,0,0,8,8,50,0,0,95,0,0,0,0,95,0,0,50,8,0,0,0
0,0,0,0,0,0,0,0,0,0,8,8,8,0,0,0,0,0,0,0,0,0,0,8,8,0,0,0
0,0,0,0,0,0,0,0,0,0,8,8,8,8,8,8,22,80,22,80,8,8,8,8,8,0,0,0
0,0,0,0,0,0,0,0,0,0,0,0,0,0,0,0,0,0,0,0,0,0,0,0,0,0,0,0
:endlayer
layer: 16
0,0,0,0,0,0,0,0,0,0,0,0,0,0,0,0,0,0,0,0,0,0,0,0,0,0,0,0
0,0,0,0,0,0,0,0,0,0,0,0,0,0,0,0,0,0,0,0,0,0,0,0,0,0,0,0
0,0,0,0,0,0,0,0,0,0,0,0,0,0,0,0,0,0,0,0,0,0,0,0,0,0,0,0
0,0,0,0,0,0,0,0,0,0,0,0,0,0,0,0,0,0,0,0,0,0,0,0,0,0,0,0
0,0,0,0,0,0,92,101,0,0,0,0,0,0,0,0,0,0,0,0,0,0,0,0,0,0,0,0
0,0,0,0,0,0,92,8,8,8,8,8,8,8,8,8,88,88,88,88,8,8,8,8,8,0,0,0
0,0,0,0,0,0,92,8,8,8,8,8,8,8,8,8,89,89,89,89,8,8,8,8,8,0,0,0
0,0,0,0,0,0,92,8,8,8,8,8,8,0,0,0,0,0,0,0,0,0,0,8,8,0,0,0
0,0,0,0,0,0,92,8,8,8,8,8,50,100,0,0,0,0,0,0,0,0,98,50,8,0,0,0
0,0,0,0,0,0,92,8,8,8,8,8,8,0,0,0,0,0,0,0,0,0,0,8,8,0,0,0
0,0,0,0,92,102,102,8,8,8,8,8,50,100,0,99,0,0,0,0,99,0,98,50,8,0,0,0
0,0,0,0,92,97,97,8,8,8,8,8,8,0,0,0,0,0,0,0,0,0,0,93,93,0,0,0
0,0,0,0,92,97,97,8,8,8,8,8,8,0,0,0,0,0,0,0,0,0,0,21,21,0,0,0
0,0,0,0,92,97,97,8,8,8,8,8,8,0,0,0,0,0,0,0,0,0,0,27,27,0,0,0
0,0,0,0,92,97,97,8,8,8,8,8,8,0,0,0,0,0,0,0,0,0,0,94,94,0,0,0
0,0,0,0,92,102,102,8,8,8,8,8,50,100,0,99,0,0,0,0,99,0,98,50,8,0,0,0
0,0,0,0,0,0,92,8,8,8,8,8,8,0,0,0,0,0,0,0,0,0,0,8,8,0,0,0
0,0,0,0,0,0,92,8,8,8,8,8,50,100,0,0,0,0,0,0,0,0,98,50,8,0,0,0
0,0,0,0,0,0,92,8,8,8,8,8,8,0,0,0,0,0,0,0,0,0,0,8,8,0,0,0
0,0,0,0,0,0,92,8,8,8,8,8,50,100,0,0,0,0,0,0,0,0,98,50,8,0,0,0
0,0,0,0,0,0,92,8,8,8,8,8,8,0,0,0,0,0,0,0,0,0,0,8,8,0,0,0
0,0,0,0,0,0,92,101,0,0,8,8,50,100,0,99,0,0,0,0,99,0,98,50,8,0,0,0
0,0,0,0,0,0,0,0,0,0,8,8,8,0,0,0,0,0,0,0,0,0,0,8,8,0,0,0
0,0,0,0,0,0,0,0,0,0,8,8,8,8,8,8,8,8,8,8,8,8,8,8,8,0,0,0
0,0,0,0,0,0,0,0,0,0,0,0,0,0,0,0,0,0,0,0,0,0,0,0,0,0,0,0
:endlayer
layer: 17
0,0,0,0,0,0,0,0,0,0,0,0,0,0,0,0,0,0,0,0,0,0,0,0,0,0,0,0
0,0,0,0,0,0,0,0,0,0,0,0,0,0,0,0,0,0,0,0,0,0,0,0,0,0,0,0
0,0,0,0,0,0,0,0,0,0,0,0,0,0,0,0,0,0,0,0,0,0,0,0,0,0,0,0
0,0,0,0,0,0,0,0,0,0,0,0,0,0,0,0,0,0,0,0,0,0,0,0,0,0,0,0
0,0,0,0,0,0,0,92,101,0,0,0,0,0,0,0,0,0,0,0,0,0,0,0,0,0,0,0
0,0,0,0,0,0,0,92,8,8,8,8,8,8,8,8,8,88,88,8,8,8,8,8,8,0,0,0
0,0,0,0,0,0,0,92,8,8,8,8,8,8,8,8,8,89,89,8,8,8,8,8,8,0,0,0
0,0,0,0,0,0,0,92,8,8,8,8,8,0,0,0,0,0,0,0,0,0,0,8,8,0,0,0
0,0,0,0,0,0,0,92,8,8,8,8,50,103,100,44,0,0,0,0,44,98,103,50,8,0,0,0
0,0,0,0,0,0,0,92,8,8,8,8,8,0,0,0,0,0,0,0,0,0,0,8,8,0,0,0
0,0,0,0,0,97,97,92,8,8,8,8,50,103,100,99,0,0,0,0,99,98,103,50,8,0,0,0
0,0,0,0,0,97,97,92,8,8,8,8,8,0,0,0,0,0,0,0,0,0,0,27,27,0,0,0
0,0,0,0,0,97,97,92,8,8,8,8,8,0,0,0,0,0,0,0,0,0,0,94,94,0,0,0
0,0,0,0,0,97,97,92,8,8,8,8,8,0,0,0,0,0,0,0,0,0,0,93,93,0,0,0
0,0,0,0,0,97,97,92,8,8,8,8,8,0,0,0,0,0,0,0,0,0,0,21,21,0,0,0
0,0,0,0,0,97,97,92,8,8,8,8,50,103,100,99,0,0,0,0,99,98,103,50,8,0,0,0
0,0,0,0,0,0,0,92,8,8,8,8,8,0,0,0,0,0,0,0,0,0,0,8,8,0,0,0
0,0,0,0,0,0,0,92,8,8,8,8,50,103,100,44,0,0,0,0,44,98,103,50,8,0,0,0
0,0,0,0,0,0,0,92,8,8,8,8,8,0,0,0,0,0,0,0,0,0,0,8,8,0,0,0
0,0,0,0,0,0,0,92,8,8,8,8,50,103,100,44,0,0,0,0,44,98,103,50,8,0,0,0
0,0,0,0,0,0,0,92,8,8,8,8,8,0,0,0,0,0,0,0,0,0,0,8,8,0,0,0
0,0,0,0,0,0,0,92,101,0,8,8,50,103,100,99,0,0,0,0,99,98,103,50,8,0,0,0
0,0,0,0,0,0,0,0,0,0,8,8,8,0,0,0,0,0,0,0,0,0,0,8,8,0,0,0
0,0,0,0,0,0,0,0,0,0,8,8,8,8,8,8,8,8,8,8,8,8,8,8,8,0,0,0
0,0,0,0,0,0,0,0,0,0,0,0,0,0,0,0,0,0,0,0,0,0,0,0,0,0,0,0
:endlayer
layer: 18
0,0,0,0,0,0,0,0,0,0,0,0,0,0,0,0,0,0,0,0,0,0,0,0,0,0,0,0
0,0,0,0,0,0,0,0,0,0,0,0,0,0,0,0,0,0,0,0,0,0,0,0,0,0,0,0
0,0,0,0,0,0,0,0,0,0,0,0,0,0,0,0,0,0,0,0,0,0,0,0,0,0,0,0
0,0,0,0,0,0,0,0,0,0,0,0,0,0,0,0,0,0,0,0,0,0,0,0,0,0,0,0
0,0,0,0,0,0,0,0,92,101,0,0,0,0,0,0,0,0,0,0,0,0,0,0,0,0,0,0
0,0,0,0,0,0,0,0,92,8,8,8,8,8,8,8,8,8,8,8,8,8,8,8,8,0,0,0
0,0,0,0,0,0,0,0,92,8,8,8,8,8,8,8,8,8,8,8,8,8,8,8,8,0,0,0
0,0,0,0,0,0,0,0,92,8,8,8,8,0,0,0,0,0,0,0,0,0,0,8,8,0,0,0
0,0,0,0,0,0,0,0,92,8,8,8,50,103,105,104,100,103,103,98,105,104,103,50,8,0,0,0
0,0,0,0,0,0,0,0,92,8,8,8,8,0,0,0,0,0,0,0,0,0,0,8,8,0,0,0
0,0,0,0,0,0,0,0,92,8,8,8,50,103,105,104,100,103,103,98,105,104,103,50,8,0,0,0
0,0,0,0,0,0,0,0,92,8,8,8,8,0,0,0,0,0,0,0,0,0,0,8,8,0,0,0
0,0,0,0,0,0,0,0,92,8,8,8,8,0,0,0,0,0,0,0,0,0,0,27,27,0,0,0
0,0,0,0,0,0,0,0,92,8,8,8,8,0,0,0,0,0,0,0,0,0,0,21,21,0,0,0
0,0,0,0,0,0,0,0,92,8,8,8,8,0,0,0,0,0,0,0,0,0,0,8,8,0,0,0
0,0,0,0,0,0,0,0,92,8,8,8,50,103,105,104,100,103,103,98,105,104,103,50,8,0,0,0
0,0,0,0,0,0,0,0,92,8,8,8,8,0,0,0,0,0,0,0,0,0,0,8,8,0,0,0
0,0,0,0,0,0,0,0,92,8,8,8,50,103,105,104,100,103,103,98,105,104,103,50,8,0,0,0
0,0,0,0,0,0,0,0,92,8,8,8,8,0,0,0,0,0,0,0,0,0,0,8,8,0,0,0
0,0,0,0,0,0,0,0,92,8,8,8,50,103,105,104,100,103,103,98,105,104,103,50,8,0,0,0
0,0,0,0,0,0,0,0,92,8,8,8,8,0,0,0,0,0,0,0,0,0,0,8,8,0,0,0
0,0,0,0,0,0,0,0,92,101,8,8,50,103,105,104,100,106,106,98,105,104,103,50,8,0,0,0
0,0,0,0,0,0,0,0,0,0,8,8,8,0,0,0,0,0,0,0,0,0,0,8,8,0,0,0
0,0,0,0,0,0,0,0,0,0,8,8,8,8,8,8,8,8,8,8,8,8,8,8,8,0,0,0
0,0,0,0,0,0,0,0,0,0,0,0,0,0,0,0,0,0,0,0,0,0,0,0,0,0,0,0
:endlayer
layer: 19
0,0,0,0,0,0,0,0,0,0,0,0,0,0,0,0,0,0,0,0,0,0,0,0,0,0,0,0
0,0,0,0,0,0,0,0,0,0,0,0,0,0,0,0,0,0,0,0,0,0,0,0,0,0,0,0
0,0,0,0,0,0,0,0,0,0,0,0,0,0,0,0,0,0,0,0,0,0,0,0,0,0,0,0
0,0,0,0,0,0,0,0,0,0,0,0,0,0,0,0,0,0,0,0,0,0,0,0,0,0,0,0
0,0,0,0,0,0,0,0,0,92,101,0,0,0,0,0,0,0,0,0,0,0,0,0,0,0,0,0
0,0,0,0,0,0,0,0,0,92,8,8,8,8,8,8,8,8,8,8,8,8,8,8,8,0,0,0
0,0,0,0,0,0,0,0,0,92,8,8,8,8,8,8,8,8,8,8,8,8,8,8,8,0,0,0
0,0,0,0,0,0,0,0,0,92,8,8,8,0,0,0,0,0,0,0,0,0,0,8,8,0,0,0
0,0,0,0,0,0,0,0,0,92,8,8,50,105,0,0,104,103,103,105,0,0,104,50,8,0,0,0
0,0,0,0,0,0,0,0,0,92,8,8,8,0,0,0,0,0,0,0,0,0,0,8,8,0,0,0
0,0,0,0,0,0,0,0,0,92,8,8,50,105,0,0,104,103,103,105,0,0,104,50,8,0,0,0
0,0,0,0,0,0,0,0,0,92,8,8,8,0,0,0,0,0,0,0,0,0,0,8,8,0,0,0
0,0,0,0,0,0,0,0,0,92,8,8,8,0,0,0,0,0,0,0,0,0,0,8,8,0,0,0
0,0,0,0,0,0,0,0,0,92,8,8,8,0,0,0,0,0,0,0,0,0,0,8,8,0,0,0
0,0,0,0,0,0,0,0,0,92,8,8,8,0,0,0,0,0,0,0,0,0,0,8,8,0,0,0
0,0,0,0,0,0,0,0,0,92,8,8,50,105,0,0,104,103,103,105,0,0,104,50,8,0,0,0
0,0,0,0,0,0,0,0,0,92,8,8,8,0,0,0,0,0,0,0,0,0,0,8,8,0,0,0
0,0,0,0,0,0,0,0,0,92,8,8,50,105,0,0,104,107,107,105,0,0,104,50,8,0,0,0
0,0,0,0,0,0,0,0,0,92,8,8,8,0,0,0,0,0,0,0,0,0,0,8,8,0,0,0
0,0,0,0,0,0,0,0,0,92,8,8,50,105,0,0,104,107,107,105,0,0,104,50,8,0,0,0
0,0,0,0,0,0,0,0,0,92,8,8,8,0,0,0,0,0,0,0,0,0,0,8,8,0,0,0
0,0,0,0,0,0,0,0,0,92,8,8,50,105,0,0,104,103,103,105,0,0,104,50,8,0,0,0
0,0,0,0,0,0,0,0,0,92,8,8,8,0,0,0,0,0,0,0,0,0,0,8,8,0,0,0
0,0,0,0,0,0,0,0,0,92,8,8,8,8,8,8,8,8,8,8,8,8,8,8,8,0,0,0
0,0,0,0,0,0,0,0,0,92,101,0,0,0,0,0,0,0,0,0,0,0,0,0,0,0,0,0
:endlayer
layer: 20
0,0,0,0,0,0,0,0,0,0,0,0,0,0,0,0,0,0,0,0,0,0,0,0,0,0,0,0
0,0,0,0,0,0,0,0,0,0,0,0,0,0,0,0,0,0,0,0,0,0,0,0,0,0,0,0
0,0,0,0,0,0,0,0,0,0,0,0,0,0,0,0,0,0,0,0,0,0,0,0,0,0,0,0
0,0,0,0,0,0,0,0,0,0,0,0,0,0,0,0,0,0,0,0,0,0,0,0,0,0,0,0
0,0,0,0,0,0,0,0,0,0,92,101,0,0,0,0,0,0,0,0,0,0,0,0,101,108,0,0
0,0,0,0,0,0,0,0,0,0,92,101,101,101,101,101,101,101,101,101,101,101,101,101,101,108,0,0
0,0,0,0,0,0,0,0,0,0,92,101,101,101,101,101,101,101,101,101,101,101,101,101,101,108,0,0
0,0,0,0,0,0,0,0,0,0,92,101,101,0,0,0,0,0,0,0,0,0,0,101,101,108,0,0
0,0,0,0,0,0,0,0,0,0,92,101,50,0,0,0,0,0,0,0,0,0,0,50,101,108,0,0
0,0,0,0,0,0,0,0,0,0,92,101,101,0,0,0,0,0,0,0,0,0,0,101,101,108,0,0
0,0,0,0,0,0,0,0,0,0,92,101,50,0,0,0,0,0,0,0,0,0,0,50,101,108,0,0
0,0,0,0,0,0,0,0,0,0,92,101,101,0,0,0,0,0,0,0,0,0,0,101,101,108,0,0
0,0,0,0,0,0,0,0,0,0,92,101,101,0,0,0,0,0,0,0,0,0,0,101,101,108,0,0
0,0,0,0,0,0,0,0,0,0,92,101,101,0,0,0,0,0,0,0,0,0,0,101,101,108,0,0
0,0,0,0,0,0,0,0,0,0,92,101,101,0,0,0,0,0,0,0,0,0,0,101,101,108,0,0
0,0,0,0,0,0,0,0,0,0,92,101,50,0,0,0,0,0,0,0,0,0,0,50,101,108,0,0
0,0,0,0,0,0,0,0,0,0,92,101,101,0,0,0,0,0,0,0,0,0,0,101,101,108,0,0
0,0,0,0,0,0,0,0,0,0,92,101,50,0,0,0,0,0,0,0,0,0,0,50,101,108,0,0
0,0,0,0,0,0,0,0,0,0,92,101,101,0,0,0,0,0,0,0,0,0,0,101,101,108,0,0
0,0,0,0,0,0,0,0,0,0,92,101,50,0,0,0,0,0,0,0,0,0,0,50,101,108,0,0
0,0,0,0,0,0,0,0,0,0,92,101,101,0,0,0,0,0,0,0,0,0,0,101,101,108,0,0
0,0,0,0,0,0,0,0,0,0,92,101,50,0,0,0,0,0,0,0,0,0,0,50,101,108,0,0
0,0,0,0,0,0,0,0,0,0,92,101,101,0,0,0,0,0,0,0,0,0,0,101,101,108,0,0
0,0,0,0,0,0,0,0,0,0,92,101,101,101,101,101,101,101,101,101,101,101,101,101,101,108,0,0
0,0,0,0,0,0,0,0,0,0,92,101,0,0,0,0,0,0,0,0,0,0,0,0,101,108,0,0
:endlayer
layer: 21
0,0,0,0,0,0,0,0,0,0,0,0,0,0,0,0,0,0,0,0,0,0,0,0,0,0,0,0
0,0,0,0,0,0,0,0,0,0,0,0,0,0,0,0,0,0,0,0,0,0,0,0,0,0,0,0
0,0,0,0,0,0,0,0,0,0,0,0,0,0,0,0,0,0,0,0,0,0,0,0,0,0,0,0
0,0,0,0,0,0,0,0,0,0,0,0,0,0,0,0,0,0,0,0,0,0,0,0,0,0,0,0
0,0,0,0,0,0,0,0,0,0,0,92,101,0,0,0,0,0,0,0,0,0,0,101,108,0,0,0
0,0,0,0,0,0,0,0,0,0,0,92,101,101,101,101,101,101,101,101,101,101,101,101,108,0,0,0
0,0,0,0,0,0,0,0,0,0,0,92,101,101,101,101,101,101,101,101,101,101,101,101,108,0,0,0
0,0,0,0,0,0,0,0,0,0,0,92,101,0,0,0,0,0,0,0,0,0,0,101,108,0,0,0
0,0,0,0,0,0,0,0,0,0,0,92,50,0,0,0,0,0,0,0,0,0,0,50,108,0,0,0
0,0,0,0,0,0,0,0,0,0,0,92,101,0,0,0,0,0,0,0,0,0,0,101,108,0,0,0
0,0,0,0,0,0,0,0,0,0,0,92,50,0,0,0,0,0,0,0,0,0,0,50,108,0,0,0
0,0,0,0,0,0,0,0,0,0,0,92,101,0,0,0,0,0,0,0,0,0,0,101,108,0,0,0
0,0,0,0,0,0,0,0,0,0,0,92,101,0,0,0,0,0,0,0,0,0,0,101,108,0,0,0
0,0,0,0,0,0,0,0,0,0,0,92,101,0,0,0,0,0,0,0,0,0,0,101,108,0,0,0
0,0,0,0,0,0,0,0,0,0,0,92,101,0,0,0,0,0,0,0,0,0,0,101,108,0,0,0
0,0,0,0,0,0,0,0,0,0,0,92,50,0,0,0,0,0,0,0,0,0,0,50,108,0,0,0
0,0,0,0,0,0,0,0,0,0,0,92,101,0,0,0,0,0,0,0,0,0,0,101,108,0,0,0
0,0,0,0,0,0,0,0,0,0,0,92,50,0,0,0,0,0,0,0,0,0,0,50,108,0,0,0
0,0,0,0,0,0,0,0,0,0,0,92,101,0,0,0,0,0,0,0,0,0,0,101,108,0,0,0
0,0,0,0,0,0,0,0,0,0,0,92,50,0,0,0,0,0,0,0,0,0,0,50,108,0,0,0
0,0,0,0,0,0,0,0,0,0,0,92,101,0,0,0,0,0,0,0,0,0,0,101,108,0,0,0
0,0,0,0,0,0,0,0,0,0,0,92,50,0,0,0,0,0,0,0,0,0,0,50,108,0,0,0
0,0,0,0,0,0,0,0,0,0,0,92,101,0,0,0,0,0,0,0,0,0,0,101,108,0,0,0
0,0,0,0,0,0,0,0,0,0,0,92,101,101,101,101,101,101,101,101,101,101,101,101,108,0,0,0
0,0,0,0,0,0,0,0,0,0,0,92,101,0,0,0,0,0,0,0,0,0,0,101,108,0,0,0
:endlayer
layer: 22
0,0,0,0,0,0,0,0,0,0,0,0,0,0,0,0,0,0,0,0,0,0,0,0,0,0,0,0
0,0,0,0,0,0,0,0,0,0,0,0,0,0,0,0,0,0,0,0,0,0,0,0,0,0,0,0
0,0,0,0,0,0,0,0,0,0,0,0,0,0,0,0,0,0,0,0,0,0,0,0,0,0,0,0
0,0,0,0,0,0,0,0,0,0,0,0,0,0,0,0,0,0,0,0,0,0,0,0,0,0,0,0
0,0,0,0,0,0,0,0,0,0,0,0,92,101,101,0,0,0,0,0,0,101,101,108,0,0,0,0
0,0,0,0,0,0,0,0,0,0,0,0,92,101,101,101,101,101,101,101,101,101,101,108,0,0,0,0
0,0,0,0,0,0,0,0,0,0,0,0,92,101,101,101,101,101,101,101,101,101,101,108,0,0,0,0
0,0,0,0,0,0,0,0,0,0,0,0,92,111,110,0,0,0,0,0,0,110,109,108,0,0,0,0
0,0,0,0,0,0,0,0,0,0,0,0,92,111,110,0,0,0,0,0,0,110,109,108,0,0,0,0
0,0,0,0,0,0,0,0,0,0,0,0,92,111,110,0,0,0,0,0,0,110,109,108,0,0,0,0
0,0,0,0,0,0,0,0,0,0,0,0,92,111,110,0,0,0,0,0,0,110,109,108,0,0,0,0
0,0,0,0,0,0,0,0,0,0,0,0,92,111,110,0,0,0,0,0,0,110,109,108,0,0,0,0
0,0,0,0,0,0,0,0,0,0,0,0,92,111,110,0,0,0,0,0,0,110,109,108,0,0,0,0
0,0,0,0,0,0,0,0,0,0,0,0,92,111,110,0,0,0,0,0,0,110,109,108,0,0,0,0
0,0,0,0,0,0,0,0,0,0,0,0,92,111,110,0,0,0,0,0,0,110,109,108,0,0,0,0
0,0,0,0,0,0,0,0,0,0,0,0,92,111,110,0,0,0,0,0,0,110,109,108,0,0,0,0
0,0,0,0,0,0,0,0,0,0,0,0,92,111,110,0,0,0,0,0,0,110,109,108,0,0,0,0
0,0,0,0,0,0,0,0,0,0,0,0,92,111,110,0,0,0,0,0,0,110,109,108,0,0,0,0
0,0,0,0,0,0,0,0,0,0,0,0,92,111,110,0,0,0,0,0,0,110,109,108,0,0,0,0
0,0,0,0,0,0,0,0,0,0,0,0,92,111,110,0,0,0,0,0,0,110,109,108,0,0,0,0
0,0,0,0,0,0,0,0,0,0,0,0,92,111,110,0,0,0,0,0,0,110,109,108,0,0,0,0
0,0,0,0,0,0,0,0,0,0,0,0,92,111,110,0,0,0,0,0,0,110,109,108,0,0,0,0
0,0,0,0,0,0,0,0,0,0,0,0,92,111,110,0,0,0,0,0,0,110,109,108,0,0,0,0
0,0,0,0,0,0,0,0,0,0,0,0,92,101,101,101,101,101,101,101,101,101,101,108,0,0,0,0
0,0,0,0,0,0,0,0,0,0,0,0,92,101,101,0,0,0,0,0,0,101,101,108,0,0,0,0
:endlayer
layer: 23
0,0,0,0,0,0,0,0,0,0,0,0,0,0,0,0,0,0,0,0,0,0,0,0,0,0,0,0
0,0,0,0,0,0,0,0,0,0,0,0,0,0,0,0,0,0,0,0,0,0,0,0,0,0,0,0
0,0,0,0,0,0,0,0,0,0,0,0,0,0,0,0,0,0,0,0,0,0,0,0,0,0,0,0
0,0,0,0,0,0,0,0,0,0,0,0,0,0,0,0,0,0,0,0,0,0,0,0,0,0,0,0
0,0,0,0,0,0,0,0,0,0,0,0,0,97,92,101,101,0,0,101,101,108,97,0,0,0,0,0
0,0,0,0,0,0,0,0,0,0,0,0,0,97,92,101,101,101,101,101,101,108,97,0,0,0,0,0
0,0,0,0,0,0,0,0,0,0,0,0,0,97,92,101,101,101,101,101,101,108,97,0,0,0,0,0
0,0,0,0,0,0,0,0,0,0,0,0,0,97,92,101,101,0,0,101,101,108,97,0,0,0,0,0
0,0,0,0,0,0,0,0,0,0,0,0,0,97,92,101,101,0,0,101,101,108,97,0,0,0,0,0
0,0,0,0,0,0,0,0,0,0,0,0,0,97,92,101,101,0,0,101,101,108,97,0,0,0,0,0
0,0,0,0,0,0,0,0,0,0,0,0,0,97,92,101,101,0,0,101,101,108,97,0,0,0,0,0
0,0,0,0,0,0,0,0,0,0,0,0,0,97,92,101,101,0,0,101,101,108,97,0,0,0,0,0
0,0,0,0,0,0,0,0,0,0,0,0,0,97,92,101,101,0,0,101,101,108,97,0,0,0,0,0
0,0,0,0,0,0,0,0,0,0,0,0,0,97,92,101,101,0,0,101,101,108,97,0,0,0,0,0
0,0,0,0,0,0,0,0,0,0,0,0,0,97,92,101,101,0,0,101,101,108,97,0,0,0,0,0
0,0,0,0,0,0,0,0,0,0,0,0,0,97,92,101,101,0,0,101,101,108,97,0,0,0,0,0
0,0,0,0,0,0,0,0,0,0,0,0,0,97,92,101,101,0,0,101,101,108,97,0,0,0,0,0
0,0,0,0,0,0,0,0,0,0,0,0,0,97,92,101,101,0,0,101,101,108,97,0,0,0,0,0
0,0,0,0,0,0,0,0,0,0,0,0,0,97,92,101,101,0,0,101,101,108,97,0,0,0,0,0
0,0,0,0,0,0,0,0,0,0,0,0,0,97,92,101,101,0,0,101,101,108,97,0,0,0,0,0
0,0,0,0,0,0,0,0,0,0,0,0,0,97,92,101,101,0,0,101,101,108,97,0,0,0,0,0
0,0,0,0,0,0,0,0,0,0,0,0,0,97,92,101,101,0,0,101,101,108,97,0,0,0,0,0
0,0,0,0,0,0,0,0,0,0,0,0,0,97,92,101,101,0,0,101,101,108,97,0,0,0,0,0
0,0,0,0,0,0,0,0,0,0,0,0,0,97,92,101,101,101,101,101,101,108,97,0,0,0,0,0
0,0,0,0,0,0,0,0,0,0,0,0,0,97,92,101,101,0,0,101,101,108,97,0,0,0,0,0
:endlayer
layer: 24
0,0,0,0,0,0,0,0,0,0,0,0,0,0,0,0,0,0,0,0,0,0,0,0,0,0,0,0
0,0,0,0,0,0,0,0,0,0,0,0,0,0,0,0,0,0,0,0,0,0,0,0,0,0,0,0
0,0,0,0,0,0,0,0,0,0,0,0,0,0,0,0,0,0,0,0,0,0,0,0,0,0,0,0
0,0,0,0,0,0,0,0,0,0,0,0,0,0,0,0,0,0,0,0,0,0,0,0,0,0,0,0
0,0,0,0,0,0,0,0,0,0,0,0,0,0,0,97,92,101,101,108,97,0,0,0,0,0,0,0
0,0,0,0,0,0,0,0,0,0,0,0,0,0,0,97,92,101,101,108,97,0,0,0,0,0,0,0
0,0,0,0,0,0,0,0,0,0,0,0,0,0,0,97,92,101,101,108,97,0,0,0,0,0,0,0
0,0,0,0,0,0,0,0,0,0,0,0,0,0,0,97,92,101,101,108,97,0,0,0,0,0,0,0
0,0,0,0,0,0,0,0,0,0,0,0,0,0,0,97,92,101,101,108,97,0,0,0,0,0,0,0
0,0,0,0,0,0,0,0,0,0,0,0,0,0,0,97,92,101,101,108,97,0,0,0,0,0,0,0
0,0,0,0,0,0,0,0,0,0,0,0,0,0,0,97,92,101,101,108,97,0,0,0,0,0,0,0
0,0,0,0,0,0,0,0,0,0,0,0,0,0,0,97,92,101,101,108,97,0,0,0,0,0,0,0
0,0,0,0,0,0,0,0,0,0,0,0,0,0,0,97,92,101,101,108,97,0,0,0,0,0,0,0
0,0,0,0,0,0,0,0,0,0,0,0,0,0,0,97,92,101,101,108,97,0,0,0,0,0,0,0
0,0,0,0,0,0,0,0,0,0,0,0,0,0,0,97,92,101,101,108,97,0,0,0,0,0,0,0
0,0,0,0,0,0,0,0,0,0,0,0,0,0,0,97,92,101,101,108,97,0,0,0,0,0,0,0
0,0,0,0,0,0,0,0,0,0,0,0,0,0,0,97,92,101,101,108,97,0,0,0,0,0,0,0
0,0,0,0,0,0,0,0,0,0,0,0,0,0,0,97,92,101,101,108,97,0,0,0,0,0,0,0
0,0,0,0,0,0,0,0,0,0,0,0,0,0,0,97,92,101,101,108,97,0,0,0,0,0,0,0
0,0,0,0,0,0,0,0,0,0,0,0,0,0,0,97,92,101,101,108,97,0,0,0,0,0,0,0
0,0,0,0,0,0,0,0,0,0,0,0,0,0,0,97,92,101,101,108,97,0,0,0,0,0,0,0
0,0,0,0,0,0,0,0,0,0,0,0,0,0,0,97,92,101,101,108,97,0,0,0,0,0,0,0
0,0,0,0,0,0,0,0,0,0,0,0,0,0,0,97,92,101,101,108,97,0,0,0,0,0,0,0
0,0,0,0,0,0,0,0,0,0,0,0,0,0,0,97,92,101,101,108,97,0,0,0,0,0,0,0
0,0,0,0,0,0,0,0,0,0,0,0,0,0,0,97,104,112,112,105,97,0,0,0,0,0,0,0
:endlayer
layer: 25
0,0,0,0,0,0,0,0,0,0,0,0,0,0,0,0,0,0,0,0,0,0,0,0,0,0,0,0
0,0,0,0,0,0,0,0,0,0,0,0,0,0,0,0,0,0,0,0,0,0,0,0,0,0,0,0
0,0,0,0,0,0,0,0,0,0,0,0,0,0,0,0,0,0,0,0,0,0,0,0,0,0,0,0
0,0,0,0,0,0,0,0,0,0,0,0,0,0,0,0,0,0,0,0,0,0,0,0,0,0,0,0
0,0,0,0,0,0,0,0,0,0,0,0,0,0,0,0,0,113,113,0,0,0,0,0,0,0,0,0
0,0,0,0,0,0,0,0,0,0,0,0,0,0,0,0,0,113,113,0,0,0,0,0,0,0,0,0
0,0,0,0,0,0,0,0,0,0,0,0,0,0,0,0,0,113,113,0,0,0,0,0,0,0,0,0
0,0,0,0,0,0,0,0,0,0,0,0,0,0,0,0,0,113,113,0,0,0,0,0,0,0,0,0
0,0,0,0,0,0,0,0,0,0,0,0,0,0,0,0,0,113,113,0,0,0,0,0,0,0,0,0
0,0,0,0,0,0,0,0,0,0,0,0,0,0,0,0,0,113,113,0,0,0,0,0,0,0,0,0
0,0,0,0,0,0,0,0,0,0,0,0,0,0,0,0,0,113,113,0,0,0,0,0,0,0,0,0
0,0,0,0,0,0,0,0,0,0,0,0,0,0,0,0,0,113,113,0,0,0,0,0,0,0,0,0
0,0,0,0,0,0,0,0,0,0,0,0,0,0,0,0,0,113,113,0,0,0,0,0,0,0,0,0
0,0,0,0,0,0,0,0,0,0,0,0,0,0,0,0,0,113,113,0,0,0,0,0,0,0,0,0
0,0,0,0,0,0,0,0,0,0,0,0,0,0,0,0,0,113,113,0,0,0,0,0,0,0,0,0
0,0,0,0,0,0,0,0,0,0,0,0,0,0,0,0,0,113,113,0,0,0,0,0,0,0,0,0
0,0,0,0,0,0,0,0,0,0,0,0,0,0,0,0,0,113,113,0,0,0,0,0,0,0,0,0
0,0,0,0,0,0,0,0,0,0,0,0,0,0,0,0,0,113,113,0,0,0,0,0,0,0,0,0
0,0,0,0,0,0,0,0,0,0,0,0,0,0,0,0,0,113,113,0,0,0,0,0,0,0,0,0
0,0,0,0,0,0,0,0,0,0,0,0,0,0,0,0,0,113,113,0,0,0,0,0,0,0,0,0
0,0,0,0,0,0,0,0,0,0,0,0,0,0,0,0,0,113,113,0,0,0,0,0,0,0,0,0
0,0,0,0,0,0,0,0,0,0,0,0,0,0,0,0,0,113,113,0,0,0,0,0,0,0,0,0
0,0,0,0,0,0,0,0,0,0,0,0,0,0,0,0,0,113,113,0,0,0,0,0,0,0,0,0
0,0,0,0,0,0,0,0,0,0,0,0,0,0,0,0,0,114,114,0,0,0,0,0,0,0,0,0
0,0,0,0,0,0,0,0,0,0,0,0,0,0,0,0,0,61,61,0,0,0,0,0,0,0,0,0
:endlayer
layer: 26
0,0,0,0,0,0,0,0,0,0,0,0,0,0,0,0,0,0,0,0,0,0,0,0,0,0,0,0
0,0,0,0,0,0,0,0,0,0,0,0,0,0,0,0,0,0,0,0,0,0,0,0,0,0,0,0
0,0,0,0,0,0,0,0,0,0,0,0,0,0,0,0,0,0,0,0,0,0,0,0,0,0,0,0
0,0,0,0,0,0,0,0,0,0,0,0,0,0,0,0,0,0,0,0,0,0,0,0,0,0,0,0
0,0,0,0,0,0,0,0,0,0,0,0,0,0,0,0,0,0,0,0,0,0,0,0,0,0,0,0
0,0,0,0,0,0,0,0,0,0,0,0,0,0,0,0,0,0,0,0,0,0,0,0,0,0,0,0
0,0,0,0,0,0,0,0,0,0,0,0,0,0,0,0,0,0,0,0,0,0,0,0,0,0,0,0
0,0,0,0,0,0,0,0,0,0,0,0,0,0,0,0,0,0,0,0,0,0,0,0,0,0,0,0
0,0,0,0,0,0,0,0,0,0,0,0,0,0,0,0,0,0,0,0,0,0,0,0,0,0,0,0
0,0,0,0,0,0,0,0,0,0,0,0,0,0,0,0,0,0,0,0,0,0,0,0,0,0,0,0
0,0,0,0,0,0,0,0,0,0,0,0,0,0,0,0,0,0,0,0,0,0,0,0,0,0,0,0
0,0,0,0,0,0,0,0,0,0,0,0,0,0,0,0,0,0,0,0,0,0,0,0,0,0,0,0
0,0,0,0,0,0,0,0,0,0,0,0,0,0,0,0,0,0,0,0,0,0,0,0,0,0,0,0
0,0,0,0,0,0,0,0,0,0,0,0,0,0,0,0,0,0,0,0,0,0,0,0,0,0,0,0
0,0,0,0,0,0,0,0,0,0,0,0,0,0,0,0,0,0,0,0,0,0,0,0,0,0,0,0
0,0,0,0,0,0,0,0,0,0,0,0,0,0,0,0,0,0,0,0,0,0,0,0,0,0,0,0
0,0,0,0,0,0,0,0,0,0,0,0,0,0,0,0,0,0,0,0,0,0,0,0,0,0,0,0
0,0,0,0,0,0,0,0,0,0,0,0,0,0,0,0,0,0,0,0,0,0,0,0,0,0,0,0
0,0,0,0,0,0,0,0,0,0,0,0,0,0,0,0,0,0,0,0,0,0,0,0,0,0,0,0
0,0,0,0,0,0,0,0,0,0,0,0,0,0,0,0,0,0,0,0,0,0,0,0,0,0,0,0
0,0,0,0,0,0,0,0,0,0,0,0,0,0,0,0,0,0,0,0,0,0,0,0,0,0,0,0
0,0,0,0,0,0,0,0,0,0,0,0,0,0,0,0,0,0,0,0,0,0,0,0,0,0,0,0
0,0,0,0,0,0,0,0,0,0,0,0,0,0,0,0,0,0,0,0,0,0,0,0,0,0,0,0
0,0,0,0,0,0,0,0,0,0,0,0,0,0,0,0,0,0,0,0,0,0,0,0,0,0,0,0
0,0,0,0,0,0,0,0,0,0,0,0,0,0,0,0,0,61,61,0,0,0,0,0,0,0,0,0
:endlayer
layer: 27
0,0,0,0,0,0,0,0,0,0,0,0,0,0,0,0,0,0,0,0,0,0,0,0,0,0,0,0
0,0,0,0,0,0,0,0,0,0,0,0,0,0,0,0,0,0,0,0,0,0,0,0,0,0,0,0
0,0,0,0,0,0,0,0,0,0,0,0,0,0,0,0,0,0,0,0,0,0,0,0,0,0,0,0
0,0,0,0,0,0,0,0,0,0,0,0,0,0,0,0,0,0,0,0,0,0,0,0,0,0,0,0
0,0,0,0,0,0,0,0,0,0,0,0,0,0,0,0,0,0,0,0,0,0,0,0,0,0,0,0
0,0,0,0,0,0,0,0,0,0,0,0,0,0,0,0,0,0,0,0,0,0,0,0,0,0,0,0
0,0,0,0,0,0,0,0,0,0,0,0,0,0,0,0,0,0,0,0,0,0,0,0,0,0,0,0
0,0,0,0,0,0,0,0,0,0,0,0,0,0,0,0,0,0,0,0,0,0,0,0,0,0,0,0
0,0,0,0,0,0,0,0,0,0,0,0,0,0,0,0,0,0,0,0,0,0,0,0,0,0,0,0
0,0,0,0,0,0,0,0,0,0,0,0,0,0,0,0,0,0,0,0,0,0,0,0,0,0,0,0
0,0,0,0,0,0,0,0,0,0,0,0,0,0,0,0,0,0,0,0,0,0,0,0,0,0,0,0
0,0,0,0,0,0,0,0,0,0,0,0,0,0,0,0,0,0,0,0,0,0,0,0,0,0,0,0
0,0,0,0,0,0,0,0,0,0,0,0,0,0,0,0,0,0,0,0,0,0,0,0,0,0,0,0
0,0,0,0,0,0,0,0,0,0,0,0,0,0,0,0,0,0,0,0,0,0,0,0,0,0,0,0
0,0,0,0,0,0,0,0,0,0,0,0,0,0,0,0,0,0,0,0,0,0,0,0,0,0,0,0
0,0,0,0,0,0,0,0,0,0,0,0,0,0,0,0,0,0,0,0,0,0,0,0,0,0,0,0
0,0,0,0,0,0,0,0,0,0,0,0,0,0,0,0,0,0,0,0,0,0,0,0,0,0,0,0
0,0,0,0,0,0,0,0,0,0,0,0,0,0,0,0,0,0,0,0,0,0,0,0,0,0,0,0
0,0,0,0,0,0,0,0,0,0,0,0,0,0,0,0,0,0,0,0,0,0,0,0,0,0,0,0
0,0,0,0,0,0,0,0,0,0,0,0,0,0,0,0,0,0,0,0,0,0,0,0,0,0,0,0
0,0,0,0,0,0,0,0,0,0,0,0,0,0,0,0,0,0,0,0,0,0,0,0,0,0,0,0
0,0,0,0,0,0,0,0,0,0,0,0,0,0,0,0,0,0,0,0,0,0,0,0,0,0,0,0
0,0,0,0,0,0,0,0,0,0,0,0,0,0,0,0,0,0,0,0,0,0,0,0,0,0,0,0
0,0,0,0,0,0,0,0,0,0,0,0,0,0,0,0,0,0,0,0,0,0,0,0,0,0,0,0
0,0,0,0,0,0,0,0,0,0,0,0,0,0,0,0,98,61,61,100,0,0,0,0,0,0,0,0
:endlayer
layer: 28
0,0,0,0,0,0,0,0,0,0,0,0,0,0,0,0,0,0,0,0,0,0,0,0,0,0,0,0
0,0,0,0,0,0,0,0,0,0,0,0,0,0,0,0,0,0,0,0,0,0,0,0,0,0,0,0
0,0,0,0,0,0,0,0,0,0,0,0,0,0,0,0,0,0,0,0,0,0,0,0,0,0,0,0
0,0,0,0,0,0,0,0,0,0,0,0,0,0,0,0,0,0,0,0,0,0,0,0,0,0,0,0
0,0,0,0,0,0,0,0,0,0,0,0,0,0,0,0,0,0,0,0,0,0,0,0,0,0,0,0
0,0,0,0,0,0,0,0,0,0,0,0,0,0,0,0,0,0,0,0,0,0,0,0,0,0,0,0
0,0,0,0,0,0,0,0,0,0,0,0,0,0,0,0,0,0,0,0,0,0,0,0,0,0,0,0
0,0,0,0,0,0,0,0,0,0,0,0,0,0,0,0,0,0,0,0,0,0,0,0,0,0,0,0
0,0,0,0,0,0,0,0,0,0,0,0,0,0,0,0,0,0,0,0,0,0,0,0,0,0,0,0
0,0,0,0,0,0,0,0,0,0,0,0,0,0,0,0,0,0,0,0,0,0,0,0,0,0,0,0
0,0,0,0,0,0,0,0,0,0,0,0,0,0,0,0,0,0,0,0,0,0,0,0,0,0,0,0
0,0,0,0,0,0,0,0,0,0,0,0,0,0,0,0,0,0,0,0,0,0,0,0,0,0,0,0
0,0,0,0,0,0,0,0,0,0,0,0,0,0,0,0,0,0,0,0,0,0,0,0,0,0,0,0
0,0,0,0,0,0,0,0,0,0,0,0,0,0,0,0,0,0,0,0,0,0,0,0,0,0,0,0
0,0,0,0,0,0,0,0,0,0,0,0,0,0,0,0,0,0,0,0,0,0,0,0,0,0,0,0
0,0,0,0,0,0,0,0,0,0,0,0,0,0,0,0,0,0,0,0,0,0,0,0,0,0,0,0
0,0,0,0,0,0,0,0,0,0,0,0,0,0,0,0,0,0,0,0,0,0,0,0,0,0,0,0
0,0,0,0,0,0,0,0,0,0,0,0,0,0,0,0,0,0,0,0,0,0,0,0,0,0,0,0
0,0,0,0,0,0,0,0,0,0,0,0,0,0,0,0,0,0,0,0,0,0,0,0,0,0,0,0
0,0,0,0,0,0,0,0,0,0,0,0,0,0,0,0,0,0,0,0,0,0,0,0,0,0,0,0
0,0,0,0,0,0,0,0,0,0,0,0,0,0,0,0,0,0,0,0,0,0,0,0,0,0,0,0
0,0,0,0,0,0,0,0,0,0,0,0,0,0,0,0,0,0,0,0,0,0,0,0,0,0,0,0
0,0,0,0,0,0,0,0,0,0,0,0,0,0,0,0,0,0,0,0,0,0,0,0,0,0,0,0
0,0,0,0,0,0,0,0,0,0,0,0,0,0,0,0,0,0,0,0,0,0,0,0,0,0,0,0
0,0,0,0,0,0,0,0,0,0,0,0,0,0,98,61,61,61,61,61,61,100,0,0,0,0,0,0
:endlayer
layer: 29
0,0,0,0,0,0,0,0,0,0,0,0,0,0,0,0,0,0,0,0,0,0,0,0,0,0,0,0
0,0,0,0,0,0,0,0,0,0,0,0,0,0,0,0,0,0,0,0,0,0,0,0,0,0,0,0
0,0,0,0,0,0,0,0,0,0,0,0,0,0,0,0,0,0,0,0,0,0,0,0,0,0,0,0
0,0,0,0,0,0,0,0,0,0,0,0,0,0,0,0,0,0,0,0,0,0,0,0,0,0,0,0
0,0,0,0,0,0,0,0,0,0,0,0,0,0,0,0,0,0,0,0,0,0,0,0,0,0,0,0
0,0,0,0,0,0,0,0,0,0,0,0,0,0,0,0,0,0,0,0,0,0,0,0,0,0,0,0
0,0,0,0,0,0,0,0,0,0,0,0,0,0,0,0,0,0,0,0,0,0,0,0,0,0,0,0
0,0,0,0,0,0,0,0,0,0,0,0,0,0,0,0,0,0,0,0,0,0,0,0,0,0,0,0
0,0,0,0,0,0,0,0,0,0,0,0,0,0,0,0,0,0,0,0,0,0,0,0,0,0,0,0
0,0,0,0,0,0,0,0,0,0,0,0,0,0,0,0,0,0,0,0,0,0,0,0,0,0,0,0
0,0,0,0,0,0,0,0,0,0,0,0,0,0,0,0,0,0,0,0,0,0,0,0,0,0,0,0
0,0,0,0,0,0,0,0,0,0,0,0,0,0,0,0,0,0,0,0,0,0,0,0,0,0,0,0
0,0,0,0,0,0,0,0,0,0,0,0,0,0,0,0,0,0,0,0,0,0,0,0,0,0,0,0
0,0,0,0,0,0,0,0,0,0,0,0,0,0,0,0,0,0,0,0,0,0,0,0,0,0,0,0
0,0,0,0,0,0,0,0,0,0,0,0,0,0,0,0,0,0,0,0,0,0,0,0,0,0,0,0
0,0,0,0,0,0,0,0,0,0,0,0,0,0,0,0,0,0,0,0,0,0,0,0,0,0,0,0
0,0,0,0,0,0,0,0,0,0,0,0,0,0,0,0,0,0,0,0,0,0,0,0,0,0,0,0
0,0,0,0,0,0,0,0,0,0,0,0,0,0,0,0,0,0,0,0,0,0,0,0,0,0,0,0
0,0,0,0,0,0,0,0,0,0,0,0,0,0,0,0,0,0,0,0,0,0,0,0,0,0,0,0
0,0,0,0,0,0,0,0,0,0,0,0,0,0,0,0,0,0,0,0,0,0,0,0,0,0,0,0
0,0,0,0,0,0,0,0,0,0,0,0,0,0,0,0,0,0,0,0,0,0,0,0,0,0,0,0
0,0,0,0,0,0,0,0,0,0,0,0,0,0,0,0,0,0,0,0,0,0,0,0,0,0,0,0
0,0,0,0,0,0,0,0,0,0,0,0,0,0,0,0,0,0,0,0,0,0,0,0,0,0,0,0
0,0,0,0,0,0,0,0,0,0,0,0,0,0,0,0,0,0,0,0,0,0,0,0,0,0,0,0
0,0,0,0,0,0,0,0,0,0,0,0,0,0,104,61,61,61,61,61,61,105,0,0,0,0,0,0
:endlayer
layer: 30
0,0,0,0,0,0,0,0,0,0,0,0,0,0,0,0,0,0,0,0,0,0,0,0,0,0,0,0
0,0,0,0,0,0,0,0,0,0,0,0,0,0,0,0,0,0,0,0,0,0,0,0,0,0,0,0
0,0,0,0,0,0,0,0,0,0,0,0,0,0,0,0,0,0,0,0,0,0,0,0,0,0,0,0
0,0,0,0,0,0,0,0,0,0,0,0,0,0,0,0,0,0,0,0,0,0,0,0,0,0,0,0
0,0,0,0,0,0,0,0,0,0,0,0,0,0,0,0,0,0,0,0,0,0,0,0,0,0,0,0
0,0,0,0,0,0,0,0,0,0,0,0,0,0,0,0,0,0,0,0,0,0,0,0,0,0,0,0
0,0,0,0,0,0,0,0,0,0,0,0,0,0,0,0,0,0,0,0,0,0,0,0,0,0,0,0
0,0,0,0,0,0,0,0,0,0,0,0,0,0,0,0,0,0,0,0,0,0,0,0,0,0,0,0
0,0,0,0,0,0,0,0,0,0,0,0,0,0,0,0,0,0,0,0,0,0,0,0,0,0,0,0
0,0,0,0,0,0,0,0,0,0,0,0,0,0,0,0,0,0,0,0,0,0,0,0,0,0,0,0
0,0,0,0,0,0,0,0,0,0,0,0,0,0,0,0,0,0,0,0,0,0,0,0,0,0,0,0
0,0,0,0,0,0,0,0,0,0,0,0,0,0,0,0,0,0,0,0,0,0,0,0,0,0,0,0
0,0,0,0,0,0,0,0,0,0,0,0,0,0,0,0,0,0,0,0,0,0,0,0,0,0,0,0
0,0,0,0,0,0,0,0,0,0,0,0,0,0,0,0,0,0,0,0,0,0,0,0,0,0,0,0
0,0,0,0,0,0,0,0,0,0,0,0,0,0,0,0,0,0,0,0,0,0,0,0,0,0,0,0
0,0,0,0,0,0,0,0,0,0,0,0,0,0,0,0,0,0,0,0,0,0,0,0,0,0,0,0
0,0,0,0,0,0,0,0,0,0,0,0,0,0,0,0,0,0,0,0,0,0,0,0,0,0,0,0
0,0,0,0,0,0,0,0,0,0,0,0,0,0,0,0,0,0,0,0,0,0,0,0,0,0,0,0
0,0,0,0,0,0,0,0,0,0,0,0,0,0,0,0,0,0,0,0,0,0,0,0,0,0,0,0
0,0,0,0,0,0,0,0,0,0,0,0,0,0,0,0,0,0,0,0,0,0,0,0,0,0,0,0
0,0,0,0,0,0,0,0,0,0,0,0,0,0,0,0,0,0,0,0,0,0,0,0,0,0,0,0
0,0,0,0,0,0,0,0,0,0,0,0,0,0,0,0,0,0,0,0,0,0,0,0,0,0,0,0
0,0,0,0,0,0,0,0,0,0,0,0,0,0,0,0,0,0,0,0,0,0,0,0,0,0,0,0
0,0,0,0,0,0,0,0,0,0,0,0,0,0,0,0,0,0,0,0,0,0,0,0,0,0,0,0
0,0,0,0,0,0,0,0,0,0,0,0,0,0,0,0,104,61,61,105,0,0,0,0,0,0,0,0
:endlayer
layer: 31
0,0,0,0,0,0,0,0,0,0,0,0,0,0,0,0,0,0,0,0,0,0,0,0,0,0,0,0
0,0,0,0,0,0,0,0,0,0,0,0,0,0,0,0,0,0,0,0,0,0,0,0,0,0,0,0
0,0,0,0,0,0,0,0,0,0,0,0,0,0,0,0,0,0,0,0,0,0,0,0,0,0,0,0
0,0,0,0,0,0,0,0,0,0,0,0,0,0,0,0,0,0,0,0,0,0,0,0,0,0,0,0
0,0,0,0,0,0,0,0,0,0,0,0,0,0,0,0,0,0,0,0,0,0,0,0,0,0,0,0
0,0,0,0,0,0,0,0,0,0,0,0,0,0,0,0,0,0,0,0,0,0,0,0,0,0,0,0
0,0,0,0,0,0,0,0,0,0,0,0,0,0,0,0,0,0,0,0,0,0,0,0,0,0,0,0
0,0,0,0,0,0,0,0,0,0,0,0,0,0,0,0,0,0,0,0,0,0,0,0,0,0,0,0
0,0,0,0,0,0,0,0,0,0,0,0,0,0,0,0,0,0,0,0,0,0,0,0,0,0,0,0
0,0,0,0,0,0,0,0,0,0,0,0,0,0,0,0,0,0,0,0,0,0,0,0,0,0,0,0
0,0,0,0,0,0,0,0,0,0,0,0,0,0,0,0,0,0,0,0,0,0,0,0,0,0,0,0
0,0,0,0,0,0,0,0,0,0,0,0,0,0,0,0,0,0,0,0,0,0,0,0,0,0,0,0
0,0,0,0,0,0,0,0,0,0,0,0,0,0,0,0,0,0,0,0,0,0,0,0,0,0,0,0
0,0,0,0,0,0,0,0,0,0,0,0,0,0,0,0,0,0,0,0,0,0,0,0,0,0,0,0
0,0,0,0,0,0,0,0,0,0,0,0,0,0,0,0,0,0,0,0,0,0,0,0,0,0,0,0
0,0,0,0,0,0,0,0,0,0,0,0,0,0,0,0,0,0,0,0,0,0,0,0,0,0,0,0
0,0,0,0,0,0,0,0,0,0,0,0,0,0,0,0,0,0,0,0,0,0,0,0,0,0,0,0
0,0,0,0,0,0,0,0,0,0,0,0,0,0,0,0,0,0,0,0,0,0,0,0,0,0,0,0
0,0,0,0,0,0,0,0,0,0,0,0,0,0,0,0,0,0,0,0,0,0,0,0,0,0,0,0
0,0,0,0,0,0,0,0,0,0,0,0,0,0,0,0,0,0,0,0,0,0,0,0,0,0,0,0
0,0,0,0,0,0,0,0,0,0,0,0,0,0,0,0,0,0,0,0,0,0,0,0,0,0,0,0
0,0,0,0,0,0,0,0,0,0,0,0,0,0,0,0,0,0,0,0,0,0,0,0,0,0,0,0
0,0,0,0,0,0,0,0,0,0,0,0,0,0,0,0,0,0,0,0,0,0,0,0,0,0,0,0
0,0,0,0,0,0,0,0,0,0,0,0,0,0,0,0,0,0,0,0,0,0,0,0,0,0,0,0
0,0,0,0,0,0,0,0,0,0,0,0,0,0,0,0,0,61,61,0,0,0,0,0,0,0,0,0
:endlayer
layer: 32
0,0,0,0,0,0,0,0,0,0,0,0,0,0,0,0,0,0,0,0,0,0,0,0,0,0,0,0
0,0,0,0,0,0,0,0,0,0,0,0,0,0,0,0,0,0,0,0,0,0,0,0,0,0,0,0
0,0,0,0,0,0,0,0,0,0,0,0,0,0,0,0,0,0,0,0,0,0,0,0,0,0,0,0
0,0,0,0,0,0,0,0,0,0,0,0,0,0,0,0,0,0,0,0,0,0,0,0,0,0,0,0
0,0,0,0,0,0,0,0,0,0,0,0,0,0,0,0,0,0,0,0,0,0,0,0,0,0,0,0
0,0,0,0,0,0,0,0,0,0,0,0,0,0,0,0,0,0,0,0,0,0,0,0,0,0,0,0
0,0,0,0,0,0,0,0,0,0,0,0,0,0,0,0,0,0,0,0,0,0,0,0,0,0,0,0
0,0,0,0,0,0,0,0,0,0,0,0,0,0,0,0,0,0,0,0,0,0,0,0,0,0,0,0
0,0,0,0,0,0,0,0,0,0,0,0,0,0,0,0,0,0,0,0,0,0,0,0,0,0,0,0
0,0,0,0,0,0,0,0,0,0,0,0,0,0,0,0,0,0,0,0,0,0,0,0,0,0,0,0
0,0,0,0,0,0,0,0,0,0,0,0,0,0,0,0,0,0,0,0,0,0,0,0,0,0,0,0
0,0,0,0,0,0,0,0,0,0,0,0,0,0,0,0,0,0,0,0,0,0,0,0,0,0,0,0
0,0,0,0,0,0,0,0,0,0,0,0,0,0,0,0,0,0,0,0,0,0,0,0,0,0,0,0
0,0,0,0,0,0,0,0,0,0,0,0,0,0,0,0,0,0,0,0,0,0,0,0,0,0,0,0
0,0,0,0,0,0,0,0,0,0,0,0,0,0,0,0,0,0,0,0,0,0,0,0,0,0,0,0
0,0,0,0,0,0,0,0,0,0,0,0,0,0,0,0,0,0,0,0,0,0,0,0,0,0,0,0
0,0,0,0,0,0,0,0,0,0,0,0,0,0,0,0,0,0,0,0,0,0,0,0,0,0,0,0
0,0,0,0,0,0,0,0,0,0,0,0,0,0,0,0,0,0,0,0,0,0,0,0,0,0,0,0
0,0,0,0,0,0,0,0,0,0,0,0,0,0,0,0,0,0,0,0,0,0,0,0,0,0,0,0
0,0,0,0,0,0,0,0,0,0,0,0,0,0,0,0,0,0,0,0,0,0,0,0,0,0,0,0
0,0,0,0,0,0,0,0,0,0,0,0,0,0,0,0,0,0,0,0,0,0,0,0,0,0,0,0
0,0,0,0,0,0,0,0,0,0,0,0,0,0,0,0,0,0,0,0,0,0,0,0,0,0,0,0
0,0,0,0,0,0,0,0,0,0,0,0,0,0,0,0,0,0,0,0,0,0,0,0,0,0,0,0
0,0,0,0,0,0,0,0,0,0,0,0,0,0,0,0,0,0,0,0,0,0,0,0,0,0,0,0
0,0,0,0,0,0,0,0,0,0,0,0,0,0,0,0,0,104,105,0,0,0,0,0,0,0,0,0
:endlayer

#### RULES ####
rule:
plugin=vanillaBlocks
number=1
data:
tag:
TAG=10={
TAG=8=blockName{stone}
TAG=3=meta{0}
TAG=3=buildPass{0}
}
:endtag
:enddata
:endrule

rule:
plugin=vanillaBlocks
number=2
data:
tag:
TAG=10={
TAG=8=blockName{dirt}
TAG=3=meta{0}
TAG=3=buildPass{0}
}
:endtag
:enddata
:endrule

rule:
plugin=vanillaBlocks
number=3
data:
tag:
TAG=10={
TAG=8=blockName{iron_ore}
TAG=3=meta{0}
TAG=3=buildPass{0}
}
:endtag
:enddata
:endrule

rule:
plugin=vanillaBlocks
number=4
data:
tag:
TAG=10={
TAG=8=blockName{gravel}
TAG=3=meta{0}
TAG=3=buildPass{1}
}
:endtag
:enddata
:endrule

rule:
plugin=vanillaBlocks
number=5
data:
tag:
TAG=10={
TAG=8=blockName{coal_ore}
TAG=3=meta{0}
TAG=3=buildPass{0}
}
:endtag
:enddata
:endrule

rule:
plugin=vanillaBlocks
number=6
data:
tag:
TAG=10={
TAG=8=blockName{stonebrick}
TAG=3=meta{1}
TAG=3=buildPass{0}
}
:endtag
:enddata
:endrule

rule:
plugin=vanillaBlocks
number=7
data:
tag:
TAG=10={
TAG=8=blockName{redstone_wire}
TAG=3=meta{0}
TAG=3=buildPass{2}
}
:endtag
:enddata
:endrule

rule:
plugin=vanillaBlocks
number=8
data:
tag:
TAG=10={
TAG=8=blockName{stonebrick}
TAG=3=meta{0}
TAG=3=buildPass{0}
}
:endtag
:enddata
:endrule

rule:
plugin=vanillaBlocks
number=9
data:
tag:
TAG=10={
TAG=8=blockName{tnt}
TAG=3=meta{0}
TAG=3=buildPass{0}
}
:endtag
:enddata
:endrule

rule:
plugin=vanillaBlocks
number=10
data:
tag:
TAG=10={
TAG=8=blockName{trapped_chest}
TAG=3=meta{3}
TAG=3=buildPass{0}
}
:endtag
:enddata
:endrule

rule:
plugin=vanillaBlocks
number=11
data:
tag:
TAG=10={
TAG=8=blockName{carpet}
TAG=3=meta{14}
TAG=3=buildPass{0}
}
:endtag
:enddata
:endrule

rule:
plugin=vanillaBlocks
number=12
data:
tag:
TAG=10={
TAG=8=blockName{vine}
TAG=3=meta{8}
TAG=3=buildPass{1}
}
:endtag
:enddata
:endrule

rule:
plugin=vanillaBlocks
number=13
data:
tag:
TAG=10={
TAG=8=blockName{stone_brick_stairs}
TAG=3=meta{4}
TAG=3=buildPass{0}
}
:endtag
:enddata
:endrule

rule:
plugin=vanillaBlocks
number=14
data:
tag:
TAG=10={
TAG=8=blockName{vine}
TAG=3=meta{4}
TAG=3=buildPass{1}
}
:endtag
:enddata
:endrule

rule:
plugin=vanillaBlocks
number=15
data:
tag:
TAG=10={
TAG=8=blockName{vine}
TAG=3=meta{1}
TAG=3=buildPass{1}
}
:endtag
:enddata
:endrule

rule:
plugin=vanillaBlocks
number=16
data:
tag:
TAG=10={
TAG=8=blockName{tripwire_hook}
TAG=3=meta{4}
TAG=3=buildPass{3}
}
:endtag
:enddata
:endrule

rule:
plugin=vanillaBlocks
number=17
data:
tag:
TAG=10={
TAG=8=blockName{tripwire}
TAG=3=meta{0}
TAG=3=buildPass{3}
}
:endtag
:enddata
:endrule

rule:
plugin=vanillaBlocks
number=18
data:
tag:
TAG=10={
TAG=8=blockName{tripwire_hook}
TAG=3=meta{6}
TAG=3=buildPass{3}
}
:endtag
:enddata
:endrule

rule:
plugin=vanillaBlocks
number=19
data:
tag:
TAG=10={
TAG=8=blockName{stone_brick_stairs}
TAG=3=meta{5}
TAG=3=buildPass{0}
}
:endtag
:enddata
:endrule

rule:
plugin=awAdvancedSpawner
number=20
data:
tag:
TAG=10={
TAG=10=teData{
TAG=8=ExtraType{}
TAG=8=id{Skull}
TAG=1=SkullType{0}
TAG=1=Rot{12}
TAG=3=z{245}
TAG=3=y{58}
TAG=3=x{161}
}
TAG=8=blockName{skull}
TAG=3=meta{1}
TAG=3=buildPass{1}
}
:endtag
:enddata
:endrule

rule:
plugin=vanillaBlocks
number=21
data:
tag:
TAG=10={
TAG=8=blockName{stone_brick_stairs}
TAG=3=meta{6}
TAG=3=buildPass{0}
}
:endtag
:enddata
:endrule

rule:
plugin=vanillaBlocks
number=22
data:
tag:
TAG=10={
TAG=8=blockName{stone_brick_stairs}
TAG=3=meta{0}
TAG=3=buildPass{0}
}
:endtag
:enddata
:endrule

rule:
plugin=vanillaBlocks
number=23
data:
tag:
TAG=10={
TAG=8=blockName{vine}
TAG=3=meta{2}
TAG=3=buildPass{1}
}
:endtag
:enddata
:endrule

rule:
plugin=vanillaBlocks
number=24
data:
tag:
TAG=10={
TAG=8=blockName{unpowered_repeater}
TAG=3=meta{3}
TAG=3=buildPass{3}
}
:endtag
:enddata
:endrule

rule:
plugin=vanillaInventory
number=25
data:
tag:
TAG=10={
TAG=3=lootLevel{0}
TAG=10=teData{
TAG=9=Items{
TAG=10={
TAG=2=id{373}
TAG=2=Damage{16456}
TAG=1=Count{1}
TAG=1=Slot{4}
}
}
TAG=8=id{Trap}
}
TAG=8=blockName{dispenser}
TAG=3=meta{4}
TAG=3=buildPass{0}
}
:endtag
:enddata
:endrule

rule:
plugin=vanillaInventory
number=26
data:
tag:
TAG=10={
TAG=3=lootLevel{0}
TAG=10=teData{
TAG=9=Items{
TAG=10={
TAG=2=id{373}
TAG=2=Damage{16452}
TAG=1=Count{1}
TAG=1=Slot{4}
}
}
TAG=8=id{Trap}
}
TAG=8=blockName{dispenser}
TAG=3=meta{4}
TAG=3=buildPass{0}
}
:endtag
:enddata
:endrule

rule:
plugin=vanillaBlocks
number=27
data:
tag:
TAG=10={
TAG=8=blockName{stone_brick_stairs}
TAG=3=meta{7}
TAG=3=buildPass{0}
}
:endtag
:enddata
:endrule

rule:
plugin=awAdvancedSpawner
number=28
data:
tag:
TAG=10={
TAG=10=teData{
TAG=8=ExtraType{}
TAG=8=id{Skull}
TAG=1=SkullType{0}
TAG=1=Rot{12}
TAG=3=z{237}
TAG=3=y{59}
TAG=3=x{161}
}
TAG=8=blockName{skull}
TAG=3=meta{1}
TAG=3=buildPass{1}
}
:endtag
:enddata
:endrule

rule:
plugin=awAdvancedSpawner
number=29
data:
tag:
TAG=10={
TAG=10=teData{
TAG=8=ExtraType{}
TAG=8=id{Skull}
TAG=1=SkullType{0}
TAG=1=Rot{3}
TAG=3=z{239}
TAG=3=y{59}
TAG=3=x{158}
}
TAG=8=blockName{skull}
TAG=3=meta{1}
TAG=3=buildPass{1}
}
:endtag
:enddata
:endrule

rule:
plugin=awAdvancedSpawner
number=30
data:
tag:
TAG=10={
TAG=10=teData{
TAG=8=ExtraType{}
TAG=8=id{Skull}
TAG=1=SkullType{0}
TAG=1=Rot{3}
TAG=3=z{241}
TAG=3=y{59}
TAG=3=x{158}
}
TAG=8=blockName{skull}
TAG=3=meta{1}
TAG=3=buildPass{1}
}
:endtag
:enddata
:endrule

rule:
plugin=awAdvancedSpawner
number=31
data:
tag:
TAG=10={
TAG=10=teData{
TAG=8=ExtraType{}
TAG=8=id{Skull}
TAG=1=SkullType{0}
TAG=1=Rot{11}
TAG=3=z{241}
TAG=3=y{59}
TAG=3=x{161}
}
TAG=8=blockName{skull}
TAG=3=meta{1}
TAG=3=buildPass{1}
}
:endtag
:enddata
:endrule

rule:
plugin=awAdvancedSpawner
number=32
data:
tag:
TAG=10={
TAG=10=teData{
TAG=8=ExtraType{}
TAG=8=id{Skull}
TAG=1=SkullType{0}
TAG=1=Rot{5}
TAG=3=z{243}
TAG=3=y{59}
TAG=3=x{158}
}
TAG=8=blockName{skull}
TAG=3=meta{1}
TAG=3=buildPass{1}
}
:endtag
:enddata
:endrule

rule:
plugin=awAdvancedSpawner
number=33
data:
tag:
TAG=10={
TAG=10=teData{
TAG=8=ExtraType{}
TAG=8=id{Skull}
TAG=1=SkullType{0}
TAG=1=Rot{13}
TAG=3=z{243}
TAG=3=y{59}
TAG=3=x{161}
}
TAG=8=blockName{skull}
TAG=3=meta{1}
TAG=3=buildPass{1}
}
:endtag
:enddata
:endrule

rule:
plugin=awAdvancedSpawner
number=34
data:
tag:
TAG=10={
TAG=10=teData{
TAG=8=ExtraType{}
TAG=8=id{Skull}
TAG=1=SkullType{0}
TAG=1=Rot{4}
TAG=3=z{247}
TAG=3=y{59}
TAG=3=x{158}
}
TAG=8=blockName{skull}
TAG=3=meta{1}
TAG=3=buildPass{1}
}
:endtag
:enddata
:endrule

rule:
plugin=awAdvancedSpawner
number=35
data:
tag:
TAG=10={
TAG=10=teData{
TAG=8=ExtraType{}
TAG=8=id{Skull}
TAG=1=SkullType{0}
TAG=1=Rot{12}
TAG=3=z{247}
TAG=3=y{59}
TAG=3=x{161}
}
TAG=8=blockName{skull}
TAG=3=meta{1}
TAG=3=buildPass{1}
}
:endtag
:enddata
:endrule

rule:
plugin=awAdvancedSpawner
number=36
data:
tag:
TAG=10={
TAG=10=teData{
TAG=8=ExtraType{}
TAG=8=id{Skull}
TAG=1=SkullType{0}
TAG=1=Rot{4}
TAG=3=z{249}
TAG=3=y{59}
TAG=3=x{158}
}
TAG=8=blockName{skull}
TAG=3=meta{1}
TAG=3=buildPass{1}
}
:endtag
:enddata
:endrule

rule:
plugin=awAdvancedSpawner
number=37
data:
tag:
TAG=10={
TAG=10=teData{
TAG=8=ExtraType{}
TAG=8=id{Skull}
TAG=1=SkullType{0}
TAG=1=Rot{11}
TAG=3=z{249}
TAG=3=y{59}
TAG=3=x{161}
}
TAG=8=blockName{skull}
TAG=3=meta{1}
TAG=3=buildPass{1}
}
:endtag
:enddata
:endrule

rule:
plugin=vanillaBlocks
number=38
data:
tag:
TAG=10={
TAG=8=blockName{grass}
TAG=3=meta{0}
TAG=3=buildPass{0}
}
:endtag
:enddata
:endrule

rule:
plugin=vanillaBlocks
number=39
data:
tag:
TAG=10={
TAG=8=blockName{stone_slab}
TAG=3=meta{8}
TAG=3=buildPass{0}
}
:endtag
:enddata
:endrule

rule:
plugin=vanillaBlocks
number=40
data:
tag:
TAG=10={
TAG=8=blockName{stone_slab}
TAG=3=meta{9}
TAG=3=buildPass{0}
}
:endtag
:enddata
:endrule

rule:
plugin=vanillaBlocks
number=41
data:
tag:
TAG=10={
TAG=8=blockName{wooden_slab}
TAG=3=meta{9}
TAG=3=buildPass{0}
}
:endtag
:enddata
:endrule

rule:
plugin=vanillaBlocks
number=42
data:
tag:
TAG=10={
TAG=8=blockName{redstone_torch}
TAG=3=meta{2}
TAG=3=buildPass{3}
}
:endtag
:enddata
:endrule

rule:
plugin=vanillaBlocks
number=43
data:
tag:
TAG=10={
TAG=8=blockName{redstone_wire}
TAG=3=meta{15}
TAG=3=buildPass{2}
}
:endtag
:enddata
:endrule

rule:
plugin=vanillaBlocks
number=44
data:
tag:
TAG=10={
TAG=8=blockName{stone_slab}
TAG=3=meta{15}
TAG=3=buildPass{0}
}
:endtag
:enddata
:endrule

rule:
plugin=vanillaBlocks
number=45
data:
tag:
TAG=10={
TAG=8=blockName{redstone_wire}
TAG=3=meta{14}
TAG=3=buildPass{2}
}
:endtag
:enddata
:endrule

rule:
plugin=vanillaBlocks
number=46
data:
tag:
TAG=10={
TAG=8=blockName{powered_repeater}
TAG=3=meta{3}
TAG=3=buildPass{3}
}
:endtag
:enddata
:endrule

rule:
plugin=vanillaBlocks
number=47
data:
tag:
TAG=10={
TAG=8=blockName{tallgrass}
TAG=3=meta{1}
TAG=3=buildPass{0}
}
:endtag
:enddata
:endrule

rule:
plugin=vanillaDoors
number=48
data:
tag:
TAG=10={
TAG=1=sideFlag{9}
TAG=8=blockName{wooden_door}
TAG=3=meta{2}
TAG=3=buildPass{1}
}
:endtag
:enddata
:endrule

rule:
plugin=vanillaDoors
number=49
data:
tag:
TAG=10={
TAG=1=sideFlag{8}
TAG=8=blockName{wooden_door}
TAG=3=meta{2}
TAG=3=buildPass{1}
}
:endtag
:enddata
:endrule

rule:
plugin=vanillaBlocks
number=50
data:
tag:
TAG=10={
TAG=8=blockName{quartz_block}
TAG=3=meta{2}
TAG=3=buildPass{0}
}
:endtag
:enddata
:endrule

rule:
plugin=vanillaBlocks
number=51
data:
tag:
TAG=10={
TAG=8=blockName{wooden_slab}
TAG=3=meta{1}
TAG=3=buildPass{0}
}
:endtag
:enddata
:endrule

rule:
plugin=vanillaBlocks
number=52
data:
tag:
TAG=10={
TAG=8=blockName{oak_stairs}
TAG=3=meta{0}
TAG=3=buildPass{0}
}
:endtag
:enddata
:endrule

rule:
plugin=vanillaInventory
number=53
data:
tag:
TAG=10={
TAG=3=lootLevel{1}
TAG=8=blockName{chest}
TAG=3=meta{4}
TAG=3=buildPass{0}
}
:endtag
:enddata
:endrule

rule:
plugin=vanillaInventory
number=54
data:
tag:
TAG=10={
TAG=3=lootLevel{1}
TAG=8=blockName{chest}
TAG=3=meta{2}
TAG=3=buildPass{0}
}
:endtag
:enddata
:endrule

rule:
plugin=vanillaBlocks
number=55
data:
tag:
TAG=10={
TAG=8=blockName{flower_pot}
TAG=3=meta{1}
TAG=3=buildPass{1}
}
:endtag
:enddata
:endrule

rule:
plugin=vanillaBlocks
number=56
data:
tag:
TAG=10={
TAG=8=blockName{oak_stairs}
TAG=3=meta{2}
TAG=3=buildPass{0}
}
:endtag
:enddata
:endrule

rule:
plugin=vanillaInventory
number=57
data:
tag:
TAG=10={
TAG=3=lootLevel{1}
TAG=8=blockName{chest}
TAG=3=meta{2}
TAG=3=buildPass{0}
}
:endtag
:enddata
:endrule

rule:
plugin=vanillaInventory
number=58
data:
tag:
TAG=10={
TAG=3=lootLevel{1}
TAG=8=blockName{chest}
TAG=3=meta{3}
TAG=3=buildPass{0}
}
:endtag
:enddata
:endrule

rule:
plugin=vanillaBlocks
number=59
data:
tag:
TAG=10={
TAG=8=blockName{oak_stairs}
TAG=3=meta{1}
TAG=3=buildPass{0}
}
:endtag
:enddata
:endrule

rule:
plugin=vanillaBlocks
number=60
data:
tag:
TAG=10={
TAG=8=blockName{lever}
TAG=3=meta{4}
TAG=3=buildPass{3}
}
:endtag
:enddata
:endrule

rule:
plugin=vanillaBlocks
number=61
data:
tag:
TAG=10={
TAG=8=blockName{quartz_block}
TAG=3=meta{1}
TAG=3=buildPass{0}
}
:endtag
:enddata
:endrule

rule:
plugin=vanillaDoors
number=62
data:
tag:
TAG=10={
TAG=1=sideFlag{9}
TAG=8=blockName{wooden_door}
TAG=3=meta{3}
TAG=3=buildPass{1}
}
:endtag
:enddata
:endrule

rule:
plugin=vanillaDoors
number=63
data:
tag:
TAG=10={
TAG=1=sideFlag{8}
TAG=8=blockName{wooden_door}
TAG=3=meta{3}
TAG=3=buildPass{1}
}
:endtag
:enddata
:endrule

rule:
plugin=vanillaInventory
number=64
data:
tag:
TAG=10={
TAG=3=lootLevel{1}
TAG=8=blockName{chest}
TAG=3=meta{3}
TAG=3=buildPass{0}
}
:endtag
:enddata
:endrule

rule:
plugin=vanillaInventory
number=65
data:
tag:
TAG=10={
TAG=3=lootLevel{1}
TAG=8=blockName{chest}
TAG=3=meta{5}
TAG=3=buildPass{0}
}
:endtag
:enddata
:endrule

rule:
plugin=vanillaBlocks
number=66
data:
tag:
TAG=10={
TAG=8=blockName{wooden_button}
TAG=3=meta{1}
TAG=3=buildPass{3}
}
:endtag
:enddata
:endrule

rule:
plugin=vanillaBlocks
number=67
data:
tag:
TAG=10={
TAG=8=blockName{sticky_piston}
TAG=3=meta{11}
TAG=3=buildPass{1}
}
:endtag
:enddata
:endrule

rule:
plugin=vanillaBlocks
number=68
data:
tag:
TAG=10={
TAG=8=blockName{piston_head}
TAG=3=meta{11}
TAG=3=buildPass{1}
}
:endtag
:enddata
:endrule

rule:
plugin=vanillaBlocks
number=69
data:
tag:
TAG=10={
TAG=8=blockName{piston_head}
TAG=3=meta{13}
TAG=3=buildPass{1}
}
:endtag
:enddata
:endrule

rule:
plugin=vanillaBlocks
number=70
data:
tag:
TAG=10={
TAG=8=blockName{piston_head}
TAG=3=meta{10}
TAG=3=buildPass{1}
}
:endtag
:enddata
:endrule

rule:
plugin=vanillaBlocks
number=71
data:
tag:
TAG=10={
TAG=8=blockName{sticky_piston}
TAG=3=meta{10}
TAG=3=buildPass{1}
}
:endtag
:enddata
:endrule

rule:
plugin=vanillaBlocks
number=72
data:
tag:
TAG=10={
TAG=8=blockName{noteblock}
TAG=3=meta{0}
TAG=3=buildPass{0}
}
:endtag
:enddata
:endrule

rule:
plugin=vanillaBlocks
number=73
data:
tag:
TAG=10={
TAG=8=blockName{sticky_piston}
TAG=3=meta{13}
TAG=3=buildPass{1}
}
:endtag
:enddata
:endrule

rule:
plugin=vanillaBlocks
number=74
data:
tag:
TAG=10={
TAG=8=blockName{redstone_wire}
TAG=3=meta{13}
TAG=3=buildPass{2}
}
:endtag
:enddata
:endrule

rule:
plugin=vanillaDoors
number=75
data:
tag:
TAG=10={
TAG=1=sideFlag{0}
TAG=8=blockName{wooden_door}
TAG=3=meta{0}
TAG=3=buildPass{1}
}
:endtag
:enddata
:endrule

rule:
plugin=vanillaDoors
number=76
data:
tag:
TAG=10={
TAG=1=sideFlag{0}
TAG=8=blockName{wooden_door}
TAG=3=meta{8}
TAG=3=buildPass{1}
}
:endtag
:enddata
:endrule

rule:
plugin=vanillaBlocks
number=77
data:
tag:
TAG=10={
TAG=8=blockName{light_weighted_pressure_plate}
TAG=3=meta{0}
TAG=3=buildPass{0}
}
:endtag
:enddata
:endrule

rule:
plugin=vanillaDoors
number=78
data:
tag:
TAG=10={
TAG=1=sideFlag{0}
TAG=8=blockName{wooden_door}
TAG=3=meta{0}
TAG=3=buildPass{1}
}
:endtag
:enddata
:endrule

rule:
plugin=vanillaDoors
number=79
data:
tag:
TAG=10={
TAG=1=sideFlag{0}
TAG=8=blockName{wooden_door}
TAG=3=meta{8}
TAG=3=buildPass{1}
}
:endtag
:enddata
:endrule

rule:
plugin=vanillaBlocks
number=80
data:
tag:
TAG=10={
TAG=8=blockName{stone_brick_stairs}
TAG=3=meta{1}
TAG=3=buildPass{0}
}
:endtag
:enddata
:endrule

rule:
plugin=vanillaBlocks
number=81
data:
tag:
TAG=10={
TAG=8=blockName{redstone_wire}
TAG=3=meta{9}
TAG=3=buildPass{2}
}
:endtag
:enddata
:endrule

rule:
plugin=vanillaBlocks
number=82
data:
tag:
TAG=10={
TAG=8=blockName{powered_repeater}
TAG=3=meta{14}
TAG=3=buildPass{3}
}
:endtag
:enddata
:endrule

rule:
plugin=vanillaBlocks
number=83
data:
tag:
TAG=10={
TAG=8=blockName{powered_repeater}
TAG=3=meta{12}
TAG=3=buildPass{3}
}
:endtag
:enddata
:endrule

rule:
plugin=vanillaBlocks
number=84
data:
tag:
TAG=10={
TAG=8=blockName{redstone_wire}
TAG=3=meta{6}
TAG=3=buildPass{2}
}
:endtag
:enddata
:endrule

rule:
plugin=vanillaBlocks
number=85
data:
tag:
TAG=10={
TAG=8=blockName{redstone_wire}
TAG=3=meta{10}
TAG=3=buildPass{2}
}
:endtag
:enddata
:endrule

rule:
plugin=vanillaBlocks
number=86
data:
tag:
TAG=10={
TAG=8=blockName{redstone_wire}
TAG=3=meta{7}
TAG=3=buildPass{2}
}
:endtag
:enddata
:endrule

rule:
plugin=vanillaBlocks
number=87
data:
tag:
TAG=10={
TAG=8=blockName{redstone_wire}
TAG=3=meta{12}
TAG=3=buildPass{2}
}
:endtag
:enddata
:endrule

rule:
plugin=vanillaBlocks
number=88
data:
tag:
TAG=10={
TAG=8=blockName{wool}
TAG=3=meta{14}
TAG=3=buildPass{0}
}
:endtag
:enddata
:endrule

rule:
plugin=vanillaBlocks
number=89
data:
tag:
TAG=10={
TAG=8=blockName{glass}
TAG=3=meta{0}
TAG=3=buildPass{0}
}
:endtag
:enddata
:endrule

rule:
plugin=vanillaBlocks
number=90
data:
tag:
TAG=10={
TAG=8=blockName{redstone_wire}
TAG=3=meta{11}
TAG=3=buildPass{2}
}
:endtag
:enddata
:endrule

rule:
plugin=vanillaBlocks
number=91
data:
tag:
TAG=10={
TAG=8=blockName{redstone_wire}
TAG=3=meta{8}
TAG=3=buildPass{2}
}
:endtag
:enddata
:endrule

rule:
plugin=vanillaBlocks
number=92
data:
tag:
TAG=10={
TAG=8=blockName{nether_brick_stairs}
TAG=3=meta{0}
TAG=3=buildPass{0}
}
:endtag
:enddata
:endrule

rule:
plugin=vanillaBlocks
number=93
data:
tag:
TAG=10={
TAG=8=blockName{stone_brick_stairs}
TAG=3=meta{3}
TAG=3=buildPass{0}
}
:endtag
:enddata
:endrule

rule:
plugin=vanillaBlocks
number=94
data:
tag:
TAG=10={
TAG=8=blockName{stone_brick_stairs}
TAG=3=meta{2}
TAG=3=buildPass{0}
}
:endtag
:enddata
:endrule

rule:
plugin=vanillaBlocks
number=95
data:
tag:
TAG=10={
TAG=8=blockName{glowstone}
TAG=3=meta{0}
TAG=3=buildPass{0}
}
:endtag
:enddata
:endrule

rule:
plugin=vanillaBlocks
number=96
data:
tag:
TAG=10={
TAG=8=blockName{powered_repeater}
TAG=3=meta{2}
TAG=3=buildPass{3}
}
:endtag
:enddata
:endrule

rule:
plugin=vanillaBlocks
number=97
data:
tag:
TAG=10={
TAG=8=blockName{stone_slab}
TAG=3=meta{6}
TAG=3=buildPass{0}
}
:endtag
:enddata
:endrule

rule:
plugin=vanillaBlocks
number=98
data:
tag:
TAG=10={
TAG=8=blockName{quartz_stairs}
TAG=3=meta{4}
TAG=3=buildPass{0}
}
:endtag
:enddata
:endrule

rule:
plugin=vanillaBlocks
number=99
data:
tag:
TAG=10={
TAG=8=blockName{fence}
TAG=3=meta{0}
TAG=3=buildPass{0}
}
:endtag
:enddata
:endrule

rule:
plugin=vanillaBlocks
number=100
data:
tag:
TAG=10={
TAG=8=blockName{quartz_stairs}
TAG=3=meta{5}
TAG=3=buildPass{0}
}
:endtag
:enddata
:endrule

rule:
plugin=vanillaBlocks
number=101
data:
tag:
TAG=10={
TAG=8=blockName{nether_brick}
TAG=3=meta{0}
TAG=3=buildPass{0}
}
:endtag
:enddata
:endrule

rule:
plugin=vanillaBlocks
number=102
data:
tag:
TAG=10={
TAG=8=blockName{double_stone_slab}
TAG=3=meta{6}
TAG=3=buildPass{0}
}
:endtag
:enddata
:endrule

rule:
plugin=vanillaBlocks
number=103
data:
tag:
TAG=10={
TAG=8=blockName{quartz_block}
TAG=3=meta{0}
TAG=3=buildPass{0}
}
:endtag
:enddata
:endrule

rule:
plugin=vanillaBlocks
number=104
data:
tag:
TAG=10={
TAG=8=blockName{quartz_stairs}
TAG=3=meta{0}
TAG=3=buildPass{0}
}
:endtag
:enddata
:endrule

rule:
plugin=vanillaBlocks
number=105
data:
tag:
TAG=10={
TAG=8=blockName{quartz_stairs}
TAG=3=meta{1}
TAG=3=buildPass{0}
}
:endtag
:enddata
:endrule

rule:
plugin=vanillaBlocks
number=106
data:
tag:
TAG=10={
TAG=8=blockName{double_stone_slab}
TAG=3=meta{7}
TAG=3=buildPass{0}
}
:endtag
:enddata
:endrule

rule:
plugin=vanillaBlocks
number=107
data:
tag:
TAG=10={
TAG=8=blockName{quartz_block}
TAG=3=meta{3}
TAG=3=buildPass{0}
}
:endtag
:enddata
:endrule

rule:
plugin=vanillaBlocks
number=108
data:
tag:
TAG=10={
TAG=8=blockName{nether_brick_stairs}
TAG=3=meta{1}
TAG=3=buildPass{0}
}
:endtag
:enddata
:endrule

rule:
plugin=vanillaBlocks
number=109
data:
tag:
TAG=10={
TAG=8=blockName{nether_brick_stairs}
TAG=3=meta{4}
TAG=3=buildPass{0}
}
:endtag
:enddata
:endrule

rule:
plugin=vanillaBlocks
number=110
data:
tag:
TAG=10={
TAG=8=blockName{stone_slab}
TAG=3=meta{14}
TAG=3=buildPass{0}
}
:endtag
:enddata
:endrule

rule:
plugin=vanillaBlocks
number=111
data:
tag:
TAG=10={
TAG=8=blockName{nether_brick_stairs}
TAG=3=meta{5}
TAG=3=buildPass{0}
}
:endtag
:enddata
:endrule

rule:
plugin=vanillaBlocks
number=112
data:
tag:
TAG=10={
TAG=8=blockName{quartz_stairs}
TAG=3=meta{7}
TAG=3=buildPass{0}
}
:endtag
:enddata
:endrule

rule:
plugin=vanillaBlocks
number=113
data:
tag:
TAG=10={
TAG=8=blockName{stone_slab}
TAG=3=meta{7}
TAG=3=buildPass{0}
}
:endtag
:enddata
:endrule

rule:
plugin=vanillaBlocks
number=114
data:
tag:
TAG=10={
TAG=8=blockName{quartz_stairs}
TAG=3=meta{2}
TAG=3=buildPass{0}
}
:endtag
:enddata
:endrule

#### ENTITIES ####
