# Ancient Warfare Structure Template File
# auto-generated structure file. created on: 4/21/2014 at: 17:14:7
# Lines beginning with # denote comments

header:
version=2.0
name=tower1
size=15,19,13
offset=7,1,12
:endheader

#### VALIDATION ####
validation:
type=ground
survival=false
worldGenEnabled=true
unique=false
preserveBlocks=false
selectionWeight=1
clusterValue=35
minDuplicateDistance=20
dimensionWhiteList=false
dimensionList=
biomeWhiteList=false
biomeList=
leveling=18
fill=6
border=6
validTargetBlocks=clay,lapis_ore,lit_redstone_ore,stone,carpet,tile.bop.mud,gravel,coal_block,diamond_ore,ice,snow,netherrack,tile.bop.longGrass,tile.bop.generic.hard_dirt,tile.bop.redRocks,dirt,redstone_ore,mycelium,tile.bop.holyStone,sand,grass,tile.bop.ash,iron_ore,snow_layer,soul_sand,stained_hardened_clay,coal_ore,gold_ore,tile.bop.generic.hard_sand
data:
:enddata
:endvalidation

#### LAYERS ####
layer: 0
1,1,1,1,1,1,1,1,1,1,1,1,1,1,1
1,2,2,2,2,1,1,1,1,1,2,2,2,2,1
1,2,3,2,2,2,2,2,2,2,2,3,3,2,1
1,2,3,3,4,4,4,4,4,4,4,3,3,2,1
1,2,2,4,3,3,3,3,3,3,3,4,2,2,1
1,1,1,2,3,3,3,3,3,3,3,2,1,1,1
1,1,1,2,3,3,3,3,3,3,3,2,1,1,1
1,1,1,2,3,3,3,3,3,3,3,2,1,1,1
1,2,2,4,4,4,4,4,4,4,4,4,2,2,1
1,2,3,3,2,4,4,4,4,4,2,3,3,2,1
1,2,3,3,2,4,4,4,4,4,2,3,3,2,1
1,2,2,2,2,1,1,1,1,1,2,2,2,2,1
1,1,1,1,1,1,1,1,1,1,1,1,1,1,1
:endlayer
layer: 1
0,0,0,0,0,0,0,0,0,0,0,0,0,0,0
0,2,2,2,2,0,0,0,0,0,2,2,2,2,0
0,2,18,0,2,2,2,2,2,2,2,0,17,2,0
0,2,16,15,0,0,0,0,0,0,0,14,13,2,0
0,2,2,2,0,0,0,0,0,0,0,2,2,2,0
0,0,0,2,0,0,0,0,0,0,0,2,0,0,0
0,0,0,2,0,0,0,0,0,0,0,2,0,0,0
0,0,0,2,0,0,0,0,0,0,0,2,0,0,0
0,2,2,12,0,2,11,0,10,2,0,9,2,2,0
0,2,7,8,2,4,0,0,0,4,2,8,7,2,0
0,2,0,5,2,6,0,0,0,0,2,5,0,2,0
0,2,2,2,2,0,0,0,0,0,2,2,2,2,0
0,0,0,0,0,0,0,0,0,0,0,0,0,0,0
:endlayer
layer: 2
0,0,0,0,0,0,0,0,0,0,0,0,0,0,0
0,2,2,2,2,0,0,0,0,0,2,2,2,2,0
0,2,0,0,2,2,2,2,2,2,2,0,0,2,0
0,2,0,24,0,0,0,0,0,0,0,23,0,2,0
0,2,2,2,0,0,0,0,0,0,0,2,2,2,0
0,0,0,2,0,0,0,0,0,0,0,2,0,0,0
0,0,0,2,0,0,0,0,0,0,0,2,0,0,0
0,0,0,2,0,0,0,0,0,0,0,2,0,0,0
0,2,2,22,0,2,0,0,0,2,0,21,2,2,0
0,2,20,0,2,4,0,0,0,4,2,0,19,2,0
0,2,0,0,2,0,0,0,0,0,2,0,0,2,0
0,2,2,2,2,0,0,0,0,0,2,2,2,2,0
0,0,0,0,0,0,0,0,0,0,0,0,0,0,0
:endlayer
layer: 3
0,0,0,0,0,0,0,0,0,0,0,0,0,0,0
0,2,2,2,2,0,0,0,0,0,2,2,2,2,0
0,2,0,0,2,2,2,2,2,2,2,0,0,2,0
0,2,0,2,0,28,0,0,0,28,0,2,0,2,0
0,2,2,2,0,0,0,0,0,0,0,2,2,2,0
0,0,0,2,0,0,0,0,0,0,0,2,0,0,0
0,0,0,2,0,0,0,0,0,0,0,2,0,0,0
0,0,0,2,0,27,0,0,0,27,0,2,0,0,0
0,2,2,0,2,2,0,0,0,2,2,0,2,2,0
0,2,0,25,2,4,0,0,0,4,2,26,0,2,0
0,2,8,0,2,26,0,0,0,25,2,0,8,2,0
0,2,2,2,2,0,0,0,0,0,2,2,2,2,0
0,0,0,0,0,0,0,0,0,0,0,0,0,0,0
:endlayer
layer: 4
0,0,0,0,0,0,0,0,0,0,0,0,0,0,0
0,2,2,2,2,0,0,0,0,0,2,2,2,2,0
0,2,0,0,2,2,2,2,2,2,2,0,0,2,0
0,2,0,2,30,0,0,0,0,0,29,2,0,2,0
0,2,2,2,32,0,0,0,0,0,32,2,2,2,0
0,0,0,2,0,0,0,0,0,0,0,2,0,0,0
0,0,0,2,0,0,0,0,0,0,0,2,0,0,0
0,0,0,2,0,0,0,0,0,0,0,2,0,0,0
0,2,2,2,2,2,31,31,31,2,2,2,2,2,0
0,2,0,0,2,4,4,4,4,4,2,0,0,2,0
0,2,0,19,2,30,0,0,0,29,2,20,0,2,0
0,2,2,2,2,0,0,0,0,0,2,2,2,2,0
0,0,0,0,0,0,0,0,0,0,0,0,0,0,0
:endlayer
layer: 5
0,0,0,0,0,0,0,0,0,0,0,0,0,0,0
0,2,2,2,2,0,0,0,0,0,2,2,2,2,0
0,2,3,3,3,3,3,3,3,3,3,3,3,2,0
0,2,3,3,2,34,34,34,34,34,2,3,3,2,0
0,2,2,2,2,34,34,34,34,34,2,2,2,2,0
0,0,0,3,34,34,34,34,34,34,34,3,0,0,0
0,0,0,3,34,34,34,34,34,34,34,3,0,0,0
0,0,0,3,34,34,34,34,34,34,34,3,0,0,0
0,2,2,2,3,3,3,3,3,3,3,2,2,2,0
0,2,0,33,3,3,3,3,3,3,2,33,0,2,0
0,2,0,0,2,2,2,2,2,2,2,0,0,2,0
0,2,2,2,2,0,0,0,0,0,2,2,2,2,0
0,0,0,0,0,0,0,0,0,0,0,0,0,0,0
:endlayer
layer: 6
0,0,0,0,0,0,0,0,0,0,0,0,0,0,0
0,2,2,2,2,0,0,0,0,0,2,2,2,2,0
0,2,0,0,2,2,38,2,38,2,2,0,0,2,0
0,2,0,0,0,0,0,0,0,0,0,0,0,2,0
0,2,2,2,2,0,0,0,0,0,2,2,2,2,0
0,0,0,2,0,0,0,0,0,0,0,2,0,0,0
0,0,0,37,0,0,0,0,0,0,0,36,0,0,0
0,0,0,2,0,0,0,0,0,0,0,2,0,0,0
0,2,2,2,2,0,0,0,0,0,2,2,2,2,0
0,2,20,0,0,0,0,0,0,0,0,0,19,2,0
0,2,0,0,2,2,35,2,35,2,2,0,0,2,0
0,2,2,2,2,0,0,0,0,0,2,2,2,2,0
0,0,0,0,0,0,0,0,0,0,0,0,0,0,0
:endlayer
layer: 7
0,0,0,0,0,0,0,0,0,0,0,0,0,0,0
0,2,2,39,2,0,0,0,0,0,2,39,2,2,0
0,2,0,0,2,2,0,2,0,2,2,0,0,2,0
0,39,0,0,0,0,0,0,0,0,0,0,0,39,0
0,2,2,2,2,0,0,0,0,0,2,2,2,2,0
0,0,0,2,0,0,0,0,0,0,0,2,0,0,0
0,0,0,0,0,0,0,0,0,0,0,0,0,0,0
0,0,0,2,0,0,0,0,0,0,0,2,0,0,0
0,2,2,2,2,0,0,0,0,0,2,2,2,2,0
0,39,0,0,0,0,0,0,0,0,0,0,0,39,0
0,2,8,0,2,2,0,2,0,2,2,0,8,2,0
0,2,2,39,2,0,0,0,0,0,2,39,2,2,0
0,0,0,0,0,0,0,0,0,0,0,0,0,0,0
:endlayer
layer: 8
0,0,0,0,0,0,0,0,0,0,0,0,0,0,0
0,2,2,40,2,0,0,0,0,0,2,40,2,2,0
0,2,0,0,2,2,40,2,40,2,2,0,0,2,0
0,40,0,0,2,28,0,0,0,28,2,0,0,40,0
0,2,2,2,2,0,0,0,0,0,2,2,2,2,0
0,0,0,2,0,0,0,0,0,0,0,2,0,0,0
0,0,0,40,0,0,0,0,0,0,0,40,0,0,0
0,0,0,2,0,0,0,0,0,0,0,2,0,0,0
0,2,2,2,2,0,0,0,0,0,2,2,2,2,0
0,40,0,0,2,27,0,0,0,27,2,0,0,40,0
0,2,0,19,2,2,40,2,40,2,2,20,0,2,0
0,2,2,40,2,0,0,0,0,0,2,40,2,2,0
0,0,0,0,0,0,0,0,0,0,0,0,0,0,0
:endlayer
layer: 9
0,0,0,0,0,0,0,0,0,0,0,0,0,0,0
0,2,2,2,2,0,0,0,0,0,2,2,2,2,0
0,2,0,0,2,2,2,2,2,2,2,0,0,2,0
0,2,0,0,2,0,0,0,0,0,2,0,0,2,0
0,2,2,2,2,0,0,0,0,0,2,2,2,2,0
0,0,0,2,0,0,0,0,0,0,0,2,0,0,0
0,0,0,2,0,0,0,0,0,0,0,2,0,0,0
0,0,0,2,0,0,0,0,0,0,0,2,0,0,0
0,2,2,2,2,0,0,0,0,0,2,2,2,2,0
0,2,0,33,2,0,0,0,0,0,2,33,0,2,0
0,2,0,0,2,2,2,2,2,2,2,0,0,2,0
0,2,2,2,2,0,0,0,0,0,2,2,2,2,0
0,0,0,0,0,0,0,0,0,0,0,0,0,0,0
:endlayer
layer: 10
0,0,0,0,0,0,0,0,0,0,0,0,0,0,0
0,2,2,2,2,0,0,0,0,0,2,2,2,2,0
0,2,5,5,2,2,2,2,2,2,2,7,7,2,0
0,2,5,5,2,41,41,41,41,3,42,7,7,2,0
0,2,2,2,2,41,41,41,41,41,2,2,2,2,0
0,0,0,2,41,41,41,41,41,41,41,2,0,0,0
0,0,0,2,41,41,41,41,41,41,41,2,0,0,0
0,0,0,2,41,41,41,41,41,41,41,2,0,0,0
0,2,2,2,2,41,41,41,41,41,2,2,2,2,0
0,2,20,0,39,41,41,41,41,41,39,0,19,2,0
0,2,0,0,2,2,2,2,2,2,2,0,0,2,0
0,2,2,2,2,0,0,0,0,0,2,2,2,2,0
0,0,0,0,0,0,0,0,0,0,0,0,0,0,0
:endlayer
layer: 11
0,0,0,0,0,0,0,0,0,0,0,0,0,0,0
0,2,2,38,2,0,0,0,0,0,2,38,2,2,0
0,2,0,0,2,2,38,2,38,2,2,0,33,2,0
0,37,0,0,0,0,0,0,0,43,44,43,0,36,0
0,2,2,2,2,0,0,0,0,0,2,2,2,2,0
0,0,0,2,0,0,0,0,0,0,0,2,0,0,0
0,0,0,37,0,0,0,0,0,0,0,36,0,0,0
0,0,0,2,0,0,0,0,0,0,0,2,0,0,0
0,2,2,2,2,0,0,0,0,0,2,2,2,2,0
0,37,0,0,0,0,0,0,0,0,0,0,0,36,0
0,2,5,0,2,2,35,2,35,2,2,0,5,2,0
0,2,2,35,2,0,0,0,0,0,2,35,2,2,0
0,0,0,0,0,0,0,0,0,0,0,0,0,0,0
:endlayer
layer: 12
0,0,0,0,0,0,0,0,0,0,0,0,0,0,0
0,2,2,0,2,0,0,0,0,0,2,0,2,2,0
0,2,0,0,2,2,0,2,0,2,2,20,0,2,0
0,0,0,0,0,0,0,28,0,0,45,0,0,0,0
0,2,2,2,2,0,0,0,0,0,2,2,2,2,0
0,0,0,2,0,0,0,0,0,0,0,2,0,0,0
0,0,0,0,0,0,0,0,0,0,0,0,0,0,0
0,0,0,2,0,0,0,0,0,0,0,2,0,0,0
0,2,2,2,2,0,0,0,0,0,2,2,2,2,0
0,0,0,0,0,0,0,27,0,0,0,0,0,0,0
0,2,0,0,2,2,0,2,0,2,2,0,0,2,0
0,2,2,0,2,0,0,0,0,0,2,0,2,2,0
0,0,0,0,0,0,0,0,0,0,0,0,0,0,0
:endlayer
layer: 13
0,0,0,0,0,0,0,0,0,0,0,0,0,0,0
0,2,2,40,2,0,0,0,0,0,2,40,2,2,0
0,2,26,0,2,2,40,2,40,2,2,0,25,2,0
0,40,0,0,2,0,0,0,0,0,2,8,0,40,0
0,2,2,2,2,0,0,0,0,0,2,2,2,2,0
0,0,0,2,0,0,0,0,0,0,0,2,0,0,0
0,0,0,40,0,0,0,0,0,0,0,40,0,0,0
0,0,0,2,0,0,0,0,0,0,0,2,0,0,0
0,2,2,2,2,0,0,0,0,0,2,2,2,2,0
0,40,0,0,2,0,0,0,0,0,2,0,0,40,0
0,2,26,0,2,2,40,2,40,2,2,0,25,2,0
0,2,2,40,2,0,0,0,0,0,2,40,2,2,0
0,0,0,0,0,0,0,0,0,0,0,0,0,0,0
:endlayer
layer: 14
0,0,0,0,0,0,0,0,0,0,0,0,0,0,0
0,2,2,2,2,31,40,31,40,31,2,2,2,2,0
0,2,0,0,2,3,3,3,3,3,2,0,0,2,0
0,2,0,0,2,0,0,0,0,0,2,0,19,2,0
0,2,2,2,2,0,0,0,0,0,2,2,2,2,0
0,0,29,3,0,0,0,0,0,0,0,3,30,0,0
0,0,40,3,0,0,0,0,0,0,0,3,40,0,0
0,0,29,3,0,0,0,0,0,0,0,3,30,0,0
0,2,2,2,2,0,0,0,0,0,2,2,2,2,0
0,2,0,0,2,0,0,0,0,0,2,0,0,2,0
0,2,0,0,2,3,3,3,3,3,2,0,0,2,0
0,2,2,2,2,32,40,32,40,32,2,2,2,2,0
0,0,0,0,0,0,0,0,0,0,0,0,0,0,0
:endlayer
layer: 15
0,31,40,40,31,0,0,0,0,0,31,40,40,31,0
29,3,3,3,3,2,2,2,2,2,3,3,3,3,30
40,3,0,0,2,2,2,2,2,2,2,0,33,3,40
40,3,0,0,2,2,2,2,2,2,2,0,0,3,40
29,3,2,2,2,2,2,2,2,2,2,2,2,3,30
0,32,2,2,2,2,2,2,2,2,2,2,2,32,0
0,0,2,2,2,2,2,2,2,2,2,2,2,0,0
0,31,2,2,2,2,2,2,2,2,2,2,2,31,0
29,3,2,2,2,2,2,2,2,2,2,2,2,3,30
40,3,0,0,2,2,2,2,2,2,2,0,0,3,40
40,3,0,0,2,2,2,2,2,2,2,0,0,3,40
29,3,3,3,3,2,2,2,2,2,3,3,3,3,30
0,32,40,40,32,0,0,0,0,0,32,0,0,32,0
:endlayer
layer: 16
0,2,2,2,2,0,0,0,0,0,2,2,2,2,0
2,39,39,39,39,2,2,2,2,2,39,39,39,39,2
2,39,39,39,39,0,0,0,0,0,39,39,0,39,2
2,39,39,39,39,0,0,0,0,0,39,0,0,39,2
2,39,39,39,0,0,0,0,0,0,0,39,39,39,2
0,2,2,0,0,0,0,0,0,0,0,0,2,2,0
0,0,2,0,0,0,0,0,0,0,0,0,2,0,0
0,2,2,0,0,0,0,0,0,0,0,0,2,2,0
2,39,39,39,0,0,0,0,0,0,0,39,39,39,2
2,39,39,39,39,0,0,0,0,0,0,39,39,39,2
2,39,39,39,39,0,0,0,0,0,39,39,39,39,2
2,39,39,39,39,2,2,2,2,2,39,39,39,39,2
0,2,2,2,2,0,0,0,0,0,2,2,2,2,0
:endlayer
layer: 17
0,2,42,2,42,0,0,0,0,0,42,42,42,42,0
42,26,0,0,0,42,39,42,39,42,0,0,0,25,42
2,0,0,0,0,28,0,0,0,28,0,0,0,0,2
42,0,0,0,0,0,0,0,0,0,0,0,0,0,42
2,0,0,0,0,0,0,0,0,0,0,0,0,0,2
0,42,2,26,0,0,0,0,0,0,0,25,42,42,0
0,0,39,0,0,0,0,0,0,0,0,0,39,0,0
0,42,2,26,0,0,0,0,0,0,0,25,2,42,0
2,0,0,0,0,0,0,0,0,0,0,0,0,0,2
42,0,0,0,0,0,0,0,0,0,0,0,0,0,42
2,0,0,0,0,27,0,0,0,27,0,0,0,0,2
42,26,0,0,0,2,39,2,39,2,0,0,0,25,42
0,2,42,2,42,0,0,0,0,0,42,2,42,2,0
:endlayer
layer: 18
0,39,0,39,0,0,0,0,0,0,0,39,0,39,0
0,0,0,0,0,39,0,0,0,39,0,0,0,0,0
39,0,0,0,0,0,0,0,0,0,0,0,0,0,39
0,0,0,0,0,0,0,0,0,0,0,0,0,0,0
39,0,0,0,0,0,0,0,0,0,0,0,0,0,39
0,0,39,0,0,0,0,0,0,0,0,0,39,0,0
0,0,0,0,0,0,0,0,0,0,0,0,0,0,0
0,0,39,0,0,0,0,0,0,0,0,0,39,0,0
39,0,0,0,0,0,0,0,0,0,0,0,0,0,39
0,0,0,0,0,0,0,0,0,0,0,0,0,0,0
39,0,0,0,0,0,0,0,0,0,0,0,0,0,39
0,0,0,0,0,39,0,0,0,39,0,0,0,0,0
0,39,0,39,0,0,0,0,0,0,0,39,0,39,0
:endlayer

#### RULES ####
rule:
plugin=vanillaBlocks
number=1
data:
tag:
TAG=10={
TAG=8=blockName{grass}
TAG=3=meta{0}
TAG=3=buildPass{0}
}
:endtag
:enddata
:endrule

rule:
plugin=vanillaBlocks
number=2
data:
tag:
TAG=10={
TAG=8=blockName{stonebrick}
TAG=3=meta{0}
TAG=3=buildPass{0}
}
:endtag
:enddata
:endrule

rule:
plugin=vanillaBlocks
number=3
data:
tag:
TAG=10={
TAG=8=blockName{double_stone_slab}
TAG=3=meta{0}
TAG=3=buildPass{0}
}
:endtag
:enddata
:endrule

rule:
plugin=vanillaBlocks
number=4
data:
tag:
TAG=10={
TAG=8=blockName{stone}
TAG=3=meta{0}
TAG=3=buildPass{0}
}
:endtag
:enddata
:endrule

rule:
plugin=vanillaBlocks
number=5
data:
tag:
TAG=10={
TAG=8=blockName{wooden_slab}
TAG=3=meta{0}
TAG=3=buildPass{0}
}
:endtag
:enddata
:endrule

rule:
plugin=vanillaBlocks
number=6
data:
tag:
TAG=10={
TAG=8=blockName{stone_button}
TAG=3=meta{3}
TAG=3=buildPass{3}
}
:endtag
:enddata
:endrule

rule:
plugin=vanillaBlocks
number=7
data:
tag:
TAG=10={
TAG=8=blockName{double_wooden_slab}
TAG=3=meta{0}
TAG=3=buildPass{0}
}
:endtag
:enddata
:endrule

rule:
plugin=vanillaBlocks
number=8
data:
tag:
TAG=10={
TAG=8=blockName{oak_stairs}
TAG=3=meta{2}
TAG=3=buildPass{0}
}
:endtag
:enddata
:endrule

rule:
plugin=vanillaDoors
number=9
data:
tag:
TAG=10={
TAG=1=sideFlag{8}
TAG=8=blockName{wooden_door}
TAG=3=meta{0}
TAG=3=buildPass{1}
}
:endtag
:enddata
:endrule

rule:
plugin=vanillaBlocks
number=10
data:
tag:
TAG=10={
TAG=8=blockName{lever}
TAG=3=meta{2}
TAG=3=buildPass{3}
}
:endtag
:enddata
:endrule

rule:
plugin=vanillaBlocks
number=11
data:
tag:
TAG=10={
TAG=8=blockName{stone_button}
TAG=3=meta{1}
TAG=3=buildPass{3}
}
:endtag
:enddata
:endrule

rule:
plugin=vanillaDoors
number=12
data:
tag:
TAG=10={
TAG=1=sideFlag{9}
TAG=8=blockName{wooden_door}
TAG=3=meta{2}
TAG=3=buildPass{1}
}
:endtag
:enddata
:endrule

rule:
plugin=vanillaInventory
number=13
data:
tag:
TAG=10={
TAG=3=lootLevel{2}
TAG=8=blockName{chest}
TAG=3=meta{4}
TAG=3=buildPass{0}
}
:endtag
:enddata
:endrule

rule:
plugin=vanillaDoors
number=14
data:
tag:
TAG=10={
TAG=1=sideFlag{8}
TAG=8=blockName{wooden_door}
TAG=3=meta{7}
TAG=3=buildPass{1}
}
:endtag
:enddata
:endrule

rule:
plugin=vanillaDoors
number=15
data:
tag:
TAG=10={
TAG=1=sideFlag{8}
TAG=8=blockName{wooden_door}
TAG=3=meta{2}
TAG=3=buildPass{1}
}
:endtag
:enddata
:endrule

rule:
plugin=vanillaInventory
number=16
data:
tag:
TAG=10={
TAG=3=lootLevel{2}
TAG=8=blockName{chest}
TAG=3=meta{5}
TAG=3=buildPass{0}
}
:endtag
:enddata
:endrule

rule:
plugin=vanillaInventory
number=17
data:
tag:
TAG=10={
TAG=3=lootLevel{2}
TAG=8=blockName{chest}
TAG=3=meta{4}
TAG=3=buildPass{0}
}
:endtag
:enddata
:endrule

rule:
plugin=vanillaInventory
number=18
data:
tag:
TAG=10={
TAG=3=lootLevel{2}
TAG=8=blockName{chest}
TAG=3=meta{5}
TAG=3=buildPass{0}
}
:endtag
:enddata
:endrule

rule:
plugin=vanillaBlocks
number=19
data:
tag:
TAG=10={
TAG=8=blockName{oak_stairs}
TAG=3=meta{0}
TAG=3=buildPass{0}
}
:endtag
:enddata
:endrule

rule:
plugin=vanillaBlocks
number=20
data:
tag:
TAG=10={
TAG=8=blockName{oak_stairs}
TAG=3=meta{1}
TAG=3=buildPass{0}
}
:endtag
:enddata
:endrule

rule:
plugin=vanillaDoors
number=21
data:
tag:
TAG=10={
TAG=1=sideFlag{0}
TAG=8=blockName{wooden_door}
TAG=3=meta{8}
TAG=3=buildPass{1}
}
:endtag
:enddata
:endrule

rule:
plugin=vanillaDoors
number=22
data:
tag:
TAG=10={
TAG=1=sideFlag{0}
TAG=8=blockName{wooden_door}
TAG=3=meta{1}
TAG=3=buildPass{1}
}
:endtag
:enddata
:endrule

rule:
plugin=vanillaDoors
number=23
data:
tag:
TAG=10={
TAG=1=sideFlag{0}
TAG=8=blockName{wooden_door}
TAG=3=meta{8}
TAG=3=buildPass{1}
}
:endtag
:enddata
:endrule

rule:
plugin=vanillaDoors
number=24
data:
tag:
TAG=10={
TAG=1=sideFlag{0}
TAG=8=blockName{wooden_door}
TAG=3=meta{8}
TAG=3=buildPass{1}
}
:endtag
:enddata
:endrule

rule:
plugin=vanillaBlocks
number=25
data:
tag:
TAG=10={
TAG=8=blockName{torch}
TAG=3=meta{2}
TAG=3=buildPass{1}
}
:endtag
:enddata
:endrule

rule:
plugin=vanillaBlocks
number=26
data:
tag:
TAG=10={
TAG=8=blockName{torch}
TAG=3=meta{1}
TAG=3=buildPass{1}
}
:endtag
:enddata
:endrule

rule:
plugin=vanillaBlocks
number=27
data:
tag:
TAG=10={
TAG=8=blockName{torch}
TAG=3=meta{4}
TAG=3=buildPass{1}
}
:endtag
:enddata
:endrule

rule:
plugin=vanillaBlocks
number=28
data:
tag:
TAG=10={
TAG=8=blockName{torch}
TAG=3=meta{3}
TAG=3=buildPass{1}
}
:endtag
:enddata
:endrule

rule:
plugin=vanillaBlocks
number=29
data:
tag:
TAG=10={
TAG=8=blockName{stone_brick_stairs}
TAG=3=meta{4}
TAG=3=buildPass{0}
}
:endtag
:enddata
:endrule

rule:
plugin=vanillaBlocks
number=30
data:
tag:
TAG=10={
TAG=8=blockName{stone_brick_stairs}
TAG=3=meta{5}
TAG=3=buildPass{0}
}
:endtag
:enddata
:endrule

rule:
plugin=vanillaBlocks
number=31
data:
tag:
TAG=10={
TAG=8=blockName{stone_brick_stairs}
TAG=3=meta{6}
TAG=3=buildPass{0}
}
:endtag
:enddata
:endrule

rule:
plugin=vanillaBlocks
number=32
data:
tag:
TAG=10={
TAG=8=blockName{stone_brick_stairs}
TAG=3=meta{7}
TAG=3=buildPass{0}
}
:endtag
:enddata
:endrule

rule:
plugin=vanillaBlocks
number=33
data:
tag:
TAG=10={
TAG=8=blockName{oak_stairs}
TAG=3=meta{3}
TAG=3=buildPass{0}
}
:endtag
:enddata
:endrule

rule:
plugin=vanillaBlocks
number=34
data:
tag:
TAG=10={
TAG=8=blockName{stone_slab}
TAG=3=meta{8}
TAG=3=buildPass{0}
}
:endtag
:enddata
:endrule

rule:
plugin=vanillaBlocks
number=35
data:
tag:
TAG=10={
TAG=8=blockName{stone_brick_stairs}
TAG=3=meta{2}
TAG=3=buildPass{0}
}
:endtag
:enddata
:endrule

rule:
plugin=vanillaBlocks
number=36
data:
tag:
TAG=10={
TAG=8=blockName{stone_brick_stairs}
TAG=3=meta{0}
TAG=3=buildPass{0}
}
:endtag
:enddata
:endrule

rule:
plugin=vanillaBlocks
number=37
data:
tag:
TAG=10={
TAG=8=blockName{stone_brick_stairs}
TAG=3=meta{1}
TAG=3=buildPass{0}
}
:endtag
:enddata
:endrule

rule:
plugin=vanillaBlocks
number=38
data:
tag:
TAG=10={
TAG=8=blockName{stone_brick_stairs}
TAG=3=meta{3}
TAG=3=buildPass{0}
}
:endtag
:enddata
:endrule

rule:
plugin=vanillaBlocks
number=39
data:
tag:
TAG=10={
TAG=8=blockName{stone_slab}
TAG=3=meta{5}
TAG=3=buildPass{0}
}
:endtag
:enddata
:endrule

rule:
plugin=vanillaBlocks
number=40
data:
tag:
TAG=10={
TAG=8=blockName{stone_slab}
TAG=3=meta{13}
TAG=3=buildPass{0}
}
:endtag
:enddata
:endrule

rule:
plugin=vanillaBlocks
number=41
data:
tag:
TAG=10={
TAG=8=blockName{stone_slab}
TAG=3=meta{0}
TAG=3=buildPass{0}
}
:endtag
:enddata
:endrule

rule:
plugin=vanillaBlocks
number=42
data:
tag:
TAG=10={
TAG=8=blockName{double_stone_slab}
TAG=3=meta{5}
TAG=3=buildPass{0}
}
:endtag
:enddata
:endrule

rule:
plugin=vanillaBlocks
number=43
data:
tag:
TAG=10={
TAG=8=blockName{wooden_pressure_plate}
TAG=3=meta{0}
TAG=3=buildPass{0}
}
:endtag
:enddata
:endrule

rule:
plugin=vanillaDoors
number=44
data:
tag:
TAG=10={
TAG=1=sideFlag{8}
TAG=8=blockName{iron_door}
TAG=3=meta{0}
TAG=3=buildPass{1}
}
:endtag
:enddata
:endrule

rule:
plugin=vanillaDoors
number=45
data:
tag:
TAG=10={
TAG=1=sideFlag{0}
TAG=8=blockName{iron_door}
TAG=3=meta{8}
TAG=3=buildPass{1}
}
:endtag
:enddata
:endrule

#### ENTITIES ####
entity:
plugin=awGates
number=0
data:
position=7,1,9
tag:
TAG=10={
TAG=10=pos1{
TAG=3=z{0}
TAG=3=y{0}
TAG=3=x{1}
}
TAG=1=orientation{2}
TAG=10=pos2{
TAG=3=z{0}
TAG=3=y{2}
TAG=3=x{-1}
}
TAG=8=gateType{gate.verticalIron}
}
:endtag
:enddata
:endentity

entity:
plugin=awNpcOld
number=1
data:
position=3,16,9
tag:
TAG=10={
TAG=5=yOffset{0.5}
TAG=5=xOffset{0.5}
TAG=5=zOffset{0.5}
TAG=5=rotation{73.72693}
TAG=3=npcLevel{2}
TAG=3=npcType{17}
TAG=3=npcTeam{17}
}
:endtag
:enddata
:endentity

entity:
plugin=awNpcOld
number=2
data:
position=12,16,9
tag:
TAG=10={
TAG=5=yOffset{0.5}
TAG=5=xOffset{0.5}
TAG=5=zOffset{0.5}
TAG=5=rotation{-40.272827}
TAG=3=npcLevel{2}
TAG=3=npcType{17}
TAG=3=npcTeam{17}
}
:endtag
:enddata
:endentity

entity:
plugin=awNpcOld
number=3
data:
position=5,1,4
tag:
TAG=10={
TAG=5=yOffset{0.0}
TAG=5=xOffset{0.9225755}
TAG=5=zOffset{0.31270617}
TAG=5=rotation{92.48181}
TAG=3=npcLevel{1}
TAG=3=npcType{16}
TAG=3=npcTeam{17}
}
:endtag
:enddata
:endentity

entity:
plugin=awNpcOld
number=4
data:
position=7,1,4
tag:
TAG=10={
TAG=5=yOffset{0.0}
TAG=5=xOffset{0.682498}
TAG=5=zOffset{0.8665819}
TAG=5=rotation{159.38196}
TAG=3=npcLevel{1}
TAG=3=npcType{16}
TAG=3=npcTeam{17}
}
:endtag
:enddata
:endentity

entity:
plugin=awNpcOld
number=5
data:
position=7,1,5
tag:
TAG=10={
TAG=5=yOffset{0.0}
TAG=5=xOffset{0.3791675}
TAG=5=zOffset{0.8035332}
TAG=5=rotation{108.68225}
TAG=3=npcLevel{0}
TAG=3=npcType{16}
TAG=3=npcTeam{17}
}
:endtag
:enddata
:endentity

entity:
plugin=awNpcOld
number=6
data:
position=5,1,6
tag:
TAG=10={
TAG=5=yOffset{0.0}
TAG=5=xOffset{0.26815754}
TAG=5=zOffset{0.76228213}
TAG=5=rotation{141.23181}
TAG=3=npcLevel{0}
TAG=3=npcType{16}
TAG=3=npcTeam{17}
}
:endtag
:enddata
:endentity

entity:
plugin=awNpcOld
number=7
data:
position=9,1,6
tag:
TAG=10={
TAG=5=yOffset{0.0}
TAG=5=xOffset{0.5}
TAG=5=zOffset{0.5}
TAG=5=rotation{-139.86829}
TAG=3=npcLevel{0}
TAG=3=npcType{16}
TAG=3=npcTeam{17}
}
:endtag
:enddata
:endentity

entity:
plugin=awNpcOld
number=8
data:
position=8,6,7
tag:
TAG=10={
TAG=5=yOffset{0.0}
TAG=5=xOffset{0.5}
TAG=5=zOffset{0.5}
TAG=5=rotation{-171.2185}
TAG=3=npcLevel{2}
TAG=3=npcType{17}
TAG=3=npcTeam{17}
}
:endtag
:enddata
:endentity

entity:
plugin=awNpcOld
number=9
data:
position=6,6,7
tag:
TAG=10={
TAG=5=yOffset{0.0}
TAG=5=xOffset{0.5}
TAG=5=zOffset{0.5}
TAG=5=rotation{177.53125}
TAG=3=npcLevel{2}
TAG=3=npcType{17}
TAG=3=npcTeam{17}
}
:endtag
:enddata
:endentity

entity:
plugin=awNpcOld
number=10
data:
position=8,10,7
tag:
TAG=10={
TAG=5=yOffset{0.5}
TAG=5=xOffset{0.5}
TAG=5=zOffset{0.5}
TAG=5=rotation{179.17883}
TAG=3=npcLevel{2}
TAG=3=npcType{17}
TAG=3=npcTeam{17}
}
:endtag
:enddata
:endentity

entity:
plugin=awNpcOld
number=11
data:
position=6,10,7
tag:
TAG=10={
TAG=5=yOffset{0.5}
TAG=5=xOffset{0.5}
TAG=5=zOffset{0.5}
TAG=5=rotation{-179.92114}
TAG=3=npcLevel{2}
TAG=3=npcType{17}
TAG=3=npcTeam{17}
}
:endtag
:enddata
:endentity

entity:
plugin=awNpcOld
number=12
data:
position=3,16,3
tag:
TAG=10={
TAG=5=yOffset{0.5}
TAG=5=xOffset{0.5}
TAG=5=zOffset{0.5}
TAG=5=rotation{146.02673}
TAG=3=npcLevel{2}
TAG=3=npcType{17}
TAG=3=npcTeam{17}
}
:endtag
:enddata
:endentity

entity:
plugin=awNpcOld
number=13
data:
position=11,16,2
tag:
TAG=10={
TAG=5=yOffset{0.5}
TAG=5=xOffset{0.5}
TAG=5=zOffset{0.5}
TAG=5=rotation{-141.823}
TAG=3=npcLevel{2}
TAG=3=npcType{17}
TAG=3=npcTeam{17}
}
:endtag
:enddata
:endentity

