# Ancient Warfare Structure Template File
# auto-generated structure file. created on: 4/21/2014 at: 17:31:38
# Lines beginning with # denote comments

header:
version=2.0
name=windmill_czarified
size=25,30,16
offset=12,1,15
:endheader

#### VALIDATION ####
validation:
type=ground
survival=true
worldGenEnabled=false
unique=false
preserveBlocks=false
selectionWeight=1
clusterValue=1
minDuplicateDistance=1
dimensionWhiteList=false
dimensionList=
biomeWhiteList=false
biomeList=
leveling=0
fill=0
border=0
validTargetBlocks=clay,lapis_ore,lit_redstone_ore,stone,tile.bop.mud,carpet,gravel,coal_block,diamond_ore,ice,snow,netherrack,tile.bop.generic.hard_dirt,tile.bop.longGrass,tile.bop.redRocks,dirt,redstone_ore,mycelium,tile.bop.holyStone,sand,grass,tile.bop.ash,iron_ore,soul_sand,snow_layer,stained_hardened_clay,coal_ore,gold_ore,tile.bop.generic.hard_sand
data:
:enddata
:endvalidation

#### LAYERS ####
layer: 0
1,1,1,1,1,1,1,1,1,2,2,2,2,2,2,2,1,1,1,1,1,1,1,1,1
1,1,1,1,1,1,1,1,2,2,3,3,3,3,3,2,2,1,1,1,1,1,1,1,1
1,1,1,1,1,1,1,2,2,3,3,3,3,3,3,3,2,2,1,1,1,1,1,1,4
1,1,1,1,1,1,2,2,3,3,3,3,3,3,3,3,3,2,2,1,1,1,1,5,5
1,1,1,1,1,2,2,3,3,3,3,0,0,0,3,3,3,3,2,2,1,5,5,5,5
1,1,1,1,1,2,3,3,3,3,0,0,0,0,0,3,3,3,3,2,1,5,5,1,5
1,1,1,1,1,2,3,3,3,0,0,0,0,0,0,0,3,3,3,2,1,4,1,4,6
1,1,1,1,1,2,3,3,3,0,0,0,7,0,0,0,3,3,3,2,1,5,5,5,5
1,1,1,1,1,2,3,3,3,0,0,0,0,0,0,0,3,3,3,2,1,5,5,1,5
1,1,1,1,1,2,3,3,3,3,0,0,0,0,0,3,3,3,3,2,1,1,1,5,4
1,1,1,1,1,2,2,3,3,3,3,0,0,0,3,3,3,3,2,2,1,5,1,1,4
1,1,1,1,1,1,2,2,3,3,3,3,3,3,3,3,3,2,2,4,1,1,5,8,1
1,1,1,1,1,1,2,2,2,3,3,3,3,3,3,3,2,2,5,5,6,5,5,1,4
1,1,1,1,1,1,1,2,2,2,3,3,3,3,3,2,2,2,1,4,1,1,5,4,5
1,1,1,1,1,1,1,1,1,2,2,2,3,2,2,2,1,6,5,5,4,4,6,1,5
1,1,1,1,1,1,1,1,1,1,1,1,1,4,1,5,5,5,1,5,4,4,4,1,1
:endlayer
layer: 1
0,0,0,0,0,0,0,0,9,10,11,10,10,10,11,10,9,0,0,0,0,0,0,0,0
0,0,0,0,0,0,0,12,10,10,11,13,14,14,11,10,10,12,0,0,0,0,0,0,0
0,0,0,0,0,0,15,10,10,14,0,0,0,0,0,13,10,10,16,0,0,0,0,0,0
0,0,0,0,0,9,10,10,13,0,0,0,0,0,0,0,14,10,10,9,0,0,0,0,0
0,0,0,0,0,10,10,13,0,0,0,17,17,17,0,0,0,14,10,10,0,0,0,0,0
0,0,0,0,0,11,11,0,0,0,17,18,18,18,17,0,0,0,11,11,0,0,0,0,0
0,0,0,0,0,10,13,0,0,17,18,18,18,18,18,17,0,0,14,10,0,0,0,0,0
0,0,0,0,0,10,14,19,0,17,18,18,17,18,18,17,0,0,13,10,0,0,0,0,0
0,0,0,0,0,10,14,0,0,17,18,18,18,18,18,17,0,0,14,10,0,0,0,0,0
0,0,0,0,0,11,11,0,0,0,17,18,18,18,17,0,0,0,11,11,0,0,0,0,0
0,0,0,0,0,10,10,14,0,0,0,17,17,17,0,0,0,13,10,10,0,0,0,0,0
0,0,0,0,0,9,10,10,13,0,0,0,0,0,0,0,14,10,10,9,0,0,0,0,0
0,0,0,0,0,0,15,10,10,14,0,0,0,0,0,14,10,10,16,0,0,0,0,0,0
0,0,0,0,0,0,0,20,10,10,11,0,0,0,11,10,10,20,0,0,0,0,0,0,0
0,0,0,0,0,0,0,0,9,10,11,21,0,22,11,10,9,0,0,0,0,0,0,0,0
0,0,0,0,0,0,0,0,0,0,0,0,0,0,0,0,0,0,0,0,0,0,0,0,0
:endlayer
layer: 2
0,0,0,0,0,0,0,0,0,0,0,10,10,10,0,0,0,0,0,0,0,0,0,0,0
0,0,0,0,0,0,0,0,10,21,11,14,13,13,11,21,10,0,0,0,0,0,0,0,0
0,0,0,0,0,0,0,10,23,0,0,0,0,0,0,0,24,10,0,0,0,0,0,0,0
0,0,0,0,0,0,10,25,0,0,0,0,0,0,0,0,0,25,10,0,0,0,0,0,0
0,0,0,0,0,0,21,0,0,0,0,0,0,0,0,0,0,0,21,0,0,0,0,0,0
0,0,0,0,0,0,11,0,0,0,0,0,0,0,0,0,0,0,11,0,0,0,0,0,0
0,0,0,0,0,10,14,0,0,0,0,0,0,0,0,0,0,0,13,10,0,0,0,0,0
0,0,0,0,0,10,14,19,0,0,10,26,27,0,0,0,0,0,14,10,0,0,0,0,0
0,0,0,0,0,10,14,0,0,0,0,0,0,0,0,0,0,0,14,10,0,0,0,0,0
0,0,0,0,0,0,11,0,0,0,0,0,0,0,0,0,0,0,11,0,0,0,0,0,0
0,0,0,0,0,0,22,0,0,0,0,0,0,0,0,0,0,0,21,0,0,0,0,0,0
0,0,0,0,0,0,10,28,0,0,0,0,0,0,0,0,0,28,10,0,0,0,0,0,0
0,0,0,0,0,0,0,10,23,0,0,0,0,0,0,0,24,10,0,0,0,0,0,0,0
0,0,0,0,0,0,0,0,10,21,11,0,0,0,11,21,10,0,0,0,0,0,0,0,0
0,0,0,0,0,0,0,0,0,0,0,21,0,21,0,0,0,0,0,0,0,0,0,0,0
0,0,0,0,0,0,0,0,0,0,0,0,0,0,0,0,0,0,0,0,0,0,0,0,0
:endlayer
layer: 3
0,0,0,0,0,0,0,0,0,0,0,0,10,0,0,0,0,0,0,0,0,0,0,0,0
0,0,0,0,0,0,0,0,0,22,11,22,13,22,11,21,0,0,0,0,0,0,0,0,0
0,0,0,0,0,0,0,10,21,0,0,0,0,0,0,0,21,10,0,0,0,0,0,0,0
0,0,0,0,0,0,0,21,0,0,0,0,0,0,0,0,0,21,0,0,0,0,0,0,0
0,0,0,0,0,0,21,0,0,0,0,0,0,0,0,0,0,0,22,0,0,0,0,0,0
0,0,0,0,0,0,11,0,0,0,0,0,0,0,0,0,0,0,11,0,0,0,0,0,0
0,0,0,0,0,0,21,0,0,0,0,0,0,0,0,0,0,0,22,0,0,0,0,0,0
0,0,0,0,0,10,13,19,0,0,0,0,26,0,0,0,0,0,14,10,0,0,0,0,0
0,0,0,0,0,0,21,0,0,0,0,0,0,0,0,0,0,0,21,0,0,0,0,0,0
0,0,0,0,0,0,11,0,0,0,0,0,0,0,0,0,0,0,11,0,0,0,0,0,0
0,0,0,0,0,0,21,0,0,0,0,0,0,0,0,0,0,0,21,0,0,0,0,0,0
0,0,0,0,0,0,0,21,0,0,0,0,0,0,0,0,0,21,0,0,0,0,0,0,0
0,0,0,0,0,0,0,10,21,0,0,0,0,0,0,0,21,10,0,0,0,0,0,0,0
0,0,0,0,0,0,0,0,0,21,11,29,0,29,11,22,0,0,0,0,0,0,0,0,0
0,0,0,0,0,0,0,0,0,0,0,0,30,0,0,0,0,0,0,0,0,0,0,0,0
0,0,0,0,0,0,0,0,0,0,0,0,0,0,0,0,0,0,0,0,0,0,0,0,0
:endlayer
layer: 4
0,0,0,0,0,0,0,0,0,0,0,0,0,0,0,0,0,0,0,0,0,0,0,0,0
0,0,0,0,0,0,0,0,0,31,11,22,21,21,11,31,0,0,0,0,0,0,0,0,0
0,0,0,0,0,0,0,0,32,0,33,33,33,33,33,0,34,0,0,0,0,0,0,0,0
0,0,0,0,0,0,0,31,11,33,33,33,33,33,33,33,11,31,0,0,0,0,0,0,0
0,0,0,0,0,0,32,0,33,33,33,33,33,33,33,33,33,0,34,0,0,0,0,0,0
0,0,0,0,0,0,11,33,33,33,33,33,33,33,33,33,33,33,11,0,0,0,0,0,0
0,0,0,0,0,0,21,33,33,33,33,33,0,33,33,33,33,33,21,0,0,0,0,0,0
0,0,0,0,0,0,22,19,33,33,33,0,27,0,33,33,33,33,21,0,0,0,0,0,0
0,0,0,0,0,0,21,33,33,33,33,33,0,33,33,33,33,33,22,0,0,0,0,0,0
0,0,0,0,0,0,11,33,33,33,33,33,33,33,33,33,33,33,11,0,0,0,0,0,0
0,0,0,0,0,0,32,0,33,33,33,33,33,33,33,33,33,0,34,0,0,0,0,0,0
0,0,0,0,0,0,0,35,11,33,33,33,33,33,33,33,11,35,0,0,0,0,0,0,0
0,0,0,0,0,0,0,0,32,0,33,33,33,33,33,0,34,0,0,0,0,0,0,0,0
0,0,0,0,0,0,0,0,0,35,11,22,21,21,11,35,0,0,0,0,0,0,0,0,0
0,0,0,0,0,0,0,0,0,0,0,0,0,0,0,0,0,0,0,0,0,0,0,0,0
0,0,0,0,0,0,0,0,0,0,0,0,0,0,0,0,0,0,0,0,0,0,0,0,0
:endlayer
layer: 5
0,0,0,0,0,0,0,0,0,0,0,0,0,0,0,0,0,0,0,0,0,0,0,0,0
0,0,0,0,0,0,0,0,0,0,11,22,22,21,11,0,0,0,0,0,0,0,0,0,0
0,0,0,0,0,0,0,0,0,21,0,36,36,36,0,21,0,0,0,0,0,0,0,0,0
0,0,0,0,0,0,0,0,11,0,37,36,36,36,38,0,11,0,0,0,0,0,0,0,0
0,0,0,0,0,0,0,22,0,0,0,36,36,36,0,0,39,21,0,0,0,0,0,0,0
0,0,0,0,0,0,11,0,0,0,0,0,0,0,0,0,39,36,11,0,0,0,0,0,0
0,0,0,0,0,0,22,0,0,0,0,7,0,7,0,0,0,36,21,0,0,0,0,0,0
0,0,0,0,0,0,21,0,0,0,0,0,27,0,0,0,40,11,22,0,0,0,0,0,0
0,0,0,0,0,0,21,0,0,0,0,7,0,7,0,0,0,39,21,0,0,0,0,0,0
0,0,0,0,0,0,11,0,0,0,0,0,0,0,0,0,41,36,11,0,0,0,0,0,0
0,0,0,0,0,0,0,21,0,0,0,36,36,36,0,0,41,21,0,0,0,0,0,0,0
0,0,0,0,0,0,0,0,11,0,36,36,36,36,36,0,11,0,0,0,0,0,0,0,0
0,0,0,0,0,0,0,0,0,21,36,36,36,36,36,21,0,0,0,0,0,0,0,0,0
0,0,0,0,0,0,0,0,0,0,11,21,22,21,11,0,0,0,0,0,0,0,0,0,0
0,0,0,0,0,0,0,0,0,0,0,0,0,0,0,0,0,0,0,0,0,0,0,0,0
0,0,0,0,0,0,0,0,0,0,0,0,0,0,0,0,0,0,0,0,0,0,0,0,0
:endlayer
layer: 6
0,0,0,0,0,0,0,0,0,0,0,0,0,0,0,0,0,0,0,0,0,0,0,0,0
0,0,0,0,0,0,0,0,0,0,42,14,11,13,42,0,0,0,0,0,0,0,0,0,0
0,0,0,0,0,0,0,0,0,22,0,0,36,0,0,22,0,0,0,0,0,0,0,0,0
0,0,0,0,0,0,0,0,11,23,0,37,36,38,0,0,11,0,0,0,0,0,0,0,0
0,0,0,0,0,0,0,21,25,0,0,0,36,0,0,0,41,21,0,0,0,0,0,0,0
0,0,0,0,0,0,43,0,0,0,0,0,0,0,0,0,0,41,44,0,0,0,0,0,0
0,0,0,0,0,0,14,0,0,0,0,0,0,0,0,0,0,0,14,0,0,0,0,0,0
0,0,0,0,0,0,11,0,0,0,0,0,27,0,0,0,40,11,11,0,0,0,0,0,0
0,0,0,0,0,0,14,0,0,0,0,0,0,0,0,0,0,0,13,0,0,0,0,0,0
0,0,0,0,0,0,43,0,0,0,0,0,0,0,0,0,0,0,44,0,0,0,0,0,0
0,0,0,0,0,0,0,21,28,0,0,0,0,0,0,0,41,21,0,0,0,0,0,0,0
0,0,0,0,0,0,0,0,11,23,0,41,36,36,0,0,11,0,0,0,0,0,0,0,0
0,0,0,0,0,0,0,0,0,21,0,36,36,36,0,22,0,0,0,0,0,0,0,0,0
0,0,0,0,0,0,0,0,0,0,45,14,11,14,45,0,0,0,0,0,0,0,0,0,0
0,0,0,0,0,0,0,0,0,0,0,0,0,0,0,0,0,0,46,46,46,46,46,0,0
0,0,0,0,0,0,0,0,0,0,0,0,0,0,0,0,0,0,0,0,0,0,0,0,0
:endlayer
layer: 7
0,0,0,0,0,0,0,0,0,0,0,0,0,0,0,0,0,0,0,0,0,0,0,0,0
0,0,0,0,0,0,0,0,0,0,0,0,42,0,0,0,0,0,0,0,0,0,0,0,0
0,0,0,0,0,0,0,0,0,27,11,13,11,14,11,27,0,0,0,0,0,0,0,0,0
0,0,0,0,0,0,0,0,11,13,0,0,47,0,0,14,11,0,0,0,0,0,0,0,0
0,0,0,0,0,0,0,27,14,0,0,0,0,0,0,0,13,27,0,0,0,0,0,0,0
0,0,0,0,0,0,0,11,0,0,0,0,0,0,0,0,0,11,0,0,0,0,0,0,0
0,0,0,0,0,0,0,13,0,0,0,0,0,0,0,0,0,13,0,0,0,0,0,0,0
0,0,0,0,0,0,43,11,0,0,0,0,27,0,0,0,40,11,44,0,0,0,0,0,0
0,0,0,0,0,0,0,14,0,0,0,0,0,0,0,0,0,14,0,0,0,0,0,0,0
0,0,0,0,0,0,0,11,0,0,0,0,0,0,0,0,0,11,0,0,0,0,0,0,0
0,0,0,0,0,0,0,27,14,0,0,0,0,0,0,0,14,27,0,0,0,0,0,0,0
0,0,0,0,0,0,0,0,11,13,0,0,41,0,0,13,11,0,0,0,0,0,0,0,0
0,0,0,0,0,0,0,0,0,27,11,14,11,13,11,27,0,0,0,0,0,0,0,0,0
0,0,46,46,0,0,0,0,0,0,0,0,45,0,0,0,0,0,0,0,0,0,0,0,0
0,46,0,0,0,0,0,0,0,0,0,0,0,0,0,0,0,46,48,48,48,48,48,46,0
0,0,0,0,0,0,0,0,0,0,0,0,0,0,0,0,0,0,0,0,0,0,0,0,0
:endlayer
layer: 8
0,0,0,0,0,0,0,0,0,0,0,0,0,0,0,0,0,0,0,0,0,0,0,0,0
0,0,0,0,0,0,0,0,0,0,0,0,28,0,0,0,0,0,0,0,0,0,0,0,0
0,0,0,0,0,0,0,0,0,0,11,13,11,14,11,0,0,0,0,0,0,0,0,0,0
0,0,0,0,0,0,0,0,27,14,33,0,33,0,33,14,27,0,0,0,0,0,0,0,0
0,0,0,0,0,0,0,0,14,0,33,33,33,33,33,0,13,0,0,0,0,0,0,0,0
0,0,0,0,0,0,0,11,33,33,33,0,0,0,33,33,33,11,0,0,0,0,0,0,0
0,0,0,0,0,0,0,13,0,33,0,0,0,0,0,33,0,14,0,0,0,0,0,0,0
0,0,0,0,0,0,24,11,33,33,0,0,27,0,0,33,40,11,23,0,0,0,0,0,0
0,0,0,0,0,0,0,14,0,33,0,0,0,0,0,33,0,14,0,0,0,0,0,0,0
0,0,0,0,0,0,0,11,33,33,33,0,0,0,33,33,33,11,0,0,0,0,0,0,0
0,0,0,0,0,0,0,0,13,0,33,33,33,33,33,0,14,0,0,0,0,0,0,0,0
0,0,0,0,0,0,0,0,27,13,33,0,33,0,33,14,27,0,0,0,0,0,0,0,0
0,0,0,0,46,0,0,0,0,0,11,13,11,14,11,0,0,0,0,0,0,0,0,0,0
0,0,48,48,0,0,0,0,0,0,0,0,25,0,0,0,0,0,0,0,0,0,48,46,0
46,48,0,0,0,0,0,0,0,0,0,0,0,0,0,0,46,48,48,48,48,48,0,0,0
0,0,0,0,0,0,0,0,0,0,0,0,0,0,0,0,0,0,0,0,0,0,0,0,0
:endlayer
layer: 9
0,0,0,0,0,0,0,0,0,0,0,0,0,0,0,0,0,0,0,0,0,0,0,0,0
0,0,0,0,0,0,0,0,0,0,0,0,0,0,0,0,0,0,0,0,0,0,0,0,0
0,0,0,0,0,0,0,0,0,0,11,31,11,31,11,0,0,0,0,0,0,0,0,0,0
0,0,0,0,0,0,0,0,0,13,0,11,0,11,0,14,0,0,0,0,0,0,0,0,0
0,0,0,0,0,0,0,0,14,11,0,0,0,0,0,11,13,0,0,0,0,0,0,0,0
0,0,0,0,0,0,0,11,41,0,0,0,0,0,0,0,0,11,0,0,0,0,0,0,0
0,0,0,0,0,0,0,32,11,0,0,0,0,0,0,0,11,34,0,0,0,0,0,0,0
0,0,0,0,0,0,0,11,0,0,0,0,27,0,0,0,0,11,0,0,0,0,0,0,0
0,0,0,0,0,0,0,32,11,0,0,0,0,0,0,40,11,34,0,0,0,0,0,0,0
0,0,0,0,0,0,0,11,0,0,0,0,0,0,0,0,41,11,0,0,0,0,0,0,0
0,0,0,0,0,0,0,0,13,11,0,0,0,0,0,11,13,0,0,0,0,0,0,0,0
0,0,0,0,0,0,0,0,0,14,0,11,0,11,41,14,0,0,0,0,0,0,0,0,0
0,0,0,0,0,46,0,0,0,0,11,35,11,35,11,0,0,0,0,0,0,0,0,0,0
0,0,0,48,48,0,0,0,0,0,0,0,0,0,0,0,0,0,0,0,0,48,48,46,0
46,48,48,0,0,0,0,0,0,0,0,0,0,0,0,46,48,48,48,48,48,0,0,0,0
0,0,0,0,0,0,0,0,0,0,0,0,0,0,0,0,0,0,0,0,0,0,0,0,0
:endlayer
layer: 10
0,0,0,0,0,0,0,0,0,0,0,0,0,0,0,0,0,0,0,0,0,0,0,0,0
0,0,0,0,0,0,0,0,0,0,0,0,0,0,0,0,0,0,0,0,0,0,0,0,0
0,0,0,0,0,0,0,0,0,0,11,0,27,0,11,0,0,0,0,0,0,0,0,0,0
0,0,0,0,0,0,0,0,0,14,0,11,0,11,0,14,0,0,0,0,0,0,0,0,0
0,0,0,0,0,0,0,0,13,11,0,0,0,0,0,11,14,0,0,0,0,0,0,0,0
0,0,0,0,0,0,0,11,41,0,0,0,0,0,0,0,0,11,0,0,0,0,0,0,0
0,0,0,0,0,0,0,0,11,0,0,0,0,0,0,0,11,0,0,0,0,0,0,0,0
0,0,0,0,0,0,0,27,0,0,0,0,27,0,0,0,0,27,0,0,0,0,0,0,0
0,0,0,0,0,0,0,0,11,0,0,0,0,0,0,40,11,0,0,0,0,0,0,0,0
0,0,0,0,0,0,0,11,0,0,0,0,0,0,0,0,39,11,0,0,0,0,0,0,0
0,0,0,0,0,0,0,0,14,11,0,0,0,0,0,11,13,0,0,0,0,0,0,0,0
0,0,0,0,0,0,0,0,0,14,0,11,0,11,41,13,0,0,0,0,0,0,0,0,0
0,0,0,0,0,0,46,0,0,0,11,0,27,0,11,0,0,0,0,0,0,0,46,0,0
0,0,0,48,48,48,0,0,0,0,0,0,0,0,0,0,0,0,0,48,48,48,0,0,0
46,48,48,0,0,0,0,0,0,0,0,0,0,0,46,48,48,48,48,0,0,0,0,0,0
0,0,0,0,0,0,0,0,0,0,0,0,0,0,0,0,0,0,0,0,0,0,0,0,0
:endlayer
layer: 11
0,0,0,0,0,0,0,0,0,0,0,0,0,0,0,0,0,0,0,0,0,0,0,0,0
0,0,0,0,0,0,0,0,0,0,0,0,0,0,0,0,0,0,0,0,0,0,0,0,0
0,0,0,0,0,0,0,0,0,0,42,0,27,0,42,0,0,0,0,0,0,0,0,0,0
0,0,0,0,0,0,0,0,0,43,49,11,0,11,49,44,0,0,0,0,0,0,0,0,0
0,0,0,0,0,0,0,0,42,11,23,0,0,0,24,11,42,0,0,0,0,0,0,0,0
0,0,0,0,0,0,0,43,49,25,0,0,0,0,0,25,49,44,0,0,0,0,0,0,0
0,0,0,0,0,0,0,0,11,0,0,0,0,0,0,0,11,0,0,0,0,0,0,0,0
0,0,0,0,0,0,0,27,0,0,0,0,27,0,0,0,0,27,0,0,0,0,0,0,0
0,0,0,0,0,0,0,0,11,0,0,0,0,0,0,40,11,0,0,0,0,0,0,0,0
0,0,0,0,0,0,0,43,49,28,0,0,0,0,0,28,49,44,0,0,0,0,0,0,0
0,0,0,0,0,0,0,0,45,11,23,0,0,0,24,11,45,0,0,0,0,0,0,0,0
0,0,0,0,0,0,0,0,0,43,49,11,0,11,49,44,0,0,0,0,0,0,0,0,0
0,0,0,0,0,0,0,46,0,0,45,0,27,0,45,0,0,0,0,0,0,46,0,0,0
0,0,0,0,48,48,48,0,0,0,0,0,0,0,0,0,0,0,48,48,48,0,0,0,0
46,48,48,48,0,0,0,0,0,0,0,0,0,0,46,48,48,48,0,0,0,0,0,0,0
0,0,0,0,0,0,0,0,0,0,0,0,0,0,0,0,0,0,0,0,0,0,0,0,0
:endlayer
layer: 12
0,0,0,0,0,0,0,0,0,0,0,0,0,0,0,0,0,0,0,0,0,0,0,0,0
0,0,0,0,0,0,0,0,0,0,0,0,0,0,0,0,0,0,0,0,0,0,0,0,0
0,0,0,0,0,0,0,0,0,0,0,0,42,0,0,0,0,0,0,0,0,0,0,0,0
0,0,0,0,0,0,0,0,0,0,49,11,49,11,49,0,0,0,0,0,0,0,0,0,0
0,0,0,0,0,0,0,0,0,11,0,0,0,0,0,11,0,0,0,0,0,0,0,0,0
0,0,0,0,0,0,0,0,49,0,0,0,0,0,0,0,49,0,0,0,0,0,0,0,0
0,0,0,0,0,0,0,0,11,0,0,0,0,0,0,0,11,0,0,0,0,0,0,0,0
0,0,0,0,0,0,0,43,49,0,0,0,27,0,0,0,49,44,0,0,0,0,0,0,0
0,0,0,0,0,0,0,0,11,0,0,0,0,0,0,40,11,0,0,0,0,0,0,0,0
0,0,0,0,0,0,0,0,49,0,0,0,0,0,0,0,49,0,0,0,0,0,0,0,0
0,0,0,0,0,0,0,0,0,11,0,0,0,0,0,11,0,0,0,0,0,0,0,0,0
0,0,0,0,0,0,0,0,0,0,49,11,49,11,49,0,0,0,0,0,0,0,0,0,0
0,0,0,0,0,0,0,0,46,0,0,0,45,0,0,0,0,0,0,0,46,0,0,0,0
0,0,0,0,0,48,48,48,0,0,0,0,0,0,0,0,0,48,48,48,0,0,0,0,0
46,48,48,48,48,0,0,0,0,0,0,0,0,46,48,48,48,0,0,0,0,0,0,0,0
0,0,0,0,0,0,0,0,0,0,0,0,0,0,0,0,0,0,0,0,0,0,0,0,0
:endlayer
layer: 13
0,0,0,0,0,0,0,0,0,0,0,0,0,0,0,0,0,0,0,0,0,0,0,0,0
0,0,0,0,0,0,0,0,0,0,0,0,0,0,0,0,0,0,0,0,0,0,0,0,0
0,0,0,0,0,0,0,0,0,0,0,0,0,0,0,0,0,0,0,0,0,0,0,0,0
0,0,0,0,0,0,0,0,0,0,49,11,49,11,49,0,0,0,0,0,0,0,0,0,0
0,0,0,0,0,0,0,0,0,11,0,0,0,0,0,11,0,0,0,0,0,0,0,0,0
0,0,0,0,0,0,0,0,49,0,0,0,0,0,0,0,49,0,0,0,0,0,0,0,0
0,0,0,0,0,0,0,0,11,0,0,0,0,0,0,0,11,0,0,0,0,0,0,0,0
0,0,0,0,0,0,0,0,49,0,0,0,27,0,0,0,49,0,0,0,0,0,0,0,0
0,0,0,0,0,0,0,0,11,0,0,0,0,0,0,40,11,0,0,0,0,0,0,0,0
0,0,0,0,0,0,0,0,49,0,0,0,0,0,0,0,49,0,0,0,0,0,0,0,0
0,0,0,0,0,0,0,0,0,11,0,0,0,0,0,11,0,0,0,0,0,0,0,0,0
0,0,0,0,0,0,0,0,0,0,49,11,49,11,49,0,0,0,0,0,0,0,0,0,0
0,0,0,0,0,0,0,0,46,0,0,0,0,0,0,0,0,0,0,46,0,0,0,0,0
0,0,0,0,0,0,48,48,0,0,0,0,0,0,0,0,48,48,48,0,0,0,0,0,0
0,46,48,48,48,48,0,0,0,0,0,0,0,46,48,48,0,0,0,0,0,0,0,0,0
0,0,0,0,0,0,0,0,0,0,0,0,0,0,0,0,0,0,0,0,0,0,0,0,0
:endlayer
layer: 14
0,0,0,0,0,0,0,0,0,0,0,0,0,0,0,0,0,0,0,0,0,0,0,0,0
0,0,0,0,0,0,0,0,0,0,0,0,0,0,0,0,0,0,0,0,0,0,0,0,0
0,0,0,0,0,0,0,0,0,0,0,0,0,0,0,0,0,0,0,0,0,0,0,0,0
0,0,0,0,0,0,0,0,0,0,49,11,49,11,49,0,0,0,0,0,0,0,0,0,0
0,0,0,0,0,0,0,0,0,11,33,33,33,33,33,11,0,0,0,0,0,0,0,0,0
0,0,0,0,0,0,0,0,49,33,33,33,33,33,33,33,49,0,0,0,0,0,0,0,0
0,0,0,0,0,0,0,0,11,33,33,33,0,33,33,33,11,0,0,0,0,0,0,0,0
0,0,0,0,0,0,0,0,49,33,33,0,27,0,33,33,49,0,0,0,0,0,0,0,0
0,0,0,0,0,0,0,0,11,33,33,0,0,0,0,40,11,0,0,0,0,0,0,0,0
0,0,0,0,0,0,0,0,49,33,33,33,0,0,0,0,49,0,0,0,0,0,0,0,0
0,0,0,0,0,0,0,0,0,11,33,33,33,0,0,11,0,0,0,0,0,0,0,0,0
0,0,0,0,0,0,0,0,0,0,49,11,49,11,49,0,0,0,0,0,0,0,0,0,0
0,0,0,0,0,0,0,0,0,46,0,0,0,0,0,0,0,46,46,0,0,0,0,0,0
0,0,0,0,0,0,0,48,48,0,0,0,0,0,0,48,48,0,0,0,0,0,0,0,0
0,0,46,48,48,48,48,0,0,0,0,0,46,48,48,0,0,0,0,0,0,0,0,0,0
0,0,0,0,0,0,0,0,0,0,0,0,0,0,0,0,0,0,0,0,0,0,0,0,0
:endlayer
layer: 15
0,0,0,0,0,0,0,0,0,0,0,0,0,0,0,0,0,0,0,0,0,0,0,0,0
0,0,0,0,0,0,0,0,0,0,0,0,0,0,0,0,0,0,0,0,0,0,0,0,0
0,0,0,0,0,0,0,0,0,0,0,0,0,0,0,0,0,0,0,0,0,0,0,0,0
0,0,0,0,0,0,0,0,0,0,49,11,50,11,49,0,0,0,0,0,0,0,0,0,0
0,0,0,0,0,0,0,0,0,11,0,0,0,0,0,11,0,0,0,0,0,0,0,0,0
0,0,0,0,0,0,0,0,49,0,0,0,0,0,0,0,49,0,0,0,0,0,0,0,0
0,0,0,0,0,0,0,0,11,0,0,0,0,0,0,0,11,0,0,0,0,0,0,0,0
0,0,0,0,0,0,0,0,50,0,0,0,27,0,0,0,50,0,0,0,0,0,0,0,0
0,0,0,0,0,0,0,0,11,0,0,0,0,0,0,0,11,0,0,0,0,0,0,0,0
0,0,0,0,0,0,0,0,49,0,0,0,0,0,0,0,49,0,0,0,0,0,0,0,0
0,0,0,0,0,0,0,0,0,11,0,0,0,0,0,11,0,0,0,0,0,0,0,0,0
0,0,0,0,0,0,0,0,0,0,49,11,50,11,49,0,0,0,0,0,0,0,0,0,0
0,0,0,0,0,0,0,0,0,0,0,0,0,0,0,0,46,0,0,0,0,0,0,0,0
0,0,0,0,0,0,0,0,48,48,46,0,0,0,48,48,0,0,0,0,0,0,0,0,0
0,0,0,46,48,48,48,48,0,0,0,0,46,48,0,0,0,0,0,0,0,0,0,0,0
0,0,0,0,0,0,0,0,0,0,0,0,0,0,0,0,0,0,0,0,0,0,0,0,0
:endlayer
layer: 16
0,0,0,0,0,0,0,0,0,0,0,0,0,0,0,0,0,0,0,0,0,0,0,0,0
0,0,0,0,0,0,0,0,0,0,0,0,0,0,0,0,0,0,0,0,0,0,0,0,0
0,0,0,0,0,0,0,0,0,0,0,0,0,0,0,0,0,0,0,0,0,0,0,0,0
0,0,0,0,0,0,0,0,0,0,49,11,50,11,49,0,0,0,0,0,0,0,0,0,0
0,0,0,0,0,0,0,0,0,11,0,0,0,0,0,11,0,0,0,0,0,0,0,0,0
0,0,0,0,0,0,0,0,49,0,0,0,0,0,0,0,49,0,0,0,0,0,0,0,0
0,0,0,0,0,0,0,0,11,0,0,0,0,0,0,0,11,0,0,0,0,0,0,0,0
0,0,0,0,0,0,0,0,50,0,0,0,27,0,0,0,50,0,0,0,0,0,0,0,0
0,0,0,0,0,0,0,0,11,0,0,0,0,0,0,0,11,0,0,0,0,0,0,0,0
0,0,0,0,0,0,0,0,49,0,0,0,0,0,0,0,49,0,0,0,0,0,0,0,0
0,0,0,0,0,0,0,0,0,11,0,0,0,0,0,11,0,0,0,0,0,0,0,0,0
0,0,0,0,0,0,0,0,0,0,49,11,50,11,49,0,0,0,0,0,0,0,0,0,0
0,0,0,0,0,0,0,0,0,0,0,0,0,0,0,0,0,0,0,0,0,0,0,0,0
0,0,0,0,0,0,0,0,0,48,46,0,0,0,46,46,0,0,0,0,0,0,0,0,0
0,0,0,0,46,46,48,48,48,0,0,0,46,48,0,0,0,0,0,0,0,0,0,0,0
0,0,0,0,0,0,0,0,0,0,0,0,0,0,0,0,0,0,0,0,0,0,0,0,0
:endlayer
layer: 17
0,0,0,0,0,0,0,0,0,0,0,0,0,0,0,0,0,0,0,0,0,0,0,0,0
0,0,0,0,0,0,0,0,0,0,0,0,0,0,0,0,0,0,0,0,0,0,0,0,0
0,0,0,0,0,0,0,0,0,0,0,0,0,0,0,0,0,0,0,0,0,0,0,0,0
0,0,0,0,0,0,0,0,0,0,49,11,49,11,49,0,0,0,0,0,0,0,0,0,0
0,0,0,0,0,0,0,0,0,11,0,0,25,0,0,11,0,0,0,0,0,0,0,0,0
0,0,0,0,0,0,0,0,49,0,0,0,0,0,0,0,49,0,0,0,0,0,0,0,0
0,0,0,0,0,0,0,0,11,0,0,0,0,0,0,0,11,0,0,0,0,0,0,0,0
0,0,0,0,0,0,0,0,49,23,0,0,26,0,0,24,49,0,0,0,0,0,0,0,0
0,0,0,0,0,0,0,0,11,0,0,0,0,0,0,0,11,0,0,0,0,0,0,0,0
0,0,0,0,0,0,0,0,49,0,0,0,0,0,0,0,49,0,0,0,0,0,0,0,0
0,0,0,0,0,0,0,0,0,11,0,0,28,0,0,11,0,0,0,0,0,0,0,0,0
0,0,0,0,0,0,0,0,0,0,49,11,10,11,49,0,0,0,0,0,0,0,0,0,0
0,0,0,0,0,0,0,0,0,0,0,0,0,0,0,0,0,0,0,0,0,0,0,0,0
0,0,0,0,0,0,0,0,0,0,0,0,0,0,0,0,0,0,0,0,0,0,0,0,0
0,0,0,0,0,0,46,46,48,48,48,0,46,0,0,0,0,0,0,0,0,0,0,0,0
0,0,0,0,0,0,0,0,0,0,0,0,0,0,0,0,0,0,0,0,0,0,0,0,0
:endlayer
layer: 18
0,0,0,0,0,0,0,0,0,0,0,0,0,0,0,0,0,0,0,0,0,0,0,0,0
0,0,0,0,0,0,0,0,0,0,0,0,0,0,0,0,0,0,0,0,0,0,0,0,0
0,0,0,0,0,0,0,0,0,0,0,0,0,0,0,0,0,0,0,0,0,0,0,0,0
0,0,0,0,0,0,0,0,0,0,49,11,49,11,49,0,0,0,0,0,0,0,0,0,0
0,0,0,0,0,0,0,0,0,11,0,0,0,0,0,11,0,0,0,0,0,0,0,0,0
0,0,0,0,0,0,0,0,49,0,0,0,0,0,0,0,49,0,0,0,0,0,0,0,0
0,0,0,0,0,0,0,0,11,0,0,0,0,0,0,0,11,0,0,0,0,0,0,0,0
0,0,0,0,0,0,0,0,49,0,0,0,27,0,0,0,49,0,0,0,0,0,0,0,0
0,0,0,0,0,0,0,0,11,0,0,0,26,0,0,0,11,0,0,0,0,0,0,0,0
0,0,0,0,0,0,0,0,49,0,0,0,51,0,0,0,49,0,0,0,0,0,0,0,0
0,0,0,0,0,0,0,0,0,11,0,0,51,0,0,11,0,0,0,0,0,0,0,0,0
0,0,0,0,0,0,0,0,0,0,49,10,51,10,49,0,0,0,0,0,0,0,0,0,0
0,0,0,0,0,0,0,0,0,0,0,0,51,0,0,0,0,0,0,0,0,0,0,0,0
0,0,0,0,0,0,0,0,0,0,0,0,51,0,0,0,0,0,0,0,0,0,0,0,0
0,0,0,0,0,0,0,0,46,46,46,46,51,46,46,46,46,0,0,0,0,0,0,0,0
0,0,0,0,0,0,0,0,0,0,0,0,52,0,0,0,0,0,0,0,0,0,0,0,0
:endlayer
layer: 19
0,0,0,0,0,0,0,0,0,0,0,0,0,0,0,0,0,0,0,0,0,0,0,0,0
0,0,0,0,0,0,0,0,0,0,0,0,0,0,0,0,0,0,0,0,0,0,0,0,0
0,0,0,0,0,0,0,0,0,0,0,0,0,0,0,0,0,0,0,0,0,0,0,0,0
0,0,0,0,0,0,0,0,0,0,49,11,49,11,49,0,0,0,0,0,0,0,0,0,0
0,0,0,0,0,0,0,0,0,11,0,0,0,0,0,11,0,0,0,0,0,0,0,0,0
0,0,0,0,0,0,0,0,49,0,0,0,0,0,0,0,49,0,0,0,0,0,0,0,0
0,0,0,0,0,0,0,0,11,0,0,0,0,0,0,0,11,0,0,0,0,0,0,0,0
0,0,0,0,0,0,0,0,49,0,0,0,0,0,0,0,49,0,0,0,0,0,0,0,0
0,0,0,0,0,0,0,0,11,0,0,0,0,0,0,0,11,0,0,0,0,0,0,0,0
0,0,0,0,0,0,0,0,49,0,0,0,0,0,0,0,49,0,0,0,0,0,0,0,0
0,0,0,0,0,0,0,0,0,11,0,0,0,0,0,11,0,0,0,0,0,0,0,0,0
0,0,0,0,0,0,0,0,0,0,49,11,10,11,49,0,0,0,0,0,0,0,0,0,0
0,0,0,0,0,0,0,0,0,0,0,0,0,0,0,0,0,0,0,0,0,0,0,0,0
0,0,0,0,0,0,0,0,0,0,0,0,0,0,0,0,0,0,0,0,0,0,0,0,0
0,0,0,0,0,0,0,0,0,0,0,0,46,0,48,48,48,46,46,0,0,0,0,0,0
0,0,0,0,0,0,0,0,0,0,0,0,0,0,0,0,0,0,0,0,0,0,0,0,0
:endlayer
layer: 20
0,0,0,0,0,0,0,0,0,0,0,0,0,0,0,0,0,0,0,0,0,0,0,0,0
0,0,0,0,0,0,0,0,0,0,0,0,0,0,0,0,0,0,0,0,0,0,0,0,0
0,0,0,0,0,0,0,0,0,0,0,0,0,0,0,0,0,0,0,0,0,0,0,0,0
0,0,0,0,0,0,0,0,0,27,49,11,49,11,49,27,0,0,0,0,0,0,0,0,0
0,0,0,0,0,0,0,0,27,11,23,0,0,0,24,11,27,0,0,0,0,0,0,0,0
0,0,0,0,0,0,0,0,49,25,0,0,0,0,0,25,49,0,0,0,0,0,0,0,0
0,0,0,0,0,0,0,0,11,0,0,0,0,0,0,0,11,0,0,0,0,0,0,0,0
0,0,0,0,0,0,0,0,49,0,0,0,0,0,0,0,49,0,0,0,0,0,0,0,0
0,0,0,0,0,0,0,0,11,0,0,0,0,0,0,0,11,0,0,0,0,0,0,0,0
0,0,0,0,0,0,0,0,49,28,0,0,0,0,0,28,49,0,0,0,0,0,0,0,0
0,0,0,0,0,0,0,0,27,11,23,0,0,0,24,11,27,0,0,0,0,0,0,0,0
0,0,0,0,0,0,0,0,0,27,49,11,49,11,49,27,0,0,0,0,0,0,0,0,0
0,0,0,0,0,0,0,0,0,0,0,0,0,0,0,0,0,0,0,0,0,0,0,0,0
0,0,0,0,0,0,0,0,0,46,46,0,0,0,46,48,0,0,0,0,0,0,0,0,0
0,0,0,0,0,0,0,0,0,0,0,48,46,0,0,0,48,48,48,46,46,0,0,0,0
0,0,0,0,0,0,0,0,0,0,0,0,0,0,0,0,0,0,0,0,0,0,0,0,0
:endlayer
layer: 21
0,0,0,0,0,0,0,0,0,0,0,0,0,0,0,0,0,0,0,0,0,0,0,0,0
0,0,0,0,0,0,0,0,0,0,0,0,0,0,0,0,0,0,0,0,0,0,0,0,0
0,0,0,0,0,0,0,0,0,0,42,42,42,42,42,0,0,0,0,0,0,0,0,0,0
0,0,0,0,0,0,0,0,0,43,53,53,53,53,53,42,0,0,0,0,0,0,0,0,0
0,0,0,0,0,0,0,0,43,53,10,10,10,10,10,53,44,0,0,0,0,0,0,0,0
0,0,0,0,0,0,0,43,53,10,0,0,0,0,0,10,53,44,0,0,0,0,0,0,0
0,0,0,0,0,0,0,43,53,10,0,0,0,0,0,10,53,44,0,0,0,0,0,0,0
0,0,0,0,0,0,0,43,53,10,0,0,0,0,0,10,53,44,0,0,0,0,0,0,0
0,0,0,0,0,0,0,43,53,10,0,0,0,0,0,10,53,44,0,0,0,0,0,0,0
0,0,0,0,0,0,0,43,53,10,0,0,0,0,0,10,53,44,0,0,0,0,0,0,0
0,0,0,0,0,0,0,0,43,53,10,10,10,10,10,53,44,0,0,0,0,0,0,0,0
0,0,0,0,0,0,0,0,0,45,53,53,53,53,53,45,0,0,0,0,0,0,0,0,0
0,0,0,0,0,0,0,0,46,0,45,45,45,45,45,0,0,0,0,0,0,0,0,0,0
0,0,0,0,0,0,0,0,0,48,48,0,0,0,46,48,48,0,0,0,0,0,0,0,0
0,0,0,0,0,0,0,0,0,0,0,48,46,0,0,0,0,48,48,48,48,46,0,0,0
0,0,0,0,0,0,0,0,0,0,0,0,0,0,0,0,0,0,0,0,0,0,0,0,0
:endlayer
layer: 22
0,0,0,0,0,0,0,0,0,0,0,0,0,0,0,0,0,0,0,0,0,0,0,0,0
0,0,0,0,0,0,0,0,0,0,0,0,0,0,0,0,0,0,0,0,0,0,0,0,0
0,0,0,0,0,0,0,0,0,0,0,0,0,0,0,0,0,0,0,0,0,0,0,0,0
0,0,0,0,0,0,0,0,0,0,54,54,54,54,54,0,0,0,0,0,0,0,0,0,0
0,0,0,0,0,0,0,0,0,42,53,53,53,53,53,42,0,0,0,0,0,0,0,0,0
0,0,0,0,0,0,0,0,54,53,10,10,10,10,10,53,54,0,0,0,0,0,0,0,0
0,0,0,0,0,0,0,0,54,53,10,0,0,0,10,53,54,0,0,0,0,0,0,0,0
0,0,0,0,0,0,0,0,54,53,10,0,0,0,10,53,54,0,0,0,0,0,0,0,0
0,0,0,0,0,0,0,0,54,53,10,0,0,0,10,53,54,0,0,0,0,0,0,0,0
0,0,0,0,0,0,0,0,54,53,10,10,10,10,10,53,54,0,0,0,0,0,0,0,0
0,0,0,0,0,0,0,0,0,45,53,53,53,53,53,45,0,0,0,0,0,0,0,0,0
0,0,0,0,0,0,0,0,0,0,54,54,54,54,54,0,0,0,0,0,0,0,0,0,0
0,0,0,0,0,0,46,46,0,0,0,0,0,0,0,46,0,0,0,0,0,0,0,0,0
0,0,0,0,0,0,0,0,48,48,0,0,0,0,0,0,48,48,0,0,0,0,0,0,0
0,0,0,0,0,0,0,0,0,0,48,48,46,0,0,0,0,0,48,48,48,48,46,0,0
0,0,0,0,0,0,0,0,0,0,0,0,0,0,0,0,0,0,0,0,0,0,0,0,0
:endlayer
layer: 23
0,0,0,0,0,0,0,0,0,0,0,0,0,0,0,0,0,0,0,0,0,0,0,0,0
0,0,0,0,0,0,0,0,0,0,0,0,0,0,0,0,0,0,0,0,0,0,0,0,0
0,0,0,0,0,0,0,0,0,0,0,0,0,0,0,0,0,0,0,0,0,0,0,0,0
0,0,0,0,0,0,0,0,0,0,0,0,0,0,0,0,0,0,0,0,0,0,0,0,0
0,0,0,0,0,0,0,0,0,0,42,42,42,42,42,0,0,0,0,0,0,0,0,0,0
0,0,0,0,0,0,0,0,0,43,53,53,53,53,53,44,0,0,0,0,0,0,0,0,0
0,0,0,0,0,0,0,0,0,43,53,0,0,0,53,44,0,0,0,0,0,0,0,0,0
0,0,0,0,0,0,0,0,0,43,53,0,0,0,53,44,0,0,0,0,0,0,0,0,0
0,0,0,0,0,0,0,0,0,43,53,0,0,0,53,44,0,0,0,0,0,0,0,0,0
0,0,0,0,0,0,0,0,0,43,53,53,53,53,53,44,0,0,0,0,0,0,0,0,0
0,0,0,0,0,0,0,0,0,0,45,45,45,45,45,0,0,0,0,0,0,0,0,0,0
0,0,0,0,0,0,0,0,0,0,0,0,0,0,0,0,0,0,0,0,0,0,0,0,0
0,0,0,0,0,46,0,0,0,0,0,0,0,0,0,0,46,0,0,0,0,0,0,0,0
0,0,0,0,0,0,48,48,48,0,0,0,0,0,0,0,0,48,48,0,0,0,0,0,0
0,0,0,0,0,0,0,0,0,48,48,46,0,0,0,0,0,0,0,48,48,48,48,46,0
0,0,0,0,0,0,0,0,0,0,0,0,0,0,0,0,0,0,0,0,0,0,0,0,0
:endlayer
layer: 24
0,0,0,0,0,0,0,0,0,0,0,0,0,0,0,0,0,0,0,0,0,0,0,0,0
0,0,0,0,0,0,0,0,0,0,0,0,0,0,0,0,0,0,0,0,0,0,0,0,0
0,0,0,0,0,0,0,0,0,0,0,0,0,0,0,0,0,0,0,0,0,0,0,0,0
0,0,0,0,0,0,0,0,0,0,0,0,0,0,0,0,0,0,0,0,0,0,0,0,0
0,0,0,0,0,0,0,0,0,0,0,0,0,0,0,0,0,0,0,0,0,0,0,0,0
0,0,0,0,0,0,0,0,0,0,54,42,42,42,0,0,0,0,0,0,0,0,0,0,0
0,0,0,0,0,0,0,0,0,0,43,53,53,53,44,0,0,0,0,0,0,0,0,0,0
0,0,0,0,0,0,0,0,0,0,43,53,0,53,44,0,0,0,0,0,0,0,0,0,0
0,0,0,0,0,0,0,0,0,0,43,53,53,53,44,0,0,0,0,0,0,0,0,0,0
0,0,0,0,0,0,0,0,0,0,0,45,45,45,54,0,0,0,0,0,0,0,0,0,0
0,0,0,0,0,0,0,0,0,0,0,0,0,0,0,0,0,0,0,0,0,0,0,0,0
0,0,0,0,0,0,0,0,0,0,0,0,0,0,0,0,0,0,0,0,0,0,0,0,0
0,0,0,0,46,0,0,0,0,0,0,0,0,0,0,0,46,0,0,0,0,0,0,0,0
0,0,0,0,0,48,48,48,0,0,0,0,0,0,0,0,0,48,48,48,0,0,0,0,0
0,0,0,0,0,0,0,0,48,48,48,46,0,0,0,0,0,0,0,0,48,48,48,48,46
0,0,0,0,0,0,0,0,0,0,0,0,0,0,0,0,0,0,0,0,0,0,0,0,0
:endlayer
layer: 25
0,0,0,0,0,0,0,0,0,0,0,0,0,0,0,0,0,0,0,0,0,0,0,0,0
0,0,0,0,0,0,0,0,0,0,0,0,0,0,0,0,0,0,0,0,0,0,0,0,0
0,0,0,0,0,0,0,0,0,0,0,0,0,0,0,0,0,0,0,0,0,0,0,0,0
0,0,0,0,0,0,0,0,0,0,0,0,0,0,0,0,0,0,0,0,0,0,0,0,0
0,0,0,0,0,0,0,0,0,0,0,0,0,0,0,0,0,0,0,0,0,0,0,0,0
0,0,0,0,0,0,0,0,0,0,0,0,0,0,0,0,0,0,0,0,0,0,0,0,0
0,0,0,0,0,0,0,0,0,0,0,42,42,44,0,0,0,0,0,0,0,0,0,0,0
0,0,0,0,0,0,0,0,0,0,0,43,10,44,0,0,0,0,0,0,0,0,0,0,0
0,0,0,0,0,0,0,0,0,0,0,43,45,44,0,0,0,0,0,0,0,0,0,0,0
0,0,0,0,0,0,0,0,0,0,0,0,0,0,0,0,0,0,0,0,0,0,0,0,0
0,0,0,0,0,0,0,0,0,0,0,0,0,0,0,0,0,0,0,0,0,0,0,0,0
0,0,0,0,0,0,0,0,0,0,0,0,0,0,0,0,0,0,0,0,0,0,0,0,0
0,0,0,46,0,0,0,0,0,0,0,0,0,0,0,0,0,46,0,0,0,0,0,0,0
0,0,0,0,48,48,48,0,0,0,0,0,0,0,0,0,0,0,48,48,48,0,0,0,0
0,0,0,0,0,0,0,48,48,48,46,0,0,0,0,0,0,0,0,0,0,48,48,48,46
0,0,0,0,0,0,0,0,0,0,0,0,0,0,0,0,0,0,0,0,0,0,0,0,0
:endlayer
layer: 26
0,0,0,0,0,0,0,0,0,0,0,0,0,0,0,0,0,0,0,0,0,0,0,0,0
0,0,0,0,0,0,0,0,0,0,0,0,0,0,0,0,0,0,0,0,0,0,0,0,0
0,0,0,0,0,0,0,0,0,0,0,0,0,0,0,0,0,0,0,0,0,0,0,0,0
0,0,0,0,0,0,0,0,0,0,0,0,0,0,0,0,0,0,0,0,0,0,0,0,0
0,0,0,0,0,0,0,0,0,0,0,0,0,0,0,0,0,0,0,0,0,0,0,0,0
0,0,0,0,0,0,0,0,0,0,0,0,0,0,0,0,0,0,0,0,0,0,0,0,0
0,0,0,0,0,0,0,0,0,0,0,0,0,0,0,0,0,0,0,0,0,0,0,0,0
0,0,0,0,0,0,0,0,0,0,0,0,54,0,0,0,0,0,0,0,0,0,0,0,0
0,0,0,0,0,0,0,0,0,0,0,0,0,0,0,0,0,0,0,0,0,0,0,0,0
0,0,0,0,0,0,0,0,0,0,0,0,0,0,0,0,0,0,0,0,0,0,0,0,0
0,0,0,0,0,0,0,0,0,0,0,0,0,0,0,0,0,0,0,0,0,0,0,0,0
0,0,0,0,0,0,0,0,0,0,0,0,0,0,0,0,0,0,0,0,0,0,0,0,0
0,0,46,0,0,0,0,0,0,0,0,0,0,0,0,0,0,0,46,0,0,0,0,0,0
0,0,0,48,48,48,0,0,0,0,0,0,0,0,0,0,0,0,0,48,48,0,0,0,0
0,0,0,0,0,0,48,48,48,48,46,0,0,0,0,0,0,0,0,0,0,48,48,48,46
0,0,0,0,0,0,0,0,0,0,0,0,0,0,0,0,0,0,0,0,0,0,0,0,0
:endlayer
layer: 27
0,0,0,0,0,0,0,0,0,0,0,0,0,0,0,0,0,0,0,0,0,0,0,0,0
0,0,0,0,0,0,0,0,0,0,0,0,0,0,0,0,0,0,0,0,0,0,0,0,0
0,0,0,0,0,0,0,0,0,0,0,0,0,0,0,0,0,0,0,0,0,0,0,0,0
0,0,0,0,0,0,0,0,0,0,0,0,0,0,0,0,0,0,0,0,0,0,0,0,0
0,0,0,0,0,0,0,0,0,0,0,0,0,0,0,0,0,0,0,0,0,0,0,0,0
0,0,0,0,0,0,0,0,0,0,0,0,0,0,0,0,0,0,0,0,0,0,0,0,0
0,0,0,0,0,0,0,0,0,0,0,0,0,0,0,0,0,0,0,0,0,0,0,0,0
0,0,0,0,0,0,0,0,0,0,0,0,0,0,0,0,0,0,0,0,0,0,0,0,0
0,0,0,0,0,0,0,0,0,0,0,0,0,0,0,0,0,0,0,0,0,0,0,0,0
0,0,0,0,0,0,0,0,0,0,0,0,0,0,0,0,0,0,0,0,0,0,0,0,0
0,0,0,0,0,0,0,0,0,0,0,0,0,0,0,0,0,0,0,0,0,0,0,0,0
0,0,0,0,0,0,0,0,0,0,0,0,0,0,0,0,0,0,0,0,0,0,0,0,0
0,0,0,0,0,0,0,0,0,0,0,0,0,0,0,0,0,0,0,46,0,0,0,0,0
0,46,48,48,48,0,0,0,0,0,0,0,0,0,0,0,0,0,0,0,48,48,0,0,0
0,0,0,0,0,48,48,48,48,46,0,0,0,0,0,0,0,0,0,0,0,0,48,48,46
0,0,0,0,0,0,0,0,0,0,0,0,0,0,0,0,0,0,0,0,0,0,0,0,0
:endlayer
layer: 28
0,0,0,0,0,0,0,0,0,0,0,0,0,0,0,0,0,0,0,0,0,0,0,0,0
0,0,0,0,0,0,0,0,0,0,0,0,0,0,0,0,0,0,0,0,0,0,0,0,0
0,0,0,0,0,0,0,0,0,0,0,0,0,0,0,0,0,0,0,0,0,0,0,0,0
0,0,0,0,0,0,0,0,0,0,0,0,0,0,0,0,0,0,0,0,0,0,0,0,0
0,0,0,0,0,0,0,0,0,0,0,0,0,0,0,0,0,0,0,0,0,0,0,0,0
0,0,0,0,0,0,0,0,0,0,0,0,0,0,0,0,0,0,0,0,0,0,0,0,0
0,0,0,0,0,0,0,0,0,0,0,0,0,0,0,0,0,0,0,0,0,0,0,0,0
0,0,0,0,0,0,0,0,0,0,0,0,0,0,0,0,0,0,0,0,0,0,0,0,0
0,0,0,0,0,0,0,0,0,0,0,0,0,0,0,0,0,0,0,0,0,0,0,0,0
0,0,0,0,0,0,0,0,0,0,0,0,0,0,0,0,0,0,0,0,0,0,0,0,0
0,0,0,0,0,0,0,0,0,0,0,0,0,0,0,0,0,0,0,0,0,0,0,0,0
0,0,0,0,0,0,0,0,0,0,0,0,0,0,0,0,0,0,0,0,0,0,0,0,0
0,0,0,0,0,0,0,0,0,0,0,0,0,0,0,0,0,0,0,0,46,0,0,0,0
0,46,48,0,0,0,0,0,0,0,0,0,0,0,0,0,0,0,0,0,0,48,48,0,0
0,0,0,48,48,48,48,48,46,0,0,0,0,0,0,0,0,0,0,0,0,0,0,48,46
0,0,0,0,0,0,0,0,0,0,0,0,0,0,0,0,0,0,0,0,0,0,0,0,0
:endlayer
layer: 29
0,0,0,0,0,0,0,0,0,0,0,0,0,0,0,0,0,0,0,0,0,0,0,0,0
0,0,0,0,0,0,0,0,0,0,0,0,0,0,0,0,0,0,0,0,0,0,0,0,0
0,0,0,0,0,0,0,0,0,0,0,0,0,0,0,0,0,0,0,0,0,0,0,0,0
0,0,0,0,0,0,0,0,0,0,0,0,0,0,0,0,0,0,0,0,0,0,0,0,0
0,0,0,0,0,0,0,0,0,0,0,0,0,0,0,0,0,0,0,0,0,0,0,0,0
0,0,0,0,0,0,0,0,0,0,0,0,0,0,0,0,0,0,0,0,0,0,0,0,0
0,0,0,0,0,0,0,0,0,0,0,0,0,0,0,0,0,0,0,0,0,0,0,0,0
0,0,0,0,0,0,0,0,0,0,0,0,0,0,0,0,0,0,0,0,0,0,0,0,0
0,0,0,0,0,0,0,0,0,0,0,0,0,0,0,0,0,0,0,0,0,0,0,0,0
0,0,0,0,0,0,0,0,0,0,0,0,0,0,0,0,0,0,0,0,0,0,0,0,0
0,0,0,0,0,0,0,0,0,0,0,0,0,0,0,0,0,0,0,0,0,0,0,0,0
0,0,0,0,0,0,0,0,0,0,0,0,0,0,0,0,0,0,0,0,0,0,0,0,0
0,0,0,0,0,0,0,0,0,0,0,0,0,0,0,0,0,0,0,0,0,0,0,0,0
0,0,0,0,0,0,0,0,0,0,0,0,0,0,0,0,0,0,0,0,0,46,46,0,0
0,46,48,48,48,48,48,46,0,0,0,0,0,0,0,0,0,0,0,0,0,0,0,46,0
0,0,0,0,0,0,0,0,0,0,0,0,0,0,0,0,0,0,0,0,0,0,0,0,0
:endlayer

#### RULES ####
rule:
plugin=vanillaBlocks
number=1
data:
tag:
TAG=10={
TAG=8=blockName{grass}
TAG=3=meta{0}
TAG=3=buildPass{0}
}
:endtag
:enddata
:endrule

rule:
plugin=vanillaBlocks
number=2
data:
tag:
TAG=10={
TAG=8=blockName{dirt}
TAG=3=meta{0}
TAG=3=buildPass{0}
}
:endtag
:enddata
:endrule

rule:
plugin=vanillaBlocks
number=3
data:
tag:
TAG=10={
TAG=8=blockName{planks}
TAG=3=meta{3}
TAG=3=buildPass{0}
}
:endtag
:enddata
:endrule

rule:
plugin=vanillaBlocks
number=4
data:
tag:
TAG=10={
TAG=8=blockName{mossy_cobblestone}
TAG=3=meta{0}
TAG=3=buildPass{0}
}
:endtag
:enddata
:endrule

rule:
plugin=vanillaBlocks
number=5
data:
tag:
TAG=10={
TAG=8=blockName{gravel}
TAG=3=meta{0}
TAG=3=buildPass{1}
}
:endtag
:enddata
:endrule

rule:
plugin=vanillaBlocks
number=6
data:
tag:
TAG=10={
TAG=8=blockName{stone_slab}
TAG=3=meta{8}
TAG=3=buildPass{0}
}
:endtag
:enddata
:endrule

rule:
plugin=vanillaBlocks
number=7
data:
tag:
TAG=10={
TAG=8=blockName{torch}
TAG=3=meta{5}
TAG=3=buildPass{1}
}
:endtag
:enddata
:endrule

rule:
plugin=vanillaBlocks
number=8
data:
tag:
TAG=10={
TAG=8=blockName{stone_slab}
TAG=3=meta{0}
TAG=3=buildPass{0}
}
:endtag
:enddata
:endrule

rule:
plugin=vanillaBlocks
number=9
data:
tag:
TAG=10={
TAG=8=blockName{stone_slab}
TAG=3=meta{3}
TAG=3=buildPass{0}
}
:endtag
:enddata
:endrule

rule:
plugin=vanillaBlocks
number=10
data:
tag:
TAG=10={
TAG=8=blockName{cobblestone}
TAG=3=meta{0}
TAG=3=buildPass{0}
}
:endtag
:enddata
:endrule

rule:
plugin=vanillaBlocks
number=11
data:
tag:
TAG=10={
TAG=8=blockName{log}
TAG=3=meta{0}
TAG=3=buildPass{0}
}
:endtag
:enddata
:endrule

rule:
plugin=vanillaBlocks
number=12
data:
tag:
TAG=10={
TAG=8=blockName{stone_stairs}
TAG=3=meta{2}
TAG=3=buildPass{0}
}
:endtag
:enddata
:endrule

rule:
plugin=vanillaBlocks
number=13
data:
tag:
TAG=10={
TAG=8=blockName{stained_hardened_clay}
TAG=3=meta{12}
TAG=3=buildPass{0}
}
:endtag
:enddata
:endrule

rule:
plugin=vanillaBlocks
number=14
data:
tag:
TAG=10={
TAG=8=blockName{hardened_clay}
TAG=3=meta{0}
TAG=3=buildPass{0}
}
:endtag
:enddata
:endrule

rule:
plugin=vanillaBlocks
number=15
data:
tag:
TAG=10={
TAG=8=blockName{stone_stairs}
TAG=3=meta{0}
TAG=3=buildPass{0}
}
:endtag
:enddata
:endrule

rule:
plugin=vanillaBlocks
number=16
data:
tag:
TAG=10={
TAG=8=blockName{stone_stairs}
TAG=3=meta{1}
TAG=3=buildPass{0}
}
:endtag
:enddata
:endrule

rule:
plugin=vanillaBlocks
number=17
data:
tag:
TAG=10={
TAG=8=blockName{stone}
TAG=3=meta{0}
TAG=3=buildPass{0}
}
:endtag
:enddata
:endrule

rule:
plugin=vanillaBlocks
number=18
data:
tag:
TAG=10={
TAG=8=blockName{stained_hardened_clay}
TAG=3=meta{4}
TAG=3=buildPass{0}
}
:endtag
:enddata
:endrule

rule:
plugin=vanillaBlocks
number=19
data:
tag:
TAG=10={
TAG=8=blockName{ladder}
TAG=3=meta{5}
TAG=3=buildPass{1}
}
:endtag
:enddata
:endrule

rule:
plugin=vanillaBlocks
number=20
data:
tag:
TAG=10={
TAG=8=blockName{stone_stairs}
TAG=3=meta{3}
TAG=3=buildPass{0}
}
:endtag
:enddata
:endrule

rule:
plugin=vanillaBlocks
number=21
data:
tag:
TAG=10={
TAG=8=blockName{stonebrick}
TAG=3=meta{2}
TAG=3=buildPass{0}
}
:endtag
:enddata
:endrule

rule:
plugin=vanillaBlocks
number=22
data:
tag:
TAG=10={
TAG=8=blockName{stonebrick}
TAG=3=meta{0}
TAG=3=buildPass{0}
}
:endtag
:enddata
:endrule

rule:
plugin=vanillaBlocks
number=23
data:
tag:
TAG=10={
TAG=8=blockName{torch}
TAG=3=meta{1}
TAG=3=buildPass{1}
}
:endtag
:enddata
:endrule

rule:
plugin=vanillaBlocks
number=24
data:
tag:
TAG=10={
TAG=8=blockName{torch}
TAG=3=meta{2}
TAG=3=buildPass{1}
}
:endtag
:enddata
:endrule

rule:
plugin=vanillaBlocks
number=25
data:
tag:
TAG=10={
TAG=8=blockName{torch}
TAG=3=meta{3}
TAG=3=buildPass{1}
}
:endtag
:enddata
:endrule

rule:
plugin=vanillaBlocks
number=26
data:
tag:
TAG=10={
TAG=8=blockName{stonebrick}
TAG=3=meta{3}
TAG=3=buildPass{0}
}
:endtag
:enddata
:endrule

rule:
plugin=vanillaBlocks
number=27
data:
tag:
TAG=10={
TAG=8=blockName{fence}
TAG=3=meta{0}
TAG=3=buildPass{0}
}
:endtag
:enddata
:endrule

rule:
plugin=vanillaBlocks
number=28
data:
tag:
TAG=10={
TAG=8=blockName{torch}
TAG=3=meta{4}
TAG=3=buildPass{1}
}
:endtag
:enddata
:endrule

rule:
plugin=vanillaBlocks
number=29
data:
tag:
TAG=10={
TAG=8=blockName{stone_brick_stairs}
TAG=3=meta{6}
TAG=3=buildPass{0}
}
:endtag
:enddata
:endrule

rule:
plugin=vanillaBlocks
number=30
data:
tag:
TAG=10={
TAG=8=blockName{stone_brick_stairs}
TAG=3=meta{3}
TAG=3=buildPass{0}
}
:endtag
:enddata
:endrule

rule:
plugin=vanillaBlocks
number=31
data:
tag:
TAG=10={
TAG=8=blockName{oak_stairs}
TAG=3=meta{2}
TAG=3=buildPass{0}
}
:endtag
:enddata
:endrule

rule:
plugin=vanillaBlocks
number=32
data:
tag:
TAG=10={
TAG=8=blockName{oak_stairs}
TAG=3=meta{0}
TAG=3=buildPass{0}
}
:endtag
:enddata
:endrule

rule:
plugin=vanillaBlocks
number=33
data:
tag:
TAG=10={
TAG=8=blockName{wooden_slab}
TAG=3=meta{8}
TAG=3=buildPass{0}
}
:endtag
:enddata
:endrule

rule:
plugin=vanillaBlocks
number=34
data:
tag:
TAG=10={
TAG=8=blockName{oak_stairs}
TAG=3=meta{1}
TAG=3=buildPass{0}
}
:endtag
:enddata
:endrule

rule:
plugin=vanillaBlocks
number=35
data:
tag:
TAG=10={
TAG=8=blockName{oak_stairs}
TAG=3=meta{3}
TAG=3=buildPass{0}
}
:endtag
:enddata
:endrule

rule:
plugin=vanillaBlocks
number=36
data:
tag:
TAG=10={
TAG=8=blockName{hay_block}
TAG=3=meta{8}
TAG=3=buildPass{0}
}
:endtag
:enddata
:endrule

rule:
plugin=vanillaBlocks
number=37
data:
tag:
TAG=10={
TAG=8=blockName{rail}
TAG=3=meta{2}
TAG=3=buildPass{1}
}
:endtag
:enddata
:endrule

rule:
plugin=vanillaBlocks
number=38
data:
tag:
TAG=10={
TAG=8=blockName{rail}
TAG=3=meta{3}
TAG=3=buildPass{1}
}
:endtag
:enddata
:endrule

rule:
plugin=vanillaBlocks
number=39
data:
tag:
TAG=10={
TAG=8=blockName{hay_block}
TAG=3=meta{4}
TAG=3=buildPass{0}
}
:endtag
:enddata
:endrule

rule:
plugin=vanillaBlocks
number=40
data:
tag:
TAG=10={
TAG=8=blockName{ladder}
TAG=3=meta{4}
TAG=3=buildPass{1}
}
:endtag
:enddata
:endrule

rule:
plugin=vanillaBlocks
number=41
data:
tag:
TAG=10={
TAG=8=blockName{hay_block}
TAG=3=meta{0}
TAG=3=buildPass{0}
}
:endtag
:enddata
:endrule

rule:
plugin=vanillaBlocks
number=42
data:
tag:
TAG=10={
TAG=8=blockName{spruce_stairs}
TAG=3=meta{2}
TAG=3=buildPass{0}
}
:endtag
:enddata
:endrule

rule:
plugin=vanillaBlocks
number=43
data:
tag:
TAG=10={
TAG=8=blockName{spruce_stairs}
TAG=3=meta{0}
TAG=3=buildPass{0}
}
:endtag
:enddata
:endrule

rule:
plugin=vanillaBlocks
number=44
data:
tag:
TAG=10={
TAG=8=blockName{spruce_stairs}
TAG=3=meta{1}
TAG=3=buildPass{0}
}
:endtag
:enddata
:endrule

rule:
plugin=vanillaBlocks
number=45
data:
tag:
TAG=10={
TAG=8=blockName{spruce_stairs}
TAG=3=meta{3}
TAG=3=buildPass{0}
}
:endtag
:enddata
:endrule

rule:
plugin=vanillaBlocks
number=46
data:
tag:
TAG=10={
TAG=8=blockName{wool}
TAG=3=meta{14}
TAG=3=buildPass{0}
}
:endtag
:enddata
:endrule

rule:
plugin=vanillaBlocks
number=47
data:
tag:
TAG=10={
TAG=8=blockName{rail}
TAG=3=meta{1}
TAG=3=buildPass{1}
}
:endtag
:enddata
:endrule

rule:
plugin=vanillaBlocks
number=48
data:
tag:
TAG=10={
TAG=8=blockName{wool}
TAG=3=meta{0}
TAG=3=buildPass{0}
}
:endtag
:enddata
:endrule

rule:
plugin=vanillaBlocks
number=49
data:
tag:
TAG=10={
TAG=8=blockName{planks}
TAG=3=meta{0}
TAG=3=buildPass{0}
}
:endtag
:enddata
:endrule

rule:
plugin=vanillaBlocks
number=50
data:
tag:
TAG=10={
TAG=8=blockName{glass_pane}
TAG=3=meta{0}
TAG=3=buildPass{0}
}
:endtag
:enddata
:endrule

rule:
plugin=vanillaBlocks
number=51
data:
tag:
TAG=10={
TAG=8=blockName{log}
TAG=3=meta{8}
TAG=3=buildPass{0}
}
:endtag
:enddata
:endrule

rule:
plugin=vanillaBlocks
number=52
data:
tag:
TAG=10={
TAG=8=blockName{stone_button}
TAG=3=meta{3}
TAG=3=buildPass{3}
}
:endtag
:enddata
:endrule

rule:
plugin=vanillaBlocks
number=53
data:
tag:
TAG=10={
TAG=8=blockName{planks}
TAG=3=meta{1}
TAG=3=buildPass{0}
}
:endtag
:enddata
:endrule

rule:
plugin=vanillaBlocks
number=54
data:
tag:
TAG=10={
TAG=8=blockName{wooden_slab}
TAG=3=meta{1}
TAG=3=buildPass{0}
}
:endtag
:enddata
:endrule

#### ENTITIES ####
